File: datas/d100-90-0.175.csv
Stage Number,Time since start of test (s),Time since start of stage (s),Radial Pressure (kPa),Radial Volume (mm3),Back Pressure (kPa),Back Volume (mm3),Load Cell (kN),Pore Pressure (kPa),Axial Displacement (mm),L/C Pressure (kPa),L/C Volume (mm3),Local Axial 1,Local Axial 2,Local Radial,Base Pressure (kPa),Base Volume (mm3),Back Differential Pressure (kPa),Axial Displacement 2 (mm),Pore Air Pressure (kPa),Pore Air Volume (mm3),Atmospheric Pressure (kPa),Temperature (°C),Mid Plane PWP (kPa),Back to Cell Differential (kPa),Total Volume Change (mm3),Undefined Tx 1,Undefined Tx 2,Undefined Tx 3,Undefined Tx. 4,HCA secondary control axial load (kN),HCA secondary control torque,Internal Cell Pr. (kPa),Internal Cell Vol. (mm3),Rotational Displ. (mm),Torque,Local Int Defmn 1 (mm),Local Int Defmn 2 (mm),Circumf. Defmn 1 (mm),Circumf. Defmn 2 (mm),Circumf. Defmn 3 (mm),Outer Cell Pr 2 (kPa),Internal cell Pr 2 (kPa),Rotation 2 (°),Secondary Cell Pr (kPa),Secondary Back Pr (kPa),Axial Force (kN),Axial Strain (%),Av Diameter Change (mm),Radial Strain (%),Axial Stress (kPa),Eff. Axial Stress (kPa),Eff. Radial Stress (kPa),Deviator Stress (kPa),Total Stress Ratio (%),Eff. Stress Ratio (%),Current Area (mm2),Shear Strain (%),Cambridge p (kPa),Eff. Cambridge p' (kPa),Max Shear Stress t,Volume Change (mm3),B Value,Mean Stress s/Eff. Axial Stress 2,Excess PWP (kPa),PWP Ratio,Lower Chamber Displacement (mm),Lower Chamber Axial Load (kPa),Specimen Air Volume (mm3),Matric Suction (kPa),Voids ratio,Degree of Saturation (°),Specimen Water Volume (mm3),kRT constant,Permeability IN,Permeability OUT,HCA Outer Rad,HCA Inner Rad,HCA Sigma Z (kPa),HCA Sigma R (kPa),HCA Sigma Theta (kPa),HCA Tau Theta Z,HCA Ez,HCA Er,HCA Etheta,HCA Gamma,HCA Sigma1,HCA Sigma2,HCA Sigma3,HCA Eff Sigma1,HCA Eff Sigma2,HCA Eff Sigma3,HCA E1,HCA E2,HCA E3,HCA P,HCA Eff P,HCA Q,HCA B,HCA Eff R,HCA Alpha,HCA Ev,HCA E1 rtv
1,0,0,604.559,135596.3,501,0,-0.1807,502.9013,0.0002,0,0,0.0528,0.0522,0.0518,0,0,0,2.9926,0,0,100,0,0,0,0,0,0,0,0,0,0,592.1887,-6267.776,-0.0011,0.02,0,0,0,0,0,0,0,0,0,0,4.5675,0.0001,0.0001,0.0001,581.5521,78.6508,101.6577,-23.0069,0.9619,0.7737,7853.983,0.0001,596.8901,93.9888,-11.5035,0,-0.261,90.1543,1.9013,0.0242,0,0,1555010,-502.9013,0,0,0,1.56E+08,0,0,50.1007,30.1675,575.6461,599.9098,623.2806,0.0971,0.0001,0.3351,-0.3341,-0.0004,623.2808,599.9098,575.6459,120.3795,97.0085,72.7446,0.0001,0.3351,-0.3341,599.6122,96.7109,47.6349,0.5094,1.6548,89.8832,0.0011,-0.0006
1,2.6,2.6,604.852,135703.4,501,0,-0.1879,503.1664,-0.0181,0,0,0.0528,0.0522,0.0518,0,0,0,2.9754,0,0,100,0,0,0,0,0,0,0,0,0,0,591.9268,-6324.114,0.216,3.5724,0,0,0,0,0,0,0,0,0,0,4.5622,-0.0091,-0.0046,-0.0046,580.9307,77.7643,101.6856,-23.9213,0.9605,0.7648,7853.26,-0.0091,596.8782,93.7118,-11.9607,0,4.1145,89.725,2.1664,0.0279,0,0,1555010,-503.1664,0,0,0,1.56E+08,0,0,50.0993,30.1676,574.8196,599.9942,624.4149,17.3535,-0.0091,0.3427,-0.3325,0.078,629.8839,599.9942,569.3506,126.7175,96.8278,66.1842,0,0.3427,-0.3416,599.7429,96.5765,60.5333,0.5062,1.9146,72.5078,0.0011,0.1204
1,5.4,5.4,604.8466,135797.3,502,0,-0.1878,504.4355,-0.0129,0,0,0.0528,0.0522,0.0518,0,0,0,2.9792,0,0,100,0,0,0,0,0,0,0,0,0,0,592.2289,-6390.466,-0.0107,-0.893,0,0,0,0,0,0,0,0,0,0,4.5623,-0.0065,-0.0033,-0.0033,580.9284,76.4929,100.4111,-23.9182,0.9605,0.7618,7853.464,-0.0065,596.8738,92.4383,-11.9591,0,21.8766,88.452,2.4355,0.0318,0,0,1555010,-504.4355,0,0,0,1.56E+08,0,0,50.101,30.1698,574.661,600.1043,623.946,-4.3376,-0.0065,0.3452,-0.3374,-0.0039,624.3248,600.1043,574.2822,119.8893,95.6688,69.8467,-0.0065,0.3452,-0.3374,599.5705,95.1349,50.0426,0.516,1.7165,-85.0085,0.0013,-0.0059
1,8.2,8.2,605.0491,135804.8,503,0,-0.1876,505.1489,-0.029,0,0,0.0528,0.0522,0.0518,0,0,0,2.9646,0,0,100,0,0,0,0,0,0,0,0,0,0,592.2457,-6419.261,-0.1992,-3.261,0,0,0,0,0,0,0,0,0,0,4.5637,-0.0146,-0.0073,-0.0073,581.1537,76.0048,99.9002,-23.8954,0.9605,0.7608,7852.829,-0.0146,597.0839,91.935,-11.9477,0,8.3726,87.9525,2.1489,0.0283,0,0,1555010,-505.1489,0,0,0,1.56E+08,0,0,50.0994,30.1693,575.0062,600.2369,624.4302,-15.8414,-0.0146,0.3507,-0.3348,-0.0719,629.0718,600.2369,570.3646,123.9229,95.088,65.2157,-0.0067,0.3507,-0.3427,599.8911,94.7422,58.7072,0.5088,1.9002,-73.6692,0.0013,-0.1121
1,11,11,604.9771,135843.4,504,0,-0.1873,505.9651,-0.0283,0,0,0.0528,0.0522,0.0518,0,0,0,2.9573,0,0,100,0,0,0,0,0,0,0,0,0,0,591.9216,-6487.491,0.0922,2.1111,0,0,0,0,0,0,0,0,0,0,4.5635,-0.0143,-0.0071,-0.0071,581.1264,75.1613,99.012,-23.8507,0.9606,0.7591,7852.852,-0.0143,597.0269,91.0618,-11.9254,0,15.3548,87.0867,1.9651,0.0261,0,0,1555010,-505.9651,0,0,0,1.56E+08,0,0,50.1006,30.1712,575.1385,600.07,624.7419,10.255,-0.0143,0.3542,-0.3386,0.0333,626.7784,600.07,573.102,120.8133,94.1049,67.1369,-0.0126,0.3542,-0.3403,599.9835,94.0184,53.6764,0.5024,1.7995,78.7679,0.0013,0.0513
1,13.8,13.8,604.8564,135862.9,504,0,-0.1875,506.8598,-0.0383,0,0,0.0528,0.0522,0.0518,0,0,0,2.945,0,0,100,0,0,0,0,0,0,0,0,0,0,592.2462,-6508.773,0.1496,2.4523,0,0,0,0,0,0,0,0,0,0,4.5621,-0.0193,-0.0096,-0.0096,580.9772,74.1174,97.9966,-23.8792,0.9605,0.7563,7852.459,-0.0193,596.8967,90.0369,-11.9396,0,48.6862,86.057,2.8598,0.0386,0,0,1555010,-506.8598,0,0,0,1.56E+08,0,0,50.0997,30.171,574.7229,600.1166,623.9474,11.9132,-0.0193,0.3578,-0.3372,0.054,626.679,600.1166,571.9913,119.8192,93.2568,65.1315,-0.0148,0.3578,-0.3417,599.5956,92.7358,54.6877,0.5143,1.8397,77.0857,0.0013,0.0848
1,16.6,16.6,604.8966,135923.3,505,0,-0.187,507.5563,-0.0402,0,0,0.0528,0.0522,0.0518,0,0,0,2.9475,0,0,100,0,0,0,0,0,0,0,0,0,0,592.0757,-6574.5,-0.1686,-3.0195,0,0,0,0,0,0,0,0,0,0,4.5629,-0.0203,-0.0101,-0.0101,581.0849,73.5286,97.3403,-23.8117,0.9606,0.7554,7852.381,-0.0203,596.9594,89.4031,-11.9059,0,38.4013,85.4345,2.5563,0.0348,0,0,1555010,-507.5563,0,0,0,1.56E+08,0,0,50.1005,30.1726,574.983,600.0776,624.3086,-14.6684,-0.0203,0.3618,-0.3402,-0.0609,628.341,600.0776,570.9505,120.7847,92.5213,63.3942,-0.0146,0.3618,-0.3459,599.7897,92.2334,57.3905,0.5075,1.9053,-74.6288,0.0013,-0.0951
1,19.4,19.4,604.7345,135991.7,506,0,-0.1881,508.58,-0.0437,0,0,0.0528,0.0522,0.0518,0,0,0,2.9329,0,0,100,0,0,0,0,0,0,0,0,0,0,592.3655,-6617.685,-0.1046,-1.3133,0,0,0,0,0,0,0,0,0,0,4.5604,-0.0221,-0.011,-0.011,580.777,72.197,96.1545,-23.9575,0.9604,0.7508,7852.24,-0.0221,596.7487,88.1687,-11.9788,0,-145.4466,84.1758,2.58,0.0357,0,0,1555010,-508.58,0,0,0,1.56E+08,0,0,50.1007,30.1735,574.3446,600.0852,623.4634,-6.3799,-0.0221,0.3653,-0.3416,-0.0378,624.2785,600.0852,573.5295,115.6985,91.5052,64.9495,-0.0199,0.3653,-0.3438,599.2978,90.7177,50.749,0.5233,1.7814,-82.7189,0.0016,-0.0591
1,22.2,22.2,604.9119,136017,507,0,-0.187,509.2359,-0.0554,0,0,0.0528,0.0522,0.0518,0,0,0,2.9529,0,0,100,0,0,0,0,0,0,0,0,0,0,591.8598,-6669.021,0.2107,3.5233,0,0,0,0,0,0,0,0,0,0,4.5626,-0.028,-0.014,-0.014,581.0915,71.8556,95.676,-23.8204,0.9606,0.751,7851.776,-0.028,596.9717,87.7358,-11.9102,0,46.3092,83.7658,2.2359,0.0311,0,0,1555010,-509.2359,0,0,0,1.56E+08,0,0,50.1001,30.1739,575.1284,600.0058,624.6765,17.1169,-0.028,0.3704,-0.3413,0.0761,630.0146,600.0058,569.7903,120.7787,90.7699,60.5544,-0.019,0.3704,-0.3503,599.9369,90.701,60.2243,0.5017,1.9945,72.6793,0.0011,0.1212
1,25,25,605.2036,136099.2,508,0,-0.187,510.1753,-0.0521,0,0,0.0528,0.0522,0.0518,0,0,0,2.9022,0,0,100,0,0,0,0,0,0,0,0,0,0,592.1378,-6739.754,0.0197,-0.0134,0,0,0,0,0,0,0,0,0,0,4.565,-0.0263,-0.0131,-0.0131,581.3872,71.2119,95.0283,-23.8164,0.9606,0.7494,7851.91,-0.0263,597.2648,87.0895,-11.9082,0,17.0591,83.1201,2.1753,0.0305,0,0,1555010,-510.1753,0,0,0,1.56E+08,0,0,50.1016,30.1761,575.4293,600.2922,624.991,-0.0651,-0.0263,0.3739,-0.3459,0.0071,624.9911,600.2922,575.4293,114.8158,90.1169,65.254,-0.0262,0.3739,-0.346,600.2375,90.0622,49.5618,0.5017,1.7595,-89.9247,0.0017,0.0111
1,27.8,27.8,604.9827,136139.4,508,0,-0.1877,510.5956,-0.0652,0,0,0.0528,0.0522,0.0518,0,0,0,2.9107,0,0,100,0,0,0,0,0,0,0,0,0,0,591.7284,-6769.174,-0.2478,-3.5376,0,0,0,0,0,0,0,0,0,0,4.5623,-0.0329,-0.0164,-0.0164,581.0817,70.4861,94.3871,-23.901,0.9605,0.7468,7851.392,-0.0329,597.0157,86.4201,-11.9505,0,37.1185,82.4366,2.5956,0.0368,0,0,1555010,-510.5956,0,0,0,1.56E+08,0,0,50.1005,30.1759,575.1745,600.0004,625.0564,-17.1868,-0.0329,0.3784,-0.3443,-0.0894,630.4047,600.0004,569.8262,119.8091,89.4048,59.2306,-0.0206,0.3784,-0.3566,600.0771,89.4815,60.5785,0.4981,2.0228,-72.7146,0.0012,-0.1432
1,30.6,30.6,604.9845,136204.7,509,0,-0.1871,511.4502,-0.0619,0,0,0.0528,0.0522,0.0518,0,0,0,2.9067,0,0,100,0,0,0,0,0,0,0,0,0,0,592.1777,-6849.717,0.041,1.3379,0,0,0,0,0,0,0,0,0,0,4.5629,-0.0313,-0.0156,-0.0156,581.1488,69.6986,93.5343,-23.8357,0.9606,0.7452,7851.518,-0.0313,597.0392,85.589,-11.9179,0,40.8649,81.6165,2.4502,0.0352,0,0,1555010,-511.4502,0,0,0,1.56E+08,0,0,50.1021,30.1782,575.0424,600.1703,624.3827,6.4996,-0.0313,0.382,-0.3492,0.0148,625.2245,600.1703,574.2006,113.7743,88.7201,62.7504,-0.031,0.382,-0.3495,599.8652,88.4149,51.0239,0.509,1.8131,82.6201,0.0015,0.0233
1,33.4,33.4,604.7375,136249.1,509,0,-0.1869,512.1144,-0.0754,0,0,0.0528,0.0522,0.0518,0,0,0,2.9078,0,0,100,0,0,0,0,0,0,0,0,0,0,592.0209,-6877.466,0.198,3.0974,0,0,0,0,0,0,0,0,0,0,4.5609,-0.0381,-0.019,-0.019,580.9336,68.8192,92.6231,-23.8039,0.9606,0.743,7850.984,-0.0381,596.8029,84.6885,-11.902,0,-254.3819,80.7212,3.1144,0.0453,0,0,1555010,-512.1144,0,0,0,1.56E+08,0,0,50.1009,30.178,574.7817,599.9572,623.9999,15.0486,-0.0381,0.387,-0.3474,0.0715,628.2363,599.9572,570.5452,116.1219,87.8428,58.4309,-0.03,0.387,-0.3555,599.5796,87.4652,57.691,0.5098,1.9873,74.277,0.0015,0.1154
1,36.2,36.2,604.9627,136346.3,510,0,-0.1881,512.7589,-0.0723,0,0,0.0528,0.0522,0.0518,0,0,0,2.8944,0,0,100,0,0,0,0,0,0,0,0,0,0,592.0341,-6969.483,-0.1451,-2.4454,0,0,0,0,0,0,0,0,0,0,4.5615,-0.0365,-0.0182,-0.0182,581.0007,68.2418,92.2038,-23.962,0.9604,0.7401,7851.109,-0.0365,596.9753,84.2164,-11.981,0,52.5141,80.2228,2.7589,0.0404,0,0,1555010,-512.7589,0,0,0,1.56E+08,0,0,50.1027,30.1806,574.8905,600.1025,624.5485,-11.8801,-0.0365,0.391,-0.3529,-0.0524,627.2443,600.1025,572.1946,114.4854,87.3436,59.4357,-0.0322,0.391,-0.3572,599.8471,87.0882,55.0497,0.507,1.9262,-77.215,0.0016,-0.0827
1,39,39,604.9186,136394.5,511,0,-0.1881,513.3581,-0.0802,0,0,0.0528,0.0522,0.0518,0,0,0,2.8834,0,0,100,0,0,0,0,0,0,0,0,0,0,591.9254,-7005.789,-0.1688,-2.0958,0,0,0,0,0,0,0,0,0,0,4.561,-0.0405,-0.0202,-0.0202,580.9602,67.6021,91.5605,-23.9584,0.9604,0.7383,7850.795,-0.0405,596.9324,83.5743,-11.9792,0,72.6764,79.5813,2.3581,0.0349,0,0,1555010,-513.3581,0,0,0,1.56E+08,0,0,50.1023,30.181,574.8821,600.0341,624.6033,-10.1821,-0.0405,0.3951,-0.3529,-0.0609,626.6076,600.0341,572.8777,113.2495,86.676,59.5196,-0.0347,0.3951,-0.3587,599.8398,86.4817,53.7299,0.5054,1.9027,-78.8638,0.0017,-0.0974
1,41.8,41.8,605.253,136430.5,511,0,-0.1875,513.9032,-0.0877,0,0,0.0528,0.0522,0.0518,0,0,0,2.8796,0,0,100,0,0,0,0,0,0,0,0,0,0,591.8923,-7072.598,0.1901,3.2386,0,0,0,0,0,0,0,0,0,0,4.564,-0.0443,-0.0221,-0.0221,581.3645,67.4613,91.3498,-23.8885,0.9605,0.7385,7850.497,-0.0443,597.2902,83.387,-11.9443,0,23.0824,79.4056,2.9032,0.043,0,0,1555010,-513.9032,0,0,0,1.56E+08,0,0,50.1024,30.1822,575.5448,600.2302,625.4965,15.7347,-0.0443,0.4006,-0.3545,0.0686,630.0397,600.2302,571.0016,116.1365,86.327,57.0984,-0.0369,0.4006,-0.3619,600.4238,86.5206,59.0381,0.4951,2.034,73.8946,0.0018,0.1104
1,44.6,44.6,604.9807,136451.1,512,0,-0.1873,514.6882,-0.0885,0,0,0.0528,0.0522,0.0518,0,0,0,2.8682,0,0,100,0,0,0,0,0,0,0,0,0,0,592.3424,-7120.34,0.0743,0.8781,0,0,0,0,0,0,0,0,0,0,4.5621,-0.0447,-0.0223,-0.0223,581.1247,66.4365,90.2925,-23.856,0.9606,0.7358,7850.466,-0.0447,597.0287,82.3405,-11.928,0,57.2713,78.3645,2.6882,0.0405,0,0,1555010,-514.6882,0,0,0,1.56E+08,0,0,50.1031,30.1834,574.9013,600.2294,624.1309,4.2661,-0.0447,0.4031,-0.3568,0.0268,624.4979,600.2294,574.5344,109.8098,85.5412,59.8463,-0.0436,0.4031,-0.3579,599.7539,85.0658,49.9635,0.5143,1.8349,85.0837,0.0016,0.0429
1,47.4,47.4,605.0023,136497,513,0,-0.1871,514.9769,-0.1008,0,0,0.0528,0.0522,0.0518,0,0,0,2.8436,0,0,100,0,0,0,0,0,0,0,0,0,0,591.7645,-7159.15,-0.2711,-3.5775,0,0,0,0,0,0,0,0,0,0,4.5622,-0.0509,-0.0254,-0.0254,581.1735,66.1966,90.0254,-23.8288,0.9606,0.7353,7849.979,-0.0509,597.0594,82.0825,-11.9144,0,53.1176,78.111,1.9769,0.0299,0,0,1555010,-514.9769,0,0,0,1.56E+08,0,0,50.1022,30.1835,575.3025,600.0256,625.062,-17.3821,-0.0509,0.4082,-0.3559,-0.0979,630.5325,600.0256,569.832,115.5555,85.0487,54.855,-0.0359,0.4082,-0.3709,600.1301,85.1531,60.7005,0.4974,2.1066,-72.5301,0.0014,-0.16
1,50.2,50.2,604.6508,136575.3,514,0,-0.187,516.2482,-0.0962,0,0,0.0528,0.0522,0.0518,0,0,0,2.8537,0,0,100,0,0,0,0,0,0,0,0,0,0,591.978,-7250.541,-0.0248,0.4626,0,0,0,0,0,0,0,0,0,0,4.5596,-0.0486,-0.0243,-0.0243,580.8289,64.5807,88.4026,-23.8219,0.9606,0.7305,7850.16,-0.0486,596.7102,80.462,-11.911,0,-108.8721,76.4917,2.2482,0.0348,0,0,1555010,-516.2482,0,0,0,1.56E+08,0,0,50.1042,30.1863,574.6509,599.8864,623.8569,2.2475,-0.0486,0.4122,-0.3618,-0.009,623.9594,599.8864,574.5485,107.7112,83.6382,58.3003,-0.0485,0.4122,-0.3619,599.4648,83.2166,49.4109,0.5128,1.8475,87.3902,0.0018,-0.0144
1,53,53,604.9479,136602,514,0,-0.1876,516.1046,-0.1146,0,0,0.0528,0.0522,0.0518,0,0,0,2.854,0,0,100,0,0,0,0,0,0,0,0,0,0,592.1876,-7270.572,0.2396,3.4126,0,0,0,0,0,0,0,0,0,0,4.5609,-0.0579,-0.0289,-0.0289,581.0486,64.944,88.8433,-23.8993,0.9605,0.731,7849.43,-0.0579,596.9814,80.8768,-11.9497,0,76.2253,76.8937,2.1046,0.0324,0,0,1555010,-516.1046,0,0,0,1.56E+08,0,0,50.1022,30.1854,574.8752,600.1505,624.287,16.5818,-0.0579,0.4177,-0.3582,0.0865,629.3357,600.1505,569.8264,113.2311,84.0459,53.7218,-0.0459,0.4177,-0.3702,599.7709,83.6663,59.5093,0.5096,2.1077,73.0659,0.0016,0.1437
1,55.8,55.8,605.0552,136695.2,515,0,-0.1866,517.2515,-0.1073,0,0,0.0528,0.0522,0.0518,0,0,0,2.8063,0,0,100,0,0,0,0,0,0,0,0,0,0,592.111,-7368.848,-0.1024,-1.7475,0,0,0,0,0,0,0,0,0,0,4.5629,-0.0542,-0.0271,-0.0271,581.2818,64.0303,87.8037,-23.7734,0.9607,0.7292,7849.721,-0.0542,597.1307,79.8792,-11.8867,0,51.2224,75.917,2.2515,0.0352,0,0,1555010,-517.2515,0,0,0,1.56E+08,0,0,50.1047,30.1886,575.289,600.1885,624.6758,-8.4902,-0.0542,0.4213,-0.3653,-0.037,626.0946,600.1885,573.8702,108.8431,82.937,56.6187,-0.052,0.4213,-0.3675,600.0511,82.7996,52.2244,0.5039,1.9224,-80.5129,0.0018,-0.0594
1,58.6,58.6,605.0359,136723.4,515,0,-0.1857,517.5173,-0.121,0,0,0.0528,0.0522,0.0518,0,0,0,2.8159,0,0,100,0,0,0,0,0,0,0,0,0,0,591.9455,-7390.757,-0.2351,-2.7422,0,0,0,0,0,0,0,0,0,0,4.5633,-0.0611,-0.0305,-0.0305,581.3729,63.8557,87.5186,-23.663,0.9609,0.7296,7849.179,-0.0611,597.1483,79.631,-11.8315,0,56.0082,75.6872,2.5173,0.0394,0,0,1555010,-517.5173,0,0,0,1.56E+08,0,0,50.1034,30.1882,575.5301,600.1141,624.8787,-13.3241,-0.0611,0.4258,-0.3632,-0.0849,628.2464,600.1141,572.1624,110.7291,82.5968,54.6451,-0.0496,0.4258,-0.3747,600.1743,82.657,56.084,0.4984,2.0263,-75.8155,0.0015,-0.1402
1,61.4,61.4,604.7027,136805.1,516,0,-0.1871,518.3589,-0.1235,0,0,0.0528,0.0522,0.0518,0,0,0,2.8203,0,0,100,0,0,0,0,0,0,0,0,0,0,592.0997,-7477.14,0.1541,2.7456,0,0,0,0,0,0,0,0,0,0,4.5593,-0.0624,-0.0312,-0.0312,580.8708,62.5119,86.3438,-23.8319,0.9606,0.724,7849.077,-0.0624,596.7587,78.3998,-11.916,0,-217.8029,74.4279,2.3589,0.0377,0,0,1555010,-518.3589,0,0,0,1.56E+08,0,0,50.1044,30.1903,574.6409,599.964,623.8092,13.3404,-0.0624,0.4313,-0.367,0.0556,627.1956,599.964,571.2546,108.8367,81.6051,52.8957,-0.0574,0.4313,-0.372,599.4714,81.1125,55.941,0.5132,2.0576,75.7569,0.0019,0.0912
1,64.2,64.2,605.076,136830.4,517,0,-0.1864,518.9086,-0.1306,0,0,0.0528,0.0522,0.0518,0,0,0,2.7963,0,0,100,0,0,0,0,0,0,0,0,0,0,592.3439,-7519.061,0.1362,1.7089,0,0,0,0,0,0,0,0,0,0,4.5627,-0.066,-0.033,-0.033,581.3249,62.4163,86.1674,-23.7511,0.9607,0.7244,7848.795,-0.066,597.1589,78.2502,-11.8756,0,53.179,74.2919,1.9086,0.0306,0,0,1555010,-518.9086,0,0,0,1.56E+08,0,0,50.1042,30.1908,575.2264,600.2888,624.3792,8.3035,-0.066,0.4349,-0.3674,0.0492,625.744,600.2888,573.8616,106.8354,81.3802,54.9529,-0.062,0.4349,-0.3714,599.9648,81.0562,51.8825,0.5094,1.9441,80.6659,0.0015,0.0816
1,67,67,605.1254,136925.1,517,0,-0.1878,519.2868,-0.139,0,0,0.0528,0.0522,0.0518,0,0,0,2.7889,0,0,100,0,0,0,0,0,0,0,0,0,0,592.0502,-7580.424,-0.2711,-3.43,0,0,0,0,0,0,0,0,0,0,4.5615,-0.0702,-0.0351,-0.0351,581.1964,61.9096,85.8386,-23.929,0.9605,0.7212,7848.465,-0.0702,597.1491,77.8623,-11.9645,0,46.7753,73.8741,2.2868,0.0369,0,0,1555010,-519.2868,0,0,0,1.56E+08,0,0,50.1041,30.1918,575.192,600.209,624.9506,-16.6668,-0.0702,0.4404,-0.3685,-0.0978,630.0173,600.209,570.1253,110.7305,80.9222,50.8385,-0.0549,0.4404,-0.3838,600.1172,80.8304,59.892,0.5023,2.1781,-73.0908,0.0017,-0.1634
1,69.8,69.8,604.9382,136958.8,518,0,-0.1868,520.3875,-0.1385,0,0,0.0528,0.0522,0.0518,0,0,0,2.7792,0,0,100,0,0,0,0,0,0,0,0,0,0,592.3358,-7637.13,-0.1003,-0.4308,0,0,0,0,0,0,0,0,0,0,4.561,-0.07,-0.035,-0.035,581.1315,60.744,84.5507,-23.8067,0.9606,0.7184,7848.481,-0.07,597.0026,76.6151,-11.9034,0,106.8053,72.6474,2.3875,0.0393,0,0,1555010,-520.3875,0,0,0,1.56E+08,0,0,50.1051,30.1934,574.935,600.1995,624.0479,-2.0932,-0.07,0.4435,-0.3717,-0.0362,624.137,600.1995,574.8459,103.7495,79.812,54.4584,-0.0678,0.4435,-0.3739,599.7275,79.34,49.2911,0.5144,1.9051,-87.5639,0.0018,-0.06
1,72.6,72.6,605.1554,136984.6,518,0,-0.1877,520.1997,-0.1583,0,0,0.0528,0.0522,0.0518,0,0,0,2.7575,0,0,100,0,0,0,0,0,0,0,0,0,0,592.111,-7676.196,0.2689,3.5929,0,0,0,0,0,0,0,0,0,0,4.5614,-0.08,-0.04,-0.04,581.2406,61.0409,84.9557,-23.9148,0.9605,0.7185,7847.697,-0.08,597.1838,76.9841,-11.9574,0,45.4938,72.9983,2.1997,0.036,0,0,1555010,-520.1997,0,0,0,1.56E+08,0,0,50.1032,30.1929,575.2218,600.2505,624.9365,17.4601,-0.08,0.4505,-0.3688,0.097,630.4559,600.2505,569.7025,110.2562,80.0508,49.5028,-0.0645,0.4505,-0.3843,600.1363,79.9366,60.7534,0.5028,2.2273,72.4577,0.0017,0.1674
1,75.4,75.4,604.8662,137096.8,519,0,-0.1865,521.6692,-0.1502,0,0,0.0528,0.0522,0.0518,0,0,0,2.7551,0,0,100,0,0,0,0,0,0,0,0,0,0,592.3439,-7784.857,-0.04,-0.9043,0,0,0,0,0,0,0,0,0,0,4.5605,-0.0759,-0.0379,-0.0379,581.1021,59.4329,83.197,-23.7641,0.9607,0.7144,7848.019,-0.0759,596.9448,75.2756,-11.8821,0,203.9762,71.315,2.6692,0.0449,0,0,1555010,-521.6692,0,0,0,1.56E+08,0,0,50.106,30.1964,574.8769,600.1574,623.8585,-4.394,-0.0759,0.4541,-0.3766,-0.0144,624.2495,600.1574,574.4858,102.5803,78.4882,52.8166,-0.0756,0.4541,-0.3769,599.6309,77.9617,49.7637,0.5159,1.9422,-84.9143,0.0016,-0.0239
1,78.2,78.2,604.9578,137093.5,519,0,-0.1881,521.6396,-0.1701,0,0,0.0528,0.0522,0.0518,0,0,0,2.7405,0,0,100,0,0,0,0,0,0,0,0,0,0,592.1292,-7797.007,-0.305,-3.2696,0,0,0,0,0,0,0,0,0,0,4.5591,-0.0859,-0.0429,-0.0429,580.9818,59.3422,83.3182,-23.976,0.9604,0.7122,7847.234,-0.0859,596.9658,75.3262,-11.988,0,102.1995,71.3302,2.6396,0.0445,0,0,1555010,-521.6396,0,0,0,1.56E+08,0,0,50.1036,30.1952,574.8208,600.1338,624.4151,-15.8896,-0.0859,0.4601,-0.3721,-0.1101,629.0692,600.1338,570.1666,107.4296,78.4942,48.527,-0.0661,0.4601,-0.3919,599.7899,78.1503,58.9026,0.5088,2.2138,-73.6745,0.0021,-0.1916
1,81,81,605.0359,137246,520,0,-0.187,522.7968,-0.1661,0,0,0.0528,0.0522,0.0518,0,0,0,2.732,0,0,100,0,0,0,0,0,0,0,0,0,0,592.0568,-7924.078,0.0966,2.0966,0,0,0,0,0,0,0,0,0,0,4.561,-0.0839,-0.0419,-0.0419,581.2123,58.4155,82.2391,-23.8236,0.9606,0.7103,7847.391,-0.0839,597.0947,74.2979,-11.9118,0,76.1619,70.3273,2.7968,0.0479,0,0,1555010,-522.7968,0,0,0,1.56E+08,0,0,50.1062,30.1989,575.2063,600.1551,624.7249,10.188,-0.0839,0.4657,-0.3799,0.0349,626.7391,600.1551,573.1921,103.9423,77.3583,50.3953,-0.0819,0.4657,-0.3819,600.0287,77.232,53.547,0.5035,2.0625,78.8169,0.0019,0.0589
1,83.8,83.8,604.8424,137247.9,521,0,-0.1871,523.2536,-0.1825,0,0,0.0528,0.0522,0.0518,0,0,0,2.7342,0,0,100,0,0,0,0,0,0,0,0,0,0,592.4867,-7936.572,0.202,2.4835,0,0,0,0,0,0,0,0,0,0,4.5589,-0.0922,-0.0461,-0.0461,580.9928,57.7392,81.5888,-23.8496,0.9606,0.7077,7846.74,-0.0922,596.8925,73.6389,-11.9248,0,298.0134,69.664,2.2536,0.039,0,0,1555010,-523.2536,0,0,0,1.56E+08,0,0,50.1043,30.198,574.6343,600.196,623.5861,12.0696,-0.0922,0.4707,-0.3765,0.0729,626.4003,600.196,571.8202,103.1467,76.9424,48.5666,-0.0831,0.4707,-0.3856,599.4722,76.2186,54.5801,0.5199,2.1238,76.8756,0.002,0.128
1,86.6,86.6,605.1157,137339.3,521,0,-0.1867,523.9719,-0.1848,0,0,0.0528,0.0522,0.0518,0,0,0,2.74,0,0,100,0,0,0,0,0,0,0,0,0,0,592.0329,-8038.629,-0.2525,-3.0325,0,0,0,0,0,0,0,0,0,0,4.5614,-0.0933,-0.0466,-0.0466,581.3178,57.3459,81.1438,-23.7979,0.9607,0.7067,7846.654,-0.0933,597.1831,73.2112,-11.899,0,61.8107,69.2449,2.9719,0.0518,0,0,1555010,-523.9719,0,0,0,1.56E+08,0,0,50.1057,30.2005,575.4031,600.1957,624.9652,-14.7371,-0.0933,0.4763,-0.3813,-0.0911,629.0161,600.1957,571.3522,105.0442,76.2238,47.3803,-0.0795,0.4763,-0.3951,600.188,76.2161,57.6639,0.5002,2.217,-74.6302,0.0017,-0.1577
1,89.4,89.4,604.9473,137380.9,522,0,-0.1876,524.4104,-0.1908,0,0,0.0528,0.0522,0.0518,0,0,0,2.6938,0,0,100,0,0,0,0,0,0,0,0,0,0,592.3626,-8093.088,-0.1935,-1.3226,0,0,0,0,0,0,0,0,0,0,4.5591,-0.0964,-0.0482,-0.0482,581.0427,56.6323,80.5369,-23.9046,0.9605,0.7032,7846.411,-0.0964,596.9791,72.5687,-11.9523,0,124.3661,68.5846,2.4104,0.0426,0,0,1555010,-524.4104,0,0,0,1.56E+08,0,0,50.1058,30.2015,574.7708,600.2145,624.0425,-6.4276,-0.0964,0.4808,-0.3827,-0.0698,624.8671,600.2145,573.9461,100.4567,75.8041,49.5357,-0.0881,0.4808,-0.391,599.6758,75.2655,50.921,0.5159,2.028,-82.6886,0.0017,-0.1217
1,92.2,92.2,605.0651,137436.2,522,0,-0.188,524.613,-0.2096,0,0,0.0528,0.0522,0.0518,0,0,0,2.6912,0,0,100,0,0,0,0,0,0,0,0,0,0,592.1004,-8155.059,0.2745,3.5669,0,0,0,0,0,0,0,0,0,0,4.5591,-0.1059,-0.0529,-0.0529,581.0979,56.4849,80.4522,-23.9672,0.9604,0.7021,7845.667,-0.1059,597.076,72.463,-11.9836,0,74.7523,68.4686,2.613,0.0463,0,0,1555010,-524.613,0,0,0,1.56E+08,0,0,50.1044,30.2017,575.023,600.1894,624.7386,17.3364,-0.1059,0.4889,-0.3812,0.099,630.1869,600.1894,569.5747,105.5739,75.5764,44.9617,-0.0891,0.4889,-0.398,599.9836,75.3707,60.6122,0.5051,2.3481,72.5536,0.0018,0.1792
1,95,95,604.9138,137548,524,0,-0.1876,526.2336,-0.205,0,0,0.0528,0.0522,0.0518,0,0,0,2.6874,0,0,100,0,0,0,0,0,0,0,0,0,0,592.3402,-8248.953,0.036,-0.0172,0,0,0,0,0,0,0,0,0,0,4.5585,-0.1035,-0.0517,-0.0517,581.0074,54.7738,78.6802,-23.9064,0.9605,0.6962,7845.854,-0.1035,596.945,70.7114,-11.9532,0,167.188,66.727,2.2336,0.0408,0,0,1555010,-526.2336,0,0,0,1.56E+08,0,0,50.1065,30.2046,574.7302,600.1849,623.9965,-0.0836,-0.1035,0.4929,-0.3874,0.013,623.9967,600.1849,574.7301,97.7631,73.9513,48.4965,-0.1032,0.4929,-0.3877,599.6373,73.4036,49.2666,0.5167,2.0159,-89.9028,0.002,0.0229
1,97.8,97.8,604.9545,137564.9,523,0,-0.1867,525.9432,-0.2289,0,0,0.0528,0.0522,0.0518,0,0,0,2.6609,0,0,100,0,0,0,0,0,0,0,0,0,0,591.9455,-8279,-0.3746,-3.5284,0,0,0,0,0,0,0,0,0,0,4.5591,-0.1156,-0.0578,-0.0578,581.1542,55.211,79.0114,-23.8004,0.9607,0.6988,7844.906,-0.1156,597.0211,71.0779,-11.9002,0,127.8935,67.1112,2.9432,0.0533,0,0,1555010,-525.9432,0,0,0,1.56E+08,0,0,50.104,30.2036,575.1946,600.0618,624.6989,-17.1508,-0.1156,0.5005,-0.383,-0.1352,630.0602,600.0618,569.8333,104.117,74.1187,43.8901,-0.0849,0.5005,-0.4137,599.9851,74.0419,60.2269,0.5019,2.3722,-72.6409,0.0019,-0.2513
1,100.6,100.6,604.7723,137665.8,525,0,-0.1884,527.3249,-0.2217,0,0,0.0528,0.0522,0.0518,0,0,0,2.6435,0,0,100,0,0,0,0,0,0,0,0,0,0,592.3026,-8422.346,0.0134,1.3275,0,0,0,0,0,0,0,0,0,0,4.5562,-0.112,-0.056,-0.056,580.7636,53.4387,77.4474,-24.0087,0.9603,0.69,7845.188,-0.112,596.7693,69.4444,-12.0044,0,-14854.63,65.4431,2.3249,0.0435,0,0,1555010,-527.3249,0,0,0,1.56E+08,0,0,50.1071,30.2079,574.3689,600.0822,623.7019,6.4519,-0.112,0.5065,-0.3922,0.0048,624.5317,600.0822,573.5391,97.2068,72.7573,46.2142,-0.112,0.5065,-0.3922,599.3843,72.0594,50.9926,0.5205,2.1034,82.6709,0.0023,0.0086
1,103.4,103.4,604.8576,137688.4,525,0,-0.1875,527.0752,-0.2487,0,0,0.0528,0.0522,0.0518,0,0,0,2.6097,0,0,100,0,0,0,0,0,0,0,0,0,0,592.0839,-8421.72,0.2769,3.0255,0,0,0,0,0,0,0,0,0,0,4.5571,-0.1256,-0.0627,-0.0627,580.9572,53.882,77.7824,-23.9004,0.9605,0.6927,7844.123,-0.1255,596.8908,69.8156,-11.9502,0,289.558,65.8322,2.0752,0.0385,0,0,1555010,-527.0752,0,0,0,1.56E+08,0,0,50.1037,30.2058,574.802,600.0532,624.2486,14.7075,-0.1256,0.5131,-0.3854,0.0999,628.2925,600.0532,570.7581,101.2173,72.978,43.6829,-0.1076,0.5131,-0.4034,599.7012,72.6261,57.5344,0.5092,2.3171,74.6261,0.0021,0.1916
1,106.2,106.2,605.1894,137828.7,526,0,-0.1861,528.274,-0.2433,0,0,0.0528,0.0522,0.0518,0,0,0,2.5997,0,0,100,0,0,0,0,0,0,0,0,0,0,592.171,-8574.455,-0.2128,-2.4588,0,0,0,0,0,0,0,0,0,0,4.5612,-0.1229,-0.0614,-0.0614,581.4643,53.1903,76.9154,-23.7251,0.9608,0.6915,7844.334,-0.1229,597.281,69.007,-11.8626,0,61.2054,65.0529,2.274,0.0428,0,0,1555010,-528.274,0,0,0,1.56E+08,0,0,50.1069,30.2103,575.5555,600.2927,624.9561,-11.9512,-0.1229,0.5197,-0.3949,-0.0768,627.6955,600.2927,572.8161,99.4215,72.0187,44.5421,-0.1125,0.5197,-0.4053,600.2681,71.9941,54.8794,0.5007,2.2321,-77.09,0.0019,-0.1409
1,109,109,605.0249,137876.1,526,0,-0.1878,528.6784,-0.2615,0,0,0.0528,0.0522,0.0518,0,0,0,2.5892,0,0,100,0,0,0,0,0,0,0,0,0,0,592.0854,-8601.371,-0.3015,-2.104,0,0,0,0,0,0,0,0,0,0,4.5578,-0.1321,-0.066,-0.066,581.0842,52.4058,76.3465,-23.9407,0.9604,0.6864,7843.614,-0.1321,597.0447,68.3663,-11.9704,0,102.9307,64.3761,2.6784,0.0511,0,0,1555010,-528.6784,0,0,0,1.56E+08,0,0,50.105,30.2096,575.0042,600.1578,624.6725,-10.228,-0.1321,0.5258,-0.3917,-0.1088,626.6963,600.1578,572.9805,98.0179,71.4794,44.3021,-0.111,0.5258,-0.4128,599.9448,71.2665,53.7158,0.5059,2.2125,-78.8078,0.002,-0.2087
1,111.8,111.8,605.0199,137973.3,527,0,-0.1876,529.1271,-0.2741,0,0,0.0528,0.0522,0.0518,0,0,0,2.5708,0,0,100,0,0,0,0,0,0,0,0,0,0,592.093,-8728.441,0.2514,3.2285,0,0,0,0,0,0,0,0,0,0,4.5576,-0.1384,-0.0691,-0.0691,581.0953,51.9682,75.8928,-23.9246,0.9605,0.6848,7843.12,-0.1383,597.045,67.9179,-11.9623,0,106.8491,63.9305,2.1271,0.0409,0,0,1555010,-529.1271,0,0,0,1.56E+08,0,0,50.1055,30.2121,575.0312,600.1573,624.652,15.6949,-0.1384,0.5359,-0.3954,0.0907,629.1995,600.1573,570.4836,100.0724,71.0302,41.3565,-0.1233,0.5359,-0.4105,599.9468,70.8197,58.7159,0.5054,2.4198,73.8414,0.0021,0.176
1,114.6,114.6,604.6082,138024.9,528,0,-0.187,530.3371,-0.28,0,0,0.0528,0.0522,0.0518,0,0,0,2.5453,0,0,100,0,0,0,0,0,0,0,0,0,0,592.4047,-8801.054,0.135,0.8907,0,0,0,0,0,0,0,0,0,0,4.5549,-0.1414,-0.0706,-0.0706,580.7684,50.4313,74.2711,-23.8398,0.9606,0.679,7842.885,-0.1413,596.6616,66.3245,-11.9199,0,-165.9031,62.3512,2.3371,0.0463,0,0,1555010,-530.3371,0,0,0,1.56E+08,0,0,50.1058,30.2135,574.3254,600.0177,623.1436,4.3301,-0.1414,0.5414,-0.3975,0.0487,623.5247,600.0177,573.9443,93.1876,69.6806,43.6072,-0.1369,0.5414,-0.402,599.1623,68.8251,49.5804,0.5259,2.137,84.9703,0.0025,0.095
1,117.4,117.4,605.0906,138082,528,0,-0.1876,530.1513,-0.3062,0,0,0.0528,0.0522,0.0518,0,0,0,2.523,0,0,100,0,0,0,0,0,0,0,0,0,0,591.8744,-8868.67,-0.4309,-3.5818,0,0,0,0,0,0,0,0,0,0,4.5574,-0.1547,-0.0773,-0.0773,581.1644,51.0131,74.9393,-23.9262,0.9605,0.6807,7841.844,-0.1547,597.1152,66.9639,-11.9631,0,86.2342,62.9762,2.1513,0.0422,0,0,1555010,-530.1513,0,0,0,1.56E+08,0,0,50.1036,30.2133,575.2628,600.119,625.166,-17.4156,-0.1547,0.5515,-0.3946,-0.1554,630.6428,600.119,569.7861,100.4915,69.9677,39.6348,-0.112,0.5515,-0.4373,600.1826,70.0313,60.8567,0.4984,2.5354,-72.543,0.0022,-0.3213
1,120.2,120.2,604.9737,138223.8,529,0,-0.1852,532.261,-0.2996,0,0,0.0528,0.0522,0.0518,0,0,0,2.5173,0,0,100,0,0,0,0,0,0,0,0,0,0,592.2996,-9002.614,-0.1065,0.4901,0,0,0,0,0,0,0,0,0,0,4.5591,-0.1513,-0.0756,-0.0756,581.3614,49.1004,72.7127,-23.6123,0.961,0.6753,7842.11,-0.1513,597.103,64.842,-11.8062,0,147.2496,60.9066,3.261,0.0664,0,0,1555010,-532.261,0,0,0,1.56E+08,0,0,50.1066,30.2174,575.3173,600.2057,624.2292,2.3827,-0.1513,0.5571,-0.4034,-0.0384,624.345,600.2057,575.2015,92.084,67.9447,42.9405,-0.1484,0.5571,-0.4063,599.9174,67.6564,49.1435,0.5088,2.1445,87.2177,0.0024,-0.0761
1,123,123,604.9893,138245.9,529,0,-0.1885,531.5302,-0.3406,0,0,0.0528,0.0522,0.0518,0,0,0,2.4692,0,0,100,0,0,0,0,0,0,0,0,0,0,592.0689,-9035.139,0.3699,3.5044,0,0,0,0,0,0,0,0,0,0,4.5549,-0.172,-0.0859,-0.0859,580.9459,49.4157,73.4591,-24.0434,0.9603,0.6727,7840.489,-0.1719,596.9749,65.4447,-12.0217,0,133.1751,61.4374,2.5302,0.0512,0,0,1555010,-531.5302,0,0,0,1.56E+08,0,0,50.1019,30.2151,574.8088,600.1286,624.6201,17.0423,-0.172,0.5692,-0.3947,0.1334,629.8928,600.1286,569.5361,98.3626,68.5984,38.0059,-0.1374,0.5692,-0.4293,599.8525,68.3223,60.3567,0.5069,2.5881,72.8086,0.0025,0.2977
1,125.8,125.8,604.887,138432,531,0,-0.1875,533.472,-0.329,0,0,0.0528,0.0522,0.0518,0,0,0,2.4589,0,0,100,0,0,0,0,0,0,0,0,0,0,592.1787,-9224.205,-0.1419,-1.7353,0,0,0,0,0,0,0,0,0,0,4.5554,-0.1662,-0.083,-0.083,580.976,47.504,71.415,-23.911,0.9605,0.6652,7840.943,-0.1661,596.9167,63.4447,-11.9555,0,270.7982,59.4595,2.472,0.052,0,0,1555010,-533.472,0,0,0,1.56E+08,0,0,50.1064,30.221,574.7892,600.1059,624.2006,-8.4374,-0.1662,0.5763,-0.4076,-0.0512,625.6016,600.1059,573.3881,92.1296,66.6339,39.9161,-0.1609,0.5763,-0.4129,599.6985,66.2265,52.2135,0.5117,2.3081,-80.5721,0.0025,-0.106
1,128.6,128.6,604.8618,138438.8,531,0,-0.1885,533.149,-0.3654,0,0,0.0528,0.0522,0.0518,0,0,0,2.4209,0,0,100,0,0,0,0,0,0,0,0,0,0,592.0561,-9247.992,-0.4397,-2.7522,0,0,0,0,0,0,0,0,0,0,4.5533,-0.1846,-0.0922,-0.0922,580.8148,47.6658,71.7128,-24.047,0.9602,0.6647,7839.503,-0.1845,596.8461,63.6971,-12.0235,0,344.7896,59.6893,2.149,0.0451,0,0,1555010,-533.149,0,0,0,1.56E+08,0,0,50.1022,30.2189,574.6139,600.044,624.3241,-13.3854,-0.1846,0.5869,-0.3998,-0.1586,627.6992,600.044,571.2388,94.5502,66.895,38.0898,-0.1368,0.5869,-0.4476,599.6606,66.5117,56.4604,0.5102,2.4823,-75.8479,0.0025,-0.3655
1,131.4,131.4,605.0303,138610.1,532,0,-0.1843,534.6008,-0.3706,0,0,0.0528,0.0522,0.0518,0,0,0,2.4227,0,0,100,0,0,0,0,0,0,0,0,0,0,591.83,-9445.797,0.1982,2.7524,0,0,0,0,0,0,0,0,0,0,4.5587,-0.1872,-0.0935,-0.0935,581.5188,46.918,70.4294,-23.5115,0.9611,0.6662,7839.3,-0.1871,597.1931,62.5923,-11.7558,0,123.8771,58.6737,2.6008,0.0554,0,0,1555010,-534.6008,0,0,0,1.56E+08,0,0,50.1048,30.2238,575.8468,600.0637,625.0978,13.3855,-0.1872,0.5986,-0.4091,0.0715,628.5006,600.0637,572.444,93.8998,65.4629,37.8431,-0.1762,0.5986,-0.4201,600.3361,65.7353,56.0567,0.4927,2.4813,75.7366,0.0023,0.1608
1,134.2,134.2,604.9627,138623.8,532,0,-0.1877,535.098,-0.3975,0,0,0.0528,0.0522,0.0518,0,0,0,2.3516,0,0,100,0,0,0,0,0,0,0,0,0,0,592.5431,-9495.874,0.2735,1.7244,0,0,0,0,0,0,0,0,0,0,4.5541,-0.2008,-0.1002,-0.1002,581.0108,45.9128,69.8647,-23.9519,0.9604,0.6572,7838.236,-0.2007,596.9788,61.8808,-11.976,0,170.8471,57.8888,3.098,0.0675,0,0,1555010,-535.098,0,0,0,1.56E+08,0,0,50.1021,30.223,574.6505,600.2897,623.8447,8.3877,-0.2008,0.6082,-0.4047,0.0986,625.2355,600.2897,573.2597,90.1375,65.1917,38.1617,-0.1792,0.6082,-0.4263,599.595,64.497,51.9758,0.52,2.362,80.5852,0.0027,0.241
1,137,137,604.9795,138754.3,533,0,-0.1871,535.1895,-0.4254,0,0,0.0528,0.0522,0.0518,0,0,0,2.3323,0,0,100,0,0,0,0,0,0,0,0,0,0,591.9539,-9646.862,-0.4841,-3.4126,0,0,0,0,0,0,0,0,0,0,4.5542,-0.2149,-0.1073,-0.1073,581.1054,45.9159,69.79,-23.8741,0.9605,0.6579,7837.133,-0.2148,597.0215,61.832,-11.9371,0,157.3423,57.853,2.1895,0.0477,0,0,1555010,-535.1895,0,0,0,1.56E+08,0,0,50.101,30.2249,575.1302,600.0783,624.787,-16.6016,-0.2149,0.6233,-0.4057,-0.1745,629.826,600.0783,570.0912,94.6365,64.8888,34.9017,-0.1543,0.6233,-0.4663,599.9985,64.809,59.7348,0.502,2.7115,-73.1156,0.0027,-0.4527
1,139.8,139.8,604.9211,138895.2,534,0,-0.1872,537.3986,-0.4319,0,0,0.0528,0.0522,0.0518,0,0,0,2.315,0,0,100,0,0,0,0,0,0,0,0,0,0,592.1974,-9771.191,-0.2948,-0.4438,0,0,0,0,0,0,0,0,0,0,4.5535,-0.2181,-0.1089,-0.1089,581.0346,43.636,67.5225,-23.8865,0.9605,0.6462,7836.883,-0.218,596.9589,59.5603,-11.9433,0,234.8084,55.5793,3.3986,0.0779,0,0,1555010,-537.3986,0,0,0,1.56E+08,0,0,50.1022,30.2277,574.8796,600.1332,624.2729,-2.159,-0.2181,0.6315,-0.4107,-0.1063,624.3671,600.1332,574.7854,86.9685,62.7346,37.3868,-0.1922,0.6315,-0.4366,599.7619,62.3633,49.5817,0.5112,2.3262,-87.5019,0.0027,-0.2749
1,142.6,142.6,604.9028,139000.5,534,0,-0.186,536.7234,-0.4929,0,0,0.0528,0.0522,0.0518,0,0,0,2.23,0,0,100,0,0,0,0,0,0,0,0,0,0,592.0795,-9890.857,0.488,3.5514,0,0,0,0,0,0,0,0,0,0,4.5531,-0.249,-0.1243,-0.1243,581.1627,44.4393,68.1794,-23.7401,0.9608,0.6518,7834.467,-0.2489,596.9894,60.266,-11.8701,0,262.937,56.3094,2.7234,0.0613,0,0,1555010,-536.7234,0,0,0,1.56E+08,0,0,50.0964,30.2262,575.1476,600.0773,624.4092,17.2835,-0.249,0.6532,-0.4016,0.1759,629.8682,600.0773,569.6886,93.1448,63.3539,32.9652,-0.1794,0.6532,-0.4712,599.8781,63.1546,60.1796,0.505,2.8255,72.4713,0.0026,0.5705
1,145.4,145.4,604.6495,139166.7,537,0,-0.1867,539.8839,-0.481,0,0,0.0528,0.0522,0.0518,0,0,0,2.2349,0,0,100,0,0,0,0,0,0,0,0,0,0,592.3183,-10104.91,-0.0056,-0.9392,0,0,0,0,0,0,0,0,0,0,4.5507,-0.2429,-0.1212,-0.1212,580.821,40.9371,64.7656,-23.8285,0.9606,0.6321,7834.944,-0.2427,596.7066,56.8227,-11.9143,0,-297.6175,52.8514,2.8839,0.0704,0,0,1555010,-539.8839,0,0,0,1.56E+08,0,0,50.1013,30.2328,574.4778,600.0088,623.4132,-4.5699,-0.2429,0.6619,-0.4159,-0.002,623.8363,600.0088,574.0547,83.9524,60.1249,34.1708,-0.2429,0.6619,-0.4159,599.2999,59.416,49.7816,0.5214,2.4568,-84.7103,0.0031,-0.0058
1,148.2,148.2,604.8956,139255,536,0,-0.187,538.4899,-0.5583,0,0,0.0528,0.0522,0.0518,0,0,0,2.1438,0,0,100,0,0,0,0,0,0,0,0,0,0,592.1312,-10158.77,-0.6806,-3.251,0,0,0,0,0,0,0,0,0,0,4.5505,-0.282,-0.1407,-0.1407,581.022,42.532,66.4057,-23.8737,0.9605,0.6405,7831.889,-0.2818,596.9377,58.4478,-11.9369,0,292.8801,54.4689,2.4899,0.0585,0,0,1555010,-538.4899,0,0,0,1.56E+08,0,0,50.0925,30.2284,574.8986,600.0918,624.32,-15.8273,-0.282,0.6842,-0.3995,-0.2452,628.9542,600.0918,570.2645,90.4643,61.6019,31.7746,-0.1577,0.6842,-0.5238,599.7702,61.2803,58.6897,0.5082,2.8471,-73.6801,0.0027,-1.0232
1,151,151,604.8486,139503.3,539,0,-0.1864,541.4835,-0.5562,0,0,0.0528,0.0522,0.0518,0,0,0,2.1279,0,0,100,0,0,0,0,0,0,0,0,0,0,592.1312,-10468.62,0.0817,2.098,0,0,0,0,0,0,0,0,0,0,4.5508,-0.2809,-0.1402,-0.1402,581.0539,39.5704,63.3651,-23.7947,0.9607,0.6245,7831.975,-0.2807,596.917,55.4335,-11.8974,0,517.6206,51.4678,2.4835,0.0628,0,0,1555010,-541.4835,0,0,0,1.56E+08,0,0,50.0977,30.2368,574.9485,600.062,624.2098,10.2123,-0.2809,0.7004,-0.4164,0.0294,626.2429,600.062,572.9153,84.7594,58.5785,31.4318,-0.2778,0.7004,-0.4195,599.7401,58.2566,53.3276,0.5091,2.6966,78.7401,0.0031,0.1085
1,153.8,153.8,604.735,139534.2,538,0,-0.1877,540.6649,-0.6387,0,0,0.0528,0.0522,0.0518,0,0,0,1.9685,0,0,100,0,0,0,0,0,0,0,0,0,0,592.0044,-10524.7,0.5344,2.4521,0,0,0,0,0,0,0,0,0,0,4.5466,-0.3226,-0.1609,-0.1609,580.7591,40.0942,64.0701,-23.9759,0.9604,0.6258,7828.72,-0.3223,596.743,56.0781,-11.988,0,-971.2194,52.0822,2.6649,0.0665,0,0,1555010,-540.6649,0,0,0,1.56E+08,0,0,50.0882,30.232,574.5684,599.9433,624.1179,11.943,-0.3226,0.7242,-0.3987,0.1924,626.8463,599.9433,571.84,86.1814,59.2784,31.1751,-0.2194,0.7242,-0.5019,599.5432,58.8783,55.0063,0.5109,2.7644,77.1315,0.0029,1.2489
1,156.6,156.6,605.1353,139814.6,540,0,-0.1861,542.3437,-0.6766,0,0,0.0528,0.0522,0.0518,0,0,0,1.9298,0,0,100,0,0,0,0,0,0,0,0,0,0,592.0169,-10855.46,-0.5584,-3.0241,0,0,0,0,0,0,0,0,0,0,4.5504,-0.3417,-0.1704,-0.1704,581.3551,39.0114,62.7916,-23.7802,0.9607,0.6213,7827.229,-0.3414,597.2086,54.8649,-11.8901,0,109.2962,50.9015,2.3437,0.0601,0,0,1555010,-542.3437,0,0,0,1.56E+08,0,0,50.0887,30.2378,575.5076,600.1971,625.1179,-14.7308,-0.3417,0.7511,-0.4065,-0.201,629.1622,600.1971,571.4633,86.8185,57.8534,29.1196,-0.2283,0.7511,-0.5199,600.2742,57.9305,57.6989,0.498,2.9814,-74.6478,0.0029,-1.5305
1,159.4,159.4,604.8692,139912.8,542,0,-0.1878,544.0316,-0.7406,0,0,0.0528,0.0522,0.0518,0,0,0,1.8075,0,0,100,0,0,0,0,0,0,0,0,0,0,592.5468,-10967.47,-0.7119,-1.3326,0,0,0,0,0,0,0,0,0,0,4.5451,-0.3741,-0.1865,-0.1865,580.8656,36.834,60.8376,-24.0036,0.9603,0.6054,7824.703,-0.3737,596.868,52.8364,-12.0018,0,432.2857,48.8358,2.0316,0.0552,0,0,1555010,-544.0316,0,0,0,1.56E+08,0,0,50.0824,30.2359,574.4349,600.2305,623.6422,-6.4941,-0.3741,0.7734,-0.3963,-0.2562,624.4849,600.2305,573.5923,80.4533,56.1989,29.5607,-0.2037,0.7734,-0.5667,599.4359,55.4043,50.8926,0.5234,2.7216,-82.607,0.003,-5.6488
1,162.2,162.2,605.0535,140222.9,541,0,-0.1856,543.6763,-0.8664,0,0,0.0528,0.0522,0.0518,0,0,0,1.6134,0,0,100,0,0,0,0,0,0,0,0,0,0,592.0285,-11341.84,0.7453,3.5085,0,0,0,0,0,0,0,0,0,0,4.5458,-0.4376,-0.2181,-0.2181,581.3225,37.6462,61.3773,-23.731,0.9608,0.6134,7819.756,-0.4371,597.1432,53.4669,-11.8655,0,146.0327,49.5118,2.6763,0.0711,0,0,1555010,-543.6763,0,0,0,1.56E+08,0,0,50.0726,30.2363,575.4431,600.1496,624.9074,17.1108,-0.4376,0.8252,-0.3846,0.268,630.2495,600.1496,570.1011,86.5732,56.4733,26.4248,-0.2198,0.8252,-0.6024,600.1667,56.4904,60.1484,0.4996,3.2762,72.6614,0.003,87.5297
1,165,165,604.8267,140491.6,545,0,-0.1869,547.9111,-0.8942,0,0,0.0528,0.0522,0.0518,0,0,0,1.5473,0,0,100,0,0,0,0,0,0,0,0,0,0,592.712,-11647.71,0.3861,0.012,0,0,0,0,0,0,0,0,0,0,4.542,-0.4516,-0.225,-0.225,580.9175,33.0064,56.9157,-23.9092,0.9605,0.5799,7818.666,-0.4511,596.857,48.9459,-11.9546,0,853.5942,44.9611,2.9111,0.0882,0,0,1555010,-547.9111,0,0,0,1.56E+08,0,0,50.074,30.2423,574.4326,600.265,623.3011,0.0585,-0.4516,0.8486,-0.3938,0.1388,623.3011,600.265,574.4325,75.39,52.3539,26.5214,-0.3204,0.8486,-0.525,599.3329,51.4218,48.8686,0.5286,2.8426,89.9314,0.0032,88.8069
1,167.8,167.8,604.89,140732.2,543,0,-0.1873,544.9342,-1.1316,0,0,0.0528,0.0522,0.0518,0,0,0,1.1737,0,0,100,0,0,0,0,0,0,0,0,0,0,592.2351,-11961.22,-1.6403,-3.4433,0,0,0,0,0,0,0,0,0,0,4.5365,-0.5715,-0.2845,-0.2845,580.9066,35.9724,59.9558,-23.9834,0.9604,0.6,7809.345,-0.5707,596.8956,51.9614,-11.9917,0,362.5583,47.9641,1.9342,0.0538,0,0,1555010,-544.9342,0,0,0,1.56E+08,0,0,50.0491,30.2325,574.6854,600.1244,624.1966,-16.8214,-0.5715,0.9255,-0.3508,-0.5888,629.3709,600.1244,569.5112,84.4367,55.1902,24.577,-0.0304,0.9255,-0.8919,599.6689,54.7346,59.8597,0.5114,3.4356,-72.902,0.0032,91.2056
1,170.6,170.6,604.6503,141211.9,548,0,-0.1834,551.5408,-1.1622,0,0,0.0528,0.0522,0.0518,0,0,0,1.1223,0,0,100,0,0,0,0,0,0,0,0,0,0,593.1412,-12522.25,-0.5651,1.2882,0,0,0,0,0,0,0,0,0,0,4.5378,-0.587,-0.2922,-0.2922,581.1626,29.6218,53.1096,-23.4877,0.9612,0.5577,7808.141,-0.5861,596.8211,45.2803,-11.7439,0,-393.9891,41.3657,3.5408,0.1195,0,0,1555010,-551.5408,0,0,0,1.56E+08,0,0,50.0542,30.245,574.5686,600.3154,622.2227,6.2929,-0.587,0.9632,-0.3726,-0.2029,623.0397,600.3154,573.7516,71.4989,48.7747,22.2108,-0.3007,0.9632,-0.6589,599.0356,47.4948,49.2881,0.539,3.2191,82.6028,0.0036,90.4668
1,173.4,173.4,604.7571,141510.9,545,0,-0.1874,547.8287,-1.5069,0,0,0.0528,0.0522,0.0518,0,0,0,0.5404,0,0,100,0,0,0,0,0,0,0,0,0,0,592.1688,-12906.71,1.5031,3.0371,0,0,0,0,0,0,0,0,0,0,4.5265,-0.7611,-0.3784,-0.3784,580.7189,32.8902,56.9284,-24.0382,0.9603,0.5777,7794.65,-0.7597,596.7443,48.9157,-12.0191,0,-2670.323,44.9093,2.8287,0.086,0,0,1555010,-547.8287,0,0,0,1.56E+08,0,0,50.0171,30.229,574.4355,600.015,623.9873,14.8721,-0.7611,1.0708,-0.3067,0.5383,628.1082,600.015,570.3146,80.2795,52.1863,22.4859,-0.0906,1.0708,-0.9772,599.4793,51.6506,57.7936,0.5139,3.5702,74.5126,0.003,89.4566
1,176.2,176.2,604.9518,142195.8,549,0,-0.1822,552.295,-1.6952,0,0,0.0528,0.0522,0.0518,0,0,0,0.2401,0,0,100,0,0,0,0,0,0,0,0,0,0,592.6556,-13707.81,-0.9601,-2.4397,0,0,0,0,0,0,0,0,0,0,4.5287,-0.8562,-0.4254,-0.4254,581.5494,29.2544,52.6568,-23.4024,0.9613,0.5556,7787.3,-0.8544,597.1509,44.8559,-11.7012,0,278.0319,40.9556,3.295,0.1126,0,0,1555010,-552.295,0,0,0,1.56E+08,0,0,50.0063,30.2359,575.4799,600.3185,623.7571,-11.959,-0.8562,1.1613,-0.3018,-0.3435,626.5571,600.3185,572.6799,74.2622,48.0235,20.3849,-0.2104,1.1613,-0.9476,599.8518,47.5569,53.8773,0.513,3.643,-76.8224,0.0033,90.2984
1,179,179,604.7844,142510.3,547,0,-0.1873,550.6353,-2.0566,0,0,0.0528,0.0522,0.0518,0,0,0,-0.4104,0,0,100,0,0,0,0,0,0,0,0,0,0,592.6182,-14145.52,-2.6541,-2.1251,0,0,0,0,0,0,0,0,0,0,4.5138,-1.0387,-0.5153,-0.5153,580.6849,30.0496,54.1491,-24.0996,0.9602,0.5549,7773.234,-1.036,596.7512,46.1159,-12.0498,0,4552.285,42.0994,3.6353,0.121,0,0,1555010,-550.6353,0,0,0,1.56E+08,0,0,49.968,30.2201,574.1515,600.1995,623.4023,-10.443,-1.0387,1.2766,-0.2346,-0.9472,625.5251,600.1995,572.0286,74.8898,49.5642,21.3933,0.1445,1.2766,-1.4178,599.251,48.6158,53.4965,0.5266,3.5006,-78.5097,0.0033,90.4715
1,181.8,181.8,604.5483,143402.8,550,0,-0.1775,552.4654,-2.6282,0,0,0.0528,0.0522,0.0518,0,0,0,-1.3289,0,0,100,0,0,0,0,0,0,0,0,0,0,592.9114,-15244.55,1.8177,3.2153,0,0,0,0,0,0,0,0,0,0,4.5084,-1.3274,-0.6572,-0.6572,581.6475,29.1821,52.0829,-22.9008,0.9621,0.5603,7751.087,-1.3231,596.9147,44.4493,-11.4504,0,-219.9018,40.6325,2.4654,0.0845,0,0,1555010,-552.4654,0,0,0,1.56E+08,0,0,49.9143,30.2059,575.4911,600.1611,622.3835,15.8597,-1.3274,1.4796,-0.15,0.6463,627.2437,600.1611,570.6308,74.7783,47.6957,18.1654,0.0066,1.4796,-1.484,599.3452,46.8798,56.6129,0.5216,4.1165,72.9622,0.0022,89.7563
1,184.6,184.6,604.6025,144002.9,554,0,-0.1855,556.3016,-2.9343,0,0,0.0528,0.0522,0.0518,0,0,0,-1.8175,0,0,100,0,0,0,0,0,0,0,0,0,0,592.9841,-15938.73,2.3638,0.9289,0,0,0,0,0,0,0,0,0,0,4.4937,-1.482,-0.7329,-0.7329,580.6355,24.3339,48.3009,-23.967,0.9604,0.5038,7739.279,-1.4766,596.6135,40.312,-11.9835,0,-311.7939,36.3174,2.3016,0.0946,0,0,1555010,-556.3016,0,0,0,1.56E+08,0,0,49.8873,30.2011,573.873,600.2213,622.4265,4.5908,-1.482,1.594,-0.1104,0.8388,622.8568,600.2213,573.4427,66.5552,43.9197,17.1411,0.1105,1.594,-1.7029,598.8403,42.5387,49.4141,0.5419,3.8828,84.6458,0.0016,89.7456
1,187.4,187.4,604.8528,144986.8,549,0,-0.1827,551.3117,-3.9849,0,0,0.0528,0.0522,0.0518,0,0,0,-3.5327,0,0,100,0,0,0,0,0,0,0,0,0,0,592.5717,-17190.78,-4.5477,-3.5682,0,0,0,0,0,0,0,0,0,0,4.4741,-2.0127,-0.9914,-0.9914,581.1261,29.8144,53.5411,-23.7267,0.9608,0.5569,7699.017,-2.0027,596.9439,45.6322,-11.8634,0,614.6091,41.6778,2.3117,0.0775,0,0,1555010,-551.3117,0,0,0,1.56E+08,0,0,49.7772,30.1552,574.8945,600.2196,623.7264,-17.7625,-2.0127,1.9264,0.0846,-1.6021,629.5039,600.2196,569.1169,78.1922,48.9079,17.8052,0.5797,1.9264,-2.5078,599.6135,48.3018,60.387,0.5151,4.3915,-71.9821,-0.0017,90.2415
1,190.2,190.2,604.5674,145852.5,559,0,-0.1763,561.9933,-4.2806,0,0,0.0528,0.0522,0.0518,0,0,0,-4.0126,0,0,100,0,0,0,0,0,0,0,0,0,0,593.8204,-18210.75,-3.0886,0.2796,0,0,0,0,0,0,0,0,0,0,4.4715,-2.162,-1.0638,-1.0638,581.6384,19.6451,42.5741,-22.929,0.9621,0.4614,7687.766,-2.1505,596.9244,34.9311,-11.4645,0,-286.3717,31.1096,2.9933,0.1524,0,0,1555010,-561.9933,0,0,0,1.56E+08,0,0,49.7569,30.1598,574.9771,600.5115,621.1069,1.3942,-2.162,2.0559,0.1042,-1.0863,621.149,600.5115,574.935,59.1557,38.5182,12.9417,0.34,2.0559,-2.3978,598.8652,36.8719,46.214,0.5534,4.5709,88.2704,-0.0019,90.1824
1,193,193,604.5546,146891,550,0,-0.1853,552.6631,-5.6354,0,0,0.0528,0.0522,0.0518,0,0,0,-6.2113,0,0,100,0,0,0,0,0,0,0,0,0,0,592.6234,-19568.79,4.8048,3.3951,0,0,0,0,0,0,0,0,0,0,4.4315,-2.8463,-1.3935,-1.3935,580.2964,27.6333,51.8915,-24.2582,0.9599,0.5325,7636.614,-2.8265,596.4686,43.8055,-12.1291,0,-227.1684,39.7624,2.6631,0.0964,0,0,1555010,-552.6631,0,0,0,1.56E+08,0,0,49.6125,30.0945,573.587,600.0498,622.9512,17.0887,-2.8463,2.4695,0.3676,1.6741,628.2896,600.0498,568.2485,75.6265,47.3867,15.5854,0.7565,2.4695,-3.2352,598.8626,46.1995,60.0411,0.5297,4.8524,72.6516,-0.0092,89.8394
1,195.8,195.8,604.7253,148127.3,559,0,-0.1649,562.3828,-6.4167,0,0,0.0528,0.0522,0.0518,0,0,0,-7.4716,0,0,100,0,0,0,0,0,0,0,0,0,0,593.9392,-21034.08,-0.8591,-1.6225,0,0,0,0,0,0,0,0,0,0,4.4355,-3.2409,-1.5821,-1.5821,583.0488,20.666,42.3425,-21.6765,0.9642,0.4881,7607.426,-3.2153,597.4998,35.117,-10.8383,0,-1223.92,31.5043,3.3828,0.1637,0,0,1555010,-562.3828,0,0,0,1.56E+08,0,0,49.5406,30.0749,577.1513,600.6508,621.39,-8.2079,-3.2409,2.7448,0.4829,-0.2978,622.8638,600.6508,575.6775,60.481,38.268,13.2947,0.4948,2.7448,-3.2528,599.7307,37.3479,47.1863,0.5292,4.5493,-79.8207,-0.0132,90.0389
1,198.6,198.6,604.8474,148997.4,552,0,-0.1892,554.5504,-7.4213,0,0,0.0528,0.0522,0.0518,0,0,0,-9.0831,0,0,100,0,0,0,0,0,0,0,0,0,0,592.6512,-22134.43,-7.0414,-2.7444,0,0,0,0,0,0,0,0,0,0,4.3896,-3.7483,-1.8231,-1.8231,579.851,25.3006,50.297,-24.9964,0.9587,0.503,7570.22,-3.7143,596.5153,41.9649,-12.4982,0,703.603,37.7988,2.5504,0.1008,0,0,1555010,-554.5504,0,0,0,1.56E+08,0,0,49.4366,30.0297,572.928,600.2385,623.7195,-13.9784,-3.7483,3.0561,0.6716,-2.4245,627.3124,600.2385,569.3351,72.762,45.6881,14.7847,1.2586,3.0561,-4.3353,598.962,44.4116,57.9773,0.533,4.9214,-75.5853,-0.0206,90.1334
1,201.4,201.4,604.5939,150480.2,558,0,-0.1695,559.4038,-8.8509,0,0,0.0528,0.0522,0.0518,0,0,0,-11.3255,0,0,100,0,0,0,0,0,0,0,0,0,0,593.6136,-23955.15,3.4258,2.7667,0,0,0,0,0,0,0,0,0,0,4.3758,-4.4704,-2.1629,-2.1629,582.0512,22.6474,45.1901,-22.5427,0.9627,0.5012,7517.895,-4.4222,597.0797,37.6759,-11.2714,0,-314.1207,33.9188,1.4038,0.062,0,0,1555010,-559.4038,0,0,0,1.56E+08,0,0,49.2939,29.9725,575.8062,600.442,621.6271,14.2268,-4.4704,3.5122,0.9255,1.1684,625.685,600.442,571.7484,66.2812,41.0382,12.3446,1.0492,3.5122,-4.5941,599.2918,39.888,53.9366,0.532,5.3692,74.0804,-0.0327,89.92
1,204.2,204.2,604.3661,151364.1,557,0,-0.1853,558.9642,-9.4894,0,0,0.0528,0.0522,0.0518,0,0,0,-12.3682,0,0,100,0,0,0,0,0,0,0,0,0,0,593.4426,-25095.13,6.3178,1.7626,0,0,0,0,0,0,0,0,0,0,4.3443,-4.7929,-2.3136,-2.3136,579.645,20.6809,45.4019,-24.7211,0.9591,0.4555,7494.759,-4.7377,596.1257,37.1615,-12.3606,0,-137.6015,33.0414,1.9642,0.095,0,0,1555010,-558.9642,0,0,0,1.56E+08,0,0,49.2357,29.9556,572.1548,600.2341,621.338,9.1007,-4.7929,3.7339,1.0212,2.1459,622.968,600.2341,570.5248,64.0039,41.2699,11.5606,1.3934,3.7339,-5.1651,597.909,38.9448,52.4433,0.5665,5.5364,79.8459,-0.0378,89.9024
1,207,207,604.6765,152904.9,554,0,-0.1779,555.1152,-11.306,0,0,0.0528,0.0522,0.0518,0,0,0,-15.3196,0,0,100,0,0,0,0,0,0,0,0,0,0,592.8127,-27039,-8.1032,-3.4148,0,0,0,0,0,0,0,0,0,0,4.3147,-5.7104,-2.7385,-2.7385,580.7361,25.6209,49.5613,-23.9404,0.9604,0.517,7429.709,-5.6326,596.6964,41.5812,-11.9702,0,-536.5858,37.5911,1.1152,0.0435,0,0,1555010,-555.1152,0,0,0,1.56E+08,0,0,49.0517,29.8748,574.2591,600.1859,623.1587,-17.8467,-5.7104,4.2921,1.3601,-2.7191,628.9792,600.1859,568.4385,73.864,45.0707,13.3233,1.8491,4.2921,-6.1994,599.2012,44.086,60.5407,0.5244,5.544,-71.9365,-0.0582,90.0862
1,209.8,209.8,604.5989,153894.3,562,0,-0.1762,564.804,-11.6757,0,0,0.0528,0.0522,0.0518,0,0,0,-15.9307,0,0,100,0,0,0,0,0,0,0,0,0,0,594.0256,-28223.44,-7.9591,-0.6293,0,0,0,0,0,0,0,0,0,0,4.3079,-5.8971,-2.8242,-2.8242,580.8449,16.0409,39.7949,-23.754,0.9607,0.4031,7416.61,-5.8142,596.6809,31.8769,-11.877,0,-353.9515,27.9179,2.804,0.1748,0,0,1555010,-564.804,0,0,0,1.56E+08,0,0,49.0268,29.8786,573.7251,600.5952,621.0973,-3.2957,-5.8971,4.4485,1.3872,-2.6652,621.3255,600.5952,573.4969,56.5215,35.7912,8.6929,1.8459,4.4485,-6.3558,598.4725,33.6685,47.8286,0.5666,6.502,-86.0393,-0.0614,90.0832
1,212.6,212.6,604.5466,155363.7,552,0,-0.1832,554.4286,-13.7172,0,0,0.0528,0.0522,0.0518,0,0,0,-19.3054,0,0,100,0,0,0,0,0,0,0,0,0,0,593.2192,-30147.36,8.0943,3.4865,0,0,0,0,0,0,0,0,0,0,4.2573,-6.9282,-3.2939,-3.2939,579.6115,25.1829,50.118,-24.9351,0.9588,0.5025,7345.092,-6.8147,596.2349,41.8063,-12.4676,0,-226.8838,37.6505,2.4286,0.0964,0,0,1555010,-554.4286,0,0,0,1.56E+08,0,0,48.8195,29.7828,572.2897,600.2546,622.2682,18.5097,-6.9282,5.0602,1.7782,2.6738,628.3767,600.2546,566.1812,73.9481,45.826,11.7526,2.171,5.0602,-7.321,598.2708,43.8422,62.1955,0.5478,6.2921,71.7362,-0.0898,89.9303
1,215.4,215.4,604.208,156704.2,565,0,-0.1604,568.9648,-14.4744,0,0,0.0528,0.0522,0.0518,0,0,0,-20.5305,0,0,100,0,0,0,0,0,0,0,0,0,0,594.1893,-31732.88,2.816,-0.405,0,0,0,0,0,0,0,0,0,0,4.2617,-7.3107,-3.4664,-3.4664,582.2861,13.3213,35.2432,-21.9219,0.9637,0.378,7318.912,-7.1847,596.9007,27.9359,-10.961,0,-116.836,24.2823,3.9648,0.2976,0,0,1555010,-568.9648,0,0,0,1.56E+08,0,0,48.7568,29.7696,575.9195,600.4099,619.9161,-2.16,-7.3107,5.3341,1.8766,0.926,620.0219,600.4099,575.8137,51.0571,31.4451,6.8489,1.923,5.3341,-7.3571,598.7485,29.7837,44.2082,0.5564,7.4548,-87.1961,-0.1,89.9593
1,218.2,218.2,604.527,157794.2,552,0,-0.187,554.7438,-15.9074,0,0,0.0528,0.0522,0.0518,0,0,0,-22.8921,0,0,100,0,0,0,0,0,0,0,0,0,0,593.0676,-33202.2,-11.0126,-3.2836,0,0,0,0,0,0,0,0,0,0,4.2078,-8.0344,-3.7903,-3.7903,578.7988,24.0551,49.7832,-25.7282,0.9574,0.4832,7269.883,-7.8831,595.9509,41.2072,-12.8641,0,-210.1597,36.9192,2.7438,0.1141,0,0,1555010,-554.7438,0,0,0,1.56E+08,0,0,48.6157,29.7065,571.1637,600.1806,622.5297,-17.6779,-8.0344,5.7686,2.1422,-3.5874,628.0256,600.1806,565.6677,73.2818,45.4368,10.924,2.7395,5.7686,-8.6317,597.9579,43.2142,62.3578,0.5535,6.7083,-72.73,-0.1236,90.0638
1,221,221,604.2897,159374.2,565,0,-0.1594,566.3656,-17.2967,0,0,0.0528,0.0522,0.0518,0,0,0,-25.1498,0,0,100,0,0,0,0,0,0,0,0,0,0,594.3058,-35096.49,1.7065,1.8907,0,0,0,0,0,0,0,0,0,0,4.2054,-8.7361,-4.1012,-4.1012,582.2259,15.8603,37.9241,-22.0638,0.9635,0.4182,7222.969,-8.5582,596.9351,30.5695,-11.0319,0,-131.1719,26.8922,1.3656,0.0861,0,0,1555010,-566.3656,0,0,0,1.56E+08,0,0,48.4875,29.6578,575.7757,600.5005,620.0148,10.269,-8.7361,6.2152,2.3734,0.551,622.2823,600.5005,573.5082,55.9167,34.1349,7.1426,2.387,6.2152,-8.7497,598.7636,32.3981,48.7741,0.5534,7.8286,77.5485,-0.1475,89.9773
1,223.8,223.8,604.6491,160310,555,0,-0.1883,557.7654,-18.2216,0,0,0.0528,0.0522,0.0518,0,0,0,-26.6498,0,0,100,0,0,0,0,0,0,0,0,0,0,593.1788,-36325.9,9.4423,2.4688,0,0,0,0,0,0,0,0,0,0,4.1604,-9.2033,-4.3066,-4.3066,578.4707,20.7053,46.8837,-26.1784,0.9567,0.4416,7192.067,-9.0066,595.923,38.1576,-13.0892,0,-440.0059,33.7945,2.7654,0.1336,0,0,1555010,-557.7654,0,0,0,1.56E+08,0,0,48.4023,29.6248,570.611,600.2941,622.7455,13.4876,-9.2033,6.5104,2.5285,3.0311,626.0281,600.2941,567.3283,68.2627,42.5288,9.5629,2.9078,6.5104,-9.5826,597.8835,40.1181,58.6998,0.5616,7.1383,76.3211,-0.1644,89.9466
1,226.6,226.6,604.7241,161995,554,0,-0.176,557.6873,-20.056,0,0,0.0528,0.0522,0.0518,0,0,0,-29.6051,0,0,100,0,0,0,0,0,0,0,0,0,0,593.2269,-38405.18,-9.8688,-3.0363,0,0,0,0,0,0,0,0,0,0,4.1366,-10.1298,-4.7099,-4.7099,580.0412,22.3539,47.0368,-24.6829,0.9592,0.4752,7131.562,-9.8931,596.4965,38.8092,-12.3415,0,-1101.143,34.6954,3.6873,0.165,0,0,1555010,-557.6873,0,0,0,1.56E+08,0,0,48.2298,29.5513,573.0741,600.356,622.9139,-16.7828,-10.1298,7.075,2.8527,-3.1312,628.0384,600.356,567.9496,70.3511,42.6687,10.2623,3.2199,7.075,-10.497,598.7813,41.094,60.0888,0.5393,6.8553,-73.0205,-0.2021,90.0486
1,229.4,229.4,604.5052,162824.2,558,0,-0.1835,562.4037,-20.4138,0,0,0.0528,0.0522,0.0518,0,0,0,-30.2288,0,0,100,0,0,0,0,0,0,0,0,0,0,593.4686,-39417.88,-12.0964,-1.4007,0,0,0,0,0,0,0,0,0,0,4.1205,-10.3105,-4.788,-4.788,578.7317,16.328,42.1015,-25.7735,0.9574,0.3878,7119.88,-10.0657,595.914,33.5103,-12.8868,0,-221.623,29.2148,4.4037,0.2697,0,0,1555010,-562.4037,0,0,0,1.56E+08,0,0,48.2056,29.5521,570.8803,600.3107,621.99,-7.7576,-10.3105,7.2185,2.8837,-3.8304,623.1415,600.3107,569.7288,60.7378,37.907,7.3251,3.4181,7.2185,-10.8449,597.727,35.3233,53.4127,0.5726,8.2917,-81.5567,-0.2083,90.0498
1,230.6,230.6,604.4313,163738.3,568,0,-0.1557,571.317,-21.3293,0,0,0.0528,0.0522,0.0518,0,0,0,-31.7398,0,0,100,0,0,0,0,0,0,0,0,0,0,594.9438,-40475.52,-4.3456,0.6935,0,0,0,0,0,0,0,0,0,0,4.1298,-10.7729,-4.987,-4.987,582.4693,11.1523,33.1143,-21.962,0.9637,0.3368,7090.159,-10.5066,597.1106,25.7936,-10.981,0,-199.8294,22.1333,3.317,0.2974,0,0,1555010,-571.317,0,0,0,1.56E+08,0,0,48.1208,29.5164,575.8413,600.8243,619.4835,3.8631,-10.7729,7.5014,3.0434,-1.3681,619.8228,600.8243,575.502,48.5058,29.5073,4.185,3.1108,7.5014,-10.8403,598.7164,27.3994,44.3208,0.5713,11.5904,84.9803,-0.2281,90.034