File: datas/d100-30-0.2.csv
Stage Number,Time since start of test (s),Time since start of stage (s),Radial Pressure (kPa),Radial Volume (mm3),Back Pressure (kPa),Back Volume (mm3),Load Cell (kN),Pore Pressure (kPa),Axial Displacement (mm),L/C Pressure (kPa),L/C Volume (mm3),Local Axial 1,Local Axial 2,Local Radial,Base Pressure (kPa),Base Volume (mm3),Back Differential Pressure (kPa),Axial Displacement 2 (mm),Pore Air Pressure (kPa),Pore Air Volume (mm3),Atmospheric Pressure (kPa),Temperature (°C),Mid Plane PWP (kPa),Back to Cell Differential (kPa),Total Volume Change (mm3),Undefined Tx 1,Undefined Tx 2,Undefined Tx 3,Undefined Tx. 4,HCA secondary control axial load (kN),HCA secondary control torque,Internal Cell Pr. (kPa),Internal Cell Vol. (mm3),Rotational Displ. (mm),Torque,Local Int Defmn 1 (mm),Local Int Defmn 2 (mm),Circumf. Defmn 1 (mm),Circumf. Defmn 2 (mm),Circumf. Defmn 3 (mm),Outer Cell Pr 2 (kPa),Internal cell Pr 2 (kPa),Rotation 2 (°),Secondary Cell Pr (kPa),Secondary Back Pr (kPa),Axial Force (kN),Axial Strain (%),Av Diameter Change (mm),Radial Strain (%),Axial Stress (kPa),Eff. Axial Stress (kPa),Eff. Radial Stress (kPa),Deviator Stress (kPa),Total Stress Ratio (%),Eff. Stress Ratio (%),Current Area (mm2),Shear Strain (%),Cambridge p (kPa),Eff. Cambridge p' (kPa),Max Shear Stress t,Volume Change (mm3),B Value,Mean Stress s/Eff. Axial Stress 2,Excess PWP (kPa),PWP Ratio,Lower Chamber Displacement (mm),Lower Chamber Axial Load (kPa),Specimen Air Volume (mm3),Matric Suction (kPa),Voids ratio,Degree of Saturation (°),Specimen Water Volume (mm3),kRT constant,Permeability IN,Permeability OUT,HCA Outer Rad,HCA Inner Rad,HCA Sigma Z (kPa),HCA Sigma R (kPa),HCA Sigma Theta (kPa),HCA Tau Theta Z,HCA Ez,HCA Er,HCA Etheta,HCA Gamma,HCA Sigma1,HCA Sigma2,HCA Sigma3,HCA Eff Sigma1,HCA Eff Sigma2,HCA Eff Sigma3,HCA E1,HCA E2,HCA E3,HCA P,HCA Eff P,HCA Q,HCA B,HCA Eff R,HCA Alpha,HCA Ev,HCA E1 rtv
1,0,0,573.7543,104513.9,478,0,0.0922,478.3654,0.0027,0,0,0.0528,0.0522,0.0518,0,0,0,7.5817,0,0,100,0,0,0,0,0,0,0,0,0,0,581.1422,16064.11,0.0045,4.4054,0,0,0,0,0,0,0,0,0,0,4.5985,0.0014,0.0007,0.0007,585.4915,107.1261,95.3889,11.7372,1.0205,1.123,7854.085,0.0014,577.6667,99.3013,5.8686,0,0.0568,101.2575,0.3654,0.0034,0,0,1525243,-478.3654,0,0,0,1.53E+08,0,0,49.7363,29.5581,588.0625,576.5082,562.9321,21.6383,0.0014,-0.8831,0.8898,0.0016,600.5193,576.5082,550.4753,122.1539,98.1428,72.1099,0.8898,-0.8831,0.0014,575.8342,97.4689,50.044,0.5202,1.694,29.9283,0.0081,89.9991
1,13.2,13.2,574.0891,104908.7,498,0,0.0934,498.8948,0.2004,0,0,0.0528,0.0522,0.0518,0,0,0,7.8942,0,0,100,0,0,0,0,0,0,0,0,0,0,580.1492,15699.8,2.2826,8.1329,0,0,0,0,0,0,0,0,0,0,4.6069,0.1032,0.0516,0.0516,585.9639,87.0691,75.1943,11.8748,1.0207,1.1579,7862.089,0.1032,578.0474,79.1526,5.9374,0,35.3628,81.1317,0.8948,0.0103,0,0,1525243,-498.8948,0,0,0,1.53E+08,0,0,49.7677,29.5833,589.34,576.3484,565.2072,39.8784,0.1032,-0.9136,0.8179,0.8323,618.9376,576.3484,535.6097,120.0428,77.4536,36.7149,1.1491,-0.9136,-0.228,576.9653,78.0704,83.3279,0.4889,3.2696,36.5826,0.0075,89.5144
1,26.6,26.6,573.5248,105589.5,514,0,0.0938,515.1849,0.343,0,0,0.0528,0.0522,0.0518,0,0,0,8.1255,0,0,100,0,0,0,0,0,0,0,0,0,0,580.8341,14921.18,2.1567,0.9492,0,0,0,0,0,0,0,0,0,0,4.6062,0.1766,0.0884,0.0884,585.4444,70.2595,58.3399,11.9196,1.0208,1.2043,7867.87,0.1767,577.498,62.3131,5.9598,0,2218.675,64.2997,1.1849,0.0169,0,0,1525243,-515.1849,0,0,0,1.53E+08,0,0,49.7988,29.6157,588.153,576.2506,562.7994,4.6473,0.1766,-0.9072,0.7373,0.7876,588.978,576.2506,561.9744,73.7932,61.0657,46.7896,1.0805,-0.9072,-0.1666,575.7344,60.5495,27.0036,0.5287,1.5771,10.0664,0.0067,89.4051
1,40,40,574.175,106008.1,520,0,0.0957,520.3282,0.4298,0,0,0.0528,0.0522,0.0518,0,0,0,8.3004,0,0,100,0,0,0,0,0,0,0,0,0,0,580.0042,14499.2,2.7738,4.4089,0,0,0,0,0,0,0,0,0,0,4.6153,0.2213,0.1108,0.1108,586.3383,66.0101,53.8468,12.1633,1.0212,1.2259,7871.395,0.2214,578.2294,57.9012,6.0817,0,62.9517,59.9285,0.3282,0.005,0,0,1525243,-520.3282,0,0,0,1.53E+08,0,0,49.8169,29.6341,589.9795,576.3492,565.616,21.5669,0.2213,-0.9057,0.691,1.0139,602.5672,576.3492,553.0283,82.239,56.021,32.7001,1.2106,-0.9057,-0.2983,577.3149,56.9867,49.5389,0.4708,2.5149,30.2704,0.0066,89.1566
1,53.4,53.4,573.8278,105334.6,515,0,0.0928,515.7497,0.4854,0,0,0.0528,0.0522,0.0518,0,0,0,8.3653,0,0,100,0,0,0,0,0,0,0,0,0,0,579.6808,15284.14,4.3386,7.8688,0,0,0,0,0,0,0,0,0,0,4.6109,0.2499,0.1252,0.1252,585.6114,69.8617,58.0781,11.7836,1.0205,1.2029,7873.651,0.2501,577.7557,62.006,5.8918,0,117.0009,63.9699,0.7497,0.0107,0,0,1525243,-515.7497,0,0,0,1.53E+08,0,0,49.8111,29.6165,589.043,576.0103,565.244,38.4903,0.2499,-0.9636,0.7207,1.5859,617.4313,576.0103,536.8558,101.6816,60.2606,21.1061,1.6311,-0.9636,-0.6605,576.7658,61.0161,80.5755,0.4859,4.8176,36.4103,0.007,88.9293
1,66.8,66.8,573.5308,106130.7,532,0,0.093,532.1721,0.6573,0,0,0.0528,0.0522,0.0518,0,0,0,8.6569,0,0,100,0,0,0,0,0,0,0,0,0,0,581.2138,14403.27,3.9139,0.7033,0,0,0,0,0,0,0,0,0,0,4.6128,0.3385,0.1697,0.1697,585.3324,53.1603,41.3587,11.8016,1.0206,1.2853,7880.651,0.3388,577.4647,45.2926,5.9008,0,2376.815,47.2595,0.1721,0.0032,0,0,1525243,-532.1721,0,0,0,1.53E+08,0,0,49.8478,29.6541,587.7616,576.3966,562.2485,3.4341,0.3385,-0.9592,0.6265,1.4332,588.2157,576.3966,561.7943,56.0436,44.2245,29.6222,1.5061,-0.9592,-0.5411,575.4689,43.2968,26.4214,0.5527,1.8919,7.5335,0.0058,88.3306
1,80.2,80.2,574.1042,106502.8,532,0,0.0949,533.0726,0.7329,0,0,0.0528,0.0522,0.0518,0,0,0,8.7964,0,0,100,0,0,0,0,0,0,0,0,0,0,579.4277,14000.17,4.7428,4.9288,0,0,0,0,0,0,0,0,0,0,4.621,0.3774,0.1892,0.1892,586.144,53.0714,41.0316,12.0398,1.021,1.2934,7883.728,0.3777,578.1174,45.0448,6.0199,0,91.8128,47.0515,1.0726,0.0202,0,0,1525243,-533.0726,0,0,0,1.53E+08,0,0,49.8642,29.6711,589.9946,576.0901,566.282,24.0473,0.3774,-0.9563,0.5843,1.7381,604.9496,576.0901,551.327,71.877,43.0175,18.2545,1.7142,-0.9563,-0.7525,577.4556,44.383,53.6225,0.4618,3.9375,31.8774,0.0054,87.4657
1,93.6,93.6,573.6473,105382.2,522,0,0.0938,523.6484,0.7554,0,0,0.0528,0.0522,0.0518,0,0,0,8.8426,0,0,100,0,0,0,0,0,0,0,0,0,0,579.8921,15303.56,6.408,7.5668,0,0,0,0,0,0,0,0,0,0,4.6168,0.389,0.1951,0.1951,585.543,61.8947,49.9989,11.8958,1.0207,1.2379,7884.646,0.3894,577.6125,53.9641,5.9479,0,325.6452,55.9468,1.6484,0.0266,0,0,1525243,-523.6484,0,0,0,1.53E+08,0,0,49.8456,29.6367,588.8208,575.9758,564.4891,36.936,0.389,-1.0337,0.6513,2.3472,615.5429,575.9758,537.7669,91.8945,52.3275,14.1185,2.185,-1.0337,-1.1447,576.4285,52.7802,77.776,0.4913,6.5088,35.8847,0.0066,87.7735
1,107,107,573.1577,106372.5,541,0,0.0928,542.5087,0.9916,0,0,0.0528,0.0522,0.0518,0,0,0,9.2374,0,0,100,0,0,0,0,0,0,0,0,0,0,581.38,14198.95,5.6965,0.5034,0,0,0,0,0,0,0,0,0,0,4.6175,0.5106,0.2563,0.2563,584.9169,42.4081,30.649,11.7592,1.0205,1.3837,7894.283,0.5113,577.0775,34.5688,5.8796,0,-183.064,36.5286,1.5087,0.0356,0,0,1525243,-542.5087,0,0,0,1.53E+08,0,0,49.8942,29.6854,587.02,576.2249,561.0798,2.4514,0.5106,-1.0332,0.5283,2.0915,587.2497,576.2249,560.8502,44.741,33.7162,18.3415,1.9984,-1.0332,-0.9595,574.775,32.2662,26.3995,0.5824,2.4393,5.3514,0.0057,58.226
1,120.4,120.4,574.1042,106759.5,536,0,0.0943,539.0574,1.0523,0,0,0.0528,0.0522,0.0518,0,0,0,9.3501,0,0,100,0,0,0,0,0,0,0,0,0,0,578.9468,13786.54,6.8946,5.4522,0,0,0,0,0,0,0,0,0,0,4.6279,0.5419,0.2721,0.2721,586.0499,46.9926,35.0468,11.9457,1.0208,1.3409,7896.768,0.5427,578.0861,39.0288,5.9729,0,101.8542,41.0197,3.0574,0.0651,0,0,1525243,-539.0574,0,0,0,1.53E+08,0,0,49.9089,29.7016,590.1074,575.9109,566.9863,26.5323,0.5419,-1.0259,0.4893,2.5332,607.4883,575.9109,549.6054,68.4309,36.8535,10.548,2.307,-1.0259,-1.2758,577.6682,38.6108,57.8829,0.4545,6.4876,33.2282,0.0053,11.3576
1,133.8,133.8,574.0535,105367.7,529,0,0.0936,528.5686,1.0615,0,0,0.0528,0.0522,0.0518,0,0,0,9.3472,0,0,100,0,0,0,0,0,0,0,0,0,0,579.9401,15396.84,8.6008,7.2005,0,0,0,0,0,0,0,0,0,0,4.627,0.5466,0.2744,0.2744,585.9083,57.3397,45.4849,11.8548,1.0207,1.2606,7897.141,0.5473,578.0051,49.4365,5.9274,0,92.0827,51.4123,-0.4314,-0.0075,0,0,1525243,-528.5686,0,0,0,1.53E+08,0,0,49.8835,29.6575,589.3545,576.2484,565.422,35.0663,0.5466,-1.1174,0.5771,3.1577,614.4401,576.2484,540.3364,85.8715,47.6798,11.7678,2.7947,-1.1174,-1.671,577.0083,48.4397,74.1037,0.4846,7.2972,35.579,0.0063,69.277
1,147.2,147.2,573.1666,106485.8,548,0,0.0923,549.511,1.3852,0,0,0.0528,0.0522,0.0518,0,0,0,9.8494,0,0,100,0,0,0,0,0,0,0,0,0,0,581.2837,14135.3,7.5762,0.3833,0,0,0,0,0,0,0,0,0,0,4.6263,0.7133,0.3586,0.3586,584.8377,35.3267,23.6556,11.6711,1.0204,1.4934,7910.4,0.7146,577.0569,27.5459,5.8356,0,-208.3414,29.4912,1.511,0.0428,0,0,1525243,-549.511,0,0,0,1.53E+08,0,0,49.9462,29.7175,586.9499,576.1946,561.2421,1.8608,0.7133,-1.1306,0.4221,2.7903,587.0839,576.1946,561.1082,37.5729,26.6836,11.5972,2.5461,-1.1306,-1.4107,574.7956,25.2846,25.9757,0.5808,3.2398,4.1186,0.0048,2.1062
1,160.6,160.6,574.213,106790.5,542,0,0.096,542.064,1.4175,0,0,0.0528,0.0522,0.0518,0,0,0,9.9325,0,0,100,0,0,0,0,0,0,0,0,0,0,578.8737,13826.03,9.2804,5.9057,0,0,0,0,0,0,0,0,0,0,4.639,0.7299,0.367,0.367,586.3451,44.2811,32.149,12.1321,1.0211,1.3774,7911.723,0.7313,578.257,36.193,6.0661,0,90.3938,38.2151,0.064,0.0014,0,0,1525243,-542.064,0,0,0,1.53E+08,0,0,49.9555,29.7286,590.6166,575.9518,567.3629,28.6583,0.7299,-1.1218,0.3964,3.4194,609.9167,575.9518,548.0627,67.8527,33.8878,5.9987,2.9868,-1.1218,-1.8605,577.9771,35.9131,61.854,0.4509,11.3112,33.9587,0.0045,1.9285
1,174,174,573.8506,105248.3,533,0,0.0937,532.3667,1.4324,0,0,0.0528,0.0522,0.0518,0,0,0,9.9446,0,0,100,0,0,0,0,0,0,0,0,0,0,579.9733,15584.63,10.9679,6.8196,0,0,0,0,0,0,0,0,0,0,4.6342,0.7376,0.3709,0.3709,585.693,53.3263,41.4839,11.8424,1.0206,1.2855,7912.336,0.739,577.798,45.4313,5.9212,0,157.7516,47.4051,-0.6333,-0.0119,0,0,1525243,-532.3667,0,0,0,1.53E+08,0,0,49.9283,29.6808,589.0079,576.1333,564.8752,33.119,0.7376,-1.2224,0.491,4.038,612.1901,576.1333,541.6929,79.8234,43.7666,9.3262,3.4723,-1.2224,-2.2437,576.6721,44.3054,70.4972,0.4885,8.5591,34.9908,0.0062,2.6927
1,187.4,187.4,573.6479,106438.3,553,0,0.0927,554.1628,1.8704,0,0,0.0528,0.0522,0.0518,0,0,0,10.6593,0,0,100,0,0,0,0,0,0,0,0,0,0,581.2098,14299.99,9.6099,0.3134,0,0,0,0,0,0,0,0,0,0,4.6419,0.9631,0.4851,0.4851,585.3334,31.1706,19.4851,11.6855,1.0204,1.5997,7930.352,0.9655,577.543,23.3803,5.8428,0,542.6359,25.3279,1.1628,0.0373,0,0,1525243,-554.1628,0,0,0,1.53E+08,0,0,50.0064,29.7504,587.7696,576.4686,562.5416,1.5158,0.9631,-1.2638,0.3049,3.5524,587.8604,576.4686,562.4509,33.6976,22.3059,8.2881,3.1674,-1.2638,-1.8994,575.5933,21.4305,25.4095,0.5517,4.0658,3.4261,0.0042,0.9848
1,200.8,200.8,574.2624,106567.1,542,0,0.0955,542.7958,1.8644,0,0,0.0528,0.0522,0.0518,0,0,0,10.6518,0,0,100,0,0,0,0,0,0,0,0,0,0,578.3997,14137.38,11.9359,6.3812,0,0,0,0,0,0,0,0,0,0,4.6495,0.96,0.4835,0.4835,586.3101,43.5143,31.4666,12.0477,1.021,1.3829,7930.104,0.9623,578.2783,35.4825,6.0239,0,85.446,37.4905,0.7958,0.0183,0,0,1525243,-542.7958,0,0,0,1.53E+08,0,0,50.0083,29.7544,590.8118,575.8058,568.1843,30.863,0.96,-1.2536,0.2975,4.4124,612.3694,575.8058,546.6267,69.5736,33.01,3.8309,3.7663,-1.2536,-2.5088,578.2673,35.4715,65.7427,0.4438,18.1612,34.934,0.0039,1.0173
1,214.2,214.2,573.9901,105051.8,536,0,0.0928,535.3809,1.9031,0,0,0.0528,0.0522,0.0518,0,0,0,10.7229,0,0,100,0,0,0,0,0,0,0,0,0,0,580.3451,15906.37,13.6002,6.3703,0,0,0,0,0,0,0,0,0,0,4.6455,0.98,0.4936,0.4936,585.6874,50.3065,38.6092,11.6973,1.0204,1.303,7931.706,0.9824,577.8892,42.5083,5.8487,0,118.3348,44.4579,-0.6191,-0.0123,0,0,1525243,-535.3809,0,0,0,1.53E+08,0,0,49.9841,29.7082,588.8001,576.3592,564.6788,30.8287,0.98,-1.3607,0.3861,5.0247,609.8433,576.3592,543.6356,74.4624,40.9783,8.2547,4.2484,-1.3607,-2.8823,576.6127,41.2318,66.2077,0.4943,9.0206,34.3169,0.0054,1.1571
1,227.6,227.6,573.4882,106294.4,556,0,0.0946,557.6359,2.4706,0,0,0.0528,0.0522,0.0518,0,0,0,11.632,0,0,100,0,0,0,0,0,0,0,0,0,0,581.0562,14572.4,11.8958,0.3421,0,0,0,0,0,0,0,0,0,0,4.6568,1.2722,0.6422,0.6422,585.3795,27.7436,15.8523,11.8913,1.0207,1.7501,7955.181,1.2763,577.452,19.8161,5.9457,0,-3972.469,21.798,1.6359,0.059,0,0,1525243,-557.6359,0,0,0,1.53E+08,0,0,50.0801,29.7893,587.9249,576.3109,562.3775,1.6471,1.2722,-1.4332,0.1635,4.4175,588.0307,576.3109,562.2718,30.3948,18.675,4.6359,3.8903,-1.4332,-2.4546,575.5378,17.9019,25.7589,0.545,6.5564,3.6737,0.0025,0.608
1,241,241,574.3549,106263.2,543,0,0.0967,542.9211,2.4216,0,0,0.0528,0.0522,0.0518,0,0,0,11.5921,0,0,100,0,0,0,0,0,0,0,0,0,0,578.7166,14591.8,14.8841,6.8115,0,0,0,0,0,0,0,0,0,0,4.6646,1.247,0.6294,0.6294,586.5097,43.5886,31.4338,12.1548,1.0212,1.3867,7953.151,1.2509,578.4065,35.4854,6.0774,0,76.2567,37.5112,-0.0789,-0.0018,0,0,1525243,-542.9211,0,0,0,1.53E+08,0,0,50.0734,29.785,590.9647,575.9817,567.9516,32.8087,1.247,-1.4215,0.1773,5.525,614.2261,575.9817,544.6902,71.305,33.0606,1.7691,4.6554,-1.4215,-3.2311,578.2993,35.3782,69.5359,0.45,40.3058,35.3367,0.0028,0.6505
1,254.4,254.4,573.7633,104703.1,537,0,0.0926,538.0498,2.4999,0,0,0.0528,0.0522,0.0518,0,0,0,11.6855,0,0,100,0,0,0,0,0,0,0,0,0,0,580.339,16364.58,16.4806,5.9133,0,0,0,0,0,0,0,0,0,0,4.6577,1.2873,0.6499,0.6499,585.4031,47.3533,35.7135,11.6398,1.0203,1.3259,7956.397,1.2915,577.6432,39.5934,5.8199,0,233.9949,41.5334,1.0498,0.0222,0,0,1525243,-538.0498,0,0,0,1.53E+08,0,0,50.0542,29.7416,588.3598,576.2142,564.1353,28.4907,1.2873,-1.5389,0.2559,6.1159,607.206,576.2142,545.2891,69.1562,38.1644,7.2393,5.1268,-1.5389,-3.5836,576.2364,38.1866,61.9169,0.4995,9.5529,33.4841,0.0043,0.6829
1,267.8,267.8,573.5002,105951.5,558,0,0.093,559.5785,3.198,0,0,0.0528,0.0522,0.0518,0,0,0,12.7794,0,0,100,0,0,0,0,0,0,0,0,0,0,580.9868,15015.15,14.4698,0.3799,0,0,0,0,0,0,0,0,0,0,4.6727,1.6468,0.8337,0.8337,585.1495,25.571,13.9217,11.6493,1.0203,1.8368,7985.48,1.6537,577.3833,17.8048,5.8247,0,-10158.97,19.7464,1.5785,0.0617,0,0,1525243,-559.5785,0,0,0,1.53E+08,0,0,50.168,29.8336,587.6012,576.2921,562.5162,1.8191,1.6468,-1.6445,-0.002,5.4029,587.7325,576.2921,562.3849,28.154,16.7136,2.8064,4.7308,-1.6445,-3.086,575.4698,15.8913,25.3476,0.5487,10.0321,4.1262,0.0003,0.4208
1,281.2,281.2,574.2048,105793.6,542,0,0.0967,542.4541,3.1029,0,0,0.0528,0.0522,0.0518,0,0,0,12.6904,0,0,100,0,0,0,0,0,0,0,0,0,0,578.2914,15237.5,18.1234,7.2374,0,0,0,0,0,0,0,0,0,0,4.6797,1.5978,0.8086,0.8086,586.3181,43.864,31.7507,12.1133,1.0211,1.3815,7981.503,1.6043,578.2426,35.7885,6.0567,0,92.023,37.8074,0.4541,0.0104,0,0,1525243,-542.4541,0,0,0,1.53E+08,0,0,50.1519,29.82,590.9003,575.7286,568.2111,34.6858,1.5978,-1.6324,0.0351,6.7613,616.0496,575.7286,543.0618,73.5955,33.2745,0.6077,5.6608,-1.6324,-4.0279,578.28,35.8259,72.9878,0.4476,121.105,35.9444,0.0005,0.4556
1,294.6,294.6,573.3277,104349.3,541,0,0.0939,540.6942,3.2316,0,0,0.0528,0.0522,0.0518,0,0,0,12.8754,0,0,100,0,0,0,0,0,0,0,0,0,0,580.7398,16864.73,19.5806,5.4159,0,0,0,0,0,0,0,0,0,0,4.673,1.6641,0.8426,0.8426,585.0842,44.39,32.6335,11.7565,1.0205,1.3603,7986.885,1.6711,577.2465,36.5523,5.8783,0,-345.4259,38.5118,-0.3058,-0.0069,0,0,1525243,-540.6942,0,0,0,1.53E+08,0,0,50.1417,29.7845,587.6564,576.0898,562.483,25.9515,1.6641,-1.7547,0.0923,7.3062,603.9125,576.0898,546.2269,63.2183,35.3956,5.5327,6.1039,-1.7547,-4.3475,575.4097,34.7155,57.6856,0.5177,11.4263,32.0631,0.0017,0.4564
1,308,308,573.8138,105541.3,560,0,0.0944,561.0876,4.0485,0,0,0.0528,0.0522,0.0518,0,0,0,14.1488,0,0,100,0,0,0,0,0,0,0,0,0,0,580.7883,15552.21,17.3048,0.5004,0,0,0,0,0,0,0,0,0,0,4.6971,2.0847,1.0589,1.0589,585.5862,24.4986,12.7262,11.7724,1.0205,1.9251,8021.193,2.0957,577.7379,16.6503,5.8862,0,270.7309,18.6124,1.0876,0.0444,0,0,1525243,-561.0876,0,0,0,1.53E+08,0,0,50.2712,29.8852,588.3905,576.4141,563.5893,2.3808,2.0847,-1.8934,-0.1951,6.503,588.6169,576.4141,563.3628,27.5293,15.3265,2.2752,5.6823,-1.8934,-3.7927,576.1313,15.0437,25.2541,0.5168,12.0997,5.434,-0.0038,0.311
1,321.4,321.4,574.671,105211.2,537,0,0.0965,541.5609,3.9073,0,0,0.0528,0.0522,0.0518,0,0,0,13.9526,0,0,100,0,0,0,0,0,0,0,0,0,0,578.3261,15952.37,21.5608,7.5627,0,0,0,0,0,0,0,0,0,0,4.7026,2.012,1.0214,1.0214,586.7072,45.1463,33.1101,12.0362,1.0209,1.3635,8015.242,2.0223,578.6831,37.1222,6.0181,0,54.3578,39.1282,4.5609,0.101,0,0,1525243,-541.5609,0,0,0,1.53E+08,0,0,50.2458,29.8629,591.4866,576.0335,569.316,36.0296,2.012,-1.8785,-0.1357,8.0917,618.0976,576.0335,542.7049,76.5367,34.4726,1.144,6.7597,-1.8785,-4.8834,578.9453,37.3844,75.3927,0.4421,66.9027,36.4492,-0.0022,0.3371
1,334.8,334.8,573.3881,103987.7,544,0,0.0921,543.3987,4.092,0,0,0.0528,0.0522,0.0518,0,0,0,14.2391,0,0,100,0,0,0,0,0,0,0,0,0,0,581.1414,17358.09,22.8309,4.9276,0,0,0,0,0,0,0,0,0,0,4.6924,2.1071,1.0705,1.0705,584.8664,41.4677,29.9894,11.4783,1.02,1.3827,8023.028,2.1184,577.2142,33.8155,5.7392,0,-541.8071,35.7286,-0.6013,-0.0145,0,0,1525243,-543.3987,0,0,0,1.53E+08,0,0,50.2468,29.838,587.1014,576.2769,562.0527,23.4583,2.1071,-2.0031,-0.1059,8.5747,601.1693,576.2769,547.9847,57.7706,32.8782,4.586,7.164,-2.0031,-5.1628,575.1436,31.7449,53.1846,0.532,12.5972,30.9512,-0.0019,0.3287
1,348.2,348.2,573.5694,105179.2,561,0,0.0937,562.4358,5.0085,0,0,0.0528,0.0522,0.0518,0,0,0,15.7069,0,0,100,0,0,0,0,0,0,0,0,0,0,580.9897,16051.59,20.3388,0.6744,0,0,0,0,0,0,0,0,0,0,4.7178,2.579,1.315,1.315,585.1977,22.7619,11.1336,11.6283,1.0203,2.0444,8061.891,2.596,577.4455,15.0097,5.8142,0,1373.518,16.9478,1.4358,0.0631,0,0,1525243,-562.4358,0,0,0,1.53E+08,0,0,50.3902,29.9469,587.6778,576.3354,562.6996,3.1852,2.579,-2.1684,-0.4196,7.6995,588.0776,576.3354,562.2999,25.6418,13.8996,-0.1359,6.7267,-2.1684,-4.5673,575.571,13.1352,25.7777,0.5445,-188.6814,7.1538,-0.009,0.2404
1,361.6,361.6,574.4057,104747.7,537,0,0.0961,540.7376,4.8239,0,0,0.0528,0.0522,0.0518,0,0,0,15.4626,0,0,100,0,0,0,0,0,0,0,0,0,0,578.3087,16537.09,25.0972,7.8694,0,0,0,0,0,0,0,0,0,0,4.7224,2.484,1.2656,1.2656,586.3395,45.6019,33.6681,11.9338,1.0208,1.3545,8054.037,2.4997,578.3836,37.646,5.9669,0,69.5094,39.635,3.7376,0.082,0,0,1525243,-540.7376,0,0,0,1.53E+08,0,0,50.3576,29.9187,590.9199,575.8604,568.6924,37.231,2.484,-2.1474,-0.3442,9.4846,618.6605,575.8604,540.9518,77.9229,35.1228,0.2142,7.924,-2.1474,-5.7842,578.4909,37.7533,77.7087,0.4492,363.7857,36.6896,-0.0076,0.2591
1,375,375,573.5882,103748.9,546,0,0.0902,546.0071,5.0632,0,0,0.0528,0.0522,0.0518,0,0,0,15.8512,0,0,100,0,0,0,0,0,0,0,0,0,0,581.1845,17738.82,26.139,4.4231,0,0,0,0,0,0,0,0,0,0,4.7157,2.6072,1.3297,1.3297,584.7679,38.7608,27.5811,11.1797,1.0195,1.4053,8064.226,2.6246,577.3148,31.3077,5.5899,0,845.5153,33.171,0.0071,0.0002,0,0,1525243,-546.0071,0,0,0,1.53E+08,0,0,50.3693,29.9038,586.9302,576.418,562.4886,20.8995,2.6072,-2.2746,-0.3402,9.891,598.9196,576.418,550.4991,52.9125,30.411,4.492,8.2811,-2.2746,-6.0141,575.2789,29.2718,48.4205,0.5353,11.7793,29.8417,-0.0076,0.2494
1,388.4,388.4,573.4932,104922.3,562,0,0.0933,562.9082,6.0576,0,0,0.0528,0.0522,0.0518,0,0,0,17.4757,0,0,100,0,0,0,0,0,0,0,0,0,0,580.8592,16425.53,23.5,0.9509,0,0,0,0,0,0,0,0,0,0,4.7425,3.1193,1.5971,1.5971,584.9989,22.0907,10.585,11.5057,1.0201,2.087,8106.852,3.1443,577.3284,14.4202,5.7529,0,-5654.606,16.3379,0.9082,0.0411,0,0,1525243,-562.9082,0,0,0,1.53E+08,0,0,50.5243,30.0198,587.4563,576.2386,562.709,4.4547,3.1193,-2.4604,-0.6755,8.969,588.2338,576.2386,561.9315,25.3256,13.3304,-0.9767,7.8417,-2.4604,-5.3979,575.468,12.5598,26.3023,0.5439,-25.9298,9.8998,-0.0166,0.1923
1,401.8,401.8,574.5806,104458.9,539,0,0.0964,540.3364,5.8396,0,0,0.0528,0.0522,0.0518,0,0,0,17.1286,0,0,100,0,0,0,0,0,0,0,0,0,0,578.3261,16960.16,28.6606,8.1245,0,0,0,0,0,0,0,0,0,0,4.749,3.007,1.5383,1.5383,586.4798,46.1434,34.2442,11.8992,1.0207,1.3475,8097.466,3.0302,578.5471,38.2107,5.9496,0,57.7977,40.1938,1.3364,0.029,0,0,1525243,-540.3364,0,0,0,1.53E+08,0,0,50.486,29.9873,591.1404,575.9764,569.1014,38.1376,3.007,-2.4328,-0.5881,10.9166,619.8185,575.9764,540.4232,79.4821,35.64,0.0868,9.1352,-2.4328,-6.7163,578.7394,38.403,79.3953,0.4478,915.6924,36.9419,-0.0139,0.2058
1,415.2,415.2,573.351,103749.9,549,0,0.0906,548.8177,6.1521,0,0,0.0528,0.0522,0.0518,0,0,0,17.6159,0,0,100,0,0,0,0,0,0,0,0,0,0,581.0542,17790.37,29.4554,3.9498,0,0,0,0,0,0,0,0,0,0,4.741,3.1679,1.6226,1.6226,584.5206,35.7029,24.5333,11.1696,1.0195,1.4553,8110.921,3.1937,577.0742,28.2565,5.5848,0,-448.3571,30.1181,-0.1823,-0.0051,0,0,1525243,-548.8177,0,0,0,1.53E+08,0,0,50.5141,29.9888,586.6117,576.2206,562.0961,18.5026,3.1679,-2.5593,-0.6247,11.2426,596.5485,576.2206,552.1593,47.7308,27.4029,3.3416,9.4444,-2.5593,-6.9012,574.9761,26.1584,44.3892,0.5421,14.2838,28.238,-0.0161,0.1954
1,428.6,428.6,573.6036,104973.6,563,0,0.0939,563.7975,7.2032,0,0,0.0528,0.0522,0.0518,0,0,0,19.3372,0,0,100,0,0,0,0,0,0,0,0,0,0,580.9454,16431.74,26.7823,1.2026,0,0,0,0,0,0,0,0,0,0,4.7725,3.7092,1.9078,1.9078,585.115,21.3175,9.8061,11.5114,1.0201,2.1739,8156.517,3.7447,577.4407,13.6432,5.7557,0,895.6804,15.5618,0.7975,0.0374,0,0,1525243,-563.7975,0,0,0,1.53E+08,0,0,50.6787,30.1114,587.5853,576.34,562.8549,5.5825,3.7092,-2.7583,-0.978,10.3158,588.787,576.34,561.6531,24.9895,12.5425,-2.1444,9.0272,-2.7583,-6.296,575.5933,11.7959,27.1339,0.5413,-11.6534,12.1488,-0.0271,0.1573
1,442,442,574.177,104368.6,537,0,0.0962,539.7217,6.947,0,0,0.0528,0.0522,0.0518,0,0,0,18.9593,0,0,100,0,0,0,0,0,0,0,0,0,0,578.366,17098.41,32.2694,8.3295,0,0,0,0,0,0,0,0,0,0,4.7731,3.5772,1.8381,1.8381,585.9907,46.269,34.4553,11.8137,1.0206,1.3429,8145.351,3.6102,578.1149,38.3933,5.9069,0,91.7586,40.3622,2.7217,0.0588,0,0,1525243,-539.7217,0,0,0,1.53E+08,0,0,50.6328,30.072,590.3478,575.7379,568.0502,38.7583,3.5772,-2.7275,-0.8733,12.3995,619.5289,575.7379,538.8691,79.8072,36.0162,-0.8526,10.3977,-2.7275,-7.6938,578.0453,38.3236,80.6598,0.4571,-93.6045,36.9761,-0.0236,0.1674
1,455.4,455.4,573.6601,103846.3,550,0,0.0897,551.6617,7.3321,0,0,0.0528,0.0522,0.0518,0,0,0,19.5627,0,0,100,0,0,0,0,0,0,0,0,0,0,581.0815,17730.1,32.81,3.4023,0,0,0,0,0,0,0,0,0,0,4.772,3.7755,1.9429,1.9429,584.6508,32.9891,21.9984,10.9907,1.0192,1.4996,8162.137,3.8123,577.3237,25.6621,5.4954,0,482.5695,27.4938,1.6617,0.0504,0,0,1525243,-551.6617,0,0,0,1.53E+08,0,0,50.6744,30.0851,586.7918,576.4247,562.8159,15.7876,3.7755,-2.8622,-0.9404,12.6422,594.627,576.4247,554.9807,42.9653,24.763,3.319,10.6627,-2.8622,-7.8276,575.3442,23.6824,39.6463,0.5409,12.9453,26.3948,-0.0271,0.1582
1,468.8,468.8,573.4443,104990.1,563,0,0.0937,564.1388,8.4372,0,0,0.0528,0.0522,0.0518,0,0,0,21.3597,0,0,100,0,0,0,0,0,0,0,0,0,0,580.8307,16478.04,30.2629,1.5178,0,0,0,0,0,0,0,0,0,0,4.8021,4.3446,2.2457,2.2457,584.859,20.7202,9.3055,11.4147,1.0199,2.2267,8210.697,4.3935,577.2492,13.1104,5.7074,0,-1342.446,15.0129,1.1388,0.055,0,0,1525243,-564.1388,0,0,0,1.53E+08,0,0,50.8459,30.2099,587.2453,576.1973,562.6309,6.9762,4.3446,-3.082,-1.3026,11.7724,589.085,576.1973,560.7912,24.9462,12.0585,-3.3476,10.3112,-3.082,-7.2692,575.3578,11.219,28.2938,0.5445,-7.452,14.7731,-0.04,0.1316
1,482.2,482.2,574.3287,104280,538,0,0.0959,539.5163,8.1494,0,0,0.0528,0.0522,0.0518,0,0,0,20.9445,0,0,100,0,0,0,0,0,0,0,0,0,0,578.1907,17253.58,35.9187,8.4285,0,0,0,0,0,0,0,0,0,0,4.8042,4.1964,2.1666,2.1666,586.0213,46.505,34.8124,11.6926,1.0204,1.3359,8197.996,4.242,578.2263,38.71,5.8463,0,74.5463,40.6587,1.5163,0.0326,0,0,1525243,-539.5163,0,0,0,1.53E+08,0,0,50.7936,30.1646,590.5026,575.7676,568.6815,38.8447,4.1964,-3.0491,-1.1836,13.9347,619.9399,575.7676,539.2441,80.4236,36.2513,-0.2722,11.7203,-3.0491,-8.7075,578.3172,38.8009,80.6958,0.4526,-295.4578,37.1556,-0.0363,0.1393
1,495.6,495.6,573.7231,104064.9,555,0,0.0881,554.5737,8.624,0,0,0.0528,0.0522,0.0518,0,0,0,21.6803,0,0,100,0,0,0,0,0,0,0,0,0,0,581.313,17541.08,36.1617,2.9325,0,0,0,0,0,0,0,0,0,0,4.8035,4.4408,2.2972,2.2972,584.4412,29.8675,19.1494,10.7181,1.0187,1.5597,8218.963,4.492,577.2958,22.7221,5.3591,0,354.6795,24.5085,-0.4263,-0.0143,0,0,1525243,-554.5737,0,0,0,1.53E+08,0,0,50.8536,30.195,586.3388,576.5508,562.6295,13.4655,4.4408,-3.188,-1.2938,14.0807,592.4244,576.5508,556.5439,37.8507,21.9771,1.9702,11.9347,-3.188,-8.7877,575.173,20.5993,35.8805,0.5576,19.2116,24.3201,-0.041,0.1308
1,509,509,573.587,105238.1,563,0,0.0943,564.3479,9.7555,0,0,0.0528,0.0522,0.0518,0,0,0,23.5149,0,0,100,0,0,0,0,0,0,0,0,0,0,580.9636,16158.1,33.9092,1.8934,0,0,0,0,0,0,0,0,0,0,4.8375,5.0234,2.6105,2.6105,584.9895,20.6416,9.2391,11.4025,1.0199,2.2342,8269.379,5.0893,577.3878,13.0399,5.7013,0,1091.376,14.9404,1.3479,0.0653,0,0,1525243,-564.3479,0,0,0,1.53E+08,0,0,51.0327,30.3268,587.3777,576.3367,562.7828,8.6087,5.0234,-3.4092,-1.671,13.3347,590.0914,576.3367,560.069,25.7435,11.9888,-4.2789,11.6817,-3.4092,-8.3293,575.499,11.1511,30.0224,0.5419,-6.0164,17.4968,-0.0568,0.1117
1,522.4,522.4,574.4366,104462.7,538,0,0.0953,539.371,9.4482,0,0,0.0528,0.0522,0.0518,0,0,0,23.0382,0,0,100,0,0,0,0,0,0,0,0,0,0,578.2995,17045.42,39.5816,8.4835,0,0,0,0,0,0,0,0,0,0,4.8376,4.8652,2.5251,2.5251,585.976,46.605,35.0656,11.5394,1.0201,1.3291,8255.628,4.9269,578.283,38.9121,5.7697,0,65.7251,40.8353,1.371,0.0294,0,0,1525243,-539.371,0,0,0,1.53E+08,0,0,50.9753,30.2764,590.3681,575.876,568.7863,38.6855,4.8652,-3.3765,-1.5405,15.5196,619.7395,575.876,539.4149,80.3685,36.505,0.0439,13.0942,-3.3765,-9.7695,578.3434,38.9725,80.3246,0.4539,1830.717,37.2071,-0.0518,0.1176
1,535.8,535.8,573.4407,104369.9,554,0,0.0864,557.3065,10.0141,0,0,0.0528,0.0522,0.0518,0,0,0,23.9306,0,0,100,0,0,0,0,0,0,0,0,0,0,581.2783,17206.24,39.5134,2.481,0,0,0,0,0,0,0,0,0,0,4.8351,5.1566,2.6825,2.6825,583.8793,26.5728,16.1342,10.4386,1.0182,1.647,8280.993,5.2261,576.9202,19.6137,5.2193,0,-1169.621,21.3535,3.3065,0.1244,0,0,1525243,-557.3065,0,0,0,1.53E+08,0,0,51.0508,30.3182,585.4725,576.361,561.9793,11.2626,5.1566,-3.5336,-1.6825,15.563,589.9995,576.361,557.4523,32.693,19.0545,0.1458,13.2608,-3.5336,-9.7867,574.6043,17.2978,32.5472,0.581,224.2318,21.8975,-0.0595,0.1101
1,549.2,549.2,573.4698,105482,561,0,0.0982,564.1362,11.1577,0,0,0.0528,0.0522,0.0518,0,0,0,25.8091,0,0,100,0,0,0,0,0,0,0,0,0,0,580.9484,15888.5,37.7924,2.3243,0,0,0,0,0,0,0,0,0,0,4.8768,5.7455,3.0028,3.0028,585.2582,21.122,9.3336,11.7884,1.0206,2.263,8332.732,5.8322,577.3992,13.2629,5.8942,0,-2234.497,15.2278,3.1362,0.1485,0,0,1525243,-564.1362,0,0,0,1.53E+08,0,0,51.2324,30.4505,587.7986,576.2578,562.5118,10.4461,5.7455,-3.7624,-2.0603,15.035,591.5557,576.2578,558.7546,27.4195,12.1216,-5.3817,13.1677,-3.7624,-9.4825,575.5227,11.3865,32.8012,0.5336,-5.095,19.7819,-0.0772,0.0964
1,562.6,562.6,574.6525,104638.1,539,0,0.0955,539.9531,10.8565,0,0,0.0528,0.0522,0.0518,0,0,0,25.3271,0,0,100,0,0,0,0,0,0,0,0,0,0,578.6184,16858.94,43.3031,8.4373,0,0,0,0,0,0,0,0,0,0,4.8761,5.5904,2.9181,2.9181,586.1371,46.184,34.6994,11.4846,1.02,1.331,8319.043,5.6723,578.4807,38.5276,5.7423,0,53.8313,40.4417,0.9531,0.0206,0,0,1525243,-539.9531,0,0,0,1.53E+08,0,0,51.1738,30.3977,590.4273,576.1304,568.85,38.0322,5.5904,-3.7356,-1.9265,17.1763,619.1715,576.1304,540.1058,79.2184,36.1773,0.1526,14.5457,-3.7356,-10.8818,578.4692,38.5161,79.0658,0.4556,519.1245,37.0814,-0.0717,0.1006
1,576,576,573.4631,105020.2,560,0,0.084,560.3749,11.5403,0,0,0.0528,0.0522,0.0518,0,0,0,26.4231,0,0,100,0,0,0,0,0,0,0,0,0,0,581.7059,16463.52,42.853,2.0674,0,0,0,0,0,0,0,0,0,0,4.8725,5.9425,3.1106,3.1106,583.52,23.1451,13.0882,10.057,1.0175,1.7684,8350.185,6.0354,576.8154,16.4406,5.0285,0,-1818.501,18.1167,0.3749,0.0162,0,0,1525243,-560.3749,0,0,0,1.53E+08,0,0,51.2763,30.4659,584.6837,576.5352,561.3959,9.2651,5.9425,-3.8942,-2.1313,17.0968,587.9201,576.5352,558.1595,27.5452,16.1603,-2.2154,14.6511,-3.8942,-10.8399,574.2049,13.83,29.7606,0.6175,-12.4335,19.2547,-0.083,0.0937
1,589.4,589.4,573.8201,106260.3,562,0,0.0992,563.4901,12.646,0,0,0.0528,0.0522,0.0518,0,0,0,28.2322,0,0,100,0,0,0,0,0,0,0,0,0,0,580.6834,15010.03,41.8809,2.8485,0,0,0,0,0,0,0,0,0,0,4.9199,6.5118,3.4241,3.4241,585.6303,22.1402,10.33,11.8102,1.0206,2.1433,8401.033,6.6239,577.7568,14.2667,5.9051,0,272.9236,16.2351,1.4901,0.0673,0,0,1525243,-563.4901,0,0,0,1.53E+08,0,0,51.4569,30.6002,588.5152,576.3796,563.7505,12.6405,6.5118,-4.1076,-2.5069,16.8743,593.8276,576.3796,558.438,30.3375,12.8895,-5.0521,14.7581,-4.1076,-10.7532,576.215,12.725,35.3896,0.507,-6.0049,22.7955,-0.1027,0.0838
1,602.8,602.8,574.1317,105328.9,540,0,0.094,540.6705,12.3767,0,0,0.0528,0.0522,0.0518,0,0,0,27.8287,0,0,100,0,0,0,0,0,0,0,0,0,0,578.689,16038.56,47.079,8.4057,0,0,0,0,0,0,0,0,0,0,4.9102,6.3732,3.3475,3.3475,585.3423,44.6718,33.4612,11.2106,1.0195,1.335,8388.597,6.4805,577.8686,37.1981,5.6053,0,99.9447,39.0665,0.6705,0.015,0,0,1525243,-540.6705,0,0,0,1.53E+08,0,0,51.4013,30.5481,589.152,575.8305,567.4556,37.4038,6.3732,-4.0915,-2.3788,18.9167,617.249,575.8305,539.3586,76.5786,35.16,-1.3119,16.0709,-4.0915,-12.0765,577.4794,36.8089,77.8905,0.4682,-58.3723,36.9132,-0.0971,0.0867
1,616.2,616.2,573.4407,105766.1,563,0,0.0809,562.8051,13.2121,0,0,0.0528,0.0522,0.0518,0,0,0,29.1292,0,0,100,0,0,0,0,0,0,0,0,0,0,581.1665,15593.08,46.1556,1.6915,0,0,0,0,0,0,0,0,0,0,4.9135,6.8033,3.5857,3.5857,583.0448,20.2397,10.6356,9.6041,1.0167,1.903,8427.311,6.926,576.642,13.8369,4.8021,0,-1251.075,15.4377,-0.1949,-0.0096,0,0,1525243,-562.8051,0,0,0,1.53E+08,0,0,51.5274,30.6313,584.2179,576.3211,562.1155,7.4733,6.8033,-4.2884,-2.6275,18.6784,586.5076,576.3211,559.8258,23.7025,13.516,-2.9793,16.112,-4.2884,-11.9362,574.2182,11.4131,26.6818,0.6182,-7.9557,17.0341,-0.1126,0.0804
1,629.6,629.6,573.8736,106975.6,560,0,0.1013,562.7878,14.2471,0,0,0.0528,0.0522,0.0518,0,0,0,30.8105,0,0,100,0,0,0,0,0,0,0,0,0,0,580.5682,14168.75,46.0781,3.4089,0,0,0,0,0,0,0,0,0,0,4.9653,7.3363,3.8832,3.8832,585.8219,23.0341,11.0858,11.9483,1.0208,2.0778,8475.784,7.4797,577.8564,15.0686,5.9742,0,231.0682,17.06,2.7878,0.121,0,0,1525243,-562.7878,0,0,0,1.53E+08,0,0,51.6997,30.7602,588.8796,576.3708,564.0392,14.9213,7.3363,-4.4867,-2.9831,18.8218,595.8734,576.3708,557.0453,33.0856,13.583,-5.7425,16.4508,-4.4867,-12.0976,576.4298,13.642,38.8281,0.4977,-5.7615,25.1133,-0.1335,0.0735
1,643,643,574.1238,105993.4,541,0,0.0956,541.4627,13.9298,0,0,0.0528,0.0522,0.0518,0,0,0,30.2929,0,0,100,0,0,0,0,0,0,0,0,0,0,578.7538,15229.82,51.0291,8.2881,0,0,0,0,0,0,0,0,0,0,4.9532,7.1729,3.7917,3.7917,585.4248,43.9621,32.6611,11.301,1.0197,1.346,8460.864,7.3097,577.8908,36.4281,5.6505,0,102.5199,38.3116,0.4627,0.0105,0,0,1525243,-541.4627,0,0,0,1.53E+08,0,0,51.6361,30.7026,589.2464,575.8502,567.3331,36.3938,7.1729,-4.4594,-2.8403,20.778,616.2971,575.8502,540.2825,74.8344,34.3875,-1.1802,17.6882,-4.4594,-13.3556,577.4766,36.0139,76.0146,0.4679,-63.4082,36.6226,-0.1268,0.076
1,656.4,656.4,573.5052,106547.8,564,0,0.0763,564.8625,15.0119,0,0,0.0528,0.0522,0.0518,0,0,0,31.9959,0,0,100,0,0,0,0,0,0,0,0,0,0,581.2581,14622.41,49.4915,1.3895,0,0,0,0,0,0,0,0,0,0,4.958,7.7301,4.1046,4.1046,582.4747,17.6122,8.6427,8.9695,1.0156,2.0378,8511.958,7.8898,576.4951,11.6326,4.4848,0,-28926.48,13.1275,0.8625,0.049,0,0,1525243,-564.8625,0,0,0,1.53E+08,0,0,51.8022,30.8127,583.2663,576.3968,562.1238,6.0447,7.7301,-4.7143,-3.1652,20.341,584.8725,576.3968,560.5176,20.01,11.5343,-4.3449,17.6628,-4.7143,-13.0979,573.929,9.0665,24.3549,0.652,-4.6054,14.8806,-0.1494,0.0698
1,669.8,669.8,574.0743,107731.4,560,0,0.1018,561.7415,15.9931,0,0,0.0528,0.0522,0.0518,0,0,0,33.6085,0,0,100,0,0,0,0,0,0,0,0,0,0,580.0686,13282.96,50.4497,3.8881,0,0,0,0,0,0,0,0,0,0,5.0152,8.2354,4.3908,4.3908,585.968,24.2265,12.3328,11.8937,1.0207,1.9644,8558.829,8.4175,578.0389,16.2974,5.9469,0,147.306,18.2797,1.7415,0.0719,0,0,1525243,-561.7415,0,0,0,1.53E+08,0,0,51.9676,30.9361,589.3687,576.3111,565.257,16.7641,8.2354,-4.9046,-3.5025,20.9206,597.9618,576.3111,556.6639,36.2203,14.5696,-5.0776,18.2812,-4.9046,-13.5483,576.9789,15.2374,41.2979,0.4757,-7.1334,27.1392,-0.1717,0.0649
1,683.2,683.2,574.0787,106809.6,541,0,0.0932,542.5741,15.8616,0,0,0.0528,0.0522,0.0518,0,0,0,33.3923,0,0,100,0,0,0,0,0,0,0,0,0,0,579.103,14305.16,55.0766,8.1153,0,0,0,0,0,0,0,0,0,0,5.003,8.1677,4.3524,4.3524,584.9738,42.3997,31.5046,10.8951,1.019,1.3458,8552.52,8.3467,577.7104,35.1363,5.4476,0,112.5735,36.9522,1.5741,0.0371,0,0,1525243,-542.5741,0,0,0,1.53E+08,0,0,51.9309,30.8952,588.3533,575.9528,566.6994,35.0473,8.1677,-4.9235,-3.4121,22.8022,614.2079,575.9528,540.8448,71.6338,33.3787,-1.7293,19.5094,-4.9235,-14.7538,577.0018,34.4277,73.3631,0.4786,-41.4236,36.4164,-0.1679,0.0659
1,696.6,696.6,573.3973,107862.5,565,0,0.0764,566.0041,17.0843,0,0,0.0528,0.0522,0.0518,0,0,0,35.3265,0,0,100,0,0,0,0,0,0,0,0,0,0,581.1401,13079.27,52.6298,1.0898,0,0,0,0,0,0,0,0,0,0,5.0142,8.7973,4.7119,4.7119,582.2639,16.2598,7.3932,8.8666,1.0155,2.1993,8611.56,9.0061,576.3528,10.3487,4.4333,0,-790.3696,11.8265,1.0041,0.0618,0,0,1525243,-566.0041,0,0,0,1.53E+08,0,0,52.131,31.0372,583.0079,576.2868,562.0046,4.6553,8.7973,-5.1854,-3.8094,22.0289,583.9935,576.2868,561.019,17.9894,10.2827,-4.9851,19.2978,-5.1854,-14.3099,573.7664,7.7623,22.9745,0.6646,-3.6086,11.9537,-0.1975,0.0605
1,710,710,574.0804,109228.6,559,0,0.1015,560.2715,17.8768,0,0,0.0528,0.0522,0.0518,0,0,0,36.653,0,0,100,0,0,0,0,0,0,0,0,0,0,580.2195,11427.92,54.8744,4.4179,0,0,0,0,0,0,0,0,0,0,5.0674,9.2054,4.947,4.947,585.8085,25.537,13.8089,11.7281,1.0204,1.8493,8650.267,9.4349,577.9897,17.7182,5.8641,0,143.1657,19.673,1.2715,0.0498,0,0,1525243,-560.2715,0,0,0,1.53E+08,0,0,52.2765,31.1547,589.033,576.3729,565.0252,18.7296,9.2054,-5.3111,-4.1126,23.1429,599.2753,576.3729,554.783,39.0039,16.1014,-5.4885,20.2139,-5.3111,-15.1211,576.8104,16.5389,44.4924,0.4852,-7.1065,28.672,-0.2183,0.0574
1,723.4,723.4,574.123,108529.5,542,0,0.0936,543.5371,17.823,0,0,0.0528,0.0522,0.0518,0,0,0,36.5805,0,0,100,0,0,0,0,0,0,0,0,0,0,579.1175,12187.28,59.0929,7.8842,0,0,0,0,0,0,0,0,0,0,5.0584,9.1777,4.931,4.931,584.9466,41.4095,30.5859,10.8236,1.0189,1.3539,8647.628,9.4058,577.7309,34.1938,5.4118,0,106.0263,35.9977,1.5371,0.0371,0,0,1525243,-543.5371,0,0,0,1.53E+08,0,0,52.2555,31.128,588.288,575.9875,566.7643,33.4529,9.1777,-5.3366,-4.0578,24.901,612.6675,575.9875,542.3848,69.1304,32.4504,-1.1523,21.3702,-5.3366,-16.2503,577.0132,33.4762,70.2827,0.4781,-59.9934,36.0835,-0.2167,0.0578
1,736.8,736.8,573.3673,109727.5,565,0,0.0781,566.5403,19.2294,0,0,0.0528,0.0522,0.0518,0,0,0,38.8572,0,0,100,0,0,0,0,0,0,0,0,0,0,581.071,10776.75,55.643,0.824,0,0,0,0,0,0,0,0,0,0,5.0762,9.9019,5.3519,5.3519,582.3242,15.7839,6.827,8.9569,1.0156,2.312,8717.138,10.1692,576.353,9.8127,4.4785,0,-626.034,11.3055,1.5403,0.0976,0,0,1525243,-566.5403,0,0,0,1.53E+08,0,0,52.4895,31.2939,583.118,576.2447,561.9933,3.4521,9.9019,-5.6408,-4.5157,23.7475,583.6678,576.2447,561.4435,17.1275,9.7044,-5.0968,20.9671,-5.6408,-15.5809,573.7853,7.245,22.2243,0.666,-3.3604,9.0495,-0.2546,0.053
1,750.2,750.2,573.9628,111097.2,559,0,0.1029,558.967,19.8417,0,0,0.0528,0.0522,0.0518,0,0,0,39.9386,0,0,100,0,0,0,0,0,0,0,0,0,0,579.8731,9150.968,59.3311,4.9351,0,0,0,0,0,0,0,0,0,0,5.1238,10.2171,5.5366,5.5366,585.7284,26.7614,14.9959,11.7656,1.0205,1.7846,8747.74,10.5025,577.8847,18.9177,5.8828,0,177.3131,20.8787,-0.033,-0.0012,0,0,1525243,-558.967,0,0,0,1.53E+08,0,0,52.6097,31.396,589.0735,576.1717,565.2157,20.5498,10.2171,-5.7213,-4.7684,25.476,600.9058,576.1717,553.3834,41.9388,17.2047,-5.5836,22.2347,-5.7213,-16.786,576.8203,17.8533,47.5224,0.4795,-7.5111,29.9327,-0.2726,0.0511
1,763.6,763.6,574.0379,110427,545,0,0.0952,544.9581,19.8724,0,0,0.0528,0.0522,0.0518,0,0,0,39.9456,0,0,100,0,0,0,0,0,0,0,0,0,0,579.5471,9864.397,63.1374,7.5625,0,0,0,0,0,0,0,0,0,0,5.1176,10.233,5.546,5.546,584.916,39.9579,29.0798,10.8781,1.019,1.3741,8749.29,10.5193,577.6639,32.7058,5.4391,0,125.7385,34.5189,-0.0419,-0.001,0,0,1525243,-544.9581,0,0,0,1.53E+08,0,0,52.6021,31.3781,587.996,576.0964,565.8929,31.4931,10.233,-5.7671,-4.7395,27.1078,610.3204,576.0964,543.5685,65.3622,31.1382,-1.3896,23.3249,-5.7671,-17.8314,576.6617,31.7036,66.7518,0.4873,-47.0367,35.3315,-0.2736,0.0512
1,777,777,573.5278,111931.9,565,0,0.0809,566.5242,21.4028,0,0,0.0528,0.0522,0.0518,0,0,0,42.3943,0,0,100,0,0,0,0,0,0,0,0,0,0,580.812,8107.392,58.621,0.4997,0,0,0,0,0,0,0,0,0,0,5.1433,11.021,6.0123,6.0123,582.6931,16.169,7.0036,9.1653,1.016,2.3087,8826.773,11.3555,576.5829,10.0587,4.5827,0,4500.382,11.5863,1.5242,0.0943,0,0,1525243,-566.5242,0,0,0,1.53E+08,0,0,52.8651,31.568,583.8116,576.2512,562.7306,2.0518,11.021,-6.0905,-5.2504,25.5265,584.0095,576.2512,562.5328,17.4854,9.7271,-3.9914,22.6841,-6.0905,-16.9135,574.2645,7.7404,21.4768,0.6388,-4.3808,5.5077,-0.3199,0.0471
1,790.4,790.4,574.3225,113489.2,557,0,0.1019,557.8371,21.8361,0,0,0.0528,0.0522,0.0518,0,0,0,43.1318,0,0,100,0,0,0,0,0,0,0,0,0,0,579.7739,6212.065,63.7199,5.4523,0,0,0,0,0,0,0,0,0,0,5.1841,11.2441,6.1454,6.1454,585.8428,28.0057,16.4854,11.5203,1.0201,1.6988,8848.961,11.593,578.1626,20.3255,5.7602,0,97.6086,22.2456,0.8371,0.0299,0,0,1525243,-557.8371,0,0,0,1.53E+08,0,0,52.9645,31.663,589.2837,576.3621,566.2194,22.2818,11.2441,-6.1099,-5.4681,27.8781,602.8408,576.3621,552.6624,45.0037,18.525,-5.1747,24.2987,-6.1099,-18.5227,577.2884,19.4513,50.1784,0.4723,-8.6969,31.3179,-0.3339,0.0459
1,803.8,803.8,573.9194,113109,547,0,0.0932,546.5825,21.9411,0,0,0.0528,0.0522,0.0518,0,0,0,43.2626,0,0,100,0,0,0,0,0,0,0,0,0,0,579.6493,6579.182,67.0725,7.2098,0,0,0,0,0,0,0,0,0,0,5.1749,11.2982,6.1778,6.1778,584.4466,37.8641,27.3369,10.5272,1.0183,1.3851,8854.358,11.6507,577.4285,30.846,5.2636,0,165.9342,32.6005,-0.4175,-0.011,0,0,1525243,-546.5825,0,0,0,1.53E+08,0,0,52.9742,31.6619,587.1817,576.0629,565.4069,29.4427,11.2982,-6.1575,-5.4777,29.3663,607.6855,576.0629,544.9031,61.103,29.4804,-1.6794,25.3055,-6.1575,-19.485,576.2172,29.6347,62.7824,0.4963,-36.3838,34.8532,-0.337,0.0458
1,817.2,817.2,573.6907,114743.9,565,0,0.0883,566.414,23.515,0,0,0.0528,0.0522,0.0518,0,0,0,45.7554,0,0,100,0,0,0,0,0,0,0,0,0,0,580.7349,4624.372,62.1033,0.3776,0,0,0,0,0,0,0,0,0,0,5.2148,12.1087,6.6663,6.6663,583.5714,17.1574,7.2767,9.8807,1.0172,2.3579,8936.01,12.5167,576.9843,10.5703,4.9404,0,482.5477,12.2171,1.414,0.0824,0,0,1525243,-566.414,0,0,0,1.53E+08,0,0,53.2522,31.8648,585.2013,576.3278,563.1956,1.5194,12.1087,-6.487,-6.0117,27.5949,585.3057,576.3278,563.0912,18.8917,9.9138,-3.3228,24.5619,-6.487,-18.4649,574.9083,8.4942,22.2145,0.5959,-5.6855,3.9312,-0.39,0.0423
1,830.6,830.6,574.1197,116267,557,0,0.1009,556.3069,23.8298,0,0,0.0528,0.0522,0.0518,0,0,0,46.2782,0,0,100,0,0,0,0,0,0,0,0,0,0,579.8507,2730.948,68.0011,5.9247,0,0,0,0,0,0,0,0,0,0,5.2407,12.2708,6.7648,6.7648,585.3882,29.0813,17.8128,11.2685,1.0196,1.6326,8952.521,12.6904,577.8759,21.569,5.6343,0,127.48,23.4471,-0.6931,-0.0238,0,0,1525243,-556.3069,0,0,0,1.53E+08,0,0,53.3346,31.9497,588.5223,576.2667,565.5573,23.7516,12.2708,-6.4761,-6.1961,30.3282,603.4213,576.2667,550.6583,47.1144,19.9598,-5.6486,26.3859,-6.4761,-20.3112,576.7821,20.4752,52.763,0.4853,-8.3409,32.0995,-0.4014,0.0416
1,844,844,573.7474,115966.6,548,0,0.0934,547.9941,24.0065,0,0,0.0528,0.0522,0.0518,0,0,0,46.5693,0,0,100,0,0,0,0,0,0,0,0,0,0,580.0341,3012.138,70.8909,6.7982,0,0,0,0,0,0,0,0,0,0,5.2352,12.3617,6.8201,6.8201,584.1679,36.1738,25.7533,10.4205,1.0182,1.4046,8961.807,12.7879,577.2209,29.2268,5.2103,0,291.1522,30.9636,-0.0059,-0.0002,0,0,1525243,-547.9941,0,0,0,1.53E+08,0,0,53.3573,31.958,586.5148,576.1024,564.3587,27.2149,12.3617,-6.539,-6.2302,31.6618,604.82,576.1024,546.0535,56.8259,28.1083,-1.9406,27.3072,-6.539,-21.1757,575.6586,27.6645,58.7665,0.5113,-29.2826,33.9254,-0.4075,0.0414
1,857.4,857.4,573.5988,117816.6,565,0,0.0905,565.9739,25.5473,0,0,0.0528,0.0522,0.0518,0,0,0,49.1031,0,0,100,0,0,0,0,0,0,0,0,0,0,581.379,789.6085,65.8301,0.3281,0,0,0,0,0,0,0,0,0,0,5.2779,13.1551,7.3069,7.3069,583.601,17.6271,7.6249,10.0022,1.0174,2.3118,9043.68,13.6413,576.9329,10.9591,5.0011,0,966.7384,12.626,0.9739,0.0553,0,0,1525243,-565.9739,0,0,0,1.53E+08,0,0,53.6396,32.1689,584.8646,576.5156,561.942,1.2942,13.1551,-6.8498,-6.7691,29.8386,584.9374,576.5156,561.8692,18.9635,10.5418,-4.1047,26.5257,-6.8498,-20.1397,574.4407,8.4669,23.0682,0.6349,-4.6199,3.2212,-0.4638,0.0386
1,870.8,870.8,574.1946,119404.6,550,0,0.1002,555.0204,25.7758,0,0,0.0528,0.0522,0.0518,0,0,0,49.5595,0,0,100,0,0,0,0,0,0,0,0,0,0,579.3533,-1171.438,72.08,6.3795,0,0,0,0,0,0,0,0,0,0,5.3001,13.2728,7.3797,7.3797,585.2613,30.2409,19.1742,11.0667,1.0193,1.5772,9055.954,13.7683,577.8835,22.8631,5.5334,0,111.697,24.7076,5.0204,0.166,0,0,1525243,-555.0204,0,0,0,1.53E+08,0,0,53.7105,32.2483,588.575,576.1299,566.4433,25.0888,13.2728,-6.8129,-6.9322,32.7703,604.93,576.1299,550.0883,49.9096,21.1095,-4.9321,28.4489,-6.8129,-22.1083,577.0494,22.029,54.8417,0.4749,-10.1193,33.0996,-0.4723,0.0381
1,884.2,884.2,573.7579,119377.8,550,0,0.0933,549.5468,26.0156,0,0,0.0528,0.0522,0.0518,0,0,0,49.9428,0,0,100,0,0,0,0,0,0,0,0,0,0,580.5428,-1235.249,74.5044,6.3805,0,0,0,0,0,0,0,0,0,0,5.2966,13.3963,7.4563,7.4563,584.042,34.4952,24.2111,10.2841,1.0179,1.4248,9068.868,13.9017,577.1859,27.6391,5.1421,0,285.1297,29.3532,-0.4532,-0.0131,0,0,1525243,-549.5468,0,0,0,1.53E+08,0,0,53.7499,32.2731,586.0077,576.3033,563.5623,25.0383,13.3963,-6.8763,-7.0016,33.946,602.2234,576.3033,547.3466,52.6766,26.7565,-2.2002,29.2777,-6.8763,-22.883,575.2911,25.7443,54.8768,0.5277,-23.9417,32.9285,-0.4816,0.0378
1,897.6,897.6,573.7579,121526.2,565,0,0.0919,566.2725,27.5056,0,0,0.0528,0.0522,0.0518,0,0,0,52.3877,0,0,100,0,0,0,0,0,0,0,0,0,0,581.2822,-3854.873,69.534,0.3666,0,0,0,0,0,0,0,0,0,0,5.3417,14.1635,7.9354,7.9354,583.7972,17.5247,7.4854,10.0393,1.0175,2.3412,9149.925,14.7326,577.1043,10.8318,5.0197,0,352.1143,12.5051,1.2725,0.0726,0,0,1525243,-566.2725,0,0,0,1.53E+08,0,0,54.0359,32.4941,585.1891,576.5834,562.408,1.4177,14.1635,-7.1573,-7.5465,32.1492,585.277,576.5834,562.3202,19.0045,10.3109,-3.9523,28.5001,-7.1573,-21.8831,574.7269,8.4544,22.9568,0.6213,-4.8085,3.5474,-0.5403,0.0355
1,911,911,573.9092,123153.4,547,0,0.0994,553.8277,27.6734,0,0,0.0528,0.0522,0.0518,0,0,0,52.6938,0,0,100,0,0,0,0,0,0,0,0,0,0,579.5742,-5904.204,75.9459,6.8142,0,0,0,0,0,0,0,0,0,0,5.3559,14.2499,7.9898,7.9898,584.7599,30.9322,20.0815,10.8507,1.0189,1.5403,9159.144,14.8265,577.5261,23.6984,5.4254,0,188.2197,25.5069,6.8277,0.2207,0,0,1525243,-553.8277,0,0,0,1.53E+08,0,0,54.0993,32.5706,587.6454,576.0381,565.3386,26.2845,14.2499,-7.1008,-7.6958,35.2028,605.045,576.0381,547.939,51.2173,22.2104,-5.8887,30.4804,-7.1008,-23.9263,576.3406,22.513,57.106,0.4921,-8.6976,33.5034,-0.5467,0.0351
1,924.4,924.4,573.8628,123284.7,554,0,0.0924,551.3943,27.9766,0,0,0.0528,0.0522,0.0518,0,0,0,53.1715,0,0,100,0,0,0,0,0,0,0,0,0,0,580.533,-6153.53,77.9522,5.9196,0,0,0,0,0,0,0,0,0,0,5.3581,14.4061,8.0883,8.0883,583.9345,32.5402,22.4685,10.0717,1.0176,1.4483,9175.858,14.9963,577.22,25.8257,5.0359,0,205.9784,27.5044,-2.6057,-0.0801,0,0,1525243,-551.3943,0,0,0,1.53E+08,0,0,54.153,32.6077,585.803,576.3698,563.7678,22.7686,14.4061,-7.1723,-7.7924,36.2363,600.0796,576.3698,549.4912,48.6853,24.9755,-1.9031,31.2305,-7.1723,-24.6168,575.3135,23.9192,50.5884,0.5313,-25.5821,32.089,-0.5586,0.0348
1,937.8,937.8,573.7535,125553.4,565,0,0.0936,566.2382,29.4322,0,0,0.0528,0.0522,0.0518,0,0,0,55.5997,0,0,100,0,0,0,0,0,0,0,0,0,0,581.232,-8913.139,73.1014,0.3806,0,0,0,0,0,0,0,0,0,0,5.4048,15.1556,8.5646,8.5646,583.8662,17.628,7.5153,10.1127,1.0176,2.3456,9256.916,15.8135,577.1244,10.8862,5.0564,0,358.2825,12.5717,1.2382,0.0702,0,0,1525243,-566.2382,0,0,0,1.53E+08,0,0,54.4407,32.8327,585.2775,576.5669,562.3901,1.4427,15.1556,-7.4417,-8.334,34.48,585.3681,576.5669,562.2995,19.1299,10.3287,-3.9387,30.4732,-7.4417,-23.6516,574.7449,8.5066,23.0686,0.6185,-4.8569,3.5927,-0.6201,0.0328
1,951.2,951.2,573.9877,127204.9,550,0,0.1,552.622,29.5778,0,0,0.0528,0.0522,0.0518,0,0,0,55.8686,0,0,100,0,0,0,0,0,0,0,0,0,0,578.989,-10995.3,79.6191,7.2203,0,0,0,0,0,0,0,0,0,0,5.4181,15.2306,8.6127,8.6127,584.7855,32.1635,21.3657,10.7979,1.0188,1.5054,9265.106,15.8955,577.587,24.965,5.399,0,154.8943,26.7646,2.622,0.0815,0,0,1525243,-552.622,0,0,0,1.53E+08,0,0,54.5017,32.9084,587.9824,575.8706,566.3655,27.3053,15.2306,-7.3787,-8.4774,37.643,606.5406,575.8706,547.8073,53.9186,23.2486,-4.8147,32.5145,-7.3787,-25.7613,576.7395,24.1175,58.7333,0.4778,-11.1987,34.2022,-0.6255,0.0326
1,964.6,964.6,573.7103,127655.5,556,0,0.0921,553.5141,29.9383,0,0,0.0528,0.0522,0.0518,0,0,0,56.4202,0,0,100,0,0,0,0,0,0,0,0,0,0,580.972,-11582.81,81.2679,5.4268,0,0,0,0,0,0,0,0,0,0,5.4193,15.4162,8.7318,8.7318,583.6344,30.1203,20.1962,9.9241,1.0173,1.4914,9285.437,16.0987,577.0184,23.5043,4.9621,0,371.8193,25.1583,-2.4859,-0.0825,0,0,1525243,-553.5141,0,0,0,1.53E+08,0,0,54.5719,32.9618,585.0375,576.4448,562.6342,20.4495,15.4162,-7.4507,-8.6066,38.5603,597.1523,576.4448,550.5193,43.6382,22.9307,-2.9948,33.1995,-7.4507,-26.3899,574.7055,21.1914,46.633,0.5559,-14.5713,30.6437,-0.6411,0.0322
1,978,978,573.6487,130159.1,566,0,0.0942,566.545,31.3501,0,0,0.0528,0.0522,0.0518,0,0,0,58.7667,0,0,100,0,0,0,0,0,0,0,0,0,0,581.1574,-14637.84,76.5967,0.4826,0,0,0,0,0,0,0,0,0,0,5.467,16.1432,9.2021,9.2021,583.711,17.166,7.1037,10.0623,1.0175,2.4165,9365.937,16.8969,577.0027,10.4577,5.0312,0,627.6992,12.1349,0.545,0.0317,0,0,1525243,-566.545,0,0,0,1.53E+08,0,0,54.8624,33.1944,585.0276,576.4792,562.1457,1.7924,16.1432,-7.698,-9.1495,36.8732,585.1672,576.4792,562.0062,18.6222,9.9342,-4.5388,32.4752,-7.698,-25.4815,574.5508,8.0059,23.161,0.6249,-4.1029,4.4519,-0.7043,0.0305
1,991.4,991.4,574.2628,132054.3,550,0,0.0979,551.7565,31.4737,0,0,0.0528,0.0522,0.0518,0,0,0,59.0251,0,0,100,0,0,0,0,0,0,0,0,0,0,579.2947,-17001.46,83.1373,7.57,0,0,0,0,0,0,0,0,0,0,5.4805,16.2068,9.2435,9.2435,584.7086,32.9522,22.5064,10.4458,1.0182,1.4641,9373.046,16.9669,577.7448,25.9883,5.2229,0,97.2718,27.7293,1.7565,0.0533,0,0,1525243,-551.7565,0,0,0,1.53E+08,0,0,54.9253,33.2765,587.6648,576.1613,566.5283,28.0513,16.2068,-7.6161,-9.2989,40.1141,607.0726,576.1613,547.1205,55.3161,24.4049,-4.636,34.5539,-7.6161,-27.646,576.7848,25.0283,59.9521,0.4844,-11.9319,34.6781,-0.7082,0.0303
1,1004.8,1004.8,573.7017,132722.6,553,0,0.0918,555.2509,31.8857,0,0,0.0528,0.0522,0.0518,0,0,0,59.6869,0,0,100,0,0,0,0,0,0,0,0,0,0,580.6165,-17873.31,84.4201,4.9229,0,0,0,0,0,0,0,0,0,0,5.4828,16.419,9.3821,9.3821,583.4726,28.2217,18.4508,9.7709,1.017,1.5296,9396.843,17.2007,576.9587,21.7078,4.8855,0,397.3262,23.3363,2.2509,0.0798,0,0,1525243,-555.2509,0,0,0,1.53E+08,0,0,55.0105,33.3444,584.95,576.3113,563.0598,18.1652,16.419,-7.6899,-9.4561,40.9059,595.2126,576.3113,552.7971,39.9617,21.0604,-2.4538,35.1678,-7.6899,-28.2049,574.7737,19.5228,42.4155,0.5544,-16.2856,29.4649,-0.727,0.0299
1,1018.2,1018.2,573.5228,135402.6,566,0,0.0946,566.753,33.2317,0,0,0.0528,0.0522,0.0518,0,0,0,61.8374,0,0,100,0,0,0,0,0,0,0,0,0,0,581.3866,-21096.53,80.0066,0.7017,0,0,0,0,0,0,0,0,0,0,5.529,17.1121,9.8385,9.8385,583.5099,16.7569,6.7698,9.9871,1.0174,2.4752,9475.418,17.9671,576.8519,10.0989,4.9936,0,6034.881,11.7634,0.753,0.0449,0,0,1525243,-566.753,0,0,0,1.53E+08,0,0,55.2977,33.5786,584.5291,576.4939,561.3651,2.553,17.1121,-7.9151,-9.9873,39.3169,584.8072,576.4939,561.0871,18.0542,9.7409,-5.6659,34.4898,-7.9151,-27.365,574.1294,7.3764,23.7201,0.6495,-3.1865,6.2154,-0.7903,0.0285
1,1031.6,1031.6,574.1602,137122,551,0,0.0973,551.5094,33.3408,0,0,0.0528,0.0522,0.0518,0,0,0,62.0517,0,0,100,0,0,0,0,0,0,0,0,0,0,578.9249,-23257.02,86.477,7.8736,0,0,0,0,0,0,0,0,0,0,5.5414,17.1683,9.8757,9.8757,584.422,32.9126,22.6508,10.2618,1.0179,1.453,9481.847,18.0293,577.5808,26.0714,5.1309,0,112.1989,27.7817,0.5094,0.0155,0,0,1525243,-551.5094,0,0,0,1.53E+08,0,0,55.3551,33.6535,587.4005,575.9617,566.7714,28.5875,17.1683,-7.8409,-10.121,42.5849,607.4773,575.9617,546.6946,55.9679,24.4523,-4.8148,36.5829,-7.8409,-29.5356,576.7112,25.2018,60.7827,0.4815,-11.6241,35.0801,-0.7936,0.0284
1,1045,1045,573.4716,138014.7,558,0,0.0914,557.1605,33.7992,0,0,0.0528,0.0522,0.0518,0,0,0,62.7682,0,0,100,0,0,0,0,0,0,0,0,0,0,581.1544,-24337.07,87.4498,4.4134,0,0,0,0,0,0,0,0,0,0,5.5445,17.4043,10.0326,10.0326,583.0829,25.9224,16.3111,9.6113,1.0168,1.5892,9508.939,18.2913,576.6754,19.5149,4.8057,0,-2155.607,21.1168,-0.8395,-0.0324,0,0,1525243,-557.1605,0,0,0,1.53E+08,0,0,55.4535,33.7334,583.9772,576.3775,561.5394,15.9473,17.4043,-7.9194,-10.3007,43.2716,592.2565,576.3775,553.2601,35.096,19.217,-3.9005,37.1391,-7.9194,-30.0355,573.9647,16.8042,38.9965,0.5928,-8.9978,27.4369,-0.8158,0.0279
1,1058.4,1058.4,573.4662,140609.5,566,0,0.0925,567.0615,35.1003,0,0,0.0528,0.0522,0.0518,0,0,0,64.9054,0,0,100,0,0,0,0,0,0,0,0,0,0,581.5361,-27508.75,83.2713,0.9272,0,0,0,0,0,0,0,0,0,0,5.5902,18.0743,10.4816,10.4816,583.1201,16.0586,6.4047,9.6539,1.0168,2.5073,9586.705,19.0373,576.6841,9.6226,4.827,0,-2112.539,11.2317,1.0615,0.0661,0,0,1525243,-567.0615,0,0,0,1.53E+08,0,0,55.7367,33.9646,583.7757,576.5218,560.8771,3.3045,18.0743,-8.1393,-10.8151,41.7751,584.243,576.5218,560.4098,17.1815,9.4603,-6.6517,36.5117,-8.1393,-29.2525,573.7249,6.6634,23.8332,0.676,-2.583,8.0496,-0.8801,0.0268
1,1071.8,1071.8,574.0817,142202.1,549,0,0.0976,550.4504,35.2005,0,0,0.0528,0.0522,0.0518,0,0,0,65.106,0,0,100,0,0,0,0,0,0,0,0,0,0,578.97,-29525.33,89.7148,8.1371,0,0,0,0,0,0,0,0,0,0,5.6046,18.1259,10.5164,10.5164,584.2539,33.8035,23.6314,10.1722,1.0177,1.4304,9592.747,19.0949,577.4725,27.0221,5.0861,0,125.7071,28.7175,1.4504,0.0429,0,0,1525243,-550.4504,0,0,0,1.53E+08,0,0,55.7904,34.0346,587.0817,575.9339,566.4346,28.9448,18.1259,-8.0705,-10.9379,45.0945,607.4889,575.9339,546.0275,57.0385,25.4835,-4.4229,38.6359,-8.0705,-31.4479,576.4835,26.033,61.4614,0.4866,-12.8962,35.1852,-0.8825,0.0266
1,1085.2,1085.2,573.429,143237.4,557,0,0.0896,559.0724,35.7157,0,0,0.0528,0.0522,0.0518,0,0,0,65.9068,0,0,100,0,0,0,0,0,0,0,0,0,0,581.1237,-30861.4,90.3546,3.9027,0,0,0,0,0,0,0,0,0,0,5.6082,18.3912,10.6959,10.6959,582.7348,23.6624,14.3566,9.3058,1.0162,1.6482,9623.932,19.3914,576.5309,17.4585,4.6529,0,-1019.686,19.0095,2.0724,0.0876,0,0,1525243,-559.0724,0,0,0,1.53E+08,0,0,55.905,34.1292,583.4046,576.3459,561.3691,13.806,18.3912,-8.1549,-11.1449,45.6673,590.0503,576.3459,554.7234,30.9779,17.2735,-4.349,39.1316,-8.1549,-31.8853,573.7065,14.6341,35.3269,0.6121,-7.123,25.7043,-0.9086,0.0262
1,1098.6,1098.6,573.4772,146027.8,566,0,0.0902,567.1692,36.9794,0,0,0.0528,0.0522,0.0518,0,0,0,67.962,0,0,100,0,0,0,0,0,0,0,0,0,0,581.2485,-34273.7,86.4154,1.2168,0,0,0,0,0,0,0,0,0,0,5.6537,19.0419,11.1399,11.1399,582.7785,15.6093,6.308,9.3013,1.0162,2.4745,9701.284,20.1212,576.5776,9.4084,4.6507,0,-2864.548,10.9587,1.1692,0.0749,0,0,1525243,-567.1692,0,0,0,1.53E+08,0,0,56.1908,34.3668,583.3607,576.4264,561.2395,4.2461,19.0419,-8.3578,-11.6584,44.2773,584.1478,576.4264,560.4525,16.9786,9.2572,-6.7167,38.561,-8.3578,-31.1775,573.6756,6.5064,23.6953,0.6741,-2.5278,10.5007,-0.9743,0.0252
1,1112,1112,574.2361,147694.8,549,0,0.0959,549.9396,37.0822,0,0,0.0528,0.0522,0.0518,0,0,0,68.1733,0,0,100,0,0,0,0,0,0,0,0,0,0,578.9205,-36356.83,92.7656,8.2976,0,0,0,0,0,0,0,0,0,0,5.6704,19.0949,11.1763,11.1763,584.1173,34.1777,24.2965,9.8812,1.0172,1.4067,9707.639,20.1808,577.5298,27.5902,4.9406,0,98.3482,29.2371,0.9396,0.0275,0,0,1525243,-549.9396,0,0,0,1.53E+08,0,0,56.2467,34.4394,586.8623,576.0151,566.8382,28.8973,19.0949,-8.2876,-11.7836,47.6257,607.4328,576.0151,546.2676,57.4932,26.0755,-3.672,40.7026,-8.2876,-33.3913,576.5718,26.6322,61.1652,0.4863,-15.6572,35.4452,-0.9763,0.0251
1,1125.4,1125.4,573.5108,149045.1,561,0,0.0894,561.2607,37.6462,0,0,0.0528,0.0522,0.0518,0,0,0,69.0528,0,0,100,0,0,0,0,0,0,0,0,0,0,581.3115,-38006.32,93.0819,3.4009,0,0,0,0,0,0,0,0,0,0,5.6769,19.3853,11.3763,11.3763,582.6878,21.4271,12.2501,9.177,1.016,1.7491,9742.609,20.5077,576.5698,15.3091,4.5885,0,31590.36,16.8386,0.2607,0.0122,0,0,1525243,-561.2607,0,0,0,1.53E+08,0,0,56.3777,34.5499,583.157,576.4749,561.1635,11.7709,19.3853,-8.3737,-12.0179,48.0849,588.2687,576.4749,556.0518,27.008,15.2142,-5.2089,41.1353,-8.3737,-33.7679,573.5984,12.3378,32.2169,0.6339,-5.185,23.4737,-1.0063,0.0247
1,1138.8,1138.8,573.5729,151967.1,566,0,0.0914,567.5786,38.8567,0,0,0.0528,0.0522,0.0518,0,0,0,71.0294,0,0,100,0,0,0,0,0,0,0,0,0,0,581.3822,-41663.13,89.568,1.5567,0,0,0,0,0,0,0,0,0,0,5.723,20.0086,11.8094,11.8094,582.8778,15.2992,5.9943,9.3049,1.0162,2.5523,9818.524,21.212,576.6745,9.0959,4.6525,0,1379.15,10.6468,1.5786,0.1032,0,0,1525243,-567.5786,0,0,0,1.53E+08,0,0,56.6631,34.7921,583.392,576.5438,561.1499,5.3162,20.0086,-8.5547,-12.5255,46.894,584.5974,576.5438,559.9446,17.0188,8.9652,-7.634,40.6758,-8.5547,-33.1927,573.6953,6.1167,24.6528,0.6733,-2.2293,12.7746,-1.0716,0.0238
1,1145,1145,573.8952,151968.7,556,0,0.0912,558.3708,38.5351,0,0,0.0528,0.0522,0.0518,0,0,0,70.521,0,0,100,0,0,0,0,0,0,0,0,0,0,581.1237,-41690.45,94.747,4.4025,0,0,0,0,0,0,0,0,0,0,5.7144,19.843,11.6939,11.6939,583.2068,24.836,15.5244,9.3116,1.0162,1.5998,9798.239,21.0246,576.9991,18.6283,4.6558,0,206.7556,20.1802,2.3708,0.0955,0,0,1525243,-558.3708,0,0,0,1.53E+08,0,0,56.605,34.757,584.0639,576.6451,562.3957,15.0812,19.843,-8.4584,-12.4362,49.4525,591.7991,576.6451,554.6605,33.4283,18.2743,-3.7103,42.2165,-8.4584,-34.8097,574.3682,15.9974,37.1386,0.592,-9.0096,27.1536,-1.0516,0.024