File: datas/d100-0-0.25.csv
Stage Number,Time since start of test (s),Time since start of stage (s),Radial Pressure (kPa),Radial Volume (mm3),Back Pressure (kPa),Back Volume (mm3),Load Cell (kN),Pore Pressure (kPa),Axial Displacement (mm),L/C Pressure (kPa),L/C Volume (mm3),Local Axial 1,Local Axial 2,Local Radial,Base Pressure (kPa),Base Volume (mm3),Back Differential Pressure (kPa),Axial Displacement 2 (mm),Pore Air Pressure (kPa),Pore Air Volume (mm3),Atmospheric Pressure (kPa),Temperature (°C),Mid Plane PWP (kPa),Back to Cell Differential (kPa),Total Volume Change (mm3),Undefined Tx 1,Undefined Tx 2,Undefined Tx 3,Undefined Tx. 4,HCA secondary control axial load (kN),HCA secondary control torque,Internal Cell Pr. (kPa),Internal Cell Vol. (mm3),Rotational Displ. (mm),Torque,Local Int Defmn 1 (mm),Local Int Defmn 2 (mm),Circumf. Defmn 1 (mm),Circumf. Defmn 2 (mm),Circumf. Defmn 3 (mm),Outer Cell Pr 2 (kPa),Internal cell Pr 2 (kPa),Rotation 2 (°),Secondary Cell Pr (kPa),Secondary Back Pr (kPa),Axial Force (kN),Axial Strain (%),Av Diameter Change (mm),Radial Strain (%),Axial Stress (kPa),Eff. Axial Stress (kPa),Eff. Radial Stress (kPa),Deviator Stress (kPa),Total Stress Ratio (%),Eff. Stress Ratio (%),Current Area (mm2),Shear Strain (%),Cambridge p (kPa),Eff. Cambridge p' (kPa),Max Shear Stress t,Volume Change (mm3),B Value,Mean Stress s/Eff. Axial Stress 2,Excess PWP (kPa),PWP Ratio,Lower Chamber Displacement (mm),Lower Chamber Axial Load (kPa),Specimen Air Volume (mm3),Matric Suction (kPa),Voids ratio,Degree of Saturation (°),Specimen Water Volume (mm3),kRT constant,Permeability IN,Permeability OUT,HCA Outer Rad,HCA Inner Rad,HCA Sigma Z (kPa),HCA Sigma R (kPa),HCA Sigma Theta (kPa),HCA Tau Theta Z,HCA Ez,HCA Er,HCA Etheta,HCA Gamma,HCA Sigma1,HCA Sigma2,HCA Sigma3,HCA Eff Sigma1,HCA Eff Sigma2,HCA Eff Sigma3,HCA E1,HCA E2,HCA E3,HCA P,HCA Eff P,HCA Q,HCA B,HCA Eff R,HCA Alpha,HCA Ev,HCA E1 rtv
1,0,0,594.23,94722.48,499,0,0.1867,498.2683,0.006,0,0,0.0528,0.0522,0.0518,0,0,0,0.52,0,0,100,0,0,0,0,0,0,0,0,0,0,608.6875,-9124.05,0.0034,0.1589,0,0,0,0,0,0,0,0,0,0,4.8539,0.003,0.0015,0.0015,617.9997,119.7314,95.9617,23.7697,1.04,1.2477,7854.21,0.003,602.1533,103.885,11.8849,0,-0.2523,107.8465,-0.7317,-0.0061,0,0,1551318,-498.2683,0,0,0,1.55E+08,0,0,50.1475,30.2445,623.1066,599.6691,572.2603,0.7707,0.003,0.4874,-0.4876,0.0012,623.1183,599.6691,572.2487,124.85,101.4008,73.9804,0.003,0.4874,-0.4876,598.3454,100.0771,50.8696,0.539,1.6876,0.8682,0.0028,0.0012
1,2.8,2.8,594.65,94844.25,500,0,0.1865,500.2346,0.0296,0,0,0.0528,0.0522,0.0518,0,0,0,0.5559,0,0,100,0,0,0,0,0,0,0,0,0,0,608.4381,-9164.738,0.3409,5.0551,0,0,0,0,0,0,0,0,0,0,4.8576,0.015,0.0075,0.0075,618.3966,118.162,94.4154,23.7466,1.0399,1.2515,7855.153,0.015,602.5656,102.331,11.8733,0,10.1083,106.2887,0.2346,0.002,0,0,1551318,-500.2346,0,0,0,1.55E+08,0,0,50.1512,30.2474,623.8644,599.8374,573.6965,24.5129,0.015,0.4833,-0.4958,0.1236,633.853,599.8374,563.7078,133.6184,99.6028,63.4732,0.0295,0.4833,-0.5103,599.1328,98.8981,70.1452,0.5151,2.1051,22.1702,0.0025,0.1204
1,5.8,5.8,594.9,94942.96,502,0,0.1863,501.9043,0.044,0,0,0.0528,0.0522,0.0518,0,0,0,0.602,0,0,100,0,0,0,0,0,0,0,0,0,0,608.3349,-9253,-0.0405,-2.4782,0,0,0,0,0,0,0,0,0,0,4.8597,0.0223,0.0112,0.0112,618.6188,116.7145,92.9957,23.7188,1.0399,1.2551,7855.727,0.0223,602.8063,100.902,11.8594,0,8.2031,104.8551,-0.0957,-0.0008,0,0,1551318,-501.9043,0,0,0,1.55E+08,0,0,50.1545,30.2509,624.2726,599.9547,574.4808,-12.0153,0.0223,0.4843,-0.5042,-0.0147,627.0204,599.9547,571.733,125.1161,98.0504,69.8287,0.0225,0.4843,-0.5044,599.5693,97.6651,55.2874,0.5105,1.7918,-12.8815,0.0024,-0.014
1,8.8,8.8,595.03,95105.01,507,0,0.1881,506.0442,0.1038,0,0,0.0528,0.0522,0.0518,0,0,0,0.6923,0,0,100,0,0,0,0,0,0,0,0,0,0,608.8084,-9381.322,-0.341,-3.5374,0,0,0,0,0,0,0,0,0,0,4.8639,0.0526,0.0263,0.0263,618.9658,112.9216,88.9858,23.9358,1.0402,1.269,7858.108,0.0526,603.0086,96.9644,11.9679,0,13.502,100.9537,-0.9558,-0.0085,0,0,1551318,-506.0442,0,0,0,1.55E+08,0,0,50.1641,30.2589,624.5512,600.2141,574.0848,-17.1419,0.0526,0.4763,-0.526,-0.1237,629.8231,600.2141,568.8129,123.7789,94.1699,62.7687,0.0655,0.4763,-0.5389,599.6167,93.5725,61.0102,0.5147,1.972,-17.0949,0.0029,-0.1064
1,11.8,11.8,594.95,95259.73,508,0,0.1857,508.1909,0.1298,0,0,0.0528,0.0522,0.0518,0,0,0,0.7471,0,0,100,0,0,0,0,0,0,0,0,0,0,608.4499,-9512.774,0.216,4.6623,0,0,0,0,0,0,0,0,0,0,4.8615,0.0657,0.0329,0.0329,618.5792,110.3883,86.7591,23.6292,1.0397,1.2724,7859.139,0.0657,602.8264,94.6355,11.8146,0,19.9562,98.5737,0.1909,0.0017,0,0,1551318,-508.1909,0,0,0,1.55E+08,0,0,50.1696,30.2644,624.1465,600.0295,574.4244,22.587,0.0657,0.4763,-0.5396,0.0784,632.8748,600.0295,565.696,124.6839,91.8386,57.5051,0.0707,0.4763,-0.5446,599.5334,91.3425,67.1788,0.5111,2.1682,21.128,0.0024,0.0646
1,14.8,14.8,594.92,95362.59,511,0,0.185,510.5956,0.1573,0,0,0.0528,0.0522,0.0518,0,0,0,0.7798,0,0,100,0,0,0,0,0,0,0,0,0,0,608.5806,-9595.771,0.0767,0.6392,0,0,0,0,0,0,0,0,0,0,4.8612,0.0796,0.0398,0.0398,618.455,107.8594,84.3244,23.535,1.0396,1.2791,7860.232,0.0796,602.765,92.1694,11.7675,0,26.3481,96.0919,-0.4044,-0.0037,0,0,1551318,-510.5956,0,0,0,1.55E+08,0,0,50.1744,30.2687,623.8791,600.0601,574.1476,3.0959,0.0796,0.4737,-0.5508,0.0278,624.071,600.0601,573.9556,113.4754,89.4645,63.36,0.0802,0.4737,-0.5514,599.3622,88.7666,50.1154,0.5209,1.791,3.5485,0.0025,0.022
1,17.8,17.8,595.13,95444.44,513,0,0.1867,513.1807,0.2145,0,0,0.0528,0.0522,0.0518,0,0,0,0.8748,0,0,100,0,0,0,0,0,0,0,0,0,0,608.6476,-9674.899,-0.5321,-5.0438,0,0,0,0,0,0,0,0,0,0,4.8659,0.1086,0.0543,0.0543,618.8733,105.6926,81.9493,23.7433,1.0399,1.2897,7862.514,0.1086,603.0444,89.8637,11.8717,0,22.0119,93.821,0.1807,0.0017,0,0,1551318,-513.1807,0,0,0,1.55E+08,0,0,50.1829,30.2752,624.4972,600.2165,574.5728,-24.4176,0.1086,0.4636,-0.5694,-0.1932,634.4539,600.2165,564.6161,121.2732,87.0358,51.4354,0.1351,0.4636,-0.5959,599.7621,86.5815,69.8378,0.5098,2.3578,-22.1841,0.0028,-0.1407
1,20.8,20.8,595.16,95586.44,516,0,0.1867,515.6115,0.2355,0,0,0.0528,0.0522,0.0518,0,0,0,0.9171,0,0,100,0,0,0,0,0,0,0,0,0,0,608.5937,-9801.344,-0.0506,2.5023,0,0,0,0,0,0,0,0,0,0,4.8667,0.1192,0.0597,0.0597,618.9094,103.2979,79.5485,23.7495,1.0399,1.2986,7863.348,0.1193,603.0765,87.465,11.8748,0,24.5066,91.4232,-0.3885,-0.0038,0,0,1551318,-515.6115,0,0,0,1.55E+08,0,0,50.1876,30.2801,624.5694,600.2151,574.7268,12.1112,0.1192,0.4647,-0.5812,-0.0184,627.3564,600.2151,571.9398,111.7449,84.6036,56.3283,0.1194,0.4647,-0.5814,599.8371,84.2256,55.4166,0.5102,1.9838,12.9594,0.0027,-0.0131
1,23.8,23.8,595,95662.31,518,0,0.1871,517.5901,0.272,0,0,0.0528,0.0522,0.0518,0,0,0,0.9587,0,0,100,0,0,0,0,0,0,0,0,0,0,608.5907,-9835.766,0.2124,3.5112,0,0,0,0,0,0,0,0,0,0,4.8667,0.1377,0.0689,0.0689,618.7948,101.2047,77.4099,23.7948,1.04,1.3074,7864.805,0.1377,602.9316,85.3415,11.8974,0,35.2322,89.3073,-0.4099,-0.0041,0,0,1551318,-517.5901,0,0,0,1.55E+08,0,0,50.1928,30.2839,624.3918,600.1143,574.3268,16.9894,0.1377,0.4576,-0.5923,0.0772,629.6126,600.1143,569.1059,112.0225,82.5242,51.5158,0.1418,0.4576,-0.5964,599.6109,82.0208,60.5067,0.5125,2.1745,17.0822,0.003,0.0528
1,26.8,26.8,594.91,95810.7,520,0,0.1859,519.3732,0.3112,0,0,0.0528,0.0522,0.0518,0,0,0,1.0336,0,0,100,0,0,0,0,0,0,0,0,0,0,608.3411,-9945.941,-0.4713,-4.667,0,0,0,0,0,0,0,0,0,0,4.8657,0.1576,0.0789,0.0789,618.5443,99.1711,75.5367,23.6343,1.0397,1.3129,7866.373,0.1577,602.7881,83.4149,11.8172,0,46.0048,87.3539,-0.6268,-0.0063,0,0,1551318,-519.3732,0,0,0,1.55E+08,0,0,50.1996,30.2898,624.1457,599.9644,574.4764,-22.5738,0.1576,0.453,-0.608,-0.1713,632.8719,599.9644,565.7501,113.4987,80.5912,46.3769,0.1763,0.453,-0.6267,599.5288,80.1556,67.1218,0.5097,2.4473,-21.1348,0.0026,-0.1108
1,29.8,29.8,594.88,95888.05,522,0,0.1852,522.438,0.3502,0,0,0.0528,0.0522,0.0518,0,0,0,1.1133,0,0,100,0,0,0,0,0,0,0,0,0,0,608.8264,-9991.631,-0.3593,-0.6308,0,0,0,0,0,0,0,0,0,0,4.8657,0.1773,0.0888,0.0888,618.4223,95.9843,72.442,23.5423,1.0396,1.325,7867.925,0.1774,602.7275,80.2895,11.7712,0,56.3386,84.2132,0.438,0.0046,0,0,1551318,-522.438,0,0,0,1.55E+08,0,0,50.2052,30.294,623.674,600.1285,573.6613,-3.0502,0.1773,0.446,-0.6201,-0.1306,623.8594,600.1285,573.476,101.4214,77.6905,51.038,0.1879,0.446,-0.6307,599.1546,76.7166,50.3834,0.529,1.9872,-3.4772,0.0032,-0.0814
1,32.8,32.8,595.11,95974.59,524,0,0.186,523.7789,0.3902,0,0,0.0528,0.0522,0.0518,0,0,0,1.1603,0,0,100,0,0,0,0,0,0,0,0,0,0,608.3118,-10069.26,0.3037,5.077,0,0,0,0,0,0,0,0,0,0,4.8692,0.1975,0.0989,0.0989,618.7419,94.963,71.3311,23.6319,1.0397,1.3313,7869.517,0.1976,602.9873,79.2084,11.816,0,38.7381,83.1471,-0.2211,-0.0023,0,0,1551318,-523.7789,0,0,0,1.55E+08,0,0,50.2116,30.2992,624.4805,600.0784,575.0218,24.5408,0.1975,0.4399,-0.6345,0.1104,634.5907,600.0784,564.9116,110.8118,76.2996,41.1328,0.2048,0.4399,-0.6418,599.8603,76.0814,69.679,0.5047,2.694,22.3904,0.0029,0.0661
1,35.8,35.8,595.07,96114.53,526,0,0.1866,525.9428,0.4169,0,0,0.0528,0.0522,0.0518,0,0,0,1.2034,0,0,100,0,0,0,0,0,0,0,0,0,0,608.5777,-10193.82,-0.2575,-2.5095,0,0,0,0,0,0,0,0,0,0,4.8702,0.2111,0.1057,0.1057,618.7846,92.8418,69.1272,23.7146,1.0399,1.3431,7870.59,0.2112,602.9749,77.0321,11.8573,0,44.7262,80.9845,-0.0572,-0.0006,0,0,1551318,-525.9428,0,0,0,1.55E+08,0,0,50.217,30.3045,624.3778,600.1537,574.5129,-12.127,0.2111,0.4394,-0.6477,-0.0937,627.1706,600.1537,571.72,101.2278,74.2109,45.7772,0.2162,0.4394,-0.6528,599.6814,73.7386,55.4506,0.5128,2.2113,-12.969,0.0028,-0.0544
1,38.8,38.8,594.98,96089.61,527,0,0.1867,527.3795,0.468,0,0,0.0528,0.0522,0.0518,0,0,0,1.2886,0,0,100,0,0,0,0,0,0,0,0,0,0,608.7385,-10168.79,-0.6244,-3.5309,0,0,0,0,0,0,0,0,0,0,4.8708,0.2369,0.1187,0.1187,618.7008,91.3213,67.6005,23.7208,1.0399,1.3509,7872.625,0.2371,602.8869,75.5074,11.8604,0,55.0348,79.4609,0.3795,0.0042,0,0,1551318,-527.3795,0,0,0,1.55E+08,0,0,50.2231,30.3078,624.1547,600.158,574.0417,-17.0565,0.2369,0.4253,-0.6592,-0.2272,629.4092,600.158,568.7872,102.0297,72.7785,41.4077,0.2648,0.4253,-0.6871,599.4514,72.072,60.622,0.5175,2.464,-17.122,0.003,-0.1247
1,41.8,41.8,595,96268.12,530,0,0.1863,529.2338,0.4993,0,0,0.0528,0.0522,0.0518,0,0,0,1.326,0,0,100,0,0,0,0,0,0,0,0,0,0,608.2726,-10324.65,0.1665,4.6808,0,0,0,0,0,0,0,0,0,0,4.8713,0.2528,0.1266,0.1266,618.6658,89.432,65.7662,23.6658,1.0398,1.3598,7873.88,0.2529,602.8886,73.6548,11.8329,0,56.4031,77.5991,-0.7662,-0.0086,0,0,1551318,-529.2338,0,0,0,1.55E+08,0,0,50.2296,30.3144,624.3657,599.9954,574.7968,22.6041,0.2528,0.4258,-0.6754,0.0606,633.1255,599.9954,566.0371,103.8917,70.7616,36.8033,0.2548,0.4258,-0.6774,599.7193,70.4855,67.0884,0.5062,2.8229,21.1828,0.0032,0.0326
1,44.8,44.8,594.88,96312.66,531,0,0.187,531.6006,0.532,0,0,0.0528,0.0522,0.0518,0,0,0,1.3896,0,0,100,0,0,0,0,0,0,0,0,0,0,608.7582,-10339.05,0.0026,0.629,0,0,0,0,0,0,0,0,0,0,4.8718,0.2693,0.1349,0.1349,618.6269,87.0263,63.2794,23.7469,1.0399,1.3753,7875.183,0.2695,602.7957,71.1951,11.8735,0,77.6473,75.1529,0.6006,0.0069,0,0,1551318,-531.6006,0,0,0,1.55E+08,0,0,50.234,30.3173,624.0314,600.1034,573.7546,3.0367,0.2693,0.4182,-0.6844,0.0009,624.2141,600.1034,573.5718,92.6135,68.5028,41.9712,0.2693,0.4182,-0.6844,599.2964,67.6958,50.6423,0.5239,2.2066,3.444,0.0031,0.0005
1,47.8,47.8,594.78,96390.16,532,0,0.1862,532.065,0.5894,0,0,0.0528,0.0522,0.0518,0,0,0,1.4867,0,0,100,0,0,0,0,0,0,0,0,0,0,608.2704,-10365.96,-0.8347,-5.0454,0,0,0,0,0,0,0,0,0,0,4.8716,0.2984,0.1495,0.1495,618.421,86.356,62.715,23.641,1.0397,1.377,7877.481,0.2986,602.6603,70.5953,11.8205,0,102.5771,74.5355,0.065,0.0008,0,0,1551318,-532.065,0,0,0,1.55E+08,0,0,50.2418,30.3224,623.9836,599.8575,574.2443,-24.3475,0.2984,0.4046,-0.7003,-0.3041,633.9177,599.8575,564.3102,101.8527,67.7925,32.2452,0.3427,0.4046,-0.7446,599.3618,67.2968,69.6075,0.5107,3.1587,-22.1961,0.0027,-0.1478
1,50.8,50.8,594.85,96505.8,535,0,0.1868,534.9276,0.6171,0,0,0.0528,0.0522,0.0518,0,0,0,1.5353,0,0,100,0,0,0,0,0,0,0,0,0,0,608.8596,-10488.63,-0.1868,2.5146,0,0,0,0,0,0,0,0,0,0,4.8734,0.3124,0.1566,0.1566,618.5627,83.6351,59.9224,23.7127,1.0399,1.3957,7878.588,0.3127,602.7542,67.8266,11.8564,0,91.7954,71.7788,-0.0724,-0.0009,0,0,1551318,-534.9276,0,0,0,1.55E+08,0,0,50.2473,30.3278,623.8681,600.123,573.5201,12.1314,0.3124,0.4041,-0.7137,-0.0681,626.6387,600.123,570.7495,91.7111,65.1954,35.8219,0.3147,0.4041,-0.716,599.1704,64.2428,55.8892,0.5256,2.5602,12.8647,0.0028,-0.0331
1,53.8,53.8,594.96,96511.29,536,0,0.1872,535.7657,0.6519,0,0,0.0528,0.0522,0.0518,0,0,0,1.5915,0,0,100,0,0,0,0,0,0,0,0,0,0,608.4044,-10466.12,0.1767,3.526,0,0,0,0,0,0,0,0,0,0,4.8755,0.33,0.1654,0.1654,618.7199,82.9542,59.1943,23.7599,1.0399,1.4014,7879.979,0.3303,602.8799,67.1142,11.88,0,73.6317,71.0743,-0.2343,-0.0028,0,0,1551318,-535.7657,0,0,0,1.55E+08,0,0,50.2514,30.3299,624.3751,600.0204,574.4913,17.0064,0.33,0.3941,-0.7214,0.0644,629.6213,600.0204,569.2452,93.8556,64.2547,33.4795,0.332,0.3941,-0.7234,599.6289,63.8633,60.3761,0.5097,2.8034,17.1439,0.0027,0.0306
1,56.8,56.8,595.15,96673.56,537,0,0.1862,536.9764,0.6971,0,0,0.0528,0.0522,0.0518,0,0,0,1.674,0,0,100,0,0,0,0,0,0,0,0,0,0,608.3162,-10628.5,-0.7526,-4.6663,0,0,0,0,0,0,0,0,0,0,4.877,0.3529,0.1769,0.1769,618.7681,81.7918,58.1737,23.6181,1.0397,1.406,7881.79,0.3532,603.0227,66.0463,11.8091,0,55.3756,69.9828,-0.0236,-0.0003,0,0,1551318,-536.9764,0,0,0,1.55E+08,0,0,50.2597,30.3377,624.5158,600.106,575.1003,-22.4969,0.3529,0.3915,-0.7412,-0.2744,633.2234,600.106,566.3927,96.247,63.1296,29.4163,0.3863,0.3915,-0.7746,599.9073,62.931,66.8307,0.5045,3.2719,-21.1592,0.0032,-0.1224
1,59.8,59.8,594.62,96660.9,539,0,0.1859,539.2042,0.7391,0,0,0.0528,0.0522,0.0518,0,0,0,1.7358,0,0,100,0,0,0,0,0,0,0,0,0,0,608.6899,-10586.92,-0.619,-0.6215,0,0,0,0,0,0,0,0,0,0,4.8736,0.3742,0.1876,0.1876,618.2045,79.0003,55.4158,23.5845,1.0397,1.4256,7883.475,0.3745,602.4815,63.2773,11.7923,0,241.1503,67.2081,0.2042,0.0026,0,0,1551318,-539.2042,0,0,0,1.55E+08,0,0,50.2644,30.3398,623.401,599.916,573.1953,-2.9954,0.3742,0.3784,-0.7496,-0.2258,623.5791,599.916,573.0172,84.3749,60.7118,33.813,0.3964,0.3784,-0.7718,598.8375,59.6332,50.5619,0.532,2.4953,-3.4023,0.003,-0.0988
1,62.8,62.8,595.05,96723.49,540,0,0.1867,539.8542,0.7859,0,0,0.0528,0.0522,0.0518,0,0,0,1.8083,0,0,100,0,0,0,0,0,0,0,0,0,0,608.136,-10627.66,0.3555,5.0638,0,0,0,0,0,0,0,0,0,0,4.8789,0.3979,0.1995,0.1995,618.7296,78.8754,55.1958,23.6796,1.0398,1.429,7885.351,0.3983,602.9432,63.089,11.8398,0,69.4051,67.0356,-0.1458,-0.0018,0,0,1551318,-539.8542,0,0,0,1.55E+08,0,0,50.2711,30.3445,624.544,599.9756,575.1224,24.3966,0.3979,0.3684,-0.7636,0.1297,634.5581,599.9756,565.1083,94.7039,60.1214,25.2541,0.4051,0.3684,-0.7708,599.8807,60.0265,69.4498,0.5021,3.75,22.3167,0.0027,0.0555
1,65.8,65.8,594.81,96858.8,543,0,0.1865,542.6435,0.8262,0,0,0.0528,0.0522,0.0518,0,0,0,1.8511,0,0,100,0,0,0,0,0,0,0,0,0,0,608.3433,-10757.13,-0.4226,-2.4957,0,0,0,0,0,0,0,0,0,0,4.8777,0.4183,0.2098,0.2098,618.4507,75.8072,52.1665,23.6407,1.0397,1.4532,7886.966,0.4187,602.6902,60.0467,11.8204,0,123.4236,63.9869,-0.3565,-0.0047,0,0,1551318,-542.6435,0,0,0,1.55E+08,0,0,50.2783,30.3511,623.9987,599.9043,574.1975,-12.0195,0.4183,0.3653,-0.7806,-0.1543,626.7479,599.9043,571.4484,84.1044,57.2608,28.8049,0.4281,0.3653,-0.7904,599.3669,56.7234,55.2995,0.5146,2.9198,-12.8833,0.003,-0.0638
1,68.8,68.8,595.08,96773.88,543,0,0.1866,542.7828,0.8842,0,0,0.0528,0.0522,0.0518,0,0,0,1.9533,0,0,100,0,0,0,0,0,0,0,0,0,0,608.671,-10597.57,-0.9958,-3.5164,0,0,0,0,0,0,0,0,0,0,4.8814,0.4477,0.2246,0.2246,618.7371,75.9544,52.2972,23.6571,1.0398,1.4524,7889.295,0.4482,602.9658,60.183,11.8286,0,70.7455,64.1258,-0.2172,-0.0029,0,0,1551318,-542.7828,0,0,0,1.55E+08,0,0,50.2832,30.3513,624.2466,600.1957,574.3843,-16.929,0.4477,0.3417,-0.7869,-0.3636,629.451,600.1957,569.1799,86.6682,57.4129,26.3971,0.4991,0.3417,-0.8383,599.6089,56.8261,60.2711,0.5146,3.2832,-17.0888,0.0025,-0.1412
1,71.8,71.8,595.08,96942.94,545,0,0.1858,544.7484,0.9344,0,0,0.0528,0.0522,0.0518,0,0,0,2.0388,0,0,100,0,0,0,0,0,0,0,0,0,0,607.9722,-10786.01,0.2061,4.6529,0,0,0,0,0,0,0,0,0,0,4.8818,0.4731,0.2374,0.2374,618.63,73.8816,50.3316,23.55,1.0396,1.4679,7891.309,0.4737,602.93,58.1816,11.775,0,73.8655,62.1066,-0.2516,-0.0034,0,0,1551318,-544.7484,0,0,0,1.55E+08,0,0,50.2926,30.3602,624.477,599.933,575.4432,22.3899,0.4731,0.3392,-0.8094,0.0753,633.1623,599.933,566.7579,88.4139,55.1846,22.0095,0.4753,0.3392,-0.8116,599.951,55.2027,66.4044,0.4996,4.0171,21.2018,0.0029,0.0293
1,74.8,74.8,595.06,96924.88,547,0,0.1861,547.1329,0.9823,0,0,0.0528,0.0522,0.0518,0,0,0,2.0989,0,0,100,0,0,0,0,0,0,0,0,0,0,608.7032,-10734.03,0.0396,0.6245,0,0,0,0,0,0,0,0,0,0,4.883,0.4973,0.2496,0.2496,618.6316,71.4987,47.9271,23.5716,1.0396,1.4918,7893.228,0.4979,602.9172,55.7843,11.7858,0,80.1988,59.7129,0.1329,0.0019,0,0,1551318,-547.1329,0,0,0,1.55E+08,0,0,50.2979,30.3625,624.0775,600.1956,574.2808,3.0041,0.4973,0.324,-0.8187,0.0145,624.2581,600.1956,574.1003,77.1252,53.0627,26.9674,0.4974,0.324,-0.8188,599.518,52.3851,50.1578,0.5203,2.8599,3.4399,0.0026,0.0055
1,77.8,77.8,594.88,96924.28,547,0,0.1857,546.3303,1.0633,0,0,0.0528,0.0522,0.0518,0,0,0,2.2354,0,0,100,0,0,0,0,0,0,0,0,0,0,608.1495,-10695.86,-1.323,-5.0448,0,0,0,0,0,0,0,0,0,0,4.8832,0.5383,0.2702,0.2702,618.402,72.0717,48.5497,23.522,1.0395,1.4845,7896.482,0.539,602.7206,56.3903,11.761,0,111.9031,60.3107,-0.6697,-0.0093,0,0,1551318,-546.3303,0,0,0,1.55E+08,0,0,50.3077,30.3678,624.0179,599.8749,574.671,-24.2529,0.5383,0.3014,-0.8373,-0.4838,633.9419,599.8749,564.7471,87.6116,53.5446,18.4168,0.6187,0.3014,-0.9177,599.5213,53.191,69.1948,0.5077,4.7572,-22.2538,0.0024,-0.1638
1,80.8,80.8,594.82,97034.25,551,0,0.1869,550.6502,1.1211,0,0,0.0528,0.0522,0.0518,0,0,0,2.3214,0,0,100,0,0,0,0,0,0,0,0,0,0,608.5358,-10808.44,-0.3406,2.4874,0,0,0,0,0,0,0,0,0,0,4.8853,0.5676,0.285,0.285,618.4857,67.8355,44.1698,23.6657,1.0398,1.5358,7898.809,0.5684,602.7086,52.0584,11.8329,0,141.7246,56.0027,-0.3498,-0.0052,0,0,1551318,-550.6502,0,0,0,1.55E+08,0,0,50.3168,30.3752,623.9272,599.9831,573.928,11.9523,0.5676,0.2929,-0.8576,-0.1246,626.6375,599.9831,571.2177,75.9873,49.3329,20.5675,0.573,0.2929,-0.863,599.2795,48.6292,55.4198,0.519,3.6945,12.7762,0.0029,-0.0435
1,83.8,83.8,594.84,96882.89,550,0,0.187,550.2793,1.1796,0,0,0.0528,0.0522,0.0518,0,0,0,2.4294,0,0,100,0,0,0,0,0,0,0,0,0,0,608.3718,-10635.75,0.4365,3.5206,0,0,0,0,0,0,0,0,0,0,4.8869,0.5972,0.2999,0.2999,618.5041,68.2248,44.5607,23.6641,1.0398,1.5311,7901.161,0.5981,602.728,52.4487,11.8321,0,133.4988,56.3928,0.2793,0.0041,0,0,1551318,-550.2793,0,0,0,1.55E+08,0,0,50.3215,30.3751,624.0639,599.9336,574.2333,16.9109,0.5972,0.2687,-0.8632,0.1597,629.2609,599.9336,569.0363,78.9816,49.6543,18.757,0.6059,0.2687,-0.8719,599.4103,49.131,60.2246,0.513,4.2108,17.0831,0.0027,0.0542
1,86.8,86.8,594.9,97053.41,551,0,0.1845,551.3954,1.2732,0,0,0.0528,0.0522,0.0518,0,0,0,2.5933,0,0,100,0,0,0,0,0,0,0,0,0,0,607.9399,-10771.59,-1.2597,-4.639,0,0,0,0,0,0,0,0,0,0,4.8871,0.6446,0.3239,0.3239,618.2345,66.8391,43.5046,23.3345,1.0392,1.5364,7904.93,0.6457,602.6782,51.2828,11.6673,0,118.1803,55.1719,0.3954,0.0059,0,0,1551318,-551.3954,0,0,0,1.55E+08,0,0,50.3358,30.386,623.8921,599.8086,575.0388,-22.2654,0.6446,0.2516,-0.8942,-0.4614,632.5171,599.8086,566.4138,81.1217,48.4132,15.0184,0.7109,0.2516,-0.9605,599.5798,48.1844,66.1033,0.5052,5.4015,-21.1749,0.002,-0.1405
1,89.8,89.8,595,96901.55,554,0,0.1864,553.9681,1.3494,0,0,0.0528,0.0522,0.0518,0,0,0,2.7091,0,0,100,0,0,0,0,0,0,0,0,0,0,608.7414,-10548.74,-1.1836,-0.6475,0,0,0,0,0,0,0,0,0,0,4.8917,0.6832,0.3434,0.3434,618.5759,64.6079,41.0319,23.5759,1.0396,1.5746,7908.002,0.6844,602.8586,48.8905,11.788,0,101.3755,52.8199,-0.0319,-0.0005,0,0,1551318,-553.9681,0,0,0,1.55E+08,0,0,50.342,30.386,623.9542,600.1722,574.0768,-3.1063,0.6832,0.2205,-0.9018,-0.4337,624.1469,600.1722,573.8841,70.1788,46.2041,19.916,0.7405,0.2205,-0.9591,599.4011,45.433,50.2628,0.523,3.5237,-3.55,0.0019,-0.1291
1,92.8,92.8,595.07,96868.78,554,0,0.1866,553.5864,1.4566,0,0,0.0528,0.0522,0.0518,0,0,0,2.8675,0,0,100,0,0,0,0,0,0,0,0,0,0,608.187,-10490.17,0.774,5.0394,0,0,0,0,0,0,0,0,0,0,4.895,0.7374,0.3708,0.3708,618.6554,65.069,41.4836,23.5854,1.0396,1.5685,7912.32,0.7388,602.9318,49.3454,11.7927,0,89.313,53.2763,-0.4136,-0.0064,0,0,1551318,-553.5864,0,0,0,1.55E+08,0,0,50.3547,30.3927,624.4024,600.0071,575.099,24.1568,0.7374,0.1904,-0.9256,0.2838,634.2653,600.0071,565.2361,80.6789,46.4207,11.6497,0.7613,0.1904,-0.9495,599.8362,46.2498,69.0292,0.5037,6.9254,22.2095,0.0022,0.0831
1,95.8,95.8,594.76,96946.98,558,0,0.1857,558.2361,1.5658,0,0,0.0528,0.0522,0.0518,0,0,0,3.0396,0,0,100,0,0,0,0,0,0,0,0,0,0,608.477,-10565.02,-0.6632,-2.493,0,0,0,0,0,0,0,0,0,0,4.8943,0.7927,0.3987,0.3987,618.2223,59.9862,36.5239,23.4623,1.0394,1.6424,7916.731,0.7943,602.5807,44.3446,11.7312,0,193.625,48.2551,0.2361,0.0039,0,0,1551318,-558.2361,0,0,0,1.55E+08,0,0,50.37,30.4032,623.5493,599.9231,573.8733,-11.9399,0.7927,0.1663,-0.9572,-0.2434,626.2701,599.9231,571.1525,68.034,41.687,12.9164,0.8095,0.1663,-0.974,599.1152,40.8791,55.1176,0.522,5.2673,-12.837,0.0018,-0.0682
1,98.8,98.8,594.55,96641.99,557,0,0.1853,556.1008,1.6696,0,0,0.0528,0.0522,0.0518,0,0,0,3.2094,0,0,100,0,0,0,0,0,0,0,0,0,0,608.3056,-10138.11,-1.98,-3.5239,0,0,0,0,0,0,0,0,0,0,4.8947,0.8453,0.4253,0.4253,617.9451,61.8443,38.4492,23.3951,1.0393,1.6085,7920.931,0.8471,602.3484,46.2476,11.6976,0,579.0217,50.1468,-0.8992,-0.0145,0,0,1551318,-556.1008,0,0,0,1.55E+08,0,0,50.3764,30.3998,623.2248,599.7269,573.617,-16.8675,0.8453,0.1171,-0.9609,-0.7272,628.4167,599.7269,568.4251,72.3159,43.6261,12.3243,0.9814,0.1171,-1.097,598.8562,42.7554,59.9916,0.5218,5.8677,-17.1085,0.0015,-0.1741
1,101.8,101.8,595.18,96768.55,559,0,0.1852,558.6539,1.8333,0,0,0.0528,0.0522,0.0518,0,0,0,3.4571,0,0,100,0,0,0,0,0,0,0,0,0,0,608.0301,-10243.92,0.6222,4.6645,0,0,0,0,0,0,0,0,0,0,4.9035,0.9282,0.4674,0.4674,618.5385,59.8846,36.5261,23.3585,1.0392,1.6395,7927.559,0.9304,602.9661,44.3123,11.6793,0,82.7982,48.2054,-0.3461,-0.0058,0,0,1551318,-558.6539,0,0,0,1.55E+08,0,0,50.3993,30.4154,624.3216,600.0162,575.6222,22.2978,0.9282,0.0806,-1.0081,0.2288,632.9886,600.0162,566.9553,74.3347,41.3623,8.3015,0.9416,0.0806,-1.0215,599.9867,41.3328,66.0332,0.5007,8.9544,21.2407,0.0007,0.0581
1,104.8,104.8,594.59,96508.84,563,0,0.1842,561.9728,1.942,0,0,0.0528,0.0522,0.0518,0,0,0,3.618,0,0,100,0,0,0,0,0,0,0,0,0,0,608.5117,-9924.033,0.5061,0.6647,0,0,0,0,0,0,0,0,0,0,4.9005,0.9832,0.4953,0.4953,617.8169,55.8441,32.6173,23.2269,1.0391,1.7121,7931.962,0.9857,602.3323,40.3595,11.6135,0,455.3808,44.2307,-1.0272,-0.0184,0,0,1551318,-561.9728,0,0,0,1.55E+08,0,0,50.4081,30.4153,622.9051,599.829,573.4108,3.1753,0.9832,0.036,-1.0188,0.1862,623.108,599.829,573.2079,61.1352,37.8562,11.2351,0.9918,0.036,-1.0274,598.715,36.7422,49.9001,0.5335,5.4414,3.6558,0.0004,0.046
1,107.8,107.8,595.09,96287.1,559,0,0.1856,558.173,2.1495,0,0,0.0528,0.0522,0.0518,0,0,0,3.9354,0,0,100,0,0,0,0,0,0,0,0,0,0,607.6677,-9633.229,-2.7821,-5.0241,0,0,0,0,0,0,0,0,0,0,4.9108,1.0882,0.5486,0.5486,618.4589,60.286,36.9171,23.3689,1.0393,1.633,7940.382,1.0912,602.8796,44.7066,11.6845,0,93.6856,48.6016,-0.827,-0.0137,0,0,1551318,-558.173,0,0,0,1.55E+08,0,0,50.4301,30.4236,624.4152,599.8228,575.9633,-23.9659,1.0882,-0.0325,-1.0559,-1.0253,634.2665,599.8228,566.112,76.0935,41.6498,7.939,1.3103,-0.0325,-1.278,600.0671,41.8941,68.1545,0.4946,9.5848,-22.3454,-0.0002,-0.1861
1,110.8,110.8,594.86,96343.59,566,0,0.1842,565.8553,2.3603,0,0,0.0528,0.0522,0.0518,0,0,0,4.2622,0,0,100,0,0,0,0,0,0,0,0,0,0,608.1697,-9572.241,-0.6076,2.4936,0,0,0,0,0,0,0,0,0,0,4.9127,1.195,0.6029,0.6029,618.0301,52.1748,29.0047,23.1701,1.039,1.7988,7948.965,1.1986,602.5833,36.728,11.5851,0,164.9925,40.5898,-0.1447,-0.0028,0,0,1551318,-565.8553,0,0,0,1.55E+08,0,0,50.4564,30.4384,623.4525,599.868,574.6219,11.876,1.195,-0.0899,-1.1061,-0.2243,626.1877,599.868,571.8868,60.3324,34.0127,6.0315,1.2059,-0.0899,-1.117,599.3141,33.4589,54.3009,0.5153,10.0029,12.9695,-0.001,-0.0479
1,113.8,113.8,594.94,95833.43,562,0,0.1857,562.9121,2.4914,0,0,0.0528,0.0522,0.0518,0,0,0,4.4905,0,0,100,0,0,0,0,0,0,0,0,0,0,608.1707,-9025.405,1.4859,3.5281,0,0,0,0,0,0,0,0,0,0,4.918,1.2613,0.6367,0.6367,618.2818,55.3697,32.0279,23.3418,1.0392,1.7288,7954.303,1.2653,602.7206,39.8085,11.6709,0,132.042,43.6988,0.9121,0.0165,0,0,1551318,-562.9121,0,0,0,1.55E+08,0,0,50.4645,30.434,623.8553,599.9174,574.8374,16.7905,1.2613,-0.1523,-1.1107,0.5489,629.0551,599.9174,569.6376,66.143,37.0053,6.7255,1.3232,-0.1523,-1.1726,599.5367,36.6246,59.4175,0.5096,9.8347,17.2071,-0.0017,0.1058
1,116.8,116.8,595.24,95810.55,564,0,0.1859,563.448,2.8158,0,0,0.0528,0.0522,0.0518,0,0,0,5.0025,0,0,100,0,0,0,0,0,0,0,0,0,0,607.7656,-8915.749,-2.8802,-4.6406,0,0,0,0,0,0,0,0,0,0,4.9285,1.4256,0.7205,0.7205,618.5708,55.1228,31.792,23.3308,1.0392,1.7339,7967.561,1.4307,603.0169,39.5689,11.6654,0,82.5785,43.4574,-0.552,-0.01,0,0,1551318,-563.448,0,0,0,1.55E+08,0,0,50.5048,30.4564,624.5382,599.952,576.2117,-22.0309,1.4256,-0.2414,-1.1872,-1.0665,633.0739,599.952,567.676,69.6259,36.504,4.228,1.6276,-0.2414,-1.3892,600.2339,36.786,65.3979,0.4935,16.4678,-21.1785,-0.003,-0.1565
1,119.8,119.8,594.67,95415.8,566,0,0.1833,567.5786,2.9749,0,0,0.0528,0.0522,0.0518,0,0,0,5.2563,0,0,100,0,0,0,0,0,0,0,0,0,0,608.2968,-8417.338,-2.9207,-0.6944,0,0,0,0,0,0,0,0,0,0,4.9252,1.5061,0.7617,0.7617,617.6518,50.0732,27.0914,22.9818,1.0386,1.8483,7974.072,1.5119,602.3306,34.752,11.4909,0,315.3412,38.5823,1.5786,0.0315,0,0,1551318,-567.5786,0,0,0,1.55E+08,0,0,50.5173,30.4554,622.8065,599.7953,573.9834,-3.2934,1.5061,-0.3085,-1.2013,-1.0826,623.0276,599.7953,573.7623,55.449,32.2167,6.1837,1.7076,-0.3085,-1.4028,598.8618,31.2831,49.2653,0.5284,8.967,-3.8417,-0.0037,-0.1524
1,122.8,122.8,595.59,95076.89,565,0,0.1875,564.2106,3.3203,0,0,0.0528,0.0522,0.0518,0,0,0,5.8285,0,0,100,0,0,0,0,0,0,0,0,0,0,607.8346,-8019.945,2.277,5.0315,0,0,0,0,0,0,0,0,0,0,4.9452,1.681,0.8512,0.8512,619.0586,54.848,31.3795,23.4686,1.0394,1.7479,7988.258,1.6881,603.4129,39.2023,11.7343,0,57.892,43.1138,-0.7894,-0.0144,0,0,1551318,-564.2106,0,0,0,1.55E+08,0,0,50.5558,30.4718,625.2784,600.1948,577.0123,23.8044,1.681,-0.4183,-1.2682,0.8461,635.0431,600.1948,567.2477,70.8325,35.9843,3.0371,1.7977,-0.4183,-1.3849,600.8286,36.618,67.7954,0.486,23.3224,22.3036,-0.0055,0.1191
1,125.8,125.8,594.98,94973.98,572,0,0.1822,571.8922,3.7191,0,0,0.0528,0.0522,0.0518,0,0,0,6.4924,0,0,100,0,0,0,0,0,0,0,0,0,0,607.8925,-7796.451,-1.3675,-2.5018,0,0,0,0,0,0,0,0,0,0,4.9448,1.8829,0.955,0.955,617.7374,45.8452,23.0878,22.7575,1.0382,1.9857,8004.695,1.8919,602.5658,30.6736,11.3788,0,139.0261,34.4665,-0.1078,-0.0024,0,0,1551318,-571.8922,0,0,0,1.55E+08,0,0,50.6041,30.4971,623.1804,599.8356,575.395,-11.8011,1.8829,-0.5321,-1.3578,-0.5096,625.9359,599.8356,572.6395,54.0437,27.9434,0.7473,1.9225,-0.5321,-1.3974,599.4703,27.5781,53.2964,0.5103,72.3186,-13.1429,-0.007,-0.0727
1,128.8,128.8,595.13,94293.44,566,0,0.1856,566.0284,3.8906,0,0,0.0528,0.0522,0.0518,0,0,0,6.7812,0,0,100,0,0,0,0,0,0,0,0,0,0,607.8865,-7056.755,-4.5487,-3.5318,0,0,0,0,0,0,0,0,0,0,4.9537,1.9697,0.9996,0.9996,618.3018,52.2734,29.1016,23.1718,1.0389,1.7962,8011.783,1.9795,602.8539,36.8255,11.5859,0,99.7299,40.6875,0.0284,0.0005,0,0,1551318,-566.0284,0,0,0,1.55E+08,0,0,50.6145,30.4907,624.0606,599.9257,575.8019,-16.6436,1.9697,-0.6152,-1.3627,-1.6968,629.244,599.9257,570.6185,63.2156,33.8973,4.5901,2.3567,-0.6152,-1.7497,599.9294,33.901,58.6255,0.4999,13.7722,-17.2983,-0.0082,-0.1558
1,131.8,131.8,595.28,94130.25,570,0,0.185,568.4489,4.4337,0,0,0.0528,0.0522,0.0518,0,0,0,7.6624,0,0,100,0,0,0,0,0,0,0,0,0,0,607.2476,-6811.352,2.0305,4.6682,0,0,0,0,0,0,0,0,0,0,4.9677,2.2447,1.1416,1.1416,618.3099,49.861,26.8311,23.0299,1.0387,1.8583,8034.321,2.2575,602.9566,34.5077,11.515,0,84.6201,38.3461,-1.5511,-0.0311,0,0,1551318,-568.4489,0,0,0,1.55E+08,0,0,50.6817,30.5269,624.4445,599.7787,577.1537,21.9089,2.2447,-0.7681,-1.4883,0.7605,633.0342,599.7787,568.5639,64.5853,31.3298,0.115,2.3206,-0.7681,-1.5642,600.4589,32.01,64.4703,0.4842,561.6113,21.4085,-0.0117,0.0871
1,134.8,134.8,595.02,93671.53,574,0,0.178,573.2706,4.6598,0,0,0.0528,0.0522,0.0518,0,0,0,8.0378,0,0,100,0,0,0,0,0,0,0,0,0,0,608.8362,-6211.633,1.964,0.7357,0,0,0,0,0,0,0,0,0,0,4.9642,2.3592,1.2009,1.2009,617.1505,43.8799,21.7494,22.1305,1.0372,2.0175,8043.743,2.3734,602.3969,29.1263,11.0653,0,131.6787,32.8147,-0.7294,-0.0166,0,0,1551318,-573.2706,0,0,0,1.55E+08,0,0,50.7016,30.5286,621.7386,600.2125,574.1115,3.4478,2.3592,-0.8576,-1.5145,0.7367,621.9869,600.2125,573.8632,48.7163,26.9419,0.5926,2.428,-0.8576,-1.5833,598.6876,25.4169,48.1237,0.5475,82.2077,4.1191,-0.0129,0.082
1,137.8,137.8,594.89,93158.23,566,0,0.1858,566.2272,5.1678,0,0,0.0528,0.0522,0.0518,0,0,0,8.8708,0,0,100,0,0,0,0,0,0,0,0,0,0,607.6489,-5598.087,-5.6812,-5.0097,0,0,0,0,0,0,0,0,0,0,4.9836,2.6163,1.3344,1.3344,617.931,51.7039,28.6628,23.041,1.0387,1.8039,8064.979,2.6338,602.5704,36.3432,11.5205,0,154.5773,40.1834,0.2272,0.0044,0,0,1551318,-566.2272,0,0,0,1.55E+08,0,0,50.7585,30.5523,623.6379,599.6841,575.5982,-23.3917,2.6163,-1.0205,-1.6121,-2.1389,633.146,599.6841,566.0901,66.9188,33.4569,-0.1371,3.1016,-1.0205,-2.0974,599.6401,33.4129,67.0559,0.501,-488.1021,-22.1205,-0.0163,-0.134
1,140.8,140.8,595.22,92985.5,574,0,0.1793,575.8652,5.7709,0,0,0.0528,0.0522,0.0518,0,0,0,9.8395,0,0,100,0,0,0,0,0,0,0,0,0,0,608.2327,-5238.721,-0.7783,2.4448,0,0,0,0,0,0,0,0,0,0,4.9948,2.9217,1.4937,1.4937,617.3775,41.5123,19.3548,22.1575,1.0372,2.1448,8090.351,2.9436,602.6058,26.7406,11.0788,0,100.8527,30.4336,1.8652,0.0449,0,0,1551318,-575.8652,0,0,0,1.55E+08,0,0,50.8324,30.5906,622.4601,600.1088,575.5544,11.3638,2.9217,-1.1946,-1.7477,-0.2944,625.0681,600.1088,572.9463,49.2029,24.2437,-2.9189,2.931,-1.1946,-1.757,599.3745,23.5092,52.1218,0.5211,-16.8567,12.926,-0.0206,-0.0307
1,143.8,143.8,595.27,92320.45,570,0,0.1859,570.3327,5.9622,0,0,0.0528,0.0522,0.0518,0,0,0,10.1595,0,0,100,0,0,0,0,0,0,0,0,0,0,607.9053,-4436.296,3.5161,3.5149,0,0,0,0,0,0,0,0,0,0,5.0067,3.0185,1.5443,1.5443,618.2313,47.8986,24.9373,22.9613,1.0386,1.9208,8098.426,3.0419,602.9238,32.5911,11.4807,0,87.9503,36.418,0.3327,0.0069,0,0,1551318,-570.3327,0,0,0,1.55E+08,0,0,50.8446,30.584,623.9736,600.0157,576.1967,16.3198,3.0185,-1.2862,-1.7544,1.3312,629.016,600.0157,571.1543,58.6833,29.683,0.8216,3.1974,-1.2862,-1.9333,600.062,29.7293,57.8617,0.4988,71.4256,17.1698,-0.0221,0.0971
1,146.8,146.8,595.05,91971.32,569,0,0.1849,570.1304,6.7197,0,0,0.0528,0.0522,0.0518,0,0,0,11.3524,0,0,100,0,0,0,0,0,0,0,0,0,0,607.5199,-3994.354,-5.4439,-4.656,0,0,0,0,0,0,0,0,0,0,5.023,3.402,1.7457,1.7457,617.7913,47.661,24.9196,22.7413,1.0382,1.9126,8130.577,3.4318,602.6304,32.5,11.3707,0,119.8675,36.2903,1.1304,0.0237,0,0,1551318,-570.1304,0,0,0,1.55E+08,0,0,50.9382,30.6326,623.5189,599.7329,576.2382,-21.4946,3.402,-1.505,-1.9257,-2.073,631.8298,599.7329,567.9272,61.6994,29.6025,-2.2032,3.7787,-1.505,-2.3024,599.83,29.6996,63.9026,0.4977,-28.0045,-21.1391,-0.0287,-0.1052
1,149.8,149.8,594.97,91461.84,577,0,0.1771,575.1302,6.9584,0,0,0.0528,0.0522,0.0518,0,0,0,11.7371,0,0,100,0,0,0,0,0,0,0,0,0,0,608.3494,-3320.114,-5.647,-0.7622,0,0,0,0,0,0,0,0,0,0,5.0206,3.5229,1.8094,1.8094,616.7233,41.5931,19.8398,21.7534,1.0366,2.0964,8140.766,3.5549,602.2211,27.0909,10.8767,0,147.9299,30.7165,-1.8698,-0.045,0,0,1551318,-575.1302,0,0,0,1.55E+08,0,0,50.9591,30.6335,621.3911,599.9932,574.8052,-3.5133,3.5229,-1.6019,-1.9519,-2.1536,621.6546,599.9932,574.5417,46.5244,24.863,-0.5885,3.918,-1.6019,-2.347,598.7298,23.5996,47.1129,0.5402,-79.0559,-4.2887,-0.0309,-0.1038
1,152.8,152.8,595.22,90900.45,570,0,0.185,569.2728,7.6286,0,0,0.0528,0.0522,0.0518,0,0,0,12.8405,0,0,100,0,0,0,0,0,0,0,0,0,0,607.7881,-2664.242,4.1141,5.0059,0,0,0,0,0,0,0,0,0,0,5.0476,3.8622,1.9889,1.9889,617.8593,48.5865,25.9471,22.6393,1.038,1.8725,8169.497,3.9007,602.7664,33.4936,11.3197,0,92.2907,37.2668,-0.7272,-0.015,0,0,1551318,-569.2728,0,0,0,1.55E+08,0,0,51.0382,30.6696,623.4998,599.9375,576.2958,22.9599,3.8622,-1.8097,-2.0901,1.5768,632.8252,599.9375,566.9705,63.5524,30.6647,-2.3023,4.0642,-1.8097,-2.2921,599.9111,30.6383,65.8547,0.5006,-27.6039,22.105,-0.0376,0.0845
1,155.8,155.8,594.9,90611.5,578,0,0.1798,577.4199,8.4374,0,0,0.0528,0.0522,0.0518,0,0,0,14.1775,0,0,100,0,0,0,0,0,0,0,0,0,0,607.61,-2189.176,-2.5066,-2.5241,0,0,0,0,0,0,0,0,0,0,5.0606,4.2717,2.2068,2.2068,616.812,39.3921,17.4801,21.912,1.0368,2.2535,8204.444,4.319,602.204,24.7841,10.956,0,176.011,28.4361,-0.5801,-0.0147,0,0,1551318,-577.4199,0,0,0,1.55E+08,0,0,51.1394,30.7221,621.9648,599.67,575.7752,-11.5058,4.2717,-2.0439,-2.274,-0.9667,624.6722,599.67,573.0678,47.2523,22.2501,-4.3521,4.3423,-2.0439,-2.3446,599.1367,21.7168,51.6044,0.5155,-10.8574,-13.2412,-0.0462,-0.0587
1,158.8,158.8,595.05,89874.76,571,0,0.185,570.6855,8.5884,0,0,0.0528,0.0522,0.0518,0,0,0,14.421,0,0,100,0,0,0,0,0,0,0,0,0,0,607.8141,-1308.408,-7.3013,-3.5044,0,0,0,0,0,0,0,0,0,0,5.071,4.3481,2.2476,2.2476,617.5864,46.9009,24.3645,22.5364,1.0379,1.925,8210.997,4.3971,602.5621,31.8766,11.2682,0,120.7927,35.6327,-0.3145,-0.0067,0,0,1551318,-570.6855,0,0,0,1.55E+08,0,0,51.1454,30.7102,623.0576,599.8388,575.868,-15.962,4.3481,-2.1297,-2.2669,-2.8179,627.9496,599.8388,570.9759,57.2641,29.1533,0.2904,4.9019,-2.1297,-2.8207,599.5881,28.9026,56.9737,0.5066,197.1904,-17.0393,-0.0485,-0.093
1,161.8,161.8,595.25,89487.17,574,0,0.1862,572.7714,9.5092,0,0,0.0528,0.0522,0.0518,0,0,0,15.9556,0,0,100,0,0,0,0,0,0,0,0,0,0,607.5391,-824.3195,3.1666,4.6783,0,0,0,0,0,0,0,0,0,0,5.0977,4.8143,2.4977,2.4977,617.8122,45.0408,22.4786,22.5622,1.0379,2.0037,8251.213,4.8747,602.7708,29.9994,11.2811,0,93.1997,33.7597,-1.2286,-0.0273,0,0,1551318,-572.7714,0,0,0,1.55E+08,0,0,51.2625,30.772,623.587,599.8597,576.7946,21.1584,4.8143,-2.3938,-2.4801,1.2308,631.7354,599.8597,568.6462,58.964,27.0883,-4.1252,4.9167,-2.3938,-2.5825,600.0804,27.309,63.0892,0.4948,-14.2936,21.0624,-0.0596,0.0609
1,164.8,164.8,595.15,88956.24,579,0,0.1727,577.9172,9.8094,0,0,0.0528,0.0522,0.0518,0,0,0,16.4244,0,0,100,0,0,0,0,0,0,0,0,0,0,608.1517,-123.3989,3.1409,0.8229,0,0,0,0,0,0,0,0,0,0,5.0913,4.9663,2.5796,2.5796,616.0512,38.134,17.2329,20.9012,1.0351,2.2129,8264.41,5.0306,602.1171,24.2,10.4506,0,113.8614,27.6835,-1.0828,-0.0284,0,0,1551318,-577.9172,0,0,0,1.55E+08,0,0,51.2918,30.7773,620.4863,600.0259,575.644,3.7141,4.9663,-2.508,-2.5212,1.2233,620.7919,600.0259,575.3385,42.8747,22.1087,-2.5787,5.0649,-2.508,-2.6198,598.7188,20.8016,45.4534,0.5431,-16.6265,4.7029,-0.0629,0.0591
1,167.8,167.8,595.17,88343.94,570,0,0.186,569.7762,10.5248,0,0,0.0528,0.0522,0.0518,0,0,0,17.6061,0,0,100,0,0,0,0,0,0,0,0,0,0,607.4535,601.8072,-7.9121,-4.9982,0,0,0,0,0,0,0,0,0,0,5.1235,5.3285,2.7757,2.7757,617.5846,47.8084,25.3938,22.4146,1.0377,1.8827,8296.029,5.4028,602.6415,32.8653,11.2073,0,99.3976,36.6011,-0.2238,-0.0047,0,0,1551318,-569.7762,0,0,0,1.55E+08,0,0,51.3779,30.8161,623.2997,599.7753,576.7606,-22.4381,5.3285,-2.7323,-2.6693,-3.0982,632.3557,599.7753,567.7047,62.5795,29.9992,-2.0715,5.8893,-2.7323,-3.2301,599.9453,30.1691,64.651,0.4961,-30.2098,-21.9789,-0.0731,-0.0787
1,170.8,170.8,595.12,88070.38,580,0,0.178,579.6061,11.4305,0,0,0.0528,0.0522,0.0518,0,0,0,19.1004,0,0,100,0,0,0,0,0,0,0,0,0,0,607.7969,1089.694,-1.0002,2.4281,0,0,0,0,0,0,0,0,0,0,5.1392,5.787,3.0255,3.0255,616.477,36.8709,15.5139,21.357,1.0359,2.3766,8336.402,5.875,602.239,22.6329,10.6785,0,121.4856,26.1924,-0.3939,-0.0107,0,0,1551318,-579.6061,0,0,0,1.55E+08,0,0,51.4946,30.8775,621.3659,599.8719,576.1343,10.8239,5.787,-2.9931,-2.8797,-0.3944,623.8226,599.8719,573.6776,44.2165,20.2658,-5.9285,5.796,-2.9931,-2.8887,599.124,19.5179,50.145,0.5224,-7.4583,12.7879,-0.0858,-0.0217
1,173.8,173.8,595.26,87344.25,573,0,0.1843,573.502,11.586,0,0,0.0528,0.0522,0.0518,0,0,0,19.3713,0,0,100,0,0,0,0,0,0,0,0,0,0,607.7134,1931.695,4.4884,3.5619,0,0,0,0,0,0,0,0,0,0,5.1508,5.8657,3.0685,3.0685,617.3523,43.8503,21.758,22.0923,1.0371,2.0154,8343.372,5.9561,602.6241,29.1221,11.0462,0,92.9499,32.8042,0.502,0.0114,0,0,1551318,-573.502,0,0,0,1.55E+08,0,0,51.5021,30.867,622.7939,599.9268,576.6317,15.8648,5.8657,-3.0778,-2.8762,1.7715,627.7204,599.9268,571.7051,54.2184,26.4248,-1.7969,6.0417,-3.0778,-3.0522,599.7841,26.2821,56.0153,0.5038,-30.1733,17.2514,-0.0883,0.0604
1,176.8,176.8,595.26,86933.64,575,0,0.188,573.2325,12.5847,0,0,0.0528,0.0522,0.0518,0,0,0,20.9877,0,0,100,0,0,0,0,0,0,0,0,0,0,607.3673,2465.723,-6.9896,-4.6614,0,0,0,0,0,0,0,0,0,0,5.1813,6.3714,3.3465,3.3465,617.6718,44.4393,22.0275,22.4118,1.0377,2.0174,8388.436,6.4786,602.7307,29.4982,11.2059,0,92.6172,33.2334,-1.7675,-0.0398,0,0,1551318,-573.2325,0,0,0,1.55E+08,0,0,51.6321,30.9354,623.4982,599.7962,577.1632,-20.6004,6.3714,-3.3662,-3.1096,-2.7803,631.3325,599.7962,569.3289,58.1,26.5637,-3.9036,6.7629,-3.3662,-3.5011,600.1525,26.92,62.0036,0.4914,-14.8837,-20.8216,-0.1044,-0.0646
1,179.8,179.8,594.99,86397.92,577,0,0.1735,578.6136,12.8516,0,0,0.0528,0.0522,0.0518,0,0,0,21.4071,0,0,100,0,0,0,0,0,0,0,0,0,0,608.1495,3178.019,-7.0827,-0.7952,0,0,0,0,0,0,0,0,0,0,5.1717,6.5065,3.4211,3.4211,615.6377,37.0241,16.3764,20.6477,1.0347,2.2608,8400.558,6.6184,601.8726,23.259,10.3239,0,148.8964,26.7003,1.6136,0.0436,0,0,1551318,-578.6136,0,0,0,1.55E+08,0,0,51.6575,30.9379,619.9009,599.9192,575.3406,-3.5079,6.5065,-3.473,-3.1423,-2.8224,620.1754,599.9192,575.0661,41.5618,21.3056,-3.5475,6.903,-3.473,-3.5388,598.3869,19.7733,45.1093,0.551,-11.7158,-4.4737,-0.1088,-0.0638
1,182.8,182.8,595.45,85782.49,572,0,0.186,571.9896,13.6485,0,0,0.0528,0.0522,0.0518,0,0,0,22.711,0,0,100,0,0,0,0,0,0,0,0,0,0,607.5859,3862.292,4.707,4.9898,0,0,0,0,0,0,0,0,0,0,5.2098,6.9099,3.645,3.645,617.4972,45.5076,23.4604,22.0472,1.037,1.9398,8436.961,7.0366,602.7991,30.8095,11.0236,0,73.7768,34.484,-0.0104,-0.0002,0,0,1551318,-571.9896,0,0,0,1.55E+08,0,0,51.7579,30.9858,623.1175,599.9947,577.3469,21.8768,6.9099,-3.717,-3.3159,1.8873,631.8918,599.9947,568.5726,59.9022,28.0051,-3.4171,7.0812,-3.717,-3.4872,600.153,28.1634,63.3193,0.4963,-17.5301,21.8547,-0.123,0.053
1,185.8,185.8,594.86,85492.06,580,0,0.1796,580.312,14.6632,0,0,0.0528,0.0522,0.0518,0,0,0,24.3562,0,0,100,0,0,0,0,0,0,0,0,0,0,607.8519,4369.832,-3.238,-2.5146,0,0,0,0,0,0,0,0,0,0,5.2263,7.4237,3.9322,3.9322,616.0339,35.7219,14.548,21.1739,1.0356,2.4555,8483.786,7.5706,601.918,21.606,10.587,0,200.2551,25.135,0.312,0.0087,0,0,1551318,-580.312,0,0,0,1.55E+08,0,0,51.8928,31.0574,620.687,599.7243,575.494,-10.9364,7.4237,-4.0095,-3.5566,-1.3088,623.1945,599.7243,572.9866,42.8825,19.4123,-7.3254,7.5012,-4.0095,-3.6341,598.6351,18.3231,50.2079,0.5325,-5.8539,-12.9132,-0.1424,-0.0418
1,188.8,188.8,595.36,84742.72,575,0,0.186,573.4564,14.7518,0,0,0.0528,0.0522,0.0518,0,0,0,24.5111,0,0,100,0,0,0,0,0,0,0,0,0,0,607.8715,5188.597,-8.3735,-3.5277,0,0,0,0,0,0,0,0,0,0,5.2394,7.4685,3.9574,3.9574,617.2792,43.8228,21.9036,21.9192,1.0368,2.0007,8487.894,7.6173,602.6664,29.21,10.9596,0,82.6877,32.8632,-1.5436,-0.0352,0,0,1551318,-573.4564,0,0,0,1.55E+08,0,0,51.8917,31.042,622.6275,600.043,576.7322,-15.3375,7.4685,-4.0754,-3.5374,-3.3856,627.2811,600.043,572.0785,53.8247,26.5866,-1.3779,7.9667,-4.0754,-4.0356,599.8009,26.3445,55.2026,0.5066,-39.0629,-16.8788,-0.1443,-0.0583
1,191.8,191.8,595.07,84397.02,574,0,0.1885,575.2446,15.7987,0,0,0.0528,0.0522,0.0518,0,0,0,26.226,0,0,100,0,0,0,0,0,0,0,0,0,0,607.8226,5656.14,3.4028,4.6479,0,0,0,0,0,0,0,0,0,0,5.2685,7.9985,4.2564,4.2564,617.1523,41.9077,19.8254,22.0823,1.0371,2.1138,8536.79,8.1699,602.4307,27.1861,11.0412,0,124.2459,30.8666,1.2446,0.0297,0,0,1551318,-575.2446,0,0,0,1.55E+08,0,0,52.033,31.1181,622.4708,599.8425,576.0961,20.0393,7.9985,-4.3744,-3.7896,1.3874,629.9302,599.8425,568.6367,54.6856,24.5979,-6.6079,8.0796,-4.3744,-3.8707,599.4698,24.2252,61.2935,0.5091,-8.2758,20.4173,-0.1655,0.0401
1,194.8,194.8,595.11,83941.72,581,0,0.1698,580.4718,16.1231,0,0,0.0528,0.0522,0.0518,0,0,0,26.7269,0,0,100,0,0,0,0,0,0,0,0,0,0,608.1239,6344.765,3.3319,0.8786,0,0,0,0,0,0,0,0,0,0,5.2592,8.1628,4.3496,4.3496,614.9628,34.491,14.6382,19.8528,1.0334,2.3562,8552.063,8.3416,601.7276,21.2558,9.9264,0,124.6399,24.5646,-0.5282,-0.0153,0,0,1551318,-580.4718,0,0,0,1.55E+08,0,0,52.0679,31.1265,618.8961,599.9791,575.7667,3.7792,8.1628,-4.4954,-3.8397,1.3617,619.2248,599.9791,575.438,38.753,19.5073,-5.0338,8.2396,-4.4954,-3.9165,598.2139,17.7422,43.7868,0.5605,-7.6986,4.9701,-0.1723,0.039
1,197.8,197.8,595.21,83296.55,572,0,0.1849,571.8169,16.8683,0,0,0.0528,0.0522,0.0518,0,0,0,27.9328,0,0,100,0,0,0,0,0,0,0,0,0,0,607.4837,7052.16,-8.7007,-4.9845,0,0,0,0,0,0,0,0,0,0,5.2962,8.54,4.5645,4.5645,616.7456,44.9287,23.3931,21.5356,1.0362,1.9206,8587.333,8.7363,602.3885,30.5716,10.7678,0,96.8463,34.1609,-0.1831,-0.0041,0,0,1551318,-571.8169,0,0,0,1.55E+08,0,0,52.1633,31.1707,622.0365,599.801,576.9856,-21.3157,8.54,-4.7283,-4.0008,-3.5766,630.5232,599.801,568.4989,58.7063,27.9841,-3.318,9.0308,-4.7283,-4.4916,599.6077,27.7908,62.0243,0.5047,-17.6933,-21.7097,-0.1891,-0.0518
1,200.8,200.8,595.08,82998.98,581,0,0.1773,581.6405,17.906,0,0,0.0528,0.0522,0.0518,0,0,0,29.5661,0,0,100,0,0,0,0,0,0,0,0,0,0,607.6948,7555.548,-1.0516,2.4269,0,0,0,0,0,0,0,0,0,0,5.317,9.0654,4.8662,4.8662,615.6109,33.9704,13.4395,20.5309,1.0345,2.5277,8636.949,9.2877,601.9236,20.2831,10.2655,0,132.4239,23.705,0.6405,0.0189,0,0,1551318,-581.6405,0,0,0,1.55E+08,0,0,52.3052,31.2463,620.1554,599.7977,576.3627,10.2917,9.0654,-5.0283,-4.2507,-0.4359,622.4534,599.7977,574.0646,40.8129,18.1572,-7.5759,9.0725,-5.0283,-4.2578,598.7719,17.1314,48.3888,0.5318,-5.3872,12.5872,-0.2136,-0.0154
1,203.8,203.8,595.09,82286.13,575,0,0.1845,575.418,17.9952,0,0,0.0528,0.0522,0.0518,0,0,0,29.7141,0,0,100,0,0,0,0,0,0,0,0,0,0,608.0141,8390.29,4.6144,3.531,0,0,0,0,0,0,0,0,0,0,5.3268,9.1106,4.8922,4.8922,616.439,41.021,19.672,21.349,1.0359,2.0852,8641.244,9.3352,602.2064,26.7884,10.6745,0,120.6304,30.3465,0.418,0.0102,0,0,1551318,-575.418,0,0,0,1.55E+08,0,0,52.3041,31.2304,621.2905,599.9219,575.9371,14.9688,9.1106,-5.095,-4.2312,1.9135,625.7854,599.9219,571.4421,50.3674,24.5039,-3.976,9.2464,-5.095,-4.367,599.0498,23.6318,54.3434,0.5241,-12.6679,16.7143,-0.2156,0.0408
1,206.8,206.8,595.65,81843.33,575,0,0.1879,574.8929,19.0624,0,0,0.0528,0.0522,0.0518,0,0,0,31.4509,0,0,100,0,0,0,0,0,0,0,0,0,0,607.2776,8936.225,-7.5665,-4.6646,0,0,0,0,0,0,0,0,0,0,5.3658,9.6509,5.2054,5.2054,617.2609,42.368,20.7571,21.6109,1.0363,2.0411,8692.92,9.9042,602.8537,27.9608,10.8055,0,63.8994,31.5626,-0.1071,-0.0025,0,0,1551318,-574.8929,0,0,0,1.55E+08,0,0,52.451,31.3081,622.988,599.9963,578.4321,-19.6037,9.6509,-5.4056,-4.488,-3.165,630.3852,599.9963,571.035,55.4923,25.1034,-3.8579,9.9967,-5.4056,-4.8338,600.4722,25.5793,59.3502,0.488,-14.3841,-20.6733,-0.2427,-0.0447
1,209.8,209.8,594.83,81303.06,579,0,0.1712,580.1107,19.3314,0,0,0.0528,0.0522,0.0518,0,0,0,31.8487,0,0,100,0,0,0,0,0,0,0,0,0,0,607.9843,9650.442,-7.6424,-0.8103,0,0,0,0,0,0,0,0,0,0,5.3498,9.7871,5.2848,5.2848,614.4927,34.382,14.7193,19.6627,1.0331,2.3358,8706.044,10.0479,601.3842,21.2735,9.8314,0,215.5181,24.5507,1.1107,0.0323,0,0,1551318,-580.1107,0,0,0,1.55E+08,0,0,52.4784,31.3113,618.2843,599.7456,575.3716,-3.3989,9.7871,-5.5137,-4.5229,-3.2028,618.5518,599.7456,575.1041,38.4411,19.6349,-5.0066,10.137,-5.5137,-4.8728,597.8005,17.6898,43.4477,0.5672,-7.6781,-4.5007,-0.2495,-0.0443
1,212.8,212.8,595.42,80690.81,574,0,0.1852,573.7227,20.137,0,0,0.0528,0.0522,0.0518,0,0,0,33.1654,0,0,100,0,0,0,0,0,0,0,0,0,0,607.3936,10339.56,4.7057,4.9988,0,0,0,0,0,0,0,0,0,0,5.3925,10.1949,5.5236,5.5236,616.5973,42.8746,21.6973,21.1773,1.0356,1.976,8745.578,10.479,602.4791,28.7564,10.5887,0,77.8476,32.286,-0.2773,-0.0065,0,0,1551318,-573.7227,0,0,0,1.55E+08,0,0,52.5856,31.3626,621.8977,599.8932,577.7258,20.8334,10.1949,-5.7626,-4.7031,1.9848,630.1732,599.8932,569.4503,56.4505,26.1705,-4.2724,10.326,-5.7626,-4.8342,599.8389,26.1162,60.7229,0.5013,-13.2128,21.6642,-0.2708,0.0371
1,215.8,215.8,595.05,80405.51,581,0,0.18,581.8986,21.2409,0,0,0.0528,0.0522,0.0518,0,0,0,34.9855,0,0,100,0,0,0,0,0,0,0,0,0,0,607.8301,10846.49,-3.67,-2.4758,0,0,0,0,0,0,0,0,0,0,5.4166,10.7538,5.8535,5.8535,615.4985,33.5999,13.1514,20.4485,1.0344,2.5549,8800.347,11.0715,601.8661,19.9675,10.2243,0,139.482,23.3757,0.8986,0.0267,0,0,1551318,-581.8986,0,0,0,1.55E+08,0,0,52.7413,31.4461,619.9599,599.8237,576.178,-10.2248,10.7538,-6.0821,-4.9739,-1.5622,622.2301,599.8237,573.9078,40.3315,17.9251,-7.9908,10.831,-6.0821,-5.0511,598.6539,16.7553,48.3223,0.5363,-5.0472,-12.5181,-0.3022,-0.0318
1,218.8,218.8,595.38,79687.93,576,0,0.1847,575.1672,21.2712,0,0,0.0528,0.0522,0.0518,0,0,0,35.0257,0,0,100,0,0,0,0,0,0,0,0,0,0,607.6918,11650.44,-8.779,-3.5262,0,0,0,0,0,0,0,0,0,0,5.4251,10.7691,5.8626,5.8626,616.3587,41.1915,20.2128,20.9787,1.0352,2.0379,8801.855,11.0878,602.3729,27.2058,10.4894,0,82.7473,30.7022,-0.8328,-0.0202,0,0,1551318,-575.1672,0,0,0,1.55E+08,0,0,52.7321,31.4257,621.3869,599.9774,577.2209,-14.5649,10.7691,-6.1315,-4.9405,-3.7363,625.7576,599.9774,572.8502,50.5905,24.8102,-2.317,11.2015,-6.1315,-5.3729,599.5284,24.3612,52.9075,0.5127,-21.8345,-16.7035,-0.3029,-0.0417
1,221.8,221.8,595.2,79327.52,576,0,0.1878,576.775,22.3634,0,0,0.0528,0.0522,0.0518,0,0,0,36.8562,0,0,100,0,0,0,0,0,0,0,0,0,0,607.9324,12118,3.2673,4.6646,0,0,0,0,0,0,0,0,0,0,5.4593,11.3221,6.1921,6.1921,616.4003,39.6253,18.425,21.2003,1.0356,2.1506,8856.744,11.6761,602.2668,25.4918,10.6002,0,104.7496,29.0252,0.775,0.0196,0,0,1551318,-576.775,0,0,0,1.55E+08,0,0,52.8883,31.5101,621.3249,599.9536,576.4333,19.0926,11.3221,-6.4468,-5.2115,1.4032,628.3467,599.9536,569.4114,51.5717,23.1786,-7.3636,11.3814,-6.4468,-5.2708,599.2372,22.4622,58.9353,0.5182,-7.0036,20.1924,-0.3362,0.0288
1,224.8,224.8,594.74,78890,582,0,0.1687,581.8958,22.6885,0,0,0.0528,0.0522,0.0518,0,0,0,37.3596,0,0,100,0,0,0,0,0,0,0,0,0,0,608.2426,12758.4,3.1829,0.8543,0,0,0,0,0,0,0,0,0,0,5.446,11.4867,6.2908,6.2908,613.7573,31.8615,12.8442,19.0173,1.032,2.4806,8873.215,11.8517,601.0791,19.1833,9.5087,0,288.584,22.3529,-0.1042,-0.0033,0,0,1551318,-581.8958,0,0,0,1.55E+08,0,0,52.9264,31.5209,617.025,599.78,574.8565,3.4881,11.4867,-6.5661,-5.2664,1.3704,617.3116,599.78,574.5699,35.4158,17.8842,-7.3259,11.5426,-6.5661,-5.3223,597.2205,15.3247,42.7417,0.5898,-4.8343,4.6969,-0.3458,0.0281
1,227.8,227.8,595.26,78294.61,574,0,0.186,573.4146,23.4274,0,0,0.0528,0.0522,0.0518,0,0,0,38.5822,0,0,100,0,0,0,0,0,0,0,0,0,0,607.3205,13429.76,-8.9313,-4.9892,0,0,0,0,0,0,0,0,0,0,5.4903,11.8608,6.5161,6.5161,616.1347,42.7201,21.8454,20.8747,1.0351,1.9556,8910.876,12.2513,602.2183,28.8037,10.4374,0,92.842,32.2828,-0.5854,-0.0137,0,0,1551318,-573.4146,0,0,0,1.55E+08,0,0,53.027,31.5683,621.2538,599.7606,577.5176,-20.2488,11.8608,-6.7977,-5.4321,-3.8685,629.1888,599.7606,569.5825,55.7742,26.346,-3.8321,12.2832,-6.7977,-5.8545,599.5107,26.096,59.6063,0.5063,-14.5545,-21.3991,-0.369,-0.0381
1,230.8,230.8,595.18,77996.34,583,0,0.1778,582.7488,24.5117,0,0,0.0528,0.0522,0.0518,0,0,0,40.3053,0,0,100,0,0,0,0,0,0,0,0,0,0,607.9158,13886.37,-1.1399,2.4528,0,0,0,0,0,0,0,0,0,0,5.5146,12.4097,6.8494,6.8494,615.0076,32.2589,12.4312,19.8276,1.0333,2.595,8966.718,12.8394,601.7892,19.0404,9.9138,0,115.8058,22.3451,-0.2512,-0.0078,0,0,1551318,-582.7488,0,0,0,1.55E+08,0,0,53.185,31.6538,619.1769,599.9318,576.4567,9.8641,12.4097,-7.1116,-5.7035,-0.4983,621.3445,599.9318,574.2891,38.5957,17.183,-8.4597,12.4166,-7.1116,-5.7104,598.5218,15.773,47.0554,0.5449,-4.5623,12.3938,-0.4054,-0.0128
1,233.8,233.8,595.07,77355.44,578,0,0.1854,576.9096,24.5576,0,0,0.0528,0.0522,0.0518,0,0,0,40.3828,0,0,100,0,0,0,0,0,0,0,0,0,0,608.1298,14634.4,4.3517,3.5246,0,0,0,0,0,0,0,0,0,0,5.5226,12.433,6.8636,6.8636,615.736,38.8264,18.1604,20.666,1.0347,2.138,8969.104,12.8644,601.9587,25.0491,10.333,0,126.9313,28.4934,-1.0904,-0.0281,0,0,1551318,-576.9096,0,0,0,1.55E+08,0,0,53.1791,31.6362,620.2148,599.9413,575.8914,14.1741,12.433,-7.162,-5.6774,1.9023,624.3599,599.9413,571.7463,47.4503,23.0317,-5.1633,12.5324,-7.162,-5.7768,598.6826,21.7729,52.6136,0.5359,-9.1899,16.301,-0.4064,0.03
1,236.8,236.8,595.45,76979.19,575,0,0.1901,575.9524,25.6108,0,0,0.0528,0.0522,0.0518,0,0,0,42.0797,0,0,100,0,0,0,0,0,0,0,0,0,0,607.4603,15085.92,-7.9612,-4.6382,0,0,0,0,0,0,0,0,0,0,5.5635,12.9662,7.1904,7.1904,616.5191,40.5667,19.4976,21.0691,1.0354,2.0806,9024.052,13.4377,602.4731,26.5207,10.5346,0,77.7396,30.0322,0.9524,0.0235,0,0,1551318,-575.9524,0,0,0,1.55E+08,0,0,53.3339,31.7198,621.7923,599.9291,577.8242,-18.4866,12.9662,-7.4678,-5.9418,-3.5113,628.532,599.9291,571.0845,52.5796,23.9767,-4.8679,13.2868,-7.4678,-6.2624,599.8485,23.8961,57.4475,0.5021,-10.8013,-20.0304,-0.4434,-0.0342
1,239.8,239.8,595.28,76548.25,581,0,0.1698,581.5865,25.8876,0,0,0.0528,0.0522,0.0518,0,0,0,42.4789,0,0,100,0,0,0,0,0,0,0,0,0,0,608.4689,15702.3,-8.2903,-0.8038,0,0,0,0,0,0,0,0,0,0,5.5503,13.1063,7.2768,7.2768,614.0662,32.4797,13.6935,18.7862,1.0316,2.3719,9038.602,13.5887,601.5421,19.9556,9.3931,0,100.4482,23.0866,0.5865,0.0181,0,0,1551318,-581.5865,0,0,0,1.55E+08,0,0,53.3663,31.7274,617.4231,600.1975,575.9423,-3.197,13.1063,-7.5739,-5.986,-3.6642,617.6681,600.1975,575.6974,36.0816,18.611,-5.8891,13.4517,-7.5739,-6.3314,597.8543,16.2678,41.9707,0.5837,-6.1268,-4.3814,-0.4536,-0.0342
1,242.8,242.8,595.2,75982.17,575,0,0.186,574.8654,26.7237,0,0,0.0528,0.0522,0.0518,0,0,0,43.8504,0,0,100,0,0,0,0,0,0,0,0,0,0,607.3215,16287.77,4.2151,5.0136,0,0,0,0,0,0,0,0,0,0,5.5921,13.5296,7.5391,7.5391,615.677,40.8116,20.3346,20.477,1.0344,2.007,9082.848,14.0458,602.0257,27.1603,10.2385,0,102.2035,30.5731,-0.1346,-0.0033,0,0,1551318,-574.8654,0,0,0,1.55E+08,0,0,53.4865,31.7878,620.5777,599.7185,577.4425,19.801,13.5296,-7.8286,-6.1851,1.8762,628.2888,599.7185,569.7314,53.4234,24.8531,-5.134,13.6185,-7.8286,-6.274,599.2463,24.3808,58.5574,0.5121,-10.4058,21.2774,-0.4841,0.0274
1,245.8,245.8,594.94,75785.31,583,0,0.1807,582.5029,27.8436,0,0,0.0528,0.0522,0.0518,0,0,0,45.6941,0,0,100,0,0,0,0,0,0,0,0,0,0,607.6776,16693.81,-4.0148,-2.502,0,0,0,0,0,0,0,0,0,0,5.6201,14.0966,7.8934,7.8934,614.7024,32.1995,12.4371,19.7624,1.0332,2.589,9142.799,14.66,601.5275,19.0246,9.8812,0,172.0241,22.3183,-0.4971,-0.0154,0,0,1551318,-582.5029,0,0,0,1.55E+08,0,0,53.6556,31.8806,618.8709,599.6875,576.291,-9.7865,14.0966,-8.1516,-6.4723,-1.8044,621.0125,599.6875,574.1494,38.5096,17.1846,-8.3535,14.1754,-8.1516,-6.5511,598.2831,15.7802,46.8631,0.545,-4.61,-12.3436,-0.5273,-0.0259
1,248.8,248.8,595.23,75127.92,578,0,0.1847,576.2672,27.8452,0,0,0.0528,0.0522,0.0518,0,0,0,45.6972,0,0,100,0,0,0,0,0,0,0,0,0,0,607.8412,17413.62,-8.9154,-3.5177,0,0,0,0,0,0,0,0,0,0,5.6268,14.0974,7.8939,7.8939,615.4295,39.1623,18.9628,20.1995,1.0339,2.0652,9142.884,14.6609,601.9631,25.6959,10.0998,0,100.0738,29.0626,-1.7328,-0.0442,0,0,1551318,-576.2672,0,0,0,1.55E+08,0,0,53.6433,31.8595,619.9222,599.9291,576.7856,-13.7641,14.0974,-8.1886,-6.4358,-4.0054,623.9399,599.9291,572.7679,47.6727,23.6619,-3.4993,14.4809,-8.1886,-6.8193,598.8789,22.6118,51.172,0.5308,-13.6235,-16.2723,-0.527,-0.0323
1,251.8,251.8,595.33,74834.84,577,0,0.1886,577.4531,28.9139,0,0,0.0528,0.0522,0.0518,0,0,0,47.5138,0,0,100,0,0,0,0,0,0,0,0,0,0,607.9178,17806.99,2.7867,4.6546,0,0,0,0,0,0,0,0,0,0,5.6661,14.6385,8.2353,8.2353,615.8242,38.3711,17.8769,20.4942,1.0344,2.1464,9200.84,15.2492,602.1614,24.7083,10.2471,0,90.0453,28.124,0.4531,0.0118,0,0,1551318,-577.4531,0,0,0,1.55E+08,0,0,53.8061,31.9487,620.5035,600.0197,576.9307,18.0444,14.6385,-8.4978,-6.7108,1.2637,627.0057,600.0197,570.4285,49.5526,22.5666,-7.0246,14.6758,-8.4978,-6.7481,599.1513,21.6982,56.5772,0.523,-7.0542,19.8165,-0.5701,0.0211
1,252.2,252.2,594.92,74726.08,576,0,0.1881,575.9001,28.8835,0,0,0.0528,0.0522,0.0518,0,0,0,47.4671,0,0,100,0,0,0,0,0,0,0,0,0,0,607.4032,17911.11,3.6649,5.0571,0,0,0,0,0,0,0,0,0,0,5.6609,14.6231,8.2256,8.2256,615.37,39.4699,19.0199,20.45,1.0344,2.0752,9199.181,15.2325,601.7366,25.8365,10.225,0,165.3024,29.2449,-0.0999,-0.0025,0,0,1551318,-575.9001,0,0,0,1.55E+08,0,0,53.7995,31.9428,620.0725,599.5705,576.6761,19.611,14.6231,-8.4949,-6.6972,1.6613,627.6216,599.5705,569.127,51.7215,23.6704,-6.7731,14.6876,-8.4949,-6.7617,598.773,22.8729,58.4946,0.5204,-7.6363,21.0538,-0.569,0.0241