File: datas/d100-90-0.25_1.5.csv
Stage Number,Time since start of test (s),Time since start of stage (s),Radial Pressure (kPa),Radial Volume (mm3),Back Pressure (kPa),Back Volume (mm3),Load Cell (kN),Pore Pressure (kPa),Axial Displacement (mm),L/C Pressure (kPa),L/C Volume (mm3),Local Axial 1,Local Axial 2,Local Radial,Base Pressure (kPa),Base Volume (mm3),Back Differential Pressure (kPa),Axial Displacement 2 (mm),Pore Air Pressure (kPa),Pore Air Volume (mm3),Atmospheric Pressure (kPa),Temperature (°C),Mid Plane PWP (kPa),Back to Cell Differential (kPa),Total Volume Change (mm3),Undefined Tx 1,Undefined Tx 2,Undefined Tx 3,Undefined Tx. 4,HCA secondary control axial load (kN),HCA secondary control torque,Internal Cell Pr. (kPa),Internal Cell Vol. (mm3),Rotational Displ. (mm),Torque,Local Int Defmn 1 (mm),Local Int Defmn 2 (mm),Circumf. Defmn 1 (mm),Circumf. Defmn 2 (mm),Circumf. Defmn 3 (mm),Outer Cell Pr 2 (kPa),Internal cell Pr 2 (kPa),Rotation 2 (°),Secondary Cell Pr (kPa),Secondary Back Pr (kPa),Axial Force (kN),Axial Strain (%),Av Diameter Change (mm),Radial Strain (%),Axial Stress (kPa),Eff. Axial Stress (kPa),Eff. Radial Stress (kPa),Deviator Stress (kPa),Total Stress Ratio (%),Eff. Stress Ratio (%),Current Area (mm2),Shear Strain (%),Cambridge p (kPa),Eff. Cambridge p' (kPa),Max Shear Stress t,Volume Change (mm3),B Value,Mean Stress s/Eff. Axial Stress 2,Excess PWP (kPa),PWP Ratio,Lower Chamber Displacement (mm),Lower Chamber Axial Load (kPa),Specimen Air Volume (mm3),Matric Suction (kPa),Voids ratio,Degree of Saturation (°),Specimen Water Volume (mm3),kRT constant,Permeability IN,Permeability OUT,HCA Outer Rad,HCA Inner Rad,HCA Sigma Z (kPa),HCA Sigma R (kPa),HCA Sigma Theta (kPa),HCA Tau Theta Z,HCA Ez,HCA Er,HCA Etheta,HCA Gamma,HCA Sigma1,HCA Sigma2,HCA Sigma3,HCA Eff Sigma1,HCA Eff Sigma2,HCA Eff Sigma3,HCA E1,HCA E2,HCA E3,HCA P,HCA Eff P,HCA Q,HCA B,HCA Eff R,HCA Alpha,HCA Ev,HCA E1 rtv
1,0,0,584.9412,45221.98,482,0,-0.1879,484.1439,0,0,0,0.0528,0.0522,0.0518,0,0,0,9.7505,0,0,100,0,0,0,0,0,0,0,0,0,0,572.2621,103784.9,0.0023,-0.0006,0,0,0,0,0,0,0,0,0,0,4.4062,0,0,0,561.0153,76.8714,100.7973,-23.9259,0.9591,0.7626,7853.975,0,576.9659,92.822,-11.963,0,2.0194,88.8344,2.1439,0.0279,0,0,1511891,-484.1439,0,0,0,1.51E+08,0,0,48.2533,26.9886,553.3317,580.3934,601.0332,-0.0031,0,-5.9474,6.3237,0.0008,601.0332,580.3934,553.3318,116.8893,96.2495,69.1879,6.3237,-5.9474,0,578.2527,94.1089,47.7014,0.5673,1.6894,-89.9963,0.3763,89.9999
1,0.8,0.8,585.0539,45304.72,483,0,-0.1879,484.4391,-0.0038,0,0,0.0528,0.0522,0.0518,0,0,0,9.744,0,0,100,0,0,0,0,0,0,0,0,0,0,571.9869,103726.6,0.1338,2.4886,0,0,0,0,0,0,0,0,0,0,4.407,-0.002,-0.001,-0.001,561.1284,76.6893,100.6148,-23.9255,0.9591,0.7622,7853.818,-0.002,577.0787,92.6396,-11.9628,0,2.5102,88.6521,1.4391,0.0188,0,0,1511891,-484.4391,0,0,0,1.51E+08,0,0,48.2538,26.9901,553.621,580.3668,601.64,12.8187,-0.002,-5.943,6.3209,0.0469,604.8477,580.3668,550.4133,120.4086,95.9277,65.9742,6.3211,-5.943,-0.0022,578.5427,94.1035,54.4344,0.5503,1.8251,75.9511,0.3759,89.9963
1,1.8,1.8,584.8502,45326.44,484,0,-0.1847,485.4868,-0.0206,0,0,0.0528,0.0522,0.0518,0,0,0,9.7184,0,0,100,0,0,0,0,0,0,0,0,0,0,572.0916,103709.1,0.3903,4.6831,0,0,0,0,0,0,0,0,0,0,4.4082,-0.0107,-0.0053,-0.0053,561.33,75.8432,99.3634,-23.5202,0.9598,0.7633,7853.135,-0.0107,577.0102,91.5234,-11.7601,0,-21.1837,87.6033,1.4868,0.0196,0,0,1511891,-485.4868,0,0,0,1.51E+08,0,0,48.2521,26.9895,553.9107,580.2737,601.0452,24.1252,-0.0107,-5.9381,6.3242,0.1367,611.2039,580.2737,543.752,125.7171,94.7869,58.2652,6.3257,-5.9381,-0.0122,578.4099,92.9231,67.4519,0.5414,2.1577,67.1649,0.3754,89.9893
1,2.8,2.8,585.2338,45401.06,486,0,-0.1872,487.6214,-0.0429,0,0,0.0528,0.0522,0.0518,0,0,0,9.6899,0,0,100,0,0,0,0,0,0,0,0,0,0,572.3344,103681.5,0.621,5.02,0,0,0,0,0,0,0,0,0,0,4.4082,-0.0223,-0.0111,-0.0111,561.3951,73.7737,97.6124,-23.8388,0.9593,0.7558,7852.224,-0.0223,577.2876,89.6662,-11.9194,0,11.1023,85.6931,1.6214,0.022,0,0,1511891,-487.6214,0,0,0,1.51E+08,0,0,48.2497,26.9888,553.8569,580.6068,601.6085,25.8651,-0.0223,-5.9306,6.3285,0.2174,612.9329,580.6068,542.5324,125.3115,92.9854,54.911,6.3322,-5.9306,-0.026,578.6907,91.0693,70.4005,0.5408,2.2821,66.3549,0.3756,89.9831
1,3.8,3.8,584.7842,45414.02,486,0,-0.187,488.8926,-0.0392,0,0,0.0528,0.0522,0.0518,0,0,0,9.674,0,0,100,0,0,0,0,0,0,0,0,0,0,572.3417,103645.6,0.5253,3.5497,0,0,0,0,0,0,0,0,0,0,4.4049,-0.0204,-0.0102,-0.0102,560.9642,72.0716,95.8916,-23.82,0.9593,0.7516,7852.373,-0.0204,576.8442,87.9516,-11.91,0,-36.406,83.9816,2.8926,0.0401,0,0,1511891,-488.8926,0,0,0,1.51E+08,0,0,48.2508,26.9901,553.2402,580.3208,600.5797,18.2885,-0.0204,-5.9297,6.3251,0.1839,606.8219,580.3208,546.9979,117.9293,91.4282,58.1053,6.3278,-5.9297,-0.0231,578.0469,89.1543,59.824,0.557,2.0296,71.1542,0.375,89.9857
1,4.8,4.8,585.0171,45451.6,488,0,-0.1879,490.6993,-0.0275,0,0,0.0528,0.0522,0.0518,0,0,0,9.6941,0,0,100,0,0,0,0,0,0,0,0,0,0,571.9481,103608.6,0.3313,0.6252,0,0,0,0,0,0,0,0,0,0,4.4062,-0.0143,-0.0071,-0.0071,561.0955,70.3962,94.3178,-23.9216,0.9591,0.7464,7852.852,-0.0143,577.0432,86.3439,-11.9608,0,65.3611,82.357,2.6993,0.0383,0,0,1511891,-490.6993,0,0,0,1.51E+08,0,0,48.2529,26.9921,553.5821,580.329,601.6091,3.2208,-0.0143,-5.9302,6.3194,0.116,601.8241,580.329,553.3671,111.1248,89.6297,62.6678,6.3205,-5.9302,-0.0154,578.5068,87.8074,48.457,0.5564,1.7732,86.1804,0.3749,89.9909
1,5.8,5.8,585.0984,45499.93,490,0,-0.1858,492.7913,-0.024,0,0,0.0528,0.0522,0.0518,0,0,0,9.692,0,0,100,0,0,0,0,0,0,0,0,0,0,572.2703,103548.2,0.0225,-2.4366,0,0,0,0,0,0,0,0,0,0,4.409,-0.0125,-0.0063,-0.0063,561.442,68.6507,92.3071,-23.6564,0.9596,0.7437,7852.993,-0.0125,577.213,84.4217,-11.8282,0,47.6951,80.4789,2.7913,0.0407,0,0,1511891,-492.7913,0,0,0,1.51E+08,0,0,48.2544,26.9942,553.973,580.4966,601.3862,-12.5515,-0.0125,-5.9275,6.3143,0.0079,604.5039,580.4966,550.8553,111.7126,87.7053,58.064,6.3143,-5.9275,-0.0125,578.6186,85.8273,53.6486,0.5525,1.924,-76.0505,0.3743,89.9994
1,6.8,6.8,584.968,45563.5,492,0,-0.1853,494.6835,-0.0563,0,0,0.0528,0.0522,0.0518,0,0,0,9.666,0,0,100,0,0,0,0,0,0,0,0,0,0,572.1763,103498.1,-0.4678,-4.6499,0,0,0,0,0,0,0,0,0,0,4.4077,-0.0292,-0.0146,-0.0146,561.3702,66.6867,90.2845,-23.5978,0.9597,0.7386,7851.682,-0.0292,577.1021,82.4186,-11.7989,0,203.6561,78.4856,2.6835,0.0402,0,0,1511891,-494.6835,0,0,0,1.51E+08,0,0,48.2512,26.9935,553.9201,580.379,601.2113,-23.9581,-0.0292,-5.9165,6.3198,-0.1638,611.2273,580.379,543.9041,116.5438,85.6955,49.2206,6.3219,-5.9165,-0.0313,578.5035,83.82,67.3232,0.5418,2.3678,-67.3119,0.3741,90.0128
1,7.8,7.8,584.9393,45665.49,495,0,-0.1871,497.363,-0.1106,0,0,0.0528,0.0522,0.0518,0,0,0,9.5963,0,0,100,0,0,0,0,0,0,0,0,0,0,572.2102,103446.8,-0.8865,-4.9698,0,0,0,0,0,0,0,0,0,0,4.4044,-0.0575,-0.0287,-0.0287,561.1085,63.7455,87.5763,-23.8308,0.9593,0.7279,7849.461,-0.0575,576.9957,79.6327,-11.9154,0,570.6457,75.6609,2.363,0.0371,0,0,1511891,-497.363,0,0,0,1.51E+08,0,0,48.2452,26.9912,553.4946,580.3727,601.1044,-25.6165,-0.0575,-5.9001,6.3315,-0.3102,612.2692,580.3727,542.3298,114.9062,83.0097,44.9668,6.339,-5.9001,-0.065,578.3239,80.9609,69.9394,0.5439,2.5554,-66.4503,0.3739,90.0235
1,8.8,8.8,584.7391,45702.68,497,0,-0.1881,499.3264,-0.1104,0,0,0.0528,0.0522,0.0518,0,0,0,9.5839,0,0,100,0,0,0,0,0,0,0,0,0,0,572.3546,103389.4,-0.8044,-3.5014,0,0,0,0,0,0,0,0,0,0,4.4018,-0.0574,-0.0287,-0.0287,560.7768,61.4504,85.4127,-23.9623,0.959,0.7195,7849.469,-0.0574,576.7516,77.4252,-11.9812,0,-86.0931,73.4316,2.3264,0.0379,0,0,1511891,-499.3264,0,0,0,1.51E+08,0,0,48.2463,26.993,552.9393,580.296,600.4681,-18.047,-0.0574,-5.897,6.3274,-0.2815,606.5439,580.296,546.8634,107.2175,80.9696,47.537,6.3336,-5.897,-0.0636,577.9011,78.5747,59.6805,0.5602,2.2555,-71.3932,0.373,90.0215
1,9.8,9.8,584.7301,45776.09,500,0,-0.187,502.4525,-0.099,0,0,0.0528,0.0522,0.0518,0,0,0,9.5839,0,0,100,0,0,0,0,0,0,0,0,0,0,572.371,103315.4,-0.5415,-0.604,0,0,0,0,0,0,0,0,0,0,4.4031,-0.0514,-0.0257,-0.0257,560.9088,58.4563,82.2776,-23.8213,0.9593,0.7105,7849.94,-0.0514,576.7897,74.3372,-11.9107,0,-98.7533,70.367,2.4525,0.042,0,0,1511891,-502.4525,0,0,0,1.51E+08,0,0,48.249,26.9961,553.1409,580.2959,600.4291,-3.1128,-0.0514,-5.8952,6.3192,-0.1895,600.6331,580.2959,552.937,98.1806,77.8434,50.4845,6.322,-5.8952,-0.0542,577.9553,75.5028,47.6961,0.5736,1.9448,-86.25,0.3726,90.0147
1,10.8,10.8,585.1764,45878.39,503,0,-0.1858,505.389,-0.1069,0,0,0.0528,0.0522,0.0518,0,0,0,9.5848,0,0,100,0,0,0,0,0,0,0,0,0,0,572.2935,103228.5,-0.009,2.4684,0,0,0,0,0,0,0,0,0,0,4.4076,-0.0555,-0.0277,-0.0277,561.505,56.116,79.7874,-23.6714,0.9595,0.7033,7849.619,-0.0555,577.2859,71.8969,-11.8357,0,81.7895,67.9517,2.389,0.0426,0,0,1511891,-505.389,0,0,0,1.51E+08,0,0,48.2495,26.9982,554.0644,580.5541,601.5432,12.7212,-0.0555,-5.8881,6.3155,-0.0031,604.7369,580.5541,550.8708,99.3479,75.1651,45.4818,6.3155,-5.8881,-0.0555,578.7206,73.3316,53.8661,0.5511,2.1843,75.9073,0.3719,90.0002
1,11.8,11.8,584.896,45943.71,504,0,-0.1842,505.5153,-0.1864,0,0,0.0528,0.0522,0.0518,0,0,0,9.4618,0,0,100,0,0,0,0,0,0,0,0,0,0,572.256,103150.7,0.7612,4.6182,0,0,0,0,0,0,0,0,0,0,4.4051,-0.0968,-0.0484,-0.0484,561.4181,55.9028,79.3807,-23.4779,0.9599,0.7042,7846.38,-0.0968,577.07,71.5547,-11.739,0,-1070.07,67.6418,1.5153,0.0271,0,0,1511891,-505.5153,0,0,0,1.51E+08,0,0,48.2409,26.995,553.9777,580.3607,600.9564,23.8141,-0.0968,-5.8642,6.3322,0.2663,610.9164,580.3607,544.0176,105.4011,74.8454,38.5023,6.3377,-5.8642,-0.1023,578.4316,72.9163,66.8988,0.5433,2.7375,67.3033,0.3712,89.9798
1,12.8,12.8,584.9257,46014.45,505,0,-0.186,506.4353,-0.2846,0,0,0.0528,0.0522,0.0518,0,0,0,9.296,0,0,100,0,0,0,0,0,0,0,0,0,0,572.1305,103091.8,1.4422,5.0122,0,0,0,0,0,0,0,0,0,0,4.4012,-0.1478,-0.0738,-0.0738,561.2069,54.7716,78.4904,-23.7188,0.9594,0.6978,7842.384,-0.1477,577.0195,70.5842,-11.8594,0,2302.242,66.631,1.4353,0.0262,0,0,1511891,-506.4353,0,0,0,1.51E+08,0,0,48.2296,26.9899,553.7016,580.3346,601.1849,25.8647,-0.1478,-5.8367,6.3554,0.5041,612.5523,580.3346,542.3342,106.117,73.8993,35.8989,6.3749,-5.8367,-0.1673,578.407,71.9717,70.2181,0.5412,2.956,66.2747,0.3709,89.9641
1,13.8,13.8,584.5616,46097.07,508,0,-0.1893,508.7783,-0.2867,0,0,0.0528,0.0522,0.0518,0,0,0,9.2792,0,0,100,0,0,0,0,0,0,0,0,0,0,572.0396,103027.9,1.3457,3.5258,0,0,0,0,0,0,0,0,0,0,4.395,-0.1489,-0.0744,-0.0744,560.4225,51.6442,75.7833,-24.1391,0.9587,0.6815,7842.298,-0.1489,576.5152,67.7369,-12.0696,0,-69.6477,63.7138,0.7783,0.0151,0,0,1511891,-508.7783,0,0,0,1.51E+08,0,0,48.2304,26.9917,552.5557,580.0684,600.4754,18.194,-0.1489,-5.8323,6.3517,0.4704,606.6003,580.0684,546.4308,97.822,71.2901,37.6525,6.3687,-5.8323,-0.1659,577.6998,68.9215,60.1695,0.559,2.598,71.3943,0.3705,89.9662
1,14.8,14.8,584.6719,46219.18,512,0,-0.1877,513.9933,-0.265,0,0,0.0528,0.0522,0.0518,0,0,0,9.3035,0,0,100,0,0,0,0,0,0,0,0,0,0,572.3875,102938,0.9701,0.6377,0,0,0,0,0,0,0,0,0,0,4.398,-0.1377,-0.0688,-0.0688,560.7423,46.749,70.6786,-23.9296,0.9591,0.6614,7843.175,-0.1377,576.6954,62.7021,-11.9648,0,-122.4716,58.7138,1.9933,0.0426,0,0,1511891,-513.9933,0,0,0,1.51E+08,0,0,48.2347,26.996,552.8819,580.2638,600.2863,3.29,-0.1377,-5.8323,6.3396,0.3392,600.5135,580.2638,552.6547,86.5202,66.2705,38.6614,6.3485,-5.8323,-0.1466,577.8107,63.8174,47.8588,0.5769,2.2379,86.0488,0.3696,89.9748
1,15.8,15.8,584.9257,46344.04,515,0,-0.1819,517.7551,-0.3007,0,0,0.0528,0.0522,0.0518,0,0,0,9.2707,0,0,100,0,0,0,0,0,0,0,0,0,0,572.2297,102832.2,-0.0219,-2.4255,0,0,0,0,0,0,0,0,0,0,4.4049,-0.1562,-0.078,-0.078,561.7258,43.9707,67.1706,-23.1999,0.9603,0.6546,7841.726,-0.1561,577.1924,59.4373,-11.6,0,3468.682,55.5707,2.7551,0.0627,0,0,1511891,-517.7551,0,0,0,1.51E+08,0,0,48.232,26.9967,554.4736,580.3696,601.0663,-12.5162,-0.1562,-5.8172,6.3424,-0.0077,604.2156,580.3696,551.3242,86.4605,62.6145,33.5691,6.3424,-5.8172,-0.1562,578.6365,60.8814,52.8914,0.5492,2.5756,-75.8763,0.369,90.0006
1,16.8,16.8,584.9374,46435.29,514,0,-0.1819,515.6697,-0.491,0,0,0.0528,0.0522,0.0518,0,0,0,8.9547,0,0,100,0,0,0,0,0,0,0,0,0,0,572.4336,102744.7,-1.7617,-4.6313,0,0,0,0,0,0,0,0,0,0,4.4005,-0.2551,-0.1273,-0.1273,561.7188,46.0491,69.2677,-23.2186,0.9603,0.6648,7833.991,-0.2549,577.1978,61.5281,-11.6093,0,1478.15,57.6584,1.6697,0.0363,0,0,1511891,-515.6697,0,0,0,1.51E+08,0,0,48.2097,26.9861,554.3628,580.4501,600.8361,-23.9329,-0.2551,-5.7653,6.3889,-0.6149,610.957,580.4501,544.2419,95.2873,64.7804,28.5722,6.4172,-5.7653,-0.2834,578.5496,62.88,66.7151,0.5427,3.335,-67.0772,0.3685,90.0415
1,17.8,17.8,585.105,46496.2,513,0,-0.1855,514.8224,-0.6879,0,0,0.0528,0.0522,0.0518,0,0,0,8.6284,0,0,100,0,0,0,0,0,0,0,0,0,0,572.3146,102686.3,-2.9276,-4.9531,0,0,0,0,0,0,0,0,0,0,4.3935,-0.3574,-0.1782,-0.1782,561.3975,46.5751,70.2826,-23.7075,0.9595,0.6627,7826.005,-0.3571,577.2025,62.3801,-11.8538,0,162.6197,58.4289,1.8224,0.0391,0,0,1511891,-514.8224,0,0,0,1.51E+08,0,0,48.1861,26.9741,553.9062,580.5146,601.3698,-25.6342,-0.3574,-5.7137,6.4393,-1.0203,612.5709,580.5146,542.7051,97.7485,65.6922,27.8827,6.515,-5.7137,-0.4331,578.5969,63.7745,69.8658,0.5412,3.5057,-66.3966,0.3682,90.0585
1,18.8,18.8,584.963,46584.98,515,0,-0.1874,517.64,-0.7033,0,0,0.0528,0.0522,0.0518,0,0,0,8.5957,0,0,100,0,0,0,0,0,0,0,0,0,0,572.3455,102614.4,-2.8629,-3.4891,0,0,0,0,0,0,0,0,0,0,4.3902,-0.3654,-0.1822,-0.1822,561.0206,43.3806,67.323,-23.9424,0.9591,0.6444,7825.381,-0.3651,576.9822,59.3422,-11.9712,0,713.811,55.3518,2.64,0.0609,0,0,1511891,-517.64,0,0,0,1.51E+08,0,0,48.1854,26.9752,553.3039,580.4346,601.01,-18.0589,-0.3654,-5.7057,6.4387,-0.9977,607.0751,580.4346,547.2389,89.4351,62.7946,29.5989,6.5111,-5.7057,-0.4378,578.2495,60.6095,59.8362,0.5548,3.0216,-71.4355,0.3676,90.0576
1,19.8,19.8,584.9104,46733.55,522,0,-0.1843,524.9576,-0.6931,0,0,0.0528,0.0522,0.0518,0,0,0,8.5981,0,0,100,0,0,0,0,0,0,0,0,0,0,572.3988,102514.1,-2.3266,-0.6479,0,0,0,0,0,0,0,0,0,0,4.3931,-0.3601,-0.1796,-0.1796,561.3615,36.4039,59.9528,-23.5489,0.9597,0.6072,7825.794,-0.3598,577.0608,52.1032,-11.7745,0,-7277.451,48.1784,2.9576,0.0812,0,0,1511891,-524.9576,0,0,0,1.51E+08,0,0,48.1884,26.979,553.8252,580.4197,600.8256,-3.3529,-0.3601,-5.7022,6.4291,-0.8109,601.0637,580.4197,553.5872,76.1061,55.4621,28.6296,6.4772,-5.7022,-0.4082,578.3569,53.3993,47.4765,0.5652,2.6583,-85.9401,0.3668,90.0502
1,20.8,20.8,584.9276,46872.05,527,0,-0.178,529.2464,-0.8866,0,0,0.0528,0.0522,0.0518,0,0,0,8.292,0,0,100,0,0,0,0,0,0,0,0,0,0,572.3718,102376.4,0.1247,2.4304,0,0,0,0,0,0,0,0,0,0,4.3949,-0.4606,-0.2295,-0.2295,562.1539,32.9075,55.6812,-22.7737,0.9611,0.591,7817.965,-0.4601,577.3364,48.09,-11.3869,0,3893.65,44.2944,2.2464,0.0683,0,0,1511891,-529.2464,0,0,0,1.51E+08,0,0,48.1667,26.9697,555.0868,580.4208,600.9028,12.5954,-0.4606,-5.647,6.473,0.0434,604.1371,580.4208,551.8524,74.8907,51.1744,22.606,6.4731,-5.647,-0.4607,578.8034,49.557,52.2847,0.5464,3.3129,75.5984,0.3654,89.9969
1,21.8,21.8,584.7795,46894.38,521,0,-0.1781,522.6345,-1.2766,0,0,0.0528,0.0522,0.0518,0,0,0,7.6424,0,0,100,0,0,0,0,0,0,0,0,0,0,572.5025,102275.6,3.0422,4.6415,0,0,0,0,0,0,0,0,0,0,4.3845,-0.6632,-0.33,-0.33,561.9547,39.3202,62.145,-22.8248,0.961,0.6327,7802.23,-0.6621,577.1712,54.5367,-11.4124,0,-282.2819,50.7326,1.6345,0.0416,0,0,1511891,-522.6345,0,0,0,1.51E+08,0,0,48.1199,26.9456,554.7208,580.3726,600.4026,24.1257,-0.6632,-5.5459,6.5736,1.0557,610.7845,580.3726,544.3389,88.15,57.7381,21.7044,6.6498,-5.5459,-0.7394,578.4987,55.8642,66.4456,0.5423,4.0614,66.7165,0.3645,89.9439
1,22.8,22.8,584.7141,46949.64,518,0,-0.1851,520.0621,-1.5292,0,0,0.0528,0.0522,0.0518,0,0,0,7.2547,0,0,100,0,0,0,0,0,0,0,0,0,0,572.1793,102207.4,4.4162,4.9647,0,0,0,0,0,0,0,0,0,0,4.371,-0.7944,-0.3948,-0.3948,560.9546,40.8925,64.652,-23.7595,0.9594,0.6325,7792.075,-0.7928,576.7943,56.7322,-11.8798,0,-178.1492,52.7723,2.0621,0.0504,0,0,1511891,-520.0621,0,0,0,1.51E+08,0,0,48.0897,26.9301,553.3239,580.2144,600.6673,25.8552,-0.7944,-5.4803,6.6385,1.5296,612.0504,580.2144,541.9408,91.9883,60.1523,21.8787,6.7927,-5.4803,-0.9486,578.0685,58.0064,70.1096,0.5459,4.2045,66.2378,0.3638,89.9333
1,23.8,23.8,585.0117,47014.52,520,0,-0.1883,522.9333,-1.5473,0,0,0.0528,0.0522,0.0518,0,0,0,7.2093,0,0,100,0,0,0,0,0,0,0,0,0,0,572.341,102130.4,4.3358,3.5118,0,0,0,0,0,0,0,0,0,0,4.3697,-0.8038,-0.3995,-0.3995,560.84,37.9067,62.0784,-24.1717,0.9587,0.6106,7791.348,-0.8022,576.9545,54.0212,-12.0859,0,405.8415,49.9926,2.9333,0.0774,0,0,1511891,-522.9333,0,0,0,1.51E+08,0,0,48.0888,26.9312,553.0394,580.4631,601.14,18.2905,-0.8038,-5.4713,6.6382,1.5016,607.3049,580.4631,546.8745,84.3716,57.5298,23.9412,6.7867,-5.4713,-0.9523,578.2142,55.2809,60.4304,0.5558,3.5241,71.3733,0.3631,89.9339
1,24.8,24.8,584.7819,47198.37,529,0,-0.1845,532.5369,-1.557,0,0,0.0528,0.0522,0.0518,0,0,0,7.2019,0,0,100,0,0,0,0,0,0,0,0,0,0,572.6527,102008.4,3.5034,0.7615,0,0,0,0,0,0,0,0,0,0,4.3715,-0.8088,-0.402,-0.402,561.0989,28.562,52.245,-23.683,0.9595,0.5467,7790.962,-0.8072,576.8876,44.3507,-11.8415,0,-361.2679,40.4035,3.5369,0.1238,0,0,1511891,-532.5369,0,0,0,1.51E+08,0,0,48.0897,26.9343,553.3239,580.4274,600.2244,3.9661,-0.8088,-5.4615,6.6325,1.2133,600.5574,580.4274,552.9909,68.0205,47.8905,20.454,6.7301,-5.4615,-0.9064,577.9919,45.455,47.5665,0.5768,3.3255,85.2003,0.3622,89.9408
1,25.8,25.8,584.7495,47333.89,533,0,-0.1731,535.2106,-2.0076,0,0,0.0528,0.0522,0.0518,0,0,0,6.4889,0,0,100,0,0,0,0,0,0,0,0,0,0,572.4003,101865,-1.2633,-2.4457,0,0,0,0,0,0,0,0,0,0,4.3721,-1.0429,-0.5174,-0.5174,562.4791,27.2686,49.5389,-22.2704,0.9619,0.5504,7772.911,-1.0402,577.326,42.1154,-11.1352,0,-307.0053,38.4038,2.2106,0.0811,0,0,1511891,-535.2106,0,0,0,1.51E+08,0,0,48.0364,26.9074,555.5996,580.3157,600.476,-12.7813,-1.0429,-5.3434,6.7467,-0.436,603.861,580.3157,552.2147,68.6505,45.1051,17.0042,6.7589,-5.3434,-1.0551,578.7972,43.5866,51.6463,0.5441,4.0373,-75.1666,0.3604,90.0264
1,26.8,26.8,584.9831,47341.37,526,0,-0.1767,526.7154,-2.528,0,0,0.0528,0.0522,0.0518,0,0,0,5.7068,0,0,100,0,0,0,0,0,0,0,0,0,0,572.1056,101768.6,-5.6673,-4.6558,0,0,0,0,0,0,0,0,0,0,4.3582,-1.3132,-0.6502,-0.6502,562.1907,35.4753,58.2677,-22.7924,0.961,0.6088,7752.173,-1.3089,577.3856,50.6702,-11.3962,0,635.419,46.8715,0.7154,0.0202,0,0,1511891,-526.7154,0,0,0,1.51E+08,0,0,47.9739,26.8744,555.2573,580.3594,601.3851,-24.4278,-1.3132,-5.211,6.8829,-1.9483,611.9167,580.3594,544.7256,85.2013,53.644,18.0102,7.1083,-5.211,-1.5386,579.0005,52.2852,67.1911,0.5303,4.7307,-66.6775,0.3587,90.0669
1,27.8,27.8,584.7281,47382.31,521,0,-0.1847,523.433,-2.7985,0,0,0.0528,0.0522,0.0518,0,0,0,5.2789,0,0,100,0,0,0,0,0,0,0,0,0,0,572.2206,101699.7,-7.4529,-4.9342,0,0,0,0,0,0,0,0,0,0,4.3419,-1.4538,-0.7191,-0.7191,560.8653,37.4323,61.2951,-23.8628,0.9592,0.6107,7741.43,-1.4486,576.7739,53.3409,-11.9314,0,-209.3363,49.3637,2.433,0.065,0,0,1511891,-523.433,0,0,0,1.51E+08,0,0,47.9418,26.8579,553.1698,580.2371,600.6608,-25.9414,-1.4538,-5.1409,6.9523,-2.557,612.0836,580.2371,541.747,88.6506,56.8041,18.314,7.3247,-5.1409,-1.8262,578.0226,54.5896,70.3366,0.5472,4.8406,-66.2347,0.3576,90.0713
1,28.8,28.8,584.8306,47431.62,524,0,-0.1876,526.255,-2.8231,0,0,0.0528,0.0522,0.0518,0,0,0,5.2345,0,0,100,0,0,0,0,0,0,0,0,0,0,572.4557,101621.5,-7.384,-3.5205,0,0,0,0,0,0,0,0,0,0,4.3393,-1.4665,-0.7253,-0.7253,560.5997,34.3447,58.5756,-24.231,0.9586,0.5863,7740.461,-1.4612,576.7537,50.4987,-12.1155,0,-493.7688,46.4602,2.255,0.0657,0,0,1511891,-526.255,0,0,0,1.51E+08,0,0,47.9402,26.8586,552.6228,580.3871,600.5967,-18.5115,-1.4665,-5.1305,6.9536,-2.533,606.9091,580.3871,546.3104,80.6541,54.1321,20.0554,7.3188,-5.1305,-1.8317,577.8688,51.6139,60.5987,0.5623,4.0216,-71.1707,0.3566,90.0709
1,29.8,29.8,584.6561,47635.45,533,0,-0.1793,536.9228,-2.8886,0,0,0.0528,0.0522,0.0518,0,0,0,5.1373,0,0,100,0,0,0,0,0,0,0,0,0,0,572.4365,101501.4,-6.3397,-0.8543,0,0,0,0,0,0,0,0,0,0,4.3447,-1.5006,-0.742,-0.742,561.4859,24.5631,47.7333,-23.1702,0.9604,0.5146,7737.861,-1.4951,576.9327,40.0099,-11.5851,0,-203.2794,36.1482,3.9228,0.1597,0,0,1511891,-536.9228,0,0,0,1.51E+08,0,0,47.9341,26.8577,554.0419,580.2681,600.2276,-4.4941,-1.5006,-5.1071,6.9636,-2.1738,600.6609,580.2681,553.6086,63.7381,43.3453,16.6858,7.2341,-5.1071,-1.7711,578.1792,41.2564,47.0523,0.5666,3.8199,-84.4937,0.3559,90.0673
1,30.8,30.8,585.1746,47789.11,537,0,-0.1654,539.3774,-3.6249,0,0,0.0528,0.0522,0.0518,0,0,0,3.9528,0,0,100,0,0,0,0,0,0,0,0,0,0,572.3228,101351.8,1.1476,2.4167,0,0,0,0,0,0,0,0,0,0,4.3456,-1.8831,-0.9285,-0.9285,563.7186,24.3413,45.7972,-21.456,0.9633,0.5315,7708.811,-1.8744,578.0226,38.6452,-10.728,0,213.7785,35.0693,2.3774,0.0977,0,0,1511891,-539.3774,0,0,0,1.51E+08,0,0,47.8466,26.8118,557.5326,580.5592,601.556,12.7839,-1.8831,-4.9195,7.1547,0.3913,604.999,580.5592,554.0896,65.6216,41.1818,14.7122,7.1632,-4.9195,-1.8916,579.8826,40.5052,50.9094,0.5199,4.4604,74.9265,0.3521,89.9794
1,31.8,31.8,585.2588,47780.73,527,0,-0.1769,527.9297,-4.2708,0,0,0.0528,0.0522,0.0518,0,0,0,2.8824,0,0,100,0,0,0,0,0,0,0,0,0,0,572.3524,101247.2,7.0203,4.6087,0,0,0,0,0,0,0,0,0,0,4.3199,-2.2186,-1.0912,-1.0912,562.2301,34.3004,57.3291,-23.0287,0.9607,0.5983,7683.509,-2.2065,577.5826,49.6529,-11.5144,0,127.8883,45.8148,0.9297,0.0271,0,0,1511891,-527.9297,0,0,0,1.51E+08,0,0,47.7698,26.7709,555.1942,580.6235,601.7127,24.4983,-2.2186,-4.7569,7.3239,2.3822,612.2346,580.6235,544.6724,84.3049,52.6938,16.7427,7.6125,-4.7569,-2.5072,579.1768,51.2471,67.5622,0.5321,5.0353,66.7569,0.3484,89.9385
1,32.8,32.8,585.0533,47792.85,522,0,-0.1846,524.412,-4.5415,0,0,0.0528,0.0522,0.0518,0,0,0,2.4425,0,0,100,0,0,0,0,0,0,0,0,0,0,572.011,101182.1,9.059,4.9434,0,0,0,0,0,0,0,0,0,0,4.3045,-2.3592,-1.1591,-1.1591,560.9964,36.5844,60.6413,-24.0569,0.9589,0.6033,7672.955,-2.3455,577.0344,52.6224,-12.0285,0,293.7245,48.6129,2.412,0.0659,0,0,1511891,-524.412,0,0,0,1.51E+08,0,0,47.7381,26.7545,553.4343,580.3691,601.6826,26.3307,-2.3592,-4.6875,7.3932,3.0678,613.2695,580.3691,541.8474,88.8575,55.9571,17.4354,7.8539,-4.6875,-2.8199,578.4953,54.0833,71.4221,0.5394,5.0964,66.2479,0.3465,89.9356
1,33.8,33.8,584.6785,47912.52,525,0,-0.1872,528.1915,-4.562,0,0,0.0528,0.0522,0.0518,0,0,0,2.3927,0,0,100,0,0,0,0,0,0,0,0,0,0,572.3253,101106.3,8.9641,3.571,0,0,0,0,0,0,0,0,0,0,4.2985,-2.3699,-1.1643,-1.1643,560.273,32.0815,56.487,-24.4055,0.9583,0.5679,7672.153,-2.3561,576.5434,48.3519,-12.2028,0,-185.6876,44.2843,3.1915,0.0995,0,0,1511891,-528.1915,0,0,0,1.51E+08,0,0,47.7369,26.7554,552.2116,580.2416,600.4312,19.0228,-2.3699,-4.6779,7.3936,3.0353,607.0322,580.2416,545.6107,78.8407,52.0501,17.4192,7.8446,-4.6779,-2.8209,577.6282,49.4367,61.4215,0.5638,4.5261,70.8632,0.3458,89.9359
1,34.8,34.8,584.9136,48103.32,536,0,-0.1757,540.5005,-4.6595,0,0,0.0528,0.0522,0.0518,0,0,0,2.2655,0,0,100,0,0,0,0,0,0,0,0,0,0,572.5852,100978,7.3719,1.0277,0,0,0,0,0,0,0,0,0,0,4.3096,-2.4205,-1.1887,-1.1887,561.9974,21.4969,44.4131,-22.9162,0.9608,0.484,7668.362,-2.4061,577.2748,36.7743,-11.4581,0,-23104.51,32.955,4.5005,0.2094,0,0,1511891,-540.5005,0,0,0,1.51E+08,0,0,47.7272,26.7526,554.7612,580.4854,600.6381,5.4783,-2.4205,-4.6466,7.4117,2.4945,601.2833,580.4854,554.1161,60.7828,39.9849,13.6156,7.7186,-4.6466,-2.7274,578.6283,38.1278,47.1672,0.5591,4.4642,83.2839,0.3446,89.9395
1,35.8,35.8,584.9765,48205.08,539,0,-0.1629,541.3571,-5.5258,0,0,0.0528,0.0522,0.0518,0,0,0,0.8085,0,0,100,0,0,0,0,0,0,0,0,0,0,572.5491,100827.8,-2.9146,-2.3232,0,0,0,0,0,0,0,0,0,0,4.3033,-2.8705,-1.4051,-1.4051,563.6415,22.2844,43.6194,-21.335,0.9635,0.5109,7634.817,-2.8504,577.8648,36.5077,-10.6675,0,946.7361,32.9519,2.3571,0.1058,0,0,1511891,-541.3571,0,0,0,1.51E+08,0,0,47.6253,26.6986,557.3338,580.5123,600.8316,-12.4647,-2.8705,-4.4283,7.637,-0.9799,604.1503,580.5123,554.0151,62.7932,39.1552,12.658,7.6825,-4.4283,-2.916,579.5593,38.2021,50.1352,0.5285,4.9608,-75.0911,0.3382,90.0369
1,36.8,36.8,585.1021,48195.7,528,0,-0.1782,529.0137,-6.1561,0,0,0.0528,0.0522,0.0518,0,0,0,-0.239,0,0,100,0,0,0,0,0,0,0,0,0,0,572.3116,100727,-10.1577,-4.6439,0,0,0,0,0,0,0,0,0,0,4.2748,-3.198,-1.5616,-1.5616,561.6911,32.6774,56.0884,-23.411,0.96,0.5826,7610.588,-3.1731,577.2984,48.2847,-11.7055,0,241.3842,44.3829,1.0137,0.031,0,0,1511891,-529.0137,0,0,0,1.51E+08,0,0,47.5513,26.6592,554.3797,580.5073,601.4233,-25.0337,-3.198,-4.27,7.8015,-3.3988,612.2521,580.5073,543.5509,83.2384,51.4937,14.5372,8.3037,-4.27,-3.7002,578.7701,49.7564,68.7012,0.5379,5.7259,-66.6083,0.3335,90.0584
1,37.8,37.8,584.9606,48216.05,524,0,-0.1854,525.6704,-6.3851,0,0,0.0528,0.0522,0.0518,0,0,0,-0.6159,0,0,100,0,0,0,0,0,0,0,0,0,0,572.3853,100663.1,-12.3,-4.934,0,0,0,0,0,0,0,0,0,0,4.2614,-3.3169,-1.6183,-1.6183,560.5756,34.9052,59.2902,-24.385,0.9583,0.5887,7601.83,-3.2901,576.8323,51.1619,-12.1925,0,933.1569,47.0977,1.6704,0.0479,0,0,1511891,-525.6704,0,0,0,1.51E+08,0,0,47.5251,26.6458,552.6184,580.443,601.0089,-26.6424,-3.3169,-4.2114,7.859,-4.1087,612.8029,580.443,540.8244,87.1325,54.7726,15.154,8.5691,-4.2114,-4.027,578.0234,52.353,71.9785,0.5504,5.7498,-66.1221,0.3307,90.0596
1,38.8,38.8,584.7563,48336.86,529,0,-0.1864,529.2167,-6.4076,0,0,0.0528,0.0522,0.0518,0,0,0,-0.6579,0,0,100,0,0,0,0,0,0,0,0,0,0,572.3289,100593.7,-12.212,-3.5195,0,0,0,0,0,0,0,0,0,0,4.2583,-3.3286,-1.6239,-1.6239,560.2312,31.0145,55.5396,-24.5251,0.9581,0.5584,7600.969,-3.3017,576.5812,47.3645,-12.2626,0,-282.5015,43.2771,0.2167,0.007,0,0,1511891,-529.2167,0,0,0,1.51E+08,0,0,47.5235,26.6463,552.1372,580.2916,600.6178,-19.007,-3.3286,-4.2017,7.8606,-4.0788,607.181,580.2916,545.574,77.9644,51.075,16.3573,8.5603,-4.2017,-4.0283,577.6822,48.4656,61.6071,0.5635,4.7663,-70.9499,0.3303,90.0594
1,39.8,39.8,584.7861,48497.01,537,0,-0.1744,541.5199,-6.5368,0,0,0.0528,0.0522,0.0518,0,0,0,-0.8631,0,0,100,0,0,0,0,0,0,0,0,0,0,572.5363,100470.9,-10.526,-1.043,0,0,0,0,0,0,0,0,0,0,4.2677,-3.3957,-1.6558,-1.6558,561.8325,20.3126,43.2662,-22.9536,0.9607,0.4695,7596.037,-3.3677,577.1349,35.615,-11.4768,0,-441.9363,31.7894,4.5199,0.2225,0,0,1511891,-541.5199,0,0,0,1.51E+08,0,0,47.5102,26.6414,554.5307,580.385,600.4243,-5.6378,-3.3957,-4.1632,7.8871,-3.5125,601.1068,580.385,553.8483,59.5869,38.8651,12.3284,8.4096,-4.1632,-3.9182,578.4467,36.9268,47.2585,0.5615,4.8333,-83.0982,0.3282,90.0573
1,40.8,40.8,584.8842,48642.68,538,0,-0.1589,543.3416,-7.54,0,0,0.0528,0.0522,0.0518,0,0,0,-2.4923,0,0,100,0,0,0,0,0,0,0,0,0,0,572.4769,100317,1.7641,2.112,0,0,0,0,0,0,0,0,0,0,4.2616,-3.9169,-1.9027,-1.9027,563.8575,20.5159,41.5426,-21.0267,0.964,0.4939,7557.938,-3.8797,577.8753,34.5337,-10.5134,0,-1863.204,31.0293,5.3416,0.2604,0,0,1511891,-543.3416,0,0,0,1.51E+08,0,0,47.3935,26.5791,557.7267,580.4261,600.7278,11.5015,-3.9169,-3.9127,8.1482,0.5843,603.6108,580.4261,554.8437,60.2692,37.0845,11.5021,8.1623,-3.9127,-3.931,579.6269,36.2853,48.7671,0.5246,5.2398,75.928,0.3186,89.9781
1,41.8,41.8,585.0171,48637.5,528,0,-0.1786,528.8666,-8.2524,0,0,0.0528,0.0522,0.0518,0,0,0,-3.6795,0,0,100,0,0,0,0,0,0,0,0,0,0,572.3942,100211.8,10.6978,4.6329,0,0,0,0,0,0,0,0,0,0,4.2272,-4.287,-2.077,-2.077,561.2979,32.4313,56.1505,-23.7192,0.9595,0.5776,7531.116,-4.2427,577.1107,48.2441,-11.8596,0,442.9774,44.2909,0.8666,0.0267,0,0,1511891,-528.8666,0,0,0,1.51E+08,0,0,47.311,26.535,553.7555,580.4814,601.139,25.3634,-4.287,-3.7351,8.3336,3.5247,612.1546,580.4814,542.7399,83.288,51.6148,13.8734,8.808,-3.7351,-4.7614,578.4587,49.5921,69.4146,0.5437,6.0034,66.5241,0.3115,89.9487
1,42.8,42.8,584.9507,48639.25,524,0,-0.1857,525.6151,-8.4896,0,0,0.0528,0.0522,0.0518,0,0,0,-4.0786,0,0,100,0,0,0,0,0,0,0,0,0,0,572.2102,100152.4,13.0565,4.9305,0,0,0,0,0,0,0,0,0,0,4.2144,-4.4102,-2.1347,-2.1347,560.2594,34.6443,59.3356,-24.6913,0.9578,0.5839,7522.229,-4.3633,576.7203,51.1052,-12.3457,0,1197.709,46.99,1.6151,0.0466,0,0,1511891,-525.6151,0,0,0,1.51E+08,0,0,47.2841,26.5212,552.2253,580.3726,601.2246,27.0396,-4.4102,-3.6743,8.3933,4.2943,613.213,580.3726,540.237,87.5979,54.7575,14.6219,9.077,-3.6743,-5.0939,577.9409,52.3258,72.976,0.55,5.9909,66.0893,0.3088,89.9476
1,43.8,43.8,584.894,48726.46,528,0,-0.1876,530.0099,-8.509,0,0,0.0528,0.0522,0.0518,0,0,0,-4.1043,0,0,100,0,0,0,0,0,0,0,0,0,0,572.2432,100076.1,12.9411,3.5228,0,0,0,0,0,0,0,0,0,0,4.2117,-4.4203,-2.1395,-2.1395,559.9546,29.9447,54.8841,-24.9394,0.9574,0.5456,7521.502,-4.3732,576.5809,46.571,-12.4697,0,-2083.94,42.4144,2.0099,0.0671,0,0,1511891,-530.0099,0,0,0,1.51E+08,0,0,47.2831,26.5221,551.73,580.348,601.0553,19.3214,-4.4203,-3.6655,8.3934,4.2559,607.7225,580.348,545.0627,77.7126,50.3381,15.0528,9.065,-3.6655,-5.0919,577.7111,47.7012,62.6598,0.5631,5.1627,70.9619,0.3076,89.9477
1,44.8,44.8,584.8478,48920.59,537,0,-0.1738,543.3923,-8.6609,0,0,0.0528,0.0522,0.0518,0,0,0,-4.3443,0,0,100,0,0,0,0,0,0,0,0,0,0,572.5544,99952.11,10.6184,1.117,0,0,0,0,0,0,0,0,0,0,4.2218,-4.4992,-2.1764,-2.1764,561.7215,18.3292,41.4555,-23.1263,0.9605,0.4421,7515.823,-4.4504,577.139,33.7467,-11.5632,0,-869.0156,29.8924,6.3923,0.3487,0,0,1511891,-543.3923,0,0,0,1.51E+08,0,0,47.2673,26.5158,554.3608,580.4299,600.556,6.1329,-4.4992,-3.6214,8.4259,3.4884,601.3563,580.4299,553.5604,57.9641,37.0376,10.1682,8.8807,-3.6214,-4.9539,578.4489,35.0566,47.7959,0.5622,5.7005,82.5649,0.3054,89.95
1,45.8,45.8,584.9154,49071.08,541,0,-0.1604,544.3033,-9.7036,0,0,0.0528,0.0522,0.0518,0,0,0,-6.0178,0,0,100,0,0,0,0,0,0,0,0,0,0,572.5604,99794.3,-4.0618,-2.1237,0,0,0,0,0,0,0,0,0,0,4.2131,-5.0408,-2.4289,-2.4289,563.4693,19.166,40.6121,-21.4461,0.9633,0.4719,7477.071,-4.9798,577.7667,33.4634,-10.7231,0,-98648.55,29.8891,3.3033,0.1724,0,0,1511891,-544.3033,0,0,0,1.51E+08,0,0,47.148,26.4521,557.0718,580.475,600.7068,-11.7499,-5.0408,-3.3625,8.6955,-1.3242,603.6696,580.475,554.1089,59.3663,36.1717,9.8056,8.759,-3.3625,-5.1043,579.4178,35.1145,49.5607,0.532,6.0543,-75.8476,0.2922,90.0336
1,46.8,46.8,585.0911,49058.96,528,0,-0.1791,529.483,-10.325,0,0,0.0528,0.0522,0.0518,0,0,0,-7.035,0,0,100,0,0,0,0,0,0,0,0,0,0,572.2784,99698.54,-13.91,-4.6286,0,0,0,0,0,0,0,0,0,0,4.1823,-5.3636,-2.5785,-2.5785,561.069,31.586,55.6082,-24.0222,0.9589,0.568,7454.164,-5.2947,577.0837,47.6007,-12.0111,0,259.2086,43.5971,1.483,0.047,0,0,1511891,-529.483,0,0,0,1.51E+08,0,0,47.0773,26.4144,553.4362,580.486,601.4703,-25.7256,-5.3636,-3.2082,8.8558,-4.5143,612.6473,580.486,542.2592,83.1643,51.0031,12.7763,9.5395,-3.2082,-6.0473,578.4642,48.9812,70.388,0.5431,6.5093,-66.5164,0.284,90.0476
1,47.8,47.8,584.844,49058.18,524,0,-0.1854,526.1342,-10.5186,0,0,0.0528,0.0522,0.0518,0,0,0,-7.3505,0,0,100,0,0,0,0,0,0,0,0,0,0,572.3267,99637.2,-16.2913,-4.9128,0,0,0,0,0,0,0,0,0,0,4.17,-5.4642,-2.625,-2.625,559.953,33.8188,58.7098,-24.891,0.9574,0.576,7447.053,-5.3928,576.547,50.4128,-12.4455,0,-583.7318,46.2643,2.1342,0.0631,0,0,1511891,-526.1342,0,0,0,1.51E+08,0,0,47.0558,26.4036,551.6964,580.3449,600.8472,-27.3435,-5.4642,-3.158,8.9037,-5.2797,613.0362,580.3449,539.5075,86.902,54.2107,13.3733,9.8158,-3.158,-6.3763,577.6296,51.4953,73.5287,0.5554,6.4982,-65.9741,0.2815,90.0481
1,48.8,48.8,585.0509,49135.48,528,0,-0.1854,530.3084,-10.5346,0,0,0.0528,0.0522,0.0518,0,0,0,-7.3832,0,0,100,0,0,0,0,0,0,0,0,0,0,572.3484,99569.59,-16.181,-3.5117,0,0,0,0,0,0,0,0,0,0,4.1712,-5.4725,-2.6288,-2.6288,560.1582,29.8498,54.7425,-24.8927,0.9575,0.5453,7446.467,-5.4009,576.7534,46.445,-12.4464,0,342.6215,42.2962,2.3084,0.0773,0,0,1511891,-530.3084,0,0,0,1.51E+08,0,0,47.0551,26.4046,551.9862,580.485,601.2929,-19.5468,-5.4725,-3.15,8.9032,-5.2435,608.1016,580.485,545.1774,77.7932,50.1766,14.869,9.8031,-3.15,-6.3724,577.9214,47.6129,62.9242,0.5611,5.2319,-70.7952,0.2807,90.0481
1,49.8,49.8,584.955,49349.3,541,0,-0.1738,543.6625,-10.6885,0,0,0.0528,0.0522,0.0518,0,0,0,-7.5588,0,0,100,0,0,0,0,0,0,0,0,0,0,572.5208,99440.07,-13.9383,-1.1286,0,0,0,0,0,0,0,0,0,0,4.1787,-5.5525,-2.6657,-2.6657,561.5911,17.9287,41.2925,-23.3639,0.9601,0.4342,7440.823,-5.4788,577.1671,33.5046,-11.682,0,1527.365,29.6106,2.6625,0.1485,0,0,1511891,-543.6625,0,0,0,1.51E+08,0,0,47.0394,26.3984,554.1751,580.4853,600.8575,-6.2887,-5.5525,-3.1055,8.9357,-4.512,601.6898,580.4853,553.3428,58.0273,36.8228,9.6803,9.6072,-3.1055,-6.224,578.5059,34.8435,48.347,0.5614,5.9944,-82.4606,0.2777,90.0467
1,50.8,50.8,584.7105,49507.91,541,0,-0.1564,545.4893,-11.8019,0,0,0.0528,0.0522,0.0518,0,0,0,-9.3681,0,0,100,0,0,0,0,0,0,0,0,0,0,572.3484,99282.9,1.8737,1.9186,0,0,0,0,0,0,0,0,0,0,4.1706,-6.1309,-2.9313,-2.9313,563.5739,18.0846,39.2212,-21.1366,0.9639,0.4611,7400.271,-6.0415,577.665,32.1757,-10.5683,0,-298.7578,28.6529,4.4893,0.2482,0,0,1511891,-545.4893,0,0,0,1.51E+08,0,0,46.9137,26.331,557.3734,580.2664,600.5251,10.7777,-6.1309,-2.831,9.2229,0.6016,603.0671,580.2664,554.8313,57.5778,34.7771,9.342,9.2347,-2.831,-6.1427,579.3882,33.899,48.2358,0.5273,6.1633,76.7283,0.261,89.9824
1,51.8,51.8,585.0845,49477.04,527,0,-0.1796,528.9301,-12.5015,0,0,0.0528,0.0522,0.0518,0,0,0,-10.4871,0,0,100,0,0,0,0,0,0,0,0,0,0,572.2267,99179.17,13.164,4.6133,0,0,0,0,0,0,0,0,0,0,4.1354,-6.4943,-3.0971,-3.0971,560.7307,31.8006,56.1544,-24.3538,0.9584,0.5663,7375.019,-6.3943,576.9666,48.0365,-12.1769,0,266.1636,43.9775,1.9301,0.0607,0,0,1511891,-528.9301,0,0,0,1.51E+08,0,0,46.8353,26.2891,552.9484,580.4619,601.5362,26.0468,-6.4943,-2.6584,9.4026,4.2055,612.8601,580.4619,541.6245,83.93,51.5318,12.6944,9.9407,-2.6584,-7.0324,578.3155,49.3854,71.2356,0.5452,6.6116,66.5029,0.2499,89.9579
1,52.8,52.8,585.0559,49472.93,524,0,-0.1847,525.5724,-12.7027,0,0,0.0528,0.0522,0.0518,0,0,0,-10.7947,0,0,100,0,0,0,0,0,0,0,0,0,0,572.34,99124.52,15.826,4.9583,0,0,0,0,0,0,0,0,0,0,4.1259,-6.5988,-3.1446,-3.1446,559.9916,34.4192,59.4835,-25.0643,0.9572,0.5786,7367.789,-6.4956,576.7011,51.1287,-12.5322,0,296.5089,46.9514,1.5724,0.0457,0,0,1511891,-525.5724,0,0,0,1.51E+08,0,0,46.8132,26.2778,551.7363,580.4843,601.3275,28.0351,-6.5988,-2.6072,9.4526,5.0487,613.959,580.4843,539.1048,88.3866,54.9119,13.5324,10.2108,-2.6072,-7.357,577.8494,52.277,74.8542,0.5528,6.5315,65.7455,0.2466,89.9572
1,53.8,53.8,584.9323,49557.31,529,0,-0.1877,530.5479,-12.7138,0,0,0.0528,0.0522,0.0518,0,0,0,-10.8184,0,0,100,0,0,0,0,0,0,0,0,0,0,572.4168,99052.54,15.686,3.5125,0,0,0,0,0,0,0,0,0,0,4.1217,-6.6046,-3.1472,-3.1472,559.4519,28.904,54.3844,-25.4804,0.9564,0.5315,7367.389,-6.5012,576.4388,45.8909,-12.7402,0,2850.627,41.6442,1.5479,0.0536,0,0,1511891,-530.5479,0,0,0,1.51E+08,0,0,46.8131,26.2792,550.883,580.4325,600.9496,19.8611,-6.6046,-2.6001,9.4507,5.0038,607.8714,580.4325,543.9611,77.3235,49.8846,13.4132,10.1959,-2.6001,-7.3498,577.4217,46.8738,63.9103,0.5707,5.7647,70.786,0.246,89.9572
1,54.8,54.8,584.5598,49775.47,544,0,-0.1732,544.9369,-12.8771,0,0,0.0528,0.0522,0.0518,0,0,0,-11.0811,0,0,100,0,0,0,0,0,0,0,0,0,0,572.498,98924.22,12.9386,1.1984,0,0,0,0,0,0,0,0,0,0,4.1301,-6.6894,-3.1857,-3.1857,561.038,16.1011,39.6229,-23.5218,0.9598,0.4064,7361.533,-6.5834,576.7192,31.7823,-11.7609,0,-170.8133,27.862,0.9369,0.0582,0,0,1511891,-544.9369,0,0,0,1.51E+08,0,0,46.7967,26.2726,553.3495,580.2229,600,6.7838,-6.6894,-2.5536,9.4851,4.1228,600.9664,580.2229,552.3831,56.0295,35.286,7.4462,9.9945,-2.5536,-7.1988,577.8574,32.9206,48.5833,0.573,7.5246,81.8919,0.2421,89.9588
1,55.8,55.8,585.0019,49934.83,538,0,-0.1605,545.3878,-13.9896,0,0,0.0528,0.0522,0.0518,0,0,0,-12.8511,0,0,100,0,0,0,0,0,0,0,0,0,0,572.2996,98759.59,-4.6219,-1.9165,0,0,0,0,0,0,0,0,0,0,4.1228,-7.2673,-3.4469,-3.4469,563.08,17.6922,39.6141,-21.9219,0.9625,0.4466,7321.873,-7.1428,577.6946,32.3068,-10.961,0,713.7559,28.6532,7.3878,0.4176,0,0,1511891,-545.3878,0,0,0,1.51E+08,0,0,46.6732,26.2066,556.5995,580.4343,601.2667,-10.936,-7.2673,-2.2798,9.7698,-1.461,603.8005,580.4343,554.0657,58.4127,35.0465,8.6779,9.8322,-2.2798,-7.3297,579.4335,34.0457,49.7348,0.5302,6.7312,-76.9553,0.2227,90.0285
1,56.8,56.8,585.0575,49902.29,530,0,-0.1803,529.0497,-14.5721,0,0,0.0528,0.0522,0.0518,0,0,0,-13.8261,0,0,100,0,0,0,0,0,0,0,0,0,0,572.3417,98666.38,-16.2485,-4.6154,0,0,0,0,0,0,0,0,0,0,4.0914,-7.5699,-3.5828,-3.5828,560.3678,31.3181,56.0078,-24.6897,0.9578,0.5592,7301.276,-7.4351,576.8276,47.7779,-12.3449,0,317.7612,43.663,-0.9503,-0.0303,0,0,1511891,-529.0497,0,0,0,1.51E+08,0,0,46.609,26.1724,552.3287,580.4848,601.3422,-26.4468,-7.5699,-2.1364,9.9182,-5.1148,612.8912,580.4848,540.7797,83.8415,51.4351,11.73,10.6367,-2.1364,-8.2884,578.0519,49.0022,72.1115,0.5506,7.1476,-66.4098,0.2119,90.0394
1,57.8,57.8,584.7824,49900.32,524,0,-0.1863,525.9689,-14.7343,0,0,0.0528,0.0522,0.0518,0,0,0,-14.0903,0,0,100,0,0,0,0,0,0,0,0,0,0,572.0876,98616.24,-18.9487,-4.918,0,0,0,0,0,0,0,0,0,0,4.08,-7.6542,-3.6205,-3.6205,559.2444,33.2755,58.8135,-25.538,0.9563,0.5658,7295.559,-7.5165,576.2697,50.3008,-12.769,0,-313.4283,46.0445,1.9689,0.0592,0,0,1511891,-525.9689,0,0,0,1.51E+08,0,0,46.5916,26.1636,550.7294,580.2172,601.0416,-28.213,-7.6542,-2.0952,9.9578,-5.9579,613.685,580.2172,538.086,87.7161,54.2484,12.1171,10.9137,-2.0952,-8.6101,577.3294,51.3605,75.599,0.5573,7.239,-65.8609,0.2084,90.0399
1,58.8,58.8,584.8568,50000.01,528,0,-0.1873,530.6285,-14.7471,0,0,0.0528,0.0522,0.0518,0,0,0,-14.1251,0,0,100,0,0,0,0,0,0,0,0,0,0,572.3839,98549.27,-18.8319,-3.5315,0,0,0,0,0,0,0,0,0,0,4.0793,-7.6608,-3.6235,-3.6235,559.1827,28.5542,54.2283,-25.6741,0.9561,0.5266,7295.111,-7.5229,576.2988,45.6704,-12.8371,0,-786.0181,41.3913,2.6285,0.0921,0,0,1511891,-530.6285,0,0,0,1.51E+08,0,0,46.5913,26.1648,550.4858,580.3713,600.8337,-20.2602,-7.6608,-2.088,9.9564,-5.9209,607.9739,580.3713,543.3456,77.3454,49.7428,12.7171,10.9008,-2.088,-8.6051,577.2303,46.6018,64.6283,0.5729,6.082,-70.5863,0.2077,90.0398
1,59.8,59.8,584.5854,50185.78,541,0,-0.1737,544.7178,-14.9093,0,0,0.0528,0.0522,0.0518,0,0,0,-14.3682,0,0,100,0,0,0,0,0,0,0,0,0,0,572.6008,98427.83,-16.2921,-1.1947,0,0,0,0,0,0,0,0,0,0,4.0876,-7.7451,-3.6612,-3.6612,560.7592,16.0414,39.8676,-23.8262,0.9592,0.4024,7289.403,-7.6042,576.6433,31.9255,-11.9131,0,-183.3628,27.9545,3.7178,0.2318,0,0,1511891,-544.7178,0,0,0,1.51E+08,0,0,46.575,26.1581,552.8746,580.2752,599.94,-6.8616,-7.7451,-2.0419,9.9912,-5.1167,600.9199,580.2752,551.8947,56.2022,35.5574,7.1769,10.7009,-2.0419,-8.4548,577.6966,32.9788,49.0253,0.5789,7.831,-81.8723,0.2042,90.0388
1,60.8,60.8,584.6903,50349.13,543,0,-0.156,546.9745,-16.0765,0,0,0.0528,0.0522,0.0518,0,0,0,-16.2988,0,0,100,0,0,0,0,0,0,0,0,0,0,572.4612,98264.45,1.8296,1.7218,0,0,0,0,0,0,0,0,0,0,4.0822,-8.3514,-3.9311,-3.9311,563.1697,16.1952,37.7158,-21.5206,0.9632,0.4294,7248.614,-8.1883,577.5168,30.5423,-10.7603,0,-278.5967,26.9555,3.9745,0.2454,0,0,1511891,-546.9745,0,0,0,1.51E+08,0,0,46.4472,26.0896,556.7001,580.2918,600.3627,9.9716,-8.3514,-1.7566,10.2888,0.5698,602.5322,580.2918,554.5306,55.5577,33.3173,7.5561,10.2975,-1.7566,-8.3601,579.1182,32.1437,48.0016,0.5367,7.3527,77.7256,0.1808,89.9861
1,61.8,61.8,584.7971,50317.95,527,0,-0.1805,528.3371,-16.7479,0,0,0.0528,0.0522,0.0518,0,0,0,-17.4276,0,0,100,0,0,0,0,0,0,0,0,0,0,572.0719,98166.8,15.1054,4.638,0,0,0,0,0,0,0,0,0,0,4.0449,-8.7002,-4.0854,-4.0854,559.8203,31.4832,56.46,-24.9768,0.9573,0.5576,7225.354,-8.5237,576.4715,48.1344,-12.4884,0,-372.123,43.9716,1.3371,0.0425,0,0,1511891,-528.3371,0,0,0,1.51E+08,0,0,46.3742,26.0506,551.6304,580.22,601.1082,26.9888,-8.7002,-1.5922,10.4594,4.6823,612.9808,580.22,539.7577,84.6437,51.8829,11.4206,11.0154,-1.5922,-9.2562,577.6528,49.3157,73.2231,0.5526,7.4115,66.2548,0.167,89.9645
1,62.8,62.8,584.93,50303.48,523,0,-0.187,525.2823,-16.9203,0,0,0.0528,0.0522,0.0518,0,0,0,-17.7264,0,0,100,0,0,0,0,0,0,0,0,0,0,572.3491,98114.22,17.7572,4.9419,0,0,0,0,0,0,0,0,0,0,4.0358,-8.7898,-4.1249,-4.1249,559.0212,33.7389,59.6477,-25.9088,0.9557,0.5656,7219.404,-8.6098,576.2937,51.0114,-12.9544,0,2946.924,46.6933,2.2823,0.0676,0,0,1511891,-525.2823,0,0,0,1.51E+08,0,0,46.356,26.0414,550.2585,580.4046,601.0575,28.7918,-8.7898,-1.5486,10.5012,5.4976,614.052,580.4046,537.2639,88.7697,55.1223,11.9816,11.2551,-1.5486,-9.5437,577.2402,51.9579,76.7881,0.5618,7.4088,65.709,0.1628,89.964
1,63.8,63.8,584.472,50391.29,530,0,-0.1884,530.4293,-16.9274,0,0,0.0528,0.0522,0.0518,0,0,0,-17.7466,0,0,100,0,0,0,0,0,0,0,0,0,0,572.4341,98049.93,17.5996,3.5024,0,0,0,0,0,0,0,0,0,0,4.031,-8.7935,-4.1265,-4.1265,558.3754,27.9461,54.0427,-26.0966,0.9554,0.5171,7219.158,-8.6133,575.7731,45.3438,-13.0483,0,-104.3539,40.9944,0.4293,0.0154,0,0,1511891,-530.4293,0,0,0,1.51E+08,0,0,46.3563,26.0428,549.2467,580.1418,599.9051,20.4054,-8.7935,-1.5433,10.4986,5.4488,607.1021,580.1418,542.0498,76.6728,49.7125,11.6205,11.2396,-1.5433,-9.5345,576.4312,46.0019,65.0523,0.5856,6.5981,70.5724,0.1618,89.964
1,64.8,64.8,584.9802,50604.09,544,0,-0.1718,545.665,-17.0955,0,0,0.0528,0.0522,0.0518,0,0,0,-18.0072,0,0,100,0,0,0,0,0,0,0,0,0,0,572.5222,97920.17,14.6372,1.2501,0,0,0,0,0,0,0,0,0,0,4.0479,-8.8808,-4.165,-4.165,561.1663,15.5013,39.3153,-23.8139,0.9593,0.3943,7213.37,-8.6972,577.0422,31.3772,-11.907,0,958.9311,27.4083,1.665,0.1074,0,0,1511891,-545.665,0,0,0,1.51E+08,0,0,46.3398,26.0362,553.5132,580.4987,600.9556,7.2915,-8.8808,-1.4953,10.5339,4.5265,602.051,580.4987,552.4178,56.3861,34.8337,6.7528,11.048,-1.4953,-9.3949,578.3225,32.6575,49.6333,0.5658,8.35,81.4567,0.1578,89.9651
1,65.8,65.8,585.0485,50777.83,539,0,-0.159,546.3641,-18.2563,0,0,0.0528,0.0522,0.0518,0,0,0,-19.8687,0,0,100,0,0,0,0,0,0,0,0,0,0,572.3439,97756.8,-4.9274,-1.7701,0,0,0,0,0,0,0,0,0,0,4.0379,-9.4838,-4.4292,-4.4292,562.8801,16.5161,38.6845,-22.1684,0.9621,0.4269,7173.641,-9.2753,577.6591,31.295,-11.0842,0,469.9445,27.6003,7.3641,0.4459,0,0,1511891,-546.3641,0,0,0,1.51E+08,0,0,46.2147,25.9691,556.2794,580.4778,601.3448,-10.4094,-9.4838,-1.2131,10.8282,-1.5114,603.6331,580.4778,553.9912,57.269,34.1137,7.6271,10.8843,-1.2131,-9.5399,579.3674,33.0033,49.6419,0.5336,7.5086,-77.6023,0.1313,90.0243
1,66.8,66.8,585.0331,50700.38,525,0,-0.1809,527.8513,-18.8148,0,0,0.0528,0.0522,0.0518,0,0,0,-20.7973,0,0,100,0,0,0,0,0,0,0,0,0,0,572.066,97668.53,-18.1534,-4.6485,0,0,0,0,0,0,0,0,0,0,4.0048,-9.7739,-4.5556,-4.5556,559.7452,31.8939,57.1818,-25.2879,0.9568,0.5578,7154.684,-9.553,576.6038,48.7525,-12.644,0,373.7938,44.5379,2.8513,0.0894,0,0,1511891,-527.8513,0,0,0,1.51E+08,0,0,46.155,25.9373,551.5117,580.3677,601.6686,-27.4438,-9.7739,-1.0768,10.9689,-5.5463,613.7666,580.3677,539.4137,85.9153,52.5164,11.5624,11.6856,-1.0768,-10.4906,577.8493,49.998,74.3529,0.5508,7.4306,-66.2107,0.1182,90.0336
1,67.8,67.8,585.0905,50708.16,524,0,-0.1857,525.252,-18.959,0,0,0.0528,0.0522,0.0518,0,0,0,-21.0313,0,0,100,0,0,0,0,0,0,0,0,0,0,572.4395,97625.34,-20.9452,-4.9382,0,0,0,0,0,0,0,0,0,0,3.9976,-9.8488,-4.5881,-4.5881,559.1201,33.8681,59.8385,-25.9704,0.9556,0.566,7149.805,-9.6246,576.4337,51.1817,-12.9852,0,235.869,46.8533,1.252,0.037,0,0,1511891,-525.252,0,0,0,1.51E+08,0,0,46.14,25.9297,550.348,580.5388,601.3217,-29.1832,-9.8488,-1.0406,11.0037,-6.3929,614.5807,580.5388,537.089,89.3287,55.2868,11.837,11.9415,-1.0406,-10.7866,577.4028,52.1508,77.4917,0.5607,7.5466,-65.566,0.1143,90.0339
1,68.8,68.8,584.7574,50807.31,531,0,-0.1871,530.2721,-18.9696,0,0,0.0528,0.0522,0.0518,0,0,0,-21.0433,0,0,100,0,0,0,0,0,0,0,0,0,0,572.3565,97572.77,-20.8096,-3.5174,0,0,0,0,0,0,0,0,0,0,3.9936,-9.8543,-4.5905,-4.5905,558.5886,28.3165,54.4853,-26.1688,0.9552,0.5197,7149.447,-9.6299,576.0345,45.7624,-13.0844,0,-291.1114,41.4009,-0.7279,-0.0257,0,0,1511891,-530.2721,0,0,0,1.51E+08,0,0,46.1397,25.9306,549.592,580.2957,600.6691,-20.7877,-9.8543,-1.0347,11.0027,-6.3512,608.06,580.2957,542.2011,77.7879,50.0236,11.929,11.9286,-1.0347,-10.7802,576.8523,46.5802,65.8589,0.5784,6.5209,-70.4277,0.1137,90.0339
1,69.8,69.8,584.869,50993.37,539,0,-0.1728,545.457,-19.1351,0,0,0.0528,0.0522,0.0518,0,0,0,-21.3319,0,0,100,0,0,0,0,0,0,0,0,0,0,572.4124,97446.95,-18.1811,-1.2375,0,0,0,0,0,0,0,0,0,0,4.0054,-9.9403,-4.6279,-4.6279,560.6777,15.2207,39.4121,-24.1914,0.9586,0.3862,7143.854,-9.7121,576.8052,31.3482,-12.0957,0,-1305.698,27.3164,6.457,0.4242,0,0,1511891,-545.457,0,0,0,1.51E+08,0,0,46.1237,25.9241,552.8267,580.387,600.8558,-7.3216,-9.9403,-0.9881,11.0374,-5.5429,601.9471,580.387,551.7354,56.4901,34.9301,6.2784,11.7458,-0.9881,-10.6487,578.0232,32.5662,50.2117,0.5706,8.9975,-81.5222,0.109,90.0332
1,70.8,70.8,585.0605,51142.7,546,0,-0.1567,548.0438,-20.333,0,0,0.0528,0.0522,0.0518,0,0,0,-23.255,0,0,100,0,0,0,0,0,0,0,0,0,0,572.4129,97288.76,1.5117,1.5754,0,0,0,0,0,0,0,0,0,0,3.9994,-10.5626,-4.8966,-4.8966,563.0067,14.9629,37.0167,-22.0538,0.9623,0.4042,7103.646,-10.3061,577.7092,29.6654,-11.0269,0,442.6576,25.9898,2.0438,0.1366,0,0,1511891,-548.0438,0,0,0,1.51E+08,0,0,45.9962,25.8556,556.4357,580.5093,601.2969,9.3993,-10.5626,-0.6981,11.3403,0.457,603.1866,580.5093,554.546,55.1428,32.4655,6.5022,11.3451,-0.6981,-10.5674,579.4139,31.3702,48.6406,0.5338,8.4806,78.6322,0.0796,89.9902
1,71.8,71.8,584.9186,51063.73,528,0,-0.1797,527.0455,-20.9963,0,0,0.0528,0.0522,0.0518,0,0,0,-24.3574,0,0,100,0,0,0,0,0,0,0,0,0,0,572.3897,97202.2,16.5359,4.6337,0,0,0,0,0,0,0,0,0,0,3.9624,-10.9072,-5.0445,-5.0445,559.5366,32.4912,57.8731,-25.382,0.9566,0.5614,7081.574,-10.6345,576.4579,49.4124,-12.691,0,16755.56,45.1822,-0.9545,-0.0294,0,0,1511891,-527.0455,0,0,0,1.51E+08,0,0,45.9261,25.8179,551.0578,580.4099,601.0049,27.774,-10.9072,-0.5381,11.5076,4.9762,613.382,580.4099,538.6807,86.3366,53.3644,11.6353,12.047,-0.5381,-11.4466,577.4909,50.4454,74.7013,0.5586,7.4202,65.9805,0.0623,89.9694
1,72.8,72.8,584.8562,51061.53,522,0,-0.1858,523.9279,-21.1671,0,0,0.0528,0.0522,0.0518,0,0,0,-24.6471,0,0,100,0,0,0,0,0,0,0,0,0,0,572.2528,97170.27,19.3758,4.9523,0,0,0,0,0,0,0,0,0,0,3.9526,-10.9959,-5.0824,-5.0824,558.5992,34.6713,60.9283,-26.257,0.9551,0.5691,7075.915,-10.7189,576.1038,52.1759,-13.1285,0,-665.975,47.7998,1.9279,0.0556,0,0,1511891,-523.9279,0,0,0,1.51E+08,0,0,45.9083,25.8085,549.6516,580.3207,601.0392,29.7186,-10.9959,-0.4965,11.5499,5.8239,614.6311,580.3207,536.0597,90.7032,56.3928,12.1318,12.2786,-0.4965,-11.7246,577.0038,53.0759,78.5714,0.5633,7.4765,65.4228,0.0575,89.9689
1,73.8,73.8,584.8698,51130.67,525,0,-0.1878,529.2,-21.172,0,0,0.0528,0.0522,0.0518,0,0,0,-24.6748,0,0,100,0,0,0,0,0,0,0,0,0,0,572.0411,97120.19,19.2169,3.5282,0,0,0,0,0,0,0,0,0,0,3.9506,-10.9984,-5.0835,-5.0835,558.3291,29.1291,55.6698,-26.5407,0.9546,0.5232,7075.755,-10.7213,576.0229,46.8229,-13.2704,0,-976.2662,42.3995,4.2,0.1442,0,0,1511891,-529.2,0,0,0,1.51E+08,0,0,45.9086,25.8097,549.3275,580.2531,601.3436,21.1728,-10.9984,-0.4921,11.5475,5.7761,608.8722,580.2531,541.799,79.6722,51.0531,12.599,12.2646,-0.4921,-11.7155,576.9748,47.7748,67.0732,0.5733,6.3237,70.4257,0.057,89.969
1,74.8,74.8,584.7905,51344.69,547,0,-0.1702,546.1998,-21.3301,0,0,0.0528,0.0522,0.0518,0,0,0,-24.9086,0,0,100,0,0,0,0,0,0,0,0,0,0,572.5612,96995.63,16.3056,1.2911,0,0,0,0,0,0,0,0,0,0,3.9646,-11.0806,-5.1186,-5.1186,560.7226,14.5228,38.5907,-24.0679,0.9588,0.3763,7070.519,-10.7995,576.7679,30.5681,-12.034,0,-494.9214,26.5568,-0.8002,-0.0551,0,0,1511891,-546.1998,0,0,0,1.51E+08,0,0,45.8936,25.8037,552.8314,580.3892,600.498,7.756,-11.0806,-0.4475,11.5802,4.896,601.7282,580.3892,551.6011,55.5284,34.1894,5.4012,12.0973,-0.4475,-11.5977,577.9062,31.7063,50.1272,0.5743,10.2808,80.9868,0.0521,89.9698
1,75.8,75.8,585.0355,51497.29,546,0,-0.1588,547.714,-22.5229,0,0,0.0528,0.0522,0.0518,0,0,0,-26.8367,0,0,100,0,0,0,0,0,0,0,0,0,0,572.2206,96838.51,-4.7257,-1.5565,0,0,0,0,0,0,0,0,0,0,3.9548,-11.7002,-5.3822,-5.3822,562.4565,14.7425,37.3215,-22.579,0.9614,0.395,7031.299,-11.3883,577.5092,29.7952,-11.2895,0,532.3629,26.032,1.714,0.1163,0,0,1511891,-547.714,0,0,0,1.51E+08,0,0,45.7687,25.7366,555.6727,580.4231,601.4997,-9.4278,-11.7002,-0.1602,11.8798,-1.4073,603.3634,580.4231,553.809,55.6494,32.7091,6.095,11.9217,-0.1602,-11.7421,579.1985,31.4845,49.5544,0.5371,9.1303,-78.8176,0.0194,90.0202
1,76.8,76.8,584.7721,51427.71,523,0,-0.1769,527.0184,-23.1398,0,0,0.0528,0.0522,0.0518,0,0,0,-27.8177,0,0,100,0,0,0,0,0,0,0,0,0,0,572.3469,96759.63,-21.8428,-4.53,0,0,0,0,0,0,0,0,0,0,3.923,-12.0207,-5.5176,-5.5176,559.5348,32.5164,57.7537,-25.2373,0.9568,0.563,7011.182,-11.6922,576.3597,49.3413,-12.6187,0,-298.2568,45.1351,4.0184,0.1236,0,0,1511891,-527.0184,0,0,0,1.51E+08,0,0,45.7045,25.702,551.0952,580.2998,600.7377,-27.5553,-12.0207,-0.0125,12.0346,-6.4771,613.0027,580.2998,538.8302,85.9843,53.2814,11.8118,12.8771,-0.0125,-12.8632,577.3776,50.3592,74.1725,0.5591,7.2795,-66.0059,0.0014,90.0295
1,77.8,77.8,584.885,51421.07,522,0,-0.1877,523.9803,-23.3417,0,0,0.0528,0.0522,0.0518,0,0,0,-28.1443,0,0,100,0,0,0,0,0,0,0,0,0,0,572.2462,96742.11,-27.2107,-4.9473,0,0,0,0,0,0,0,0,0,0,3.9092,-12.1256,-5.5618,-5.5618,558.0886,34.1083,60.9047,-26.7964,0.9542,0.56,7004.623,-11.7916,575.9529,51.9726,-13.3982,0,-1286.444,47.5065,1.9803,0.0581,0,0,1511891,-523.9803,0,0,0,1.51E+08,0,0,45.6834,25.6905,548.8611,580.3358,601.1256,-30.1357,-12.1256,0.0355,12.0858,-8.0576,614.8814,580.3358,535.1053,90.9011,56.3555,11.125,13.3596,0.0355,-13.3994,576.7742,52.7939,79.7761,0.567,8.1709,-65.4651,-0.0043,90.0299
1,78.8,78.8,584.6451,51489.37,534,0,-0.1867,529.6072,-23.3497,0,0,0.0528,0.0522,0.0518,0,0,0,-28.1673,0,0,100,0,0,0,0,0,0,0,0,0,0,572.3455,96699.36,-27.0746,-3.5244,0,0,0,0,0,0,0,0,0,0,3.9084,-12.1297,-5.5635,-5.5635,557.9948,28.3876,55.0379,-26.6503,0.9544,0.5158,7004.366,-11.7955,575.7617,46.1545,-13.3252,0,-167.9893,41.7128,-4.3928,-0.1547,0,0,1511891,-529.6072,0,0,0,1.51E+08,0,0,45.6832,25.6912,548.6862,580.2178,600.4509,-21.469,-12.1297,0.04,12.085,-8.017,608.1962,580.2178,540.941,78.5891,50.6106,11.3338,13.3464,0.04,-13.3911,576.4517,46.8445,67.2553,0.584,6.934,-70.1624,-0.0047,90.0299
1,79.8,79.8,584.799,51698.54,546,0,-0.1704,546.7507,-23.543,0,0,0.0528,0.0522,0.0518,0,0,0,-28.4415,0,0,100,0,0,0,0,0,0,0,0,0,0,572.3373,96585.62,-24.0122,-1.3436,0,0,0,0,0,0,0,0,0,0,3.9221,-12.2301,-5.6058,-5.6058,560.4521,13.7014,38.0483,-24.3469,0.9584,0.3601,6998.1,-11.8906,576.6833,29.9326,-12.1735,0,-535.5156,25.8749,0.7507,0.0548,0,0,1511891,-546.7507,0,0,0,1.51E+08,0,0,45.6646,25.683,552.5187,580.3132,600.8165,-8.1951,-12.2301,0.0921,12.1271,-7.1011,602.1692,580.3132,551.166,55.4185,33.5625,4.4153,13.1216,0.0921,-13.2246,577.8828,31.1321,51.0032,0.5715,12.5515,-80.6275,-0.0109,90.0294
1,80.8,80.8,584.7885,51849.77,547,0,-0.1544,550.2024,-24.7743,0,0,0.0528,0.0522,0.0518,0,0,0,-30.5185,0,0,100,0,0,0,0,0,0,0,0,0,0,572.5387,96440.39,-0.9178,1.2206,0,0,0,0,0,0,0,0,0,0,3.9148,-12.8698,-5.8737,-5.8737,562.5975,12.3951,34.5861,-22.191,0.9621,0.3584,6958.438,-12.4957,577.3915,27.1891,-11.0955,0,-518.4952,23.4906,3.2024,0.2584,0,0,1511891,-550.2024,0,0,0,1.51E+08,0,0,45.5374,25.6143,555.788,580.3786,600.5376,7.508,-12.8698,0.386,12.4358,-0.2691,601.7637,580.3786,554.562,51.5613,30.1762,4.3596,12.4372,0.386,-12.8712,578.9014,28.699,47.2017,0.5469,11.8271,80.7252,-0.048,90.0052
1,81.6,81.6,584.952,51783.61,533,0,-0.1767,529.6369,-25.5219,0,0,0.0528,0.0522,0.0518,0,0,0,-31.7692,0,0,100,0,0,0,0,0,0,0,0,0,0,572.2289,96367.16,22.5631,4.3003,0,0,0,0,0,0,0,0,0,0,3.8797,-13.2581,-6.0352,-6.0352,559.4714,29.8345,55.3151,-25.4807,0.9564,0.5394,6934.582,-12.8622,576.4585,46.8216,-12.7404,0,1264.731,42.5748,-3.3631,-0.1127,0,0,1511891,-529.6369,0,0,0,1.51E+08,0,0,45.4604,25.5724,551.0276,580.3716,601.3116,26.5869,-13.2581,0.5632,12.624,6.5828,612.7617,580.3716,539.5775,83.1248,50.7347,9.9406,13.4357,0.5632,-14.0698,577.5703,47.9334,73.1842,0.5574,8.3622,66.7,-0.0709,89.9726