File: datas/d100-30-0.175.csv
Stage Number,Time since start of test (s),Time since start of stage (s),Radial Pressure (kPa),Radial Volume (mm3),Back Pressure (kPa),Back Volume (mm3),Load Cell (kN),Pore Pressure (kPa),Axial Displacement (mm),L/C Pressure (kPa),L/C Volume (mm3),Local Axial 1,Local Axial 2,Local Radial,Base Pressure (kPa),Base Volume (mm3),Back Differential Pressure (kPa),Axial Displacement 2 (mm),Pore Air Pressure (kPa),Pore Air Volume (mm3),Atmospheric Pressure (kPa),Temperature (°C),Mid Plane PWP (kPa),Back to Cell Differential (kPa),Total Volume Change (mm3),Undefined Tx 1,Undefined Tx 2,Undefined Tx 3,Undefined Tx. 4,HCA secondary control axial load (kN),HCA secondary control torque,Internal Cell Pr. (kPa),Internal Cell Vol. (mm3),Rotational Displ. (mm),Torque,Local Int Defmn 1 (mm),Local Int Defmn 2 (mm),Circumf. Defmn 1 (mm),Circumf. Defmn 2 (mm),Circumf. Defmn 3 (mm),Outer Cell Pr 2 (kPa),Internal cell Pr 2 (kPa),Rotation 2 (°),Secondary Cell Pr (kPa),Secondary Back Pr (kPa),Axial Force (kN),Axial Strain (%),Av Diameter Change (mm),Radial Strain (%),Axial Stress (kPa),Eff. Axial Stress (kPa),Eff. Radial Stress (kPa),Deviator Stress (kPa),Total Stress Ratio (%),Eff. Stress Ratio (%),Current Area (mm2),Shear Strain (%),Cambridge p (kPa),Eff. Cambridge p' (kPa),Max Shear Stress t,Volume Change (mm3),B Value,Mean Stress s/Eff. Axial Stress 2,Excess PWP (kPa),PWP Ratio,Lower Chamber Displacement (mm),Lower Chamber Axial Load (kPa),Specimen Air Volume (mm3),Matric Suction (kPa),Voids ratio,Degree of Saturation (°),Specimen Water Volume (mm3),kRT constant,Permeability IN,Permeability OUT,HCA Outer Rad,HCA Inner Rad,HCA Sigma Z (kPa),HCA Sigma R (kPa),HCA Sigma Theta (kPa),HCA Tau Theta Z,HCA Ez,HCA Er,HCA Etheta,HCA Gamma,HCA Sigma1,HCA Sigma2,HCA Sigma3,HCA Eff Sigma1,HCA Eff Sigma2,HCA Eff Sigma3,HCA E1,HCA E2,HCA E3,HCA P,HCA Eff P,HCA Q,HCA B,HCA Eff R,HCA Alpha,HCA Ev,HCA E1 rtv
1,0,0,567.6933,86520.77,471,0,0.0842,472.0692,-0.0006,0,0,0.0528,0.0522,0.0518,0,0,0,4.305,0,0,100,0,0,0,0,0,0,0,0,0,0,574.5339,85745.82,0.0034,4.3258,0,0,0,0,0,0,0,0,0,0,4.5428,-0.0003,-0.0002,-0.0002,578.4095,106.3403,95.6241,10.7162,1.0189,1.1121,7853.951,-0.0003,571.2654,99.1962,5.3581,0,0.412,100.9822,1.0692,0.0101,0,0,1541658,-472.0692,0,0,0,1.54E+08,0,0,48.5895,27.5853,581.1911,570.1705,558.7094,22.0368,-0.0003,-4.7809,5.0216,0.0012,594.6884,570.1705,545.2121,122.6192,98.1013,73.1429,5.0216,-4.7809,-0.0003,570.0237,97.9545,49.4763,0.5045,1.6764,31.4871,0.2404,89.9999
1,8,8,567.7755,86774.94,478,0,0.0935,479.7317,0.0504,0,0,0.0528,0.0522,0.0518,0,0,0,4.3742,0,0,100,0,0,0,0,0,0,0,0,0,0,574.2332,85582.61,0.1001,0.9933,0,0,0,0,0,0,0,0,0,0,4.5539,0.0257,0.0129,0.0129,579.672,99.9403,88.0438,11.8965,1.021,1.1351,7855.994,0.0257,571.741,92.0093,5.9483,0,-203.4821,93.9921,1.7317,0.0173,0,0,1541658,-479.7317,0,0,0,1.54E+08,0,0,48.5986,27.5937,583.2996,570.1142,559.2921,5.0577,0.0257,-4.7841,4.9975,0.0348,584.3217,570.1142,558.2701,104.59,90.3825,78.5384,4.9976,-4.7841,0.0256,570.902,91.1703,26.0516,0.4546,1.3317,11.4239,0.2391,89.9965
1,16.2,16.2,567.9714,86923.72,483,0,0.0938,484.5661,0.0885,0,0,0.0528,0.0522,0.0518,0,0,0,4.4289,0,0,100,0,0,0,0,0,0,0,0,0,0,574.0867,85420.92,0.4489,1.9603,0,0,0,0,0,0,0,0,0,0,4.5566,0.0451,0.0226,0.0226,579.9032,95.3371,83.4053,11.9318,1.021,1.1431,7857.519,0.0451,571.9487,87.3826,5.9659,0,78.5599,89.3712,1.5661,0.0164,0,0,1541658,-484.5661,0,0,0,1.54E+08,0,0,48.606,27.6011,583.7135,570.1863,559.9357,9.9777,0.0451,-4.7841,4.9771,0.156,587.3455,570.1863,556.3036,102.7794,85.6202,71.7375,4.9796,-4.7841,0.0426,571.2784,86.7124,31.0419,0.4472,1.4327,20.0025,0.2381,89.9843
1,24.4,24.4,567.9109,87069.31,485,0,0.093,486.7881,0.115,0,0,0.0528,0.0522,0.0518,0,0,0,4.4685,0,0,100,0,0,0,0,0,0,0,0,0,0,573.9971,85289.41,0.9707,5.722,0,0,0,0,0,0,0,0,0,0,4.556,0.0586,0.0293,0.0293,579.7485,92.9604,81.1228,11.8376,1.0208,1.1459,7858.58,0.0586,571.8568,85.0687,5.9188,0,149.7486,87.0416,1.7881,0.0192,0,0,1541658,-486.7881,0,0,0,1.54E+08,0,0,48.6114,27.6068,583.5045,570.1153,559.9117,29.1165,0.0586,-4.7828,4.9618,0.3374,603.1235,570.1153,540.2927,116.3354,83.3272,53.5046,4.9734,-4.7828,0.047,571.1772,84.3891,62.8308,0.4746,2.1743,33.9724,0.2376,89.9668
1,32.6,32.6,567.7267,87280.31,487,0,0.093,488.2618,0.1381,0,0,0.0528,0.0522,0.0518,0,0,0,4.5092,0,0,100,0,0,0,0,0,0,0,0,0,0,574.0685,85047.23,1.3515,7.9617,0,0,0,0,0,0,0,0,0,0,4.5551,0.0704,0.0352,0.0352,579.5655,91.3037,79.4649,11.8388,1.0209,1.149,7859.508,0.0704,571.6729,83.4111,5.9194,0,-187.1847,85.3843,1.2618,0.0138,0,0,1541658,-488.2618,0,0,0,1.54E+08,0,0,48.6184,27.6156,583.1948,570.024,559.3881,40.5005,0.0704,-4.7746,4.9401,0.47,613.505,570.024,529.078,125.2432,81.7622,40.8162,4.9627,-4.7746,0.0478,570.869,82.6072,84.427,0.485,3.0685,36.8108,0.2359,89.9549
1,40.8,40.8,567.7263,87538.65,493,0,0.0975,494.0626,0.176,0,0,0.0528,0.0522,0.0518,0,0,0,4.5754,0,0,100,0,0,0,0,0,0,0,0,0,0,574.0535,84769.92,1.2769,6.1397,0,0,0,0,0,0,0,0,0,0,4.5604,0.0897,0.0449,0.0449,580.1278,86.0652,73.6637,12.4015,1.0218,1.1684,7861.026,0.0897,571.8602,77.7976,6.2008,0,-253.37,79.8645,1.0626,0.0123,0,0,1541658,-494.0626,0,0,0,1.54E+08,0,0,48.6277,27.6264,584.0905,570.0186,559.4031,31.2184,0.0897,-4.7678,4.9124,0.4442,605.317,570.0186,538.1766,111.2544,75.956,44.114,4.9328,-4.7678,0.0693,571.1707,77.1081,67.1404,0.4743,2.522,34.2131,0.2343,89.9567
1,49,49,567.6058,87714.7,498,0,0.0952,499.7967,0.2223,0,0,0.0528,0.0522,0.0518,0,0,0,4.6476,0,0,100,0,0,0,0,0,0,0,0,0,0,574.1571,84590.27,1.2374,2.3153,0,0,0,0,0,0,0,0,0,0,4.5582,0.1133,0.0567,0.0567,579.711,79.9143,67.8091,12.1052,1.0213,1.1785,7862.884,0.1133,571.6409,71.8442,6.0526,0,-133.6121,73.8617,1.7967,0.0225,0,0,1541658,-499.7967,0,0,0,1.54E+08,0,0,48.6364,27.6349,583.4003,569.9794,558.9852,11.7673,0.1133,-4.7687,4.8887,0.4307,588.1484,569.9794,554.2371,88.3517,70.1827,54.4404,4.908,-4.7687,0.094,570.7883,70.9916,33.9113,0.4642,1.6229,21.974,0.2333,89.9574
1,57.2,57.2,567.8714,87819.31,502,0,0.0933,503.5865,0.2534,0,0,0.0528,0.0522,0.0518,0,0,0,4.7007,0,0,100,0,0,0,0,0,0,0,0,0,0,574.1354,84530.8,1.3253,0.8883,0,0,0,0,0,0,0,0,0,0,4.5591,0.1291,0.0646,0.0646,579.7338,76.1473,64.2849,11.8624,1.0209,1.1845,7864.127,0.1291,571.8255,68.239,5.9312,0,538.1749,70.2161,1.5865,0.0208,0,0,1541658,-503.5865,0,0,0,1.54E+08,0,0,48.6413,27.6389,583.4221,570.1411,559.6281,4.5135,0.1291,-4.7728,4.8765,0.4614,584.2496,570.1411,558.8007,80.6631,66.5546,55.2142,4.8988,-4.7728,0.1068,571.0638,67.4773,25.4489,0.4456,1.4609,10.3879,0.2328,89.9545
1,65.4,65.4,567.5706,87835.52,502,0,0.0933,503.1934,0.2623,0,0,0.0528,0.0522,0.0518,0,0,0,4.6991,0,0,100,0,0,0,0,0,0,0,0,0,0,574.3329,84510.77,1.8124,3.521,0,0,0,0,0,0,0,0,0,0,4.5569,0.1336,0.0669,0.0669,579.4279,76.2345,64.3772,11.8573,1.0209,1.1842,7864.482,0.1337,571.523,68.3296,5.9287,0,-128.2446,70.3059,1.1934,0.0157,0,0,1541658,-503.1934,0,0,0,1.54E+08,0,0,48.6427,27.6401,582.8827,570.0209,558.6713,17.8888,0.1336,-4.7737,4.8729,0.631,592.3769,570.0209,549.1771,89.1835,66.8275,45.9837,4.9145,-4.7737,0.092,570.525,67.3316,43.1998,0.4825,1.9395,27.9565,0.2328,89.9406
1,73.6,73.6,567.9452,87970.19,500,0,0.0933,501.4982,0.2685,0,0,0.0528,0.0522,0.0518,0,0,0,4.7188,0,0,100,0,0,0,0,0,0,0,0,0,0,573.7784,84388.09,2.2959,7.1775,0,0,0,0,0,0,0,0,0,0,4.56,0.1368,0.0685,0.0685,579.8035,78.3053,66.447,11.8583,1.0209,1.1785,7864.734,0.1369,571.8979,70.3997,5.9292,0,222.1306,72.3761,1.4982,0.0191,0,0,1541658,-501.4982,0,0,0,1.54E+08,0,0,48.6455,27.6441,583.699,570.059,560.267,36.462,0.1368,-4.7683,4.8636,0.7995,610.2811,570.059,533.685,108.7829,68.5608,32.1868,4.9303,-4.7683,0.0701,571.3417,69.8435,76.5961,0.4749,3.3797,36.0934,0.2321,89.9287
1,81.8,81.8,567.9446,88155.59,502,0,0.0941,503.3353,0.2879,0,0,0.0528,0.0522,0.0518,0,0,0,4.803,0,0,100,0,0,0,0,0,0,0,0,0,0,573.9513,84133.31,2.3995,7.6545,0,0,0,0,0,0,0,0,0,0,4.5613,0.1467,0.0734,0.0734,579.9112,76.5759,64.6093,11.9666,1.0211,1.1852,7865.514,0.1467,571.9334,68.5981,5.9833,0,237.1145,70.5926,1.3353,0.0174,0,0,1541658,-503.3353,0,0,0,1.54E+08,0,0,48.6522,27.653,583.7712,570.1214,560.0345,38.8739,0.1467,-4.7583,4.8421,0.8358,612.5481,570.1214,531.2576,109.2128,66.7861,27.9223,4.9153,-4.7583,0.0735,571.309,67.9737,81.2905,0.4781,3.9113,36.5112,0.2305,89.9259
1,90,90,567.8482,88384.5,508,0,0.0948,509.7239,0.3355,0,0,0.0528,0.0522,0.0518,0,0,0,4.8467,0,0,100,0,0,0,0,0,0,0,0,0,0,573.8887,83928.63,2.2308,4.4199,0,0,0,0,0,0,0,0,0,0,4.5623,0.1709,0.0856,0.0856,579.8979,70.174,58.1243,12.0497,1.0212,1.2073,7867.42,0.171,571.8647,62.1408,6.0249,0,1065.964,64.1492,1.7239,0.0246,0,0,1541658,-509.7239,0,0,0,1.54E+08,0,0,48.6615,27.6624,583.7919,570.0375,559.8911,22.4362,0.1709,-4.7578,4.8164,0.7774,597.2618,570.0375,546.4211,87.5379,60.3136,36.6972,4.8806,-4.7578,0.1067,571.2402,61.5162,50.8407,0.4645,2.3854,30.9793,0.2295,89.9289
1,98.2,98.2,567.9286,88461.56,513,0,0.0935,513.9529,0.3766,0,0,0.0528,0.0522,0.0518,0,0,0,4.8928,0,0,100,0,0,0,0,0,0,0,0,0,0,574.1315,83893.57,2.1758,1.156,0,0,0,0,0,0,0,0,0,0,4.5626,0.1919,0.0961,0.0961,579.814,65.8612,53.9757,11.8854,1.0209,1.2202,7869.076,0.192,571.8904,57.9375,5.9427,0,361.6963,59.9185,0.9529,0.0145,0,0,1541658,-513.9529,0,0,0,1.54E+08,0,0,48.6672,27.6663,583.5325,570.1768,559.757,5.8661,0.1919,-4.766,4.8033,0.7585,584.9011,570.1768,558.3885,70.9482,56.2239,44.4356,4.8649,-4.766,0.1303,571.1555,57.2026,26.5126,0.4446,1.5967,13.1322,0.2292,89.9296
1,106.4,106.4,567.7357,88455.06,513,0,0.0945,514.8605,0.3887,0,0,0.0528,0.0522,0.0518,0,0,0,4.9244,0,0,100,0,0,0,0,0,0,0,0,0,0,574.0092,83944.46,2.5032,1.626,0,0,0,0,0,0,0,0,0,0,4.5623,0.198,0.0991,0.0991,579.7404,64.8799,52.8752,12.0047,1.0211,1.227,7869.557,0.1981,571.7373,56.8768,6.0024,0,-553.5846,58.8776,1.8605,0.0287,0,0,1541658,-514.8605,0,0,0,1.54E+08,0,0,48.6678,27.6656,583.5036,570.0094,559.4718,8.2506,0.198,-4.7719,4.8034,0.8727,586.0635,570.0094,556.9119,71.203,55.1489,42.0515,4.8847,-4.7719,0.1167,570.9949,56.1345,29.1515,0.4493,1.6932,17.2375,0.2295,89.9221
1,114.6,114.6,567.8036,88459.27,510,0,0.0927,511.8716,0.3783,0,0,0.0528,0.0522,0.0518,0,0,0,4.9056,0,0,100,0,0,0,0,0,0,0,0,0,0,574.1113,83940.52,3.1388,5.3268,0,0,0,0,0,0,0,0,0,0,4.5608,0.1927,0.0965,0.0965,579.5806,67.709,55.932,11.777,1.0207,1.2106,7869.139,0.1928,571.7292,59.8576,5.8885,0,-4256.961,61.8205,1.8716,0.0276,0,0,1541658,-511.8716,0,0,0,1.54E+08,0,0,48.6666,27.665,583.1987,570.0897,559.4946,27.031,0.1927,-4.7692,4.8059,1.0942,600.8619,570.0897,541.8315,88.9903,58.2181,29.9599,4.9322,-4.7692,0.0664,570.9277,59.0561,59.0304,0.4787,2.9703,33.1622,0.2294,89.91
1,122.8,122.8,568.1165,88600.67,508,0,0.094,509.1725,0.3821,0,0,0.0528,0.0522,0.0518,0,0,0,4.9514,0,0,100,0,0,0,0,0,0,0,0,0,0,573.8594,83745.72,3.6117,7.93,0,0,0,0,0,0,0,0,0,0,4.5647,0.1947,0.0975,0.0975,580.0646,70.8921,58.944,11.9481,1.021,1.2027,7869.296,0.1948,572.0992,62.9267,5.9741,0,122.0532,64.9181,1.1725,0.0165,0,0,1541658,-509.1725,0,0,0,1.54E+08,0,0,48.6704,27.671,584.0379,570.1981,560.5491,40.2354,0.1947,-4.7592,4.7924,1.2592,614.2079,570.1981,530.379,105.0354,61.0256,21.2065,4.9588,-4.7592,0.0283,571.595,62.4225,83.8289,0.475,4.953,36.8639,0.2279,89.9022
1,131,131,567.9609,88875.07,513,0,0.0944,514.4985,0.4259,0,0,0.0528,0.0522,0.0518,0,0,0,5.0119,0,0,100,0,0,0,0,0,0,0,0,0,0,573.9436,83476.68,3.4537,6.5262,0,0,0,0,0,0,0,0,0,0,4.5649,0.217,0.1087,0.1087,579.9604,65.4619,53.4624,11.9995,1.0211,1.2244,7871.055,0.2171,571.9607,57.4622,5.9998,0,286.4495,59.4622,1.4985,0.0229,0,0,1541658,-514.4985,0,0,0,1.54E+08,0,0,48.6803,27.682,583.8413,570.1296,560.0739,33.0969,0.217,-4.7542,4.7637,1.2047,607.1234,570.1296,536.7919,92.6249,55.6311,22.2934,4.9181,-4.7542,0.0626,571.3483,56.8498,70.3315,0.474,4.1548,35.1245,0.2265,89.9034
1,139.2,139.2,567.7908,89000.55,519,0,0.0942,521.0939,0.4834,0,0,0.0528,0.0522,0.0518,0,0,0,5.0927,0,0,100,0,0,0,0,0,0,0,0,0,0,574.1579,83372.83,3.2861,2.6959,0,0,0,0,0,0,0,0,0,0,4.5646,0.2463,0.1234,0.1234,579.752,58.6581,46.6969,11.9612,1.0211,1.2561,7873.367,0.2465,571.7778,50.6839,5.9806,0,-2210.503,52.6775,2.0939,0.0357,0,0,1541658,-521.0939,0,0,0,1.54E+08,0,0,48.6892,27.6891,583.4416,570.099,559.3956,13.6651,0.2463,-4.7624,4.7418,1.1468,589.6199,570.099,553.2173,68.526,49.0051,32.1234,4.8836,-4.7624,0.1045,570.9787,49.8848,36.4026,0.4637,2.1332,24.3288,0.2257,89.9051
1,147.4,147.4,567.9743,88956.05,522,0,0.0929,523.8992,0.5164,0,0,0.0528,0.0522,0.0518,0,0,0,5.1283,0,0,100,0,0,0,0,0,0,0,0,0,0,574.4831,83447.57,3.3416,0.8548,0,0,0,0,0,0,0,0,0,0,4.5655,0.2631,0.1318,0.1318,579.7686,55.8695,44.0751,11.7943,1.0208,1.2676,7874.693,0.2633,571.9058,48.0067,5.8972,0,320.8678,49.9723,1.8992,0.034,0,0,1541658,-523.8992,0,0,0,1.54E+08,0,0,48.6921,27.6893,583.2968,570.3339,559.3933,4.3319,0.2631,-4.7746,4.7375,1.1664,584.0577,570.3339,558.6325,60.1585,46.4348,34.7333,4.8847,-4.7746,0.1159,571.0081,47.1089,25.4252,0.4602,1.732,9.9615,0.226,89.9037
1,155.6,155.6,567.6907,88876.07,519,0,0.0929,521.0273,0.5002,0,0,0.0528,0.0522,0.0518,0,0,0,5.1074,0,0,100,0,0,0,0,0,0,0,0,0,0,574.2332,83553.05,4.0538,3.0631,0,0,0,0,0,0,0,0,0,0,4.5629,0.2548,0.1276,0.1276,579.4867,58.4594,46.6634,11.796,1.0208,1.2528,7874.038,0.2549,571.6227,50.5954,5.898,0,-400.0607,52.5614,2.0273,0.0347,0,0,1541658,-521.0273,0,0,0,1.54E+08,0,0,48.6882,27.685,582.9994,570.0623,559.0667,15.5261,0.2548,-4.7764,4.7488,1.4147,590.6354,570.0623,551.4307,69.6081,49.035,30.4034,4.9614,-4.7764,0.0422,570.7095,49.6822,39.2047,0.4752,2.2895,26.1888,0.2272,89.8937
1,163.8,163.8,567.9062,88937.14,515,0,0.0939,516.1229,0.484,0,0,0.0528,0.0522,0.0518,0,0,0,5.0909,0,0,100,0,0,0,0,0,0,0,0,0,0,573.8903,83494.84,4.7509,6.8537,0,0,0,0,0,0,0,0,0,0,4.5652,0.2466,0.1235,0.1235,579.8264,63.7035,51.7833,11.9202,1.021,1.2302,7873.391,0.2467,571.8796,55.7567,5.9601,0,471.838,57.7434,1.1229,0.0176,0,0,1541658,-516.1229,0,0,0,1.54E+08,0,0,48.6872,27.6856,583.6813,570.0754,560.0176,34.7428,0.2466,-4.7692,4.7493,1.6579,608.5517,570.0754,535.1472,92.4288,53.9525,19.0243,5.0362,-4.7692,-0.0403,571.2581,55.1352,73.4045,0.4758,4.8585,35.5967,0.2267,89.8858
1,172,172,568.0841,89183.41,515,0,0.0945,516.384,0.506,0,0,0.0528,0.0522,0.0518,0,0,0,5.1318,0,0,100,0,0,0,0,0,0,0,0,0,0,573.6979,83241.32,5.0139,7.7721,0,0,0,0,0,0,0,0,0,0,4.5678,0.2578,0.1291,0.1291,580.0915,63.7075,51.7001,12.0074,1.0211,1.2323,7874.275,0.2579,572.0866,55.7026,6.0037,0,163.2333,57.7038,1.384,0.0217,0,0,1541658,-516.384,0,0,0,1.54E+08,0,0,48.6942,27.6946,584.1517,570.1194,560.6805,39.3861,0.2578,-4.7601,4.7274,1.7502,613.5134,570.1194,531.3188,97.1295,53.7354,14.9348,5.0472,-4.7601,-0.062,571.6506,55.2666,82.1947,0.4721,6.5036,36.7039,0.2251,89.8823
1,180.2,180.2,567.6485,89335.46,523,0,0.0945,524.9556,0.5808,0,0,0.0528,0.0522,0.0518,0,0,0,5.2479,0,0,100,0,0,0,0,0,0,0,0,0,0,573.9956,83047.89,4.7539,4.853,0,0,0,0,0,0,0,0,0,0,4.566,0.2959,0.1483,0.1483,579.6414,54.6858,42.6929,11.9929,1.0211,1.2809,7877.284,0.2961,571.6462,46.6906,5.9965,0,-321.3376,48.6894,1.9556,0.0358,0,0,1541658,-524.9556,0,0,0,1.54E+08,0,0,48.7067,27.7055,583.3571,569.9498,559.2752,24.5766,0.2959,-4.7673,4.6953,1.6605,598.6839,569.9498,543.9484,73.7283,44.9942,18.9928,4.9891,-4.7673,0.0021,570.8608,45.9051,54.7355,0.475,3.8819,31.9491,0.2239,89.8831
1,188.4,188.4,567.7721,89357.75,529,0,0.0938,530.6092,0.646,0,0,0.0528,0.0522,0.0518,0,0,0,5.3318,0,0,100,0,0,0,0,0,0,0,0,0,0,574.0135,83101.1,4.6395,1.3791,0,0,0,0,0,0,0,0,0,0,4.5678,0.3291,0.165,0.165,579.6768,49.0676,37.1629,11.9047,1.021,1.3203,7879.908,0.3294,571.7403,41.1311,5.9524,0,-1432.454,43.1153,1.6092,0.0328,0,0,1541658,-530.6092,0,0,0,1.54E+08,0,0,48.7139,27.7086,583.3865,570.035,559.5389,6.9808,0.3291,-4.7859,4.6812,1.6213,585.2796,570.035,557.6457,54.6704,39.4258,27.0365,4.9647,-4.7859,0.0456,570.9868,40.3776,27.6339,0.4483,2.0221,15.1734,0.2244,89.883
1,196.6,196.6,567.8882,89285.41,528,0,0.0923,530.6039,0.6539,0,0,0.0528,0.0522,0.0518,0,0,0,5.3436,0,0,100,0,0,0,0,0,0,0,0,0,0,574.4563,83263.35,5.1132,1.4181,0,0,0,0,0,0,0,0,0,0,4.5674,0.3331,0.167,0.167,579.6028,48.9989,37.2843,11.7146,1.0206,1.3142,7880.224,0.3334,571.793,41.1892,5.8573,0,777.1488,43.1416,2.6039,0.0531,0,0,1541658,-530.6039,0,0,0,1.54E+08,0,0,48.7122,27.7044,583.0493,570.2694,559.2263,7.1784,0.3331,-4.7973,4.6893,1.7868,585.0451,570.2694,557.2305,54.4412,39.6655,26.6267,5.0292,-4.7973,-0.0068,570.8483,40.2445,27.8145,0.4688,2.0446,15.5375,0.2251,89.8783
1,204.8,204.8,568.0531,89221.3,523,0,0.0955,524.0296,0.6069,0,0,0.0528,0.0522,0.0518,0,0,0,5.2795,0,0,100,0,0,0,0,0,0,0,0,0,0,574.0468,83352.74,6.1324,4.8314,0,0,0,0,0,0,0,0,0,0,4.5708,0.3092,0.155,0.155,580.1733,56.1437,44.0235,12.1202,1.0213,1.2753,7878.335,0.3095,572.0932,48.0636,6.0601,0,216.1402,50.0836,1.0296,0.0183,0,0,1541658,-524.0296,0,0,0,1.54E+08,0,0,48.7048,27.6984,584.1284,570.226,560.15,24.4664,0.3092,-4.7909,4.7077,2.1421,599.3853,570.226,544.8932,75.3557,46.1964,20.8636,5.1788,-4.7909,-0.1619,571.5015,47.4719,54.4921,0.4649,3.6118,31.9469,0.226,89.8711
1,213,213,567.8572,89325.42,518,0,0.0932,519.2699,0.6017,0,0,0.0528,0.0522,0.0518,0,0,0,5.2803,0,0,100,0,0,0,0,0,0,0,0,0,0,573.5085,83178.09,6.8512,7.789,0,0,0,0,0,0,0,0,0,0,4.5668,0.3065,0.1536,0.1536,579.6813,60.4114,48.5873,11.8241,1.0208,1.2434,7878.122,0.3067,571.7985,52.5286,5.9121,0,1065.557,54.4994,1.2699,0.021,0,0,1541658,-519.2699,0,0,0,1.54E+08,0,0,48.7071,27.7032,583.6395,569.9061,560.4034,39.4416,0.3065,-4.7796,4.6979,2.3933,613.1386,569.9061,530.9044,93.8687,50.6362,11.6345,5.2744,-4.7796,-0.27,571.3163,52.0465,82.2342,0.4743,8.0681,36.7935,0.2248,89.8662
1,221.2,221.2,568.2202,89568.5,525,0,0.0944,524.8458,0.6656,0,0,0.0528,0.0522,0.0518,0,0,0,5.3851,0,0,100,0,0,0,0,0,0,0,0,0,0,573.8919,82926.95,6.7656,6.8556,0,0,0,0,0,0,0,0,0,0,4.5724,0.3391,0.17,0.17,580.2024,55.3566,43.3744,11.9822,1.0211,1.2763,7880.698,0.3394,572.2143,47.3685,5.9911,0,129.4597,49.3655,-0.1542,-0.0028,0,0,1541658,-524.8458,0,0,0,1.54E+08,0,0,48.7193,27.7151,584.2232,570.2767,560.7364,34.6933,0.3391,-4.7809,4.6649,2.3649,609.1068,570.2767,535.8528,84.261,45.4309,11.007,5.236,-4.7809,-0.232,571.7454,46.8996,73.254,0.4699,7.6552,35.6497,0.2231,89.8647
1,229.4,229.4,567.7721,89679.09,533,0,0.0941,534.8466,0.775,0,0,0.0528,0.0522,0.0518,0,0,0,5.5413,0,0,100,0,0,0,0,0,0,0,0,0,0,574.1729,82865.74,6.4628,3.0909,0,0,0,0,0,0,0,0,0,0,4.571,0.3948,0.198,0.198,579.7006,44.854,32.9255,11.9285,1.021,1.3623,7885.105,0.3952,571.7483,36.9017,5.9643,0,-1536.229,38.8898,1.8466,0.0412,0,0,1541658,-534.8466,0,0,0,1.54E+08,0,0,48.734,27.7247,583.3559,570.0931,559.3254,15.628,0.3948,-4.8041,4.6316,2.261,591.0536,570.0931,551.6277,56.207,35.2465,16.7811,5.1672,-4.8041,-0.1408,570.9248,36.0782,39.4259,0.4684,3.3494,26.2229,0.2223,89.8638
1,237.6,237.6,567.9847,89595.34,536,0,0.0936,538.1431,0.8346,0,0,0.0528,0.0522,0.0518,0,0,0,5.6184,0,0,100,0,0,0,0,0,0,0,0,0,0,574.7335,83024.11,6.5306,0.8368,0,0,0,0,0,0,0,0,0,0,4.5736,0.4252,0.2133,0.2133,579.8532,41.7101,29.8416,11.8685,1.0209,1.3977,7887.513,0.4257,571.9409,33.7978,5.9343,0,384.4163,35.7759,2.1431,0.0514,0,0,1541658,-538.1431,0,0,0,1.54E+08,0,0,48.7387,27.7242,583.2983,570.4317,559.0811,4.2294,0.4252,-4.8276,4.6259,2.2856,584.0157,570.4317,558.3637,45.8726,32.2886,20.2206,5.1757,-4.8276,-0.1246,570.937,32.7939,25.652,0.4705,2.2686,9.6269,0.2235,89.8621
1,245.8,245.8,567.8048,89410.17,532,0,0.0925,532.8698,0.7752,0,0,0.0528,0.0522,0.0518,0,0,0,5.5375,0,0,100,0,0,0,0,0,0,0,0,0,0,574.2933,83231.55,7.6858,2.6708,0,0,0,0,0,0,0,0,0,0,4.5697,0.3949,0.198,0.198,579.5351,46.6653,34.935,11.7303,1.0207,1.3358,7885.113,0.3953,571.7149,38.8451,5.8652,0,-7483.831,40.8002,0.8698,0.0186,0,0,1541658,-532.8698,0,0,0,1.54E+08,0,0,48.7278,27.7139,583.0321,570.1572,559.2476,13.5067,0.3949,-4.8249,4.6549,2.6884,589.1359,570.1572,553.1439,56.2661,37.2874,20.2741,5.3798,-4.8249,-0.33,570.8124,37.9425,35.992,0.4727,2.7753,24.3185,0.2249,89.8574
1,254,254,568.3433,89362.61,523,0,0.0932,524.9041,0.7317,0,0,0.0528,0.0522,0.0518,0,0,0,5.4816,0,0,100,0,0,0,0,0,0,0,0,0,0,573.874,83245.07,8.7404,6.5249,0,0,0,0,0,0,0,0,0,0,4.5737,0.3728,0.1869,0.1869,580.1711,55.267,43.4392,11.8278,1.0208,1.2723,7883.364,0.3731,572.2859,47.3818,5.9139,0,99.5212,49.3531,1.9041,0.0345,0,0,1541658,-524.9041,0,0,0,1.54E+08,0,0,48.7223,27.7105,584.1713,570.3485,561.0494,33.0085,0.3728,-4.8154,4.6671,3.0562,607.5849,570.3485,537.6358,82.6808,45.4444,12.7317,5.5663,-4.8154,-0.5264,571.8564,46.9523,69.9491,0.4677,6.4941,35.3488,0.2245,89.8539
1,262.2,262.2,568.194,89577.86,523,0,0.0944,523.6021,0.756,0,0,0.0528,0.0522,0.0518,0,0,0,5.5395,0,0,100,0,0,0,0,0,0,0,0,0,0,573.8843,83021.6,9.2981,7.9319,0,0,0,0,0,0,0,0,0,0,4.5742,0.3851,0.1931,0.1931,580.1629,56.5608,44.5919,11.9689,1.0211,1.2684,7884.337,0.3855,572.1836,48.5815,5.9845,0,135.1125,50.5764,0.6021,0.0106,0,0,1541658,-523.6021,0,0,0,1.54E+08,0,0,48.7289,27.7187,584.18,570.2572,560.6867,40.1144,0.3851,-4.8081,4.6468,3.2522,614.2322,570.2572,530.6345,90.6301,46.6551,7.0324,5.6511,-4.8081,-0.6192,571.7079,48.1059,83.5977,0.474,12.8875,36.8392,0.2238,89.8507
1,270.4,270.4,567.7701,89823.01,534,0,0.095,534.0572,0.8784,0,0,0.0528,0.0522,0.0518,0,0,0,5.7306,0,0,100,0,0,0,0,0,0,0,0,0,0,573.8257,82820.67,8.9909,5.3116,0,0,0,0,0,0,0,0,0,0,4.5743,0.4475,0.2245,0.2245,579.8121,45.7549,33.7129,12.042,1.0212,1.3572,7889.279,0.448,571.7841,37.7269,6.021,0,-1445.589,39.7339,0.0572,0.0013,0,0,1541658,-534.0572,0,0,0,1.54E+08,0,0,48.7476,27.7333,583.6872,569.9659,559.7783,26.8343,0.4475,-4.8267,4.6013,3.1481,601.1094,569.9659,542.3561,67.0522,35.9087,8.2989,5.5689,-4.8267,-0.5201,571.1437,37.0866,58.7533,0.4699,8.0797,32.9937,0.2221,89.8479
1,278.6,278.6,567.7603,89765.16,540,0,0.0946,542.4365,1.0142,0,0,0.0528,0.0522,0.0518,0,0,0,5.9437,0,0,100,0,0,0,0,0,0,0,0,0,0,574.5218,82926.45,8.667,1.6465,0,0,0,0,0,0,0,0,0,0,4.5769,0.5167,0.2594,0.2594,579.7384,37.3019,25.3238,11.9781,1.0211,1.473,7894.767,0.5174,571.753,29.3165,5.9891,0,-1336.532,31.3129,2.4365,0.0653,0,0,1541658,-542.4365,0,0,0,1.54E+08,0,0,48.7627,27.7398,583.2482,570.212,558.8385,8.31,0.5167,-4.8656,4.5717,3.0377,585.8087,570.212,556.278,43.3722,27.7755,13.8415,5.4979,-4.8656,-0.4095,570.7663,28.3297,29.5307,0.4718,3.1335,17.125,0.2228,89.8455
1,286.8,286.8,568.0121,89583.28,541,0,0.0914,542.1103,1.0227,0,0,0.0528,0.0522,0.0518,0,0,0,5.9196,0,0,100,0,0,0,0,0,0,0,0,0,0,574.2112,83174.96,9.3568,1.1769,0,0,0,0,0,0,0,0,0,0,4.5759,0.521,0.2615,0.2615,579.5867,37.4764,25.9018,11.5746,1.0204,1.4469,7895.108,0.5217,571.8703,29.76,5.7873,0,351.439,31.6891,1.1103,0.0296,0,0,1541658,-542.1103,0,0,0,1.54E+08,0,0,48.7596,27.7331,583.1365,570.2596,559.8358,5.9403,0.521,-4.8819,4.5851,3.2792,584.5635,570.2596,558.4088,42.4532,28.1493,16.2985,5.6362,-4.8819,-0.5301,571.0773,28.967,26.1547,0.4531,2.6047,13.5081,0.2242,89.8432
1,295,295,567.9316,89397.06,530,0,0.0922,532.1817,0.9074,0,0,0.0528,0.0522,0.0518,0,0,0,5.7496,0,0,100,0,0,0,0,0,0,0,0,0,0,574.0333,83381.53,10.9751,4.4102,0,0,0,0,0,0,0,0,0,0,4.5734,0.4623,0.232,0.232,579.6119,47.4302,35.7499,11.6803,1.0206,1.3267,7890.453,0.4629,571.825,39.6433,5.8402,0,506.2117,41.5901,2.1817,0.046,0,0,1541658,-532.1817,0,0,0,1.54E+08,0,0,48.7418,27.7189,583.2729,570.1436,559.8864,22.2824,0.4623,-4.8656,4.6289,3.8425,596.7438,570.1436,546.4155,64.5621,37.9619,14.2338,5.9694,-4.8656,-0.8782,571.101,38.9193,50.3283,0.4715,4.5358,31.1553,0.2256,89.8421
1,303.2,303.2,568.097,89465.59,524,0,0.0926,525.3427,0.8969,0,0,0.0528,0.0522,0.0518,0,0,0,5.7524,0,0,100,0,0,0,0,0,0,0,0,0,0,574.0512,83281.2,12.0319,7.7097,0,0,0,0,0,0,0,0,0,0,4.5749,0.4569,0.2292,0.2292,579.8335,54.4908,42.7543,11.7365,1.0207,1.2745,7890.024,0.4574,572.0092,46.6665,5.8683,0,187.3712,48.6226,1.3427,0.0246,0,0,1541658,-525.3427,0,0,0,1.54E+08,0,0,48.7422,27.7211,583.5883,570.2556,560.245,38.9539,0.4569,-4.8575,4.6254,4.2124,612.5815,570.2556,531.2517,87.2388,44.9129,5.909,6.1766,-4.8575,-1.0943,571.363,46.0202,81.3298,0.4796,14.7637,36.6602,0.2248,89.8395
1,311.4,311.4,567.84,89684.14,527,0,0.0956,530.1821,0.9904,0,0,0.0528,0.0522,0.0518,0,0,0,5.8973,0,0,100,0,0,0,0,0,0,0,0,0,0,574.2211,83047.27,12.1557,7.1533,0,0,0,0,0,0,0,0,0,0,4.578,0.5046,0.2533,0.2533,579.9483,49.7662,37.6579,12.1083,1.0213,1.3215,7893.807,0.5053,571.8762,41.6941,6.0542,0,2142.6,43.7121,3.1821,0.0639,0,0,1541658,-530.1821,0,0,0,1.54E+08,0,0,48.7578,27.7346,583.7108,570.1536,559.4219,36.112,0.5046,-4.867,4.5856,4.2594,609.6658,570.1536,533.4669,79.4836,39.9715,3.2848,6.1831,-4.867,-1.0929,571.0954,40.9133,76.1988,0.4815,24.1974,35.7061,0.2232,89.8358
1,319.6,319.6,567.8384,89800.13,541,0,0.0945,542.9185,1.1844,0,0,0.0528,0.0522,0.0518,0,0,0,6.1913,0,0,100,0,0,0,0,0,0,0,0,0,0,574.1956,82998.45,11.7287,3.5464,0,0,0,0,0,0,0,0,0,0,4.5814,0.6034,0.3031,0.3031,579.8027,36.8842,24.9199,11.9643,1.0211,1.4801,7901.654,0.6043,571.8265,28.908,5.9822,0,2781.745,30.9021,1.9185,0.052,0,0,1541658,-542.9185,0,0,0,1.54E+08,0,0,48.7828,27.7498,583.484,570.1434,559.451,17.8762,0.6034,-4.9113,4.5306,4.116,593.0071,570.1434,549.9279,50.0886,27.2249,7.0094,6.0779,-4.9113,-0.9439,571.0261,28.1076,43.0792,0.4693,7.1459,28.0454,0.2227,89.8304
1,327.8,327.8,567.7725,89616.08,546,0,0.0947,547.8657,1.3175,0,0,0.0528,0.0522,0.0518,0,0,0,6.3728,0,0,100,0,0,0,0,0,0,0,0,0,0,574.2886,83248.33,11.6336,0.8566,0,0,0,0,0,0,0,0,0,0,4.5841,0.6712,0.3373,0.3373,579.7487,31.883,19.9068,11.9762,1.0211,1.6016,7907.047,0.6723,571.7646,23.8989,5.9881,0,-1874.687,25.8949,1.8657,0.0585,0,0,1541658,-547.8657,0,0,0,1.54E+08,0,0,48.7953,27.7519,583.3705,570.1349,559.1793,4.314,0.6712,-4.9583,4.5107,4.0862,584.1168,570.1349,558.433,36.2511,22.2692,10.5673,6.0599,-4.9583,-0.878,570.8949,23.0292,25.6838,0.4556,3.4305,9.8146,0.2236,89.8267
1,336,336,567.7897,89392.56,541,0,0.0905,541.2973,1.1872,0,0,0.0528,0.0522,0.0518,0,0,0,6.1679,0,0,100,0,0,0,0,0,0,0,0,0,0,574.3157,83544.47,13.4366,2.3053,0,0,0,0,0,0,0,0,0,0,4.577,0.6048,0.3038,0.3038,579.2377,37.9404,26.4924,11.448,1.0202,1.4321,7901.765,0.6057,571.6057,30.3084,5.724,0,-2974.87,32.2164,0.2973,0.0078,0,0,1541658,-541.2973,0,0,0,1.54E+08,0,0,48.7741,27.734,582.5669,570.1553,559.1874,11.6234,0.6048,-4.9434,4.5641,4.714,587.3621,570.1553,554.3922,46.0648,28.858,13.0949,6.4613,-4.9434,-1.2924,570.6365,29.3392,32.9699,0.4781,3.5178,22.4185,0.2255,89.828
1,344.2,344.2,568.2112,89303.44,531,0,0.0932,530.8474,1.1106,0,0,0.0528,0.0522,0.0518,0,0,0,6.0578,0,0,100,0,0,0,0,0,0,0,0,0,0,573.985,83657.59,15.0217,6.1691,0,0,0,0,0,0,0,0,0,0,4.5813,0.5658,0.2841,0.2841,580.0093,49.1619,37.3638,11.7981,1.0208,1.3158,7898.666,0.5666,572.1439,41.2965,5.8991,0,147.4658,43.2629,-0.1526,-0.0031,0,0,1541658,-530.8474,0,0,0,1.54E+08,0,0,48.7626,27.7252,583.8896,570.3041,560.6019,31.1251,0.5658,-4.9312,4.5918,5.2667,605.4775,570.3041,539.014,74.6301,39.4567,8.1666,6.8121,-4.9312,-1.6545,571.5984,40.7511,66.4635,0.4708,9.1385,34.7446,0.2264,89.8282
1,352.4,352.4,568.0239,89409.05,526,0,0.0946,527.3135,1.1506,0,0,0.0528,0.0522,0.0518,0,0,0,6.15,0,0,100,0,0,0,0,0,0,0,0,0,0,573.7048,83489.83,16.0008,7.9805,0,0,0,0,0,0,0,0,0,0,4.5822,0.5862,0.2944,0.2944,580.0043,52.6908,40.7105,11.9804,1.0211,1.2943,7900.287,0.5871,572.0174,44.7039,5.9902,0,261.5894,46.7007,1.3135,0.0249,0,0,1541658,-527.3135,0,0,0,1.54E+08,0,0,48.7704,27.733,584.0189,570.0833,560.535,40.2481,0.5862,-4.9312,4.5705,5.6122,614.2029,570.0833,530.3511,86.8894,42.7698,3.0376,7.0187,-4.9312,-1.862,571.5457,44.2323,83.8518,0.4738,28.6046,36.868,0.2255,89.825
1,360.6,360.6,567.9413,89608.73,537,0,0.0957,537.8876,1.3158,0,0,0.0528,0.0522,0.0518,0,0,0,6.3907,0,0,100,0,0,0,0,0,0,0,0,0,0,573.9069,83344.6,15.7542,5.7317,0,0,0,0,0,0,0,0,0,0,4.5864,0.6703,0.3368,0.3368,580.0448,42.1572,30.0537,12.1035,1.0213,1.4027,7906.976,0.6714,571.9758,34.0883,6.0518,0,512.392,36.1055,0.8876,0.0211,0,0,1541658,-537.8876,0,0,0,1.54E+08,0,0,48.7935,27.749,584.0008,570.1041,560.075,28.8677,0.6703,-4.9633,4.5171,5.5332,603.2862,570.1041,540.7896,65.3986,32.2166,2.902,6.9535,-4.9633,-1.7661,571.3933,33.5057,62.4966,0.4691,22.5357,33.7453,0.2241,89.8191
1,368.8,368.8,567.7303,89518.24,547,0,0.0956,550.1118,1.5945,0,0,0.0528,0.0522,0.0518,0,0,0,6.8079,0,0,100,0,0,0,0,0,0,0,0,0,0,574.3893,83480.56,15.0151,1.9268,0,0,0,0,0,0,0,0,0,0,4.5911,0.8123,0.4086,0.4086,579.8092,29.6974,17.6185,12.0789,1.0213,1.6856,7918.295,0.8139,571.7566,21.6448,6.0395,0,-943.7537,23.658,3.1118,0.1048,0,0,1541658,-550.1118,0,0,0,1.54E+08,0,0,48.8261,27.7648,583.4125,570.1442,558.9518,9.6843,0.8123,-5.0391,4.4511,5.2845,586.7823,570.1442,555.5819,36.6705,20.0324,5.4701,6.7878,-5.0391,-1.5244,570.8361,20.7243,31.2004,0.4667,6.7038,19.1865,0.2243,89.8099
1,377,377,567.5394,89275.95,549,0,0.0893,550.3198,1.633,0,0,0.0528,0.0522,0.0518,0,0,0,6.8528,0,0,100,0,0,0,0,0,0,0,0,0,0,574.6276,83810.13,15.8314,1.0106,0,0,0,0,0,0,0,0,0,0,4.5841,0.8319,0.4186,0.4186,578.8107,28.4909,17.2196,11.2713,1.0199,1.6546,7919.86,0.8337,571.2966,20.9768,5.6357,0,-285.9296,22.8553,1.3198,0.0463,0,0,1541658,-550.3198,0,0,0,1.54E+08,0,0,48.8254,27.7579,581.7723,570.1086,558.2002,5.0788,0.8319,-5.0671,4.4614,5.5725,582.8199,570.1086,557.1525,32.5001,19.7888,6.8327,6.9848,-5.0671,-1.6915,570.027,19.7072,25.6674,0.5048,4.7566,11.656,0.2262,89.8081
1,385.2,385.2,567.8608,89006.32,535,0,0.0903,537.7084,1.4131,0,0,0.0528,0.0522,0.0518,0,0,0,6.5106,0,0,100,0,0,0,0,0,0,0,0,0,0,574.4962,84111.41,18.3838,4.0227,0,0,0,0,0,0,0,0,0,0,4.5826,0.7199,0.3619,0.3619,579.2748,41.5664,30.1524,11.414,1.0201,1.3785,7910.926,0.7212,571.6655,33.9572,5.707,0,1370.694,35.8594,2.7084,0.0652,0,0,1541658,-537.7084,0,0,0,1.54E+08,0,0,48.7928,27.7333,582.5293,570.2655,559.1225,20.2537,0.7199,-5.031,4.5395,6.4589,594.2178,570.2655,547.434,56.5094,32.5571,9.7256,7.5801,-5.031,-2.3207,570.6391,32.9307,46.7838,0.488,5.8104,29.9895,0.2284,89.8145
1,393.4,393.4,568.0215,89003.83,528,0,0.0937,529.1825,1.4195,0,0,0.0528,0.0522,0.0518,0,0,0,6.5748,0,0,100,0,0,0,0,0,0,0,0,0,0,573.7949,84110.16,19.9046,7.4291,0,0,0,0,0,0,0,0,0,0,4.5874,0.7232,0.3636,0.3636,579.8623,50.6798,38.839,11.8408,1.0208,1.3049,7911.188,0.7245,571.9684,42.7859,5.9204,0,273.6133,44.7594,1.1825,0.0233,0,0,1541658,-529.1825,0,0,0,1.54E+08,0,0,48.7936,27.7338,583.7724,570.1138,560.4185,37.4025,0.7232,-5.0323,4.5377,6.9936,611.2783,570.1138,532.9126,82.0958,40.9313,3.7301,7.9307,-5.0323,-2.6698,571.4349,42.2524,78.3657,0.4747,22.009,36.3309,0.2286,89.8127
1,401.6,401.6,568.0951,89202.47,533,0,0.0956,532.4755,1.563,0,0,0.0528,0.0522,0.0518,0,0,0,6.7728,0,0,100,0,0,0,0,0,0,0,0,0,0,573.6816,83945.4,20.4814,7.4468,0,0,0,0,0,0,0,0,0,0,4.5932,0.7963,0.4005,0.4005,580.168,47.6925,35.6196,12.0729,1.0213,1.3389,7917.018,0.7979,572.1194,39.6439,6.0365,0,213.9064,41.6561,-0.5245,-0.011,0,0,1541658,-532.4755,0,0,0,1.54E+08,0,0,48.8144,27.7489,584.2956,570.1198,560.7362,37.4467,0.7963,-5.058,4.4887,7.2048,611.7717,570.1198,533.2601,79.2962,37.6443,0.7845,8.0613,-5.058,-2.7763,571.7172,39.2417,78.5117,0.4695,101.0787,36.2689,0.227,89.806
1,409.8,409.8,567.914,89286.31,543,0,0.0979,547.0227,1.8939,0,0,0.0528,0.0522,0.0518,0,0,0,7.3126,0,0,100,0,0,0,0,0,0,0,0,0,0,574.4307,83921.12,20.0181,3.9693,0,0,0,0,0,0,0,0,0,0,4.6017,0.9648,0.4859,0.4859,580.2543,33.2316,20.8913,12.3403,1.0217,1.5907,7930.488,0.9671,572.0274,25.0047,6.1702,0,741.0812,27.0615,4.0227,0.1211,0,0,1541658,-547.0227,0,0,0,1.54E+08,0,0,48.8563,27.7732,584.0913,570.2759,559.3294,19.9088,0.9648,-5.1373,4.3984,7.0599,595.1549,570.2759,548.2657,48.1322,23.2532,1.243,7.9607,-5.1373,-2.5975,571.2322,24.2095,46.8892,0.4694,38.7226,29.0616,0.2259,89.7918
1,418,418,567.5652,89080.35,553,0,0.0944,554.8552,2.1918,0,0,0.0528,0.0522,0.0518,0,0,0,7.7623,0,0,100,0,0,0,0,0,0,0,0,0,0,574.3339,84195.91,19.491,0.9538,0,0,0,0,0,0,0,0,0,0,4.6024,1.1166,0.563,0.563,579.453,24.5978,12.71,11.8878,1.0209,1.9353,7942.663,1.1197,571.5278,16.6726,5.9439,0,-333.9637,18.6539,1.8552,0.0754,0,0,1541658,-554.8552,0,0,0,1.54E+08,0,0,48.8892,27.7864,582.9059,570.0181,558.6526,4.7737,1.1166,-5.2258,4.3357,6.8888,583.8116,570.0181,557.7468,28.9564,15.1629,2.8916,7.8563,-5.2258,-2.404,570.5255,15.6703,26.0648,0.4708,10.014,10.7436,0.2265,89.7784
1,426.2,426.2,567.8518,88793.38,545,0,0.0869,548.0551,1.9671,0,0,0.0528,0.0522,0.0518,0,0,0,7.3888,0,0,100,0,0,0,0,0,0,0,0,0,0,574.7581,84556.28,22.2782,1.9655,0,0,0,0,0,0,0,0,0,0,4.5919,1.0021,0.5048,0.5048,578.8005,30.7454,19.7967,10.9487,1.0193,1.5531,7933.477,1.0046,571.5014,23.4463,5.4744,0,1953.133,25.2711,3.0551,0.0994,0,0,1541658,-548.0551,0,0,0,1.54E+08,0,0,48.8548,27.7597,581.6739,570.3541,558.7635,9.8562,1.0021,-5.1913,4.4189,7.8587,585.3305,570.3541,555.1069,37.2754,22.299,7.0518,8.5241,-5.1913,-3.1031,570.2639,22.2087,30.2236,0.5045,5.2859,20.3546,0.2297,89.7887
1,434.4,434.4,567.9555,88606.07,532,0,0.093,534.6742,1.8717,0,0,0.0528,0.0522,0.0518,0,0,0,7.2635,0,0,100,0,0,0,0,0,0,0,0,0,0,573.9799,84765.54,24.696,5.7323,0,0,0,0,0,0,0,0,0,0,4.5967,0.9535,0.4802,0.4802,579.69,45.0158,33.2813,11.7345,1.0207,1.3526,7929.583,0.9558,571.867,37.1928,5.8673,0,438.7468,39.1486,2.6742,0.0594,0,0,1541658,-534.6742,0,0,0,1.54E+08,0,0,48.8393,27.7467,583.4097,570.1381,560.0306,28.7698,0.9535,-5.18,4.4577,8.7042,602.7741,570.1381,540.6662,68.0999,35.4639,5.992,9.1049,-5.18,-3.6937,571.1928,36.5186,62.1079,0.4745,11.3651,33.9437,0.2312,89.7922
1,442.6,442.6,568.1176,88650.06,528,0,0.0936,529.4528,1.9783,0,0,0.0528,0.0522,0.0518,0,0,0,7.4383,0,0,100,0,0,0,0,0,0,0,0,0,0,573.6454,84697.94,26.3097,7.9271,0,0,0,0,0,0,0,0,0,0,4.601,1.0078,0.5077,0.5077,579.9141,50.4613,38.6648,11.7965,1.0208,1.3051,7933.933,1.0103,572.0498,42.597,5.8983,0,188.1742,44.5631,1.4528,0.0288,0,0,1541658,-529.4528,0,0,0,1.54E+08,0,0,48.8539,27.7563,583.9162,570.1204,560.8452,39.7508,1.0078,-5.2025,4.4247,9.281,613.7715,570.1204,530.99,84.3187,40.6676,1.5372,9.4976,-5.2025,-4.0651,571.6273,42.1745,82.7815,0.4727,54.8521,36.9088,0.23,89.7858
1,450.8,450.8,568.2592,88777.11,538,0,0.0989,540.2295,2.3147,0,0,0.0528,0.0522,0.0518,0,0,0,8.013,0,0,100,0,0,0,0,0,0,0,0,0,0,573.7356,84626.52,26.3773,6.1303,0,0,0,0,0,0,0,0,0,0,4.6153,1.1792,0.5949,0.5949,580.7093,40.4798,28.0297,12.4501,1.0219,1.4442,7947.694,1.1827,572.4092,32.1797,6.2251,0,152.6163,34.2548,2.2295,0.0551,0,0,1541658,-540.2295,0,0,0,1.54E+08,0,0,48.8974,27.7825,585.092,570.2434,561.0535,30.6598,1.1792,-5.2802,4.3298,9.3294,606.0043,570.2434,540.1412,65.7748,30.0139,-0.0883,9.5369,-5.2802,-4.0279,572.1296,31.9001,65.8631,0.457,-744.9016,34.2969,0.2288,89.7677
1,459,459,567.7689,88708,554,0,0.0971,555.8871,2.8586,0,0,0.0528,0.0522,0.0518,0,0,0,8.8808,0,0,100,0,0,0,0,0,0,0,0,0,0,574.3472,84768.67,25.4108,2.2209,0,0,0,0,0,0,0,0,0,0,4.6222,1.4563,0.7362,0.7362,579.9467,24.0596,11.8818,12.1778,1.0214,2.0249,7970.042,1.4617,571.8282,15.9411,6.0889,0,-1903.557,17.9707,1.8871,0.0784,0,0,1541658,-555.8871,0,0,0,1.54E+08,0,0,48.9637,27.8173,583.67,570.1522,559.1154,11.0617,1.4563,-5.4212,4.1924,9.0248,587.9182,570.1522,554.8672,32.0311,14.2651,-1.0199,9.3508,-5.4212,-3.7021,570.9792,15.0921,33.051,0.4625,-31.4061,21.0093,0.2275,89.7331
1,467.2,467.2,567.8706,88421.25,554,0,0.0841,556.4194,2.9946,0,0,0.0528,0.0522,0.0518,0,0,0,9.1128,0,0,100,0,0,0,0,0,0,0,0,0,0,574.2,85096.05,26.286,0.8834,0,0,0,0,0,0,0,0,0,0,4.6132,1.5256,0.7716,0.7716,578.4105,21.9912,11.4512,10.5399,1.0186,1.9204,7975.651,1.5315,571.3839,14.9645,5.27,0,1461.572,16.7212,2.4194,0.11,0,0,1541658,-556.4194,0,0,0,1.54E+08,0,0,48.9754,27.8174,581.3322,570.1633,559.5491,4.3961,1.5256,-5.4731,4.1764,9.3438,582.186,570.1633,558.6954,25.7666,13.744,2.276,9.5897,-5.4731,-3.8877,570.3482,13.9289,23.4906,0.4882,11.321,10.9901,0.2289,89.7238
1,475.4,475.4,567.8378,88133.34,541,0,0.0917,542.6566,2.6346,0,0,0.0528,0.0522,0.0518,0,0,0,8.4915,0,0,100,0,0,0,0,0,0,0,0,0,0,574.327,85428.56,30.6127,3.5147,0,0,0,0,0,0,0,0,0,0,4.6122,1.3422,0.6779,0.6779,579.362,36.7054,25.1812,11.5242,1.0203,1.4577,7960.825,1.3467,571.6792,29.0226,5.7621,0,2832.589,30.9433,1.6566,0.0451,0,0,1541658,-542.6566,0,0,0,1.54E+08,0,0,48.9243,27.7817,582.7478,570.1881,559.3109,17.5424,1.3422,-5.4043,4.2943,10.8495,592.1257,570.1881,549.933,49.4691,27.5315,7.2764,10.6307,-5.4043,-4.9942,570.7489,28.0923,42.1927,0.4801,6.7986,28.1284,0.2322,89.7495
1,483.6,483.6,567.7451,88030.73,532,0,0.0933,532.1166,2.7504,0,0,0.0528,0.0522,0.0518,0,0,0,8.6966,0,0,100,0,0,0,0,0,0,0,0,0,0,573.6258,85524.84,33.0131,7.1655,0,0,0,0,0,0,0,0,0,0,4.6157,1.4012,0.708,0.708,579.4549,47.3383,35.6285,11.7098,1.0206,1.3287,7965.589,1.4061,571.6484,39.5318,5.8549,0,-884.7961,41.4834,0.1166,0.0025,0,0,1541658,-532.1166,0,0,0,1.54E+08,0,0,48.9374,27.7872,583.2483,569.8749,560.0191,35.7338,1.4012,-5.4382,4.269,11.7101,609.2076,569.8749,534.0597,77.091,37.7583,1.9431,11.2386,-5.4382,-5.5684,571.0474,38.9308,75.1479,0.4766,39.6742,35.9971,0.232,89.741
1,491.8,491.8,568.1318,88155.97,530,0,0.0967,533.4211,3.0612,0,0,0.0528,0.0522,0.0518,0,0,0,9.2473,0,0,100,0,0,0,0,0,0,0,0,0,0,573.5987,85428.38,34.448,7.6492,0,0,0,0,0,0,0,0,0,0,4.6295,1.5595,0.789,0.789,580.2543,46.8332,34.7107,12.1225,1.0213,1.3492,7978.398,1.5657,572.1726,38.7515,6.0613,0,192.2629,40.772,3.4211,0.073,0,0,1541658,-533.4211,0,0,0,1.54E+08,0,0,48.9783,27.8124,584.4678,570.1119,560.9481,38.0523,1.5595,-5.5084,4.1793,12.2492,612.5359,570.1119,532.8799,79.1148,36.6908,-0.5412,11.6294,-5.5084,-5.8906,571.8425,38.4215,79.656,0.4674,-146.184,36.4133,0.2304,89.7158
1,500,500,568.0903,88288.3,551,0,0.0996,549.7586,3.7016,0,0,0.0528,0.0522,0.0518,0,0,0,10.2793,0,0,100,0,0,0,0,0,0,0,0,0,0,573.9941,85407.78,34.077,4.4246,0,0,0,0,0,0,0,0,0,0,4.6471,1.8858,0.9564,0.9564,580.5296,30.771,18.3317,12.4393,1.0219,1.6786,8004.932,1.8948,572.2368,22.4782,6.2197,0,279.9418,24.5514,-1.2414,-0.0403,0,0,1541658,-549.7586,0,0,0,1.54E+08,0,0,49.06,27.8592,584.7216,570.2285,560.3323,21.9014,1.8858,-5.6639,4.0052,12.1779,597.5945,570.2285,547.4595,47.8359,20.4699,-2.2991,11.6215,-5.6639,-5.7305,571.7608,22.0022,50.135,0.4542,-20.8064,30.4455,0.2271,89.6488
1,508.2,508.2,567.7071,88109.27,558,0,0.0934,560.0661,4.3464,0,0,0.0528,0.0522,0.0518,0,0,0,11.3047,0,0,100,0,0,0,0,0,0,0,0,0,0,574.2164,85652.53,32.7314,1.1151,0,0,0,0,0,0,0,0,0,0,4.6531,2.2143,1.1259,1.1259,579.3329,19.2668,7.641,11.6258,1.0205,2.5215,8031.824,2.2268,571.5823,11.5162,5.8129,0,-830.9882,13.4539,2.0661,0.1072,0,0,1541658,-560.0661,0,0,0,1.54E+08,0,0,49.1382,27.8987,582.7806,570.0644,559.1569,5.4927,2.2143,-5.8358,3.8463,11.7545,583.9952,570.0644,557.9423,23.9291,9.9983,-2.1238,11.382,-5.8358,-5.3213,570.6673,10.6012,26.0529,0.4653,-11.2671,12.4696,0.2249,89.5448
1,516.4,516.4,567.6303,87833.4,554,0,0.0834,553.7024,4.0313,0,0,0.0528,0.0522,0.0518,0,0,0,10.7969,0,0,100,0,0,0,0,0,0,0,0,0,0,574.0963,85954.38,37.4772,1.6963,0,0,0,0,0,0,0,0,0,0,4.635,2.0537,1.0429,1.0429,578.0272,24.3248,13.9279,10.3969,1.0183,1.7465,8018.654,2.0644,571.0959,17.3935,5.1985,0,-446.7482,19.1264,-0.2976,-0.0122,0,0,1541658,-553.7024,0,0,0,1.54E+08,0,0,49.0928,27.8668,580.8077,569.9716,559.1413,8.3775,2.0537,-5.7759,3.9506,13.4235,583.669,569.9716,556.28,29.9666,16.2692,2.5776,12.5413,-5.7759,-6.537,569.9736,16.2711,27.389,0.4999,11.6258,18.8577,0.2284,89.6056
1,524.6,524.6,567.8456,87618,536,0,0.0922,538.2585,4.0541,0,0,0.0528,0.0522,0.0518,0,0,0,10.8468,0,0,100,0,0,0,0,0,0,0,0,0,0,574.0721,86200.88,41.3831,5.3,0,0,0,0,0,0,0,0,0,0,4.6461,2.0654,1.049,1.049,579.3422,41.0837,29.5871,11.4966,1.0202,1.3886,8019.612,2.0763,571.6778,33.4193,5.7483,0,2025.491,35.3354,2.2585,0.055,0,0,1541658,-538.2585,0,0,0,1.54E+08,0,0,49.0916,27.8612,582.851,570.0999,559.6744,26.1739,2.0654,-5.7955,3.9598,14.8232,599.8872,570.0999,542.6382,61.6287,31.8414,4.3797,13.5369,-5.7955,-7.5117,570.8751,32.6166,57.249,0.4797,14.0714,33.0595,0.2297,89.6032
1,532.8,532.8,568.0653,87669.65,530,0,0.0936,531.7208,4.4287,0,0,0.0528,0.0522,0.0518,0,0,0,11.4732,0,0,100,0,0,0,0,0,0,0,0,0,0,573.8213,86163.32,44.1655,7.9169,0,0,0,0,0,0,0,0,0,0,4.6582,2.2562,1.1476,1.1476,579.7194,47.9986,36.3445,11.6541,1.0205,1.3207,8035.267,2.2692,571.95,40.2292,5.8271,0,236.1607,42.1716,1.7208,0.0359,0,0,1541658,-531.7208,0,0,0,1.54E+08,0,0,49.1402,27.8895,583.5312,570.1494,560.5111,38.9821,2.2562,-5.8855,3.856,15.8665,612.667,570.1494,531.3752,80.9462,38.4286,-0.3456,14.3039,-5.8855,-8.1917,571.3972,39.6764,81.2918,0.477,-234.2193,36.775,0.2267,89.5287
1,541,541,568.1848,87833.4,541,0,0.0997,541.2334,5.1563,0,0,0.0528,0.0522,0.0518,0,0,0,12.6491,0,0,100,0,0,0,0,0,0,0,0,0,0,573.6137,86049.39,45.0211,6.5015,0,0,0,0,0,0,0,0,0,0,4.6826,2.6269,1.3399,1.3399,580.5459,39.3125,26.9514,12.3611,1.0218,1.4586,8065.857,2.6445,572.3052,31.0718,6.1806,0,185.8491,33.132,0.2334,0.0059,0,0,1541658,-541.2334,0,0,0,1.54E+08,0,0,49.2355,27.9459,584.9182,570.1506,561.0585,31.829,2.6269,-6.0574,3.6519,16.2673,606.9796,570.1506,538.9971,65.7462,28.9172,-2.2363,14.6535,-6.0574,-8.3747,572.0424,30.809,67.9825,0.4583,-29.3995,34.7267,0.2214,89.2637
1,549.2,549.2,567.5914,87877.05,558,0,0.1009,558.9804,6.2726,0,0,0.0528,0.0522,0.0518,0,0,0,14.4237,0,0,100,0,0,0,0,0,0,0,0,0,0,574.4509,86115.74,43.7292,2.6237,0,0,0,0,0,0,0,0,0,0,4.7059,3.1956,1.6371,1.6371,580.0271,21.0467,8.611,12.4357,1.0219,2.4442,8113.242,3.2218,571.7366,12.7562,6.2179,0,-392.0511,14.8289,0.9804,0.0466,0,0,1541658,-558.9804,0,0,0,1.54E+08,0,0,49.3788,28.0259,583.7636,570.075,558.5881,12.7328,3.1956,-6.3359,3.3529,15.9394,589.0805,570.075,553.2712,30.1001,11.0946,-5.7092,14.5454,-6.3359,-7.9969,570.8089,11.8285,35.8093,0.4693,-5.2722,22.6641,0.2126,85.2062
1,557.4,557.4,568.0031,87723.63,559,0,0.0735,561.2854,6.6512,0,0,0.0528,0.0522,0.0518,0,0,0,15.0014,0,0,100,0,0,0,0,0,0,0,0,0,0,574.0399,86345.47,44.2486,0.8551,0,0,0,0,0,0,0,0,0,0,4.691,3.3885,1.7386,1.7386,577.0384,15.753,6.7177,9.0353,1.0159,2.345,8129.441,3.4181,571.0149,9.7295,4.5177,0,468.8416,11.2354,2.2854,0.1451,0,0,1541658,-561.2854,0,0,0,1.54E+08,0,0,49.4242,28.047,579.2626,570.1886,560.0828,4.1379,3.3885,-6.4424,3.2642,16.175,580.1172,570.1886,559.2282,18.8318,8.9032,-2.0572,14.764,-6.4424,-8.1113,569.8447,8.5593,20.889,0.5247,-9.1541,11.6698,0.2103,6.0702
1,565.6,565.6,567.7701,87515.55,545,0,0.0886,548.129,6.2551,0,0,0.0528,0.0522,0.0518,0,0,0,14.3726,0,0,100,0,0,0,0,0,0,0,0,0,0,574.5644,86574.13,51.9904,3.1103,0,0,0,0,0,0,0,0,0,0,4.6946,3.1867,1.6325,1.6325,578.6875,30.5585,19.6411,10.9174,1.0192,1.5558,8112.496,3.2128,571.4092,23.2802,5.4587,0,-1774.012,25.0998,3.129,0.1024,0,0,1541658,-548.129,0,0,0,1.54E+08,0,0,49.3688,28.0109,581.6091,570.2296,558.8594,15.1001,3.1867,-6.3578,3.3863,18.9433,589.1393,570.2296,551.3292,41.0103,22.1006,3.2002,16.6818,-6.3578,-10.1088,570.2327,22.1037,37.8101,0.4999,12.8149,26.5047,0.2152,86.1973
1,573.8,573.8,567.9645,87459.34,533,0,0.0929,535.6725,6.778,0,0,0.0528,0.0522,0.0518,0,0,0,15.2491,0,0,100,0,0,0,0,0,0,0,0,0,0,573.8701,86629.66,56.0126,6.8623,0,0,0,0,0,0,0,0,0,0,4.7132,3.4531,1.7726,1.7726,579.3816,43.7091,32.292,11.4171,1.0201,1.3536,8134.88,3.4838,571.7702,36.0977,5.7086,0,419.359,38.0006,2.6725,0.0611,0,0,1541658,-535.6725,0,0,0,1.54E+08,0,0,49.4359,28.0479,583.0048,570.1022,560.2199,33.1792,3.4531,-6.4896,3.2474,20.4927,606.6929,570.1022,536.5318,71.0204,34.4297,0.8593,17.8411,-6.4896,-11.1406,571.1089,35.4365,70.1611,0.4785,82.6491,35.5248,0.2109,3.6997
1,582,582,567.9218,87606.86,532,0,0.097,535.0112,7.5789,0,0,0.0528,0.0522,0.0518,0,0,0,16.5832,0,0,100,0,0,0,0,0,0,0,0,0,0,573.9069,86482.5,58.9797,7.8083,0,0,0,0,0,0,0,0,0,0,4.7366,3.8611,1.9883,1.9883,579.7975,44.7863,32.9106,11.8757,1.0209,1.3608,8169.404,3.8996,571.8804,36.8691,5.9379,0,577.5978,38.8485,3.0112,0.0672,0,0,1541658,-535.0112,0,0,0,1.54E+08,0,0,49.5432,28.1117,583.6322,570.0885,560.0711,37.5109,3.8611,-6.6794,3.0199,21.7175,611.1689,570.0885,532.5344,76.1577,35.0773,-2.4768,18.8029,-6.6794,-11.9219,571.2639,36.2527,78.6345,0.4776,-30.7484,36.2824,0.2016,0.9063
1,590.2,590.2,567.7814,87799.85,551,0,0.1022,551.111,8.8865,0,0,0.0528,0.0522,0.0518,0,0,0,18.7255,0,0,100,0,0,0,0,0,0,0,0,0,0,574.066,86379.27,58.938,4.8772,0,0,0,0,0,0,0,0,0,0,4.773,4.5272,2.3435,2.3435,580.2051,29.0941,16.6704,12.4237,1.0219,1.7453,8226.4,4.5805,571.9226,20.8116,6.2119,0,-2503.314,22.8823,0.111,0.0038,0,0,1541658,-551.111,0,0,0,1.54E+08,0,0,49.7174,28.2127,584.2081,570.0565,559.5364,23.1857,4.5272,-6.9971,2.6561,21.9309,598.1354,570.0565,545.6091,47.0244,18.9455,-5.502,19.1273,-6.9971,-11.944,571.267,20.156,52.5264,0.4654,-8.5468,30.9925,0.1862,0.4076
1,598.4,598.4,567.8188,87742.16,561,0,0.0891,562.9743,10.0583,0,0,0.0528,0.0522,0.0518,0,0,0,20.6298,0,0,100,0,0,0,0,0,0,0,0,0,0,574.4523,86461.9,56.0168,1.2519,0,0,0,0,0,0,0,0,0,0,4.7896,5.1242,2.665,2.665,578.5823,15.608,4.8445,10.7635,1.019,3.2218,8278.165,5.1928,571.4066,8.4323,5.3818,0,15506.06,10.2263,1.9743,0.1265,0,0,1541658,-562.9743,0,0,0,1.54E+08,0,0,49.8723,28.2989,581.4863,570.2202,559.1172,5.8959,5.1242,-7.2932,2.3395,21.0401,582.9452,570.2202,557.6583,19.9709,7.2459,-5.316,18.6745,-7.2932,-11.2108,570.2746,7.3003,25.2869,0.4968,-3.7568,13.8979,0.1705,0.2735
1,606.6,606.6,567.589,87647.84,558,0,0.0753,558.9243,9.817,0,0,0.0528,0.0522,0.0518,0,0,0,20.2332,0,0,100,0,0,0,0,0,0,0,0,0,0,574.3915,86597.8,63.9508,1.5318,0,0,0,0,0,0,0,0,0,0,4.7678,5.0013,2.5985,2.5985,576.695,17.7707,8.6647,9.106,1.016,2.0509,8267.455,5.0665,570.6243,11.7,4.553,0,-387.6333,13.2177,0.9243,0.052,0,0,1541658,-558.9243,0,0,0,1.54E+08,0,0,49.8377,28.2765,578.5909,570.0515,558.6678,7.2287,5.0013,-7.2408,2.4142,23.9717,580.9373,570.0515,556.3214,22.013,11.1272,-2.6029,20.7076,-7.2408,-13.2921,569.1034,10.1791,24.6159,0.5578,-8.4571,17.9835,0.1747,0.2955
1,614.8,614.8,567.8388,87549.06,541,0,0.0921,542.8781,10.1334,0,0,0.0528,0.0522,0.0518,0,0,0,20.8066,0,0,100,0,0,0,0,0,0,0,0,0,0,574.0926,86699.77,70.2631,4.8574,0,0,0,0,0,0,0,0,0,0,4.7947,5.1625,2.6857,2.6857,578.9646,36.0865,24.9607,11.1258,1.0196,1.4457,8281.508,5.2321,571.5474,28.6693,5.5629,0,2734.258,30.5236,1.8781,0.052,0,0,1541658,-542.8781,0,0,0,1.54E+08,0,0,49.8782,28.2974,582.2474,570.1025,559.6387,22.8654,5.1625,-7.325,2.3337,26.4035,596.4501,570.1025,545.4359,53.572,27.2244,2.5578,22.4717,-7.325,-14.9755,570.6628,27.7847,51.0142,0.4835,20.9446,31.8464,0.1712,0.271
1,623,623,567.9446,87691.45,534,0,0.0926,535.1538,11.0192,0,0,0.0528,0.0522,0.0518,0,0,0,22.2068,0,0,100,0,0,0,0,0,0,0,0,0,0,573.7649,86528.63,74.628,7.8027,0,0,0,0,0,0,0,0,0,0,4.8185,5.6137,2.9308,2.9308,579.0703,43.9165,32.7908,11.1257,1.0196,1.3393,8321.097,5.6963,571.6531,36.4993,5.5629,0,478.7995,38.3537,1.1538,0.0263,0,0,1541658,-535.1538,0,0,0,1.54E+08,0,0,50.0002,28.3701,582.5691,570.0515,560.3107,36.4648,5.6137,-7.5363,2.0795,28.2477,609.5652,570.0515,533.3146,74.4114,34.8977,-1.8392,23.8988,-7.5363,-16.2056,570.9771,35.8233,76.2506,0.4818,-40.4586,36.5138,0.1569,0.2172
1,631.2,631.2,568.0263,87993.84,540,0,0.1006,542.4548,12.3086,0,0,0.0528,0.0522,0.0518,0,0,0,24.3209,0,0,100,0,0,0,0,0,0,0,0,0,0,574.063,86245.82,76.7054,6.8623,0,0,0,0,0,0,0,0,0,0,4.8603,6.2706,3.2909,3.2909,580.0286,37.5739,25.5715,12.0023,1.0211,1.4694,8379.415,6.3743,572.0271,29.5723,6.0012,0,329.6309,31.5727,2.4548,0.0653,0,0,1541658,-542.4548,0,0,0,1.54E+08,0,0,50.18,28.478,583.9172,570.2119,560.1048,31.7309,6.2706,-7.8426,1.7061,29.3444,605.9021,570.2119,538.1199,63.4473,27.7571,-4.3349,24.8631,-7.8426,-16.8864,571.4113,28.9565,67.7822,0.4735,-14.6364,34.7164,0.1341,0.1683
1,639.4,639.4,567.7963,88193.69,558,0,0.1028,560.5518,14.1052,0,0,0.0528,0.0522,0.0518,0,0,0,27.27,0,0,100,0,0,0,0,0,0,0,0,0,0,574.4464,86093.84,75.0046,3.0307,0,0,0,0,0,0,0,0,0,0,4.9075,7.1859,3.799,3.799,579.9422,19.3904,7.2445,12.1459,1.0214,2.6766,8462.05,7.3233,571.845,11.2932,6.073,0,-5326.807,13.3175,2.5518,0.1316,0,0,1541658,-560.5518,0,0,0,1.54E+08,0,0,50.4295,28.6227,583.6177,570.2041,559.0677,13.8078,7.1859,-8.2855,1.199,29.1216,589.8178,570.2041,552.8675,29.266,9.6523,-7.6843,25.001,-8.2855,-16.6161,570.9631,10.4113,36.9503,0.4692,-3.8085,24.1816,0.0994,0.1283
1,647.6,647.6,567.7407,88232.72,562,0,0.0788,564.0562,14.8574,0,0,0.0528,0.0522,0.0518,0,0,0,28.4406,0,0,100,0,0,0,0,0,0,0,0,0,0,574.3773,86081.5,74.03,0.9762,0,0,0,0,0,0,0,0,0,0,4.903,7.5691,4.0139,4.0139,577.0182,12.962,3.6845,9.2775,1.0163,3.518,8497.132,7.722,570.8332,6.777,4.6388,0,-1273.295,8.3233,2.0562,0.1586,0,0,1541658,-564.0562,0,0,0,1.54E+08,0,0,50.5341,28.6823,579.0768,570.1436,559.0296,4.42,7.5691,-8.4744,0.9892,28.9223,580.0081,570.1436,558.0984,15.9519,6.0874,-5.9578,24.9932,-8.4744,-16.4349,569.4167,5.3605,21.9097,0.5498,-2.6775,11.8978,0.0839,0.1167
1,655.8,655.8,567.9793,88259.17,555,0,0.0856,553.8689,14.6276,0,0,0.0528,0.0522,0.0518,0,0,0,28.0765,0,0,100,0,0,0,0,0,0,0,0,0,0,574.463,86053.27,86.4806,2.7179,0,0,0,0,0,0,0,0,0,0,4.9057,7.452,3.9481,3.9481,578.0675,24.1986,14.1104,10.0882,1.0178,1.7149,8486.38,7.6001,571.342,17.4731,5.0441,0,491.3421,19.1545,-1.1311,-0.0467,0,0,1541658,-553.8689,0,0,0,1.54E+08,0,0,50.5026,28.665,580.6583,570.3269,559.4686,12.3292,7.452,-8.4148,1.0514,33.723,586.3196,570.3269,553.8074,32.4507,16.458,-0.0615,28.3113,-8.4148,-19.8079,570.1513,16.2824,32.5122,0.5081,-527.6536,24.6633,0.0886,0.1204
1,664,664,567.6865,88338.92,539,0,0.0926,540.3507,15.73,0,0,0.0528,0.0522,0.0518,0,0,0,29.8462,0,0,100,0,0,0,0,0,0,0,0,0,0,573.8564,85883.45,92.2787,6.5033,0,0,0,0,0,0,0,0,0,0,4.9396,8.0137,4.265,4.265,578.5294,38.1787,27.3358,10.8429,1.0191,1.3967,8538.201,8.1858,571.3008,30.9501,5.4215,0,-539.7955,32.7573,1.3507,0.0354,0,0,1541658,-540.3507,0,0,0,1.54E+08,0,0,50.6595,28.7576,581.699,569.9207,559.5854,29.2302,8.0137,-8.6837,0.734,36.3174,601.8937,569.9207,539.3907,61.543,29.57,-0.96,30.3108,-8.6837,-21.5631,570.4017,30.051,62.503,0.4885,-64.1073,34.64,0.064,0.106
1,672.2,672.2,568.1147,88698.53,536,0,0.0973,537.9705,17.2412,0,0,0.0528,0.0522,0.0518,0,0,0,32.2692,0,0,100,0,0,0,0,0,0,0,0,0,0,573.7124,85479.7,97.0596,7.9365,0,0,0,0,0,0,0,0,0,0,4.9889,8.7835,4.704,4.704,579.4136,41.4431,30.1442,11.2989,1.0199,1.3748,8610.257,8.9917,571.881,33.9105,5.6495,0,218.2281,35.7937,1.9705,0.0475,0,0,1541658,-537.9705,0,0,0,1.54E+08,0,0,50.8799,28.8911,583.1079,570.142,560.7599,35.2172,8.7835,-9.0446,0.2871,38.6921,608.8813,570.142,534.9865,70.9108,32.1715,-2.984,32.2226,-9.0446,-23.152,571.3366,33.3661,73.8948,0.4758,-23.7637,36.1982,0.026,0.0909
1,680.4,680.4,568.2508,89130.43,548,0,0.1042,551.9105,19.3996,0,0,0.0528,0.0522,0.0518,0,0,0,35.7439,0,0,100,0,0,0,0,0,0,0,0,0,0,574.0347,85082.34,97.8003,5.2893,0,0,0,0,0,0,0,0,0,0,5.0567,9.8831,5.3409,5.3409,580.2083,28.2978,16.3403,11.9575,1.021,1.7318,8715.318,10.1493,572.2366,20.3261,5.9788,0,182.2292,22.3191,3.9105,0.1382,0,0,1541658,-551.9105,0,0,0,1.54E+08,0,0,51.1964,29.0792,584.1773,570.3459,560.6462,23.0425,9.8831,-9.5726,-0.3433,39.7117,598.2842,570.3459,546.5392,46.3737,18.4354,-5.3713,33.3121,-9.5726,-23.7723,571.7231,19.8126,51.745,0.4601,-8.6336,31.4755,-0.0328,0.0756
1,688.6,688.6,567.5786,89339.81,563,0,0.0824,565.7165,21.2371,0,0,0.0528,0.0522,0.0518,0,0,0,38.7523,0,0,100,0,0,0,0,0,0,0,0,0,0,574.3127,84833.14,91.6001,1.3718,0,0,0,0,0,0,0,0,0,0,5.081,10.8192,5.8923,5.8923,576.9405,11.224,1.8621,9.3619,1.0165,6.0276,8806.801,11.141,570.6992,4.9827,4.681,0,-399.4554,6.5431,2.7165,0.242,0,0,1541658,-565.7165,0,0,0,1.54E+08,0,0,51.4687,29.2391,578.9891,570.0182,558.7212,5.8825,10.8192,-10.0299,-0.877,37.7864,580.5726,570.0182,557.1376,14.8561,4.3017,-8.5789,32.3226,-10.0299,-22.3804,569.2428,3.5263,23.435,0.5496,-1.7317,15.067,-0.0877,0.066
1,696.8,696.8,567.889,89571.07,561,0,0.0689,564.5427,21.6759,0,0,0.0528,0.0522,0.0518,0,0,0,39.4607,0,0,100,0,0,0,0,0,0,0,0,0,0,574.5208,84560.85,103.3271,1.4985,0,0,0,0,0,0,0,0,0,0,5.0828,11.0428,6.0253,6.0253,575.6979,11.1552,3.3463,7.8089,1.0138,3.3336,8828.937,11.3787,570.4919,5.9492,3.9045,0,1215.312,7.2508,3.5427,0.3176,0,0,1541658,-564.5427,0,0,0,1.54E+08,0,0,51.5382,29.2843,576.9205,570.2919,559.162,6.4007,11.0428,-10.1281,-1.0177,42.7911,578.9871,570.2919,557.0955,14.4444,5.7491,-7.4472,35.8655,-10.1281,-25.8404,568.7915,4.2488,21.8916,0.6028,-1.9396,17.8932,-0.103,0.0642
1,700,700,567.8518,89815.91,556,0,0.1024,556.9551,23.4345,0,0,0.0528,0.0522,0.0518,0,0,0,42.3506,0,0,100,0,0,0,0,0,0,0,0,0,0,574.2766,84260.02,107.187,4.3802,0,0,0,0,0,0,0,0,0,0,5.1669,11.9387,6.5632,6.5632,579.3295,22.3745,10.8967,11.4777,1.0202,2.0533,8918.759,12.3346,571.6777,14.7226,5.7389,0,2182.045,16.6356,0.9551,0.0427,0,0,1541658,-556.9551,0,0,0,1.54E+08,0,0,51.8051,29.4423,582.7262,570.1801,559.393,18.4246,11.9387,-10.5658,-1.5353,45.0761,592.8672,570.1801,549.2519,35.9121,13.225,-7.7032,37.7795,-10.5658,-27.3761,570.7664,13.8113,43.6153,0.4798,-4.662,28.8288,-0.1624,0.0575