File: datas/d100-0-0.3.csv
Stage Number,Time since start of test (s),Time since start of stage (s),Radial Pressure (kPa),Radial Volume (mm3),Back Pressure (kPa),Back Volume (mm3),Load Cell (kN),Pore Pressure (kPa),Axial Displacement (mm),L/C Pressure (kPa),L/C Volume (mm3),Local Axial 1,Local Axial 2,Local Radial,Base Pressure (kPa),Base Volume (mm3),Back Differential Pressure (kPa),Axial Displacement 2 (mm),Pore Air Pressure (kPa),Pore Air Volume (mm3),Atmospheric Pressure (kPa),Temperature (°C),Mid Plane PWP (kPa),Back to Cell Differential (kPa),Total Volume Change (mm3),Undefined Tx 1,Undefined Tx 2,Undefined Tx 3,Undefined Tx. 4,HCA secondary control axial load (kN),HCA secondary control torque,Internal Cell Pr. (kPa),Internal Cell Vol. (mm3),Rotational Displ. (mm),Torque,Local Int Defmn 1 (mm),Local Int Defmn 2 (mm),Circumf. Defmn 1 (mm),Circumf. Defmn 2 (mm),Circumf. Defmn 3 (mm),Outer Cell Pr 2 (kPa),Internal cell Pr 2 (kPa),Rotation 2 (°),Secondary Cell Pr (kPa),Secondary Back Pr (kPa),Axial Force (kN),Axial Strain (%),Av Diameter Change (mm),Radial Strain (%),Axial Stress (kPa),Eff. Axial Stress (kPa),Eff. Radial Stress (kPa),Deviator Stress (kPa),Total Stress Ratio (%),Eff. Stress Ratio (%),Current Area (mm2),Shear Strain (%),Cambridge p (kPa),Eff. Cambridge p' (kPa),Max Shear Stress t,Volume Change (mm3),B Value,Mean Stress s/Eff. Axial Stress 2,Excess PWP (kPa),PWP Ratio,Lower Chamber Displacement (mm),Lower Chamber Axial Load (kPa),Specimen Air Volume (mm3),Matric Suction (kPa),Voids ratio,Degree of Saturation (°),Specimen Water Volume (mm3),kRT constant,Permeability IN,Permeability OUT,HCA Outer Rad,HCA Inner Rad,HCA Sigma Z (kPa),HCA Sigma R (kPa),HCA Sigma Theta (kPa),HCA Tau Theta Z,HCA Ez,HCA Er,HCA Etheta,HCA Gamma,HCA Sigma1,HCA Sigma2,HCA Sigma3,HCA Eff Sigma1,HCA Eff Sigma2,HCA Eff Sigma3,HCA E1,HCA E2,HCA E3,HCA P,HCA Eff P,HCA Q,HCA B,HCA Eff R,HCA Alpha,HCA Ev,HCA E1 rtv
1,0,0,495.11,38336.23,400,0,0.1227,399.6243,-0.0006,0,0,0.0528,0.0522,0.0518,0,0,0,7.3669,0,0,100,0,0,0,0,0,0,0,0,0,0,508.1924,-36202.01,0.0034,0.0069,0,0,0,0,0,0,0,0,0,0,4.0113,-0.0003,-0.0002,-0.0002,510.7366,111.1123,95.4857,15.6266,1.0316,1.1637,7853.951,-0.0003,500.3188,100.6945,7.8133,0,-0.2872,103.299,-0.3757,-0.0034,0,0,1519117,-399.6243,0,0,0,1.52E+08,0,0,50.5922,30.977,511.6744,500.0782,474.4497,0.033,-0.0003,1.9617,-1.9238,0.0013,511.6744,500.0782,474.4497,112.0501,100.4539,74.8254,-0.0003,1.9617,-1.9238,495.4008,95.7765,37.2247,0.6885,1.4975,0.0508,0.0376,0.0003
1,2.2,2.2,494.95,38414.9,406,0,0.1844,404.7896,0.0833,0,0,0.0528,0.0522,0.0518,0,0,0,7.4783,0,0,100,0,0,0,0,0,0,0,0,0,0,508.1615,-36211.38,0.582,6.0914,0,0,0,0,0,0,0,0,0,0,4.0734,0.0431,0.0216,0.0216,518.4183,113.6287,90.1604,23.4683,1.0474,1.2603,7857.361,0.0431,502.7728,97.9832,11.7342,0,11.9013,101.8945,-1.2104,-0.0107,0,0,1519117,-404.7896,0,0,0,1.52E+08,0,0,50.6033,30.984,523.6959,499.9673,474.0856,29.1325,0.0431,1.9404,-1.9455,0.2185,537.153,499.9673,460.6285,132.3634,95.1777,55.8389,0.055,1.9404,-1.9574,499.2496,94.46,76.5245,0.5141,2.3705,24.7935,0.038,0.0541
1,4.6,4.6,495.07,38523.07,410,0,0.186,410.406,0.1537,0,0,0.0528,0.0522,0.0518,0,0,0,7.5885,0,0,100,0,0,0,0,0,0,0,0,0,0,508.0482,-36240.31,0.5164,1.5537,0,0,0,0,0,0,0,0,0,0,4.0774,0.0795,0.0398,0.0398,518.7384,108.3324,84.664,23.6684,1.0478,1.2796,7860.224,0.0795,502.9595,92.5535,11.8342,0,19.6573,96.4982,0.406,0.0037,0,0,1519117,-410.406,0,0,0,1.52E+08,0,0,50.613,30.9904,524.2602,499.9987,474.5733,7.4265,0.0795,1.9233,-1.9649,0.1939,525.3464,499.9987,473.487,114.9404,89.5927,63.081,0.0887,1.9233,-1.9741,499.6107,89.2047,51.8594,0.5112,1.8221,8.3215,0.0379,0.0468
1,7,7,494.49,38694.05,416,0,0.1832,416.9852,0.3083,0,0,0.0528,0.0522,0.0518,0,0,0,7.8406,0,0,100,0,0,0,0,0,0,0,0,0,0,508.1585,-36408.79,-0.56,-5.9494,0,0,0,0,0,0,0,0,0,0,4.0731,0.1594,0.0798,0.0798,517.777,100.7918,77.5048,23.287,1.0471,1.3005,7866.514,0.1595,502.2523,85.2671,11.6435,0,-429.7658,89.1483,0.9852,0.0098,0,0,1519117,-416.9852,0,0,0,1.52E+08,0,0,50.636,31.0072,522.6779,499.6812,472.8982,-28.4008,0.1594,1.8911,-2.0127,-0.2106,535.5519,499.6812,460.0242,118.5667,82.696,43.039,0.1696,1.8911,-2.0229,498.4191,81.4339,75.5277,0.5251,2.7549,-24.3847,0.0378,-0.0478
1,9.4,9.4,494.62,38838.26,424,0,0.186,423.2455,0.4298,0,0,0.0528,0.0522,0.0518,0,0,0,8.0423,0,0,100,0,0,0,0,0,0,0,0,0,0,508.224,-36550.26,-0.6793,-2.2865,0,0,0,0,0,0,0,0,0,0,4.0794,0.2222,0.1113,0.1113,518.2517,95.0062,71.3745,23.6317,1.0478,1.3311,7871.465,0.2223,502.4972,79.2517,11.8159,0,260.6175,83.1904,-0.7545,-0.0079,0,0,1519117,-423.2455,0,0,0,1.52E+08,0,0,50.6542,31.0208,523.3777,499.7869,473.1256,-10.9041,0.2222,1.8672,-2.0508,-0.2557,525.6417,499.7869,470.8615,102.3962,76.5414,47.616,0.2365,1.8672,-2.0651,498.7633,75.5179,54.7802,0.528,2.1505,-11.7298,0.0386,-0.0551
1,11.8,11.8,495.03,39065.79,429,0,0.1836,429.2296,0.5997,0,0,0.0528,0.0522,0.0518,0,0,0,8.3277,0,0,100,0,0,0,0,0,0,0,0,0,0,508.3351,-36736.07,0.7027,5.635,0,0,0,0,0,0,0,0,0,0,4.0836,0.3101,0.1554,0.1554,518.3282,89.0986,65.8004,23.2982,1.0471,1.3541,7878.406,0.3103,502.7961,73.5665,11.6491,0,58.8774,77.4495,0.2296,0.0026,0,0,1519117,-429.2296,0,0,0,1.52E+08,0,0,50.6796,31.0394,523.4559,500.0837,474.0026,26.8349,0.3101,1.832,-2.1035,0.2649,535.2192,500.0837,462.2393,105.9896,70.8541,33.0097,0.3246,1.832,-2.118,499.1807,69.9511,72.9799,0.5186,3.2109,23.6707,0.0386,0.0536
1,14.2,14.2,494.64,39151.84,433,0,0.1856,433.9784,0.74,0,0,0.0528,0.0522,0.0518,0,0,0,8.5493,0,0,100,0,0,0,0,0,0,0,0,0,0,508.3765,-36853.62,1.0387,2.9655,0,0,0,0,0,0,0,0,0,0,4.0854,0.3826,0.1919,0.1919,518.1796,84.2012,60.6616,23.5396,1.0476,1.388,7884.14,0.383,502.4866,68.5082,11.7698,0,310.7506,72.4314,0.9784,0.0116,0,0,1519117,-433.9784,0,0,0,1.52E+08,0,0,50.6999,31.0538,523.1753,499.8578,472.9273,14.1061,0.3826,1.8014,-2.1451,0.392,526.8644,499.8578,469.2382,92.886,65.8794,35.2598,0.4126,1.8014,-2.1751,498.6534,64.6751,57.6262,0.5313,2.6343,14.6562,0.0389,0.0739
1,16.6,16.6,494.85,39405.29,439,0,0.1831,439.1558,0.9425,0,0,0.0528,0.0522,0.0518,0,0,0,8.911,0,0,100,0,0,0,0,0,0,0,0,0,0,508.5358,-37056.43,-0.6742,-5.2626,0,0,0,0,0,0,0,0,0,0,4.0887,0.4873,0.2445,0.2445,518.0531,78.8973,55.6942,23.2031,1.0469,1.4166,7892.435,0.4879,502.5844,63.4286,11.6016,0,123.0125,67.2958,0.1558,0.002,0,0,1519117,-439.1558,0,0,0,1.52E+08,0,0,50.7299,31.0755,522.8792,500.0488,473.2114,-24.9908,0.4873,1.7584,-2.2069,-0.2549,533.2769,500.0488,462.8137,94.1211,60.893,23.6579,0.4993,1.7584,-2.2189,498.7131,59.5573,70.4632,0.5284,3.9784,-22.5902,0.0388,-0.0463
1,19,19,495.01,39460.4,441,0,0.1859,441.9924,1.1141,0,0,0.0528,0.0522,0.0518,0,0,0,9.1793,0,0,100,0,0,0,0,0,0,0,0,0,0,508.2361,-37125.29,-1.3491,-3.6444,0,0,0,0,0,0,0,0,0,0,4.0962,0.576,0.2893,0.2893,518.5407,76.5483,53.0176,23.5307,1.0475,1.4438,7899.476,0.5769,502.8536,60.8612,11.7654,0,87.9178,64.783,0.9924,0.013,0,0,1519117,-441.9924,0,0,0,1.52E+08,0,0,50.7536,31.0912,523.836,500.0343,474.0962,-17.2827,0.576,1.717,-2.254,-0.5107,529.2515,500.0343,468.6807,87.2591,58.0419,26.6883,0.6214,1.717,-2.2994,499.3222,57.3298,60.5708,0.5176,3.2696,-17.3982,0.039,-0.0834
1,21.4,21.4,494.83,39630,447,0,0.1829,447.9033,1.3387,0,0,0.0528,0.0522,0.0518,0,0,0,9.552,0,0,100,0,0,0,0,0,0,0,0,0,0,508.081,-37315.58,0.7301,4.8125,0,0,0,0,0,0,0,0,0,0,4.0964,0.6921,0.3479,0.3479,517.9605,70.0572,46.9267,23.1305,1.0467,1.4929,7908.711,0.6933,502.5402,54.6369,11.5653,0,160.3812,58.492,0.9033,0.0129,0,0,1519117,-447.9033,0,0,0,1.52E+08,0,0,50.7864,31.1145,523.0027,499.8641,473.8712,22.7801,0.6921,1.6679,-2.321,0.2769,531.9393,499.8641,464.9346,84.036,51.9608,17.0313,0.7048,1.6679,-2.3337,498.9126,51.0094,67.0047,0.5213,4.9342,21.4201,0.039,0.0448
1,23.8,23.8,494.88,39648.84,448,0,0.186,448.5951,1.5387,0,0,0.0528,0.0522,0.0518,0,0,0,9.8767,0,0,100,0,0,0,0,0,0,0,0,0,0,508.2578,-37331.23,1.9215,4.2497,0,0,0,0,0,0,0,0,0,0,4.1039,0.7955,0.4001,0.4001,518.3685,69.7734,46.2849,23.4885,1.0475,1.5075,7916.955,0.7971,502.7095,54.1144,11.7443,0,139.4381,58.0292,0.5951,0.0085,0,0,1519117,-448.5951,0,0,0,1.52E+08,0,0,50.8131,31.1311,523.5506,499.9623,473.7202,20.0845,0.7955,1.6157,-2.3726,0.7299,530.6378,499.9623,466.633,82.0427,51.3672,18.0379,0.8775,1.6157,-2.4546,499.0777,50.4826,64.0048,0.5207,4.5484,19.4364,0.0386,0.0995
1,26.2,26.2,494.98,39819.73,454,0,0.182,454.7274,1.8329,0,0,0.0528,0.0522,0.0518,0,0,0,10.3598,0,0,100,0,0,0,0,0,0,0,0,0,0,507.9168,-37497.74,-0.6119,-4.279,0,0,0,0,0,0,0,0,0,0,4.1068,0.9476,0.4772,0.4772,517.9395,63.2121,40.2526,22.9595,1.0464,1.5704,7929.111,0.9499,502.6332,47.9058,11.4798,0,122.0778,51.7324,0.7274,0.0115,0,0,1519117,-454.7274,0,0,0,1.52E+08,0,0,50.8548,31.1594,523.0688,499.895,474.5131,-20.1748,0.9476,1.5466,-2.4559,-0.233,530.3574,499.895,467.2246,75.63,45.1676,12.4972,0.9556,1.5466,-2.4639,499.159,44.4316,63.1328,0.5175,6.0518,-19.8632,0.0383,-0.0336
1,28.6,28.6,494.58,39838.18,452,0,0.1865,452.7443,2.0685,0,0,0.0528,0.0522,0.0518,0,0,0,10.7529,0,0,100,0,0,0,0,0,0,0,0,0,0,508.2396,-37479.6,-2.376,-4.7965,0,0,0,0,0,0,0,0,0,0,4.1129,1.0694,0.539,0.539,518.071,65.3267,41.8357,23.491,1.0475,1.5615,7938.874,1.0723,502.4103,49.666,11.7455,0,1059.327,53.5812,0.7443,0.0114,0,0,1519117,-452.7443,0,0,0,1.52E+08,0,0,50.8858,31.1781,523.0762,499.7696,472.9701,-22.5733,1.0694,1.4832,-2.515,-0.9063,531.7457,499.7696,464.3006,79.0014,47.0253,11.5563,1.1805,1.4832,-2.6261,498.6053,45.861,67.4451,0.5259,6.8362,-21.0097,0.0376,-0.1027
1,31,31,494.86,39993.52,459,0,0.1814,460.8006,2.407,0,0,0.0528,0.0522,0.0518,0,0,0,11.3035,0,0,100,0,0,0,0,0,0,0,0,0,0,508.1384,-37612.29,0.4681,3.6585,0,0,0,0,0,0,0,0,0,0,4.117,1.2444,0.6281,0.6281,517.6701,56.8695,34.0594,22.8101,1.0461,1.6697,7952.941,1.2483,502.4634,41.6628,11.4051,0,184.8854,45.4645,1.8006,0.0317,0,0,1519117,-460.8006,0,0,0,1.52E+08,0,0,50.9331,31.2093,522.5165,499.905,473.8493,17.1708,1.2444,1.4003,-2.6082,0.179,527.9648,499.905,468.401,67.1642,39.1044,7.6004,1.2486,1.4003,-2.6124,498.7569,37.9563,59.5638,0.5289,8.8369,17.6042,0.0365,0.023
1,33.4,33.4,494.93,39926.21,456,0,0.1875,456.5493,2.6732,0,0,0.0528,0.0522,0.0518,0,0,0,11.7384,0,0,100,0,0,0,0,0,0,0,0,0,0,508.1066,-37531.23,3.1073,5.2645,0,0,0,0,0,0,0,0,0,0,4.1291,1.3821,0.6983,0.6983,518.4676,61.9183,38.3807,23.5376,1.0476,1.6133,7964.046,1.3869,502.7759,46.2266,11.7688,0,141.8981,50.1495,0.5493,0.0089,0,0,1519117,-456.5493,0,0,0,1.52E+08,0,0,50.9673,31.2289,523.7959,499.9362,474.0828,24.6577,1.3821,1.3253,-2.6719,1.191,533.9515,499.9362,463.9272,77.4022,43.3869,7.3779,1.5501,1.3253,-2.8399,499.2716,42.7223,70.0243,0.5142,10.4911,22.3849,0.0355,0.1076
1,35.8,35.8,494.93,40067.46,465,0,0.1797,465.3551,3.0901,0,0,0.0528,0.0522,0.0518,0,0,0,12.3999,0,0,100,0,0,0,0,0,0,0,0,0,0,508.2119,-37628.57,-0.0418,-3.0074,0,0,0,0,0,0,0,0,0,0,4.13,1.5976,0.8085,0.8085,517.4474,52.0923,29.5749,22.5174,1.0455,1.7614,7981.487,1.6041,502.4358,37.0807,11.2587,0,163.913,40.8336,0.3551,0.0068,0,0,1519117,-465.3551,0,0,0,1.52E+08,0,0,51.0247,31.2657,522.1239,499.9764,473.9133,-14.0392,1.5976,1.2197,-2.7833,-0.0161,525.9142,499.9764,470.123,60.5591,34.6213,4.7679,1.5976,1.2197,-2.7833,498.6712,33.3161,55.7912,0.5351,12.7014,-15.1085,0.034,-0.0018
1,38.2,38.2,494.91,39935.29,458,0,0.1856,458.2009,3.4008,0,0,0.0528,0.0522,0.0518,0,0,0,12.9284,0,0,100,0,0,0,0,0,0,0,0,0,0,507.9157,-37511.57,-3.555,-5.6428,0,0,0,0,0,0,0,0,0,0,4.1422,1.7582,0.8909,0.8909,518.129,59.9281,36.7091,23.219,1.0469,1.6325,7994.535,1.7661,502.6497,44.4488,11.6095,0,153.7086,48.3186,0.2009,0.0034,0,0,1519117,-458.2009,0,0,0,1.52E+08,0,0,51.0645,31.2881,523.3672,499.8512,474.3338,-26.2787,1.7582,1.1306,-2.8567,-1.3704,534.7899,499.8512,462.9111,76.589,41.6503,4.7102,1.9534,1.1306,-3.0519,499.1841,40.9832,71.8788,0.5139,16.2602,-23.4933,0.0321,-0.1019
1,40.6,40.6,494.91,40034,468,0,0.1782,469.1813,3.8256,0,0,0.0528,0.0522,0.0518,0,0,0,13.585,0,0,100,0,0,0,0,0,0,0,0,0,0,507.9963,-37560.86,-0.5617,2.2451,0,0,0,0,0,0,0,0,0,0,4.1436,1.9779,1.0039,1.0039,517.145,47.9637,25.7287,22.235,1.0449,1.8642,8012.453,1.9879,502.3217,33.1404,11.1175,0,182.604,36.8462,1.1813,0.0246,0,0,1519117,-469.1813,0,0,0,1.52E+08,0,0,51.1224,31.3244,521.794,499.8819,474.2048,10.4203,1.9779,1.0203,-2.9677,-0.2173,523.9756,499.8819,472.0231,54.7943,30.7006,2.8418,1.9827,1.0203,-2.9725,498.6269,29.4456,51.9525,0.5362,19.2816,11.825,0.0305,-0.0216
1,43,43,494.74,39917.6,461,0,0.1857,460.5299,4.1892,0,0,0.0528,0.0522,0.0518,0,0,0,14.1518,0,0,100,0,0,0,0,0,0,0,0,0,0,507.6664,-37443.94,4.2885,5.9309,0,0,0,0,0,0,0,0,0,0,4.1574,2.1659,1.1009,1.1009,517.8722,57.3423,34.2101,23.1322,1.0468,1.6762,8027.85,2.1779,502.4507,41.9208,11.5661,0,289.2452,45.7762,-0.4701,-0.0082,0,0,1519117,-460.5299,0,0,0,1.52E+08,0,0,51.1696,31.3514,523.1148,499.651,474.2911,27.4497,2.1659,0.9173,-3.055,1.6634,535.4374,499.651,461.9684,74.9075,39.1211,1.4385,2.4186,0.9173,-3.3077,499.0189,38.489,73.469,0.5129,52.0733,24.1762,0.0282,0.0986
1,45.4,45.4,494.82,39967.15,471,0,0.1757,472.0522,4.6424,0,0,0.0528,0.0522,0.0518,0,0,0,14.9014,0,0,100,0,0,0,0,0,0,0,0,0,0,508.2526,-37445.79,1.468,-1.4188,0,0,0,0,0,0,0,0,0,0,4.1576,2.4002,1.2221,1.2221,516.6567,44.6045,22.7678,21.8367,1.0441,1.9591,8047.122,2.4149,502.0989,30.0467,10.9184,0,249.1695,33.6862,1.0522,0.0236,0,0,1519117,-472.0522,0,0,0,1.52E+08,0,0,51.231,31.389,520.8623,499.9233,473.5703,-6.543,2.4002,0.7963,-3.1711,0.5715,521.7509,499.9233,472.6818,49.6987,27.8711,0.6296,2.4294,0.7963,-3.2003,498.1187,26.0665,49.0691,0.5552,78.9369,-7.7336,0.0254,0.0466
1,47.8,47.8,494.89,39859.29,461,0,0.1852,461.3811,5.0847,0,0,0.0528,0.0522,0.0518,0,0,0,15.6352,0,0,100,0,0,0,0,0,0,0,0,0,0,507.7257,-37313.72,-4.527,-6.0589,0,0,0,0,0,0,0,0,0,0,4.177,2.6288,1.3409,1.3409,517.8518,56.4707,33.5089,22.9618,1.0464,1.6852,8066.014,2.6465,502.5439,41.1628,11.4809,0,171.0764,44.9898,0.3811,0.0067,0,0,1519117,-461.3811,0,0,0,1.52E+08,0,0,51.2889,31.4223,523.0532,499.7664,474.5882,-27.8451,2.6288,0.6715,-3.2779,-1.7683,535.7336,499.7664,461.9078,74.3525,38.3853,0.5267,2.8826,0.6715,-3.5317,499.136,37.7548,73.8258,0.5128,141.1667,-24.4841,0.0224,-0.0894
1,50.2,50.2,494.93,39872.09,472,0,0.174,473.5651,5.4619,0,0,0.0528,0.0522,0.0518,0,0,0,16.2553,0,0,100,0,0,0,0,0,0,0,0,0,0,508.2458,-37271.14,-2.4203,0.6139,0,0,0,0,0,0,0,0,0,0,4.1741,2.8239,1.4426,1.4426,516.4554,42.8903,21.3649,21.5254,1.0435,2.0075,8082.208,2.8443,502.1051,28.54,10.7627,0,184.4383,32.1276,1.5651,0.0365,0,0,1519117,-473.5651,0,0,0,1.52E+08,0,0,51.3397,31.4527,520.5681,499.9886,473.8701,2.8129,2.8239,0.5682,-3.3728,-0.9482,520.7369,499.9886,473.7013,47.1718,26.4235,0.1362,2.8956,0.5682,-3.4445,498.1422,24.5772,47.0356,0.5589,346.3421,3.4347,0.0193,-0.0612
1,52.6,52.6,495.12,39763.93,463,0,0.1854,463.055,6.0068,0,0,0.0528,0.0522,0.0518,0,0,0,17.1662,0,0,100,0,0,0,0,0,0,0,0,0,0,507.7483,-37146.59,5.0809,6.1339,0,0,0,0,0,0,0,0,0,0,4.1987,3.1056,1.5899,1.5899,517.9931,54.9381,32.065,22.8731,1.0462,1.7133,8105.706,3.1303,502.7444,39.6894,11.4366,0,107.228,43.5016,0.055,0.001,0,0,1519117,-463.055,0,0,0,1.52E+08,0,0,51.4122,31.495,523.2728,499.9173,475.1509,27.9852,3.1056,0.4157,-3.5066,1.9992,536.1185,499.9173,462.3052,73.0635,36.8623,-0.7498,3.3952,0.4157,-3.7962,499.447,36.392,73.8133,0.5096,-97.444,24.6559,0.0147,0.0837
1,55,55,494.84,39714.68,474,0,0.1734,474.4318,6.3486,0,0,0.0528,0.0522,0.0518,0,0,0,17.6703,0,0,100,0,0,0,0,0,0,0,0,0,0,508.0074,-37049.55,3.4466,0.2036,0,0,0,0,0,0,0,0,0,0,4.1918,3.2823,1.6827,1.6827,516.1988,41.767,20.4082,21.3588,1.0432,2.0466,8120.515,3.31,501.9596,27.5278,10.6794,0,240.779,31.0876,0.4318,0.0103,0,0,1519117,-474.4318,0,0,0,1.52E+08,0,0,51.4576,31.5212,520.2961,499.8419,474.0212,0.9264,3.2823,0.319,-3.5898,1.3598,520.3146,499.8419,474.0027,45.8828,25.4101,-0.4291,3.4143,0.319,-3.7218,498.0531,23.6213,46.3119,0.5579,-106.928,1.1464,0.0115,0.0682
1,57.4,57.4,495.24,39598.37,464,0,0.1851,463.43,7.0121,0,0,0.0528,0.0522,0.0518,0,0,0,18.797,0,0,100,0,0,0,0,0,0,0,0,0,0,507.7092,-36928.78,-5.0469,-6.2105,0,0,0,0,0,0,0,0,0,0,4.221,3.6253,1.8635,1.8635,517.9512,54.5212,31.81,22.7112,1.0459,1.714,8149.416,3.6592,502.8104,39.3804,11.3556,0,89.6336,43.1656,-0.57,-0.0105,0,0,1519117,-463.43,0,0,0,1.52E+08,0,0,51.547,31.5739,523.242,499.9765,475.5284,-28.11,3.6253,0.1347,-3.7547,-2.0017,536.2542,499.9765,462.5162,72.8242,36.5465,-0.9138,3.8875,0.1347,-4.0169,499.5823,36.1523,73.738,0.508,-79.6938,-24.8395,0.0053,-0.075
1,59.8,59.8,494.77,39505.84,474,0,0.1757,473.4155,7.256,0,0,0.0528,0.0522,0.0518,0,0,0,19.1852,0,0,100,0,0,0,0,0,0,0,0,0,0,508.3494,-36782.26,-4.111,-0.8979,0,0,0,0,0,0,0,0,0,0,4.2131,3.7514,1.9302,1.9302,516.3054,42.8899,21.3545,21.5354,1.0435,2.0085,8160.093,3.7877,501.9485,28.533,10.7677,0,306.7817,32.1222,-0.5845,-0.0136,0,0,1519117,-473.4155,0,0,0,1.52E+08,0,0,51.5784,31.5907,520.261,499.9279,473.3076,-4.0564,3.7514,0.0615,-3.8104,-1.6336,520.6089,499.9279,472.9597,47.1934,26.5124,-0.4558,3.9239,0.0615,-3.9829,497.8322,24.4167,47.6492,0.566,-103.5397,-4.9015,0.0025,-0.0675
1,62.2,62.2,495.06,39444.62,465,0,0.1858,465.2187,8.0129,0,0,0.0528,0.0522,0.0518,0,0,0,20.4681,0,0,100,0,0,0,0,0,0,0,0,0,0,507.4627,-36673.99,5.2907,6.1342,0,0,0,0,0,0,0,0,0,0,4.242,4.1427,2.138,2.138,517.7336,52.5149,29.8413,22.6736,1.0458,1.7598,8193.403,4.1871,502.6178,37.3991,11.3368,0,123.449,41.1781,0.2187,0.0042,0,0,1519117,-465.2187,0,0,0,1.52E+08,0,0,51.6817,31.6521,523.0482,499.7708,475.4604,27.5448,4.1427,-0.1478,-4.0005,2.1151,535.653,499.7708,462.8556,70.4343,34.5521,-2.3631,4.4087,-0.1478,-4.2665,499.4265,34.2078,72.7974,0.5071,-29.8059,24.5893,-0.0056,0.0693
1,64.6,64.6,495.06,39313.21,473,0,0.1782,473.5236,8.2168,0,0,0.0528,0.0522,0.0518,0,0,0,20.7927,0,0,100,0,0,0,0,0,0,0,0,0,0,507.8744,-36497.45,4.9162,1.6305,0,0,0,0,0,0,0,0,0,0,4.2389,4.2482,2.1943,2.1943,516.7859,43.2623,21.5364,21.7259,1.0439,2.0088,8202.431,4.295,502.302,28.7784,10.863,0,139.1186,32.3994,0.5236,0.0121,0,0,1519117,-473.5236,0,0,0,1.52E+08,0,0,51.7073,31.6648,521.3166,499.9269,474.8148,7.3101,4.2482,-0.212,-4.0446,1.9685,522.4387,499.9269,473.6927,48.9151,26.4033,0.1691,4.4756,-0.212,-4.272,498.6861,25.1625,48.746,0.5382,289.2673,8.7266,-0.0084,0.0664
1,67,67,495.03,39208.94,466,0,0.1848,466.0677,9.0885,0,0,0.0528,0.0522,0.0518,0,0,0,22.2245,0,0,100,0,0,0,0,0,0,0,0,0,0,507.4063,-36398.56,-4.8686,-5.9401,0,0,0,0,0,0,0,0,0,0,4.2644,4.6988,2.4356,2.4356,517.4481,51.3804,28.9623,22.4181,1.0453,1.774,8241.213,4.7563,502.5027,36.435,11.2091,0,132.5536,40.1714,0.0677,0.0013,0,0,1519117,-466.0677,0,0,0,1.52E+08,0,0,51.8277,31.7368,522.6423,499.7304,475.4797,-26.4449,4.6988,-0.4525,-4.2656,-1.9632,534.4927,499.7304,463.6292,68.425,33.6627,-2.4385,4.9088,-0.4525,-4.4756,499.2841,33.2164,70.8635,0.5094,-28.0603,-24.1381,-0.0193,-0.0613
1,69.4,69.4,494.95,39078.59,473,0,0.1812,472.0735,9.2336,0,0,0.0528,0.0522,0.0518,0,0,0,22.4623,0,0,100,0,0,0,0,0,0,0,0,0,0,507.967,-36180.73,-5.1265,-2.3299,0,0,0,0,0,0,0,0,0,0,4.2634,4.7739,2.476,2.476,516.9191,44.8456,22.8765,21.9691,1.0444,1.9603,8247.713,4.8333,502.273,30.1995,10.9846,0,172.0959,33.8611,-0.9265,-0.0207,0,0,1519117,-472.0735,0,0,0,1.52E+08,0,0,51.8445,31.7434,521.4713,499.8934,474.3938,-10.3614,4.7739,-0.503,-4.2924,-2.0694,523.6509,499.8934,472.2142,51.5774,27.8199,0.1407,5.0042,-0.503,-4.5227,498.5862,26.5127,51.4367,0.5381,366.5771,-11.8792,-0.0215,-0.0618
1,71.8,71.8,494.99,39017.15,470,0,0.1851,468.5769,10.14,0,0,0.0528,0.0522,0.0518,0,0,0,23.9363,0,0,100,0,0,0,0,0,0,0,0,0,0,507.7,-36102.02,4.7647,5.6172,0,0,0,0,0,0,0,0,0,0,4.2878,5.2425,2.729,2.729,517.3192,48.7423,26.4131,22.3292,1.0451,1.8454,8288.5,5.3143,502.4331,33.8562,11.1646,0,149.5376,37.5777,-1.4231,-0.0292,0,0,1519117,-468.5769,0,0,0,1.52E+08,0,0,51.9713,31.8197,522.2626,499.8166,474.9206,24.7972,5.2425,-0.7523,-4.5244,1.9376,532.873,499.8166,464.3102,64.2961,31.2397,-4.2667,5.4311,-0.7523,-4.713,498.9999,30.423,68.5628,0.5179,-15.0693,23.1655,-0.0342,0.056
1,74.2,74.2,495.02,38815.84,471,0,0.1835,471.7706,10.2554,0,0,0.0528,0.0522,0.0518,0,0,0,24.1139,0,0,100,0,0,0,0,0,0,0,0,0,0,508.0578,-35863.99,5.7256,3.0734,0,0,0,0,0,0,0,0,0,0,4.2891,5.3021,2.7614,2.7614,517.1506,45.38,23.2494,22.1306,1.0447,1.9519,8293.716,5.3757,502.3969,30.6263,11.0653,0,146.9003,34.3147,0.7706,0.017,0,0,1519117,-471.7706,0,0,0,1.52E+08,0,0,51.9836,31.8232,521.7759,499.9707,474.4398,13.5564,5.3021,-0.7956,-4.5424,2.3303,525.3834,499.9707,470.8324,53.6128,28.2001,-0.9382,5.5706,-0.7956,-4.8109,498.7289,26.9582,54.551,0.5341,-57.1443,14.9014,-0.0359,0.0592
1,76.6,76.6,494.98,38756.77,470,0,0.185,469.5314,11.249,0,0,0.0528,0.0522,0.0518,0,0,0,25.7295,0,0,100,0,0,0,0,0,0,0,0,0,0,507.9948,-35784.5,-4.0737,-5.2729,0,0,0,0,0,0,0,0,0,0,4.3126,5.8158,3.0412,3.0412,517.1633,47.6319,25.4486,22.1833,1.0448,1.8717,8338.952,5.9047,502.3744,32.843,11.0917,0,154.9747,36.5403,-0.4686,-0.0098,0,0,1519117,-469.5314,0,0,0,1.52E+08,0,0,52.1239,31.9077,521.8442,499.9219,474.4384,-23.0699,5.8158,-1.0694,-4.7977,-1.6715,531.2177,499.9219,465.0649,61.6863,30.3905,-4.4665,5.9458,-1.0694,-4.9277,498.7349,29.2034,66.1528,0.5269,-13.8109,-22.1123,-0.0513,-0.0486
1,79,79,494.89,38526.27,471,0,0.1848,470.615,11.3446,0,0,0.0528,0.0522,0.0518,0,0,0,25.8861,0,0,100,0,0,0,0,0,0,0,0,0,0,507.8565,-35525.34,-5.6826,-3.6815,0,0,0,0,0,0,0,0,0,0,4.3138,5.8653,3.0683,3.0683,517.0353,46.4203,24.275,22.1453,1.0447,1.9123,8343.337,5.9557,502.2718,31.6568,11.0727,0,196.7249,35.3477,-0.385,-0.0083,0,0,1519117,-470.615,0,0,0,1.52E+08,0,0,52.1332,31.909,521.7311,499.8131,474.432,-16.0966,5.8653,-1.1086,-4.8097,-2.3332,526.6893,499.8131,469.4738,56.0743,29.1981,-1.1412,6.1145,-1.1086,-5.0589,498.6587,28.0437,57.2155,0.5303,-49.1363,-17.1202,-0.053,-0.0546
1,81.4,81.4,495.01,38496.01,471,0,0.186,472.4239,12.3235,0,0,0.0528,0.0522,0.0518,0,0,0,27.4944,0,0,100,0,0,0,0,0,0,0,0,0,0,507.8648,-35463.38,3.5938,4.8102,0,0,0,0,0,0,0,0,0,0,4.3384,6.3714,3.3465,3.3465,517.1882,44.7643,22.5861,22.1782,1.0448,1.9819,8388.436,6.4786,502.4027,29.9788,11.0891,0,151.3153,33.6752,1.4239,0.0318,0,0,1519117,-472.4239,0,0,0,1.52E+08,0,0,52.2729,31.9934,521.9562,499.8906,474.73,20.8629,6.3714,-1.3782,-5.0629,1.4875,529.8524,499.8906,466.8337,57.4285,27.4667,-5.5902,6.4674,-1.3782,-5.1589,498.8589,26.435,63.0187,0.5246,-10.2731,20.7308,-0.0697,0.0428
1,83.8,83.8,494.86,38222.89,469,0,0.1862,470.5583,12.3965,0,0,0.0528,0.0522,0.0518,0,0,0,27.6083,0,0,100,0,0,0,0,0,0,0,0,0,0,507.7294,-35191.74,6.1314,4.289,0,0,0,0,0,0,0,0,0,0,4.339,6.4091,3.3673,3.3673,517.0515,46.4932,24.3017,22.1915,1.0448,1.9132,8391.814,6.5176,502.2572,31.6989,11.0958,0,214.4554,35.3975,1.5583,0.0335,0,0,1519117,-470.5583,0,0,0,1.52E+08,0,0,52.2789,31.9924,521.8242,499.7457,474.5646,18.5935,6.4091,-1.4123,-5.0685,2.539,528.2625,499.7457,468.1264,57.7042,29.1874,-2.4319,6.6834,-1.4123,-5.3428,498.7115,28.1532,60.1361,0.5258,-23.728,19.099,-0.0717,0.0521
1,86.2,86.2,495.14,38208.48,474,0,0.1833,473.7785,13.4344,0,0,0.0528,0.0522,0.0518,0,0,0,29.2541,0,0,100,0,0,0,0,0,0,0,0,0,0,507.9308,-35108.45,-2.7491,-4.282,0,0,0,0,0,0,0,0,0,0,4.3624,6.9457,3.6649,3.6649,516.8594,43.0809,21.3615,21.7194,1.0439,2.0168,8440.206,7.0737,502.3798,28.6013,10.8597,0,121.288,32.2212,-0.2215,-0.0051,0,0,1519117,-473.7785,0,0,0,1.52E+08,0,0,52.428,32.0822,521.4168,499.9957,474.9709,-18.4045,6.9457,-1.6996,-5.3369,-1.1482,527.8254,499.9957,468.5623,54.0469,26.2172,-5.2162,6.9991,-1.6996,-5.3903,498.7944,25.016,59.2631,0.5304,-10.3614,-19.1986,-0.0908,-0.0348
1,88.6,88.6,494.74,37924.17,469,0,0.1853,469.4753,13.5164,0,0,0.0528,0.0522,0.0518,0,0,0,29.3862,0,0,100,0,0,0,0,0,0,0,0,0,0,507.9535,-34818,-6.0132,-4.8048,0,0,0,0,0,0,0,0,0,0,4.3629,6.9881,3.6885,3.6885,516.6831,47.2078,25.2647,21.9431,1.0444,1.8685,8444.054,7.1177,502.0544,32.5791,10.9716,0,331.8441,36.2363,0.4753,0.0101,0,0,1519117,-469.4753,0,0,0,1.52E+08,0,0,52.435,32.0815,521.1224,499.7557,473.9127,-20.6404,6.9881,-1.7368,-5.3439,-2.5129,528.8738,499.7557,466.1613,59.3985,30.2804,-3.314,7.239,-1.7368,-5.5948,498.2636,28.7883,62.7125,0.5357,-17.9235,-20.5834,-0.0926,-0.0483
1,91,91,494.97,37923.49,475,0,0.1817,476.4454,14.5077,0,0,0.0528,0.0522,0.0518,0,0,0,30.9903,0,0,100,0,0,0,0,0,0,0,0,0,0,507.7092,-34734.75,1.9343,3.6692,0,0,0,0,0,0,0,0,0,0,4.3844,7.5006,3.9754,3.9754,516.3683,39.9229,18.5246,21.3983,1.0432,2.1551,8490.839,7.6507,502.1028,25.6574,10.6992,0,174.2138,29.2238,1.4454,0.0362,0,0,1519117,-476.4454,0,0,0,1.52E+08,0,0,52.5786,32.1679,520.7859,499.8055,474.8926,15.6327,7.5006,-2.0122,-5.6008,0.815,525.6049,499.8055,470.0736,49.1595,23.3601,-6.3718,7.5259,-2.0122,-5.6261,498.4947,22.0493,55.5313,0.5354,-7.7152,17.1326,-0.1124,0.0261
1,93.4,93.4,494.85,37611.65,470,0,0.1857,469.7161,14.5872,0,0,0.0528,0.0522,0.0518,0,0,0,31.1412,0,0,100,0,0,0,0,0,0,0,0,0,0,507.4748,-34444.7,6.3484,5.2519,0,0,0,0,0,0,0,0,0,0,4.3893,7.5417,3.9985,3.9985,516.7157,46.9996,25.1339,21.8657,1.0442,1.87,8494.613,7.6935,502.1386,32.4225,10.9329,0,218.5112,36.0668,-0.2839,-0.006,0,0,1519117,-469.7161,0,0,0,1.52E+08,0,0,52.5855,32.1671,521.4589,499.6417,474.9609,22.3639,7.5417,-2.0491,-5.6076,2.6763,530.4692,499.6417,465.9506,60.7531,29.9256,-3.7655,7.8086,-2.0491,-5.8745,498.6871,28.9711,64.5186,0.5222,-16.1341,21.9442,-0.115,0.0461
1,95.8,95.8,495.15,37604.79,479,0,0.178,477.8534,15.5963,0,0,0.0528,0.0522,0.0518,0,0,0,32.7252,0,0,100,0,0,0,0,0,0,0,0,0,0,507.7707,-34336.01,-0.9269,-3.0386,0,0,0,0,0,0,0,0,0,0,4.408,8.0634,4.2931,4.2931,515.9891,38.1357,17.2966,20.8391,1.0421,2.2048,8542.816,8.2377,502.0963,24.2429,10.4196,0,125.9082,27.7162,-1.1466,-0.0301,0,0,1519117,-477.8534,0,0,0,1.52E+08,0,0,52.7326,32.2552,520.1617,499.9399,475.2704,-12.8304,8.0634,-2.3314,-5.8688,-0.3941,523.5699,499.9399,471.8621,45.7165,22.0865,-5.9913,8.069,-2.3314,-5.8744,498.4573,20.6039,51.7078,0.543,-7.6305,-14.8766,-0.1368,-0.0135
1,98.2,98.2,494.88,37316.73,468,0,0.1857,469.2147,15.7257,0,0,0.0528,0.0522,0.0518,0,0,0,32.9439,0,0,100,0,0,0,0,0,0,0,0,0,0,507.6041,-34042.13,-6.1993,-5.643,0,0,0,0,0,0,0,0,0,0,4.4164,8.1303,4.3311,4.3311,516.5962,47.3815,25.6653,21.7162,1.0439,1.8461,8549.037,8.3076,502.1187,32.904,10.8581,0,198.3503,36.5234,1.2147,0.0256,0,0,1519117,-469.2147,0,0,0,1.52E+08,0,0,52.7468,32.2588,521.2174,499.7087,474.8456,-23.8049,8.1303,-2.3819,-5.8886,-2.6381,531.2619,499.7087,464.8011,62.0472,30.494,-4.4136,8.3743,-2.3819,-6.1326,498.5906,29.3759,66.4608,0.5252,-14.0582,-22.8774,-0.1402,-0.0431
1,100.6,100.6,494.79,37276.56,479,0,0.1714,480.4495,16.6042,0,0,0.0528,0.0522,0.0518,0,0,0,34.3147,0,0,100,0,0,0,0,0,0,0,0,0,0,508.093,-33940.4,-0.5835,2.1181,0,0,0,0,0,0,0,0,0,0,4.4224,8.5845,4.59,4.59,514.7405,34.291,14.3405,19.9505,1.0403,2.3912,8591.514,8.783,501.4402,20.9907,9.9753,0,310.2137,24.3158,1.4495,0.0423,0,0,1519117,-480.4495,0,0,0,1.52E+08,0,0,52.8759,32.336,518.0145,499.8382,473.8471,8.8695,8.5845,-2.6286,-6.1164,-0.2501,519.7291,499.8382,472.1325,39.2796,19.3887,-8.317,8.5866,-2.6286,-6.1185,497.2333,16.7838,47.5966,0.5821,-4.7228,10.941,-0.1605,-0.0083
1,103,103,494.86,37016.41,469,0,0.186,469.6411,16.801,0,0,0.0528,0.0522,0.0518,0,0,0,34.6667,0,0,100,0,0,0,0,0,0,0,0,0,0,507.8139,-33663.72,6.4327,5.9259,0,0,0,0,0,0,0,0,0,0,4.4423,8.6863,4.6483,4.6483,516.4809,46.8398,25.2189,21.6209,1.0437,1.8573,8601.092,8.8897,502.067,32.4259,10.8105,0,211.6759,36.0294,0.6411,0.0137,0,0,1519117,-469.6411,0,0,0,1.52E+08,0,0,52.9007,32.3463,520.9142,499.7753,474.4745,24.7763,8.6863,-2.6972,-6.1551,2.762,531.6506,499.7753,463.7381,62.0095,30.1342,-5.903,8.939,-2.6972,-6.4078,498.388,28.7469,67.9125,0.5306,-10.5047,23.4287,-0.166,0.0412
1,105.4,105.4,494.96,36977.3,480,0,0.1676,481.6593,17.6109,0,0,0.0528,0.0522,0.0518,0,0,0,35.9506,0,0,100,0,0,0,0,0,0,0,0,0,0,507.6543,-33541.76,1.899,-1.2706,0,0,0,0,0,0,0,0,0,0,4.4444,9.105,4.889,4.889,514.3557,32.6964,13.3007,19.3957,1.0392,2.4582,8640.712,9.3293,501.4252,19.7659,9.6979,0,190.3949,22.9986,1.6593,0.0507,0,0,1519117,-481.6593,0,0,0,1.52E+08,0,0,53.0203,32.4173,517.6886,499.7765,474.9864,-5.2762,9.105,-2.9268,-6.3644,0.821,518.3309,499.7765,474.3441,36.6716,18.1172,-7.3152,9.1268,-2.9268,-6.3862,497.4838,15.8245,43.9868,0.5782,-5.0131,-6.9403,-0.1862,0.0222
1,107.8,107.8,494.98,36737.27,468,0,0.1857,468.0959,17.9161,0,0,0.0528,0.0522,0.0518,0,0,0,36.4552,0,0,100,0,0,0,0,0,0,0,0,0,0,507.3485,-33267.02,-6.5463,-6.0091,0,0,0,0,0,0,0,0,0,0,4.4701,9.2628,4.9802,4.9802,516.4319,48.336,26.8841,21.4519,1.0433,1.7979,8655.739,9.4953,502.1306,34.0347,10.726,0,151.7848,37.6101,0.0959,0.002,0,0,1519117,-468.0959,0,0,0,1.52E+08,0,0,53.0617,32.4378,521.1213,499.6725,475.5266,-24.8914,9.2628,-3.0251,-6.4322,-2.837,532.0775,499.6725,464.5704,63.9816,31.5766,-3.5255,9.5151,-3.0251,-6.6845,498.7735,30.6776,67.5071,0.52,-18.1482,-23.7572,-0.1945,-0.0392
1,110.2,110.2,494.71,36624.91,480,0,0.1651,482.2674,18.5427,0,0,0.0528,0.0522,0.0518,0,0,0,37.4875,0,0,100,0,0,0,0,0,0,0,0,0,0,508.0758,-33100.98,-3.5432,0.4859,0,0,0,0,0,0,0,0,0,0,4.4625,9.5868,5.1681,5.1681,513.713,31.4456,12.4426,19.003,1.0384,2.5273,8686.757,9.8366,501.0443,18.7769,9.5015,0,458.2214,21.9441,2.2674,0.0721,0,0,1519117,-482.2674,0,0,0,1.52E+08,0,0,53.1538,32.4912,516.4335,499.7806,473.6927,2.0021,9.5868,-3.2068,-6.5912,-1.5437,516.527,499.7806,473.5991,34.2596,17.5132,-8.6683,9.6601,-3.2068,-6.6645,496.6356,14.3682,42.9279,0.6099,-3.9523,2.6761,-0.2112,-0.0308
1,112.6,112.6,494.99,36427.95,470,0,0.1864,469.7977,19.0449,0,0,0.0528,0.0522,0.0518,0,0,0,38.3406,0,0,100,0,0,0,0,0,0,0,0,0,0,507.7198,-32847.63,6.3077,6.147,0,0,0,0,0,0,0,0,0,0,4.4986,9.8464,5.3194,5.3194,516.3818,46.5841,25.1923,21.3918,1.0432,1.8491,8711.771,10.1105,502.1206,32.3229,10.6959,0,152.1915,35.8882,-0.2023,-0.0043,0,0,1519117,-469.7977,0,0,0,1.52E+08,0,0,53.226,32.5309,520.8311,499.8189,474.9798,25.2225,9.8464,-3.3588,-6.713,2.7596,531.9901,499.8189,463.8209,62.1924,30.0212,-5.9768,10.0732,-3.3588,-6.9398,498.5433,28.7456,68.1692,0.5281,-10.4056,23.8656,-0.2254,0.0369
1,115,115,494.9,36299.05,481,0,0.1653,482.3168,19.5363,0,0,0.0528,0.0522,0.0518,0,0,0,39.1469,0,0,100,0,0,0,0,0,0,0,0,0,0,507.9202,-32665.31,4.2411,0.2581,0,0,0,0,0,0,0,0,0,0,4.4889,10.1005,5.4682,5.4682,513.8161,31.4993,12.5832,18.9161,1.0382,2.5033,8736.395,10.3791,501.2054,18.8886,9.4581,0,223.0459,22.0413,1.3168,0.0418,0,0,1519117,-482.3168,0,0,0,1.52E+08,0,0,53.298,32.5717,516.7025,499.8387,474.4386,1.0547,10.1005,-3.5042,-6.8356,1.8632,516.7288,499.8387,474.4123,34.412,17.5219,-7.9045,10.2024,-3.5042,-6.9375,496.9933,14.6765,42.3165,0.6009,-4.3535,1.4286,-0.2393,0.0318
1,117.4,117.4,494.98,36116.96,470,0,0.1858,469.5039,20.1916,0,0,0.0528,0.0522,0.0518,0,0,0,40.2211,0,0,100,0,0,0,0,0,0,0,0,0,0,507.5725,-32434.33,-6.1992,-6.2225,0,0,0,0,0,0,0,0,0,0,4.5265,10.4393,5.6675,5.6675,516.1673,46.6634,25.4761,21.1873,1.0428,1.8317,8769.443,10.7379,502.0424,32.5385,10.5937,0,154.9136,36.0698,-0.4961,-0.0106,0,0,1519117,-469.5039,0,0,0,1.52E+08,0,0,53.3947,32.6267,520.5817,499.7562,475.1971,-25.286,10.4393,-3.698,-6.9999,-2.7386,531.8647,499.7562,463.9141,62.3608,30.2523,-5.5898,10.6517,-3.698,-7.2123,498.5116,29.0078,67.9506,0.5275,-11.1562,-24.0472,-0.2586,-0.035
1,119.8,119.8,494.81,35916.48,479,0,0.1716,480.6357,20.496,0,0,0.0528,0.0522,0.0518,0,0,0,40.6887,0,0,100,0,0,0,0,0,0,0,0,0,0,508.015,-32215.24,-5.1327,-0.9478,0,0,0,0,0,0,0,0,0,0,4.5184,10.5966,5.7604,5.7604,514.3387,33.703,14.1743,19.5287,1.0395,2.3778,8784.873,10.9047,501.3196,20.6839,9.7644,0,288.7328,23.9387,1.6357,0.0485,0,0,1519117,-480.6357,0,0,0,1.52E+08,0,0,53.4379,32.6492,517.4659,499.8181,474.0712,-3.8418,10.5966,-3.7939,-7.0709,-2.2732,517.8034,499.8181,473.7337,37.1677,19.1824,-6.902,10.7417,-3.7939,-7.216,497.1184,16.4827,44.0697,0.5919,-5.3851,-5.0205,-0.2682,-0.0327
1,122.2,122.2,494.98,35772.88,470,0,0.1871,470.6792,21.271,0,0,0.0528,0.0522,0.0518,0,0,0,41.9908,0,0,100,0,0,0,0,0,0,0,0,0,0,507.7828,-32001.81,5.8951,6.1095,0,0,0,0,0,0,0,0,0,0,4.555,10.9973,5.9982,5.9982,516.181,45.5018,24.3008,21.201,1.0428,1.8724,8824.423,11.3303,502.047,31.3678,10.6005,0,157.5253,34.9013,0.6792,0.0149,0,0,1519117,-470.6792,0,0,0,1.52E+08,0,0,53.5544,32.7166,520.4859,499.8352,474.8788,24.6002,10.9973,-4.0206,-7.269,2.6282,531.226,499.8352,464.1388,60.5468,29.156,-6.5404,11.1845,-4.0206,-7.4562,498.4,27.7208,67.0872,0.5321,-9.2574,23.5853,-0.2923,0.033
1,124.6,124.6,495.01,35550.45,478,0,0.1741,479.6381,21.496,0,0,0.0528,0.0522,0.0518,0,0,0,42.3164,0,0,100,0,0,0,0,0,0,0,0,0,0,508.2321,-31746.4,5.4754,1.6453,0,0,0,0,0,0,0,0,0,0,4.548,11.1136,6.0675,6.0675,514.7143,35.0762,15.3719,19.7043,1.0398,2.2818,8835.97,11.4541,501.5781,21.94,9.8522,0,166.3445,25.2241,1.6381,0.0467,0,0,1519117,-479.6381,0,0,0,1.52E+08,0,0,53.585,32.7308,517.9277,500.0238,474.2579,6.6127,11.1136,-4.0961,-7.3171,2.4456,518.907,500.0238,473.2785,39.2689,20.3857,-6.3596,11.2745,-4.0961,-7.478,497.4031,17.765,45.6285,0.5862,-6.1747,8.4245,-0.2996,0.0321
1,127,127,495.1,35431.7,470,0,0.1871,471.2646,22.4174,0,0,0.0528,0.0522,0.0518,0,0,0,43.806,0,0,100,0,0,0,0,0,0,0,0,0,0,507.5484,-31551.88,-5.5605,-5.9348,0,0,0,0,0,0,0,0,0,0,4.5854,11.59,6.3529,6.3529,516.1657,44.9011,23.8354,21.0657,1.0425,1.8838,8883.582,11.9619,502.1219,30.8573,10.5329,0,125.3908,34.3683,1.2646,0.0282,0,0,1519117,-471.2646,0,0,0,1.52E+08,0,0,53.7258,32.8133,520.6021,499.8201,475.5676,-23.6637,11.59,-4.3634,-7.5562,-2.5035,530.7498,499.8201,465.4199,59.4852,28.5555,-5.8447,11.7523,-4.3634,-7.7185,498.6633,27.3987,65.3299,0.5266,-10.1776,-23.211,-0.3296,-0.0311
1,129.4,129.4,494.99,35236.1,476,0,0.1801,477.4726,22.5462,0,0,0.0528,0.0522,0.0518,0,0,0,43.9756,0,0,100,0,0,0,0,0,0,0,0,0,0,508.2854,-31278.18,-5.8207,-2.3349,0,0,0,0,0,0,0,0,0,0,4.5807,11.6566,6.393,6.393,515.2481,37.7755,17.5174,20.2581,1.0409,2.1565,8890.279,12.0331,501.7427,24.2701,10.1291,0,168.8764,27.6465,1.4726,0.039,0,0,1519117,-477.4726,0,0,0,1.52E+08,0,0,53.7413,32.8179,518.7369,500.0308,474.1364,-9.3006,11.6566,-4.4132,-7.5777,-2.6232,520.5986,500.0308,472.2747,43.126,22.5582,-5.1979,11.8338,-4.4132,-7.7549,497.6347,20.1621,48.3239,0.5744,-8.2968,-11.3196,-0.3343,-0.0314
1,131.8,131.8,494.84,35106.82,473,0,0.1876,473.0373,23.5041,0,0,0.0528,0.0522,0.0518,0,0,0,45.538,0,0,100,0,0,0,0,0,0,0,0,0,0,507.8512,-31129.2,5.0009,5.6199,0,0,0,0,0,0,0,0,0,0,4.6117,12.1518,6.6924,6.6924,515.8274,42.7901,21.8027,20.9874,1.0424,1.9626,8940.394,12.5628,501.8358,28.7985,10.4937,0,236.2806,32.2964,0.0373,0.0009,0,0,1519117,-473.0373,0,0,0,1.52E+08,0,0,53.89,32.9061,519.8912,499.7728,474.4364,22.1995,12.1518,-4.6888,-7.83,2.2727,528.9341,499.7728,465.3935,55.8968,26.7355,-7.6438,12.2802,-4.6888,-7.9584,498.0334,24.9962,63.5406,0.5411,-7.3127,22.1634,-0.367,0.0289
1,134.2,134.2,494.72,34884.78,478,0,0.1817,477.2369,23.5809,0,0,0.0528,0.0522,0.0518,0,0,0,45.6356,0,0,100,0,0,0,0,0,0,0,0,0,0,507.9404,-30848.14,5.9449,3.0179,0,0,0,0,0,0,0,0,0,0,4.6067,12.1916,6.7166,6.7166,515.0347,37.7978,17.4831,20.3147,1.0411,2.162,8944.446,12.6055,501.4916,24.2547,10.1574,0,407.6054,27.6405,-0.7631,-0.0202,0,0,1519117,-477.2369,0,0,0,1.52E+08,0,0,53.8973,32.9055,518.6051,499.7316,473.9965,11.9147,12.1916,-4.7247,-7.8371,2.7032,521.588,499.7316,471.0136,44.3511,22.4947,-6.2233,12.3724,-4.7247,-8.0179,497.4444,20.2075,50.5744,0.5678,-7.1266,14.0553,-0.3702,0.0304
1,136.6,136.6,495.18,34775.92,475,0,0.1887,473.9043,24.6446,0,0,0.0528,0.0522,0.0518,0,0,0,47.3672,0,0,100,0,0,0,0,0,0,0,0,0,0,507.8623,-30714.58,-4.4962,-5.2772,0,0,0,0,0,0,0,0,0,0,4.6457,12.7415,7.0523,7.0523,516.1422,42.2379,21.2757,20.9622,1.0423,1.9853,9000.813,13.1959,502.1674,28.2631,10.4811,0,114.0217,31.7568,-1.0957,-0.0259,0,0,1519117,-473.9043,0,0,0,1.52E+08,0,0,54.0645,33.0052,520.4031,499.9874,475.3037,-20.6404,12.7415,-5.0301,-8.1196,-2.0637,528.4232,499.9874,467.2836,54.5189,26.0831,-6.6207,12.8431,-5.0301,-8.2212,498.5647,24.6604,61.1396,0.5349,-8.2346,-21.2344,-0.4082,-0.0268
1,139,139,494.74,34538.18,475,0,0.1844,475.148,24.6876,0,0,0.0528,0.0522,0.0518,0,0,0,47.4418,0,0,100,0,0,0,0,0,0,0,0,0,0,508.0174,-30407.46,-6.0505,-3.6611,0,0,0,0,0,0,0,0,0,0,4.6386,12.7637,7.066,7.066,515.2223,40.0743,19.592,20.4823,1.0414,2.0454,9003.104,13.2198,501.5674,26.4194,10.2412,0,358.858,29.8332,0.148,0.0037,0,0,1519117,-475.148,0,0,0,1.52E+08,0,0,54.066,33.0006,518.8591,499.7725,473.9399,-14.3161,12.7637,-5.0576,-8.1163,-2.7777,523.0338,499.7725,469.7652,47.8858,24.6245,-5.3828,12.9469,-5.0576,-8.2995,497.5238,22.3758,53.2686,0.5633,-8.8961,-16.257,-0.4102,-0.0293
1,141.4,141.4,494.92,34436.57,474,0,0.1873,475.8155,25.7396,0,0,0.0528,0.0522,0.0518,0,0,0,49.2146,0,0,100,0,0,0,0,0,0,0,0,0,0,507.6447,-30291.76,3.6593,4.8129,0,0,0,0,0,0,0,0,0,0,4.6711,13.3076,7.4013,7.4013,515.5974,39.7819,19.1045,20.6774,1.0418,2.0823,9059.589,13.8059,501.8125,25.997,10.3387,0,194.9275,29.4432,1.8155,0.0456,0,0,1519117,-475.8155,0,0,0,1.52E+08,0,0,54.2334,33.1007,519.6694,499.7428,474.9889,18.6453,13.3076,-5.3599,-8.3977,1.6957,526.4278,499.7428,468.2304,50.6123,23.9273,-7.5851,13.3736,-5.3599,-8.4637,498.1337,22.3182,58.1974,0.5415,-6.6726,19.9243,-0.45,0.0239
1,143.8,143.8,494.69,34230.01,474,0,0.1843,474.8859,25.7409,0,0,0.0528,0.0522,0.0518,0,0,0,49.2239,0,0,100,0,0,0,0,0,0,0,0,0,0,507.8461,-29984.31,6.0335,4.2476,0,0,0,0,0,0,0,0,0,0,4.666,13.3083,7.4017,7.4017,515.0302,40.1443,19.8041,20.3402,1.0411,2.0271,9059.662,13.8067,501.4701,26.5842,10.1701,0,469.333,29.9742,0.8859,0.0221,0,0,1519117,-474.8859,0,0,0,1.52E+08,0,0,54.2282,33.092,518.6698,499.6758,474.0921,16.4576,13.3083,-5.3756,-8.3832,2.7955,524.0873,499.6758,468.6745,49.2014,24.7899,-6.2114,13.487,-5.3756,-8.5619,497.4792,22.5933,55.4128,0.5595,-7.9211,18.2207,-0.4505,0.0283
1,146.2,146.2,494.96,34131.67,474,0,0.1851,477.1609,26.8514,0,0,0.0528,0.0522,0.0518,0,0,0,51.0922,0,0,100,0,0,0,0,0,0,0,0,0,0,507.6664,-29873.53,-3.0282,-4.2744,0,0,0,0,0,0,0,0,0,0,4.6992,13.8824,7.7591,7.7591,515.2599,38.099,17.7991,20.2999,1.041,2.1405,9120.058,14.4277,501.7267,24.5658,10.15,0,179.9333,27.9491,3.1609,0.083,0,0,1519117,-477.1609,0,0,0,1.52E+08,0,0,54.4067,33.1989,519.1346,499.7752,475.0693,-16.3981,13.8824,-5.6951,-8.6816,-1.417,524.5671,499.7752,469.6368,47.4062,22.6143,-7.5241,13.9268,-5.6951,-8.726,497.993,20.8321,54.9303,0.5487,-6.3006,-18.3295,-0.4943,-0.0212
1,148.6,148.6,494.91,33870.6,474,0,0.1865,473.3483,26.8667,0,0,0.0528,0.0522,0.0518,0,0,0,51.0981,0,0,100,0,0,0,0,0,0,0,0,0,0,507.6707,-29565.7,-6.0863,-4.7742,0,0,0,0,0,0,0,0,0,0,4.7005,13.8903,7.7641,7.7641,515.3552,42.0069,21.5617,20.4452,1.0413,1.9482,9120.895,14.4363,501.7251,28.3768,10.2226,0,193.5696,31.7843,-0.6517,-0.0155,0,0,1519117,-473.3483,0,0,0,1.52E+08,0,0,54.4038,33.1916,519.2934,499.7453,474.9428,-18.3158,13.8903,-5.7146,-8.671,-2.848,525.8794,499.7453,468.3568,52.5311,26.397,-4.9915,14.0687,-5.7146,-8.8493,497.9939,24.6455,57.5226,0.5457,-10.5241,-19.7776,-0.4952,-0.0273
1,151,151,495.17,33780.58,480,0,0.183,478.9181,27.9171,0,0,0.0528,0.0522,0.0518,0,0,0,52.8743,0,0,100,0,0,0,0,0,0,0,0,0,0,507.7565,-29455.49,1.9064,3.6576,0,0,0,0,0,0,0,0,0,0,4.7281,14.4334,8.1055,8.1055,515.1117,36.1936,16.2519,19.9417,1.0403,2.227,9178.786,15.0259,501.8172,22.8991,9.9709,0,123.6334,26.2228,-1.0819,-0.0299,0,0,1519117,-478.9181,0,0,0,1.52E+08,0,0,54.5743,33.2936,518.8607,499.9391,475.4785,13.9002,14.4334,-6.0181,-8.9542,0.9005,522.9324,499.9391,471.4069,44.0143,21.021,-7.5112,14.4507,-6.0181,-8.9715,498.0928,19.1747,51.5255,0.5537,-5.8598,16.3264,-0.5389,0.0157
1,153.4,153.4,494.65,33546.65,473,0,0.1858,473.2807,27.9221,0,0,0.0528,0.0522,0.0518,0,0,0,52.8656,0,0,100,0,0,0,0,0,0,0,0,0,0,507.5821,-29149.9,6.0109,5.2605,0,0,0,0,0,0,0,0,0,0,4.7262,14.436,8.1072,8.1072,514.8891,41.6084,21.3693,20.2391,1.0409,1.9471,9179.064,15.0288,501.3964,28.1157,10.1196,0,612.44,31.4889,0.2807,0.0067,0,0,1519117,-473.2807,0,0,0,1.52E+08,0,0,54.5697,33.2853,518.6157,499.5495,474.4263,19.9939,14.436,-6.0345,-8.9409,2.8391,526.3192,499.5495,466.7228,53.0385,26.2688,-6.5579,14.6072,-6.0345,-9.1121,497.5305,24.2498,59.5964,0.5508,-8.0877,21.0713,-0.5394,0.0264
1,155.8,155.8,494.78,33480.8,480,0,0.1795,480.1971,28.9916,0,0,0.0528,0.0522,0.0518,0,0,0,54.6211,0,0,100,0,0,0,0,0,0,0,0,0,0,508.178,-29016.57,-1.1879,-3.0321,0,0,0,0,0,0,0,0,0,0,4.7507,14.9889,8.4582,8.4582,514.2138,34.0167,14.5829,19.4338,1.0393,2.3326,9238.765,15.6314,501.2579,21.0608,9.7169,0,321.6249,24.2998,0.1971,0.0058,0,0,1519117,-480.1971,0,0,0,1.52E+08,0,0,54.7445,33.3895,517.2016,499.8558,473.8316,-11.4135,14.9889,-6.3451,-9.2291,-0.5665,520.0219,499.8558,471.0114,39.8248,19.6587,-9.1857,14.9955,-6.3451,-9.2357,496.963,16.7659,49.0105,0.5885,-4.3355,-13.8796,-0.5853,-0.0106
1,158.2,158.2,494.91,33193.2,472,0,0.1857,472.2398,29.0577,0,0,0.0528,0.0522,0.0518,0,0,0,54.7364,0,0,100,0,0,0,0,0,0,0,0,0,0,507.5334,-28719.63,-6.0019,-5.6408,0,0,0,0,0,0,0,0,0,0,4.7599,15.0231,8.48,8.48,515.0023,42.7625,22.6702,20.0923,1.0406,1.8863,9242.482,15.6687,501.6074,29.3676,10.0462,0,190.6526,32.7164,0.2398,0.0056,0,0,1519117,-472.2398,0,0,0,1.52E+08,0,0,54.7503,33.3876,518.8302,499.6919,475.181,-21.2235,15.0231,-6.3789,-9.2331,-2.8636,527.4482,499.6919,466.563,55.2084,27.4521,-5.6768,15.191,-6.3789,-9.401,497.901,25.6612,60.8852,0.5441,-9.7253,-22.1,-0.5889,-0.0255
1,160.6,160.6,494.88,33160.57,480,0,0.1725,482.6456,29.9752,0,0,0.0528,0.0522,0.0518,0,0,0,56.285,0,0,100,0,0,0,0,0,0,0,0,0,0,507.9645,-28599.68,-0.4642,2.1414,0,0,0,0,0,0,0,0,0,0,4.7721,15.4975,8.7841,8.7841,513.4398,30.7942,12.2344,18.5598,1.0375,2.517,9294.37,16.1877,501.0666,18.421,9.2799,0,236.7236,21.5143,2.6456,0.0859,0,0,1519117,-482.6456,0,0,0,1.52E+08,0,0,54.9016,33.4777,516.1345,499.8363,474.4337,7.9901,15.4975,-6.6463,-9.4811,-0.2233,517.613,499.8363,472.9552,34.9674,17.1907,-9.6904,15.4985,-6.6463,-9.4821,496.8015,14.1559,44.6578,0.6019,-3.6085,10.4837,-0.6299,-0.0044
1,163,163,495.09,32870.54,472,0,0.1857,472.4266,30.0993,0,0,0.0528,0.0522,0.0518,0,0,0,56.466,0,0,100,0,0,0,0,0,0,0,0,0,0,507.5787,-28319.89,5.8939,5.9205,0,0,0,0,0,0,0,0,0,0,4.7907,15.5616,8.8253,8.8253,515.0501,42.6235,22.6634,19.9601,1.0403,1.8807,9301.426,16.2579,501.7434,29.3168,9.9801,0,129.7072,32.6435,0.4266,0.01,0,0,1519117,-472.4266,0,0,0,1.52E+08,0,0,54.9175,33.4822,518.8961,499.8202,475.5826,22.0688,15.5616,-6.696,-9.502,2.8385,528.1594,499.8202,466.3194,55.7328,27.3936,-6.1072,15.7213,-6.696,-9.6617,498.0997,25.6731,61.84,0.5417,-9.1258,22.77,-0.6364,0.0246
1,165.4,165.4,494.99,32820.38,483,0,0.1667,483.5017,30.9453,0,0,0.0528,0.0522,0.0518,0,0,0,57.8947,0,0,100,0,0,0,0,0,0,0,0,0,0,507.9096,-28192.8,1.4858,-1.2984,0,0,0,0,0,0,0,0,0,0,4.7948,15.999,9.1083,9.1083,512.8205,29.3188,11.4883,17.8305,1.036,2.5521,9349.859,16.7382,500.9335,17.4318,8.9153,0,181.9834,20.4036,0.5017,0.0171,0,0,1519117,-483.5017,0,0,0,1.52E+08,0,0,55.058,33.5656,515.2061,499.8832,474.8129,-4.8026,15.999,-6.9438,-9.7306,0.7211,515.7693,499.8832,474.2498,32.2676,16.3815,-9.2519,16.0091,-6.9438,-9.7407,496.6341,13.1324,41.5195,0.6174,-3.4877,-6.688,-0.6754,0.0121
1,167.8,167.8,495.02,32579.89,472,0,0.1853,471.9888,31.2174,0,0,0.0528,0.0522,0.0518,0,0,0,58.3412,0,0,100,0,0,0,0,0,0,0,0,0,0,507.7813,-27936.02,-5.8725,-6.0799,0,0,0,0,0,0,0,0,0,0,4.8214,16.1397,9.1998,9.1998,514.8018,42.813,23.0312,19.7818,1.04,1.8589,9365.546,16.893,501.6139,29.6251,9.8909,0,147.3456,32.9221,-0.0112,-0.0003,0,0,1519117,-471.9888,0,0,0,1.52E+08,0,0,55.0996,33.5862,518.3896,499.8528,475.0973,-22.4348,16.1397,-7.0347,-9.7939,-2.857,527.9183,499.8528,465.5685,55.9295,27.864,-6.4203,16.2961,-7.0347,-9.9503,497.7799,25.7911,62.3498,0.5499,-8.7114,-23.0125,-0.6889,-0.0238
1,170.2,170.2,494.98,32505.96,482,0,0.1653,483.7092,31.8189,0,0,0.0528,0.0522,0.0518,0,0,0,59.3345,0,0,100,0,0,0,0,0,0,0,0,0,0,508.003,-27787.17,-3.1048,0.5374,0,0,0,0,0,0,0,0,0,0,4.8183,16.4507,9.4028,9.4028,512.5628,28.8536,11.2708,17.5828,1.0355,2.56,9400.408,17.2357,500.8409,17.1317,8.7914,0,186.4801,20.0622,1.7092,0.0592,0,0,1519117,-483.7092,0,0,0,1.52E+08,0,0,55.1994,33.6443,514.7579,499.9117,474.653,1.9721,16.4507,-7.2145,-9.9542,-1.5188,514.8546,499.9117,474.5563,31.1454,16.2025,-9.1529,16.4943,-7.2145,-9.9978,496.4409,12.7317,40.2983,0.6292,-3.4028,2.8084,-0.718,-0.0187
1,172.6,172.6,494.99,32284.83,472,0,0.1876,472.5498,32.2509,0,0,0.0528,0.0522,0.0518,0,0,0,60.0614,0,0,100,0,0,0,0,0,0,0,0,0,0,508.003,-27560.58,5.6326,6.1746,0,0,0,0,0,0,0,0,0,0,4.8532,16.674,9.5493,9.5493,514.8956,42.3458,22.4402,19.9056,1.0402,1.8871,9425.6,17.4822,501.6252,29.0754,9.9528,0,158.1745,32.393,0.5498,0.013,0,0,1519117,-472.5498,0,0,0,1.52E+08,0,0,55.2693,33.6827,518.4001,499.9175,474.6852,22.571,16.674,-7.3499,-10.0639,2.7661,527.9623,499.9175,465.123,55.4125,27.3677,-7.4268,16.8163,-7.3499,-10.2062,497.6676,25.1178,62.8393,0.5537,-7.4612,22.9601,-0.7398,0.0229
1,175,175,494.8,32207.61,482,0,0.1658,483.6262,32.7341,0,0,0.0528,0.0522,0.0518,0,0,0,60.8253,0,0,100,0,0,0,0,0,0,0,0,0,0,508.0721,-27399.7,3.7015,0.2534,0,0,0,0,0,0,0,0,0,0,4.8436,16.9238,9.7139,9.7139,512.3366,28.7104,11.1738,17.5366,1.0354,2.5694,9453.941,17.7585,500.6455,17.0193,8.7683,0,310.5137,19.9421,1.6262,0.0566,0,0,1519117,-483.6262,0,0,0,1.52E+08,0,0,55.3494,33.7286,514.363,499.8254,474.0954,0.9222,16.9238,-7.4965,-10.1911,1.8258,514.3841,499.8254,474.0743,30.7579,16.1992,-9.5519,16.9851,-7.4965,-10.2524,496.0946,12.4684,40.3098,0.6388,-3.2201,1.3113,-0.7638,0.0197
1,177.4,177.4,495.17,32025.59,472,0,0.1876,472.077,33.3549,0,0,0.0528,0.0522,0.0518,0,0,0,61.8438,0,0,100,0,0,0,0,0,0,0,0,0,0,507.4689,-27199.49,-5.5487,-6.2151,0,0,0,0,0,0,0,0,0,0,4.8871,17.2448,9.9265,9.9265,514.9405,42.8635,23.093,19.7705,1.0399,1.8561,9490.612,18.1142,501.7602,29.6832,9.8853,0,112.9445,32.9783,0.077,0.0018,0,0,1519117,-472.077,0,0,0,1.52E+08,0,0,55.4531,33.7881,518.7936,499.8266,475.989,-22.49,17.2448,-7.6852,-10.3553,-2.7527,528.4374,499.8266,466.3452,56.3604,27.7496,-5.7318,17.3814,-7.6852,-10.4919,498.203,26.1261,62.0922,0.5392,-9.8329,-23.2098,-0.7957,-0.0221
1,179.8,179.8,494.63,31912.47,481,0,0.1733,482.1941,33.6484,0,0,0.0528,0.0522,0.0518,0,0,0,62.3058,0,0,100,0,0,0,0,0,0,0,0,0,0,508.0487,-27009.09,-4.5654,-0.905,0,0,0,0,0,0,0,0,0,0,4.8763,17.3965,10.0274,10.0274,512.8606,30.6665,12.4359,18.2306,1.0369,2.466,9508.041,18.2826,500.7069,18.5128,9.1153,0,823.9817,21.5512,1.1941,0.0389,0,0,1519117,-482.1941,0,0,0,1.52E+08,0,0,55.5006,33.8135,515.1884,499.7101,473.7082,-3.2661,17.3965,-7.7793,-10.4285,-2.2709,515.444,499.7101,473.4526,33.2499,17.516,-8.7415,17.4889,-7.7793,-10.5209,496.2022,14.0081,41.9914,0.6253,-3.8037,-4.4746,-0.8113,-0.0208
1,182.2,182.2,495.43,31784.41,473,0,0.1872,473.1781,34.388,0,0,0.0528,0.0522,0.0518,0,0,0,63.5393,0,0,100,0,0,0,0,0,0,0,0,0,0,507.7978,-26854.81,5.1178,6.1055,0,0,0,0,0,0,0,0,0,0,4.9197,17.7789,10.2829,10.2829,515.0299,41.8518,22.2519,19.5999,1.0396,1.8808,9552.262,18.7079,501.9633,28.7852,9.8,0,81.5419,32.0519,0.1781,0.0043,0,0,1519117,-473.1781,0,0,0,1.52E+08,0,0,55.6267,33.8875,518.7525,500.1121,476.1508,21.8836,17.7789,-8.0003,-10.6287,2.5633,527.9905,500.1121,466.9128,54.8124,26.934,-6.2653,17.8941,-8.0003,-10.7439,498.3385,25.1604,61.0777,0.5436,-8.7486,22.8866,-0.8501,0.0211
1,184.6,184.6,494.79,31625.32,482,0,0.1751,481.494,34.6005,0,0,0.0528,0.0522,0.0518,0,0,0,63.86,0,0,100,0,0,0,0,0,0,0,0,0,0,508.0044,-26659.8,4.7379,1.6301,0,0,0,0,0,0,0,0,0,0,4.9078,17.8888,10.3567,10.3567,513.0973,31.6033,13.296,18.3073,1.037,2.3769,9565.047,18.8303,500.8924,19.3984,9.1537,0,314.2309,22.4497,-0.506,-0.016,0,0,1519117,-481.494,0,0,0,1.52E+08,0,0,55.6604,33.9044,515.5981,499.7923,474.1968,5.8315,17.8888,-8.0713,-10.6792,2.3775,516.4038,499.7923,473.3911,34.9098,18.2983,-8.1029,17.9874,-8.0713,-10.7778,496.5291,15.0351,43.0127,0.6138,-4.3083,7.8664,-0.8617,0.0205
1,187,187,495.14,31543.08,474,0,0.1876,473.5476,35.4861,0,0,0.0528,0.0522,0.0518,0,0,0,65.352,0,0,100,0,0,0,0,0,0,0,0,0,0,507.7339,-26531.5,-4.8746,-5.9225,0,0,0,0,0,0,0,0,0,0,4.9502,18.3467,10.6657,10.6657,514.6441,41.0965,21.5924,19.5041,1.0394,1.9033,9618.687,19.3416,501.6414,28.0938,9.7521,0,120.9095,31.3445,-0.4524,-0.011,0,0,1519117,-473.5476,0,0,0,1.52E+08,0,0,55.8139,33.9955,518.1869,499.9071,475.5174,-21.0115,18.3467,-8.3343,-10.9225,-2.4666,526.7963,499.9071,466.908,53.2487,26.3595,-6.6396,18.4503,-8.3343,-11.0261,497.8705,24.3229,59.8883,0.551,-8.0199,-22.2813,-0.9101,-0.0203
1,189.4,189.4,494.7,31354.88,480,0,0.1805,479.1485,35.6063,0,0,0.0528,0.0522,0.0518,0,0,0,65.4921,0,0,100,0,0,0,0,0,0,0,0,0,0,507.9761,-26301.14,-5.0711,-2.3259,0,0,0,0,0,0,0,0,0,0,4.9425,18.4088,10.7078,10.7078,513.4527,34.3042,15.5515,18.7527,1.0379,2.2058,9626.008,19.4111,500.9509,21.8024,9.3764,0,466.7726,24.9279,-0.8515,-0.0248,0,0,1519117,-479.1485,0,0,0,1.52E+08,0,0,55.831,34.0016,516.172,499.725,474.0211,-8.2432,18.4088,-8.3805,-10.9455,-2.5686,517.7267,499.725,472.4664,38.5782,20.5765,-6.6821,18.5208,-8.3805,-11.0575,496.6394,17.4909,45.2603,0.6023,-5.7734,-10.6809,-0.9172,-0.0204
1,191.8,191.8,494.92,31290.09,475,0,0.1877,475.1807,36.5144,0,0,0.0528,0.0522,0.0518,0,0,0,67.0106,0,0,100,0,0,0,0,0,0,0,0,0,0,507.5055,-26197.11,4.2524,5.6254,0,0,0,0,0,0,0,0,0,0,4.9794,18.8783,11.0277,11.0277,514.3095,39.1288,19.7393,19.3895,1.0392,1.9823,9681.719,19.9373,501.3832,26.2025,9.6948,0,193.2999,29.4341,0.1807,0.0046,0,0,1519117,-475.1807,0,0,0,1.52E+08,0,0,55.9905,34.0968,517.7938,499.6834,475.3197,19.7661,18.8783,-8.6495,-11.1973,2.1726,525.569,499.6834,467.5445,50.3883,24.5027,-7.6362,18.9566,-8.6495,-11.2756,497.599,22.4183,58.0245,0.5539,-6.5986,21.4727,-0.9685,0.0189
1,194.2,194.2,494.73,31085.43,479,0,0.1818,478.3797,36.5846,0,0,0.0528,0.0522,0.0518,0,0,0,67.1052,0,0,100,0,0,0,0,0,0,0,0,0,0,507.6799,-25957.48,5.0314,3.0131,0,0,0,0,0,0,0,0,0,0,4.9738,18.9146,11.0526,11.0526,513.5012,35.1215,16.3503,18.7712,1.0379,2.1481,9686.053,19.9781,500.9871,22.6074,9.3856,0,392.92,25.7359,-0.6203,-0.0177,0,0,1519117,-478.3797,0,0,0,1.52E+08,0,0,55.9987,34.0973,516.4269,499.631,474.5689,10.5813,18.9146,-8.6816,-11.2058,2.572,518.9497,499.631,472.0461,40.57,21.2513,-6.3336,19.024,-8.6816,-11.3152,496.8756,18.4959,46.9036,0.5881,-6.4055,13.4101,-0.9728,0.0199
1,196.6,196.6,495.01,31008.13,474,0,0.1866,475.5008,37.5908,0,0,0.0528,0.0522,0.0518,0,0,0,68.7724,0,0,100,0,0,0,0,0,0,0,0,0,0,507.5935,-25872.36,-3.8946,-5.2909,0,0,0,0,0,0,0,0,0,0,5.0123,19.4348,11.4105,11.4105,514.1562,38.6554,19.5092,19.1462,1.0387,1.9814,9748.595,20.5635,501.3921,25.8913,9.5731,0,157.7253,29.0823,1.5008,0.0388,0,0,1519117,-475.5008,0,0,0,1.52E+08,0,0,56.1776,34.2046,517.5051,499.7722,475.4217,-18.4027,19.4348,-8.9792,-11.487,-2.0101,524.4172,499.7722,468.5096,48.9164,24.2714,-6.9912,19.5,-8.9792,-11.5522,497.5663,22.0655,55.9076,0.5592,-6.9969,-20.5862,-1.0314,-0.0179
1,199,199,494.8,30823.52,475,0,0.184,476.6148,37.6345,0,0,0.0528,0.0522,0.0518,0,0,0,68.839,0,0,100,0,0,0,0,0,0,0,0,0,0,507.8008,-25621.96,-5.1897,-3.6634,0,0,0,0,0,0,0,0,0,0,5.009,19.4574,11.4262,11.4262,513.6735,37.0587,18.1852,18.8735,1.0381,2.0378,9751.33,20.5891,501.0912,24.4764,9.4368,0,284.5446,27.622,1.6148,0.0436,0,0,1519117,-476.6148,0,0,0,1.52E+08,0,0,56.1809,34.2019,516.6276,499.7197,474.5692,-12.7382,19.4574,-9.004,-11.4876,-2.6793,520.1848,499.7197,471.0121,43.57,23.1049,-5.6027,19.573,-9.004,-11.6032,496.9722,20.3574,49.1727,0.5838,-7.7766,-15.6025,-1.0342,-0.0196
1,201.4,201.4,495.22,30797.3,478,0,0.1863,477.3063,38.6075,0,0,0.0528,0.0522,0.0518,0,0,0,70.4186,0,0,100,0,0,0,0,0,0,0,0,0,0,507.8257,-25556.24,3.0399,4.7936,0,0,0,0,0,0,0,0,0,0,5.0457,19.9604,11.7757,11.7757,514.2056,36.8993,17.9137,18.9856,1.0383,2.0598,9812.611,21.1574,501.5486,24.2423,9.4928,0,112.3408,27.4065,-0.6937,-0.0188,0,0,1519117,-477.3063,0,0,0,1.52E+08,0,0,56.356,34.3073,517.4632,499.99,475.6058,16.5127,19.9604,-9.2917,-11.7614,1.5842,523.1931,499.99,469.8759,45.8868,22.6837,-7.4304,19.9999,-9.2917,-11.8009,497.6863,20.38,53.3172,0.5648,-6.1755,19.1367,-1.0927,0.0159
1,201.6,201.6,495.09,30771.69,475,0,0.1873,476.1006,38.6033,0,0,0.0528,0.0522,0.0518,0,0,0,70.4238,0,0,100,0,0,0,0,0,0,0,0,0,0,507.7107,-25536.23,3.6184,5.2376,0,0,0,0,0,0,0,0,0,0,5.0453,19.9583,11.7743,11.7743,514.1784,38.0778,18.9894,19.0884,1.0386,2.0052,9812.354,21.1551,501.4528,25.3522,9.5442,0,136.2679,28.5336,1.1006,0.0289,0,0,1519117,-476.1006,0,0,0,1.52E+08,0,0,56.3549,34.3062,517.4846,499.8657,475.4532,18.043,19.9583,-9.2917,-11.7593,1.8856,524.1675,499.8657,468.7704,48.0669,23.7651,-7.3302,20.0143,-9.2917,-11.8153,497.6012,21.5006,55.3971,0.5613,-6.5574,20.3238,-1.0927,0.0171