File: datas/d100-30-0.25.csv
Stage Number,Time since start of test (s),Time since start of stage (s),Radial Pressure (kPa),Radial Volume (mm3),Back Pressure (kPa),Back Volume (mm3),Load Cell (kN),Pore Pressure (kPa),Axial Displacement (mm),L/C Pressure (kPa),L/C Volume (mm3),Local Axial 1,Local Axial 2,Local Radial,Base Pressure (kPa),Base Volume (mm3),Back Differential Pressure (kPa),Axial Displacement 2 (mm),Pore Air Pressure (kPa),Pore Air Volume (mm3),Atmospheric Pressure (kPa),Temperature (°C),Mid Plane PWP (kPa),Back to Cell Differential (kPa),Total Volume Change (mm3),Undefined Tx 1,Undefined Tx 2,Undefined Tx 3,Undefined Tx. 4,HCA secondary control axial load (kN),HCA secondary control torque,Internal Cell Pr. (kPa),Internal Cell Vol. (mm3),Rotational Displ. (mm),Torque,Local Int Defmn 1 (mm),Local Int Defmn 2 (mm),Circumf. Defmn 1 (mm),Circumf. Defmn 2 (mm),Circumf. Defmn 3 (mm),Outer Cell Pr 2 (kPa),Internal cell Pr 2 (kPa),Rotation 2 (°),Secondary Cell Pr (kPa),Secondary Back Pr (kPa),Axial Force (kN),Axial Strain (%),Av Diameter Change (mm),Radial Strain (%),Axial Stress (kPa),Eff. Axial Stress (kPa),Eff. Radial Stress (kPa),Deviator Stress (kPa),Total Stress Ratio (%),Eff. Stress Ratio (%),Current Area (mm2),Shear Strain (%),Cambridge p (kPa),Eff. Cambridge p' (kPa),Max Shear Stress t,Volume Change (mm3),B Value,Mean Stress s/Eff. Axial Stress 2,Excess PWP (kPa),PWP Ratio,Lower Chamber Displacement (mm),Lower Chamber Axial Load (kPa),Specimen Air Volume (mm3),Matric Suction (kPa),Voids ratio,Degree of Saturation (°),Specimen Water Volume (mm3),kRT constant,Permeability IN,Permeability OUT,HCA Outer Rad,HCA Inner Rad,HCA Sigma Z (kPa),HCA Sigma R (kPa),HCA Sigma Theta (kPa),HCA Tau Theta Z,HCA Ez,HCA Er,HCA Etheta,HCA Gamma,HCA Sigma1,HCA Sigma2,HCA Sigma3,HCA Eff Sigma1,HCA Eff Sigma2,HCA Eff Sigma3,HCA E1,HCA E2,HCA E3,HCA P,HCA Eff P,HCA Q,HCA B,HCA Eff R,HCA Alpha,HCA Ev,HCA E1 rtv
1,0,0,497.5057,123693.5,402,0,0.0884,401.8484,0.0042,0,0,0.0528,0.0522,0.0518,0,0,0,5.1325,0,0,100,0,0,0,0,0,0,0,0,0,0,504.633,39780.64,0.0124,4.3722,0,0,0,0,0,0,0,0,0,0,3.9959,0.0022,0.0011,0.0011,508.763,106.9146,95.6573,11.2573,1.0226,1.1177,7854.148,0.0022,501.2581,99.4097,5.6287,0,-0.2174,101.2859,-0.1516,-0.0014,0,0,1523672,-401.8484,0,0,0,1.52E+08,0,0,49.3435,28.892,511.3736,500.1378,487.4369,21.7403,0.0022,-2.2077,2.2554,0.0045,524.2222,500.1378,474.5883,122.3738,98.2894,72.7399,2.2554,-2.2077,0.0022,499.6494,97.801,49.6339,0.5148,1.6823,30.5833,0.0499,89.999
1,9,9,497.905,123882.7,418,0,0.0934,418.4277,0.129,0,0,0.0528,0.0522,0.0518,0,0,0,5.3706,0,0,100,0,0,0,0,0,0,0,0,0,0,504.1954,39615.38,0.4691,1.4163,0,0,0,0,0,0,0,0,0,0,4.0065,0.0665,0.0333,0.0333,509.7846,91.3569,79.4773,11.8796,1.0239,1.1495,7859.201,0.0665,501.8649,83.4372,5.9398,0,37.7205,85.4171,0.4277,0.0047,0,0,1523672,-418.4277,0,0,0,1.52E+08,0,0,49.3621,28.906,513.1912,500.2281,489.0161,7.035,0.0665,-2.2296,2.2128,0.169,515.0894,500.2281,487.118,96.6617,81.8004,68.6903,2.2194,-2.2296,0.0599,500.8119,82.3841,27.9714,0.4687,1.4072,15.0998,0.0497,89.961
1,18.2,18.2,497.8405,123943.2,427,0,0.0929,426.9427,0.2144,0,0,0.0528,0.0522,0.0518,0,0,0,5.4693,0,0,100,0,0,0,0,0,0,0,0,0,0,504.2286,39550.31,0.7841,-0.2407,0,0,0,0,0,0,0,0,0,0,4.0073,0.1105,0.0553,0.0553,509.6619,82.7192,70.8978,11.8214,1.0237,1.1667,7862.663,0.1105,501.781,74.8383,5.9107,0,66.9276,76.8085,-0.0573,-0.0007,0,0,1523672,-426.9427,0,0,0,1.52E+08,0,0,49.3741,28.9142,512.9677,500.1999,488.8128,-1.1948,0.1105,-2.2478,2.1864,0.2827,513.0267,500.1999,488.7538,86.084,73.2572,61.8111,2.2055,-2.2478,0.0914,500.6601,73.7174,24.2729,0.4716,1.3927,-2.8249,0.0491,89.9336
1,27.4,27.4,497.7091,123941.2,432,0,0.0932,433.171,0.2881,0,0,0.0528,0.0522,0.0518,0,0,0,5.5806,0,0,100,0,0,0,0,0,0,0,0,0,0,504.5194,39570.32,1.0652,-0.7203,0,0,0,0,0,0,0,0,0,0,4.008,0.1485,0.0743,0.0743,509.557,76.386,64.5381,11.8479,1.0238,1.1836,7865.655,0.1485,501.6584,68.4874,5.924,0,128.6477,70.4621,1.171,0.0153,0,0,1523672,-433.171,0,0,0,1.52E+08,0,0,49.3831,28.9191,512.6687,500.2243,488.085,-3.5734,0.1485,-2.2674,2.1683,0.3843,513.1776,500.2243,487.5761,80.0066,67.0533,54.4051,2.2042,-2.2674,0.1126,500.326,67.155,25.6015,0.494,1.4706,-8.1049,0.0494,89.9092
1,36.6,36.6,497.7377,123861.4,437,0,0.0935,437.7332,0.3527,0,0,0.0528,0.0522,0.0518,0,0,0,5.6903,0,0,100,0,0,0,0,0,0,0,0,0,0,505.0288,39704.38,1.5144,0.0754,0,0,0,0,0,0,0,0,0,0,4.0098,0.1818,0.091,0.091,509.6159,71.8827,60.0045,11.8782,1.0239,1.198,7868.279,0.1819,501.6971,63.9639,5.9391,0,131.8959,65.9436,0.7332,0.0102,0,0,1523672,-437.7332,0,0,0,1.52E+08,0,0,49.3891,28.9201,512.5008,500.4304,487.4363,0.3739,0.1818,-2.2913,2.1591,0.5466,512.5064,500.4304,487.4308,74.7732,62.6972,49.6976,2.232,-2.2913,0.1089,500.1225,62.3893,25.0756,0.5184,1.5046,0.8545,0.0496,89.8735
1,45.8,45.8,497.3476,123643.5,438,0,0.0948,439.6554,0.4062,0,0,0.0528,0.0522,0.0518,0,0,0,5.7645,0,0,100,0,0,0,0,0,0,0,0,0,0,504.9057,39994.59,2.1383,1.9283,0,0,0,0,0,0,0,0,0,0,4.0092,0.2094,0.1049,0.1049,509.3987,69.7433,57.6922,12.0511,1.0242,1.2089,7870.456,0.2095,501.3646,61.7092,6.0256,0,-320.0452,63.7178,1.6554,0.0237,0,0,1523672,-439.6554,0,0,0,1.52E+08,0,0,49.3911,28.9159,512.2266,500.1385,486.6737,9.5596,0.2094,-2.3209,2.162,0.772,515.4071,500.1385,483.4932,75.7517,60.4831,43.8378,2.3043,-2.3209,0.0672,499.6796,60.0242,31.9139,0.5216,1.728,18.4023,0.0506,89.8317
1,55,55,497.6787,123327,441,0,0.0922,439.2806,0.4529,0,0,0.0528,0.0522,0.0518,0,0,0,5.84,0,0,100,0,0,0,0,0,0,0,0,0,0,504.544,40367.21,2.8695,4.4023,0,0,0,0,0,0,0,0,0,0,4.0101,0.2335,0.117,0.117,509.39,70.1094,58.3981,11.7113,1.0235,1.2005,7872.357,0.2337,501.5825,62.3019,5.8557,0,175.6868,64.2538,-1.7194,-0.0245,0,0,1523672,-439.2806,0,0,0,1.52E+08,0,0,49.3909,28.9088,512.401,500.2135,487.9889,21.8208,0.2335,-2.3538,2.1715,1.0361,525.1976,500.2135,475.1922,85.917,60.9329,35.9116,2.4173,-2.3538,-0.0123,500.2011,60.9205,50.0054,0.5004,2.3925,30.3892,0.0512,89.7928
1,64.2,64.2,497.916,123049.9,437,0,0.0919,438.3309,0.505,0,0,0.0528,0.0522,0.0518,0,0,0,5.9175,0,0,100,0,0,0,0,0,0,0,0,0,0,504.5315,40682.03,3.5258,6.8485,0,0,0,0,0,0,0,0,0,0,4.0127,0.2603,0.1304,0.1304,509.5834,71.2525,59.5851,11.6674,1.0234,1.1958,7874.472,0.2605,501.8051,63.4742,5.8337,0,81.0013,65.4188,1.3309,0.0187,0,0,1523672,-438.3309,0,0,0,1.52E+08,0,0,49.3923,28.9037,512.7061,500.3582,488.5833,33.9377,0.2603,-2.3847,2.1764,1.2734,536.662,500.3582,464.6274,98.3311,62.0273,26.2965,2.5331,-2.3847,-0.0964,500.5492,62.2183,72.0346,0.496,3.7393,35.2174,0.052,89.7638
1,73.4,73.4,497.9941,122961.9,438,0,0.0934,438.0417,0.57,0,0,0.0528,0.0522,0.0518,0,0,0,6.0306,0,0,100,0,0,0,0,0,0,0,0,0,0,503.7512,40849.77,4.1501,8.7416,0,0,0,0,0,0,0,0,0,0,4.0162,0.2938,0.1472,0.1472,509.8565,71.8148,59.9524,11.8624,1.0238,1.1979,7877.118,0.294,501.9482,63.9065,5.9312,0,68.478,65.8836,0.0417,0.0006,0,0,1523672,-438.0417,0,0,0,1.52E+08,0,0,49.3978,28.9038,513.5237,500.1193,489.8746,43.301,0.2938,-2.4105,2.169,1.4995,546.5856,500.1193,456.8127,108.5439,62.0776,18.771,2.6468,-2.4105,-0.184,501.1725,63.1308,89.7729,0.4824,5.7825,37.3631,0.0523,89.738
1,82.6,82.6,498.3614,123015.4,439,0,0.0937,438.8552,0.6452,0,0,0.0528,0.0522,0.0518,0,0,0,6.1768,0,0,100,0,0,0,0,0,0,0,0,0,0,502.7971,40745.72,4.6492,9.5227,0,0,0,0,0,0,0,0,0,0,4.0209,0.3326,0.1667,0.1667,510.2545,71.3993,59.5062,11.8931,1.0239,1.1999,7880.185,0.3329,502.3258,63.4706,5.9466,0,41.3068,65.4528,-0.1448,-0.002,0,0,1523672,-438.8552,0,0,0,1.52E+08,0,0,49.4092,28.9124,514.6306,499.9988,492.1045,47.1398,0.3326,-2.4238,2.143,1.681,551.8342,499.9988,454.9009,112.979,61.1436,16.0457,2.7319,-2.4238,-0.2563,502.2446,63.3894,96.9333,0.4652,7.0411,38.2812,0.0518,89.7144
1,91.8,91.8,498.3094,123286.5,445,0,0.0946,444.2244,0.7487,0,0,0.0528,0.0522,0.0518,0,0,0,6.3129,0,0,100,0,0,0,0,0,0,0,0,0,0,502.7213,40443.04,4.8514,9.0552,0,0,0,0,0,0,0,0,0,0,4.0235,0.3859,0.1935,0.1935,510.3114,66.087,54.085,12.002,1.0241,1.2219,7884.401,0.3863,502.3101,58.0857,6.001,0,50.2167,60.086,-0.7756,-0.0117,0,0,1523672,-444.2244,0,0,0,1.52E+08,0,0,49.4274,28.9287,514.7581,499.9383,492.0831,44.7827,0.3859,-2.4328,2.098,1.7557,549.6161,499.9383,457.225,105.3917,55.7139,13.0006,2.75,-2.4328,-0.266,502.2598,58.0354,92.3911,0.4623,8.1067,37.8965,0.0512,89.6925
1,101,101,498.3743,123574.5,451,0,0.0959,452.0402,0.8848,0,0,0.0528,0.0522,0.0518,0,0,0,6.5161,0,0,100,0,0,0,0,0,0,0,0,0,0,502.7528,40118.75,4.9518,7.4714,0,0,0,0,0,0,0,0,0,0,4.0281,0.4561,0.2288,0.2288,510.5348,58.4946,46.3341,12.1605,1.0244,1.2625,7889.961,0.4566,502.4278,50.3876,6.0803,0,55.2313,52.4144,1.0402,0.0178,0,0,1523672,-452.0402,0,0,0,1.52E+08,0,0,49.4503,28.9482,515.0832,499.991,492.192,36.9045,0.4561,-2.449,2.0428,1.7943,542.2762,499.991,464.9989,90.236,47.9508,12.9587,2.7458,-2.449,-0.2469,502.422,50.3818,77.2773,0.4528,6.9634,36.3846,0.0499,89.6652
1,110.2,110.2,498.0587,123745.4,460,0,0.0951,460.746,1.0504,0,0,0.0528,0.0522,0.0518,0,0,0,6.7978,0,0,100,0,0,0,0,0,0,0,0,0,0,503.2666,39933.15,5.006,5.0543,0,0,0,0,0,0,0,0,0,0,4.0281,0.5414,0.2718,0.2718,510.0973,49.3513,37.3127,12.0386,1.0242,1.3226,7896.728,0.5421,502.0715,41.3255,6.0193,0,99.3089,43.332,0.746,0.0151,0,0,1523672,-460.746,0,0,0,1.52E+08,0,0,49.4745,28.9658,514.1596,499.9818,490.7032,24.931,0.5414,-2.4804,1.9884,1.8164,529.9833,499.9818,474.8795,69.2373,39.2358,14.1335,2.739,-2.4804,-0.2092,501.6149,40.8689,55.1038,0.4555,4.8988,32.4032,0.0494,89.6311
1,119.4,119.4,497.8862,123650.3,466,0,0.0942,467.2964,1.2298,0,0,0.0528,0.0522,0.0518,0,0,0,7.0516,0,0,100,0,0,0,0,0,0,0,0,0,0,504.0811,40047.95,5.0116,2.5006,0,0,0,0,0,0,0,0,0,0,4.0295,0.6339,0.3185,0.3185,509.8001,42.5037,30.5898,11.9139,1.0239,1.3895,7904.079,0.6349,501.8575,34.5611,5.957,0,155.622,36.5468,1.2964,0.0305,0,0,1523672,-467.2964,0,0,0,1.52E+08,0,0,49.4957,28.9761,513.2777,500.1737,489.1383,12.318,0.6339,-2.5322,1.9474,1.8209,518.4536,500.1737,483.9624,51.1572,32.8773,16.666,2.736,-2.5322,-0.1547,500.8633,33.5668,34.4912,0.47,3.0696,22.7917,0.0491,89.5932
1,128.6,128.6,497.7153,123375.9,469,0,0.0937,470.1352,1.4048,0,0,0.0528,0.0522,0.0518,0,0,0,7.3305,0,0,100,0,0,0,0,0,0,0,0,0,0,504.7011,40389.73,5.2339,0.4634,0,0,0,0,0,0,0,0,0,0,4.0313,0.7241,0.364,0.364,509.5648,39.4296,27.5801,11.8495,1.0238,1.4296,7911.26,0.7254,501.6651,31.5299,5.9248,0,273.5465,33.5049,1.1352,0.0288,0,0,1523672,-470.1352,0,0,0,1.52E+08,0,0,49.5124,28.9795,512.5812,500.2945,487.8558,2.28,0.7241,-2.5954,1.9213,1.9039,512.7897,500.2945,487.6473,42.6545,30.1593,17.5121,2.796,-2.5954,-0.1506,500.2438,30.1086,25.1424,0.503,2.4357,5.2247,0.05,89.546
1,137.8,137.8,497.5274,122987.9,471,0,0.0953,472.1135,1.5908,0,0,0.0528,0.0522,0.0518,0,0,0,7.6221,0,0,100,0,0,0,0,0,0,0,0,0,0,504.7883,40910.31,5.661,-0.6116,0,0,0,0,0,0,0,0,0,0,4.0352,0.82,0.4125,0.4125,509.5651,37.4516,25.4139,12.0377,1.0242,1.4737,7918.91,0.8217,501.5399,29.4264,6.0189,0,1138.557,31.4328,1.1135,0.0297,0,0,1523672,-472.1135,0,0,0,1.52E+08,0,0,49.5276,28.9786,512.5517,500.2076,487.288,-3.0057,0.82,-2.6717,1.9028,2.0617,512.9044,500.2076,486.9353,40.7909,28.0941,14.8218,2.9165,-2.6717,-0.1937,500.0158,27.9023,25.9691,0.5111,2.7521,-6.6922,0.0511,89.4832
1,147,147,497.2462,122463.4,471,0,0.0906,473.5251,1.7593,0,0,0.0528,0.0522,0.0518,0,0,0,7.8912,0,0,100,0,0,0,0,0,0,0,0,0,0,505.2226,41555.26,6.5114,-0.4652,0,0,0,0,0,0,0,0,0,0,4.0317,0.9069,0.4566,0.4566,508.677,35.1519,23.7211,11.4308,1.023,1.4819,7925.854,0.909,501.0565,27.5314,5.7154,0,-326.4865,29.4365,2.5251,0.0718,0,0,1523672,-473.5251,0,0,0,1.52E+08,0,0,49.5386,28.9729,510.9602,500.1897,486.0091,-2.284,0.9069,-2.7507,1.8959,2.3737,511.1675,500.1897,485.8018,37.6424,26.6646,12.2767,3.1512,-2.7507,-0.3484,499.053,25.5279,25.3657,0.5672,3.0662,-5.1874,0.0521,89.4074
1,156.2,156.2,497.4846,121781.6,470,0,0.0885,471.4473,1.8458,0,0,0.0528,0.0522,0.0519,0,0,0,8.0326,0,0,100,0,0,0,0,0,0,0,0,0,0,505.4043,42345.82,8.2047,0.8995,0,0,0,0,0,0,0,0,0,0,4.0333,0.9514,0.4791,0.4791,508.6503,37.203,26.0373,11.1657,1.0224,1.4288,7929.416,0.9537,501.2065,29.7592,5.5829,0,3683.897,31.6202,1.4473,0.0389,0,0,1523672,-471.4473,0,0,0,1.52E+08,0,0,49.5365,28.9568,510.8127,500.4062,486.3411,4.4151,0.9514,-2.8168,1.9195,2.9918,511.5849,500.4062,485.5689,40.1376,28.9589,14.1216,3.6056,-2.8168,-0.7347,499.1867,27.7394,26.016,0.5703,2.8423,9.9206,0.0541,89.3553
1,165.4,165.4,497.3607,121130.6,465,0,0.0894,464.4802,1.9209,0,0,0.0528,0.0522,0.0518,0,0,0,8.1924,0,0,100,0,0,0,0,0,0,0,0,0,0,505.5518,43180.13,9.9748,3.1372,0,0,0,0,0,0,0,0,0,0,4.0347,0.9902,0.4988,0.4988,508.6276,44.1474,32.8805,11.2669,1.0227,1.3427,7932.523,0.9927,501.1163,36.6361,5.6335,0,-596.3481,38.514,-0.5198,-0.0118,0,0,1523672,-464.4802,0,0,0,1.52E+08,0,0,49.5322,28.9386,510.7254,500.3814,485.8504,15.3963,0.9902,-2.8824,1.9487,3.6378,518.0803,500.3814,478.4955,53.6001,35.9012,14.0153,4.086,-2.8824,-1.1471,498.9857,34.5055,39.5848,0.5529,3.8244,25.5339,0.0565,89.3205
1,174.6,174.6,497.6348,120562,458,0,0.0952,457.8492,2.0844,0,0,0.0528,0.0522,0.0518,0,0,0,8.4479,0,0,100,0,0,0,0,0,0,0,0,0,0,504.5396,43920.17,11.3784,5.7241,0,0,0,0,0,0,0,0,0,0,4.0461,1.0744,0.5416,0.5416,509.631,51.7818,39.7856,11.9962,1.0241,1.3015,7939.274,1.0773,501.6335,43.7843,5.9981,0,331.1225,45.7837,-0.1508,-0.0029,0,0,1523672,-457.8492,0,0,0,1.52E+08,0,0,49.5409,28.9297,512.7978,500.1803,487.9432,28.067,1.0744,-2.9654,1.949,4.1534,531.0657,500.1803,469.6753,73.2165,42.3311,11.8261,4.481,-2.9654,-1.4576,500.3071,42.4579,61.3904,0.4969,6.1911,33.0588,0.058,89.2371
1,183.8,183.8,498.0783,120136.8,453,0,0.0928,453.755,2.3157,0,0,0.0528,0.0522,0.0518,0,0,0,8.835,0,0,100,0,0,0,0,0,0,0,0,0,0,503.6837,44467.16,12.617,7.9084,0,0,0,0,0,0,0,0,0,0,4.052,1.1937,0.6022,0.6022,509.7586,56.0036,44.3233,11.6803,1.0235,1.2635,7948.86,1.1973,501.9718,48.2168,5.8402,0,84.7161,50.1635,0.755,0.0135,0,0,1523672,-453.755,0,0,0,1.52E+08,0,0,49.5617,28.9315,513.4225,500.1444,490.2174,38.7181,1.1937,-3.0547,1.9197,4.6125,542.2391,500.1444,461.4008,88.4841,46.3894,7.6458,4.8384,-3.0547,-1.725,501.2614,47.5064,80.8383,0.4793,11.5729,36.6591,0.0587,89.0652
1,193,193,498.2912,120026,452,0,0.0935,452.1764,2.5981,0,0,0.0528,0.0522,0.0518,0,0,0,9.3203,0,0,100,0,0,0,0,0,0,0,0,0,0,502.5206,44627.71,13.7644,9.2762,0,0,0,0,0,0,0,0,0,0,4.0602,1.3392,0.6764,0.6764,510.038,57.8616,46.1148,11.7468,1.0236,1.2547,7960.583,1.3437,502.2068,50.0304,5.8734,0,60.9561,51.9882,0.1764,0.003,0,0,1523672,-452.1764,0,0,0,1.52E+08,0,0,49.5955,28.9482,514.4579,499.85,492.3614,45.3183,1.3392,-3.135,1.8541,5.0427,550.0552,499.85,456.764,97.8788,47.6736,4.5876,5.1717,-3.135,-1.9784,502.2231,50.0467,93.2912,0.4618,21.3355,38.1495,0.0583,88.6648
1,202.2,202.2,498.2961,120086.2,452,0,0.0951,453.8477,2.9436,0,0,0.0528,0.0522,0.0518,0,0,0,9.874,0,0,100,0,0,0,0,0,0,0,0,0,0,502.217,44614.12,14.6123,9.424,0,0,0,0,0,0,0,0,0,0,4.069,1.5173,0.7674,0.7674,510.2207,56.373,44.4484,11.9246,1.0239,1.2683,7974.979,1.5231,502.271,48.4233,5.9623,0,62.6081,50.4107,1.8477,0.0328,0,0,1523672,-453.8477,0,0,0,1.52E+08,0,0,49.6405,28.9747,514.9025,499.7412,492.7988,45.9156,1.5173,-3.2217,1.7615,5.3679,551.0776,499.7412,456.6237,97.2299,45.8935,2.776,5.437,-3.2217,-2.1582,502.4808,48.6331,94.4539,0.4565,35.0252,38.2332,0.0571,87.1609
1,211.4,211.4,498.5364,120201,458,0,0.0974,460.3141,3.3781,0,0,0.0528,0.0522,0.0518,0,0,0,10.6297,0,0,100,0,0,0,0,0,0,0,0,0,0,502.4103,44538.08,15.0171,8.3446,0,0,0,0,0,0,0,0,0,0,4.0823,1.7413,0.8822,0.8822,510.7242,50.4101,38.2223,12.1878,1.0244,1.3189,7993.16,1.749,502.599,42.2849,6.0939,0,54.5965,44.3162,2.3141,0.0459,0,0,1523672,-460.3141,0,0,0,1.52E+08,0,0,49.6984,29.0099,515.574,499.9642,493.1043,40.5161,1.7413,-3.3279,1.6411,5.5357,546.3841,499.9642,462.2942,86.07,39.6501,1.9801,5.6059,-3.3279,-2.2235,502.8808,42.5667,84.0899,0.448,43.4675,37.2508,0.0545,6.9465
1,220.6,220.6,498.0465,120216.4,471,0,0.0975,469.2433,3.8946,0,0,0.0528,0.0522,0.0518,0,0,0,11.4494,0,0,100,0,0,0,0,0,0,0,0,0,0,502.5004,44561.41,15.1032,6.2876,0,0,0,0,0,0,0,0,0,0,4.0893,2.0075,1.0191,1.0191,510.2139,40.9706,28.8032,12.1674,1.0244,1.4224,8014.874,2.0177,502.1023,32.859,6.0837,0,116.021,34.8869,-1.7567,-0.0429,0,0,1523672,-469.2433,0,0,0,1.52E+08,0,0,49.7654,29.0486,514.7524,499.6881,491.8014,30.4051,2.0075,-3.46,1.5048,5.59,535.7755,499.6881,470.7783,66.5322,30.4448,1.535,5.7169,-3.46,-2.2046,502.0807,32.8373,64.9972,0.4448,43.3435,34.6612,0.0523,1.3863
1,229.8,229.8,498.0575,119990.6,477,0,0.0975,478.2539,4.4731,0,0,0.0528,0.0522,0.0518,0,0,0,12.4073,0,0,100,0,0,0,0,0,0,0,0,0,0,504.0957,44847.8,14.7929,3.7637,0,0,0,0,0,0,0,0,0,0,4.1016,2.3057,1.1732,1.1732,510.1913,31.9374,19.8036,12.1338,1.0244,1.6127,8039.338,2.3193,502.1021,23.8482,6.0669,0,129.093,25.8705,1.2539,0.0393,0,0,1523672,-478.2539,0,0,0,1.52E+08,0,0,49.8365,29.0847,513.8885,500.2828,489.5947,18.1199,2.3057,-3.6228,1.3669,5.4994,523.5562,500.2828,479.9269,45.3023,22.0289,1.673,5.7532,-3.6228,-2.0806,501.2553,23.0014,43.6293,0.4666,27.0785,28.0818,0.0498,0.7408
1,239,239,497.4359,119515.8,482,0,0.0941,483.6153,4.9916,0,0,0.0528,0.0522,0.0518,0,0,0,13.1766,0,0,100,0,0,0,0,0,0,0,0,0,0,504.793,45486.01,14.1774,1.32,0,0,0,0,0,0,0,0,0,0,4.1041,2.573,1.3119,1.3119,509.1055,25.4902,13.8206,11.6696,1.0235,1.8444,8061.395,2.5899,501.3258,17.7105,5.8348,0,-2744.931,19.6554,1.6153,0.0634,0,0,1523672,-483.6153,0,0,0,1.52E+08,0,0,49.8941,29.1061,511.8796,500.1465,487.1349,6.331,2.573,-3.7906,1.2656,5.2906,513.4053,500.1465,485.6092,29.79,16.5312,1.9939,5.717,-3.7906,-1.8784,499.7203,16.105,27.7961,0.523,14.9406,13.5495,0.048,0.5293
1,248.2,248.2,497.6897,118970.5,483,0,0.0932,483.5157,5.4593,0,0,0.0528,0.0522,0.0518,0,0,0,13.9127,0,0,100,0,0,0,0,0,0,0,0,0,0,504.5426,46201.8,14.6857,-0.2177,0,0,0,0,0,0,0,0,0,0,4.1152,2.8141,1.4375,1.4375,509.2191,25.7034,14.174,11.5294,1.0232,1.8134,8081.394,2.8344,501.5328,18.0171,5.7647,0,364.5489,19.9387,0.5157,0.0201,0,0,1523672,-483.5157,0,0,0,1.52E+08,0,0,49.9438,29.1214,512.1794,500.2138,488.1055,-1.0407,2.8141,-3.9496,1.1823,5.4986,512.2243,500.2138,488.0606,28.7086,16.6981,4.5449,5.971,-3.9496,-1.9746,500.1663,16.6505,24.1637,0.503,6.3167,-2.4707,0.0468,0.4262
1,257.4,257.4,497.7099,118427.9,483,0,0.0904,483.7078,5.9416,0,0,0.0528,0.0522,0.0518,0,0,0,14.7045,0,0,100,0,0,0,0,0,0,0,0,0,0,504.5645,46913.55,15.7492,-0.7126,0,0,0,0,0,0,0,0,0,0,4.1229,3.0627,1.5674,1.5674,508.8669,25.1591,14.0021,11.157,1.0224,1.7968,8102.119,3.0867,501.4289,17.7211,5.5785,0,335.1767,19.5806,0.7078,0.0281,0,0,1523672,-483.7078,0,0,0,1.52E+08,0,0,49.9958,29.1381,511.6176,500.2339,488.134,-3.3946,3.0627,-4.1122,1.0945,5.9172,512.0984,500.2339,487.6531,28.3906,16.5261,3.9453,6.3769,-4.1122,-2.2197,499.9951,16.2873,24.4453,0.5147,7.1961,-8.0624,0.045,0.3565
1,266.6,266.6,497.5372,117713.3,482,0,0.08,483.7499,6.2236,0,0,0.0528,0.0522,0.0518,0,0,0,15.1723,0,0,100,0,0,0,0,0,0,0,0,0,0,505.1355,47708.51,18.5523,0.1203,0,0,0,0,0,0,0,0,0,0,4.1172,3.208,1.6437,1.6437,507.4017,23.6518,13.7873,9.8645,1.0198,1.7155,8114.281,3.2345,500.8253,17.0754,4.9323,0,1145.311,18.7196,1.7499,0.074,0,0,1523672,-483.7499,0,0,0,1.52E+08,0,0,50.0198,29.1368,509.0399,500.334,486.9358,0.572,3.208,-4.2283,1.0655,6.9832,509.0547,500.334,486.921,25.3048,16.5841,3.1711,7.1895,-4.2283,-2.916,498.7699,15.02,22.1337,0.606,7.9798,1.4814,0.0452,0.3334
1,275.8,275.8,497.4385,116941.5,476,0,0.083,477.9834,6.3287,0,0,0.0528,0.0522,0.0518,0,0,0,15.3464,0,0,100,0,0,0,0,0,0,0,0,0,0,505.113,48661.09,22.1584,1.9879,0,0,0,0,0,0,0,0,0,0,4.1216,3.2622,1.6721,1.6721,507.6595,29.6761,19.4551,10.221,1.0205,1.5254,8118.828,3.2895,500.8455,22.8621,5.1105,0,-2799.671,24.5656,1.9834,0.0668,0,0,1523672,-477.9834,0,0,0,1.52E+08,0,0,50.0177,29.1173,509.4782,500.2623,486.7468,9.4493,3.2622,-4.3081,1.0931,8.3433,512.8932,500.2623,483.3318,34.9098,22.2789,5.3484,8.1761,-4.3081,-3.8208,498.8291,20.8457,29.5614,0.5727,6.5271,19.8698,0.0472,0.3346
1,285,285,497.5902,116231.3,472,0,0.0901,468.3209,6.6672,0,0,0.0528,0.0522,0.0518,0,0,0,15.8921,0,0,100,0,0,0,0,0,0,0,0,0,0,504.8981,49548.01,24.3862,4.4009,0,0,0,0,0,0,0,0,0,0,4.1372,3.4367,1.7639,1.7639,508.6618,40.3409,29.2693,11.0716,1.0223,1.3783,8133.499,3.4671,501.2808,32.9599,5.5358,0,533.7956,34.8051,-3.6791,-0.0912,0,0,1523672,-468.3209,0,0,0,1.52E+08,0,0,50.0478,29.1177,511.1597,500.2781,487.4236,20.8726,3.4367,-4.4438,1.0541,9.2027,523.3024,500.2781,475.2809,54.9815,31.9572,6.96,8.8608,-4.4438,-4.37,499.6205,31.2996,48.0215,0.5205,7.8996,30.1888,0.047,0.3069
1,294.2,294.2,497.7757,115679.2,460,0,0.0919,461.4648,7.1636,0,0,0.0528,0.0522,0.0518,0,0,0,16.7547,0,0,100,0,0,0,0,0,0,0,0,0,0,504.5893,50233.59,26.0327,6.8451,0,0,0,0,0,0,0,0,0,0,4.1513,3.6926,1.8991,1.8991,509.0427,47.5779,36.3109,11.267,1.0226,1.3103,8155.111,3.7278,501.5314,40.0666,5.6335,0,192.2845,41.9444,1.4648,0.0308,0,0,1523672,-461.4648,0,0,0,1.52E+08,0,0,50.1026,29.1363,511.9019,500.2811,488.3071,32.3476,3.6926,-4.6088,0.9605,9.8597,534.5363,500.2811,465.6727,73.0715,38.8163,4.2079,9.431,-4.6088,-4.7779,500.1634,38.6986,68.8636,0.5026,17.3653,34.9814,0.0443,0.269
1,303.4,303.4,497.9446,115390.6,457,0,0.0931,457.9492,7.7247,0,0,0.0528,0.0522,0.0518,0,0,0,17.6287,0,0,100,0,0,0,0,0,0,0,0,0,0,503.2373,50600.74,27.4995,8.7472,0,0,0,0,0,0,0,0,0,0,4.1661,3.9818,2.0524,2.0524,509.3235,51.3743,39.9954,11.3789,1.0229,1.2845,8179.673,4.0228,501.7375,43.7883,5.6895,0,117.1239,45.6849,0.9492,0.0185,0,0,1523672,-457.9492,0,0,0,1.52E+08,0,0,50.1717,29.1694,513.0263,499.8904,490.5937,41.1584,3.9818,-4.7723,0.8305,10.4603,544.4694,499.8904,459.1507,86.5202,41.9412,1.2015,9.9687,-4.7723,-5.1564,501.1702,43.221,85.3187,0.4775,72.0102,37.3781,0.04,0.2341
1,312.6,312.6,498.0655,115356.1,457,0,0.0943,457.2682,8.332,0,0,0.0528,0.0522,0.0518,0,0,0,18.6844,0,0,100,0,0,0,0,0,0,0,0,0,0,502.477,50655.75,28.734,9.4519,0,0,0,0,0,0,0,0,0,0,4.1816,4.2948,2.2191,2.2191,509.552,52.2838,40.7973,11.4865,1.0231,1.2816,8206.425,4.3426,501.8943,44.6261,5.7433,0,92.3838,46.5406,0.2682,0.0051,0,0,1523672,-457.2682,0,0,0,1.52E+08,0,0,50.2528,29.2155,513.7679,499.6873,491.9391,44.2581,4.2948,-4.9308,0.6691,10.9832,548.4375,499.6873,457.2695,91.1693,42.4191,0.0013,10.457,-4.9308,-5.4931,501.7981,44.5299,91.168,0.4653,70130.23,38.0734,0.0331,0.2041
1,321.8,321.8,498.5542,115541.1,460,0,0.0972,460.7657,9.0334,0,0,0.0528,0.0522,0.0518,0,0,0,19.8465,0,0,100,0,0,0,0,0,0,0,0,0,0,502.4034,50503.5,29.4403,9.0316,0,0,0,0,0,0,0,0,0,0,4.2041,4.6564,2.4128,2.4128,510.3582,49.5925,37.7885,11.804,1.0237,1.3124,8237.548,4.7128,502.4889,41.7232,5.902,0,54.119,43.6905,0.7657,0.0154,0,0,1523672,-460.7657,0,0,0,1.52E+08,0,0,50.3506,29.2753,515.0253,499.9694,493.2074,42.0472,4.6564,-5.1022,0.4698,11.3182,547.5557,499.9694,460.6771,86.79,39.2037,-0.0886,10.8355,-5.1022,-5.7093,502.7341,41.9684,86.8786,0.4523,-979.5711,37.7278,0.024,0.1771
1,331,331,498.1649,115660.1,467,0,0.0992,468.5114,9.8386,0,0,0.0528,0.0522,0.0518,0,0,0,21.1451,0,0,100,0,0,0,0,0,0,0,0,0,0,502.7296,50438.47,29.5797,7.3996,0,0,0,0,0,0,0,0,0,0,4.2208,5.0714,2.6364,2.6364,510.1552,41.6438,29.6535,11.9903,1.0241,1.4043,8273.561,5.1385,502.1617,33.6503,5.9952,0,95.331,35.6487,1.5114,0.0363,0,0,1523672,-468.5114,0,0,0,1.52E+08,0,0,50.4616,29.3411,514.5677,499.8432,491.8234,34.2236,5.0714,-5.3053,0.2472,11.4468,539.2591,499.8432,467.132,70.7477,31.3318,-1.3794,11.1052,-5.3053,-5.7866,502.0781,33.5667,72.1271,0.4535,-51.2888,35.8094,0.0133,0.1538
1,340.2,340.2,498.1037,115602.1,471,0,0.1007,477.7627,10.7168,0,0,0.0528,0.0522,0.0518,0,0,0,22.6017,0,0,100,0,0,0,0,0,0,0,0,0,0,503.4907,50531.15,29.1723,5.062,0,0,0,0,0,0,0,0,0,0,4.2415,5.5241,2.882,2.882,510.2124,32.4497,20.341,12.1087,1.0243,1.5953,8313.205,5.6041,502.1399,24.3772,6.0544,0,118.9742,26.3954,6.7627,0.2084,0,0,1523672,-477.7627,0,0,0,1.52E+08,0,0,50.5808,29.4086,514.2796,500.0843,490.621,23.2459,5.5241,-5.5365,0.0133,11.3698,528.533,500.0843,476.3677,50.7703,22.3216,-1.395,11.2674,-5.5365,-5.73,501.6617,23.899,52.1653,0.4546,-36.3945,31.5148,0.0009,0.1346
1,349.4,349.4,497.7531,115251.2,484,0,0.0947,485.4207,11.5617,0,0,0.0528,0.0522,0.0518,0,0,0,23.9259,0,0,100,0,0,0,0,0,0,0,0,0,0,504.5052,50920.31,27.9967,2.4001,0,0,0,0,0,0,0,0,0,0,4.2518,5.9596,3.12,3.12,509.0938,23.6731,12.3324,11.3407,1.0228,1.9196,8351.703,6.0531,501.5334,16.1127,5.6704,0,290.7424,18.0028,1.4207,0.06,0,0,1523672,-485.4207,0,0,0,1.52E+08,0,0,50.6911,29.4651,512.0248,500.2351,488.3802,10.9479,5.9596,-5.7759,-0.1949,10.9852,516.3153,500.2351,484.0897,30.8946,14.8144,-1.331,11.2374,-5.7759,-5.4727,500.2134,14.7927,32.2256,0.501,-23.2116,21.4004,-0.0112,0.1202
1,358.6,358.6,497.7405,114837.3,485,0,0.092,486.6163,12.1885,0,0,0.0528,0.0522,0.0518,0,0,0,24.9052,0,0,100,0,0,0,0,0,0,0,0,0,0,504.563,51452.91,27.4729,0.4068,0,0,0,0,0,0,0,0,0,0,4.2633,6.2827,3.2976,3.2976,508.7169,22.1006,11.1242,10.9764,1.0221,1.9867,8380.496,6.3869,501.3993,14.783,5.4882,0,308.4276,16.6124,1.6163,0.0731,0,0,1523672,-486.6163,0,0,0,1.52E+08,0,0,50.7692,29.5,511.4158,500.2479,488.2778,1.8466,6.2827,-5.9673,-0.3354,10.8324,511.5623,500.2479,488.1313,24.946,13.6316,1.515,11.3175,-5.9673,-5.3702,499.9805,13.3642,23.431,0.5171,16.466,4.5344,-0.02,0.1117
1,367.8,367.8,497.5806,114381.4,485,0,0.0956,485.961,12.869,0,0,0.0528,0.0522,0.0518,0,0,0,26.051,0,0,100,0,0,0,0,0,0,0,0,0,0,504.4983,52037.92,28.4299,-0.576,0,0,0,0,0,0,0,0,0,0,4.2812,6.6335,3.4914,3.4914,508.9405,22.9795,11.6196,11.3599,1.0228,1.9777,8411.984,6.7499,501.3672,15.4062,5.68,0,731.9833,17.2996,0.961,0.0418,0,0,1523672,-485.961,0,0,0,1.52E+08,0,0,50.8544,29.538,511.8159,500.1223,487.9948,-2.6007,6.6335,-6.1755,-0.4881,11.2695,512.0965,500.1223,487.7142,26.1355,14.1613,1.7532,11.8008,-6.1755,-5.6554,499.9777,14.0167,24.3823,0.5089,14.9073,-6.1587,-0.0301,0.1041
1,377,377,497.6392,113931.5,485,0,0.0868,486.0594,13.4663,0,0,0.0528,0.0522,0.0518,0,0,0,27.0188,0,0,100,0,0,0,0,0,0,0,0,0,0,504.7868,52565.14,30.4172,-0.4785,0,0,0,0,0,0,0,0,0,0,4.2868,6.9414,3.6625,3.6625,507.9257,21.8663,11.5798,10.2865,1.0207,1.8883,8439.816,7.0693,501.068,15.0086,5.1433,0,485.337,16.7231,1.0594,0.0484,0,0,1523672,-486.0594,0,0,0,1.52E+08,0,0,50.9293,29.5711,510.0736,500.2648,487.743,-2.1504,6.9414,-6.3591,-0.6216,12.1138,510.2788,500.2648,487.5378,24.2194,14.2054,1.4784,12.5232,-6.3591,-6.2034,499.3605,13.3011,22.741,0.5596,16.3822,-5.4507,-0.0393,0.0984
1,386.2,386.2,497.6665,113352.6,482,0,0.0743,485.649,13.6747,0,0,0.0528,0.0522,0.0518,0,0,0,27.3873,0,0,100,0,0,0,0,0,0,0,0,0,0,504.9959,53195,35.135,1.0738,0,0,0,0,0,0,0,0,0,0,4.2794,7.0488,3.7224,3.7224,506.4637,20.8147,12.0175,8.7972,1.0177,1.732,8449.568,7.1808,500.5989,14.9499,4.3986,0,417.2786,16.4161,3.649,0.1753,0,0,1523672,-485.649,0,0,0,1.52E+08,0,0,50.9478,29.5694,507.6832,500.3582,487.5289,4.8191,7.0488,-6.4476,-0.6423,14.0122,508.7762,500.3582,486.4359,23.1272,14.7092,0.7869,13.8315,-6.4476,-7.425,498.5234,12.8744,22.3403,0.6232,29.3903,12.779,-0.0411,0.0975
1,395.4,395.4,497.7067,112803.4,476,0,0.0863,477.3613,13.9673,0,0,0.0528,0.0522,0.0518,0,0,0,27.8516,0,0,100,0,0,0,0,0,0,0,0,0,0,505.2325,53918.84,38.3886,3.1752,0,0,0,0,0,0,0,0,0,0,4.2985,7.1996,3.8066,3.8066,507.8989,30.5376,20.3454,10.1922,1.0205,1.501,8463.299,7.3375,501.1041,23.7428,5.0961,0,313.299,25.4415,1.3613,0.0446,0,0,1523672,-477.3613,0,0,0,1.52E+08,0,0,50.9767,29.5718,509.8223,500.4696,487.3095,14.2206,7.1996,-6.5634,-0.681,15.3412,516.7024,500.4696,480.4294,39.3411,23.1083,3.0681,14.8006,-6.5634,-8.282,499.2005,21.8392,36.273,0.5525,12.8226,25.8182,-0.0448,0.0955
1,404.6,404.6,497.5067,112398.1,470,0,0.0916,468.7449,14.5756,0,0,0.0528,0.0522,0.0518,0,0,0,28.8334,0,0,100,0,0,0,0,0,0,0,0,0,0,504.8929,54427.61,40.2482,5.6882,0,0,0,0,0,0,0,0,0,0,4.3164,7.5132,3.9825,3.9825,508.2905,39.5456,28.7618,10.7838,1.0217,1.3749,8491.995,7.6638,501.1013,32.3564,5.3919,0,1630.789,34.1537,-1.2551,-0.0317,0,0,1523672,-468.7449,0,0,0,1.52E+08,0,0,51.0541,29.6066,510.6184,500.2179,487.3107,25.3535,7.5132,-6.749,-0.8191,16.1618,526.8682,500.2179,471.0609,58.1233,31.473,2.316,15.5109,-6.749,-8.8168,499.3824,30.6374,55.8073,0.5225,25.0964,32.657,-0.0549,0.0906
1,413.8,413.8,497.9814,112098.7,464,0,0.0932,463.4122,15.2893,0,0,0.0528,0.0522,0.0518,0,0,0,30.019,0,0,100,0,0,0,0,0,0,0,0,0,0,503.583,54783.73,41.7702,7.9164,0,0,0,0,0,0,0,0,0,0,4.3389,7.8811,4.1899,4.1899,508.9076,45.4954,34.5692,10.9262,1.0219,1.3161,8525.91,8.0473,501.6234,38.2112,5.4631,0,119.3584,40.0323,-0.5878,-0.0129,0,0,1523672,-463.4122,0,0,0,1.52E+08,0,0,51.1498,29.655,512.2255,500.0372,490.2533,35.0813,7.8811,-6.9542,-0.996,16.8704,538.0007,500.0372,464.4781,74.5885,36.625,1.0659,16.1707,-6.9542,-9.2856,500.8386,37.4265,73.5226,0.4836,69.977,36.3057,-0.0691,0.0851
1,423,423,498.2156,112140.8,460,0,0.0938,460.9717,16.046,0,0,0.0528,0.0522,0.0518,0,0,0,31.2183,0,0,100,0,0,0,0,0,0,0,0,0,0,502.4635,54782.89,43.1561,9.2489,0,0,0,0,0,0,0,0,0,0,4.3596,8.2711,4.4112,4.4112,509.1706,48.1989,37.2439,10.955,1.022,1.2941,8562.16,8.4549,501.8673,40.8956,5.4775,0,78.8291,42.7214,0.9717,0.0202,0,0,1523672,-460.9717,0,0,0,1.52E+08,0,0,51.2584,29.718,513.1823,499.7746,492.355,40.7263,8.2711,-7.1512,-1.2058,17.5414,544.8053,499.7746,460.7321,83.8336,38.8029,-0.2396,16.8106,-7.1512,-9.7453,501.7706,40.799,84.0732,0.4644,-349.8898,37.8284,-0.0859,0.0799
1,432.2,432.2,498.5432,112371.4,461,0,0.0953,462.0811,16.8704,0,0,0.0528,0.0522,0.0518,0,0,0,32.5341,0,0,100,0,0,0,0,0,0,0,0,0,0,502.362,54548.76,44.1457,9.4356,0,0,0,0,0,0,0,0,0,0,4.3838,8.6961,4.6539,4.6539,509.6248,47.5437,36.4621,11.0816,1.0222,1.3039,8602.015,8.9,502.2371,40.156,5.5408,0,55.8916,42.0029,1.0811,0.0227,0,0,1523672,-462.0811,0,0,0,1.52E+08,0,0,51.3817,29.7942,513.9194,499.9448,493.2727,41.2548,8.6961,-7.3538,-1.4486,18.0714,546.1229,499.9448,461.0692,84.0418,37.8637,-1.0119,17.3721,-7.3538,-10.1246,502.379,40.2979,85.0537,0.4571,-83.0535,37.9756,-0.1063,0.0747
1,441.4,441.4,498.3077,112681.2,468,0,0.0997,467.323,17.805,0,0,0.0528,0.0522,0.0518,0,0,0,34.0261,0,0,100,0,0,0,0,0,0,0,0,0,0,502.5866,54187.62,44.4674,8.3638,0,0,0,0,0,0,0,0,0,0,4.4089,9.1778,4.931,4.931,509.8386,42.5156,30.9847,11.5309,1.0231,1.3721,8647.638,9.4059,502.1513,34.8283,5.7655,0,77.7495,36.7502,-0.677,-0.0159,0,0,1523672,-467.323,0,0,0,1.52E+08,0,0,51.5241,29.884,514.1529,499.8784,492.3987,36.2726,9.1778,-7.579,-1.7297,18.3516,541.1442,499.8784,465.4075,73.8212,32.5554,-1.9155,17.8001,-7.579,-10.352,502.1433,34.8204,75.7367,0.4551,-38.5389,36.6538,-0.1309,0.0695
1,450.6,450.6,498.2436,112983.8,472,0,0.1005,475.7473,18.8275,0,0,0.0528,0.0522,0.0518,0,0,0,35.6757,0,0,100,0,0,0,0,0,0,0,0,0,0,503.4464,53881.61,44.1725,6.2919,0,0,0,0,0,0,0,0,0,0,4.4343,9.7049,5.2369,5.2369,509.7999,34.0526,22.4963,11.5563,1.0232,1.5137,8698.119,9.9612,502.0957,26.3484,5.7782,0,94.9876,28.2745,3.7473,0.11,0,0,1523672,-475.7473,0,0,0,1.52E+08,0,0,51.6797,29.9804,513.6579,500.1537,491.0552,27.0454,9.7049,-7.8311,-2.0329,18.3928,531.6682,500.1537,473.0449,55.9209,24.4064,-2.7024,18.1046,-7.8311,-10.4326,501.6223,25.875,58.6233,0.4624,-20.6931,33.6608,-0.1591,0.0646
1,459.8,459.8,497.6849,112948.5,484,0,0.1001,483.5714,19.8669,0,0,0.0528,0.0522,0.0518,0,0,0,37.3733,0,0,100,0,0,0,0,0,0,0,0,0,0,504.4256,53887.14,43.179,3.8034,0,0,0,0,0,0,0,0,0,0,4.4549,10.2407,5.5505,5.5505,509.1291,25.5577,14.1135,11.4442,1.023,1.8109,8750.04,10.5275,501.4996,17.9282,5.7221,0,372.7711,19.8356,-0.4286,-0.0168,0,0,1523672,-483.5714,0,0,0,1.52E+08,0,0,51.8336,30.0695,512.1407,500.1596,488.3719,16.2034,10.2407,-8.1055,-2.3236,18.1402,520.3508,500.1596,480.1618,36.7794,16.5882,-3.4096,18.2414,-8.1055,-10.3243,500.2241,16.6527,40.189,0.4976,-10.787,26.8709,-0.1884,0.0603
1,469,469,497.7917,112806.7,487,0,0.0886,488.0729,20.6684,0,0,0.0528,0.0522,0.0518,0,0,0,38.683,0,0,100,0,0,0,0,0,0,0,0,0,0,504.8755,54071.26,41.4131,1.242,0,0,0,0,0,0,0,0,0,0,4.4644,10.6538,5.7942,5.7942,507.8666,19.7937,9.7188,10.0749,1.0202,2.0366,8790.497,10.9653,501.15,13.0771,5.0375,0,264.4748,14.7563,1.0729,0.0542,0,0,1523672,-488.0729,0,0,0,1.52E+08,0,0,51.95,30.1334,509.9484,500.3922,488.0075,5.2553,10.6538,-8.3267,-2.5382,17.5174,511.1422,500.3922,486.8137,23.0693,12.3193,-1.2592,18.0912,-8.3267,-9.9756,499.4494,11.3765,24.3285,0.5581,-18.3206,12.7982,-0.2111,0.0574
1,478.2,478.2,497.8934,112760.1,487,0,0.0929,487.0026,21.4036,0,0,0.0528,0.0522,0.0518,0,0,0,39.8862,0,0,100,0,0,0,0,0,0,0,0,0,0,504.6176,54138.39,41.9177,-0.2333,0,0,0,0,0,0,0,0,0,0,4.4883,11.0328,6.0193,6.0193,508.4196,21.417,10.8908,10.5262,1.0211,1.9665,8827.944,11.3681,501.4021,14.3995,5.2631,0,199.0759,16.1539,0.0026,0.0001,0,0,1523672,-487.0026,0,0,0,1.52E+08,0,0,52.0593,30.1954,510.9272,500.3618,488.6069,-0.9809,11.0328,-8.525,-2.7411,17.8436,510.9702,500.3618,488.5639,23.9676,13.3592,1.5613,18.5204,-8.525,-10.2287,499.9653,12.9627,22.4063,0.5265,15.3511,-2.5115,-0.2333,0.055
1,487.4,487.4,497.7201,112692.2,486,0,0.0938,486.5836,22.179,0,0,0.0528,0.0522,0.0518,0,0,0,41.1373,0,0,100,0,0,0,0,0,0,0,0,0,0,504.7984,54229.32,43.1915,-0.6791,0,0,0,0,0,0,0,0,0,0,4.5075,11.4325,6.2583,6.2583,508.3006,21.717,11.1365,10.5805,1.0213,1.9501,8867.784,11.7939,501.2469,14.6633,5.2903,0,333.0516,16.4268,0.5836,0.0269,0,0,1523672,-486.5836,0,0,0,1.52E+08,0,0,52.1751,30.2607,510.6597,500.3184,487.946,-2.8362,11.4325,-8.7358,-2.9548,18.5096,511.0085,500.3184,487.5972,24.4249,13.7348,1.0136,19.1738,-8.7358,-10.6961,499.6414,13.0578,23.4113,0.5434,24.0972,-7.011,-0.2581,0.0527
1,496.6,496.6,497.5378,112595.8,486,0,0.0771,487.9434,22.7128,0,0,0.0528,0.0522,0.0518,0,0,0,41.9997,0,0,100,0,0,0,0,0,0,0,0,0,0,504.9274,54322.86,46.8,0.1783,0,0,0,0,0,0,0,0,0,0,4.5029,11.7076,6.4237,6.4237,506.2047,18.2613,9.5944,8.6669,1.0174,1.9033,8895.414,12.0875,500.4268,12.4834,4.3335,0,1193.769,13.9279,1.9434,0.1064,0,0,1523672,-487.9434,0,0,0,1.52E+08,0,0,52.2546,30.3049,507.3356,500.2503,487.3353,0.7412,11.7076,-8.8826,-3.1002,20.1488,507.363,500.2503,487.3079,19.4196,12.3069,-0.6355,20.36,-8.8826,-11.7526,498.307,10.3637,20.0551,0.6453,-30.558,2.1195,-0.2752,0.0514
1,505.8,505.8,497.658,112562.8,485,0,0.0786,484.8489,22.9148,0,0,0.0528,0.0522,0.0518,0,0,0,42.3292,0,0,100,0,0,0,0,0,0,0,0,0,0,504.9596,54360.38,51.6085,2.0663,0,0,0,0,0,0,0,0,0,0,4.5107,11.8118,6.4865,6.4865,506.4831,21.6342,12.8091,8.8251,1.0177,1.689,8905.925,12.1989,500.5997,15.7508,4.4126,0,431.5944,17.2217,-0.1511,-0.007,0,0,1523672,-484.8489,0,0,0,1.52E+08,0,0,52.2849,30.3217,507.7478,500.3381,487.5776,8.575,11.8118,-8.9386,-3.1554,22.258,510.9005,500.3381,484.4249,26.0516,15.4892,-0.424,21.7556,-8.9386,-13.0992,498.5545,13.7056,26.4756,0.6011,-61.4425,20.1867,-0.2822,0.051
1,515,515,497.7073,112542.4,472,0,0.0887,475.4897,23.4491,0,0,0.0528,0.0522,0.0518,0,0,0,43.1867,0,0,100,0,0,0,0,0,0,0,0,0,0,505.1227,54372.16,53.9329,4.3963,0,0,0,0,0,0,0,0,0,0,4.5351,12.0872,6.6532,6.6532,507.6326,32.1429,22.2176,9.9253,1.0199,1.4467,8933.824,12.4936,501.0157,25.526,4.9627,0,304.761,27.1803,3.4897,0.1086,0,0,1523672,-475.4897,0,0,0,1.52E+08,0,0,52.3665,30.3688,509.463,500.4292,487.47,18.1591,12.0872,-9.0814,-3.3061,23.3697,519.6956,500.4292,477.2374,44.2059,24.9395,1.7477,22.6199,-9.0814,-13.8388,499.1207,23.631,42.4582,0.5462,25.2938,29.4012,-0.3003,0.0496
1,524.2,524.2,497.7001,112810.3,467,0,0.0924,469.1866,24.1921,0,0,0.0528,0.0522,0.0518,0,0,0,44.3574,0,0,100,0,0,0,0,0,0,0,0,0,0,504.6044,54073.91,55.4411,6.8594,0,0,0,0,0,0,0,0,0,0,4.5582,12.4702,6.8863,6.8863,507.9954,38.8088,28.5135,10.2953,1.0207,1.3611,8972.915,12.9043,501.1319,31.9453,5.1477,0,287.2353,33.6612,2.1866,0.0563,0,0,1523672,-469.1866,0,0,0,1.52E+08,0,0,52.4862,30.4443,510.2894,500.2347,488.1639,28.1437,12.4702,-9.2637,-3.5337,24.1849,529.4666,500.2347,468.9868,60.28,31.0481,-0.1998,23.3491,-9.2637,-14.4126,499.5627,30.3761,60.4798,0.5167,-301.7017,34.2706,-0.3272,0.0478
1,533.4,533.4,498.0869,113303.2,464,0,0.0931,465.4976,24.9881,0,0,0.0528,0.0522,0.0518,0,0,0,45.6465,0,0,100,0,0,0,0,0,0,0,0,0,0,503.2021,53440.88,56.7575,8.7612,0,0,0,0,0,0,0,0,0,0,4.5834,12.8805,7.1377,7.1377,508.4094,42.9118,32.5893,10.3225,1.0207,1.3167,9015.175,13.3455,501.5277,36.0301,5.1613,0,102.4451,37.7506,1.4976,0.0349,0,0,1523672,-465.4976,0,0,0,1.52E+08,0,0,52.621,30.5355,511.626,499.9653,491.0146,35.6821,12.8805,-9.4428,-3.7959,24.9427,538.4609,499.9653,464.1798,72.9633,34.4677,-1.3178,24.0511,-9.4428,-14.9665,500.8687,35.3711,74.2811,0.4818,-55.3675,36.9451,-0.3582,0.0459
1,542.6,542.6,498.1912,114046.3,464,0,0.0953,464.6912,25.8065,0,0,0.0528,0.0522,0.0518,0,0,0,47.0017,0,0,100,0,0,0,0,0,0,0,0,0,0,502.6535,52568.68,57.8384,9.4579,0,0,0,0,0,0,0,0,0,0,4.6084,13.3023,7.398,7.398,508.7076,44.0164,33.5,10.5164,1.0211,1.3139,9059.035,13.8002,501.6967,37.0055,5.2582,0,86.6087,38.7582,0.6912,0.0157,0,0,1523672,-464.6912,0,0,0,1.52E+08,0,0,52.7645,30.6366,512.359,499.8304,492.013,38.2224,13.3023,-9.6164,-4.078,25.6153,541.739,499.8304,462.633,77.0478,35.1392,-2.0582,24.7017,-9.6164,-15.4774,501.4008,36.7096,79.106,0.4702,-37.4346,37.548,-0.3921,0.0441
1,551.8,551.8,498.2929,114923.5,466,0,0.0979,467.431,26.699,0,0,0.0528,0.0522,0.0518,0,0,0,48.4938,0,0,100,0,0,0,0,0,0,0,0,0,0,502.6804,51533.2,58.3864,9.0294,0,0,0,0,0,0,0,0,0,0,4.636,13.7624,7.6841,7.6841,509.0385,41.6075,30.8619,10.7456,1.0216,1.3482,9107.367,14.2977,501.8748,34.4438,5.3728,0,79.2712,36.2347,1.431,0.0344,0,0,1523672,-467.431,0,0,0,1.52E+08,0,0,52.9237,30.7503,512.853,499.9053,492.2083,36.1807,13.7624,-9.8018,-4.3908,26.0796,540.155,499.9053,464.9063,72.724,32.4743,-2.5247,25.2396,-9.8018,-15.868,501.6555,34.2245,75.2487,0.4651,-28.805,37.0383,-0.4302,0.0422
1,561,561,498.0763,115781.8,472,0,0.1,473.9573,27.6794,0,0,0.0528,0.0522,0.0518,0,0,0,50.1539,0,0,100,0,0,0,0,0,0,0,0,0,0,503.0531,50462.48,58.2814,7.4326,0,0,0,0,0,0,0,0,0,0,4.6629,14.2677,8.001,8.001,508.9921,35.0348,24.119,10.9158,1.0219,1.4526,9161.046,14.8458,501.7149,27.7576,5.4579,0,118.0818,29.5769,1.9573,0.0559,0,0,1523672,-473.9573,0,0,0,1.52E+08,0,0,53.0987,30.874,512.5903,499.9061,491.1627,29.5043,14.2677,-10.01,-4.7309,26.278,533.2657,499.9061,470.4872,59.3084,25.9488,-3.4701,25.6371,-10.01,-16.1003,501.2196,27.2624,62.7785,0.4686,-17.0913,35.0213,-0.4732,0.0403
1,570.2,570.2,497.8057,116468.6,481,0,0.0997,481.7587,28.7027,0,0,0.0528,0.0522,0.0518,0,0,0,51.87,0,0,100,0,0,0,0,0,0,0,0,0,0,504.0558,49613.92,57.5323,5.0601,0,0,0,0,0,0,0,0,0,0,4.6884,14.7952,8.3348,8.3348,508.6267,26.868,16.047,10.821,1.0217,1.6743,9217.762,15.42,501.4127,19.654,5.4105,0,235.0073,21.4575,0.7587,0.0282,0,0,1523672,-481.7587,0,0,0,1.52E+08,0,0,53.2782,30.9958,511.5081,500.1045,489.1116,19.8923,14.7952,-10.2431,-5.0716,26.1934,523.1376,500.1045,477.4821,41.3789,18.3458,-4.2766,25.8789,-10.2431,-16.1553,500.2414,18.4827,45.6555,0.4955,-9.6757,30.3115,-0.5195,0.0386
1,579.4,579.4,497.5121,116935.1,485,0,0.0918,488.0438,29.6128,0,0,0.0528,0.0522,0.0518,0,0,0,53.3165,0,0,100,0,0,0,0,0,0,0,0,0,0,505.113,49003.45,55.8011,2.3607,0,0,0,0,0,0,0,0,0,0,4.7031,15.2643,8.6343,8.6343,507.4125,19.3687,9.4683,9.9004,1.0199,2.0456,9268.791,15.9324,500.8122,12.7684,4.9502,0,1858.004,14.4185,3.0438,0.1572,0,0,1523672,-488.0438,0,0,0,1.52E+08,0,0,53.4365,31.1004,509.0938,500.3084,486.9287,9.2009,15.2643,-10.4589,-5.3668,25.6247,512.4154,500.3084,483.6071,24.3716,12.2646,-4.4367,25.7988,-10.4589,-15.9013,498.777,10.7332,28.8083,0.5797,-5.4932,19.85,-0.5614,0.0371
1,588.6,588.6,497.2504,117468.6,487,0,0.0937,488.0433,30.2847,0,0,0.0528,0.0522,0.0518,0,0,0,54.4313,0,0,100,0,0,0,0,0,0,0,0,0,0,504.9862,48394.01,55.2098,0.4729,0,0,0,0,0,0,0,0,0,0,4.7215,15.6107,8.857,8.857,507.3152,19.2719,9.2071,10.0648,1.0202,2.0932,9306.837,16.3118,500.6053,12.562,5.0324,0,-400.3047,14.2395,1.0433,0.0541,0,0,1523672,-488.0433,0,0,0,1.52E+08,0,0,53.5571,31.1832,509.014,500.0971,486.4688,1.8313,15.6107,-10.6101,-5.5939,25.5177,509.1618,500.0971,486.321,21.1185,12.0538,-1.7223,25.9365,-10.6101,-15.9197,498.5266,10.4833,22.8408,0.6031,-12.2618,4.6137,-0.5933,0.0361
1,597.8,597.8,497.7073,118076.7,486,0,0.0946,486.9872,31.0376,0,0,0.0528,0.0522,0.0518,0,0,0,55.6864,0,0,100,0,0,0,0,0,0,0,0,0,0,504.9222,47624.95,56.1026,-0.5823,0,0,0,0,0,0,0,0,0,0,4.7481,15.9988,9.1082,9.1082,507.827,20.8398,10.7201,10.1197,1.0203,1.944,9349.837,16.738,501.0805,14.0933,5.0599,0,352.3486,15.78,0.9872,0.0474,0,0,1523672,-486.9872,0,0,0,1.52E+08,0,0,53.6947,31.2792,509.8104,500.3631,487.6395,-2.2385,15.9988,-10.776,-5.8534,26.1209,510.0341,500.3631,487.4157,23.0469,13.3759,0.4285,26.5327,-10.776,-16.3873,499.271,12.2838,22.6184,0.5724,53.7851,-5.7081,-0.6306,0.0351
1,607,607,497.7409,118676.3,487,0,0.0874,487.5439,31.7159,0,0,0.0528,0.0522,0.0518,0,0,0,56.7817,0,0,100,0,0,0,0,0,0,0,0,0,0,505.0688,46889.83,57.9092,-0.4525,0,0,0,0,0,0,0,0,0,0,4.7606,16.3484,9.3359,9.3359,507.0449,19.501,10.197,9.304,1.0187,1.9124,9388.912,17.1229,500.8423,13.2984,4.652,0,311.3535,14.849,0.5439,0.0279,0,0,1523672,-487.5439,0,0,0,1.52E+08,0,0,53.8202,31.3675,508.5164,500.4392,487.5035,-1.728,16.3484,-10.9239,-6.0897,27.1417,508.6575,500.4392,487.3624,21.1136,12.8953,-0.1815,27.36,-10.9239,-17.1013,498.8197,11.2758,21.2951,0.6141,-116.3284,-4.6699,-0.6652,0.0342
1,616.2,616.2,497.1968,119204.8,486,0,0.0744,487.9141,32.0685,0,0,0.0528,0.0522,0.0518,0,0,0,57.3996,0,0,100,0,0,0,0,0,0,0,0,0,0,505.554,46155.65,62.2235,1.0695,0,0,0,0,0,0,0,0,0,0,4.7527,16.5302,9.4549,9.4549,505.1033,17.1892,9.2827,7.9065,1.0159,1.8517,9409.361,17.3234,499.8323,11.9182,3.9533,0,-320.045,13.236,1.9141,0.1114,0,0,1523672,-487.9141,0,0,0,1.52E+08,0,0,53.8922,31.4246,505.2462,500.275,485.5079,4.0692,16.5302,-10.9829,-6.2318,29.2705,506.0522,500.275,484.7019,18.1381,12.3609,-3.2122,28.7693,-10.9829,-18.4709,497.0097,9.0956,21.3503,0.7294,-5.6466,11.2036,-0.6845,0.0338
1,625.4,625.4,497.4731,119792.8,484,0,0.0851,482.4641,32.3774,0,0,0.0528,0.0522,0.0519,0,0,0,57.9229,0,0,100,0,0,0,0,0,0,0,0,0,0,505.298,45429.65,65.3931,3.1683,0,0,0,0,0,0,0,0,0,0,4.7749,16.6894,9.5595,9.5595,506.4948,24.0307,15.009,9.0217,1.0181,1.6011,9427.342,17.4993,500.4803,18.0162,4.5109,0,10869.67,19.5199,-1.5359,-0.0639,0,0,1523672,-482.4641,0,0,0,1.52E+08,0,0,53.9569,31.4773,507.5407,500.3561,486.5162,12.0156,16.6894,-11.0304,-6.3607,30.8615,512.9935,500.3561,481.0634,30.5294,17.892,-1.4007,29.8431,-11.0304,-19.5144,498.1377,15.6736,31.9301,0.6042,-21.7958,24.4089,-0.7017,0.0334
1,634.6,634.6,497.7275,120526.2,473,0,0.0913,474.8589,33.0045,0,0,0.0528,0.0522,0.0518,0,0,0,58.9696,0,0,100,0,0,0,0,0,0,0,0,0,0,504.9725,44521.43,66.9085,5.6776,0,0,0,0,0,0,0,0,0,0,4.8018,17.0126,9.7726,9.7726,507.3722,32.5133,22.8686,9.6447,1.0194,1.4217,9464.058,17.8568,500.9424,26.0835,4.8224,0,278.8347,27.691,1.8589,0.0572,0,0,1523672,-474.8589,0,0,0,1.52E+08,0,0,54.0784,31.567,509.0565,500.3978,487.5681,21.3967,17.0126,-11.1561,-6.5916,31.7765,522.2551,500.3978,474.3695,47.3962,25.5389,-0.4894,30.5909,-11.1561,-20.1699,499.0075,24.1486,47.8856,0.5436,-96.8455,31.6684,-0.7351,0.0326
1,643.8,643.8,497.9038,121493.3,469,0,0.0926,470.1625,33.728,0,0,0.0528,0.0522,0.0518,0,0,0,60.1681,0,0,100,0,0,0,0,0,0,0,0,0,0,503.9295,43306.67,68.0337,7.9139,0,0,0,0,0,0,0,0,0,0,4.8261,17.3856,10.0201,10.0201,507.6478,37.4853,27.7413,9.744,1.0196,1.3512,9506.787,18.2705,501.1518,30.9893,4.872,0,155.9092,32.6133,1.1625,0.031,0,0,1523672,-470.1625,0,0,0,1.52E+08,0,0,54.2226,31.6763,510.0014,500.1259,489.438,29.6046,17.3856,-11.2936,-6.8673,32.5508,531.0589,500.1259,468.3805,60.8964,29.9634,-1.782,31.2751,-11.2936,-20.7568,499.8551,29.6926,62.6784,0.5065,-34.1731,35.4239,-0.7753,0.0318
1,653,653,498.1892,122766.3,467,0,0.0942,468.1066,34.4724,0,0,0.0528,0.0522,0.0518,0,0,0,61.3754,0,0,100,0,0,0,0,0,0,0,0,0,0,503.0743,41734.66,69.0266,9.2601,0,0,0,0,0,0,0,0,0,0,4.8525,17.7693,10.2765,10.2765,508.0541,39.9475,30.0826,9.8649,1.0198,1.3279,9551.147,18.6972,501.4775,33.3709,4.9325,0,91.5667,35.0151,1.1066,0.0277,0,0,1523672,-468.1066,0,0,0,1.52E+08,0,0,54.3779,31.7995,511.0608,499.9918,491.309,34.3709,17.7693,-11.4198,-7.1682,33.2849,536.9465,499.9918,465.4233,68.8399,31.8852,-2.6833,31.9353,-11.4198,-21.3342,500.7872,32.6806,71.5232,0.4833,-25.6549,36.9844,-0.8187,0.0309
1,662.2,662.2,498.2288,124144.3,468,0,0.0963,468.2887,35.2537,0,0,0.0528,0.0522,0.0518,0,0,0,62.6434,0,0,100,0,0,0,0,0,0,0,0,0,0,502.8437,40001.59,69.6707,9.4335,0,0,0,0,0,0,0,0,0,0,4.8784,18.172,10.5475,10.5475,508.2645,39.9758,29.9401,10.0357,1.0201,1.3352,9598.151,19.1463,501.574,33.2853,5.0179,0,87.0558,34.958,0.2887,0.0072,0,0,1523672,-468.2887,0,0,0,1.52E+08,0,0,54.5434,31.9321,511.499,499.9329,491.7115,34.726,18.172,-11.5486,-7.4882,33.8745,537.7131,499.9329,465.4973,69.4244,31.6442,-2.7914,32.5145,-11.5486,-21.8307,501.0478,32.7591,72.2158,0.4768,-24.8708,37.0486,-0.8648,0.03
1,671.4,671.4,498.0009,125632.6,474,0,0.0949,472.911,36.0095,0,0,0.0528,0.0522,0.0518,0,0,0,63.8921,0,0,100,0,0,0,0,0,0,0,0,0,0,502.8857,38152.44,69.8334,8.2962,0,0,0,0,0,0,0,0,0,0,4.8977,18.5616,10.8116,10.8116,507.8458,34.9348,25.0899,9.8449,1.0198,1.3924,9644.068,19.5821,501.2825,28.3715,4.9225,0,132.7647,30.0124,-1.089,-0.0312,0,0,1523672,-472.911,0,0,0,1.52E+08,0,0,54.7077,32.0665,510.8197,499.806,491.0826,30.2924,18.5616,-11.6654,-7.8067,34.2307,532.8105,499.806,469.0918,59.8995,26.895,-3.8192,32.94,-11.6654,-22.1851,500.5694,27.6584,63.7187,0.482,-15.6838,35.9778,-0.9105,0.0292
1,680.6,680.6,498.1289,126935.9,480,0,0.1247,479.4213,36.9626,0,0,0.0528,0.0522,0.0518,0,0,0,65.4543,0,0,100,0,0,0,0,0,0,0,0,0,0,504.1316,36552.55,69.303,6.8217,0,0,0,0,0,0,0,0,0,0,4.9578,19.0529,11.1474,11.1474,510.9763,31.555,18.7076,12.8474,1.0258,1.6867,9702.603,20.1335,502.4114,22.9901,6.4237,0,116.9531,25.1313,-0.5787,-0.0183,0,0,1523672,-479.4213,0,0,0,1.52E+08,0,0,54.9031,32.2141,515.059,500.3485,489.6062,24.6626,19.0529,-11.8516,-8.1697,34.3092,530.0852,500.3485,474.58,50.6639,20.9272,-4.8413,33.2594,-11.8516,-22.3762,501.6712,22.2499,55.5052,0.4643,-10.4649,31.3527,-0.9684,0.0283
1,689.8,689.8,497.5188,128041.5,485,0,0.0966,486.257,37.8734,0,0,0.0528,0.0522,0.0518,0,0,0,66.9371,0,0,100,0,0,0,0,0,0,0,0,0,0,504.8336,35169.7,68.195,3.7653,0,0,0,0,0,0,0,0,0,0,4.952,19.5224,11.4712,11.4712,507.4183,21.1613,11.2618,9.8995,1.0199,1.879,9759.206,20.6624,500.8186,14.5616,4.9498,0,1589.434,16.2116,1.257,0.0594,0,0,1523672,-486.257,0,0,0,1.52E+08,0,0,55.0886,32.3515,509.1342,500.2252,487.1109,13.4848,19.5224,-12.038,-8.5088,34.0811,515.5322,500.2252,480.7129,29.2752,13.9682,-5.5441,33.3851,-12.038,-22.3715,498.8235,12.5664,34.8193,0.5604,-5.2804,25.3825,-1.0244,0.0275
1,699,699,497.4843,129130.2,487,0,0.0894,488.8774,38.5754,0,0,0.0528,0.0522,0.0518,0,0,0,68.0534,0,0,100,0,0,0,0,0,0,0,0,0,0,505.4627,33824.97,66.6964,1.278,0,0,0,0,0,0,0,0,0,0,4.9664,19.8842,11.7226,11.7226,506.6061,17.7287,8.6069,9.1218,1.0183,2.0598,9803.278,21.0712,500.5249,11.6475,4.5609,0,4674.561,13.1678,1.8774,0.1059,0,0,1523672,-488.8774,0,0,0,1.52E+08,0,0,55.2377,32.4669,507.5223,500.4377,486.1087,4.5429,19.8842,-12.1682,-8.7847,33.5817,508.4462,500.4377,485.1848,19.5688,11.5603,-3.6926,33.2868,-12.1682,-22.1873,498.0229,9.1455,23.2614,0.6557,-5.2995,11.4958,-1.0687,0.0269
1,708.2,708.2,497.6879,130304.9,487,0,0.0945,487.688,39.2006,0,0,0.0528,0.0522,0.0518,0,0,0,69.0776,0,0,100,0,0,0,0,0,0,0,0,0,0,504.9515,32394.36,65.8473,-0.2104,0,0,0,0,0,0,0,0,0,0,4.9932,20.2065,11.948,11.948,507.2907,19.6027,9.9999,9.6028,1.0193,1.9603,9842.876,21.4363,500.8888,13.2008,4.8014,0,386.2803,14.8013,0.688,0.0351,0,0,1523672,-487.688,0,0,0,1.52E+08,0,0,55.3758,32.5776,508.8447,500.3783,487.3085,-0.7428,20.2065,-12.2738,-9.0427,33.3801,508.8703,500.3783,487.2829,21.1823,12.6903,-0.4051,33.3487,-12.2738,-22.1849,498.8438,11.1558,21.5874,0.6066,-52.2891,-1.9731,-1.11,0.0263
1,717.4,717.4,497.5464,131594.6,487,0,0.0918,487.7556,40.1503,0,0,0.0528,0.0522,0.0518,0,0,0,70.6655,0,0,100,0,0,0,0,0,0,0,0,0,0,505.2896,30771.79,67.7426,-0.7067,0,0,0,0,0,0,0,0,0,0,5.0193,20.696,12.2929,12.2929,506.8142,19.0586,9.7908,9.2678,1.0186,1.9466,9903.63,21.9926,500.6357,12.8801,4.6339,0,1064.57,14.4247,0.7556,0.0396,0,0,1523672,-487.7556,0,0,0,1.52E+08,0,0,55.5766,32.7293,507.9185,500.4163,486.454,-2.4701,20.696,-12.4623,-9.4058,34.6886,508.1991,500.4163,486.1734,20.4435,12.6607,-1.5822,34.4232,-12.4623,-23.133,498.2629,10.5073,22.0257,0.6466,-12.9209,-6.4807,-1.1721,0.0256
1,726.6,726.6,497.4249,132942,487,0,0.0825,488.7533,40.7565,0,0,0.0528,0.0522,0.0518,0,0,0,71.5792,0,0,100,0,0,0,0,0,0,0,0,0,0,505.3519,29129.99,70.3761,0.067,0,0,0,0,0,0,0,0,0,0,5.0283,21.0085,12.5148,12.5148,505.7222,16.9689,8.6716,8.2973,1.0167,1.9568,9942.811,22.3489,500.1907,11.4374,4.1487,0,-2129.705,12.8203,1.7533,0.1033,0,0,1523672,-488.7533,0,0,0,1.52E+08,0,0,55.717,32.8459,506.1675,500.3649,486.0407,0.2326,21.0085,-12.5534,-9.6687,36.282,506.1702,500.3649,486.038,17.4169,11.6116,-2.7153,35.5608,-12.5534,-24.221,497.5244,8.7711,20.1322,0.7116,-6.4144,0.662,-1.2136,0.0252
1,735.8,735.8,497.4475,134138.9,487,0,0.0828,487.0206,41.0659,0,0,0.0528,0.0522,0.0518,0,0,0,72.0812,0,0,100,0,0,0,0,0,0,0,0,0,0,505.9945,27621.66,74.3154,2.0735,0,0,0,0,0,0,0,0,0,0,5.0388,21.168,12.6286,12.6286,505.7549,18.7343,10.4269,8.3074,1.0167,1.7967,9962.928,22.5311,500.2166,13.196,4.1537,0,-4682.278,14.5806,0.0206,0.0011,0,0,1523672,-487.0206,0,0,0,1.52E+08,0,0,55.8015,32.9268,505.8676,500.6192,485.1446,7.1711,21.168,-12.5672,-9.8371,38.4592,508.1071,500.6192,482.9051,21.0865,13.5986,-4.1155,36.9686,-12.5672,-25.6377,497.2104,10.1899,25.202,0.7029,-5.1237,17.3434,-1.2363,0.0249
1,745,745,497.6232,135416.5,479,0,0.0915,479.8518,41.5885,0,0,0.0528,0.0522,0.0518,0,0,0,72.9252,0,0,100,0,0,0,0,0,0,0,0,0,0,505.2204,26063.54,76.21,4.4186,0,0,0,0,0,0,0,0,0,0,5.0663,21.4374,12.8216,12.8216,506.7774,26.9256,17.7714,9.1542,1.0184,1.5151,9997.092,22.8393,500.6746,20.8228,4.5771,0,495.2007,22.3485,0.8518,0.0316,0,0,1523672,-479.8518,0,0,0,1.52E+08,0,0,55.9262,33.0325,507.8539,500.4442,486.6615,15.1911,21.4374,-12.6397,-10.0706,39.6747,515.7793,500.4442,478.7361,35.9275,20.5924,-1.1157,37.8584,-12.6397,-26.4916,498.3199,18.4681,37.0432,0.586,-32.2018,27.5516,-1.2729,0.0245
1,754.2,754.2,497.5414,136755.3,475,0,0.0921,473.8566,42.2916,0,0,0.0528,0.0522,0.0518,0,0,0,74.0972,0,0,100,0,0,0,0,0,0,0,0,0,0,504.6418,24405.73,77.3326,6.8526,0,0,0,0,0,0,0,0,0,0,5.0891,21.7998,13.0827,13.0827,506.7098,32.8532,23.6848,9.1684,1.0184,1.3871,10043.42,23.255,500.5975,26.7409,4.5842,0,950.9391,28.269,-1.1434,-0.0348,0,0,1523672,-473.8566,0,0,0,1.52E+08,0,0,56.0867,33.1615,508.0535,500.1797,487.2706,23.3763,21.7998,-12.7598,-10.3623,40.574,523.244,500.1797,472.0801,49.3874,26.3231,-1.7765,38.6083,-12.7598,-27.1708,498.5013,24.6447,51.1639,0.5492,-27.8004,33.0167,-1.3223,0.024
1,763.4,763.4,497.9648,138371.6,470,0,0.0931,470.8713,43.0366,0,0,0.0528,0.0522,0.0518,0,0,0,75.3323,0,0,100,0,0,0,0,0,0,0,0,0,0,503.6732,22437.04,78.2607,8.7279,0,0,0,0,0,0,0,0,0,0,5.119,22.1838,13.3613,13.3613,507.1841,36.3128,27.0935,9.2193,1.0185,1.3403,10092.98,23.6967,501.0379,30.1666,4.6097,0,138.2732,31.7032,0.8713,0.024,0,0,1523672,-470.8713,0,0,0,1.52E+08,0,0,56.2618,33.3056,509.298,500.0874,489.683,29.5245,22.1838,-12.8776,-10.6818,41.4072,530.6013,500.0874,468.3797,59.73,29.2161,-2.4916,39.3265,-12.8776,-27.8245,499.6895,28.8182,62.2216,0.5096,-23.9726,35.8122,-1.3756,0.0235
1,772.6,772.6,498.1776,140176.2,469,0,0.0938,469.7171,43.7512,0,0,0.0528,0.0522,0.0518,0,0,0,76.4927,0,0,100,0,0,0,0,0,0,0,0,0,0,503.1014,20199.42,79.0301,9.4782,0,0,0,0,0,0,0,0,0,0,5.1458,22.5522,13.6306,13.6306,507.4257,37.7086,28.4605,9.2481,1.0186,1.3249,10140.99,24.1219,501.2603,31.5432,4.6241,0,95.3205,33.0846,0.7171,0.019,0,0,1523672,-469.7171,0,0,0,1.52E+08,0,0,56.4374,33.4556,509.9625,500.0101,491.0098,31.7987,22.5522,-12.9746,-11.0053,42.1614,533.6669,500.0101,467.3055,63.9498,30.293,-2.4116,39.9834,-12.9746,-28.4365,500.3275,30.6104,66.3614,0.4928,-26.5176,36.7027,-1.4277,0.0231
1,781.8,781.8,498.2929,142190.4,470,0,0.0965,472.0551,44.5816,0,0,0.0528,0.0522,0.0518,0,0,0,77.8071,0,0,100,0,0,0,0,0,0,0,0,0,0,503.3713,17708.91,79.3041,9.0448,0,0,0,0,0,0,0,0,0,0,5.1778,22.9802,13.9459,13.9459,507.7596,35.7045,26.2378,9.4667,1.019,1.3608,10197.35,24.6174,501.4485,29.3934,4.7334,0,84.8613,30.9712,2.0551,0.0576,0,0,1523672,-472.0551,0,0,0,1.52E+08,0,0,56.6409,33.6274,510.3148,500.1848,490.8723,30.055,22.9802,-13.0945,-11.3753,42.7153,532.1816,500.1848,469.0055,60.1265,28.1297,-3.0496,40.5497,-13.0945,-28.9448,500.4573,28.4022,63.1761,0.4935,-19.7162,36.0381,-1.4896,0.0225
1,786,786,497.671,142424.3,485,0,0.0797,488.1005,44.9815,0,0,0.0528,0.0522,0.0518,0,0,0,78.3931,0,0,100,0,0,0,0,0,0,0,0,0,0,505.3361,17375.21,77.7003,1.5359,0,0,0,0,0,0,0,0,0,0,5.1682,23.1863,14.0987,14.0987,505.462,17.3615,9.5705,7.791,1.0157,1.8141,10224.71,24.8567,500.268,12.1675,3.8955,0,420.1017,13.466,3.1005,0.1786,0,0,1523672,-488.1005,0,0,0,1.52E+08,0,0,56.7231,33.6831,505.6754,500.5268,486.4651,5.0823,23.1863,-13.1944,-11.5105,42.0271,506.9371,500.5268,485.2034,18.8366,12.4263,-2.8971,40.2487,-13.1944,-28.5729,497.5558,9.4553,21.7337,0.7051,-6.5019,13.9421,-1.5186,0.0223