File: datas/d100-0-0.2.csv
Stage Number,Time since start of test (s),Time since start of stage (s),Radial Pressure (kPa),Radial Volume (mm3),Back Pressure (kPa),Back Volume (mm3),Load Cell (kN),Pore Pressure (kPa),Axial Displacement (mm),L/C Pressure (kPa),L/C Volume (mm3),Local Axial 1,Local Axial 2,Local Radial,Base Pressure (kPa),Base Volume (mm3),Back Differential Pressure (kPa),Axial Displacement 2 (mm),Pore Air Pressure (kPa),Pore Air Volume (mm3),Atmospheric Pressure (kPa),Temperature (°C),Mid Plane PWP (kPa),Back to Cell Differential (kPa),Total Volume Change (mm3),Undefined Tx 1,Undefined Tx 2,Undefined Tx 3,Undefined Tx. 4,HCA secondary control axial load (kN),HCA secondary control torque,Internal Cell Pr. (kPa),Internal Cell Vol. (mm3),Rotational Displ. (mm),Torque,Local Int Defmn 1 (mm),Local Int Defmn 2 (mm),Circumf. Defmn 1 (mm),Circumf. Defmn 2 (mm),Circumf. Defmn 3 (mm),Outer Cell Pr 2 (kPa),Internal cell Pr 2 (kPa),Rotation 2 (°),Secondary Cell Pr (kPa),Secondary Back Pr (kPa),Axial Force (kN),Axial Strain (%),Av Diameter Change (mm),Radial Strain (%),Axial Stress (kPa),Eff. Axial Stress (kPa),Eff. Radial Stress (kPa),Deviator Stress (kPa),Total Stress Ratio (%),Eff. Stress Ratio (%),Current Area (mm2),Shear Strain (%),Cambridge p (kPa),Eff. Cambridge p' (kPa),Max Shear Stress t,Volume Change (mm3),B Value,Mean Stress s/Eff. Axial Stress 2,Excess PWP (kPa),PWP Ratio,Lower Chamber Displacement (mm),Lower Chamber Axial Load (kPa),Specimen Air Volume (mm3),Matric Suction (kPa),Voids ratio,Degree of Saturation (°),Specimen Water Volume (mm3),kRT constant,Permeability IN,Permeability OUT,HCA Outer Rad,HCA Inner Rad,HCA Sigma Z (kPa),HCA Sigma R (kPa),HCA Sigma Theta (kPa),HCA Tau Theta Z,HCA Ez,HCA Er,HCA Etheta,HCA Gamma,HCA Sigma1,HCA Sigma2,HCA Sigma3,HCA Eff Sigma1,HCA Eff Sigma2,HCA Eff Sigma3,HCA E1,HCA E2,HCA E3,HCA P,HCA Eff P,HCA Q,HCA B,HCA Eff R,HCA Alpha,HCA Ev,HCA E1 rtv
1,0,0,596.11,57297.7,501,-65,0.1857,500.6041,0.0031,0,0,0.0528,0.0522,0.0518,0,0,0,4.7687,0,0,100,0,0,0,0,0,0,0,0,0,0,608.4636,18873.44,-0.0011,0.0571,0,0,0,0,0,0,0,0,0,0,4.8674,0.0016,-0.0013,-0.0013,619.7536,119.1495,95.5059,23.6436,1.0397,1.2476,7853.767,0.0002,603.9912,103.3871,11.8218,-65,0.1357,107.3277,-0.3959,-0.0033,0,0,1530427,-500.6041,0,0,0,1.53E+08,0,0,49.69,29.4819,626.3445,600.7102,578.0871,0.2809,0.0016,-1.0298,1.046,-0.0004,626.3461,600.7102,578.0855,125.742,100.1061,77.4814,1.046,-1.0298,0.0016,601.7139,101.1098,48.2606,0.4688,1.6229,0.3335,0.0178,90.0002
1,10.5,10.5,594.6,57310.36,506,-65,0.1858,505.6188,0.0657,0,0,0.0528,0.0522,0.0518,0,0,0,4.869,0,0,100,0,0,0,0,0,0,0,0,0,0,608.6047,18729.34,0.0348,1.2871,0,0,0,0,0,0,0,0,0,0,4.8571,0.0337,0.0147,0.0147,618.2435,112.6247,88.9812,23.6436,1.0398,1.2657,7856.289,0.0323,602.4811,96.8623,11.8218,-65,-3.54,100.8029,-0.3812,-0.0034,0,0,1530427,-505.6188,0,0,0,1.53E+08,0,0,49.7004,29.4906,623.9434,599.8153,574.164,6.3278,0.0337,-1.0381,1.0216,0.0126,624.7352,599.8153,573.3723,119.1164,94.1965,67.7535,1.0217,-1.0381,0.0336,599.3076,93.6888,51.3629,0.5148,1.7581,7.1322,0.0172,89.9936
1,21.5,21.5,595.07,57464.95,511,-65,0.1876,510.1462,0.1292,0,0,0.0528,0.0522,0.0518,0,0,0,4.9632,0,0,100,0,0,0,0,0,0,0,0,0,0,608.6274,18566.72,0.1687,3.3329,0,0,0,0,0,0,0,0,0,0,4.8642,0.0663,0.031,0.031,618.9454,108.7992,84.9238,23.8754,1.0401,1.2811,7858.852,0.0649,603.0285,92.8823,11.9377,-65,-10.0571,96.8615,-0.8538,-0.0078,0,0,1530427,-510.1462,0,0,0,1.53E+08,0,0,49.7111,29.4999,625.0002,600.1191,575.2819,16.3763,0.0663,-1.045,0.9961,0.0612,629.9095,600.1191,570.3726,119.7633,89.9729,60.2264,0.9981,-1.045,0.0643,600.1337,89.9875,59.5369,0.4996,1.9886,16.6877,0.0174,89.9671
1,32.5,32.5,595.09,57607.19,514,-65,0.186,513.8965,0.1842,0,0,0.0528,0.0522,0.0518,0,0,0,5.0527,0,0,100,0,0,0,0,0,0,0,0,0,0,608.3494,18492.23,0.2542,4.0944,0,0,0,0,0,0,0,0,0,0,4.864,0.0945,0.0452,0.0452,618.7452,104.8487,81.1935,23.6552,1.0398,1.2913,7861.07,0.0931,602.9751,89.0786,11.8276,-65,-14.3061,93.0211,-0.1035,-0.001,0,0,1530427,-513.8965,0,0,0,1.53E+08,0,0,49.7194,29.5062,624.8526,600.0283,575.7346,20.1086,0.0945,-1.0547,0.9775,0.0922,632.0347,600.0283,568.5524,118.1382,86.1318,54.6559,0.9823,-1.0547,0.0897,600.2051,86.3086,63.4823,0.4958,2.1615,19.6551,0.0173,89.9479
1,43.5,43.5,594.93,57730.52,517,-65,0.1865,517.2032,0.2291,0,0,0.0528,0.0522,0.0518,0,0,0,5.1483,0,0,100,0,0,0,0,0,0,0,0,0,0,608.6956,18435.9,0.1961,3.3232,0,0,0,0,0,0,0,0,0,0,4.8644,0.1176,0.0567,0.0567,618.6531,101.4499,77.7268,23.7231,1.0399,1.3052,7862.888,0.1162,602.8377,85.6345,11.8616,-65,-15.2394,89.5884,0.2032,0.002,0,0,1530427,-517.2032,0,0,0,1.53E+08,0,0,49.7261,29.5112,624.5073,600.0568,574.8339,16.3149,0.1176,-1.0631,0.9626,0.0712,629.3866,600.0568,569.9547,112.1834,82.8536,52.7515,0.9656,-1.0631,0.1146,599.7994,82.5962,59.4319,0.5065,2.1266,16.6502,0.0171,89.9579
1,54.5,54.5,594.86,57808.95,520,-65,0.1861,520.2147,0.2745,0,0,0.0528,0.0522,0.0518,0,0,0,5.2089,0,0,100,0,0,0,0,0,0,0,0,0,0,608.8128,18365.16,0.0731,1.2813,0,0,0,0,0,0,0,0,0,0,4.8645,0.1409,0.0684,0.0684,618.5215,98.3068,74.6453,23.6615,1.0398,1.317,7864.723,0.1395,602.7471,82.5324,11.8308,-65,-16.9157,86.4761,0.2147,0.0022,0,0,1530427,-520.2147,0,0,0,1.53E+08,0,0,49.7331,29.5166,624.2463,600.0567,574.4885,6.288,0.1409,-1.0709,0.9468,0.0265,625.0286,600.0567,573.7062,104.8139,79.842,53.4915,0.9472,-1.0709,0.1405,599.5972,79.3825,51.3224,0.5134,1.9595,7.0921,0.0168,89.9836
1,65.5,65.5,595.03,57896.07,523,-65,0.1862,522.8478,0.3167,0,0,0.0528,0.0522,0.0518,0,0,0,5.2774,0,0,100,0,0,0,0,0,0,0,0,0,0,608.3239,18325.1,-0.0711,-1.2344,0,0,0,0,0,0,0,0,0,0,4.867,0.1625,0.0792,0.0792,618.7055,95.8577,72.1823,23.6755,1.0398,1.328,7866.424,0.1611,602.9219,80.0741,11.8378,-65,-22.4809,84.02,-0.1522,-0.0016,0,0,1530427,-522.8478,0,0,0,1.53E+08,0,0,49.7391,29.5208,624.786,599.9814,575.6196,-6.0557,0.1625,-1.0797,0.9338,-0.0258,625.5209,599.9814,574.8848,102.6731,77.1336,52.0371,0.9342,-1.0797,0.1621,600.129,77.2813,50.636,0.4956,1.9731,-6.9192,0.0166,90.0167
1,76.5,76.5,594.67,57993.41,525,-65,0.1864,524.7895,0.3575,0,0,0.0528,0.0522,0.0518,0,0,0,5.3688,0,0,100,0,0,0,0,0,0,0,0,0,0,608.5078,18284.41,-0.225,-3.3191,0,0,0,0,0,0,0,0,0,0,4.8653,0.1835,0.0898,0.0898,618.3593,93.5698,69.8805,23.6893,1.0398,1.339,7868.08,0.1822,602.5664,77.7769,11.8447,-65,-17.9237,81.7252,-0.2105,-0.0022,0,0,1530427,-524.7895,0,0,0,1.53E+08,0,0,49.745,29.5251,624.1616,599.824,574.464,-16.2774,0.1835,-1.0875,0.9208,-0.0818,629.0183,599.824,569.6073,104.2288,75.0345,44.8178,0.9253,-1.0875,0.179,599.4832,74.6937,59.411,0.5086,2.3256,-16.6135,0.0168,90.0553
1,87.5,87.5,594.64,58013.3,527,-65,0.186,526.5497,0.3985,0,0,0.0528,0.0522,0.0518,0,0,0,5.417,0,0,100,0,0,0,0,0,0,0,0,0,0,608.2418,18302.56,-0.3195,-4.109,0,0,0,0,0,0,0,0,0,0,4.8657,0.2045,0.1003,0.1003,618.28,91.7304,68.0903,23.64,1.0398,1.3472,7869.735,0.2032,602.52,75.9703,11.82,-65,-18.8099,79.9104,-0.4503,-0.0049,0,0,1530427,-526.5497,0,0,0,1.53E+08,0,0,49.7499,29.5277,624.1731,599.7061,574.7791,-20.145,0.2045,-1.0988,0.9112,-0.1161,631.3471,599.7061,567.605,104.7974,73.1564,41.0553,0.9206,-1.0988,0.1951,599.5527,73.003,63.7421,0.5036,2.5526,-19.6018,0.0169,90.0818
1,98.5,98.5,594.94,58036.64,529,-65,0.1862,528.4359,0.4359,0,0,0.0528,0.0522,0.0518,0,0,0,5.4971,0,0,100,0,0,0,0,0,0,0,0,0,0,608.5319,18308.2,-0.2622,-3.317,0,0,0,0,0,0,0,0,0,0,4.8691,0.2237,0.1099,0.1099,618.593,90.1571,66.5041,23.653,1.0398,1.3557,7871.25,0.2224,602.8243,74.3884,11.8265,-65,-25.7811,78.3306,-0.5641,-0.0063,0,0,1530427,-528.4359,0,0,0,1.53E+08,0,0,49.7546,29.5304,624.5111,600.0024,575.0937,-16.2575,0.2237,-1.1086,0.9018,-0.0953,629.3798,600.0024,570.2249,100.9439,71.5665,41.789,0.9084,-1.1086,0.2171,599.8691,71.4331,59.1549,0.5034,2.4156,-16.6718,0.0169,90.0701
1,109.5,109.5,594.9,58096.16,531,-65,0.1858,530.6423,0.4696,0,0,0.0528,0.0522,0.0518,0,0,0,5.5295,0,0,100,0,0,0,0,0,0,0,0,0,0,608.3913,18263.75,-0.1339,-1.2538,0,0,0,0,0,0,0,0,0,0,4.8692,0.241,0.1186,0.1186,618.4985,87.8562,64.2578,23.5985,1.0397,1.3672,7872.614,0.2397,602.7662,72.1239,11.7993,-65,-26.8308,76.057,-0.3577,-0.0041,0,0,1530427,-530.6423,0,0,0,1.53E+08,0,0,49.7597,29.5342,624.4394,599.925,575.1994,-6.1434,0.241,-1.1149,0.8905,-0.0487,625.1943,599.925,574.4445,94.552,69.2827,43.8023,0.8923,-1.1149,0.2392,599.8546,69.2123,50.7497,0.5021,2.1586,-7.0054,0.0166,90.0375
1,120.5,120.5,594.88,58177.18,533,-65,0.1877,532.3604,0.5031,0,0,0.0528,0.0522,0.0518,0,0,0,5.5775,0,0,100,0,0,0,0,0,0,0,0,0,0,608.5521,18219.93,0.027,1.2925,0,0,0,0,0,0,0,0,0,0,4.8718,0.2582,0.1272,0.1272,618.722,86.3616,62.5196,23.842,1.0401,1.3814,7873.972,0.2569,602.8273,70.4669,11.921,-65,-27.8668,74.4406,-0.6396,-0.0074,0,0,1530427,-532.3604,0,0,0,1.53E+08,0,0,49.7647,29.5379,624.691,599.9724,574.9141,6.3313,0.2582,-1.1213,0.8794,0.0098,625.4836,599.9724,574.1215,93.1232,67.612,41.7611,0.8795,-1.1213,0.2581,599.8592,67.4988,51.3621,0.5033,2.2299,7.1363,0.0163,89.9921
1,131.5,131.5,594.99,58256.68,534,-65,0.1869,533.6588,0.535,0,0,0.0528,0.0522,0.0518,0,0,0,5.6198,0,0,100,0,0,0,0,0,0,0,0,0,0,608.4506,18216.8,0.198,3.3235,0,0,0,0,0,0,0,0,0,0,4.8726,0.2746,0.1355,0.1355,618.7219,85.0631,61.3312,23.7319,1.0399,1.3869,7875.267,0.2734,602.9006,69.2418,11.866,-65,-32.1029,73.1972,-0.3412,-0.004,0,0,1530427,-533.6588,0,0,0,1.53E+08,0,0,49.7688,29.5404,624.7512,600.0037,575.3328,16.2761,0.2746,-1.1291,0.871,0.072,629.6301,600.0037,570.4539,95.9713,66.3449,36.7951,0.8753,-1.1291,0.2703,600.0292,66.3704,59.1762,0.4994,2.6083,16.6866,0.0165,89.9397
1,142.5,142.5,594.83,58259.98,535,-65,0.1854,534.6678,0.5687,0,0,0.0528,0.0522,0.0518,0,0,0,5.6824,0,0,100,0,0,0,0,0,0,0,0,0,0,608.2931,18261.25,0.299,4.1007,0,0,0,0,0,0,0,0,0,0,4.8707,0.2919,0.1441,0.1441,618.3733,83.7055,60.1622,23.5433,1.0396,1.3913,7876.633,0.2907,602.6778,68.01,11.7717,-65,-28.6352,71.9339,-0.3322,-0.004,0,0,1530427,-534.6678,0,0,0,1.53E+08,0,0,49.7724,29.5418,624.2866,599.8445,575.1705,20.0775,0.2919,-1.1399,0.8647,0.1088,631.4493,599.8445,568.0078,96.7815,65.1767,33.34,0.8749,-1.1399,0.2817,599.7672,65.0994,63.4415,0.5018,2.9029,19.6339,0.0167,89.9054
1,153.5,153.5,594.76,58300.98,537,-65,0.1866,536.4467,0.6037,0,0,0.0528,0.0522,0.0518,0,0,0,5.7348,0,0,100,0,0,0,0,0,0,0,0,0,0,608.3268,18263.75,0.2342,3.3161,0,0,0,0,0,0,0,0,0,0,4.8721,0.3098,0.1531,0.1531,618.44,81.9933,58.3133,23.68,1.0398,1.4061,7878.047,0.3086,602.6533,66.2066,11.84,-65,-28.456,70.1533,-0.5533,-0.0067,0,0,1530427,-536.4467,0,0,0,1.53E+08,0,0,49.7769,29.5444,624.3915,599.8132,574.9493,16.2316,0.3098,-1.1492,0.8556,0.0853,629.244,599.8132,570.0968,92.7973,63.3665,33.6501,0.8622,-1.1492,0.3032,599.718,63.2713,59.1472,0.5024,2.7577,16.6442,0.0162,89.922
1,164.5,164.5,594.73,58309.29,538,-65,0.1872,538.2175,0.6381,0,0,0.0528,0.0522,0.0518,0,0,0,5.7984,0,0,100,0,0,0,0,0,0,0,0,0,0,608.7131,18259.38,0.1014,1.2052,0,0,0,0,0,0,0,0,0,0,4.8733,0.3275,0.162,0.162,618.4825,80.265,56.5125,23.7525,1.0399,1.4203,7879.447,0.3263,602.6475,64.43,11.8763,-65,-29.1663,68.3888,0.2175,0.0027,0,0,1530427,-538.2175,0,0,0,1.53E+08,0,0,49.7813,29.5471,624.2475,599.9382,574.311,5.8976,0.3275,-1.1574,0.8466,0.0369,624.9346,599.9382,573.6239,86.717,61.7206,35.4064,0.8479,-1.1574,0.3262,599.4989,61.2813,51.3106,0.5128,2.4492,6.645,0.0167,89.9645
1,175.5,175.5,594.63,58359.29,540,-65,0.1877,539.769,0.6749,0,0,0.0528,0.0522,0.0518,0,0,0,5.8615,0,0,100,0,0,0,0,0,0,0,0,0,0,608.5516,18251.86,-0.0855,-1.2741,0,0,0,0,0,0,0,0,0,0,4.8739,0.3464,0.1715,0.1715,618.4414,78.6724,54.861,23.8114,1.04,1.434,7880.941,0.3453,602.5671,62.7981,11.9057,-65,-28.1847,66.7667,-0.231,-0.0029,0,0,1530427,-539.769,0,0,0,1.53E+08,0,0,49.7862,29.5501,624.2729,599.8153,574.3008,-6.233,0.3464,-1.1667,0.8366,-0.0311,625.0386,599.8153,573.5351,85.2696,60.0463,33.7661,0.8376,-1.1667,0.3454,599.463,59.694,51.5035,0.5103,2.5253,-7.0035,0.0163,90.0317
1,186.5,186.5,595.01,58355.71,541,-65,0.1874,540.5222,0.7104,0,0,0.0528,0.0522,0.0518,0,0,0,5.9155,0,0,100,0,0,0,0,0,0,0,0,0,0,608.4664,18272.52,-0.288,-3.3239,0,0,0,0,0,0,0,0,0,0,4.8775,0.3646,0.1807,0.1807,618.7852,78.263,54.4878,23.7752,1.04,1.4363,7882.38,0.3635,602.9351,62.4129,11.8876,-65,-39.5346,66.3754,-0.4778,-0.0061,0,0,1530427,-540.5222,0,0,0,1.53E+08,0,0,49.7904,29.5522,624.8399,600.022,575.3608,-16.2564,0.3646,-1.177,0.8286,-0.1049,629.703,600.022,570.4977,89.1808,59.4998,29.9755,0.8402,-1.177,0.353,600.0742,59.552,59.2053,0.4987,2.9751,-16.6545,0.0162,90.1126
1,197.5,197.5,594.92,58350.29,542,-65,0.186,541.1387,0.7487,0,0,0.0528,0.0522,0.0518,0,0,0,5.9675,0,0,100,0,0,0,0,0,0,0,0,0,0,608.1764,18344.5,-0.4084,-4.0934,0,0,0,0,0,0,0,0,0,0,4.8763,0.3842,0.1905,0.1905,618.5112,77.3726,53.7813,23.5913,1.0397,1.4387,7883.932,0.3831,602.7838,61.6451,11.7957,-65,-36.8595,65.577,-0.8613,-0.0111,0,0,1530427,-541.1387,0,0,0,1.53E+08,0,0,49.7941,29.5532,624.5749,599.8573,575.5646,-20.0148,0.3842,-1.1902,0.8226,-0.1488,631.7098,599.8573,568.4296,90.5711,58.7186,27.291,0.8465,-1.1902,0.3603,599.999,58.8602,63.2801,0.4966,3.3187,-19.6203,0.0166,90.1685
1,208.5,208.5,594.85,58336.51,543,-65,0.1852,542.931,0.7892,0,0,0.0528,0.0522,0.0518,0,0,0,6.0535,0,0,100,0,0,0,0,0,0,0,0,0,0,608.5883,18398.83,-0.3533,-3.3227,0,0,0,0,0,0,0,0,0,0,4.8759,0.405,0.201,0.201,618.3313,75.4003,51.919,23.4813,1.0395,1.4523,7885.578,0.404,602.6771,59.7461,11.7407,-65,-36.1859,63.6597,-0.069,-0.0009,0,0,1530427,-542.931,0,0,0,1.53E+08,0,0,49.7984,29.5547,624.0773,599.9668,574.7927,-16.2418,0.405,-1.2038,0.8152,-0.1288,628.9484,599.9668,569.9216,86.0174,57.0358,26.9905,0.8345,-1.2038,0.3857,599.6123,56.6812,59.0269,0.509,3.187,-16.6945,0.0164,90.1561
1,219.5,219.5,594.79,58366.46,545,-65,0.1863,544.8108,0.8283,0,0,0.0528,0.0522,0.0518,0,0,0,6.1102,0,0,100,0,0,0,0,0,0,0,0,0,0,608.7047,18396.46,-0.2115,-1.2572,0,0,0,0,0,0,0,0,0,0,4.8775,0.4251,0.2111,0.2111,618.4094,73.5986,49.9792,23.6195,1.0397,1.4726,7887.17,0.4241,602.6631,57.8523,11.8098,-65,-35.9491,61.7889,-0.1892,-0.0026,0,0,1530427,-544.8108,0,0,0,1.53E+08,0,0,49.8035,29.5578,624.1319,599.9725,574.4751,-6.1435,0.4251,-1.2136,0.8048,-0.0771,624.8806,599.9725,573.7263,80.0698,55.1617,28.9155,0.8125,-1.2136,0.4174,599.5264,54.7157,51.1543,0.5131,2.7691,-6.949,0.0163,90.1013
1,230.5,230.5,594.75,58401.3,547,-65,0.1861,546.5133,0.8701,0,0,0.0528,0.0522,0.0518,0,0,0,6.1921,0,0,100,0,0,0,0,0,0,0,0,0,0,608.4371,18370.8,0.0067,1.2609,0,0,0,0,0,0,0,0,0,0,4.878,0.4465,0.2219,0.2219,618.3399,71.8266,48.2367,23.5899,1.0397,1.489,7888.865,0.4456,602.6133,56.1,11.795,-65,-36.158,60.0317,-0.4867,-0.0068,0,0,1530427,-546.5133,0,0,0,1.53E+08,0,0,49.8093,29.5617,624.1677,599.8477,574.7667,6.1595,0.4465,-1.2229,0.7925,0.0024,624.9241,599.8477,574.0103,78.4108,53.3344,27.497,0.7925,-1.2229,0.4465,599.594,53.0807,50.9138,0.5075,2.8516,7.0011,0.0161,89.9965
1,241.5,241.5,594.94,58407.31,547,-65,0.1867,547.2005,0.9098,0,0,0.0528,0.0522,0.0518,0,0,0,6.2577,0,0,100,0,0,0,0,0,0,0,0,0,0,608.4987,18389.79,0.2531,3.3214,0,0,0,0,0,0,0,0,0,0,4.8811,0.4669,0.2321,0.2321,618.6061,71.4056,47.7395,23.6661,1.0398,1.4957,7890.482,0.466,602.8287,55.6282,11.8331,-65,-43.1554,59.5726,0.2005,0.0028,0,0,1530427,-547.2005,0,0,0,1.53E+08,0,0,49.814,29.5642,624.5392,599.9899,575.1446,16.2203,0.4669,-1.2336,0.7833,0.0924,629.3894,599.9899,570.2944,82.1889,52.7894,23.0939,0.7963,-1.2336,0.4539,599.8913,52.6907,59.095,0.5025,3.5589,16.6477,0.0166,89.8544
1,252.5,252.5,594.85,58402.28,548,-65,0.1887,547.731,0.9556,0,0,0.0528,0.0522,0.0518,0,0,0,6.3355,0,0,100,0,0,0,0,0,0,0,0,0,0,608.1195,18454.6,0.4015,4.1308,0,0,0,0,0,0,0,0,0,0,4.8835,0.4904,0.244,0.244,618.7641,71.0331,47.119,23.9141,1.0402,1.5075,7892.346,0.4896,602.8214,55.0904,11.9571,-65,-40.2883,59.0761,-0.269,-0.0038,0,0,1530427,-547.731,0,0,0,1.53E+08,0,0,49.8189,29.5659,624.9944,599.7921,575.4787,20.1664,0.4904,-1.2492,0.775,0.1466,632.1683,599.7921,568.3049,84.4373,52.0611,20.5739,0.8088,-1.2492,0.4566,600.0884,52.3574,63.8634,0.493,4.1041,19.5822,0.0162,89.7443
1,263.5,263.5,594.84,58373.1,549,-65,0.1868,549.5192,1.0052,0,0,0.0528,0.0522,0.0518,0,0,0,6.4304,0,0,100,0,0,0,0,0,0,0,0,0,0,608.2935,18516.56,0.3465,3.3045,0,0,0,0,0,0,0,0,0,0,4.8827,0.5159,0.2568,0.2568,618.5042,68.985,45.3208,23.6642,1.0398,1.5221,7894.369,0.5151,602.7281,53.2089,11.8321,-65,-41.4641,57.1529,0.5192,0.0075,0,0,1530427,-549.5192,0,0,0,1.53E+08,0,0,49.8242,29.5679,624.4997,599.8505,575.2021,16.1268,0.5159,-1.2653,0.7657,0.1265,629.3066,599.8505,570.3952,79.7874,50.3313,20.876,0.7944,-1.2653,0.4872,599.8508,50.3316,58.9114,0.5,3.822,16.5976,0.0163,89.7481
1,274.5,274.5,594.95,58378.34,551,-65,0.1863,551.5609,1.0596,0,0,0.0528,0.0522,0.0518,0,0,0,6.5127,0,0,100,0,0,0,0,0,0,0,0,0,0,608.4492,18539.81,0.1989,1.2714,0,0,0,0,0,0,0,0,0,0,4.8844,0.5438,0.2709,0.2709,618.546,66.9851,43.3891,23.596,1.0397,1.5438,7896.583,0.5431,602.8154,51.2545,11.798,-65,-47.6343,55.1871,0.5609,0.0084,0,0,1530427,-551.5609,0,0,0,1.53E+08,0,0,49.8308,29.5714,624.4759,599.9775,575.246,6.2022,0.5438,-1.2804,0.7529,0.0727,625.2453,599.9775,574.4766,73.6844,48.4166,22.9157,0.7649,-1.2804,0.5318,599.8998,48.3389,50.7687,0.5023,3.2155,7.0712,0.0163,89.8265
1,285.5,285.5,594.86,58430.42,553,-65,0.1862,553.475,1.1225,0,0,0.0528,0.0522,0.0518,0,0,0,6.63,0,0,100,0,0,0,0,0,0,0,0,0,0,608.7227,18529.37,-0.0778,-1.2808,0,0,0,0,0,0,0,0,0,0,4.8851,0.5761,0.2872,0.2872,618.4337,64.9587,41.385,23.5737,1.0396,1.5696,7899.148,0.5755,602.7179,49.2429,11.7869,-65,-45.5875,53.1719,0.475,0.0073,0,0,1530427,-553.475,0,0,0,1.53E+08,0,0,49.8391,29.5765,624.1563,600.0228,574.6252,-6.245,0.5761,-1.296,0.7359,-0.0284,624.9316,600.0228,573.8499,71.4566,46.5479,20.3749,0.7384,-1.296,0.5736,599.6014,46.1265,51.0817,0.5124,3.5071,-7.0765,0.016,90.0888
1,296.5,296.5,594.7,58404.43,554,-65,0.1865,553.8481,1.1852,0,0,0.0528,0.0522,0.0518,0,0,0,6.7376,0,0,100,0,0,0,0,0,0,0,0,0,0,608.4644,18582.99,-0.4104,-3.3294,0,0,0,0,0,0,0,0,0,0,4.8856,0.6082,0.3034,0.3034,618.2974,64.4493,40.8519,23.5974,1.0397,1.5776,7901.7,0.6077,602.5659,48.7178,11.7987,-65,-40.3454,52.6506,-0.1519,-0.0024,0,0,1530427,-553.8481,0,0,0,1.53E+08,0,0,49.8462,29.5798,624.0981,599.8262,574.6102,-16.2263,0.6082,-1.3145,0.7227,-0.1501,628.9439,599.8262,569.7643,75.0958,45.9781,15.9162,0.786,-1.3145,0.5449,599.5114,45.6634,59.1796,0.508,4.7182,-16.6278,0.0164,90.6506
1,307.5,307.5,594.81,58299.38,554,-65,0.1853,554.1316,1.2571,0,0,0.0528,0.0522,0.0518,0,0,0,6.834,0,0,100,0,0,0,0,0,0,0,0,0,0,608.2184,18767.63,-0.6251,-4.1,0,0,0,0,0,0,0,0,0,0,4.8871,0.6451,0.322,0.322,618.2576,64.126,40.6784,23.4476,1.0394,1.5764,7904.634,0.6447,602.6259,48.4943,11.7238,-65,-44.2469,52.4022,0.1316,0.0021,0,0,1530427,-554.1316,0,0,0,1.53E+08,0,0,49.8525,29.5802,624.1531,599.8032,575.2452,-19.9726,0.6451,-1.3432,0.7142,-0.2287,631.2728,599.8032,568.1254,77.1412,45.6716,13.9938,0.845,-1.3432,0.5143,599.7338,45.6022,63.1474,0.5016,5.5125,-19.62,0.0161,91.6269
1,318.5,318.5,594.8,58143.12,556,-65,0.1887,555.8902,1.34,0,0,0.0528,0.0522,0.0518,0,0,0,6.9855,0,0,100,0,0,0,0,0,0,0,0,0,0,608.2785,18953.93,-0.6009,-3.3134,0,0,0,0,0,0,0,0,0,0,4.8924,0.6877,0.3435,0.3435,618.6627,62.7725,38.9098,23.8627,1.0401,1.6133,7908.025,0.6875,602.7542,46.864,11.9314,-65,-45.3253,50.8412,-0.1098,-0.0017,0,0,1530427,-555.8902,0,0,0,1.53E+08,0,0,49.8601,29.5813,624.7636,599.819,575.1384,-16.1319,0.6877,-1.3748,0.7032,-0.2199,629.5467,599.819,570.3554,73.6565,43.9288,14.4652,0.8511,-1.3748,0.5398,599.907,44.0168,59.1913,0.4978,5.092,-16.5149,0.0161,96.9824
1,329.5,329.5,594.8,58054,558,-65,0.1871,558.5129,1.4346,0,0,0.0528,0.0522,0.0518,0,0,0,7.1234,0,0,100,0,0,0,0,0,0,0,0,0,0,608.6033,19076.88,-0.4545,-1.2677,0,0,0,0,0,0,0,0,0,0,4.8931,0.7362,0.368,0.368,618.449,59.9361,36.2871,23.649,1.0398,1.6517,7911.889,0.7361,602.683,44.1701,11.8245,-65,-47.475,48.1116,0.5129,0.0086,0,0,1530427,-558.5129,0,0,0,1.53E+08,0,0,49.8702,29.5851,624.2548,599.9396,574.6684,-6.1679,0.7362,-1.4055,0.6855,-0.1665,625.0105,599.9396,573.9127,66.4976,41.4267,15.3998,0.8313,-1.4055,0.5904,599.6209,41.108,51.0978,0.5094,4.3181,-6.985,0.0162,-1.6271
1,340.5,340.5,594.83,58045.34,561,-65,0.1858,561.1573,1.5513,0,0,0.0528,0.0522,0.0518,0,0,0,7.3206,0,0,100,0,0,0,0,0,0,0,0,0,0,608.5671,19157.63,-0.0769,1.2675,0,0,0,0,0,0,0,0,0,0,4.8949,0.7961,0.3983,0.3983,618.3032,57.1459,33.6727,23.4732,1.0395,1.6971,7916.666,0.7963,602.6544,41.4971,11.7366,-65,-50.8952,45.4093,0.1573,0.0028,0,0,1530427,-561.1573,0,0,0,1.53E+08,0,0,49.8839,29.5918,624.0431,599.9449,574.7974,6.1616,0.7961,-1.4395,0.6597,-0.0282,624.8024,599.9449,574.0382,63.6451,38.7876,12.8809,0.799,-1.4395,0.6568,599.5952,38.4379,50.7642,0.5103,4.941,7.0246,0.0163,-0.1033
1,351.5,351.5,594.89,57910.33,562,-65,0.186,561.4138,1.6765,0,0,0.0528,0.0522,0.0518,0,0,0,7.5146,0,0,100,0,0,0,0,0,0,0,0,0,0,608.2652,19371.08,0.4571,3.3045,0,0,0,0,0,0,0,0,0,0,4.8986,0.8604,0.4309,0.4309,618.3695,56.9557,33.4762,23.4795,1.0395,1.7014,7921.801,0.8609,602.7165,41.3027,11.7398,-65,-53.8245,45.216,-0.5862,-0.0103,0,0,1530427,-561.4138,0,0,0,1.53E+08,0,0,49.8966,29.5955,624.3181,599.8698,575.3912,16.0501,0.8604,-1.4832,0.6389,0.1677,629.1132,599.8698,570.596,67.6994,38.456,9.1822,0.9119,-1.4832,0.5874,599.8597,38.4459,58.5172,0.5003,7.3729,16.6341,0.0161,0.3751
1,362.5,362.5,595.28,57592.48,562,-65,0.1864,561.2321,1.8285,0,0,0.0528,0.0522,0.0518,0,0,0,7.7765,0,0,100,0,0,0,0,0,0,0,0,0,0,608.0382,19786.59,0.8494,4.091,0,0,0,0,0,0,0,0,0,0,4.9058,0.9384,0.4704,0.4704,618.7912,57.5591,34.0479,23.5112,1.0395,1.6905,7928.038,0.9392,603.1171,41.885,11.7556,-65,-81.9473,45.8035,-0.7679,-0.0133,0,0,1530427,-561.2321,0,0,0,1.53E+08,0,0,49.9094,29.5956,625.0984,600.0292,576.6924,19.8509,0.9384,-1.5448,0.6226,0.3119,632.1978,600.0292,569.593,70.9657,38.7971,8.3609,1.0517,-1.5448,0.5093,600.6067,39.3746,62.6048,0.4862,8.4878,19.679,0.0162,0.4787
1,373.5,373.5,594.75,57180.63,563,-65,0.1855,563.0159,2.01,0,0,0.0528,0.0522,0.0518,0,0,0,8.086,0,0,100,0,0,0,0,0,0,0,0,0,0,608.408,20262.45,0.9045,3.3203,0,0,0,0,0,0,0,0,0,0,4.9051,1.0315,0.5176,0.5176,618.1214,55.1055,31.7341,23.3714,1.0393,1.7365,7935.496,1.0327,602.5405,39.5246,11.6857,-65,-49.152,43.4198,0.0159,0.0003,0,0,1530427,-563.0159,0,0,0,1.53E+08,0,0,49.925,29.5962,623.8752,599.8333,574.8655,16.0924,1.0315,-1.6174,0.6021,0.3326,628.6868,599.8333,570.054,65.6709,36.8174,7.0381,1.1352,-1.6174,0.4984,599.5247,36.5088,58.6328,0.5079,9.3308,16.6465,0.0162,0.3739
1,384.5,384.5,594.64,56797.36,566,-65,0.1866,566.4509,2.2364,0,0,0.0528,0.0522,0.0518,0,0,0,8.4333,0,0,100,0,0,0,0,0,0,0,0,0,0,608.7414,20801.18,0.7774,1.2588,0,0,0,0,0,0,0,0,0,0,4.9109,1.1477,0.5767,0.5767,618.1257,51.6747,28.1891,23.4857,1.0395,1.8331,7944.824,1.1496,602.4686,36.0177,11.7429,-65,-47.7238,39.9319,0.4509,0.0087,0,0,1530427,-566.4509,0,0,0,1.53E+08,0,0,49.9454,29.5986,623.7063,599.8872,574.1267,6.0919,1.1477,-1.7044,0.5733,0.2863,624.4438,599.8872,573.3892,57.9929,33.4363,6.9383,1.2119,-1.7044,0.5091,599.2401,32.7892,51.0546,0.519,8.3584,6.9032,0.0166,0.2427
1,395.5,395.5,594.88,56393.22,569,-65,0.1858,569.7189,2.547,0,0,0.0528,0.0522,0.0518,0,0,0,8.9544,0,0,100,0,0,0,0,0,0,0,0,0,0,608.559,21381.69,0.0521,-1.2323,0,0,0,0,0,0,0,0,0,0,4.9197,1.3071,0.6579,0.6579,618.2349,48.5161,25.1611,23.3549,1.0393,1.9282,7957.656,1.31,602.665,32.9461,11.6775,-65,-60.6369,36.8386,0.7189,0.0148,0,0,1530427,-569.7189,0,0,0,1.53E+08,0,0,49.9761,29.6062,623.9667,599.9689,574.9985,-5.951,1.3071,-1.8159,0.5249,0.0192,624.6795,599.9689,574.2856,54.9606,30.25,4.5667,1.3073,-1.8159,0.5247,599.6447,29.9258,50.3939,0.5097,12.0351,-6.8306,0.0161,0.0123
1,406.5,406.5,594.91,55767.43,569,-65,0.186,568.7827,2.8789,0,0,0.0528,0.0522,0.0518,0,0,0,9.4717,0,0,100,0,0,0,0,0,0,0,0,0,0,608.018,22229.21,-1.0773,-3.3326,0,0,0,0,0,0,0,0,0,0,4.9283,1.4774,0.7448,0.7448,618.2469,49.4642,26.1273,23.3369,1.0392,1.8932,7971.411,1.4815,602.689,33.9063,11.6685,-65,-61.4306,37.7958,-0.2173,-0.0044,0,0,1530427,-568.7827,0,0,0,1.53E+08,0,0,50.0052,29.6081,624.2931,599.7849,575.8826,-16.0592,1.4774,-1.9468,0.4857,-0.3984,629.136,599.7849,571.0398,60.3533,31.0022,2.2571,1.5518,-1.9468,0.4113,599.9869,31.2042,58.0962,0.4948,26.7393,-16.7813,0.0163,-0.1911
1,417.5,417.5,595.01,54974.99,568,-65,0.1851,567.4042,3.2399,0,0,0.0528,0.0522,0.0518,0,0,0,10.0679,0,0,100,0,0,0,0,0,0,0,0,0,0,607.7112,23227.23,-1.8635,-4.0846,0,0,0,0,0,0,0,0,0,0,4.9371,1.6627,0.8397,0.8397,618.186,50.7818,27.6058,23.176,1.039,1.8395,7986.432,1.6683,602.7354,35.3312,11.588,-65,-66.1501,39.1938,-0.5958,-0.0117,0,0,1530427,-567.4042,0,0,0,1.53E+08,0,0,50.0358,29.608,624.3809,599.7318,576.601,-19.6374,1.6627,-2.0942,0.4472,-0.6907,631.416,599.7318,569.5659,64.0118,32.3276,2.1617,1.8346,-2.0942,0.2753,600.2379,32.8337,61.8501,0.4877,29.6118,-19.71,0.0157,-0.2486
1,428.5,428.5,594.77,54108.23,569,-65,0.1875,569.1765,3.6471,0,0,0.0528,0.0522,0.0518,0,0,0,10.7272,0,0,100,0,0,0,0,0,0,0,0,0,0,607.9843,24378.66,-2.0203,-3.308,0,0,0,0,0,0,0,0,0,0,4.9477,1.8717,0.9471,0.9471,618.1965,49.02,25.5935,23.4265,1.0394,1.9153,8003.442,1.8792,602.5789,33.4024,11.7133,-65,-54.8677,37.3068,0.1765,0.0036,0,0,1530427,-569.1765,0,0,0,1.53E+08,0,0,50.0698,29.6071,624.2717,599.6804,575.6505,-15.8625,1.8717,-2.2612,0.4055,-0.7508,628.9891,599.6804,570.9331,59.8126,30.5039,1.7566,2.0437,-2.2612,0.2335,599.8675,30.691,58.056,0.4952,34.0502,-16.5621,0.016,-0.2196
1,439.5,439.5,594.86,53310.91,572,-65,0.1838,572.6484,4.1228,0,0,0.0528,0.0522,0.0518,0,0,0,11.4592,0,0,100,0,0,0,0,0,0,0,0,0,0,608.6971,25475.49,-1.8589,-1.2824,0,0,0,0,0,0,0,0,0,0,4.9566,2.1158,1.0728,1.0728,617.768,45.1196,22.2116,22.908,1.0385,2.0314,8023.4,2.1257,602.496,29.8476,11.454,-65,-62.1158,33.6656,0.6484,0.0144,0,0,1530427,-572.6484,0,0,0,1.53E+08,0,0,50.114,29.6131,623.2306,599.9995,574.8726,-6.1299,2.1158,-2.4433,0.3423,-0.693,623.9955,599.9995,574.1077,51.3471,27.3511,1.4594,2.2422,-2.4433,0.2159,599.3676,26.7192,49.8877,0.519,35.1837,-7.113,0.0148,-0.1709
1,450.5,450.5,594.9,52502.18,576,-65,0.1835,576.2725,4.7372,0,0,0.0528,0.0522,0.0518,0,0,0,12.4596,0,0,100,0,0,0,0,0,0,0,0,0,0,608.281,26502.06,-0.4327,1.2253,0,0,0,0,0,0,0,0,0,0,4.972,2.4311,1.236,1.236,617.6913,41.4188,18.6275,22.7913,1.0383,2.2235,8049.329,2.4447,602.4971,26.2246,11.3957,-65,-67.5723,30.0232,0.2725,0.0066,0,0,1530427,-576.2725,0,0,0,1.53E+08,0,0,50.1778,29.632,623.3559,599.8682,575.6014,5.8317,2.4311,-2.6565,0.2383,-0.162,624.0577,599.8682,574.8995,47.7852,23.5957,-1.373,2.4371,-2.6565,0.2323,599.6085,23.336,49.1582,0.5079,-34.8035,6.8625,0.0129,-0.0366
1,461.5,461.5,595.22,51445.78,573,-65,0.1886,573.4403,5.2937,0,0,0.0528,0.0522,0.0518,0,0,0,13.4079,0,0,100,0,0,0,0,0,0,0,0,0,0,607.873,27846.61,1.549,3.3023,0,0,0,0,0,0,0,0,0,0,4.9938,2.7167,1.3845,1.3845,618.5836,45.1433,21.7797,23.3637,1.0393,2.0727,8072.959,2.7341,603.0079,29.5676,11.6819,-65,-91.055,33.4615,0.4403,0.0098,0,0,1530427,-573.4403,0,0,0,1.53E+08,0,0,50.2289,29.6374,624.9659,599.9153,577.0084,15.659,2.7167,-2.8726,0.1674,0.5821,629.626,599.9153,572.3483,56.1857,26.475,-1.092,2.7815,-2.8726,0.1026,600.6299,27.1896,57.2777,0.4813,-51.4521,16.573,0.0115,0.1034
1,472.5,472.5,595.28,50368.18,572,-65,0.1859,571.0407,5.8278,0,0,0.0528,0.0522,0.0518,0,0,0,14.2931,0,0,100,0,0,0,0,0,0,0,0,0,0,607.7339,29238.23,2.6089,4.0674,0,0,0,0,0,0,0,0,0,0,5.0052,2.9908,1.5276,1.5276,618.2488,47.2081,24.2393,22.9688,1.0386,1.9476,8095.77,3.0123,602.9363,31.8956,11.4844,-65,-95.2024,35.7237,-0.9593,-0.0203,0,0,1530427,-571.0407,0,0,0,1.53E+08,0,0,50.2765,29.6397,624.526,599.899,577.3931,19.2193,2.9908,-3.0858,0.1049,0.9839,631.3694,599.899,570.5497,60.3287,28.8583,-0.491,3.1498,-3.0858,-0.0541,600.606,29.5653,60.8197,0.4826,-122.869,19.5993,0.0099,0.1347
1,483.5,483.5,595.02,49225.25,572,-65,0.1856,572.4103,6.4078,0,0,0.0528,0.0522,0.0518,0,0,0,15.1874,0,0,100,0,0,0,0,0,0,0,0,0,0,607.8008,30692.01,2.7236,3.3134,0,0,0,0,0,0,0,0,0,0,5.0176,3.2884,1.6837,1.6837,617.8791,45.4688,22.6097,22.8591,1.0384,2.011,8120.682,3.3147,602.6397,30.2294,11.4296,-65,-71.8184,34.0393,0.4103,0.009,0,0,1530427,-572.4103,0,0,0,1.53E+08,0,0,50.3294,29.6439,623.9431,599.7575,576.7042,15.5962,3.2884,-3.3139,0.0334,1.0311,628.6277,599.7575,572.0196,56.2174,27.3472,-0.3907,3.4443,-3.3139,-0.1225,600.1349,27.7246,56.6081,0.49,-143.8889,16.7186,0.0079,0.123
1,494.5,494.5,594.93,48149.05,575,-65,0.1834,576.067,7.0506,0,0,0.0528,0.0522,0.0518,0,0,0,16.2705,0,0,100,0,0,0,0,0,0,0,0,0,0,608.2135,32089.41,2.4114,1.3096,0,0,0,0,0,0,0,0,0,0,5.0312,3.6183,1.8576,1.8576,617.4404,41.3734,18.863,22.5104,1.0378,2.1934,8148.478,3.6506,602.4335,26.3665,11.2552,-65,-69.2415,30.1182,1.067,0.0258,0,0,1530427,-576.067,0,0,0,1.53E+08,0,0,50.392,29.6547,623.0612,599.8511,575.9343,6.1372,3.6183,-3.5554,-0.0583,0.917,623.8474,599.8511,575.1483,47.7804,23.7841,-0.9187,3.7293,-3.5554,-0.1693,599.6156,23.5486,48.6991,0.5073,-52.0087,7.2993,0.0046,0.1009
1,505.5,505.5,595.12,47073.67,578,-65,0.1826,578.7449,7.8585,0,0,0.0528,0.0522,0.0518,0,0,0,17.6035,0,0,100,0,0,0,0,0,0,0,0,0,0,608.1847,33457.14,0.2982,-1.2194,0,0,0,0,0,0,0,0,0,0,5.0529,4.0329,2.0774,2.0774,617.4361,38.6912,16.3751,22.3161,1.0375,2.3628,8183.681,4.0735,602.5587,23.8138,11.1581,-65,-86.8343,27.5332,0.7449,0.0193,0,0,1530427,-578.7449,0,0,0,1.53E+08,0,0,50.4777,29.6795,623.0813,599.9575,576.4764,-5.6817,4.0329,-3.8378,-0.1961,0.114,623.7639,599.9575,575.7937,45.019,21.2127,-2.9512,4.0344,-3.8378,-0.1976,599.8384,21.0935,47.9702,0.5037,-15.2545,-6.8514,-0.001,0.0134
1,516.5,516.5,595.06,45895.84,575,-65,0.1875,575.4266,8.4902,0,0,0.0528,0.0522,0.0518,0,0,0,18.6702,0,0,100,0,0,0,0,0,0,0,0,0,0,607.891,34897.85,-2.1361,-3.3274,0,0,0,0,0,0,0,0,0,0,5.0738,4.3571,2.2503,2.2503,617.8955,42.4689,19.6334,22.8355,1.0384,2.1631,8211.421,4.4049,602.6718,27.2452,11.4178,-65,-77.951,31.0512,0.4266,0.01,0,0,1530427,-575.4266,0,0,0,1.53E+08,0,0,50.5388,29.6883,623.9784,599.8082,576.7903,-15.4368,4.3571,-4.079,-0.2831,-0.8205,628.5797,599.8082,572.189,53.1531,24.3817,-3.2375,4.4285,-4.079,-0.3545,600.1923,24.7658,56.3906,0.4898,-16.418,-16.5977,-0.005,-0.074
1,527.5,527.5,595.06,44718.01,573,-65,0.186,572.8602,9.0651,0,0,0.0528,0.0522,0.0518,0,0,0,19.6175,0,0,100,0,0,0,0,0,0,0,0,0,0,607.6505,36385.36,-3.2035,-4.0659,0,0,0,0,0,0,0,0,0,0,5.0874,4.6521,2.4083,2.4083,617.6407,44.7805,22.1998,22.5807,1.0379,2.0172,8236.827,4.7069,602.5869,29.7267,11.2904,-65,-75.2778,33.4902,-0.1398,-0.0031,0,0,1530427,-572.8602,0,0,0,1.53E+08,0,0,50.5918,29.6913,623.7295,599.7164,577.1738,-18.7901,4.6521,-4.3085,-0.3526,-1.2353,630.3669,599.7164,570.5364,57.5067,26.8561,-2.3239,4.8002,-4.3085,-0.5007,600.2065,27.3463,59.8306,0.4877,-24.7458,-19.4554,-0.009,-0.0889
1,538.5,538.5,594.93,43517.71,575,-65,0.1865,573.8957,9.6792,0,0,0.0528,0.0522,0.0518,0,0,0,20.5675,0,0,100,0,0,0,0,0,0,0,0,0,0,608.1631,37893.73,-3.1906,-3.3176,0,0,0,0,0,0,0,0,0,0,5.1031,4.9673,2.578,2.578,617.4987,43.603,21.0343,22.5687,1.0379,2.0729,8264.146,5.0302,602.4529,28.5572,11.2844,-65,-67.2495,32.3187,-1.1043,-0.0253,0,0,1530427,-573.8957,0,0,0,1.53E+08,0,0,50.65,29.6969,623.2602,599.8211,576.1747,-15.268,4.9673,-4.5487,-0.4318,-1.2355,627.7776,599.8211,571.6572,53.8819,25.9254,-2.2385,5.1051,-4.5487,-0.5696,599.752,25.8563,56.1204,0.5018,-24.0705,-16.4822,-0.0132,-0.0825
1,549.5,549.5,594.88,42383.86,576,-65,0.1838,577.4095,10.339,0,0,0.0528,0.0522,0.0518,0,0,0,21.6808,0,0,100,0,0,0,0,0,0,0,0,0,0,608.4809,39324.3,-2.7659,-1.3095,0,0,0,0,0,0,0,0,0,0,5.1176,5.3059,2.7612,2.7612,617.0469,39.6374,17.4705,22.1669,1.0373,2.2688,8293.696,5.3781,602.269,24.8595,11.0835,-65,-67.383,28.554,1.4095,0.0356,0,0,1530427,-577.4095,0,0,0,1.53E+08,0,0,50.7161,29.7084,622.4032,599.9041,575.6461,-5.9988,5.3059,-4.7968,-0.5278,-1.076,623.1606,599.9041,574.8887,45.7511,22.4946,-2.5208,5.4035,-4.7968,-0.6254,599.3178,21.9083,48.2719,0.5182,-18.1494,-7.1956,-0.0187,-0.0705
1,560.5,560.5,595.3,41410.46,580,-65,0.1825,580.7755,11.1504,0,0,0.0528,0.0522,0.0518,0,0,0,22.9855,0,0,100,0,0,0,0,0,0,0,0,0,0,608.1946,40641.3,-0.4311,1.1985,0,0,0,0,0,0,0,0,0,0,5.1415,5.7223,2.9879,2.9879,617.2026,36.4271,14.5245,21.9026,1.0368,2.508,8330.328,5.8068,602.6008,21.8253,10.9513,-65,-111.3612,25.4758,0.7755,0.0213,0,0,1530427,-580.7755,0,0,0,1.53E+08,0,0,50.8056,29.7356,622.8132,600.0606,577.1021,5.4578,5.7223,-5.0783,-0.672,-0.1687,623.4558,600.0606,576.4595,42.6803,19.2851,-4.316,5.7245,-5.0783,-0.6742,599.9919,19.2165,46.9963,0.5022,-9.8889,6.7152,-0.028,-0.0131
1,571.5,571.5,595.09,40304.98,578,-65,0.1885,576.4977,11.7302,0,0,0.0528,0.0522,0.0518,0,0,0,23.9556,0,0,100,0,0,0,0,0,0,0,0,0,0,607.7955,42022.01,2.1341,3.3067,0,0,0,0,0,0,0,0,0,0,5.1615,6.0198,3.1508,3.1508,617.6482,41.1505,18.5924,22.5582,1.0379,2.2133,8356.698,6.1137,602.6094,26.1117,11.2791,-65,-81.6198,29.8715,-1.5023,-0.0365,0,0,1530427,-576.4977,0,0,0,1.53E+08,0,0,50.8623,29.7423,623.7337,599.7782,577.1976,14.998,6.0198,-5.303,-0.7501,0.8385,628.1486,599.7782,572.7827,51.6509,23.2805,-3.715,6.0713,-5.303,-0.8016,600.2365,23.7388,55.3659,0.4876,-13.9033,16.4024,-0.0333,0.0515
1,582.5,582.5,595.06,39128.29,574,-65,0.1866,573.85,12.2498,0,0,0.0528,0.0522,0.0518,0,0,0,24.8492,0,0,100,0,0,0,0,0,0,0,0,0,0,607.9872,43485.07,3.2074,4.0622,0,0,0,0,0,0,0,0,0,0,5.1735,6.2865,3.2975,3.2975,617.3274,43.4774,21.21,22.2674,1.0374,2.0499,8380.48,6.3893,602.4825,28.6325,11.1337,-65,-76.3088,32.3437,-0.15,-0.0035,0,0,1530427,-573.85,0,0,0,1.53E+08,0,0,50.9096,29.7418,623.1535,599.8271,576.8967,18.3604,6.2865,-5.5169,-0.8077,1.2646,629.5552,599.8271,570.4951,55.7052,25.9771,-3.3549,6.3975,-5.5169,-0.9187,599.9592,26.1091,59.0601,0.4966,-16.6041,19.2221,-0.0381,0.0636
1,593.5,593.5,595.07,38049.26,575,-65,0.1861,574.9594,12.8259,0,0,0.0528,0.0522,0.0518,0,0,0,25.7157,0,0,100,0,0,0,0,0,0,0,0,0,0,608.0788,44909.77,3.1784,3.3117,0,0,0,0,0,0,0,0,0,0,5.1889,6.5821,3.4608,3.4608,617.212,42.2526,20.1106,22.142,1.0372,2.101,8406.998,6.6953,602.4507,27.4913,11.071,-65,-78.2806,31.1816,-0.0406,-0.001,0,0,1530427,-574.9594,0,0,0,1.53E+08,0,0,50.9657,29.747,622.9374,599.8644,576.8327,14.9086,6.5821,-5.7435,-0.883,1.2582,627.3382,599.8644,572.4318,52.3788,24.905,-2.5276,6.6867,-5.7435,-0.9876,599.8782,24.9187,54.9064,0.4996,-20.7227,16.4459,-0.0444,0.0602
1,604.5,604.5,594.88,37031.8,578,-65,0.182,578.7152,13.4545,0,0,0.0528,0.0522,0.0518,0,0,0,26.7245,0,0,100,0,0,0,0,0,0,0,0,0,0,608.1621,46217.41,2.7309,1.3159,0,0,0,0,0,0,0,0,0,0,5.2005,6.9047,3.6399,3.6399,616.4556,37.7404,16.1648,21.5756,1.0363,2.3347,8436.131,7.0297,602.0718,23.3566,10.7878,-65,-68.5284,26.9526,0.7152,0.019,0,0,1530427,-578.7152,0,0,0,1.53E+08,0,0,51.0314,29.7599,621.7451,599.7725,576.2976,5.8973,6.9047,-5.9775,-0.9794,1.0859,622.4979,599.7725,575.5449,43.7827,21.0573,-3.1703,6.9788,-5.9775,-1.0535,599.2718,20.5566,46.953,0.516,-13.8103,7.2743,-0.0522,0.0524
1,615.5,615.5,595.07,36202.79,581,-65,0.1838,581.6088,14.2473,0,0,0.0528,0.0522,0.0518,0,0,0,27.9905,0,0,100,0,0,0,0,0,0,0,0,0,0,607.9028,47359.01,0.2957,-1.2027,0,0,0,0,0,0,0,0,0,0,5.2259,7.3116,3.8671,3.8671,616.7589,35.1501,13.4612,21.6889,1.0364,2.6112,8473.165,7.4525,602.2996,20.6908,10.8445,-65,-85.2799,24.3057,0.6088,0.0173,0,0,1530427,-581.6088,0,0,0,1.53E+08,0,0,51.1236,29.7914,622.3663,599.7948,577.1484,-5.3579,7.3116,-6.245,-1.1308,0.1183,622.9924,599.7948,576.5222,41.3835,18.186,-5.0866,7.3124,-6.245,-1.1316,599.7698,18.161,46.4701,0.5008,-8.1358,-6.666,-0.0642,0.007
1,626.5,626.5,595.21,35187.02,578,-65,0.1883,577.6993,14.7784,0,0,0.0528,0.0522,0.0518,0,0,0,28.8717,0,0,100,0,0,0,0,0,0,0,0,0,0,607.594,48624.75,-2.1605,-3.3303,0,0,0,0,0,0,0,0,0,0,5.2465,7.5841,4.0201,4.0201,617.3697,39.6704,17.5107,22.1597,1.0372,2.2655,8498.149,7.7361,602.5966,24.8973,11.0799,-65,-95.1946,28.5906,-0.3007,-0.0076,0,0,1530427,-577.6993,0,0,0,1.53E+08,0,0,51.1771,29.7978,623.4807,599.7672,577.9496,-14.7806,7.5841,-6.4516,-1.204,-0.8675,627.858,599.7672,573.5723,50.1587,22.0679,-4.127,7.6267,-6.4516,-1.2466,600.3992,22.6999,54.2857,0.4825,-12.1538,-16.4969,-0.0715,-0.0407
1,637.5,637.5,595.18,34114.84,575,-65,0.1869,574.8929,15.2535,0,0,0.0528,0.0522,0.0518,0,0,0,29.6231,0,0,100,0,0,0,0,0,0,0,0,0,0,607.8474,49942.88,-3.1509,-4.0646,0,0,0,0,0,0,0,0,0,0,5.2582,7.8279,4.1576,4.1576,617.1142,42.2213,20.2871,21.9342,1.0369,2.0812,8520.628,7.9903,602.4914,27.5985,10.9671,-65,-88.4507,31.2542,-0.1071,-0.0025,0,0,1530427,-574.8929,0,0,0,1.53E+08,0,0,51.2219,29.798,622.9744,599.8389,577.5612,-17.9808,7.8279,-6.6463,-1.2588,-1.2693,629.2316,599.8389,571.3041,54.3388,24.946,-3.5888,7.9157,-6.6463,-1.3466,600.1249,25.232,57.9276,0.4926,-15.1412,-19.1874,-0.0772,-0.0497
1,648.5,648.5,594.92,33074.44,576,-65,0.1868,575.7257,15.7883,0,0,0.0528,0.0522,0.0518,0,0,0,30.4432,0,0,100,0,0,0,0,0,0,0,0,0,0,608.1177,51298.29,-3.0872,-3.3159,0,0,0,0,0,0,0,0,0,0,5.271,8.1024,4.3131,4.3131,616.7741,41.0484,19.1943,21.8541,1.0367,2.1386,8546.079,8.277,602.2047,26.479,10.9271,-65,-68.3012,30.1214,-0.2743,-0.0067,0,0,1530427,-575.7257,0,0,0,1.53E+08,0,0,51.2749,29.8021,622.341,599.7712,576.6028,-14.6137,8.1024,-6.8589,-1.3284,-1.2483,626.6115,599.7712,572.3323,50.8858,24.0455,-3.3934,8.1843,-6.8589,-1.4103,599.5717,23.846,54.2792,0.5055,-14.9955,-16.2896,-0.0849,-0.0475
1,659.5,659.5,594.83,32144.72,578,-65,0.1817,579.4038,16.3696,0,0,0.0528,0.0522,0.0518,0,0,0,31.3682,0,0,100,0,0,0,0,0,0,0,0,0,0,608.6542,52501.46,-2.6256,-1.3082,0,0,0,0,0,0,0,0,0,0,5.2817,8.4007,4.4828,4.4828,616.02,36.6162,15.4262,21.19,1.0356,2.3736,8573.91,8.589,601.8934,22.4896,10.595,-65,-66.2284,26.0212,1.4038,0.0383,0,0,1530427,-579.4038,0,0,0,1.53E+08,0,0,51.3374,29.8146,620.9081,599.9089,575.68,-5.7411,8.4007,-7.0753,-1.4196,-1.0662,621.6255,599.9089,574.9626,42.2217,20.5051,-4.4412,8.4582,-7.0753,-1.4771,598.8323,19.4285,46.6629,0.5346,-9.5068,-7.1225,-0.0942,-0.0416
1,670.5,670.5,594.85,31302.51,582,-65,0.1829,582.3052,17.0993,0,0,0.0528,0.0522,0.0518,0,0,0,32.5479,0,0,100,0,0,0,0,0,0,0,0,0,0,608.135,53596.9,-0.2541,1.2116,0,0,0,0,0,0,0,0,0,0,5.304,8.7752,4.697,4.697,616.0917,33.7865,12.5448,21.2417,1.0357,2.6933,8609.107,8.9815,601.9305,19.6253,10.6209,-65,-69.8378,23.1657,0.3052,0.009,0,0,1530427,-582.3052,0,0,0,1.53E+08,0,0,51.4236,29.8429,621.2997,599.7285,576.4787,5.2876,8.7752,-7.3246,-1.5585,-0.1038,621.915,599.7285,575.8633,39.6098,17.4233,-6.4419,8.7757,-7.3246,-1.559,599.1689,16.8637,46.0517,0.5182,-6.1488,6.6379,-0.1079,-0.005
1,681.5,681.5,595.12,30290.02,579,-65,0.1901,577.9583,17.5625,0,0,0.0528,0.0522,0.0518,0,0,0,33.3249,0,0,100,0,0,0,0,0,0,0,0,0,0,608.1276,54889.44,2.1852,3.3055,0,0,0,0,0,0,0,0,0,0,5.3269,9.0129,4.8337,4.8337,617.1394,39.1811,17.1617,22.0194,1.037,2.2831,8631.599,9.2311,602.4598,24.5015,11.0097,-65,-85.9604,28.1714,-1.0417,-0.0266,0,0,1530427,-577.9583,0,0,0,1.53E+08,0,0,51.4682,29.843,622.9446,599.8941,577.1693,14.3792,9.0129,-7.5153,-1.6126,0.8952,627.0867,599.8941,573.0272,49.1284,21.9358,-4.9311,9.0505,-7.5153,-1.6502,600.0026,22.0444,54.0595,0.497,-9.963,16.0696,-0.115,0.0344
1,692.5,692.5,595.09,29165.55,576,-65,0.1869,575.1718,17.9837,0,0,0.0528,0.0522,0.0518,0,0,0,34.0109,0,0,100,0,0,0,0,0,0,0,0,0,0,607.9134,56268.41,3.1658,4.0818,0,0,0,0,0,0,0,0,0,0,5.3357,9.229,4.9584,4.9584,616.6908,41.519,19.9182,21.6008,1.0363,2.0845,8652.148,9.4583,602.2903,27.1185,10.8004,-65,-80.1941,30.7186,-0.8282,-0.0199,0,0,1530427,-575.1718,0,0,0,1.53E+08,0,0,51.5053,29.8369,622.3665,599.7937,577.4325,17.706,9.229,-7.6997,-1.6501,1.3006,628.5049,599.7937,571.2941,53.3331,24.6219,-3.8777,9.3062,-7.6997,-1.7273,599.8643,24.6924,57.2108,0.4982,-13.7538,19.1206,-0.1208,0.0421
1,703.5,703.5,594.98,28133.63,576,-65,0.1859,576.3785,18.4787,0,0,0.0528,0.0522,0.0518,0,0,0,34.8126,0,0,100,0,0,0,0,0,0,0,0,0,0,607.9471,57616.21,3.1253,3.322,0,0,0,0,0,0,0,0,0,0,5.3482,9.4831,5.1056,5.1056,616.4051,40.0266,18.6015,21.4251,1.036,2.1518,8676.437,9.7258,602.1216,25.7431,10.7126,-65,-72.869,29.3141,0.3785,0.0095,0,0,1530427,-576.3785,0,0,0,1.53E+08,0,0,51.554,29.8381,621.9271,599.7336,577.1628,14.3599,9.4831,-7.9016,-1.7104,1.2884,626.1376,599.7336,572.9523,49.7591,23.3551,-3.4262,9.5568,-7.9016,-1.7841,599.6078,23.2293,53.1853,0.5035,-14.5231,16.3417,-0.1289,0.0407
1,714.5,714.5,594.98,27218.15,580,-65,0.1817,579.834,19.0251,0,0,0.0528,0.0522,0.0518,0,0,0,35.7103,0,0,100,0,0,0,0,0,0,0,0,0,0,608.5191,58839.35,2.6852,1.2967,0,0,0,0,0,0,0,0,0,0,5.36,9.7635,5.2688,5.2688,615.8515,36.0175,15.146,20.8715,1.0351,2.378,8703.397,10.0215,601.9372,22.1032,10.4358,-65,-76.1915,25.5818,-0.166,-0.0046,0,0,1530427,-579.834,0,0,0,1.53E+08,0,0,51.6126,29.8473,620.7981,599.9408,576.4135,5.5828,9.7635,-8.1106,-1.7922,1.1114,621.4896,599.9408,575.7221,41.6556,20.1068,-4.1119,9.8167,-8.1106,-1.8454,599.0508,19.2168,45.7675,0.5292,-10.1305,7.0603,-0.1393,0.0363
1,725.5,725.5,594.74,26325.49,582,-65,0.1827,582.5154,19.7309,0,0,0.0528,0.0522,0.0518,0,0,0,36.8813,0,0,100,0,0,0,0,0,0,0,0,0,0,608.2352,59979.23,0.3151,-1.2265,0,0,0,0,0,0,0,0,0,0,5.3798,10.1257,5.4807,5.4807,615.6453,33.1299,12.2246,20.9053,1.0352,2.7101,8738.473,10.4043,601.7084,19.193,10.4527,-65,-64.0013,22.6773,0.5154,0.0156,0,0,1530427,-582.5154,0,0,0,1.53E+08,0,0,51.6964,29.8727,620.6438,599.6823,576.2674,-5.252,10.1257,-8.3565,-1.9236,0.1311,621.2569,599.6823,575.6542,38.7415,17.1669,-6.8612,10.1264,-8.3565,-1.9243,598.8644,16.3491,45.6027,0.5269,-5.6465,-6.6585,-0.1544,0.0054
1,736.5,736.5,595.12,25394.4,580,-65,0.186,578.5372,20.1641,0,0,0.0528,0.0522,0.0518,0,0,0,37.6002,0,0,100,0,0,0,0,0,0,0,0,0,0,608.3975,61222.39,-1.9915,-3.2994,0,0,0,0,0,0,0,0,0,0,5.3993,10.348,5.6114,5.6114,616.3486,37.8114,16.5828,21.2286,1.0357,2.2802,8760.141,10.6396,602.1962,23.6591,10.6143,-65,-86.6035,27.1971,-1.4628,-0.0387,0,0,1530427,-578.5372,0,0,0,1.53E+08,0,0,51.7387,29.8719,621.6574,599.98,576.9818,-14.0853,10.348,-8.5371,-1.9735,-0.8313,625.7274,599.98,572.9117,47.1903,21.4428,-5.6255,10.376,-8.5371,-2.0015,599.5397,21.0025,52.8158,0.5125,-8.3886,-16.1169,-0.1626,-0.0281
1,747.5,747.5,595.01,24379.46,576,-65,0.1862,575.897,20.5567,0,0,0.0528,0.0522,0.0518,0,0,0,38.237,0,0,100,0,0,0,0,0,0,0,0,0,0,607.9158,62460.54,-2.8856,-4.0702,0,0,0,0,0,0,0,0,0,0,5.4103,10.5495,5.7303,5.7303,616.2161,40.3192,19.113,21.2061,1.0356,2.1095,8779.874,10.8532,602.0787,26.1817,10.6031,-65,-74.5588,29.7161,-0.103,-0.0026,0,0,1530427,-575.897,0,0,0,1.53E+08,0,0,51.7751,29.8677,621.7107,599.7314,577.4147,-17.3288,10.5495,-8.7066,-2.0122,-1.2078,627.6842,599.7314,571.4412,51.7872,23.8344,-4.4558,10.6073,-8.7066,-2.07,599.6189,23.7219,56.243,0.503,-11.6224,-19.02,-0.1693,-0.035
1,758.5,758.5,594.89,23424.66,577,-65,0.186,577.0797,21.0176,0,0,0.0528,0.0522,0.0518,0,0,0,38.9853,0,0,100,0,0,0,0,0,0,0,0,0,0,608.1404,63647.21,-2.8175,-3.3189,0,0,0,0,0,0,0,0,0,0,5.4229,10.786,5.8703,5.8703,616.0182,38.9385,17.8103,21.1282,1.0355,2.1863,8803.149,11.1042,601.9327,24.853,10.5641,-65,-67.6881,28.3744,0.0797,0.002,0,0,1530427,-577.0797,0,0,0,1.53E+08,0,0,51.8227,29.8709,621.3118,599.7349,576.8596,-14.0831,10.786,-8.8913,-2.0731,-1.1832,625.3979,599.7349,572.7734,48.3182,22.6552,-4.3063,10.8402,-8.8913,-2.1273,599.3021,22.2224,52.6245,0.5123,-11.2204,-16.1798,-0.1784,-0.0338
1,769.5,769.5,594.84,22573.01,579,-65,0.1833,580.0649,21.5268,0,0,0.0528,0.0522,0.0518,0,0,0,39.7912,0,0,100,0,0,0,0,0,0,0,0,0,0,608.5772,64724.68,-2.3697,-1.3234,0,0,0,0,0,0,0,0,0,0,5.4351,11.0473,6.0257,6.0257,615.5957,35.5308,14.7752,20.7557,1.0349,2.4048,8829.009,11.382,601.7586,21.6937,10.3779,-65,-67.3504,25.153,1.0649,0.03,0,0,1530427,-580.0649,0,0,0,1.53E+08,0,0,51.8797,29.8816,620.4601,599.8606,576.1798,-5.5942,11.0473,-9.0831,-2.1542,-0.999,621.1559,599.8606,575.484,41.091,19.7957,-4.5809,11.085,-9.0831,-2.1919,598.8335,18.7686,45.6719,0.5337,-8.9701,-7.0901,-0.19,-0.0297
1,780.5,780.5,595.13,21803.83,582,-65,0.1837,582.704,22.1788,0,0,0.0528,0.0522,0.0518,0,0,0,40.8364,0,0,100,0,0,0,0,0,0,0,0,0,0,608.066,65708.45,-0.0971,1.2192,0,0,0,0,0,0,0,0,0,0,5.4579,11.3819,6.2257,6.2257,615.8528,33.1488,12.426,20.7228,1.0348,2.6677,8862.345,11.7384,602.0376,19.3336,10.3614,-65,-92.2593,22.7874,0.704,0.0212,0,0,1530427,-582.704,0,0,0,1.53E+08,0,0,51.9601,29.9077,621.1094,599.8557,577.5861,5.1274,11.3819,-9.3069,-2.2815,-0.0411,621.7053,599.8557,576.9902,39.0013,17.1517,-5.7138,11.382,-9.3069,-2.2816,599.5171,16.8131,44.7151,0.5114,-6.8258,6.629,-0.2065,-0.0015
1,791.5,791.5,595.1,20917.63,580,-65,0.189,579.113,22.5595,0,0,0.0528,0.0522,0.0518,0,0,0,41.4564,0,0,100,0,0,0,0,0,0,0,0,0,0,607.8609,66814.14,2.15,3.3051,0,0,0,0,0,0,0,0,0,0,5.4746,11.5773,6.343,6.343,616.3751,37.2622,15.987,21.2752,1.0358,2.3308,8881.929,11.9469,602.1917,23.0787,10.6376,-65,-85.3449,26.6246,-0.887,-0.0238,0,0,1530427,-579.113,0,0,0,1.53E+08,0,0,51.9978,29.9066,622.0415,599.7595,577.8245,13.862,11.5773,-9.4662,-2.3251,0.9135,626.0278,599.7595,573.8381,46.9148,20.6466,-5.2749,11.6073,-9.4662,-2.355,599.8752,20.7622,52.1897,0.4967,-8.894,16.0438,-0.2139,0.0266
1,802.5,802.5,594.85,19942.35,577,-65,0.1868,576.1914,22.9107,0,0,0.0528,0.0522,0.0518,0,0,0,42.0138,0,0,100,0,0,0,0,0,0,0,0,0,0,607.9129,67990.64,3.051,4.0744,0,0,0,0,0,0,0,0,0,0,5.481,11.7575,6.4515,6.4515,615.8381,39.6467,18.6586,20.9881,1.0353,2.1248,8900.066,12.1393,601.846,25.6546,10.4941,-65,-64.6126,29.1527,-0.8086,-0.0204,0,0,1530427,-576.1914,0,0,0,1.53E+08,0,0,52.0299,29.9007,621.204,599.6173,577.1995,17.0471,11.7575,-9.6217,-2.3564,1.2995,627.0352,599.6173,571.3683,50.8438,23.4259,-4.8231,11.8171,-9.6217,-2.416,599.3403,23.1489,55.6669,0.5075,-10.5417,18.8841,-0.2206,0.0324
1,813.5,813.5,595.06,19027.58,577,-65,0.1857,576.9647,23.3442,0,0,0.0528,0.0522,0.0518,0,0,0,42.6781,0,0,100,0,0,0,0,0,0,0,0,0,0,607.9405,69154.56,2.9981,3.3072,0,0,0,0,0,0,0,0,0,0,5.4952,11.98,6.586,6.586,615.8768,38.9121,18.0953,20.8168,1.035,2.1504,8922.564,12.3773,601.999,25.0343,10.4084,-65,-79.5532,28.5037,-0.0353,-0.0009,0,0,1530427,-576.9647,0,0,0,1.53E+08,0,0,52.0749,29.9024,621.2439,599.7584,577.6891,13.7935,11.98,-9.7982,-2.412,1.281,625.2447,599.7584,573.6883,48.28,22.7937,-3.2764,12.0368,-9.7982,-2.4688,599.5638,22.5991,51.5564,0.5057,-14.7357,16.1748,-0.2302,0.0315
1,824.5,824.5,594.82,18195.56,580,-65,0.1821,580.574,23.8334,0,0,0.0528,0.0522,0.0518,0,0,0,43.4842,0,0,100,0,0,0,0,0,0,0,0,0,0,608.0887,70246.3,2.5692,1.2789,0,0,0,0,0,0,0,0,0,0,5.5046,12.231,6.7383,6.7383,615.171,34.5971,14.246,20.351,1.0342,2.4285,8948.081,12.6462,601.6037,21.0297,10.1755,-65,-66.6511,24.4216,0.574,0.0166,0,0,1530427,-580.574,0,0,0,1.53E+08,0,0,52.1299,29.9112,620.1063,599.6576,576.9575,5.3143,12.231,-9.9857,-2.4879,1.1018,620.7512,599.6576,576.3126,40.1773,19.0836,-4.2614,12.2721,-9.9857,-2.529,598.9072,18.3332,44.4387,0.5253,-9.4282,6.9189,-0.2426,0.0283
1,835.5,835.5,594.9,17363.81,583,-65,0.1834,582.946,24.4745,0,0,0.0528,0.0522,0.0518,0,0,0,44.5205,0,0,100,0,0,0,0,0,0,0,0,0,0,608.0835,71245.34,0.3095,-1.2222,0,0,0,0,0,0,0,0,0,0,5.5266,12.56,6.9389,6.9389,615.3144,32.3684,11.954,20.4144,1.0343,2.7077,8981.749,12.9993,601.7048,18.7588,10.2072,-65,-73.5308,22.1612,-0.054,-0.0017,0,0,1530427,-582.946,0,0,0,1.53E+08,0,0,52.21,29.9362,620.3485,599.7045,577.1813,-5.0529,12.56,-10.2084,-2.6127,0.1334,620.9321,599.7045,576.5977,37.9862,16.7585,-6.3483,12.5606,-10.2084,-2.6133,599.0781,16.1321,44.3345,0.5212,-5.9837,-6.5881,-0.2611,0.0044
1,846.5,846.5,595.06,16573.51,580,-65,0.1892,578.8976,24.8422,0,0,0.0528,0.0522,0.0518,0,0,0,45.1653,0,0,100,0,0,0,0,0,0,0,0,0,0,608.0916,72284.45,-1.8146,-3.3333,0,0,0,0,0,0,0,0,0,0,5.5454,12.7487,7.0545,7.0545,616.0752,37.1776,16.1624,21.0152,1.0353,2.3003,9001.174,13.2021,602.0651,23.1675,10.5076,-65,-81.5666,26.67,-1.1024,-0.0297,0,0,1530427,-578.8976,0,0,0,1.53E+08,0,0,52.2478,29.9361,621.5347,599.8068,577.5752,-13.7438,12.7487,-10.3609,-2.6573,-0.7843,625.4779,599.8068,573.632,46.5803,20.9092,-5.2656,12.7686,-10.3609,-2.6772,599.6389,20.7413,51.8459,0.5049,-8.8462,-16.0087,-0.2695,-0.0216
1,857.5,857.5,594.92,15747.78,577,-65,0.1866,576.453,25.179,0,0,0.0528,0.0522,0.0518,0,0,0,45.7325,0,0,100,0,0,0,0,0,0,0,0,0,0,607.7507,73310.09,-2.626,-4.0694,0,0,0,0,0,0,0,0,0,0,5.5522,12.9216,7.1607,7.1607,615.6083,39.1553,18.467,20.6883,1.0348,2.1203,9019.047,13.3882,601.8161,25.3631,10.3442,-65,-68.9624,28.8112,-0.547,-0.014,0,0,1530427,-576.453,0,0,0,1.53E+08,0,0,52.2812,29.9337,620.9909,599.5915,577.7337,-16.7384,12.9216,-10.5045,-2.694,-1.1377,626.7114,599.5915,572.0132,50.2584,23.1385,-4.4398,12.9629,-10.5045,-2.7353,599.4387,22.9857,54.6982,0.5042,-11.32,-18.8682,-0.2769,-0.0272
1,868.5,868.5,594.9,14973.01,577,-65,0.1862,577.5079,25.5911,0,0,0.0528,0.0522,0.0518,0,0,0,46.3923,0,0,100,0,0,0,0,0,0,0,0,0,0,608.3627,74340.11,-2.547,-3.3254,0,0,0,0,0,0,0,0,0,0,5.5647,13.1331,7.2911,7.2911,615.4957,37.9879,17.3922,20.5957,1.0346,2.1842,9041.006,13.6161,601.7653,24.2575,10.2979,-65,-68.6753,27.6901,0.5079,0.0134,0,0,1530427,-577.5079,0,0,0,1.53E+08,0,0,52.3263,29.9378,620.5292,599.7994,576.8978,-13.636,13.1331,-10.6684,-2.7522,-1.1069,624.4402,599.7994,572.9868,46.9323,22.2915,-4.5211,13.1716,-10.6684,-2.7907,599.0754,21.5676,51.4534,0.5211,-10.3807,-16.0038,-0.2875,-0.0263
1,879.5,879.5,594.77,14158.49,581,-65,0.183,580.9746,26.0479,0,0,0.0528,0.0522,0.0518,0,0,0,47.1528,0,0,100,0,0,0,0,0,0,0,0,0,0,608.6604,75377.33,-2.1189,-1.2962,0,0,0,0,0,0,0,0,0,0,5.5749,13.3675,7.4361,7.4361,614.96,33.9854,13.7954,20.19,1.0339,2.4635,9065.468,13.8691,601.5,20.5254,10.095,-65,-64.3062,23.8904,-0.0254,-0.0007,0,0,1530427,-580.9746,0,0,0,1.53E+08,0,0,52.3784,29.9456,619.5674,599.8228,576.2277,-5.2966,13.3675,-10.8448,-2.823,-0.9241,620.2053,599.8228,575.5898,39.2307,18.8482,-5.3848,13.3938,-10.8448,-2.8493,598.5393,17.5647,44.6155,0.5432,-7.2855,-6.8675,-0.3003,-0.023
1,890.5,890.5,594.94,13532.36,583,-65,0.1839,583.1942,26.6406,0,0,0.0528,0.0522,0.0518,0,0,0,48.14,0,0,100,0,0,0,0,0,0,0,0,0,0,608.0887,76203.6,0.0282,1.2288,0,0,0,0,0,0,0,0,0,0,5.5963,13.6717,7.6253,7.6253,615.153,31.9588,11.7458,20.213,1.034,2.7209,9097.412,14.198,601.6777,18.4835,10.1065,-65,-76.4824,21.8523,0.1942,0.0061,0,0,1530427,-583.1942,0,0,0,1.53E+08,0,0,52.4557,29.9723,620.1524,599.7211,577.4117,4.997,13.6717,-11.0455,-2.9456,0.0124,620.7289,599.7211,576.8352,37.5347,16.5269,-6.359,13.6717,-11.0455,-2.9456,599.095,15.9009,43.8937,0.5214,-5.9026,6.5805,-0.3194,0.0004
1,901.5,901.5,594.94,12824.47,580,-65,0.1883,579.4345,26.968,0,0,0.0528,0.0522,0.0518,0,0,0,48.713,0,0,100,0,0,0,0,0,0,0,0,0,0,607.8503,77106.24,2.1029,3.3072,0,0,0,0,0,0,0,0,0,0,5.6113,13.8397,7.7301,7.7301,615.6014,36.1669,15.5055,20.6614,1.0347,2.3325,9115.151,14.3799,601.8271,22.3926,10.3307,-65,-73.0013,25.8362,-0.5655,-0.0156,0,0,1530427,-579.4345,0,0,0,1.53E+08,0,0,52.4905,29.9729,620.9727,599.6325,577.7553,13.4163,13.8397,-11.1806,-2.9873,0.9238,624.7989,599.6325,573.9291,45.3644,20.198,-5.5054,13.865,-11.1806,-3.0126,599.4535,20.019,50.8698,0.5053,-8.24,15.9176,-0.3282,0.0222
1,903.5,903.5,594.62,12525.6,577,-65,0.1857,577.8704,26.9123,0,0,0.0528,0.0522,0.0518,0,0,0,48.6246,0,0,100,0,0,0,0,0,0,0,0,0,0,608.2004,77416.09,2.8881,3.3199,0,0,0,0,0,0,0,0,0,0,5.604,13.8111,7.7123,7.7123,615.0047,37.1343,16.7496,20.3847,1.0343,2.217,9112.126,14.3489,601.4149,23.5445,10.1924,-65,-55.198,26.942,0.8704,0.0234,0,0,1530427,-577.8704,0,0,0,1.53E+08,0,0,52.4762,29.9582,619.8976,599.5553,576.5526,13.4769,13.8111,-11.1822,-2.9531,1.2678,623.7462,599.5553,572.704,45.8758,21.6849,-5.1664,13.8589,-11.1822,-3.0009,598.6685,20.7981,51.0422,0.5261,-8.8796,15.9376,-0.3242,0.0269