File: datas/d100-60-0.175.csv
Stage Number,Time since start of test (s),Time since start of stage (s),Radial Pressure (kPa),Radial Volume (mm3),Back Pressure (kPa),Back Volume (mm3),Load Cell (kN),Pore Pressure (kPa),Axial Displacement (mm),L/C Pressure (kPa),L/C Volume (mm3),Local Axial 1,Local Axial 2,Local Radial,Base Pressure (kPa),Base Volume (mm3),Back Differential Pressure (kPa),Axial Displacement 2 (mm),Pore Air Pressure (kPa),Pore Air Volume (mm3),Atmospheric Pressure (kPa),Temperature (°C),Mid Plane PWP (kPa),Back to Cell Differential (kPa),Total Volume Change (mm3),Undefined Tx 1,Undefined Tx 2,Undefined Tx 3,Undefined Tx. 4,HCA secondary control axial load (kN),HCA secondary control torque,Internal Cell Pr. (kPa),Internal Cell Vol. (mm3),Rotational Displ. (mm),Torque,Local Int Defmn 1 (mm),Local Int Defmn 2 (mm),Circumf. Defmn 1 (mm),Circumf. Defmn 2 (mm),Circumf. Defmn 3 (mm),Outer Cell Pr 2 (kPa),Internal cell Pr 2 (kPa),Rotation 2 (°),Secondary Cell Pr (kPa),Secondary Back Pr (kPa),Axial Force (kN),Axial Strain (%),Av Diameter Change (mm),Radial Strain (%),Axial Stress (kPa),Eff. Axial Stress (kPa),Eff. Radial Stress (kPa),Deviator Stress (kPa),Total Stress Ratio (%),Eff. Stress Ratio (%),Current Area (mm2),Shear Strain (%),Cambridge p (kPa),Eff. Cambridge p' (kPa),Max Shear Stress t,Volume Change (mm3),B Value,Mean Stress s/Eff. Axial Stress 2,Excess PWP (kPa),PWP Ratio,Lower Chamber Displacement (mm),Lower Chamber Axial Load (kPa),Specimen Air Volume (mm3),Matric Suction (kPa),Voids ratio,Degree of Saturation (°),Specimen Water Volume (mm3),kRT constant,Permeability IN,Permeability OUT,HCA Outer Rad,HCA Inner Rad,HCA Sigma Z (kPa),HCA Sigma R (kPa),HCA Sigma Theta (kPa),HCA Tau Theta Z,HCA Ez,HCA Er,HCA Etheta,HCA Gamma,HCA Sigma1,HCA Sigma2,HCA Sigma3,HCA Eff Sigma1,HCA Eff Sigma2,HCA Eff Sigma3,HCA E1,HCA E2,HCA E3,HCA P,HCA Eff P,HCA Q,HCA B,HCA Eff R,HCA Alpha,HCA Ev,HCA E1 rtv
1,0,0,571.4051,83840.25,471,0,-0.0977,463.6692,2.0279,0,0,0.0528,0.0522,0.0518,0,0,0,7.729,0,0,100,0,0,0,0,0,0,0,0,0,0,566.3878,-161677.8,0.3634,4.394,0,0,0,0,0,0,0,0,0,0,4.438,1.0562,0.5323,0.5323,559.096,95.4268,107.7359,-12.3091,0.9785,0.8857,7937.814,1.059,567.3021,103.6329,-6.1546,0,-0.2694,101.5814,-7.3308,-0.0768,0,0,1507964,-463.6692,0,0,0,1.51E+08,0,0,52.8922,34.3585,555.8363,569.4293,580.7064,19.5325,1.0562,7.9115,-8.3102,0.1478,591.4263,569.4293,545.1165,127.7571,105.7601,81.4473,1.0574,7.9115,-8.3114,568.6574,104.9882,46.3098,0.525,1.5686,61.2411,0.6575,0.0078
1,15.2,15.2,571.8082,84153.25,480,0,-0.0945,473.0414,2.0502,0,0,0.0528,0.0522,0.0518,0,0,0,7.7695,0,0,100,0,0,0,0,0,0,0,0,0,0,566.1572,-162027,0.7886,3.918,0,0,0,0,0,0,0,0,0,0,4.4449,1.0678,0.5382,0.5382,559.8996,86.8582,98.7668,-11.9086,0.9792,0.8794,7938.745,1.0707,567.8387,94.7973,-5.9543,0,3106.41,92.8125,-6.9586,-0.0801,0,0,1507964,-473.0414,0,0,0,1.51E+08,0,0,52.9008,34.369,557.3362,569.5827,582.2885,17.4108,1.0678,7.9226,-8.3303,0.3209,591.2318,569.5827,548.393,118.1904,96.5413,75.3516,1.0733,7.9226,-8.3358,569.7358,96.6944,42.8388,0.4946,1.5685,62.8122,0.6601,0.0165
1,30.6,30.6,571.8594,84400.91,484,0,-0.0952,476.8948,2.0581,0,0,0.0528,0.0522,0.0518,0,0,0,7.7871,0,0,100,0,0,0,0,0,0,0,0,0,0,566.0483,-162267.4,0.9573,5.7311,0,0,0,0,0,0,0,0,0,0,4.4448,1.0719,0.5403,0.5403,559.8638,82.969,94.9646,-11.9956,0.979,0.8737,7939.074,1.0748,567.8608,90.966,-5.9978,0,246.0073,88.9668,-7.1052,-0.0856,0,0,1507964,-476.8948,0,0,0,1.51E+08,0,0,52.9057,34.3756,557.3687,569.5707,582.6397,25.4637,1.0719,7.9325,-8.3423,0.3896,598.4305,569.5707,541.5779,121.5357,92.6759,64.6831,1.08,7.9325,-8.3504,569.8597,92.9649,56.8526,0.4924,1.8789,58.1957,0.6621,0.0197
1,46,46,571.8028,84630.57,490,0,-0.0948,482.7392,2.0708,0,0,0.0528,0.0522,0.0518,0,0,0,7.7974,0,0,100,0,0,0,0,0,0,0,0,0,0,566.1402,-162535.3,1.1205,2.2844,0,0,0,0,0,0,0,0,0,0,4.4451,1.0785,0.5437,0.5437,559.8642,77.125,89.0636,-11.9386,0.9791,0.866,7939.604,1.0815,567.8232,85.084,-5.9693,0,-8056.641,83.0943,-7.2608,-0.0941,0,0,1507964,-482.7392,0,0,0,1.51E+08,0,0,52.9118,34.3833,557.2852,569.5724,582.3108,10.1475,1.0785,7.9418,-8.3568,0.4562,585.9083,569.5724,553.6877,103.1691,86.8332,70.9485,1.0895,7.9418,-8.3678,569.7228,86.9836,32.2206,0.493,1.4541,70.4795,0.6635,0.0227
1,61.4,61.4,571.9779,84766.25,491,0,-0.0936,483.5808,2.0579,0,0,0.0528,0.0522,0.0518,0,0,0,7.7892,0,0,100,0,0,0,0,0,0,0,0,0,0,565.9238,-162659.3,1.4804,7.1715,0,0,0,0,0,0,0,0,0,0,4.4474,1.0718,0.5402,0.5402,560.1919,76.6111,88.3971,-11.786,0.9794,0.8667,7939.066,1.0747,568.0493,84.4685,-5.893,0,115.9004,82.5041,-7.4192,-0.0968,0,0,1507964,-483.5808,0,0,0,1.51E+08,0,0,52.912,34.3852,557.9822,569.5933,583.2141,31.8579,1.0718,7.9517,-8.359,0.6027,604.8631,569.5933,536.3332,121.2823,86.0125,52.7524,1.091,7.9517,-8.3782,570.2632,86.6824,68.5299,0.4853,2.2991,55.802,0.6645,0.0288
1,76.8,76.8,571.821,85110.34,498,0,-0.0948,490.826,2.0829,0,0,0.0528,0.0522,0.0518,0,0,0,7.8233,0,0,100,0,0,0,0,0,0,0,0,0,0,566.2859,-163033.6,1.2804,1.1609,0,0,0,0,0,0,0,0,0,0,4.4455,1.0848,0.5469,0.5469,559.8789,69.0529,80.995,-11.9421,0.9791,0.8526,7940.109,1.0878,567.8403,77.0143,-5.9711,0,1724.722,75.024,-7.174,-0.1039,0,0,1507964,-490.826,0,0,0,1.51E+08,0,0,52.9213,34.3965,557.2142,569.6406,582.0985,5.1552,1.0848,7.9634,-8.3806,0.5214,583.1243,569.6406,556.1885,92.2983,78.8146,65.3625,1.0991,7.9634,-8.3949,569.6511,78.8251,26.9358,0.4994,1.4121,78.7471,0.6676,0.0254
1,92.2,92.2,571.9084,85107.23,496,0,-0.0939,488.2976,2.0483,0,0,0.0528,0.0522,0.0518,0,0,0,7.7806,0,0,100,0,0,0,0,0,0,0,0,0,0,566.0065,-163011.7,1.8591,7.9227,0,0,0,0,0,0,0,0,0,0,4.4463,1.0668,0.5377,0.5377,560.0816,71.784,83.6108,-11.8268,0.9793,0.8585,7938.665,1.0697,567.9661,79.6685,-5.9134,0,239.6676,77.6974,-7.7024,-0.1073,0,0,1507964,-488.2976,0,0,0,1.51E+08,0,0,52.9162,34.3929,557.7436,569.5835,582.8667,35.1924,1.0668,7.9721,-8.3715,0.7569,607.6722,569.5835,532.9381,119.3746,81.2859,44.6405,1.0971,7.9721,-8.4018,570.0646,81.767,74.7341,0.4903,2.6741,54.8217,0.6674,0.0343
1,107.6,107.6,571.9845,85512.09,504,0,-0.0946,496.9518,2.0891,0,0,0.0528,0.0522,0.0518,0,0,0,7.8228,0,0,100,0,0,0,0,0,0,0,0,0,0,566.4564,-163509.9,1.5221,0.8216,0,0,0,0,0,0,0,0,0,0,4.4472,1.0881,0.5485,0.5485,560.0744,63.1226,75.0327,-11.9101,0.9792,0.8413,7940.374,1.0911,568.0145,71.0627,-5.9551,0,186.2044,69.0777,-7.0482,-0.1117,0,0,1507964,-496.9518,0,0,0,1.51E+08,0,0,52.9298,34.4087,557.4154,569.8066,582.2545,3.6475,1.0881,7.985,-8.4024,0.62,582.7791,569.8066,556.8909,85.8273,72.8548,59.9391,1.1083,7.985,-8.4226,569.8255,72.8737,25.8882,0.4989,1.4319,81.8165,0.6707,0.0292
1,123,123,572.1734,85414.09,500,0,-0.095,492.7709,2.0381,0,0,0.0528,0.0522,0.0518,0,0,0,7.7693,0,0,100,0,0,0,0,0,0,0,0,0,0,566.0981,-163344,2.2365,7.8284,0,0,0,0,0,0,0,0,0,0,4.447,1.0615,0.535,0.535,560.1998,67.4289,79.4025,-11.9736,0.9791,0.8492,7938.239,1.0643,568.1822,75.4113,-5.9868,0,79.3251,73.4157,-7.2291,-0.1072,0,0,1507964,-492.7709,0,0,0,1.51E+08,0,0,52.92,34.4,557.92,569.78,583.458,34.7713,1.0615,7.9914,-8.383,0.9106,607.7307,569.78,533.6472,114.9598,77.0091,40.8763,1.1052,7.9914,-8.4267,570.386,77.6151,74.0835,0.4877,2.8124,55.0823,0.6699,0.0391
1,138.4,138.4,571.8303,85926.68,509,0,-0.094,501.999,2.0904,0,0,0.0528,0.0522,0.0518,0,0,0,7.8282,0,0,100,0,0,0,0,0,0,0,0,0,0,566.268,-163956.3,1.8394,1.3668,0,0,0,0,0,0,0,0,0,0,4.4466,1.0887,0.5488,0.5488,559.9954,57.9964,69.8313,-11.8349,0.9793,0.8305,7940.422,1.0917,567.8853,65.8863,-5.9175,0,1528.547,63.9139,-7.001,-0.1207,0,0,1507964,-501.999,0,0,0,1.51E+08,0,0,52.937,34.4197,557.407,569.6387,582.1695,6.0668,1.0887,8.0071,-8.4214,0.7494,583.5759,569.6387,556.0005,81.5769,67.6397,54.0015,1.1181,8.0071,-8.4508,569.7383,67.7394,27.5754,0.4946,1.5106,76.9476,0.6744,0.0338
1,153.8,153.8,572.0119,85751.38,505,0,-0.0957,498.0469,2.0366,0,0,0.0528,0.0522,0.0518,0,0,0,7.7562,0,0,100,0,0,0,0,0,0,0,0,0,0,566.8577,-163747.2,2.4987,6.8501,0,0,0,0,0,0,0,0,0,0,4.445,1.0607,0.5346,0.5346,559.9524,61.9055,73.965,-12.0595,0.9789,0.837,7938.175,1.0635,567.9921,69.9452,-6.0298,0,166.8174,67.9353,-6.9531,-0.1123,0,0,1507964,-498.0469,0,0,0,1.51E+08,0,0,52.9262,34.4097,556.9487,569.9812,581.59,30.421,1.0607,8.0118,-8.3996,1.0175,602.0907,569.9812,536.4481,104.0438,71.9343,38.4012,1.1151,8.0118,-8.454,569.5067,71.4598,65.6426,0.5108,2.7094,56.0241,0.6729,0.042
1,169.2,169.2,572.2408,86345.19,513,0,-0.0944,506.593,2.0854,0,0,0.0528,0.0522,0.0518,0,0,0,7.8269,0,0,100,0,0,0,0,0,0,0,0,0,0,565.8004,-164411.8,2.2217,2.7281,0,0,0,0,0,0,0,0,0,0,4.4493,1.0861,0.5475,0.5475,560.3501,53.7571,65.6478,-11.8907,0.9792,0.8189,7940.214,1.0891,568.2772,61.6842,-5.9454,0,98.7851,59.7025,-6.407,-0.1192,0,0,1507964,-506.593,0,0,0,1.51E+08,0,0,52.9435,34.4303,558.3843,569.7029,584.2183,12.1072,1.0861,8.031,-8.4394,0.9053,589.0053,569.7029,553.5972,82.4123,63.1099,47.0042,1.1289,8.031,-8.4822,570.7685,64.1755,35.4081,0.4549,1.7533,68.4268,0.6777,0.0386
1,184.6,184.6,571.8246,86176.48,510,0,-0.0953,503.7493,2.0375,0,0,0.0528,0.0522,0.0518,0,0,0,7.7547,0,0,100,0,0,0,0,0,0,0,0,0,0,566.561,-164242.3,2.8035,5.2898,0,0,0,0,0,0,0,0,0,0,4.444,1.0612,0.5349,0.5349,559.8235,56.0742,68.0753,-12.0011,0.979,0.8237,7938.215,1.0641,567.8242,64.0749,-6.0006,0,2070.561,62.0748,-6.2507,-0.1115,0,0,1507964,-503.7493,0,0,0,1.51E+08,0,0,52.9342,34.4219,556.923,569.7505,581.6118,23.4866,1.0612,8.0363,-8.4208,1.1419,595.8005,569.7505,542.7343,92.0512,66.0012,38.985,1.1295,8.0363,-8.4891,569.4285,65.6791,53.0662,0.5091,2.3612,58.8631,0.6767,0.0449
1,200,200,572.0987,86752.45,516,0,-0.0939,509.52,2.0691,0,0,0.0528,0.0522,0.0518,0,0,0,7.7972,0,0,100,0,0,0,0,0,0,0,0,0,0,566.0026,-164864,2.745,4.413,0,0,0,0,0,0,0,0,0,0,4.4483,1.0777,0.5432,0.5432,560.2718,50.7518,62.5787,-11.8269,0.9793,0.811,7939.54,1.0806,568.1564,58.6364,-5.9135,0,156.5784,56.6653,-6.48,-0.1277,0,0,1507964,-509.52,0,0,0,1.51E+08,0,0,52.9484,34.4399,558.0896,569.6962,583.442,19.5835,1.0777,8.0585,-8.4546,1.1186,594.0939,569.6962,547.4377,84.5739,60.1762,37.9177,1.1429,8.0585,-8.5198,570.4092,60.8893,46.6562,0.4771,2.2305,61.4573,0.6816,0.0441
1,215.4,215.4,571.8798,86739.13,517,0,-0.0949,510.1021,2.0421,0,0,0.0528,0.0522,0.0518,0,0,0,7.7312,0,0,100,0,0,0,0,0,0,0,0,0,0,566.9689,-164836.4,3.0913,3.51,0,0,0,0,0,0,0,0,0,0,4.4449,1.0636,0.5361,0.5361,559.9234,49.8213,61.7777,-11.9564,0.9791,0.8065,7938.408,1.0665,567.8943,57.7922,-5.9782,0,623.4857,55.7995,-6.8979,-0.1385,0,0,1507964,-510.1021,0,0,0,1.51E+08,0,0,52.9442,34.4367,556.8021,569.9445,581.0175,15.5797,1.0636,8.0643,-8.4468,1.2595,588.6411,569.9445,549.1785,78.539,59.8424,39.0764,1.1463,8.0643,-8.5295,569.2547,59.1526,39.4626,0.5262,2.0099,63.9262,0.6811,0.0473
1,230.8,230.8,572.2994,87125.26,518,0,-0.0943,510.9576,2.0366,0,0,0.0528,0.0522,0.0518,0,0,0,7.7693,0,0,100,0,0,0,0,0,0,0,0,0,0,565.5961,-165267.1,3.3738,6.1462,0,0,0,0,0,0,0,0,0,0,4.4487,1.0607,0.5346,0.5346,560.4185,49.4609,61.3418,-11.8809,0.9792,0.8063,7938.175,1.0635,568.3391,57.3815,-5.9405,0,95.9046,55.4014,-7.0424,-0.1424,0,0,1507964,-510.9576,0,0,0,1.51E+08,0,0,52.9502,34.4467,558.6564,569.6573,584.7784,27.2772,1.0607,8.0877,-8.4636,1.3748,601.9603,569.6573,541.4745,91.0027,58.6997,30.5169,1.1589,8.0877,-8.5618,571.0307,60.0731,60.4858,0.4659,2.982,57.7931,0.6848,0.0494
1,246.2,246.2,571.9833,87300.97,524,0,-0.0944,516.8681,2.0454,0,0,0.0528,0.0522,0.0518,0,0,0,7.7772,0,0,100,0,0,0,0,0,0,0,0,0,0,566.9525,-165518.5,3.411,1.973,0,0,0,0,0,0,0,0,0,0,4.4463,1.0653,0.5369,0.5369,560.0901,43.222,55.1152,-11.8932,0.9792,0.7842,7938.544,1.0681,568.0189,51.1508,-5.9466,0,299.3067,49.1686,-7.1319,-0.165,0,0,1507964,-516.8681,0,0,0,1.51E+08,0,0,52.9554,34.4536,557.0956,570.0003,581.3514,8.7547,1.0653,8.0976,-8.4762,1.3902,584.1812,570.0003,554.2659,67.3131,53.1322,37.3978,1.1655,8.0976,-8.5764,569.4825,52.6144,29.9153,0.526,1.7999,72.0879,0.6867,0.0496
1,261.6,261.6,572.2151,87417.28,518,0,-0.0937,511.2358,1.9878,0,0,0.0528,0.0522,0.0518,0,0,0,7.7045,0,0,100,0,0,0,0,0,0,0,0,0,0,565.3383,-165584.6,4.1419,7.4354,0,0,0,0,0,0,0,0,0,0,4.4475,1.0353,0.5217,0.5217,560.4112,49.1754,60.9793,-11.8039,0.9794,0.8064,7936.138,1.038,568.2805,57.0447,-5.902,0,116.304,55.0774,-6.7642,-0.1376,0,0,1507964,-511.2358,0,0,0,1.51E+08,0,0,52.9485,34.45,558.8151,569.5045,585.0217,33.0067,1.0353,8.1169,-8.4653,1.6874,607.431,569.5045,536.4059,96.1952,58.2687,25.1701,1.1829,8.1169,-8.6129,571.1138,59.878,71.0251,0.466,3.8218,55.8263,0.6869,0.0545
1,277,277,571.59,87957.63,529,0,-0.0939,522.7302,2.0435,0,0,0.0528,0.0522,0.0518,0,0,0,7.7698,0,0,100,0,0,0,0,0,0,0,0,0,0,566.8134,-166261.4,3.8025,0.9941,0,0,0,0,0,0,0,0,0,0,4.4436,1.0643,0.5364,0.5364,559.7557,37.0255,48.8598,-11.8344,0.9793,0.7578,7938.464,1.0671,567.6453,44.9151,-5.9172,0,-275.0133,42.9427,-6.2698,-0.1693,0,0,1507964,-522.7302,0,0,0,1.51E+08,0,0,52.9669,34.4715,556.6177,569.7068,580.4926,4.4097,1.0643,8.135,-8.507,1.5502,581.2811,569.7068,555.8293,58.5509,46.9766,33.0991,1.1882,8.135,-8.6309,568.939,46.2089,25.4518,0.5452,1.769,79.8629,0.6923,0.0521
1,292.4,292.4,572.2328,87717.13,518,0,-0.0927,511.3623,1.9248,0,0,0.0528,0.0522,0.0518,0,0,0,7.5858,0,0,100,0,0,0,0,0,0,0,0,0,0,565.5909,-165925.6,5.0286,7.959,0,0,0,0,0,0,0,0,0,0,4.4471,1.0025,0.505,0.505,560.5465,49.1842,60.8705,-11.6863,0.9796,0.808,7933.508,1.005,568.3373,56.975,-5.8432,0,111.7856,55.0274,-6.6377,-0.135,0,0,1507964,-511.3623,0,0,0,1.51E+08,0,0,52.9451,34.4526,558.8536,569.6146,584.6071,35.3435,1.0025,8.152,-8.4644,2.0479,609.3465,569.6146,534.1142,97.9842,58.2523,22.7519,1.219,8.152,-8.6809,571.0251,59.6628,75.2323,0.4719,4.3066,55.0092,0.6901,0.059
1,307.8,307.8,571.7906,88676.28,534,0,-0.0949,527.2562,2.0285,0,0,0.0528,0.0522,0.0518,0,0,0,7.7571,0,0,100,0,0,0,0,0,0,0,0,0,0,566.4236,-167112.6,4.3976,0.8623,0,0,0,0,0,0,0,0,0,0,4.4439,1.0565,0.5325,0.5325,559.8376,32.5814,44.5344,-11.953,0.9791,0.7316,7937.838,1.0593,567.8062,40.55,-5.9765,0,-4366.427,38.5579,-6.7438,-0.207,0,0,1507964,-527.2562,0,0,0,1.51E+08,0,0,52.9783,34.4908,557.0586,569.6743,581.8034,3.8241,1.0565,8.1812,-8.5391,1.7933,582.3809,569.6743,556.4811,55.1247,42.4181,29.2249,1.2212,8.1812,-8.7038,569.5121,42.2559,25.8998,0.5094,1.8862,81.4123,0.6986,0.0553
1,323.2,323.2,572.1022,88124.95,521,0,-0.0949,513.8268,1.8683,0,0,0.0528,0.0522,0.0518,0,0,0,7.5072,0,0,100,0,0,0,0,0,0,0,0,0,0,565.9863,-166429.5,5.8768,7.6815,0,0,0,0,0,0,0,0,0,0,4.4425,0.9731,0.4901,0.4901,560.1329,46.3061,58.2754,-11.9693,0.9791,0.7946,7931.153,0.9755,568.1124,54.2856,-5.9847,0,169.2454,52.2908,-7.1732,-0.1549,0,0,1507964,-513.8268,0,0,0,1.51E+08,0,0,52.9452,34.4597,557.901,569.691,583.5029,34.119,0.9731,8.1929,-8.472,2.3927,607.1433,569.691,534.2606,93.3165,55.8642,20.4338,1.267,8.1929,-8.7659,570.3649,56.5382,72.8827,0.4861,4.5668,55.2827,0.694,0.0622
1,338.6,338.6,571.9412,89405.67,537,0,-0.0944,530.3734,1.9935,0,0,0.0528,0.0522,0.0518,0,0,0,7.68,0,0,100,0,0,0,0,0,0,0,0,0,0,566.2493,-167958,5.2112,1.6582,0,0,0,0,0,0,0,0,0,0,4.4447,1.0383,0.5232,0.5232,560.0413,29.6679,41.5678,-11.8999,0.9792,0.7137,7936.378,1.041,567.9746,37.6012,-5.95,0,491.0938,35.6179,-6.6266,-0.2234,0,0,1507964,-530.3734,0,0,0,1.51E+08,0,0,52.9868,34.5082,557.5482,569.6964,582.5707,7.3531,1.0383,8.2333,-8.5662,2.1252,584.5715,569.6964,555.5474,54.1981,39.323,25.174,1.2679,8.2333,-8.7958,569.9384,39.565,29.0241,0.4875,2.1529,74.7782,0.7054,0.0589
1,354,354,571.6855,88694.86,524,0,-0.0944,517.9001,1.8229,0,0,0.0528,0.0522,0.0518,0,0,0,7.4024,0,0,100,0,0,0,0,0,0,0,0,0,0,566.8134,-167115.4,6.6544,6.5051,0,0,0,0,0,0,0,0,0,0,4.4386,0.9494,0.4781,0.4781,559.7751,41.875,53.7854,-11.9104,0.9792,0.7786,7929.255,0.9517,567.7153,49.8152,-5.9552,0,-453.9954,47.8302,-6.0999,-0.1457,0,0,1507964,-517.9001,0,0,0,1.51E+08,0,0,52.9497,34.4722,556.6677,569.7643,580.775,28.8955,0.9494,8.2397,-8.4897,2.7092,600.0302,569.7643,537.4126,82.1301,51.8642,19.5125,1.3234,8.2397,-8.8637,569.069,51.1689,62.6176,0.5167,4.2091,56.3216,0.6994,0.0645
1,369.4,369.4,572.0389,90117.23,539,0,-0.0942,532.0556,1.9368,0,0,0.0528,0.0522,0.0518,0,0,0,7.591,0,0,100,0,0,0,0,0,0,0,0,0,0,565.8509,-168775.6,6.2074,3.0988,0,0,0,0,0,0,0,0,0,0,4.4444,1.0088,0.5082,0.5082,560.1705,28.1149,39.9833,-11.8684,0.9793,0.7032,7934.013,1.0113,568.0828,36.0272,-5.9342,0,293.0815,34.0491,-6.9444,-0.247,0,0,1507964,-532.0556,0,0,0,1.51E+08,0,0,52.9918,34.5229,558.0503,569.5979,583.6057,13.7427,1.0088,8.2902,-8.5868,2.5313,589.5932,569.5979,552.0628,57.5376,37.5423,20.0072,1.3318,8.2902,-8.9098,570.418,38.3624,37.5304,0.4672,2.8758,66.4581,0.7122,0.0622
1,384.8,384.8,571.8082,89501.48,531,0,-0.0961,523.7571,1.791,0,0,0.0528,0.0522,0.0518,0,0,0,7.3512,0,0,100,0,0,0,0,0,0,0,0,0,0,567.029,-168011.1,7.4273,4.8856,0,0,0,0,0,0,0,0,0,0,4.4372,0.9328,0.4697,0.4697,559.6924,35.9353,48.0512,-12.1158,0.9788,0.7479,7927.927,0.935,567.7696,44.0125,-6.0579,0,19724.92,41.9933,-7.2429,-0.2016,0,0,1507964,-523.7571,0,0,0,1.51E+08,0,0,52.9594,34.4911,556.3884,569.9233,580.7339,21.6989,0.9328,8.2937,-8.5197,3.0243,593.4412,569.9233,543.6811,69.6841,46.1662,19.924,1.3941,8.2937,-8.981,569.0152,45.2581,49.7601,0.5274,3.4975,59.6459,0.7068,0.0662
1,400.2,400.2,572.2028,90718.59,539,0,-0.0906,530.3028,1.8304,0,0,0.0528,0.0522,0.0518,0,0,0,7.4266,0,0,100,0,0,0,0,0,0,0,0,0,0,565.2964,-169469.4,7.4066,4.8875,0,0,0,0,0,0,0,0,0,0,4.4467,0.9533,0.4801,0.4801,560.7746,30.4718,41.9,-11.4282,0.98,0.7273,7929.567,0.9556,568.3934,38.0906,-5.7141,0,167.8421,36.1859,-8.6972,-0.2854,0,0,1507964,-530.3028,0,0,0,1.51E+08,0,0,52.9879,34.53,559.4479,569.4779,585.123,21.687,0.9533,8.3547,-8.5901,3.0187,597.4872,569.4779,547.0836,67.1844,39.1751,16.7808,1.409,8.3547,-9.0458,571.3495,41.0468,50.4036,0.4443,4.0036,60.3116,0.7179,0.0655
1,415.6,415.6,571.5306,90362.3,536,0,-0.0952,530.1279,1.7605,0,0,0.0528,0.0522,0.0518,0,0,0,7.304,0,0,100,0,0,0,0,0,0,0,0,0,0,567.244,-169077.8,8.1327,3.0911,0,0,0,0,0,0,0,0,0,0,4.4351,0.9169,0.4616,0.4616,559.5173,29.3893,41.4027,-12.0133,0.979,0.7098,7926.654,0.919,567.5261,37.3982,-6.0067,0,-242.4152,35.396,-5.8721,-0.1998,0,0,1507964,-530.1279,0,0,0,1.51E+08,0,0,52.972,34.5142,555.9269,569.8395,579.546,13.7258,0.9169,8.3553,-8.557,3.3122,585.8434,569.8395,549.6295,55.7155,39.7116,19.5016,1.4643,8.3553,-9.1044,568.4374,38.3096,36.2139,0.5581,2.857,65.3542,0.7152,0.0674
1,431,431,572.3256,91199.24,535,0,-0.0932,527.1442,1.7323,0,0,0.0528,0.0522,0.0518,0,0,0,7.2915,0,0,100,0,0,0,0,0,0,0,0,0,0,565.0115,-170077,8.7204,6.5191,0,0,0,0,0,0,0,0,0,0,4.4428,0.9022,0.4542,0.4542,560.5718,33.4276,45.1814,-11.7539,0.9795,0.7399,7925.479,0.9043,568.4077,41.2635,-5.877,0,122.1697,39.3045,-7.8558,-0.235,0,0,1507964,-527.1442,0,0,0,1.51E+08,0,0,52.9838,34.5358,559.3545,569.4394,586.0182,28.9416,0.9022,8.4128,-8.5919,3.5523,604.551,569.4394,540.8217,77.4068,42.2952,13.6775,1.5258,8.4128,-9.2155,571.6041,44.4598,63.7293,0.4491,5.6594,57.3665,0.7231,0.0683
1,446.4,446.4,571.5802,91390.11,542,0,-0.0963,537.2005,1.7402,0,0,0.0528,0.0522,0.0518,0,0,0,7.2713,0,0,100,0,0,0,0,0,0,0,0,0,0,567.1071,-170320.5,8.722,1.6314,0,0,0,0,0,0,0,0,0,0,4.4339,0.9064,0.4563,0.4563,559.4251,22.2246,34.3797,-12.1551,0.9787,0.6464,7925.814,0.9085,567.5285,30.328,-6.0776,0,-327.3204,28.3022,-4.7995,-0.216,0,0,1507964,-537.2005,0,0,0,1.51E+08,0,0,52.9888,34.5425,555.901,569.8151,579.9565,7.2414,0.9064,8.4228,-8.6041,3.5535,581.9681,569.8151,553.8893,44.7676,32.6146,16.6888,1.5294,8.4228,-9.2271,568.5575,31.357,28.0788,0.5672,2.6825,74.4748,0.7251,0.0682
1,461.8,461.8,572.5054,91591.65,531,0,-0.0929,523.6161,1.6027,0,0,0.0528,0.0522,0.0518,0,0,0,7.0879,0,0,100,0,0,0,0,0,0,0,0,0,0,564.5705,-170560.4,10.0552,7.6455,0,0,0,0,0,0,0,0,0,0,4.4414,0.8347,0.42,0.42,560.7769,37.1608,48.8893,-11.7285,0.9795,0.7601,7920.084,0.8365,568.5959,44.9798,-5.8643,0,85.7685,43.0251,-7.3839,-0.1987,0,0,1507964,-523.6161,0,0,0,1.51E+08,0,0,52.9735,34.5358,560.0435,569.3738,587.3683,33.9697,0.8347,8.4734,-8.5811,4.0927,610.3201,569.3738,537.0917,86.704,45.7577,13.4756,1.653,8.4734,-9.3994,572.2618,48.6458,73.2284,0.4408,6.4341,55.9548,0.727,0.0707
1,477.2,477.2,571.3593,92558.57,549,0,-0.0954,542.2209,1.7093,0,0,0.0528,0.0522,0.0518,0,0,0,7.2369,0,0,100,0,0,0,0,0,0,0,0,0,0,567.5769,-171699.4,9.3097,0.902,0,0,0,0,0,0,0,0,0,0,4.4324,0.8903,0.4481,0.4481,559.3268,17.1059,29.1384,-12.0325,0.9789,0.5871,7924.527,0.8923,567.3484,25.1275,-6.0163,0,-176.4212,23.1222,-6.7791,-0.3963,0,0,1507964,-542.2209,0,0,0,1.51E+08,0,0,53.0063,34.573,555.3496,569.8662,578.4535,4.0023,0.8903,8.4993,-8.6542,3.7943,579.1272,569.8662,554.6759,36.9063,27.6453,12.455,1.5928,8.4993,-9.3567,567.8898,25.6689,24.4513,0.6212,2.9632,80.4454,0.7354,0.0688
1,492.6,492.6,572.1882,92006.94,529,0,-0.0922,521.6072,1.4796,0,0,0.0528,0.0522,0.0518,0,0,0,6.8553,0,0,100,0,0,0,0,0,0,0,0,0,0,565.0529,-171124.3,11.3116,7.9799,0,0,0,0,0,0,0,0,0,0,4.4367,0.7706,0.3875,0.3875,560.5455,38.9383,50.581,-11.6427,0.9797,0.7698,7914.968,0.7721,568.3073,46.7001,-5.8214,0,151.5573,44.7597,-7.3928,-0.1899,0,0,1507964,-521.6072,0,0,0,1.51E+08,0,0,52.9653,34.5383,559.2657,569.3718,585.562,35.4812,0.7706,8.5364,-8.5752,4.6008,610.2528,569.3718,534.5748,88.6456,47.7647,12.9677,1.7915,8.5364,-9.5961,571.3998,49.7927,75.6779,0.4598,6.8359,55.1665,0.7318,0.0726
1,508,508,571.7656,93645.08,551,0,-0.0942,543.8434,1.6513,0,0,0.0528,0.0522,0.0518,0,0,0,7.126,0,0,100,0,0,0,0,0,0,0,0,0,0,567.0608,-173050,10.1992,0.9947,0,0,0,0,0,0,0,0,0,0,4.4354,0.8601,0.4328,0.4328,559.8759,16.0325,27.9222,-11.8897,0.9792,0.5742,7922.113,0.8619,567.8024,23.9591,-5.9449,0,-2029.846,21.9774,-7.1566,-0.4464,0,0,1507964,-543.8434,0,0,0,1.51E+08,0,0,53.0195,34.6004,556.6764,569.9077,580.6038,4.4131,0.8601,8.5829,-8.6965,4.1574,581.3918,569.9077,555.8884,37.5484,26.0643,12.045,1.692,8.5829,-9.5284,569.0627,25.2192,25.5034,0.5497,3.1173,79.8762,0.7465,0.0698
1,523.4,523.4,571.9333,92669.31,531,0,-0.0932,523.5624,1.3806,0,0,0.0528,0.0522,0.0518,0,0,0,6.7337,0,0,100,0,0,0,0,0,0,0,0,0,0,565.9627,-171937.8,12.3493,7.4473,0,0,0,0,0,0,0,0,0,0,4.4313,0.7191,0.3615,0.3615,560.1539,36.5915,48.3709,-11.7794,0.9794,0.7565,7910.862,0.7204,568.0068,44.4444,-5.8897,0,468.3449,42.4812,-7.4376,-0.2033,0,0,1507964,-523.5624,0,0,0,1.51E+08,0,0,52.9643,34.549,557.9472,569.5762,583.1347,33.1275,0.7191,8.6054,-8.5853,5.0207,605.9815,569.5762,535.1004,82.4191,46.0138,11.538,1.919,8.6054,-9.7852,570.2193,46.657,70.8811,0.4864,7.1433,55.4074,0.7392,0.0738
1,538.8,538.8,571.9052,94719.99,550,0,-0.0919,544.3105,1.5698,0,0,0.0528,0.0522,0.0518,0,0,0,7.0053,0,0,100,0,0,0,0,0,0,0,0,0,0,566.2906,-174354.6,11.3073,1.9509,0,0,0,0,0,0,0,0,0,0,4.4369,0.8176,0.4113,0.4113,560.3053,15.9948,27.5947,-11.5999,0.9797,0.5796,7918.718,0.8193,568.0386,23.7281,-5.8,0,807.1953,21.7948,-5.6895,-0.3557,0,0,1507964,-544.3105,0,0,0,1.51E+08,0,0,53.0287,34.6245,557.9443,569.6874,582.4681,8.6562,0.8176,8.6708,-8.7312,4.6087,585.2156,569.6874,555.1967,40.9051,25.3769,10.8862,1.8238,8.6708,-9.7374,570.0332,25.7227,30.0189,0.4827,3.7575,72.39,0.7572,0.0711
1,554.2,554.2,571.9882,93471.59,534,0,-0.0963,527.1542,1.3131,0,0,0.0528,0.0522,0.0518,0,0,0,6.5921,0,0,100,0,0,0,0,0,0,0,0,0,0,566.755,-172923.7,13.2584,6.1241,0,0,0,0,0,0,0,0,0,0,4.427,0.6839,0.3437,0.3437,559.8087,32.6545,44.8341,-12.1795,0.9787,0.7283,7908.058,0.6851,567.9284,40.7742,-6.0898,0,347.4171,38.7443,-6.8458,-0.2096,0,0,1507964,-527.1542,0,0,0,1.51E+08,0,0,52.9705,34.5667,556.8423,569.9217,581.8174,27.2444,0.6839,8.6732,-8.6103,5.3897,599.2997,569.9217,539.3599,72.1455,42.7675,12.2058,2.0468,8.6732,-9.9732,569.5271,42.3729,59.9397,0.5099,5.9108,57.3122,0.7468,0.0746
1,569.6,569.6,572.2376,95724.25,548,0,-0.093,542.477,1.4633,0,0,0.0528,0.0522,0.0518,0,0,0,6.8519,0,0,100,0,0,0,0,0,0,0,0,0,0,565.5315,-175509.7,12.6425,3.5067,0,0,0,0,0,0,0,0,0,0,4.4359,0.7621,0.3832,0.3832,560.4925,18.0155,29.7606,-11.7451,0.9795,0.6053,7914.29,0.7635,568.3226,25.8456,-5.8726,0,182.4916,23.8881,-5.523,-0.3066,0,0,1507964,-542.477,0,0,0,1.51E+08,0,0,53.0321,34.6427,558.8686,569.5878,584.8709,15.5646,0.7621,8.7583,-8.7537,5.1511,592.15,569.5878,551.5895,49.673,27.1108,9.1125,1.9962,8.7583,-9.9878,571.1091,28.6321,40.5605,0.4437,5.4511,64.9361,0.7667,0.0725
1,585,585,571.2878,94591.16,539,0,-0.0961,532.7115,1.2604,0,0,0.0528,0.0522,0.0518,0,0,0,6.4924,0,0,100,0,0,0,0,0,0,0,0,0,0,567.3257,-174235.9,14.0492,4.4022,0,0,0,0,0,0,0,0,0,0,4.4204,0.6565,0.3299,0.3299,559.1284,26.4169,38.5763,-12.1594,0.9787,0.6848,7905.877,0.6576,567.2347,34.5232,-6.0797,0,-133.6505,32.4966,-6.2885,-0.238,0,0,1507964,-532.7115,0,0,0,1.51E+08,0,0,52.9839,34.5936,555.2388,569.7227,578.7408,19.5812,0.6565,8.753,-8.6523,5.712,589.8264,569.7227,544.1531,57.1149,37.0112,11.4416,2.1646,8.753,-10.1604,567.9007,35.1892,45.6733,0.5598,4.9919,60.4843,0.7572,0.0751
1,600.4,600.4,572.2664,96422.95,545,0,-0.0925,537.1018,1.3207,0,0,0.0528,0.0522,0.0518,0,0,0,6.6334,0,0,100,0,0,0,0,0,0,0,0,0,0,564.8207,-176372.8,14.0702,5.2977,0,0,0,0,0,0,0,0,0,0,4.4332,0.6879,0.3457,0.3457,560.5702,23.4684,35.1646,-11.6962,0.9796,0.6674,7908.376,0.6891,568.3677,31.2659,-5.8481,0,159.4397,29.3165,-7.8982,-0.3365,0,0,1507964,-537.1018,0,0,0,1.51E+08,0,0,53.0259,34.6506,559.5397,569.3239,586.307,23.5317,0.6879,8.8418,-8.7555,5.7285,599.9948,569.3239,545.8519,62.893,32.2221,8.7501,2.1873,8.8418,-10.2549,571.7236,34.6217,54.1429,0.4335,7.1877,59.8145,0.7742,0.074
1,615.8,615.8,571.4532,95852.09,549,0,-0.0964,539.743,1.2264,0,0,0.0528,0.0522,0.0518,0,0,0,6.4639,0,0,100,0,0,0,0,0,0,0,0,0,0,567.7136,-175695,14.6702,2.6773,0,0,0,0,0,0,0,0,0,0,4.4206,0.6388,0.3209,0.3209,559.2533,19.5103,31.7102,-12.1999,0.9787,0.6153,7904.469,0.6398,567.3865,27.6435,-6.1,0,-216.4312,25.6103,-9.257,-0.4745,0,0,1507964,-539.743,0,0,0,1.51E+08,0,0,53.0021,34.6257,555.1818,569.9755,578.4995,11.9045,0.6388,8.8352,-8.7048,5.9666,583.5034,569.9755,550.178,43.7604,30.2325,10.435,2.2619,8.8352,-10.3279,567.8857,28.1426,33.3254,0.5941,4.1936,67.2013,0.7692,0.0752
1,631.2,631.2,572.5316,96964.67,538,0,-0.0919,531.9556,1.1692,0,0,0.0528,0.0522,0.0518,0,0,0,6.4104,0,0,100,0,0,0,0,0,0,0,0,0,0,564.6082,-177023,15.4512,6.8829,0,0,0,0,0,0,0,0,0,0,4.4323,0.609,0.3059,0.3059,560.9016,28.946,40.576,-11.63,0.9797,0.7134,7902.099,0.6099,568.655,36.6994,-5.815,0,94.1498,34.761,-6.0444,-0.2088,0,0,1507964,-531.9556,0,0,0,1.51E+08,0,0,53.015,34.6524,560.2703,569.3997,587.4841,30.601,0.609,8.917,-8.746,6.285,607.367,569.3997,540.3874,75.4114,37.4441,8.4318,2.3836,8.917,-10.5206,572.3847,40.4291,66.9796,0.4332,8.9437,56.9863,0.78,0.0755
1,646.6,646.6,571.6631,97208.52,553,0,-0.0973,546.7306,1.2041,0,0,0.0528,0.0522,0.0518,0,0,0,6.4065,0,0,100,0,0,0,0,0,0,0,0,0,0,568.1277,-177297.6,15.0555,1.3694,0,0,0,0,0,0,0,0,0,0,4.4209,0.6271,0.315,0.315,559.3571,12.6265,24.9325,-12.306,0.9785,0.5064,7903.538,0.6281,567.5611,20.8305,-6.153,0,-585.3282,18.7795,-6.2694,-0.4965,0,0,1507964,-546.7306,0,0,0,1.51E+08,0,0,53.0242,34.6622,555.0654,570.2656,578.3369,6.0859,0.6271,8.9206,-8.7658,6.1264,579.8324,570.2656,553.5699,33.1018,23.535,6.8393,2.3199,8.9206,-10.4586,567.8893,21.1587,26.2625,0.6357,4.8399,76.1944,0.7819,0.075
1,662,662,572.6849,97395.48,534,0,-0.093,527.5062,1.0136,0,0,0.0528,0.0522,0.0518,0,0,0,6.1871,0,0,100,0,0,0,0,0,0,0,0,0,0,564.2714,-177576,16.785,7.832,0,0,0,0,0,0,0,0,0,0,4.4287,0.5279,0.265,0.265,560.9033,33.3971,45.1787,-11.7816,0.9794,0.7392,7895.656,0.5286,568.7577,41.2515,-5.8908,0,72.6894,39.2879,-6.4938,-0.1944,0,0,1507964,-527.5062,0,0,0,1.51E+08,0,0,53.0021,34.6516,560.5614,569.3588,588.5721,34.855,0.5279,8.9888,-8.7317,6.8208,612.1303,569.3588,537.0032,84.6241,41.8526,9.4969,2.5837,8.9888,-10.7875,572.8307,45.3245,75.1272,0.4307,8.9107,55.9456,0.785,0.077
1,677.4,677.4,571.6209,98591.84,557,0,-0.0958,550.3347,1.1593,0,0,0.0528,0.0522,0.0518,0,0,0,6.3492,0,0,100,0,0,0,0,0,0,0,0,0,0,568.0565,-178953.8,15.4918,0.8181,0,0,0,0,0,0,0,0,0,0,4.421,0.6038,0.3033,0.3033,559.5009,9.1662,21.2862,-12.12,0.9788,0.4306,7901.686,0.6047,567.5809,17.2462,-6.06,0,-470.9155,15.2262,-6.6653,-0.7272,0,0,1507964,-550.3347,0,0,0,1.51E+08,0,0,53.044,34.698,555.343,570.2113,578.3623,3.6345,0.6038,9.0156,-8.8236,6.3062,578.9225,570.2113,554.7828,28.5878,19.8766,4.4481,2.3788,9.0156,-10.5986,567.9722,17.6375,24.1397,0.6391,6.427,81.2375,0.7958,0.075
1,692.8,692.8,572.6713,97959.71,534,0,-0.0936,526.2783,0.8894,0,0,0.0528,0.0522,0.0518,0,0,0,5.9646,0,0,100,0,0,0,0,0,0,0,0,0,0,564.8404,-178268.2,17.9201,7.9298,0,0,0,0,0,0,0,0,0,0,4.4251,0.4632,0.2324,0.2324,560.8119,34.5336,46.393,-11.8594,0.9793,0.7444,7890.524,0.4637,568.7182,42.4399,-5.9297,0,72.4089,40.4633,-7.7217,-0.2236,0,0,1507964,-526.2783,0,0,0,1.51E+08,0,0,52.9958,34.657,559.9879,569.5751,587.4705,35.3142,0.4632,9.0584,-8.7308,7.2771,611.6227,569.5751,535.8358,85.3444,43.2968,9.5575,2.7662,9.0584,-11.0338,572.3445,46.0662,75.7869,0.4452,8.9296,55.6309,0.7908,0.078
1,708.2,708.2,571.6717,99877.59,557,0,-0.094,550.6418,1.0906,0,0,0.0528,0.0522,0.0518,0,0,0,6.2464,0,0,100,0,0,0,0,0,0,0,0,0,0,567.4073,-180512.9,16.4046,1.1774,0,0,0,0,0,0,0,0,0,0,4.4215,0.568,0.2852,0.2852,559.7657,9.1239,21.0299,-11.906,0.9792,0.4339,7898.84,0.5688,567.7031,17.0613,-5.953,0,-652.3663,15.0769,-6.3582,-0.6969,0,0,1507964,-550.6418,0,0,0,1.51E+08,0,0,53.059,34.7292,556.2736,569.9847,579.7515,5.2301,0.568,9.1119,-8.8716,6.6786,580.8639,569.9847,555.1613,30.2221,19.3429,4.5195,2.5249,9.1119,-10.8285,568.67,18.0282,25.7026,0.5767,6.687,77.9927,0.8083,0.0753
1,723.6,723.6,571.9583,98613.88,536,0,-0.095,527.7628,0.7904,0,0,0.0528,0.0522,0.0519,0,0,0,5.8114,0,0,100,0,0,0,0,0,0,0,0,0,0,565.8484,-179106.6,18.8415,7.157,0,0,0,0,0,0,0,0,0,0,4.4157,0.4117,0.2065,0.2065,559.9102,32.1474,44.1955,-12.0481,0.9789,0.7274,7886.443,0.4121,567.9423,40.1795,-6.0241,0,419.2411,38.1715,-8.2372,-0.2562,0,0,1507964,-527.7628,0,0,0,1.51E+08,0,0,52.9953,34.6682,557.7072,569.5421,583.5162,31.8859,0.4117,9.128,-8.742,7.6481,605.0099,569.5421,536.2135,77.2471,41.7793,8.4507,2.9196,9.128,-11.2499,570.2552,42.4924,68.7964,0.4845,9.1409,56.0168,0.7977,0.0787
1,739,739,571.8626,101096.4,556,0,-0.0939,549.7148,0.9869,0,0,0.0528,0.0522,0.0518,0,0,0,6.0841,0,0,100,0,0,0,0,0,0,0,0,0,0,566.8129,-181942.3,17.5958,2.2799,0,0,0,0,0,0,0,0,0,0,4.4207,0.514,0.258,0.258,559.9684,10.2536,22.1478,-11.8942,0.9792,0.463,7894.553,0.5147,567.8979,18.1831,-5.9471,0,1500.039,16.2007,-6.2852,-0.613,0,0,1507964,-549.7148,0,0,0,1.51E+08,0,0,53.067,34.754,557.0702,569.8643,581.4457,10.1295,0.514,9.212,-8.9056,7.1621,585.1056,569.8643,553.4103,35.3908,20.1495,3.6955,2.7201,9.212,-11.1117,569.4601,19.7453,31.6953,0.5191,9.5767,70.1346,0.8204,0.076
1,754.4,754.4,571.7417,99516.45,537,0,-0.0952,531.8642,0.7056,0,0,0.0528,0.0522,0.0518,0,0,0,5.6595,0,0,100,0,0,0,0,0,0,0,0,0,0,566.6474,-180218.7,19.7083,5.7205,0,0,0,0,0,0,0,0,0,0,4.4118,0.3675,0.1843,0.1843,559.6639,27.7997,39.8775,-12.0778,0.9789,0.6971,7882.945,0.3679,567.7158,35.8516,-6.0389,0,-1076.032,33.8386,-5.1358,-0.1847,0,0,1507964,-531.8642,0,0,0,1.51E+08,0,0,53.001,34.6872,556.6887,569.7264,581.3906,25.4908,0.3675,9.2073,-8.7677,7.9984,597.3651,569.7264,540.7143,65.5009,37.8622,8.8501,3.0697,9.2073,-11.4699,569.2686,37.4044,56.6508,0.5121,7.4011,57.9257,0.8071,0.0792
1,769.8,769.8,572.4329,102041.3,552,0,-0.0918,544.8802,0.854,0,0,0.0528,0.0522,0.0518,0,0,0,5.9142,0,0,100,0,0,0,0,0,0,0,0,0,0,565.6241,-183105.8,19.12,3.9535,0,0,0,0,0,0,0,0,0,0,4.4242,0.4448,0.2231,0.2231,560.8015,15.9213,27.5527,-11.6314,0.9797,0.5778,7889.065,0.4453,568.5558,23.6756,-5.8157,0,129.5408,21.737,-7.1198,-0.4472,0,0,1507964,-544.8802,0,0,0,1.51E+08,0,0,53.0668,34.7698,559.3729,569.7377,585.3718,17.575,0.4448,9.3075,-8.9218,7.7783,594.2325,569.7377,550.5122,49.3523,24.8575,5.632,2.9854,9.3075,-11.4624,571.4941,26.6139,43.7203,0.4397,8.7628,63.2443,0.8305,0.077
1,785.2,785.2,571.4705,100668.5,543,0,-0.0963,537.3983,0.6528,0,0,0.0528,0.0522,0.0518,0,0,0,5.5829,0,0,100,0,0,0,0,0,0,0,0,0,0,567.3656,-181581.3,20.4242,3.9566,0,0,0,0,0,0,0,0,0,0,4.4073,0.34,0.1704,0.1704,559.2474,21.8491,34.0722,-12.2231,0.9786,0.6413,7880.77,0.3403,567.3962,29.9979,-6.1116,0,-220.6354,27.9607,-5.6017,-0.2564,0,0,1507964,-537.3983,0,0,0,1.51E+08,0,0,53.015,34.715,555.4587,569.8463,579.2575,17.6279,0.34,9.2896,-8.8111,8.2903,588.6263,569.8463,546.0898,51.228,32.448,8.6915,3.2009,9.2896,-11.672,568.1875,30.7892,42.5365,0.5585,5.894,62.0103,0.8185,0.0793
1,800.6,800.6,572.2134,102622.6,543,0,-0.0922,538.3041,0.6877,0,0,0.0528,0.0522,0.0518,0,0,0,5.647,0,0,100,0,0,0,0,0,0,0,0,0,0,564.6208,-183833.9,20.5838,5.7361,0,0,0,0,0,0,0,0,0,0,4.4181,0.3582,0.1796,0.1796,560.5154,22.2113,33.9093,-11.698,0.9796,0.655,7882.209,0.3585,568.314,30.01,-5.849,0,183.1017,28.0603,-4.6959,-0.2114,0,0,1507964,-538.3041,0,0,0,1.51E+08,0,0,53.0551,34.7721,559.6535,569.2074,586.6536,25.5248,0.3582,9.3912,-8.912,8.3654,602.0286,569.2074,544.2786,63.7246,30.9033,5.9745,3.238,9.3912,-11.7918,571.8382,33.5341,57.7501,0.4317,10.6661,58.9372,0.8374,0.0783
1,816,816,571.3397,102024.7,555,0,-0.0978,545.382,0.6156,0,0,0.0528,0.0522,0.0518,0,0,0,5.4974,0,0,100,0,0,0,0,0,0,0,0,0,0,567.7271,-183115.3,20.9399,2.3107,0,0,0,0,0,0,0,0,0,0,4.4039,0.3206,0.1607,0.1607,558.9248,13.5428,25.9577,-12.4149,0.9783,0.5217,7879.236,0.3209,567.2014,21.8194,-6.2075,0,-175.7867,19.7503,-9.618,-0.7102,0,0,1507964,-545.382,0,0,0,1.51E+08,0,0,53.0339,34.7484,554.6629,569.9097,578.2049,10.2912,0.3206,9.3763,-8.8655,8.5027,582.0693,569.9097,550.7985,36.6873,24.5277,5.4165,3.2935,9.3763,-11.8384,567.5925,22.2105,31.2708,0.6112,6.7732,69.4187,0.8314,0.0791
1,831.4,831.4,572.4175,103181.3,541,0,-0.0927,533.0179,0.5284,0,0,0.0528,0.0522,0.0518,0,0,0,5.4108,0,0,100,0,0,0,0,0,0,0,0,0,0,564.1091,-184489.1,21.9554,7.1748,0,0,0,0,0,0,0,0,0,0,4.4155,0.2752,0.1379,0.1379,560.6522,27.6343,39.3996,-11.7653,0.9794,0.7014,7875.649,0.2754,568.4957,35.4778,-5.8827,0,113.4345,33.517,-7.9821,-0.2888,0,0,1507964,-533.0179,0,0,0,1.51E+08,0,0,53.0433,34.7733,560.2878,569.1275,588.2309,31.9578,0.2752,9.4691,-8.9011,8.9142,609.1378,569.1275,539.3809,76.1199,36.1096,6.363,3.4834,9.4691,-12.1093,572.5488,39.5308,69.7569,0.4264,11.9629,56.8072,0.8432,0.0795
1,846.8,846.8,571.4557,103453.5,557,0,-0.0944,551.7789,0.5941,0,0,0.0528,0.0522,0.0518,0,0,0,5.4916,0,0,100,0,0,0,0,0,0,0,0,0,0,567.9834,-184844.7,21.1179,1.162,0,0,0,0,0,0,0,0,0,0,4.4077,0.3094,0.1551,0.1551,559.4699,7.691,19.6768,-11.9858,0.979,0.3909,7878.351,0.3097,567.4604,15.6815,-5.9929,0,-252.4197,13.6839,-5.2211,-0.6789,0,0,1507964,-551.7789,0,0,0,1.51E+08,0,0,53.058,34.7878,555.3517,570.0806,578.0672,5.1723,0.3094,9.4679,-8.9313,8.5799,579.1895,570.0806,554.2294,27.4106,18.3018,2.4505,3.315,9.4679,-11.9369,567.8332,16.0543,24.9601,0.6351,11.1857,77.7578,0.846,0.0787
1,862.2,862.2,572.5926,103546.3,536,0,-0.0941,528.7189,0.3698,0,0,0.0528,0.0522,0.0518,0,0,0,5.178,0,0,100,0,0,0,0,0,0,0,0,0,0,564.1165,-185000.4,23.2412,7.9356,0,0,0,0,0,0,0,0,0,0,4.4117,0.1926,0.0964,0.0964,560.6337,31.9149,43.8737,-11.9589,0.9791,0.7274,7869.131,0.1927,568.6063,39.8875,-5.9795,0,82.7486,37.8943,-7.2811,-0.2281,0,0,1507964,-528.7189,0,0,0,1.51E+08,0,0,53.0294,34.7712,560.3006,569.2359,588.7346,35.3827,0.1926,9.5398,-8.8844,9.4266,612.6497,569.2359,536.3854,83.9309,40.517,7.6665,3.7181,9.5398,-12.4099,572.757,44.0381,76.2644,0.4307,10.9478,55.9453,0.848,0.0807
1,877.6,877.6,571.5802,104872.6,561,0,-0.0954,554.452,0.5337,0,0,0.0528,0.0522,0.0519,0,0,0,5.3844,0,0,100,0,0,0,0,0,0,0,0,0,0,568.0151,-186524.9,21.4853,0.9032,0,0,0,0,0,0,0,0,0,0,4.4063,0.278,0.1393,0.1393,559.4684,5.0164,17.1282,-12.1118,0.9788,0.2929,7875.87,0.2782,567.5429,13.0909,-6.0559,0,-404.0022,11.0723,-6.548,-1.3053,0,0,1507964,-554.452,0,0,0,1.51E+08,0,0,53.076,34.8225,555.3481,570.1678,578.3815,4.0194,0.278,9.568,-8.9859,8.7313,579.0627,570.1678,554.6668,24.6107,15.7158,0.2148,3.3644,9.568,-12.0723,567.9658,13.5138,24.3959,0.6354,114.575,80.3803,0.8601,0.0786
1,893,893,572.4147,103996.3,535,0,-0.0936,527.793,0.2441,0,0,0.0528,0.0522,0.0518,0,0,0,4.9947,0,0,100,0,0,0,0,0,0,0,0,0,0,564.6043,-185582.7,24.3529,7.8013,0,0,0,0,0,0,0,0,0,0,4.4079,0.1271,0.0636,0.0636,560.5184,32.7253,44.6216,-11.8963,0.9792,0.7334,7863.97,0.1271,568.4492,40.6562,-5.9482,0,105.3846,38.6735,-7.207,-0.2202,0,0,1507964,-527.793,0,0,0,1.51E+08,0,0,53.0212,34.7737,559.7125,569.3212,587.2986,34.8094,0.1271,9.6041,-8.8785,9.8702,610.9481,569.3212,536.063,83.1551,41.5282,8.27,3.9301,9.6041,-12.6815,572.1108,44.3178,74.8851,0.4441,10.055,55.8078,0.8527,0.0816
1,908.4,908.4,571.901,106113.4,561,0,-0.0949,554.1679,0.4592,0,0,0.0528,0.0522,0.0518,0,0,0,5.2699,0,0,100,0,0,0,0,0,0,0,0,0,0,567.3715,-188057.2,22.4961,1.3602,0,0,0,0,0,0,0,0,0,0,4.4076,0.2392,0.1198,0.1198,559.8512,5.6833,17.7331,-12.0498,0.9789,0.3205,7872.807,0.2393,567.8844,13.7165,-6.0249,0,945.5395,11.7082,-6.8321,-1.2021,0,0,1507964,-554.1679,0,0,0,1.51E+08,0,0,53.0897,34.8522,556.4969,570.106,580.557,6.0526,0.2392,9.6642,-9.0308,9.1426,581.9938,570.106,555.0601,27.8259,15.9381,0.8922,3.5589,9.6642,-12.3505,569.0533,14.8854,26.9337,0.5586,31.188,76.646,0.8726,0.0788
1,923.8,923.8,572.1528,104640.7,537,0,-0.0951,530.1049,0.1467,0,0,0.0528,0.0522,0.0518,0,0,0,4.8052,0,0,100,0,0,0,0,0,0,0,0,0,0,565.8071,-186375.6,25.2642,6.8418,0,0,0,0,0,0,0,0,0,0,4.402,0.0764,0.0382,0.0382,560.0523,29.9474,42.0479,-12.1005,0.9789,0.7122,7859.98,0.0764,568.1193,38.0144,-6.0503,0,191.4397,35.9977,-6.8951,-0.2302,0,0,1507964,-530.1049,0,0,0,1.51E+08,0,0,53.0201,34.7837,558.0426,569.6389,584.2563,30.5411,0.0764,9.6708,-8.8878,10.2352,604.3842,569.6389,537.9147,74.2793,39.534,7.8098,4.1072,9.6708,-12.9186,570.6459,40.541,66.4695,0.4773,9.511,56.6134,0.8594,0.0822
1,939.2,939.2,571.5544,107255.3,556,0,-0.0936,551.4111,0.3456,0,0,0.0528,0.0522,0.0518,0,0,0,5.1276,0,0,100,0,0,0,0,0,0,0,0,0,0,566.6774,-189396.5,24.0036,2.6786,0,0,0,0,0,0,0,0,0,0,4.4035,0.18,0.0901,0.0901,559.6623,8.2512,20.1433,-11.8921,0.9792,0.4096,7868.138,0.1801,567.5903,16.1792,-5.9461,0,-350.2869,14.1973,-4.5889,-0.5561,0,0,1507964,-551.4111,0,0,0,1.51E+08,0,0,53.0949,34.8738,556.6672,569.621,580.8884,11.9231,0.18,9.7629,-9.0586,9.7521,585.7728,569.621,551.7829,34.3618,18.2099,0.3718,3.8607,9.7629,-12.7393,569.0589,17.6478,33.99,0.5248,92.4201,67.7235,0.8843,0.0795
1,954.6,954.6,571.895,105532.3,544,0,-0.0961,534.5015,0.0466,0,0,0.0528,0.0522,0.0518,0,0,0,4.6206,0,0,100,0,0,0,0,0,0,0,0,0,0,566.8451,-187464.2,26.1133,5.277,0,0,0,0,0,0,0,0,0,0,4.3966,0.0243,0.0122,0.0122,559.6569,25.1554,37.3935,-12.2381,0.9786,0.6727,7855.884,0.0243,567.8157,33.3142,-6.1191,0,789.5944,31.2745,-9.4985,-0.3776,0,0,1507964,-534.5015,0,0,0,1.51E+08,0,0,53.0233,34.8006,556.6027,569.894,581.5391,23.5636,0.0243,9.7532,-8.9086,10.5758,595.7299,569.894,542.412,61.2284,35.3925,7.9105,4.2684,9.7532,-13.1527,569.3453,34.8438,53.3179,0.5154,7.7401,58.9423,0.8689,0.0826
1,970,970,572.2579,108082.8,549,0,-0.0941,544.2773,0.1392,0,0,0.0528,0.0522,0.0518,0,0,0,4.7892,0,0,100,0,0,0,0,0,0,0,0,0,0,565.0822,-190414.1,25.6348,4.3971,0,0,0,0,0,0,0,0,0,0,4.4037,0.0725,0.0363,0.0363,560.2904,16.0131,27.9806,-11.9675,0.9791,0.5723,7859.673,0.0725,568.2687,23.9914,-5.9838,0,178.2997,21.9969,-4.7227,-0.2949,0,0,1507964,-544.2773,0,0,0,1.51E+08,0,0,53.0822,34.8792,559.0029,569.4125,586.0074,19.5958,0.0725,9.872,-9.051,10.4025,596.3023,569.4125,548.7079,52.025,25.1352,4.4306,4.1661,9.872,-13.1446,571.4742,27.1969,47.5944,0.435,11.7422,62.2841,0.8935,0.0808
1,985.4,985.4,571.7101,106790.7,550,0,-0.0958,541.1818,-0.0002,0,0,0.0528,0.0522,0.0518,0,0,0,4.533,0,0,100,0,0,0,0,0,0,0,0,0,0,567.5685,-188913.1,26.8015,3.5149,0,0,0,0,0,0,0,0,0,0,4.3944,-0.0001,0,0,559.5134,18.3316,30.5283,-12.1967,0.9787,0.6005,7853.967,-0.0001,567.6445,26.4627,-6.0984,0,-816.2599,24.43,-8.8182,-0.481,0,0,1507964,-541.1818,0,0,0,1.51E+08,0,0,53.0395,34.8309,555.7916,570.0684,579.6324,15.6913,-0.0001,9.8382,-8.9568,10.8572,587.4177,570.0684,548.0064,46.2359,28.8866,6.8246,4.4095,9.8382,-13.3664,568.4975,27.3157,39.4113,0.5598,6.7749,63.6116,0.8813,0.0826
1,1000.8,1000.8,572.6118,108701.5,545,0,-0.0922,538.2163,0.0134,0,0,0.0528,0.0522,0.0518,0,0,0,4.5832,0,0,100,0,0,0,0,0,0,0,0,0,0,564.705,-191178.2,27.1591,6.1406,0,0,0,0,0,0,0,0,0,0,4.4054,0.007,0.0035,0.0035,560.8741,22.6578,34.3955,-11.7377,0.9795,0.6587,7854.525,0.007,568.6992,30.4829,-5.8689,0,92.5504,28.5267,-6.7837,-0.2994,0,0,1507964,-538.2163,0,0,0,1.51E+08,0,0,53.0768,34.886,560.2844,569.476,587.7753,27.3838,0.007,9.9457,-9.0525,11.0138,604.6699,569.476,543.3899,66.4536,31.2597,5.1736,4.4867,9.9457,-13.5322,572.512,34.2956,61.28,0.4257,12.8448,58.3273,0.9002,0.0817
1,1016.2,1016.2,571.4836,108146.9,559,0,-0.097,549.2562,-0.0271,0,0,0.0528,0.0522,0.0518,0,0,0,4.4955,0,0,100,0,0,0,0,0,0,0,0,0,0,568.2606,-190543.6,27.2516,1.9563,0,0,0,0,0,0,0,0,0,0,4.3908,-0.0141,-0.007,-0.007,559.1333,9.8771,22.2274,-12.3503,0.9784,0.4444,7852.868,-0.0141,567.3668,18.1106,-6.1752,0,-266.4688,16.0523,-9.7438,-0.9865,0,0,1507964,-549.2562,0,0,0,1.51E+08,0,0,53.0612,34.8672,554.6325,570.2055,577.66,8.7292,-0.0141,9.9263,-9.0169,11.0449,580.595,570.2055,551.6975,31.3388,20.9493,2.4413,4.4988,9.9263,-13.5298,567.4993,18.2431,28.8975,0.6405,12.8369,71.4161,0.8953,0.0822
1,1031.6,1031.6,572.4441,109170.6,541,0,-0.0933,532.619,-0.1914,0,0,0.0528,0.0522,0.0518,0,0,0,4.2687,0,0,100,0,0,0,0,0,0,0,0,0,0,564.2073,-191783.4,28.6244,7.4305,0,0,0,0,0,0,0,0,0,0,4.3982,-0.0997,-0.0498,-0.0498,560.555,27.936,39.8251,-11.8891,0.9792,0.7015,7846.152,-0.0997,568.481,35.862,-5.9446,0,108.0856,33.8806,-8.381,-0.3,0,0,1507964,-532.619,0,0,0,1.51E+08,0,0,53.0579,34.8818,560.1341,569.1769,588.2514,33.1808,-0.0997,10.0346,-9.0286,11.5925,610.229,569.1769,538.1565,77.61,36.5579,5.5375,4.7699,10.0346,-13.8982,572.5208,39.9018,72.0725,0.4304,14.0154,56.4812,0.9063,0.0831
1,1047,1047,571.2866,109776.7,561,0,-0.0956,555.8355,-0.0983,0,0,0.0528,0.0522,0.0518,0,0,0,4.3729,0,0,100,0,0,0,0,0,0,0,0,0,0,568.2545,-192456,27.2177,0.9992,0,0,0,0,0,0,0,0,0,0,4.389,-0.0512,-0.0256,-0.0256,559.1114,3.2759,15.4511,-12.1752,0.9787,0.212,7849.956,-0.0512,567.2282,11.3927,-6.0876,0,-177.9448,9.3635,-5.1645,-1.5765,0,0,1507964,-555.8355,0,0,0,1.51E+08,0,0,53.0813,34.9062,554.5681,570.0837,577.11,4.4574,-0.0512,10.0407,-9.078,11.0339,577.9594,570.0837,553.7188,22.1239,14.2482,-2.1167,4.449,10.0407,-13.5782,567.254,11.4185,24.2406,0.6751,-10.4521,79.2112,0.9115,0.082
1,1062.4,1062.4,572.5206,109783.6,536,0,-0.0934,529.0097,-0.3369,0,0,0.0528,0.0522,0.0518,0,0,0,4.0512,0,0,100,0,0,0,0,0,0,0,0,0,0,564.149,-192586.8,30.0542,7.982,0,0,0,0,0,0,0,0,0,0,4.3953,-0.1755,-0.0876,-0.0876,560.6096,31.5999,43.5109,-11.911,0.9792,0.7263,7840.215,-0.1754,568.5503,39.5406,-5.9555,0,91.478,37.5554,-6.9903,-0.2212,0,0,1507964,-529.0097,0,0,0,1.51E+08,0,0,53.0504,34.8876,560.2863,569.1993,588.6011,35.6717,-0.1755,10.1152,-9.0268,12.1618,612.8221,569.1993,536.0653,83.8124,40.1896,7.0556,5.0705,10.1152,-14.2728,572.6956,43.6859,76.7568,0.4317,11.8789,55.8236,0.9129,0.0841
1,1077.8,1077.8,571.4446,111505.1,564,0,-0.0959,556.9893,-0.1741,0,0,0.0528,0.0522,0.0518,0,0,0,4.2528,0,0,100,0,0,0,0,0,0,0,0,0,0,568.0787,-194546,27.6851,0.8569,0,0,0,0,0,0,0,0,0,0,4.3881,-0.0907,-0.0453,-0.0453,559.2175,2.2282,14.4553,-12.2271,0.9786,0.1541,7846.858,-0.0907,567.3689,10.3796,-6.1136,0,-259.0933,8.3418,-7.0107,-3.1464,0,0,1507964,-556.9893,0,0,0,1.51E+08,0,0,53.1034,34.9489,554.9204,570.1086,577.9241,3.8215,-0.0907,10.1655,-9.1449,11.2266,578.5423,570.1086,554.3022,21.553,13.1193,-2.6871,4.5207,10.1655,-13.7563,567.6511,10.6617,24.2401,0.6521,-8.0209,80.8104,0.9299,0.0818
1,1093.2,1093.2,572.2584,110602.7,537,0,-0.0946,529.0908,-0.4679,0,0,0.0528,0.0522,0.0518,0,0,0,3.8409,0,0,100,0,0,0,0,0,0,0,0,0,0,564.9906,-193566.1,31.2536,7.6488,0,0,0,0,0,0,0,0,0,0,4.389,-0.2437,-0.1216,-0.1216,560.1872,31.0964,43.1676,-12.0712,0.9789,0.7204,7834.881,-0.2435,568.2347,39.1439,-6.0356,0,144.5777,37.132,-7.9092,-0.2543,0,0,1507964,-529.0908,0,0,0,1.51E+08,0,0,53.0476,34.899,558.9383,569.3744,586.2341,34.2035,-0.2437,10.2013,-9.0357,12.6395,609.412,569.3744,535.7603,80.3212,40.2836,6.6695,5.3204,10.2013,-14.5998,571.5156,42.4248,73.6517,0.4564,12.0431,55.8765,0.9219,0.0848
1,1108.6,1108.6,571.6831,113001.2,563,0,-0.0952,556.8568,-0.2575,0,0,0.0528,0.0522,0.0518,0,0,0,4.1267,0,0,100,0,0,0,0,0,0,0,0,0,0,567.697,-196400,29.0429,1.6213,0,0,0,0,0,0,0,0,0,0,4.3888,-0.1341,-0.067,-0.067,559.5492,2.6924,14.8263,-12.1339,0.9788,0.1816,7843.457,-0.1341,567.6385,10.7817,-6.067,0,-764.276,8.7594,-6.1432,-2.2817,0,0,1507964,-556.8568,0,0,0,1.51E+08,0,0,53.1208,34.9852,555.7716,570.1003,579.3726,7.2295,-0.1341,10.2803,-9.2003,11.7788,581.4111,570.1003,553.7332,24.5543,13.2435,-3.1236,4.8154,10.2803,-14.1498,568.4149,11.5581,27.6779,0.5913,-7.8609,74.2533,0.9459,0.082
1,1124,1124,572.0369,111488.2,538,0,-0.0923,531.8663,-0.58,0,0,0.0528,0.0522,0.0518,0,0,0,3.6127,0,0,100,0,0,0,0,0,0,0,0,0,0,565.9476,-194643.6,32.3055,6.5081,0,0,0,0,0,0,0,0,0,0,4.3869,-0.3021,-0.1507,-0.1507,560.2453,28.379,40.1707,-11.7916,0.9794,0.7065,7830.32,-0.3019,568.1064,36.2401,-5.8958,0,294.7345,34.2749,-6.1337,-0.2161,0,0,1507964,-531.8663,0,0,0,1.51E+08,0,0,53.0489,34.9143,558.2723,569.62,583.7607,29.1149,-0.3021,10.2864,-9.0529,13.0594,602.7984,569.62,539.2346,70.9321,37.7537,7.3683,5.541,10.2864,-14.896,570.551,38.6847,63.5638,0.478,9.6267,56.82,0.9314,0.0854
1,1139.4,1139.4,571.7943,114356.4,555,0,-0.0929,551.6118,-0.3973,0,0,0.0528,0.0522,0.0518,0,0,0,3.9167,0,0,100,0,0,0,0,0,0,0,0,0,0,566.3581,-198087.5,31.0941,3.084,0,0,0,0,0,0,0,0,0,0,4.3887,-0.2069,-0.1033,-0.1033,559.9432,8.3314,20.1825,-11.8511,0.9793,0.4128,7837.759,-0.2068,567.8439,16.2321,-5.9256,0,-8104.596,14.257,-3.3882,-0.4067,0,0,1507964,-551.6118,0,0,0,1.51E+08,0,0,53.1278,35.0124,557.4479,569.6349,582.3011,13.7571,-0.2069,10.4033,-9.2355,12.6059,588.4131,569.6349,551.3359,36.8013,18.0231,-0.2759,5.2705,10.4033,-14.7129,569.7946,18.1828,37.0772,0.4935,-133.3864,66.0455,0.9609,0.0826
1,1154.8,1154.8,571.8137,112772.2,545,0,-0.0962,537.5156,-0.6711,0,0,0.0528,0.0522,0.0518,0,0,0,3.4512,0,0,100,0,0,0,0,0,0,0,0,0,0,567.2011,-196215.5,33.27,4.8693,0,0,0,0,0,0,0,0,0,0,4.3792,-0.3495,-0.1743,-0.1743,559.5263,22.0107,34.2981,-12.2874,0.9785,0.6417,7826.621,-0.3492,567.718,30.2024,-6.1437,0,8654.757,28.1544,-7.4844,-0.34,0,0,1507964,-537.5156,0,0,0,1.51E+08,0,0,53.0608,34.9432,556.1408,569.9822,580.71,21.7845,-0.3495,10.3899,-9.095,13.4487,593.4349,569.9822,543.4159,55.9193,32.4666,5.9003,5.7446,10.3899,-15.1891,568.9443,31.4287,50.019,0.5311,9.4774,59.7097,0.9454,0.0856
1,1170.2,1170.2,572.3091,115532.4,549,0,-0.0904,544.7589,-0.5913,0,0,0.0528,0.0522,0.0518,0,0,0,3.5985,0,0,100,0,0,0,0,0,0,0,0,0,0,564.5952,-199512,32.9663,4.8572,0,0,0,0,0,0,0,0,0,0,4.3907,-0.308,-0.1536,-0.1536,560.7636,16.0047,27.5502,-11.5455,0.9798,0.5809,7829.859,-0.3077,568.4606,23.7017,-5.7728,0,161.1361,21.7775,-4.2411,-0.265,0,0,1507964,-544.7589,0,0,0,1.51E+08,0,0,53.1231,35.0283,560.2028,569.2438,587.2418,21.6869,-0.308,10.529,-9.247,13.3526,599.2781,569.2438,548.1665,54.5192,24.4849,3.4076,5.6687,10.529,-15.2237,572.2294,27.4706,51.1116,0.4124,15.9993,60.9696,0.974,0.0837
1,1185.6,1185.6,571.4496,114379.2,553,0,-0.0961,544.7125,-0.7546,0,0,0.0528,0.0522,0.0518,0,0,0,3.317,0,0,100,0,0,0,0,0,0,0,0,0,0,567.4131,-198176.4,34.1039,3.0941,0,0,0,0,0,0,0,0,0,0,4.3745,-0.393,-0.1959,-0.1959,559.168,14.4555,26.7371,-12.2816,0.9785,0.5407,7823.229,-0.3926,567.3557,22.6432,-6.1408,0,-228.2149,20.5963,-8.2875,-0.5733,0,0,1507964,-544.7125,0,0,0,1.51E+08,0,0,53.0799,34.982,555.3553,569.8461,579.2518,13.8401,-0.393,10.5101,-9.1548,13.7882,585.5876,569.8461,549.0194,40.8751,25.1336,4.3069,5.9149,10.5101,-15.4627,568.1511,23.4385,36.5682,0.5695,9.4906,65.4021,0.9623,0.0855
1,1201,1201,572.4811,116420.2,546,0,-0.0925,537.6102,-0.7906,0,0,0.0528,0.0522,0.0518,0,0,0,3.2796,0,0,100,0,0,0,0,0,0,0,0,0,0,564.3383,-200648.2,34.7565,6.5689,0,0,0,0,0,0,0,0,0,0,4.3853,-0.4118,-0.2053,-0.2053,560.6535,23.0433,34.8709,-11.8276,0.9793,0.6608,7821.765,-0.4114,568.5386,30.9283,-5.9138,0,109.5554,28.9571,-8.3898,-0.3641,0,0,1507964,-537.6102,0,0,0,1.51E+08,0,0,53.1133,35.037,560.2762,569.2446,588.264,29.361,-0.4118,10.6421,-9.2459,14.0626,606.7954,569.2446,541.7448,69.1852,31.6344,4.1346,6.0518,10.6421,-15.7095,572.595,34.9847,65.0506,0.4227,16.7332,57.7416,0.9844,0.0849
1,1216.4,1216.4,571.4606,116194,562,0,-0.096,553.3283,-0.8126,0,0,0.0528,0.0522,0.0518,0,0,0,3.2036,0,0,100,0,0,0,0,0,0,0,0,0,0,567.9351,-200346.9,34.5956,1.6832,0,0,0,0,0,0,0,0,0,0,4.3733,-0.4232,-0.2109,-0.2109,559.1828,5.8545,18.1323,-12.2778,0.9785,0.3229,7820.877,-0.4227,567.368,14.0397,-6.1389,0,-260.4926,11.9934,-8.6717,-1.4812,0,0,1507964,-553.3283,0,0,0,1.51E+08,0,0,53.1057,35.0279,554.9961,570.0594,578.2916,7.5256,-0.4232,10.6329,-9.2287,13.9934,580.5113,570.0594,552.7764,27.183,16.7311,-0.5519,6.0042,10.6329,-15.6561,567.7824,14.4541,27.7349,0.6231,-49.2535,73.5668,0.981,0.0851
1,1231.8,1231.8,572.6549,117232.2,537,0,-0.0903,531.2677,-1.0318,0,0,0.0528,0.0522,0.0518,0,0,0,2.8935,0,0,100,0,0,0,0,0,0,0,0,0,0,563.9617,-201676.8,36.5141,7.674,0,0,0,0,0,0,0,0,0,0,4.3833,-0.5374,-0.2676,-0.2676,561.0988,29.8311,41.3872,-11.5561,0.9798,0.7208,7811.993,-0.5367,568.8029,37.5352,-5.7781,0,79.6796,35.6092,-5.7323,-0.1922,0,0,1507964,-531.2677,0,0,0,1.51E+08,0,0,53.0961,35.0393,561.3003,569.1988,589.5241,34.3499,-0.5374,10.7616,-9.2306,14.7524,612.548,569.1988,538.2765,81.2803,37.9311,7.0088,6.4169,10.7616,-16.1849,573.3411,42.0734,74.2715,0.4163,11.5969,56.1671,0.9936,0.0865
1,1247.2,1247.2,571.2513,118153.3,564,0,-0.0943,558.6876,-0.9468,0,0,0.0528,0.0522,0.0518,0,0,0,2.9902,0,0,100,0,0,0,0,0,0,0,0,0,0,568.2284,-202699.2,34.1746,0.9243,0,0,0,0,0,0,0,0,0,0,4.3703,-0.4931,-0.2456,-0.2456,559.1882,0.5005,12.5637,-12.0631,0.9789,0.0398,7815.437,-0.4925,567.2302,8.5426,-6.0316,0,-171.7408,6.5321,-5.3124,-10.6142,0,0,1507964,-558.6876,0,0,0,1.51E+08,0,0,53.1237,35.0711,554.7336,570.0493,577.1238,4.1328,-0.4931,10.7874,-9.2917,13.8223,577.8623,570.0493,553.9951,19.1747,11.3617,-4.6925,5.8259,10.7874,-15.6107,567.3022,8.6146,23.8672,0.6726,-4.0862,79.8689,1.0026,0.0852
1,1262.6,1262.6,572.4311,118159.1,536,0,-0.0932,529.083,-1.2231,0,0,0.0528,0.0522,0.0518,0,0,0,2.5761,0,0,100,0,0,0,0,0,0,0,0,0,0,564.2352,-202783.7,38.1802,7.9452,0,0,0,0,0,0,0,0,0,0,4.3742,-0.637,-0.317,-0.317,560.4886,31.4056,43.3481,-11.9425,0.9791,0.7245,7804.262,-0.636,568.4503,39.3673,-5.9713,0,104.6812,37.3769,-6.917,-0.2202,0,0,1507964,-529.083,0,0,0,1.51E+08,0,0,53.087,35.048,560.1037,569.1719,588.3549,35.6003,-0.637,10.8709,-9.2302,15.4098,612.5296,569.1719,535.929,83.4466,40.0889,6.846,6.7793,10.8709,-16.6465,572.5435,43.4605,76.6006,0.434,12.1891,55.8212,1.0037,0.0876
1,1278,1278,571.5368,120044.9,565,0,-0.0933,557.8564,-1.3212,0,0,0.0528,0.0522,0.0519,0,0,0,2.408,0,0,100,0,0,0,0,0,0,0,0,0,0,568.0353,-205062.6,34.2281,0.9362,0,0,0,0,0,0,0,0,0,0,4.3649,-0.6881,-0.3423,-0.3423,559.581,1.7246,13.6804,-11.9558,0.9791,0.1261,7800.301,-0.6869,567.5515,9.6951,-5.9779,0,-351.3598,7.7025,-7.1436,-4.1422,0,0,1507964,-557.8564,0,0,0,1.51E+08,0,0,53.1089,35.0926,555.5612,570.1436,578.3571,4.194,-0.6881,11.0106,-9.2986,13.8174,579.1042,570.1436,554.8141,21.2478,12.2872,-3.0423,5.6835,11.0106,-15.6702,568.0206,10.1642,24.2901,0.6311,-6.9841,79.8992,1.0239,0.087
1,1293.4,1293.4,572.209,119335.5,536,0,-0.0934,529.6702,-1.4683,0,0,0.0528,0.0522,0.0518,0,0,0,2.1926,0,0,100,0,0,0,0,0,0,0,0,0,0,565.0093,-204314.5,39.7995,7.4678,0,0,0,0,0,0,0,0,0,0,4.3666,-0.7647,-0.3802,-0.3802,560.2248,30.5546,42.5388,-11.9842,0.9791,0.7183,7794.372,-0.7633,568.2143,38.5441,-5.9921,0,163.7133,36.5467,-6.3298,-0.2072,0,0,1507964,-529.6702,0,0,0,1.51E+08,0,0,53.0771,35.0617,559.0596,569.345,586.2211,33.5034,-0.7647,11.0161,-9.2341,16.0431,608.7917,569.345,536.4891,79.1215,39.6747,6.8188,7.1094,11.0161,-17.1082,571.5419,41.8717,72.3027,0.4544,11.6034,56.0327,1.0173,0.0891
1,1308.8,1308.8,571.4922,122236.4,566,0,-0.0953,559.1141,-1.3029,0,0,0.0528,0.0522,0.0518,0,0,0,2.3936,0,0,100,0,0,0,0,0,0,0,0,0,0,568.0189,-207802.6,37.2263,1.8241,0,0,0,0,0,0,0,0,0,0,4.3629,-0.6786,-0.3376,-0.3376,559.2718,0.1577,12.3781,-12.2204,0.9786,0.0127,7801.037,-0.6775,567.4187,8.3046,-6.1102,0,-305.2915,6.2679,-6.8859,-43.6646,0,0,1507964,-559.1141,0,0,0,1.51E+08,0,0,53.1539,35.1585,555.1058,570.1094,578.2781,8.1612,-0.6786,11.1395,-9.4125,15.047,580.8638,570.1094,552.52,21.7497,10.9953,-6.5941,6.4556,11.1395,-16.5467,567.8311,8.717,28.3438,0.6206,-3.2984,72.4197,1.0484,0.0861
1,1309.8,1309.8,572.3897,122480,558,0,-0.0927,549.6353,-1.3383,0,0,0.0528,0.0522,0.0518,0,0,0,2.3774,0,0,100,0,0,0,0,0,0,0,0,0,0,565.6157,-208109.9,38.8483,3.9598,0,0,0,0,0,0,0,0,0,0,4.3717,-0.697,-0.3467,-0.3467,560.5022,10.8669,22.7544,-11.8875,0.9792,0.4776,7799.612,-0.6958,568.4272,18.7919,-5.9438,0,147.2523,16.8107,-8.3647,-0.7697,0,0,1507964,-549.6353,0,0,0,1.51E+08,0,0,53.1538,35.1625,559.0902,569.6927,585.6289,17.7191,-0.697,11.1648,-9.4165,15.7003,594.4965,569.6927,550.2227,44.8612,20.0574,0.5874,6.8704,11.1648,-16.9839,571.4706,21.8353,44.2738,0.4398,76.3725,63.4143,1.0513,0.0864