File: datas/d100-30-0.25_1.2_2.csv
Stage Number,Time since start of test (s),Time since start of stage (s),Radial Pressure (kPa),Radial Volume (mm3),Back Pressure (kPa),Back Volume (mm3),Load Cell (kN),Pore Pressure (kPa),Axial Displacement (mm),L/C Pressure (kPa),L/C Volume (mm3),Local Axial 1,Local Axial 2,Local Radial,Base Pressure (kPa),Base Volume (mm3),Back Differential Pressure (kPa),Axial Displacement 2 (mm),Pore Air Pressure (kPa),Pore Air Volume (mm3),Atmospheric Pressure (kPa),Temperature (°C),Mid Plane PWP (kPa),Back to Cell Differential (kPa),Total Volume Change (mm3),Undefined Tx 1,Undefined Tx 2,Undefined Tx 3,Undefined Tx. 4,HCA secondary control axial load (kN),HCA secondary control torque,Internal Cell Pr. (kPa),Internal Cell Vol. (mm3),Rotational Displ. (mm),Torque,Local Int Defmn 1 (mm),Local Int Defmn 2 (mm),Circumf. Defmn 1 (mm),Circumf. Defmn 2 (mm),Circumf. Defmn 3 (mm),Outer Cell Pr 2 (kPa),Internal cell Pr 2 (kPa),Rotation 2 (°),Secondary Cell Pr (kPa),Secondary Back Pr (kPa),Axial Force (kN),Axial Strain (%),Av Diameter Change (mm),Radial Strain (%),Axial Stress (kPa),Eff. Axial Stress (kPa),Eff. Radial Stress (kPa),Deviator Stress (kPa),Total Stress Ratio (%),Eff. Stress Ratio (%),Current Area (mm2),Shear Strain (%),Cambridge p (kPa),Eff. Cambridge p' (kPa),Max Shear Stress t,Volume Change (mm3),B Value,Mean Stress s/Eff. Axial Stress 2,Excess PWP (kPa),PWP Ratio,Lower Chamber Displacement (mm),Lower Chamber Axial Load (kPa),Specimen Air Volume (mm3),Matric Suction (kPa),Voids ratio,Degree of Saturation (°),Specimen Water Volume (mm3),kRT constant,Permeability IN,Permeability OUT,HCA Outer Rad,HCA Inner Rad,HCA Sigma Z (kPa),HCA Sigma R (kPa),HCA Sigma Theta (kPa),HCA Tau Theta Z,HCA Ez,HCA Er,HCA Etheta,HCA Gamma,HCA Sigma1,HCA Sigma2,HCA Sigma3,HCA Eff Sigma1,HCA Eff Sigma2,HCA Eff Sigma3,HCA E1,HCA E2,HCA E3,HCA P,HCA Eff P,HCA Q,HCA B,HCA Eff R,HCA Alpha,HCA Ev,HCA E1 rtv
1,0,0,577.5811,142185.6,481,0,0.0908,482.0748,0.0012,0,0,0.0528,0.0522,0.0518,0,0,0,9.3275,0,0,100,0,0,0,0,0,0,0,0,0,0,584.5171,19932.57,-0.0045,4.3793,0,0,0,0,0,0,0,0,0,0,4.6271,0.0006,0.0003,0.0003,589.1376,107.0628,95.5063,11.5565,1.02,1.121,7854.022,0.0006,581.4333,99.3585,5.7783,0,0.3844,101.2845,1.0748,0.01,0,0,1507964,-482.0748,0,0,0,1.51E+08,0,0,49.6686,29.4442,591.8869,580.1625,567.4832,21.5554,0.0006,-1.1095,1.1214,-0.0017,604.4544,580.1625,554.9157,122.3796,98.0877,72.8409,1.1214,-1.1095,0.0006,579.8442,97.7694,49.5387,0.5096,1.6801,30.2436,0.0125,90.0008
1,2.8,2.8,577.524,142423.5,494,0,0.0925,497.1932,0.1252,0,0,0.0528,0.0522,0.0518,0,0,0,9.5401,0,0,100,0,0,0,0,0,0,0,0,0,0,584.5297,19767.32,2.341,9.3228,0,0,0,0,0,0,0,0,0,0,4.6313,0.0652,0.0326,0.0326,589.2915,92.0983,80.3308,11.7675,1.0204,1.1465,7859.099,0.0652,581.4465,84.2533,5.8838,0,179.748,86.2146,3.1932,0.0347,0,0,1507964,-497.1932,0,0,0,1.51E+08,0,0,49.6874,29.4583,592.117,580.1316,567.322,45.8395,0.0652,-1.1325,1.0794,0.861,627.2059,580.1316,532.2331,130.0127,82.9384,35.0399,1.3646,-1.1325,-0.22,579.8569,82.6637,94.9728,0.5043,3.7104,37.4331,0.0121,89.6496
1,5.8,5.8,577.5868,143100.5,508,0,0.0939,511.8576,0.2115,0,0,0.0528,0.0522,0.0518,0,0,0,9.674,0,0,100,0,0,0,0,0,0,0,0,0,0,585.2363,19021.01,1.8858,1.9488,0,0,0,0,0,0,0,0,0,0,4.6353,0.1102,0.0551,0.0551,589.5349,77.6773,65.7292,11.9481,1.0207,1.1818,7862.64,0.1102,581.5695,69.7119,5.9741,0,202.6754,71.7033,3.8576,0.0497,0,0,1507964,-511.8576,0,0,0,1.51E+08,0,0,49.711,29.486,592.095,580.4348,566.4345,9.572,0.1102,-1.1125,1.0139,0.6943,595.2722,580.4348,563.2573,83.4146,68.5772,51.3997,1.2293,-1.1125,-0.1052,579.6548,67.7972,32.0149,0.5365,1.6229,18.3624,0.0116,89.6642
1,8.8,8.8,577.8864,143826.7,518,0,0.0942,519.4925,0.2769,0,0,0.0528,0.0522,0.0518,0,0,0,9.7923,0,0,100,0,0,0,0,0,0,0,0,0,0,584.2142,18181.12,1.4891,0.9332,0,0,0,0,0,0,0,0,0,0,4.6395,0.1442,0.0722,0.0722,589.8682,70.3757,58.3939,11.9818,1.0207,1.2052,7865.317,0.1443,581.8804,62.3879,5.9909,0,83.8605,64.3848,1.4925,0.0212,0,0,1507964,-519.4925,0,0,0,1.51E+08,0,0,49.7335,29.5146,593.1597,580.2431,568.6495,4.5793,0.1442,-1.0827,0.9488,0.5488,593.9874,580.2431,567.8218,74.4949,60.7506,48.3293,1.1055,-1.0827,-0.0125,580.6841,61.1916,26.1656,0.4747,1.5414,10.2445,0.0103,89.6881
1,11.8,11.8,578.4427,143539.1,509,0,0.0932,511.0653,0.2627,0,0,0.0528,0.0522,0.0518,0,0,0,9.7619,0,0,100,0,0,0,0,0,0,0,0,0,0,583.2478,18543.37,2.9699,9.0163,0,0,0,0,0,0,0,0,0,0,4.6425,0.1368,0.0685,0.0685,590.2933,79.228,67.3774,11.8506,1.0205,1.1759,7864.734,0.1369,582.3929,71.3276,5.9253,0,28.9548,73.3027,2.0653,0.0261,0,0,1507964,-511.0653,0,0,0,1.51E+08,0,0,49.7257,29.5034,594.3483,580.232,571.4323,44.2566,0.1368,-1.0993,0.973,1.0942,628.6061,580.232,537.1746,117.5408,69.1667,26.1093,1.4344,-1.0993,-0.3246,582.0042,70.9389,91.4315,0.4709,4.5019,37.7424,0.0105,89.5035
1,14.8,14.8,577.8058,143462.6,518,0,0.0927,518.6519,0.3364,0,0,0.0528,0.0522,0.0518,0,0,0,9.862,0,0,100,0,0,0,0,0,0,0,0,0,0,585.0026,18640.42,3.7757,5.0551,0,0,0,0,0,0,0,0,0,0,4.6387,0.1752,0.0877,0.0877,589.5834,70.9315,59.1539,11.7776,1.0204,1.1991,7867.759,0.1753,581.7316,63.0797,5.8888,0,100.0285,65.0427,0.6519,0.0092,0,0,1507964,-518.6519,0,0,0,1.51E+08,0,0,49.7336,29.5063,592.3063,580.4857,567.3074,24.8,0.1752,-1.1237,0.9592,1.3918,607.5787,580.4857,552.035,88.9268,61.8338,33.3831,1.6265,-1.1237,-0.4921,580.0331,61.3812,55.5437,0.5122,2.6638,31.6257,0.0107,89.3956
1,17.8,17.8,577.7277,144702.5,535,0,0.0947,536.4141,0.4952,0,0,0.0528,0.0522,0.0518,0,0,0,10.1343,0,0,100,0,0,0,0,0,0,0,0,0,0,585.0912,17223.01,2.5628,-0.6192,0,0,0,0,0,0,0,0,0,0,4.6439,0.2579,0.1292,0.1292,589.7553,53.3412,41.3136,12.0276,1.0208,1.2911,7874.283,0.2581,581.7369,45.3228,6.0138,0,188.7708,47.3274,1.4141,0.0265,0,0,1507964,-536.4141,0,0,0,1.51E+08,0,0,49.7779,29.5584,592.5085,580.4711,566.9632,-3.0318,0.2579,-1.0856,0.8366,0.9466,592.8634,580.4711,566.6083,56.4493,44.057,30.1942,1.2765,-1.0856,-0.182,579.9809,43.5668,26.2551,0.528,1.8695,-6.6765,0.0089,89.3451
1,20.8,20.8,578.0315,144725.3,526,0,0.0946,528.7693,0.4606,0,0,0.0528,0.0522,0.0518,0,0,0,10.1076,0,0,100,0,0,0,0,0,0,0,0,0,0,582.7285,17168.48,3.6838,6.8969,0,0,0,0,0,0,0,0,0,0,4.6454,0.2399,0.1202,0.1202,590.0523,61.283,49.2622,12.0208,1.0208,1.244,7872.862,0.2401,582.0384,53.2691,6.0104,0,78.9786,55.2726,2.7693,0.0452,0,0,1507964,-528.7693,0,0,0,1.51E+08,0,0,49.7743,29.5573,594.2479,579.7815,571.1644,33.7772,0.2399,-1.0733,0.8425,1.3603,618.4009,579.7815,547.0115,89.6316,51.0122,18.2422,1.5492,-1.0733,-0.4668,581.7313,52.962,71.3894,0.459,4.9134,35.5673,0.0091,89.2226
1,23.8,23.8,578.2108,143807.2,518,0,0.0937,520.2462,0.4522,0,0,0.0528,0.0522,0.0518,0,0,0,10.0623,0,0,100,0,0,0,0,0,0,0,0,0,0,584.6299,18238.71,6.1471,7.9142,0,0,0,0,0,0,0,0,0,0,4.6457,0.2355,0.118,0.118,590.1164,69.8702,57.9646,11.9056,1.0206,1.2054,7872.515,0.2357,582.1794,61.9332,5.9528,0,49.5641,63.9174,2.2462,0.0321,0,0,1507964,-520.2462,0,0,0,1.51E+08,0,0,49.7553,29.5265,593.3185,580.6014,568.8414,38.7834,0.2355,-1.1311,0.9059,2.2685,621.7485,580.6014,540.4114,101.5023,60.3552,20.1652,2.2094,-1.1311,-1.068,580.9204,60.6742,81.3371,0.4941,5.0335,36.2431,0.0103,89.1381
1,26.8,26.8,577.5478,144976.2,543,0,0.0907,544.2539,0.6666,0,0,0.0528,0.0522,0.0518,0,0,0,10.4086,0,0,100,0,0,0,0,0,0,0,0,0,0,585.7366,16955.08,4.6073,-0.2465,0,0,0,0,0,0,0,0,0,0,4.6426,0.3472,0.1741,0.1741,589.0624,44.8085,33.2939,11.5146,1.0199,1.3458,7881.339,0.3475,581.386,37.1321,5.7573,0,575.0897,39.0512,1.2539,0.028,0,0,1507964,-544.2539,0,0,0,1.51E+08,0,0,49.8046,29.5792,591.067,580.599,565.572,-1.2051,0.3472,-1.1144,0.7762,1.7042,591.1238,580.599,565.5152,46.8699,36.3451,21.2613,1.7857,-1.1144,-0.6623,579.0793,34.8254,25.6086,0.589,2.2045,-2.7002,0.009,88.7877
1,29.8,29.8,577.9004,145712.3,543,0,0.0943,544.402,0.71,0,0,0.0528,0.0522,0.0518,0,0,0,10.522,0,0,100,0,0,0,0,0,0,0,0,0,0,584.0601,16017.17,4.9702,3.7847,0,0,0,0,0,0,0,0,0,0,4.65,0.3698,0.1854,0.1854,589.8675,45.4655,33.4984,11.9671,1.0207,1.3572,7883.127,0.3701,581.8894,37.4874,5.9836,0,135.3722,39.482,1.402,0.0308,0,0,1507964,-544.402,0,0,0,1.51E+08,0,0,49.8259,29.6089,593.2288,580.1964,568.8792,18.4882,0.3698,-1.0734,0.7115,1.84,603.1909,580.1964,558.9172,58.7889,35.7944,14.5152,1.8529,-1.0734,-0.7716,580.7681,36.3662,44.2737,0.4806,4.0502,28.3172,0.0079,88.4299
1,32.8,32.8,578.4749,144506.3,521,0,0.0937,521.7166,0.5975,0,0,0.0528,0.0522,0.0518,0,0,0,10.3384,0,0,100,0,0,0,0,0,0,0,0,0,0,582.8691,17375.31,7.7801,9.3919,0,0,0,0,0,0,0,0,0,0,4.6512,0.3112,0.156,0.156,590.3667,68.6501,56.7583,11.8918,1.0206,1.2095,7878.493,0.3115,582.4388,60.7222,5.9459,0,38.3413,62.7042,0.7166,0.0104,0,0,1507964,-521.7166,0,0,0,1.51E+08,0,0,49.7886,29.562,594.6653,580.112,572.0527,45.952,0.3112,-1.1203,0.8184,2.8757,630.6815,580.112,536.0365,108.9649,58.3954,14.3199,2.614,-1.1203,-1.4844,582.2767,60.5601,94.645,0.4657,7.6093,38.0886,0.0093,88.7814
1,35.8,35.8,577.3611,144982.9,540,0,0.0905,541.9329,0.747,0,0,0.0528,0.0522,0.0518,0,0,0,10.561,0,0,100,0,0,0,0,0,0,0,0,0,0,585.7637,16925.15,6.9047,1.9428,0,0,0,0,0,0,0,0,0,0,4.6428,0.3891,0.1951,0.1951,588.84,46.9071,35.4282,11.4789,1.0199,1.324,7884.654,0.3895,581.1874,39.2545,5.7395,0,-763.3025,41.1677,1.9329,0.0412,0,0,1507964,-541.9329,0,0,0,1.51E+08,0,0,49.8156,29.5862,590.7163,580.492,565.072,9.4922,0.3891,-1.134,0.7534,2.5557,593.8475,580.492,561.9408,51.9146,38.5591,20.0079,2.3876,-1.134,-1.2451,578.7601,36.8272,31.9067,0.5814,2.5947,18.2562,0.0085,88.356
1,38.8,38.8,577.8546,146269.3,552,0,0.0933,554.6657,1.0083,0,0,0.0528,0.0522,0.0518,0,0,0,10.9805,0,0,100,0,0,0,0,0,0,0,0,0,0,584.5734,15416.35,5.4717,0.877,0,0,0,0,0,0,0,0,0,0,4.6557,0.5252,0.2636,0.2636,589.6694,35.0037,23.1889,11.8148,1.0204,1.5095,7895.442,0.5259,581.7929,27.1272,5.9074,0,175.0325,29.0963,2.6657,0.0762,0,0,1507964,-554.6657,0,0,0,1.51E+08,0,0,49.8749,29.6489,592.6466,580.3596,568.0056,4.2728,0.5252,-1.1174,0.5988,2.031,593.3665,580.3596,567.2857,38.7008,25.6939,12.62,1.9986,-1.1174,-0.8746,580.3372,25.6716,26.0808,0.5013,3.0666,9.5634,0.0066,82.437
1,41.8,41.8,578.4049,145629.4,529,0,0.0948,529.6033,0.8348,0,0,0.0528,0.0522,0.0518,0,0,0,10.7347,0,0,100,0,0,0,0,0,0,0,0,0,0,582.6168,16102.52,8.7561,9.0536,0,0,0,0,0,0,0,0,0,0,4.6574,0.4348,0.2181,0.2181,590.4207,60.8174,48.8016,12.0158,1.0208,1.2462,7888.273,0.4353,582.4102,52.807,6.0079,0,49.2917,54.8095,0.6033,0.0099,0,0,1507964,-529.6033,0,0,0,1.51E+08,0,0,49.8408,29.6162,594.8838,579.9749,572.2371,44.1853,0.4348,-1.1105,0.6834,3.2446,629.1736,579.9749,537.9473,99.5703,50.3716,8.3441,2.8567,-1.1105,-1.7385,582.3652,52.762,91.2262,0.4607,11.933,37.8131,0.0077,87.442
1,44.8,44.8,577.7784,144978.4,536,0,0.093,535.16,0.8654,0,0,0.0528,0.0522,0.0518,0,0,0,10.7611,0,0,100,0,0,0,0,0,0,0,0,0,0,585.2385,16881.23,9.3148,5.0394,0,0,0,0,0,0,0,0,0,0,4.6514,0.4507,0.2261,0.2261,589.5659,54.4059,42.6184,11.7875,1.0204,1.2766,7889.533,0.4512,581.7076,46.5476,5.8938,0,156.8436,48.5122,-0.84,-0.0154,0,0,1507964,-535.16,0,0,0,1.51E+08,0,0,49.8317,29.5966,592.131,580.5582,566.8669,24.5984,0.4507,-1.1618,0.7198,3.4511,607.1512,580.5582,551.8466,71.9912,45.3983,16.6867,3.0293,-1.1618,-1.8588,579.8521,44.6921,55.3045,0.5192,4.3143,31.409,0.0087,87.6054
1,47.8,47.8,577.6857,146431.9,558,0,0.0931,559.7056,1.3696,0,0,0.0528,0.0522,0.0518,0,0,0,11.5707,0,0,100,0,0,0,0,0,0,0,0,0,0,585.4982,15256.33,6.3225,-0.6271,0,0,0,0,0,0,0,0,0,0,4.6628,0.7133,0.3586,0.3586,589.4518,29.7462,17.9801,11.7661,1.0204,1.6544,7910.4,0.7146,581.6077,21.9021,5.8831,0,315.5951,23.8632,1.7056,0.0573,0,0,1507964,-559.7056,0,0,0,1.51E+08,0,0,49.9248,29.6815,591.8042,580.5987,566.2308,-3.0463,0.7133,-1.2019,0.4946,2.3537,592.162,580.5987,565.8729,32.4564,20.8931,6.1673,2.2719,-1.2019,-1.064,579.5446,19.8389,26.2891,0.5601,5.2627,-6.7002,0.006,2.6727
1,50.8,50.8,578.2054,146705.2,539,0,0.0965,543.8564,1.2302,0,0,0.0528,0.0522,0.0518,0,0,0,11.3841,0,0,100,0,0,0,0,0,0,0,0,0,0,582.8558,14897.04,9.4335,6.8929,0,0,0,0,0,0,0,0,0,0,4.667,0.6407,0.3219,0.3219,590.4142,46.5578,34.349,12.2088,1.0211,1.3554,7904.62,0.6417,582.275,38.4186,6.1044,0,80.7461,40.4534,4.8564,0.1043,0,0,1507964,-543.8564,0,0,0,1.51E+08,0,0,49.9125,29.6807,594.7364,579.9395,571.3831,33.5152,0.6407,-1.1457,0.5111,3.5087,618.5508,579.9395,547.5687,74.6944,36.0831,3.7123,3.0578,-1.1457,-1.906,582.0197,38.1633,70.9821,0.456,20.1208,35.3959,0.0061,4.989
1,53.8,53.8,578.159,145208.3,529,0,0.0926,530.5509,1.1079,0,0,0.0528,0.0522,0.0518,0,0,0,11.1624,0,0,100,0,0,0,0,0,0,0,0,0,0,583.9202,16600.56,11.6416,7.9082,0,0,0,0,0,0,0,0,0,0,4.6598,0.577,0.2898,0.2898,589.8813,59.3304,47.6081,11.7223,1.0203,1.2462,7899.555,0.5779,582.0664,51.5155,5.8612,0,67.4577,53.4693,1.5509,0.0261,0,0,1507964,-530.5509,0,0,0,1.51E+08,0,0,49.8681,29.6233,593.3333,580.306,569.7288,38.5225,0.577,-1.2092,0.6398,4.322,621.821,580.306,541.2411,91.2701,49.7551,10.6902,3.6647,-1.2092,-2.4479,581.1227,50.5718,80.5799,0.4848,8.5377,36.4832,0.0076,79.304
1,56.8,56.8,577.4485,146368.5,561,0,0.084,561.9636,1.6622,0,0,0.0528,0.0522,0.0518,0,0,0,12.0335,0,0,100,0,0,0,0,0,0,0,0,0,0,585.5194,15354.61,8.5435,-0.2092,0,0,0,0,0,0,0,0,0,0,4.6589,0.8657,0.4357,0.4357,588.0548,26.0912,15.4849,10.6063,1.0184,1.6849,7922.561,0.8676,580.9839,19.0203,5.3032,0,8971.164,20.7881,0.9636,0.0369,0,0,1507964,-561.9636,0,0,0,1.51E+08,0,0,49.9615,29.7015,589.6036,580.4576,565.6164,-1.014,0.8657,-1.2833,0.423,3.1877,589.6464,580.4576,565.5736,27.6828,18.494,3.61,2.9092,-1.2833,-1.6205,578.5592,16.5956,24.0728,0.6183,7.6684,-2.4163,0.0054,1.4308
1,59.8,59.8,577.9004,147255.9,557,0,0.0984,558.218,1.8553,0,0,0.0528,0.0522,0.0518,0,0,0,12.3913,0,0,100,0,0,0,0,0,0,0,0,0,0,584.3735,14265.09,9.8042,3.7943,0,0,0,0,0,0,0,0,0,0,4.6815,0.9663,0.4867,0.4867,590.3078,32.0898,19.6824,12.4074,1.0215,1.6304,7930.608,0.9687,582.0362,23.8182,6.2037,0,165.3539,25.8861,1.218,0.038,0,0,1507964,-558.218,0,0,0,1.51E+08,0,0,50.0051,29.7473,593.7419,580.3149,568.395,18.3523,0.9663,-1.2726,0.3105,3.6657,603.3715,580.3149,558.7655,45.1535,22.0969,0.5475,3.2511,-1.2726,-1.9743,580.8173,22.5993,44.606,0.4831,82.4722,27.6862,0.0042,0.9946
1,62.8,62.8,578.2744,145836.3,528,0,0.0938,529.2094,1.5208,0,0,0.0528,0.0522,0.0518,0,0,0,11.851,0,0,100,0,0,0,0,0,0,0,0,0,0,582.797,15872.17,14.1405,9.3586,0,0,0,0,0,0,0,0,0,0,4.6718,0.7921,0.3984,0.3984,590.1209,60.9115,49.065,11.8465,1.0205,1.2414,7916.683,0.7937,582.2232,53.0138,5.9233,0,56.5247,54.9883,1.2094,0.0199,0,0,1507964,-529.2094,0,0,0,1.51E+08,0,0,49.9343,29.6759,594.3179,579.9603,571.6495,45.4228,0.7921,-1.2755,0.4896,5.2688,629.7992,579.9603,536.1681,100.5898,50.7509,6.9587,4.3695,-1.2755,-3.0878,581.9759,52.7665,93.6311,0.4677,14.4553,37.9946,0.0062,2.2863
1,65.8,65.8,577.5422,146160.2,554,0,0.0866,553.5033,1.7527,0,0,0.0528,0.0522,0.0518,0,0,0,12.2176,0,0,100,0,0,0,0,0,0,0,0,0,0,585.89,15615.25,13.0006,1.9795,0,0,0,0,0,0,0,0,0,0,4.6644,0.9129,0.4596,0.4596,588.4687,34.9654,24.0389,10.9265,1.0189,1.4545,7926.334,0.915,581.1843,27.681,5.4633,0,696.7139,29.5022,-0.4967,-0.0142,0,0,1507964,-553.5033,0,0,0,1.51E+08,0,0,49.9691,29.7013,590.0528,580.6543,565.3089,9.5888,0.9129,-1.3213,0.4137,4.8535,593.3336,580.6543,562.0281,39.8303,27.151,8.5248,4.1043,-1.3213,-2.7777,578.672,25.1687,31.3055,0.595,4.6723,18.8886,0.0053,1.3698
1,68.8,68.8,577.8844,147309.9,564,0,0.0911,566.7517,2.614,0,0,0.0528,0.0522,0.0518,0,0,0,13.5653,0,0,100,0,0,0,0,0,0,0,0,0,0,585.1008,14289.62,9.1854,0.7853,0,0,0,0,0,0,0,0,0,0,4.6924,1.3615,0.6878,0.6878,589.3211,22.5694,11.1327,11.4367,1.0198,2.0273,7962.383,1.3662,581.6966,14.9449,5.7184,0,190.4827,16.8511,2.7517,0.1219,0,0,1507964,-566.7517,0,0,0,1.51E+08,0,0,50.1048,29.8061,591.809,580.576,567.288,3.7757,1.3615,-1.4715,0.1115,3.455,592.3773,580.576,566.7198,25.6256,13.8243,-0.0319,3.2582,-1.4715,-1.7852,579.8911,13.1393,25.6575,0.54,-803.3104,8.5583,0.0015,0.5156
1,71.8,71.8,578.6163,146680.6,531,0,0.0968,534.6268,2.2104,0,0,0.0528,0.0522,0.0518,0,0,0,12.971,0,0,100,0,0,0,0,0,0,0,0,0,0,582.1194,14940.17,16.14,9.0556,0,0,0,0,0,0,0,0,0,0,4.6942,1.1513,0.5807,0.5807,590.8035,56.1768,43.9895,12.1873,1.0211,1.2771,7945.451,1.1547,582.6787,48.0519,6.0937,0,44.7068,50.0832,3.6268,0.0646,0,0,1507964,-534.6268,0,0,0,1.51E+08,0,0,50.0406,29.7561,595.736,579.9225,573.4774,43.6926,1.1513,-1.4025,0.2548,6.0495,629.6945,579.9225,539.5189,95.0678,45.2957,4.8922,5.0041,-1.4025,-3.598,583.0453,48.4186,90.1756,0.4481,19.4325,37.8548,0.0036,0.7847
1,74.8,74.8,577.4075,145832.6,540,0,0.0907,541.7929,2.2095,0,0,0.0528,0.0522,0.0518,0,0,0,12.9297,0,0,100,0,0,0,0,0,0,0,0,0,0,585.1521,15930.8,16.7154,5.0375,0,0,0,0,0,0,0,0,0,0,4.6784,1.1508,0.5804,0.5804,588.8179,47.025,35.6146,11.4104,1.0198,1.3204,7945.411,1.1541,581.2109,39.418,5.7052,0,-1861.812,41.3198,1.7929,0.0381,0,0,1507964,-541.7929,0,0,0,1.51E+08,0,0,50.0238,29.7281,591.0155,580.2944,566.0635,24.3183,1.1508,-1.457,0.3111,6.2619,605.8713,580.2944,551.2076,64.0784,38.5015,9.4147,5.1786,-1.457,-3.7167,579.1245,37.3315,54.6637,0.5321,6.8062,31.4204,0.0049,0.841
1,77.8,77.8,577.3851,147122.3,566,0,0.092,567.7747,3.481,0,0,0.0528,0.0522,0.0518,0,0,0,14.9554,0,0,100,0,0,0,0,0,0,0,0,0,0,585.3128,14532.68,10.2218,-0.6094,0,0,0,0,0,0,0,0,0,0,4.7105,1.813,0.919,0.919,588.8863,21.1116,9.6104,11.5012,1.0199,2.1967,7998.997,1.8213,581.2188,13.4441,5.7506,0,-1573.347,15.361,1.7747,0.0841,0,0,1507964,-567.7747,0,0,0,1.51E+08,0,0,50.2158,29.8677,591.0161,580.3417,565.7484,-2.9102,1.813,-1.7107,-0.1043,3.8709,591.347,580.3417,565.4175,23.5723,12.567,-2.3572,3.7545,-1.7107,-2.0458,579.0354,11.2607,25.9295,0.5756,-10.0001,-6.4859,-0.002,0.3437
1,80.8,80.8,578.3921,147407.5,548,0,0.0994,547.5522,3.3045,0,0,0.0528,0.0522,0.0518,0,0,0,14.7036,0,0,100,0,0,0,0,0,0,0,0,0,0,582.9501,14160.29,17.2785,6.8789,0,0,0,0,0,0,0,0,0,0,4.7216,1.7211,0.8718,0.8718,590.8265,43.2743,30.8399,12.4344,1.0215,1.4032,7991.517,1.7286,582.5369,34.9847,6.2172,0,68.7987,37.0571,-0.4478,-0.0103,0,0,1507964,-547.5522,0,0,0,1.51E+08,0,0,50.1985,29.8642,595.3298,580.0923,571.6979,32.8905,1.7211,-1.644,-0.0783,6.5352,618.4623,580.0923,548.5652,70.9101,32.5401,1.013,5.5293,-1.644,-3.8865,582.3732,34.8211,69.8971,0.4511,70.0001,35.1196,-0.0012,0.3943
1,83.8,83.8,578.1174,145842.7,534,0,0.0933,535.6099,3.0254,0,0,0.0528,0.0522,0.0518,0,0,0,14.233,0,0,100,0,0,0,0,0,0,0,0,0,0,583.6004,15907.22,20.313,7.9133,0,0,0,0,0,0,0,0,0,0,4.7065,1.5757,0.7973,0.7973,589.8083,54.1984,42.5075,11.6909,1.0202,1.275,7979.711,1.582,582.0143,46.4044,5.8455,0,79.0645,48.353,1.6099,0.0297,0,0,1507964,-535.6099,0,0,0,1.51E+08,0,0,50.1321,29.7928,593.3925,580.1613,570.0859,37.9544,1.5757,-1.6682,0.094,7.6591,621.4423,580.1613,542.0361,85.8324,44.5514,6.4261,6.3011,-1.6682,-4.6314,581.2132,45.6033,79.4063,0.4801,13.3568,36.4658,0.0015,0.4863
1,86.8,86.8,577.5508,146892.3,566,0,0.068,569.5188,4.0945,0,0,0.0528,0.0522,0.0518,0,0,0,15.9723,0,0,100,0,0,0,0,0,0,0,0,0,0,585.4796,14783.67,15.1611,-0.0273,0,0,0,0,0,0,0,0,0,0,4.7029,2.1326,1.0837,1.0837,586.0225,16.5037,8.032,8.4717,1.0147,2.0547,8025.119,2.1442,580.3747,10.8559,4.2359,0,786.8134,12.2679,3.5188,0.2132,0,0,1507964,-569.5188,0,0,0,1.51E+08,0,0,50.2934,29.9093,586.452,580.5076,565.9169,-0.1298,2.1326,-1.8843,-0.2527,5.7687,586.4528,580.5076,565.9161,16.934,10.9888,-3.6027,5.1898,-1.8843,-3.3099,577.6255,8.1067,20.5367,0.7105,-4.7004,-0.3621,-0.0044,0.2933
1,89.8,89.8,577.9919,147701.8,560,0,0.1002,562.412,4.8174,0,0,0.0528,0.0522,0.0518,0,0,0,17.1903,0,0,100,0,0,0,0,0,0,0,0,0,0,584.2932,13839.44,17.3515,3.7852,0,0,0,0,0,0,0,0,0,0,4.7566,2.5091,1.2787,1.2787,590.4338,28.0218,15.5799,12.4419,1.0215,1.7986,8056.111,2.5252,582.1392,19.7272,6.221,0,145.556,21.8009,2.412,0.0861,0,0,1507964,-562.412,0,0,0,1.51E+08,0,0,50.4064,29.9938,593.9718,580.3427,568.7328,17.8782,2.5091,-2.0213,-0.4978,6.6437,603.2357,580.3427,559.4689,40.8237,17.9307,-2.9431,5.9382,-2.0213,-3.9269,581.0157,18.6038,43.7668,0.4769,-13.871,27.3916,-0.01,0.2364
1,92.8,92.8,578.4286,146334.2,532,0,0.0936,533.5687,4.1708,0,0,0.0528,0.0522,0.0518,0,0,0,16.1326,0,0,100,0,0,0,0,0,0,0,0,0,0,582.5003,15363.08,23.9546,9.3657,0,0,0,0,0,0,0,0,0,0,4.7374,2.1723,1.1042,1.1042,590.082,56.5132,44.8599,11.6534,1.0201,1.2598,8028.375,2.1843,582.313,48.7443,5.8267,0,52.121,50.6866,1.5687,0.0278,0,0,1507964,-533.5687,0,0,0,1.51E+08,0,0,50.2939,29.899,594.4197,579.9467,572.4595,44.5003,2.1723,-1.9363,-0.2405,9.1174,629.2745,579.9467,537.6047,95.7058,46.378,4.036,7.5248,-1.9363,-5.593,582.2753,48.7066,91.6698,0.4619,23.713,38.0698,-0.0045,0.3029
1,95.8,95.8,577.4771,146593.8,555,0,0.0821,560.1041,4.4797,0,0,0.0528,0.0522,0.0518,0,0,0,16.6305,0,0,100,0,0,0,0,0,0,0,0,0,0,585.8629,15175.11,22.6503,2.0204,0,0,0,0,0,0,0,0,0,0,4.7259,2.3332,1.1874,1.1874,587.6815,27.5774,17.373,10.2044,1.0177,1.5874,8041.602,2.3471,580.8786,20.7745,5.1022,0,2080.202,22.4752,5.1041,0.1851,0,0,1507964,-560.1041,0,0,0,1.51E+08,0,0,50.3385,29.9289,588.8441,580.6038,565.1801,9.5751,2.3332,-2.0069,-0.3331,8.6432,592.2331,580.6038,561.7911,32.129,20.4997,1.687,7.2554,-2.0069,-5.2553,578.2093,18.1052,30.442,0.618,19.0451,19.4908,-0.0068,0.273
1,98.8,98.8,577.7253,147582.5,569,0,0.0839,571.2847,6.2788,0,0,0.0528,0.0522,0.0518,0,0,0,19.569,0,0,100,0,0,0,0,0,0,0,0,0,0,584.7946,14023.93,15.0915,0.6639,0,0,0,0,0,0,0,0,0,0,4.7747,3.2702,1.6763,1.6763,588.0535,16.7688,6.4406,10.3283,1.0179,2.6036,8119.499,3.2977,581.168,9.8833,5.1642,0,312.4347,11.6047,2.2847,0.1362,0,0,1507964,-571.2847,0,0,0,1.51E+08,0,0,50.6012,30.1063,589.997,580.3623,567.3406,3.0994,3.2702,-2.4147,-0.8766,5.8461,590.4134,580.3623,566.9243,19.1287,9.0776,-4.3604,5.8215,-2.4147,-3.4279,579.2333,7.9486,23.4891,0.5721,-4.3869,7.6508,-0.0211,0.169
1,101.8,101.8,578.2515,147086.2,539,0,0.0986,538.3272,5.7522,0,0,0.0528,0.0522,0.0518,0,0,0,18.7418,0,0,100,0,0,0,0,0,0,0,0,0,0,582.4739,14532.19,26.7518,9.0869,0,0,0,0,0,0,0,0,0,0,4.7804,2.9959,1.5325,1.5325,590.4251,52.0979,39.9243,12.1736,1.0211,1.3049,8096.539,3.0189,582.3094,43.9822,6.0868,0,69.3476,46.0111,-0.6728,-0.0129,0,0,1507964,-538.3272,0,0,0,1.51E+08,0,0,50.521,30.0493,594.9682,579.8263,572.0538,42.6133,2.9959,-2.3042,-0.7078,10.3165,627.6376,579.8263,539.3843,89.3104,41.4991,1.0571,8.6703,-2.3042,-6.3822,582.2827,43.9555,88.2533,0.4582,84.4862,37.4755,-0.0161,0.199
1,104.8,104.8,577.6174,146236,548,0,0.0909,546.6118,5.714,0,0,0.0528,0.0522,0.0518,0,0,0,18.6319,0,0,100,0,0,0,0,0,0,0,0,0,0,584.9837,15489.78,27.4774,5.0432,0,0,0,0,0,0,0,0,0,0,4.7666,2.976,1.5221,1.5221,588.8415,42.2297,31.0056,11.2241,1.0194,1.362,8094.878,2.9987,581.3587,34.7469,5.6121,0,363.2908,36.6177,-1.3882,-0.0329,0,0,1507964,-546.6118,0,0,0,1.51E+08,0,0,50.4996,30.0189,591.1379,580.3636,566.8204,23.6692,2.976,-2.3471,-0.644,10.5878,605.5886,580.3636,552.3696,58.9768,33.7518,5.7578,8.8684,-2.3471,-6.5364,579.4406,32.8288,53.219,0.526,10.2429,31.4053,-0.0151,0.204
1,107.8,107.8,577.6106,147425.8,569,0,0.0902,570.6725,7.8409,0,0,0.0528,0.0522,0.0518,0,0,0,22.1262,0,0,100,0,0,0,0,0,0,0,0,0,0,584.8207,14225.46,16.6545,-0.5998,0,0,0,0,0,0,0,0,0,0,4.8199,4.0838,2.1066,2.1066,588.6274,17.9549,6.9381,11.0168,1.0191,2.5879,8188.372,4.1269,581.2829,10.6104,5.5084,0,518.3712,12.4465,1.6725,0.0932,0,0,1507964,-570.6725,0,0,0,1.51E+08,0,0,50.8119,30.228,590.8731,580.3,567.0224,-2.7652,4.0838,-2.8367,-1.2832,6.5332,591.1895,580.3,566.706,20.517,9.6275,-3.9665,6.7428,-2.8367,-3.9422,579.3985,8.726,24.4835,0.5552,-5.1726,-6.5274,-0.0361,0.1322
1,110.8,110.8,578.2375,147707.5,548,0,0.1028,551.0481,7.8458,0,0,0.0528,0.0522,0.0518,0,0,0,22.1742,0,0,100,0,0,0,0,0,0,0,0,0,0,582.9684,13829.02,27.9772,6.8849,0,0,0,0,0,0,0,0,0,0,4.8378,4.0864,2.108,2.108,590.7974,39.7493,27.1894,12.5599,1.0217,1.4619,8188.594,4.1296,582.4241,31.376,6.28,0,86.5104,33.4694,3.0481,0.0767,0,0,1507964,-551.0481,0,0,0,1.51E+08,0,0,50.8193,30.2397,595.2599,580.0024,571.2859,31.7326,4.0864,-2.8164,-1.3065,10.9775,617.1941,580.0024,549.3517,66.146,28.9543,-1.6964,9.6072,-2.8164,-6.8273,582.1827,31.1346,67.8424,0.4518,-38.992,34.653,-0.0365,0.1372
1,113.8,113.8,578.1127,146259.1,538,0,0.0926,539.5895,7.4201,0,0,0.0528,0.0522,0.0518,0,0,0,21.4603,0,0,100,0,0,0,0,0,0,0,0,0,0,583.5447,15461.94,31.7689,7.916,0,0,0,0,0,0,0,0,0,0,4.8156,3.8646,1.9902,1.9902,589.4463,49.8568,38.5232,11.3336,1.0196,1.2942,8169.701,3.9032,581.8906,42.3012,5.6668,0,85.5288,44.19,1.5895,0.0319,0,0,1507964,-539.5895,0,0,0,1.51E+08,0,0,50.733,30.1582,592.8544,580.1378,570.1505,36.6422,3.8646,-2.7937,-1.1017,12.4117,619.8628,580.1378,543.1421,80.2733,40.5483,3.5526,10.5024,-2.7937,-7.7395,581.0475,41.4581,76.7207,0.4822,22.5957,36.3934,-0.0308,0.1501
1,116.8,116.8,577.4696,147247.1,570,0,0.0564,572.5774,8.9197,0,0,0.0528,0.0522,0.0518,0,0,0,23.8739,0,0,100,0,0,0,0,0,0,0,0,0,0,585.0162,14451.13,25.0171,0.175,0,0,0,0,0,0,0,0,0,0,4.8128,4.6457,2.4071,2.4071,584.3171,11.7397,4.8922,6.8475,1.0119,2.3997,8236.624,4.7019,579.7521,7.1747,3.4238,0,3015.622,8.316,2.5774,0.2195,0,0,1507964,-572.5774,0,0,0,1.51E+08,0,0,50.9575,30.3104,584.0369,580.2843,566.3911,0.7998,4.6457,-3.1341,-1.5601,9.8994,584.0731,580.2843,566.3549,11.4957,7.7069,-6.2225,9.1996,-3.1341,-6.114,576.9041,4.3267,17.7182,0.7862,-1.8474,2.5899,-0.0485,0.1184
1,119.8,119.8,577.7747,147967.4,564,0,0.1009,564.3607,10.3214,0,0,0.0528,0.0522,0.0518,0,0,0,26.1822,0,0,100,0,0,0,0,0,0,0,0,0,0,583.9746,13578.41,27.4614,3.7978,0,0,0,0,0,0,0,0,0,0,4.8965,5.3757,2.8013,2.8013,589.9279,25.5672,13.414,12.1532,1.021,1.906,8300.167,5.4513,581.8257,17.465,6.0766,0,245.6864,19.4906,0.3607,0.0141,0,0,1507964,-564.3607,0,0,0,1.51E+08,0,0,51.1687,30.4522,593.3688,580.0879,568.6612,17.1501,5.3757,-3.4586,-1.9859,10.9975,602.1513,580.0879,559.8787,37.7906,15.7272,-4.482,10.2984,-3.4586,-6.9086,580.706,16.3453,42.2726,0.4781,-8.4316,27.1168,-0.0688,0.1005
1,122.8,122.8,578.1304,146707.6,536,0,0.0943,537.2053,9.4615,0,0,0.0528,0.0522,0.0518,0,0,0,24.7868,0,0,100,0,0,0,0,0,0,0,0,0,0,582.9489,14944.62,35.7971,9.375,0,0,0,0,0,0,0,0,0,0,4.8703,4.9279,2.5589,2.5589,589.5481,52.3428,40.9251,11.4177,1.0197,1.279,8261.072,4.9912,581.9363,44.731,5.7089,0,79.886,46.634,1.2053,0.023,0,0,1507964,-537.2053,0,0,0,1.51E+08,0,0,51.0247,30.3412,593.3305,579.9272,571.062,42.6665,4.9279,-3.3046,-1.6787,14.2246,626.2917,579.9272,538.1009,89.0864,42.7219,0.8956,12.2115,-3.3046,-8.9623,581.4399,44.2346,88.1908,0.4743,99.4712,37.6871,-0.0554,0.1136
1,125.8,125.8,577.6221,146945.1,564,0,0.0789,563.9708,9.8177,0,0,0.0528,0.0522,0.0518,0,0,0,25.3313,0,0,100,0,0,0,0,0,0,0,0,0,0,585.6945,14770.45,34.4427,2.0281,0,0,0,0,0,0,0,0,0,0,4.86,5.1134,2.6591,2.6591,587.1535,23.1827,13.6513,9.5314,1.0165,1.6982,8277.223,5.1817,580.7993,16.8285,4.7657,0,449.0555,18.417,-0.0292,-0.0013,0,0,1507964,-563.9708,0,0,0,1.51E+08,0,0,51.0776,30.3759,588.0989,580.6325,565.7773,9.2022,5.1134,-3.3896,-1.7845,13.7278,591.4034,580.6325,562.4728,27.4326,16.6617,-1.498,11.966,-3.3896,-8.6371,578.1696,14.1988,28.9306,0.6277,-18.3128,19.753,-0.0607,0.1086
1,128.8,128.8,577.9379,147870,570,0,0.0794,573.1023,12.3172,0,0,0.0528,0.0522,0.0518,0,0,0,29.3827,0,0,100,0,0,0,0,0,0,0,0,0,0,585.3715,13693.76,23.5016,0.5935,0,0,0,0,0,0,0,0,0,0,4.9297,6.4152,3.3707,3.3707,587.4032,14.3009,4.8356,9.4653,1.0164,2.9574,8392.361,6.5239,581.093,7.9907,4.7327,0,182.7662,9.5683,3.1023,0.2169,0,0,1507964,-573.1023,0,0,0,1.51E+08,0,0,51.4501,30.6176,588.6448,580.7112,567.0128,2.6362,6.4152,-3.9962,-2.5195,9.5684,588.9614,580.7112,566.6962,15.8591,7.6089,-6.4061,10.0555,-3.9962,-6.1598,578.7896,5.6873,22.2652,0.6295,-2.4756,6.8489,-0.1005,0.0821
1,131.8,131.8,578.5934,147474.7,542,0,0.1005,541.4248,11.8613,0,0,0.0528,0.0522,0.0518,0,0,0,28.6987,0,0,100,0,0,0,0,0,0,0,0,0,0,582.4922,14095.95,38.6434,9.0608,0,0,0,0,0,0,0,0,0,0,4.944,6.1778,3.2398,3.2398,590.6015,49.1767,37.1686,12.0081,1.0208,1.3231,8371.127,6.2784,582.5961,41.1713,6.0041,0,51.4855,43.1727,-0.5752,-0.0117,0,0,1507964,-541.4248,0,0,0,1.51E+08,0,0,51.3781,30.5672,595.2159,580.0477,572.8668,40.4082,6.1778,-3.8965,-2.3739,15.6703,625.9662,580.0477,542.1165,84.5414,38.6229,0.6917,13.7789,-3.8965,-9.975,582.7101,41.2853,83.8497,0.4524,122.2226,37.2708,-0.0926,0.0881
1,134.8,134.8,577.629,146717.9,550,0,0.0905,550.296,11.7952,0,0,0.0528,0.0522,0.0518,0,0,0,28.5555,0,0,100,0,0,0,0,0,0,0,0,0,0,584.9169,14984.76,39.479,5.047,0,0,0,0,0,0,0,0,0,0,4.9241,6.1433,3.2208,3.2208,588.4406,38.1446,27.333,10.8116,1.0187,1.3956,8368.05,6.2427,581.2329,30.9369,5.4058,0,360.3827,32.7388,0.296,0.0078,0,0,1507964,-550.296,0,0,0,1.51E+08,0,0,51.3533,30.5359,590.5412,580.3466,566.9389,22.5309,6.1433,-3.9265,-2.307,15.993,604.1744,580.3466,553.3057,53.8784,30.0506,3.0097,13.9904,-3.9265,-10.1541,579.2756,28.9796,50.8687,0.5316,17.9016,31.1778,-0.0902,0.0892
1,137.8,137.8,577.8258,147883.9,570,0,0.0885,572.0967,14.3684,0,0,0.0528,0.0522,0.0518,0,0,0,32.6706,0,0,100,0,0,0,0,0,0,0,0,0,0,584.9174,13728.59,25.6984,-0.5727,0,0,0,0,0,0,0,0,0,0,4.9938,7.4835,3.9658,3.9658,588.2485,16.1518,5.7291,10.4227,1.018,2.8193,8489.27,7.6329,581.3,9.2033,5.2114,0,233.219,10.9405,2.0967,0.1298,0,0,1507964,-572.0967,0,0,0,1.51E+08,0,0,51.7457,30.7928,590.2266,580.4716,567.4038,-2.5005,7.4835,-4.5478,-3.0755,10.6444,590.4973,580.4716,567.1331,18.4006,8.3749,-4.9636,11.3977,-4.5478,-6.9897,579.3674,7.2706,23.3642,0.5709,-3.7071,-6.1797,-0.1398,0.0699
1,140.8,140.8,578.2883,148319.8,549,0,0.1045,552.8718,14.6107,0,0,0.0528,0.0522,0.0518,0,0,0,33.111,0,0,100,0,0,0,0,0,0,0,0,0,0,583.2764,13170.47,39.5643,6.9105,0,0,0,0,0,0,0,0,0,0,5.0205,7.6097,4.0368,4.0368,590.587,37.7152,25.4165,12.2987,1.0213,1.4839,8500.865,7.7643,582.3879,29.5161,6.1494,0,83.4769,31.5659,3.8718,0.1027,0,0,1507964,-552.8718,0,0,0,1.51E+08,0,0,51.7907,30.8301,594.7582,580.1497,570.9515,30.1015,7.6097,-4.5829,-3.1721,16.426,615.2244,580.1497,550.4853,62.3526,27.2779,-2.3865,15.0238,-4.5829,-10.5862,581.9531,29.0813,64.7391,0.4582,-26.1272,34.2121,-0.1453,0.07
1,143.8,143.8,577.8289,147014.3,540,0,0.093,542.7651,14.1166,0,0,0.0528,0.0522,0.0518,0,0,0,32.2762,0,0,100,0,0,0,0,0,0,0,0,0,0,584.0194,14620.01,43.6759,7.9022,0,0,0,0,0,0,0,0,0,0,4.9914,7.3524,3.8922,3.8922,588.7989,46.0338,35.0638,10.97,1.019,1.3129,8477.257,7.4964,581.4856,38.7205,5.485,0,156.0183,40.5488,2.7651,0.0601,0,0,1507964,-542.7651,0,0,0,1.51E+08,0,0,51.6937,30.7451,591.582,580.1376,568.7435,34.5908,7.3524,-4.5282,-2.9583,18.0441,616.5897,580.1376,543.7358,73.8247,37.3725,0.9707,15.9583,-4.5282,-11.5642,580.1544,37.3893,72.854,0.4997,76.0531,35.8654,-0.1341,0.0735
1,146.8,146.8,577.3683,147983.6,571,0,0.0522,573.6948,15.7713,0,0,0.0528,0.0522,0.0518,0,0,0,34.9142,0,0,100,0,0,0,0,0,0,0,0,0,0,585.022,13588.73,36.1496,0.2526,0,0,0,0,0,0,0,0,0,0,4.9927,8.2142,4.3788,4.3788,583.474,9.7792,3.6735,6.1057,1.0106,2.6621,8556.852,8.3953,579.4035,5.7087,3.0529,0,-1285.954,6.7264,2.6948,0.2756,0,0,1507964,-573.6948,0,0,0,1.51E+08,0,0,51.9537,30.9192,582.7027,580.2238,566.1179,1.0898,8.2142,-4.9181,-3.4666,15.1535,582.774,580.2238,566.0466,9.0792,6.529,-7.6483,14.5773,-4.9181,-9.8297,576.3481,2.6533,16.7275,0.8475,-1.1871,3.7435,-0.1705,0.0644
1,149.8,149.8,577.9997,148833.3,563,0,0.1005,566.2592,17.5064,0,0,0.0528,0.0522,0.0518,0,0,0,37.8009,0,0,100,0,0,0,0,0,0,0,0,0,0,584.3826,12555.62,38.5537,3.7809,0,0,0,0,0,0,0,0,0,0,5.0955,9.1179,4.8965,4.8965,589.6247,23.3655,11.7405,11.625,1.0201,1.9902,8641.938,9.3429,581.8747,15.6155,5.8125,0,150.3943,17.553,3.2592,0.1395,0,0,1507964,-566.2592,0,0,0,1.51E+08,0,0,52.2294,31.1029,592.6632,580.3821,568.6026,16.0626,9.1179,-5.3322,-3.9988,16.4117,600.7012,580.3821,560.5647,34.442,14.1229,-5.6945,15.8894,-5.3322,-10.7703,580.5493,14.2901,40.1365,0.4938,-6.0483,26.5841,-0.2131,0.0576
1,152.8,152.8,578.3931,147823.3,539,0,0.0942,540.4526,16.5997,0,0,0.0528,0.0522,0.0518,0,0,0,36.3008,0,0,100,0,0,0,0,0,0,0,0,0,0,582.9112,13630.95,47.4732,9.3619,0,0,0,0,0,0,0,0,0,0,5.0668,8.6457,4.625,4.625,589.3499,48.8973,37.9406,10.9568,1.0189,1.2888,8597.27,8.8471,582.0454,41.5928,5.4784,0,61.2784,43.419,1.4526,0.0297,0,0,1507964,-540.4526,0,0,0,1.51E+08,0,0,52.0755,30.9909,593.0358,580.0788,571.7523,40.1051,8.6457,-5.144,-3.6915,20.041,623.887,580.0788,540.9011,83.4345,39.6262,0.4485,17.9326,-5.144,-12.9784,581.6223,41.1697,82.986,0.4721,186.0301,37.5696,-0.1898,0.0616
1,155.8,155.8,577.5398,148145.3,562,0,0.0775,566.4453,16.9748,0,0,0.0528,0.0522,0.0518,0,0,0,36.9037,0,0,100,0,0,0,0,0,0,0,0,0,0,585.467,13355.27,46.0912,2.0366,0,0,0,0,0,0,0,0,0,0,5.0534,8.841,4.737,4.737,586.5347,20.0894,11.0945,8.9949,1.0156,1.8108,8615.688,9.052,580.5381,14.0928,4.4975,0,842.3983,15.592,4.4453,0.2213,0,0,1507964,-566.4453,0,0,0,1.51E+08,0,0,52.1361,31.0322,587.2455,580.4976,565.8833,8.6953,8.841,-5.2308,-3.8095,19.5229,590.3373,580.4976,562.7914,23.892,14.0523,-3.6539,17.7006,-5.2308,-12.6691,577.8754,11.4301,27.5459,0.6428,-6.5388,19.5742,-0.1993,0.0601
1,158.8,158.8,577.4832,149176.7,571,0,0.0769,573.626,19.641,0,0,0.0528,0.0522,0.0518,0,0,0,41.2719,0,0,100,0,0,0,0,0,0,0,0,0,0,584.9866,12101.92,33.8284,0.5811,0,0,0,0,0,0,0,0,0,0,5.1293,10.2297,5.544,5.544,586.2749,12.6489,3.8572,8.7917,1.0152,3.2793,8748.968,10.5158,580.4138,6.7878,4.3959,0,2099.113,8.2531,2.626,0.2076,0,0,1507964,-573.626,0,0,0,1.51E+08,0,0,52.5598,31.3083,587.0904,580.2842,566.4291,2.423,10.2297,-5.889,-4.6121,14.672,587.3708,580.2842,566.1487,13.7448,6.6582,-7.4773,15.5643,-5.889,-9.9467,577.9346,4.3086,21.2221,0.6661,-1.8382,6.5999,-0.2714,0.0506
1,161.8,161.8,578.467,149044,543,0,0.1002,544.1597,19.3277,0,0,0.0528,0.0522,0.0518,0,0,0,40.7941,0,0,100,0,0,0,0,0,0,0,0,0,0,582.6152,12179.74,49.996,9.0478,0,0,0,0,0,0,0,0,0,0,5.152,10.0665,5.4482,5.4482,589.94,45.7803,34.3073,11.473,1.0198,1.3344,8733.092,10.3431,582.2913,38.1316,5.7365,0,60.4819,40.0438,1.1597,0.0253,0,0,1507964,-544.1597,0,0,0,1.51E+08,0,0,52.5108,31.2776,594.1134,580.0155,572.3564,37.8304,10.0665,-5.8079,-4.5214,21.6243,622.5983,580.0155,543.8714,78.4386,35.8558,-0.2883,19.7138,-5.8079,-14.1687,582.1617,38.002,78.7269,0.4591,-272.0728,36.9784,-0.2628,0.0523
1,164.8,164.8,577.8802,148485.8,554,0,0.0906,553.12,19.2619,0,0,0.0528,0.0522,0.0518,0,0,0,40.654,0,0,100,0,0,0,0,0,0,0,0,0,0,585.2661,12858.79,50.8197,5.0402,0,0,0,0,0,0,0,0,0,0,5.1354,10.0322,5.4281,5.4281,588.2635,35.1435,24.7602,10.3833,1.018,1.4194,8729.762,10.3069,581.3413,28.2213,5.1917,0,161.3653,29.9519,-0.88,-0.025,0,0,1507964,-553.12,0,0,0,1.51E+08,0,0,52.4888,31.2516,590.0401,580.6366,567.0115,21.0935,10.0322,-5.8256,-4.4667,21.9603,602.5573,580.6366,554.4942,49.4373,27.5166,1.3742,19.9199,-5.8256,-14.3544,579.2293,26.1094,48.0631,0.5439,35.9753,30.6856,-0.2601,0.0526
1,167.8,167.8,577.8082,149672.9,571,0,0.0894,572.2523,21.8914,0,0,0.0528,0.0522,0.0518,0,0,0,44.8544,0,0,100,0,0,0,0,0,0,0,0,0,0,584.9837,11508.48,36.3476,-0.5863,0,0,0,0,0,0,0,0,0,0,5.2115,11.4018,6.2399,6.2399,587.8928,15.6405,5.5559,10.0846,1.0175,2.8151,8864.712,11.7611,581.1697,8.9174,5.0423,0,244.7616,10.5982,1.2523,0.0801,0,0,1507964,-572.2523,0,0,0,1.51E+08,0,0,52.9168,31.5323,589.6153,580.4875,567.2277,-2.3962,11.4018,-6.4743,-5.2684,16.0834,589.8689,580.4875,566.9741,17.6166,8.2352,-5.2782,17.1668,-6.4743,-11.0334,579.1102,6.8579,22.8948,0.5902,-3.3376,-6.0413,-0.3409,0.0453
1,170.8,170.8,578.2524,150324.5,553,0,0.1052,555.0221,22.2948,0,0,0.0528,0.0522,0.0518,0,0,0,45.5298,0,0,100,0,0,0,0,0,0,0,0,0,0,583.6093,10709.56,50.6422,6.8912,0,0,0,0,0,0,0,0,0,0,5.2434,11.6119,6.3661,6.3661,590.0887,35.0666,23.2303,11.8363,1.0205,1.5095,8885.783,11.9853,582.1978,27.1757,5.9182,0,89.8145,29.1485,2.0221,0.0577,0,0,1507964,-555.0221,0,0,0,1.51E+08,0,0,52.9938,31.5935,593.7972,580.2532,570.3438,28.0528,11.6119,-6.5434,-5.4232,22.4977,612.4756,580.2532,551.6653,57.4535,25.2311,-3.3568,21.1394,-6.5434,-14.9507,581.4647,26.4426,60.8103,0.4701,-17.1156,33.657,-0.3547,0.0448
1,173.8,173.8,578.3743,149234.6,544,0,0.0929,545.5676,21.8213,0,0,0.0528,0.0522,0.0518,0,0,0,44.7726,0,0,100,0,0,0,0,0,0,0,0,0,0,583.8355,11883.26,54.6683,7.9096,0,0,0,0,0,0,0,0,0,0,5.2179,11.3653,6.218,6.218,588.8572,43.2896,32.8067,10.4829,1.0181,1.3195,8861.062,11.7222,581.8686,36.301,5.2415,0,67.9829,38.0482,1.5676,0.0362,0,0,1507964,-545.5676,0,0,0,1.51E+08,0,0,52.8993,31.5147,591.751,580.4132,570.3262,32.3528,11.3653,-6.4748,-5.229,24.1705,615.1188,580.4132,546.9584,69.5512,34.8456,1.3907,22.0668,-6.4748,-15.9305,580.8301,35.2625,68.1605,0.4908,50.0117,35.8398,-0.3385,0.0461
1,176.8,176.8,577.4898,150327.8,572,0,0.0535,574.231,23.5039,0,0,0.0528,0.0522,0.0518,0,0,0,47.4654,0,0,100,0,0,0,0,0,0,0,0,0,0,585.3744,10721.65,46.8203,0.2645,0,0,0,0,0,0,0,0,0,0,5.2218,12.2416,6.747,6.747,583.4712,9.2402,3.2588,5.9814,1.0104,2.8355,8949.542,12.6591,579.4836,5.2526,2.9907,0,1835.697,6.2495,2.231,0.2414,0,0,1507964,-574.231,0,0,0,1.51E+08,0,0,53.1834,31.7063,582.4829,580.4347,565.8499,1.0652,12.2416,-6.8776,-5.7601,21.024,582.5508,580.4347,565.7819,8.3198,6.2037,-8.4491,20.6195,-6.8776,-14.138,576.2558,2.0248,16.7689,0.8738,-0.9847,3.6494,-0.3961,0.0423
1,179.8,179.8,577.884,151300.7,563,0,0.0983,567.2639,25.3106,0,0,0.0528,0.0522,0.0518,0,0,0,50.5311,0,0,100,0,0,0,0,0,0,0,0,0,0,584.8448,9475.11,49.4336,3.768,0,0,0,0,0,0,0,0,0,0,5.3262,13.1826,7.3239,7.3239,588.7552,21.4913,10.6201,10.8712,1.0188,2.0236,9046.545,13.671,581.5078,14.2439,5.4356,0,191.8184,16.0557,4.2639,0.1984,0,0,1507964,-567.2639,0,0,0,1.51E+08,0,0,53.4931,31.915,591.015,580.485,567.5886,14.9223,13.1826,-7.3134,-6.3321,22.5738,598.2722,580.485,560.3315,31.0083,13.2211,-6.9324,22.1334,-7.3134,-15.2829,579.6962,12.4323,37.9407,0.5312,-4.473,25.935,-0.4629,0.0391
1,182.8,182.8,578.3513,150590.2,542,0,0.0944,543.3784,24.4746,0,0,0.0528,0.0522,0.0518,0,0,0,49.1338,0,0,100,0,0,0,0,0,0,0,0,0,0,583.2719,10248.28,58.163,9.3797,0,0,0,0,0,0,0,0,0,0,5.3004,12.7472,7.0558,7.0558,588.8416,45.4632,34.9729,10.4903,1.0181,1.3,9001.401,13.202,581.8481,38.4697,5.2452,0,67.2975,40.2181,1.3784,0.0303,0,0,1507964,-543.3784,0,0,0,1.51E+08,0,0,53.3457,31.8121,592.0221,580.1895,571.082,37.4407,12.7472,-7.1219,-6.0568,26.351,620.4291,580.1895,542.6749,77.0507,36.8111,-0.7035,24.2159,-7.1219,-17.5255,581.0978,37.7194,77.7542,0.4825,-109.5248,37.1883,-0.4315,0.0408
1,185.8,185.8,577.6423,151009.4,567,0,0.0772,567.9277,24.8543,0,0,0.0528,0.0522,0.0518,0,0,0,49.7475,0,0,100,0,0,0,0,0,0,0,0,0,0,585.6563,9834.858,56.7783,2.0576,0,0,0,0,0,0,0,0,0,0,5.2886,12.9449,7.1773,7.1773,586.1995,18.2719,9.7146,8.5573,1.0148,1.8809,9021.844,13.4148,580.4947,12.567,4.2787,0,423.8196,13.9933,0.9277,0.0508,0,0,1507964,-567.9277,0,0,0,1.51E+08,0,0,53.4136,31.8606,586.5864,580.6365,565.7955,8.1837,12.9449,-7.2055,-6.185,25.8168,589.4211,580.6365,562.9607,21.4934,12.7088,-4.967,23.9892,-7.2055,-17.2293,577.6728,9.7451,26.4604,0.668,-4.3272,19.1056,-0.4456,0.04
1,188.8,188.8,577.4477,152112.1,571,0,0.0759,574.1488,27.4809,0,0,0.0528,0.0522,0.0518,0,0,0,54.1188,0,0,100,0,0,0,0,0,0,0,0,0,0,585.1169,8457.148,44.4517,0.5918,0,0,0,0,0,0,0,0,0,0,5.3687,14.313,8.0295,8.0295,585.7261,11.5773,3.2989,8.2784,1.0143,3.5094,9165.889,14.895,580.2072,6.0584,4.1392,0,11349.11,7.4381,3.1488,0.272,0,0,1507964,-574.1488,0,0,0,1.51E+08,0,0,53.8631,32.1554,586.1396,580.3146,566.0873,2.2969,14.313,-7.8668,-6.9967,20.7126,586.3993,580.3146,565.8275,12.2505,6.1658,-8.3213,21.7698,-7.8668,-14.4535,577.5138,3.365,20.5718,0.7042,-1.4722,6.4516,-0.5505,0.0357
1,191.8,191.8,578.2438,152251.2,546,0,0.1007,546.5269,27.3645,0,0,0.0528,0.0522,0.0518,0,0,0,53.9657,0,0,100,0,0,0,0,0,0,0,0,0,0,583.1914,8219.339,60.4304,9.0594,0,0,0,0,0,0,0,0,0,0,5.3971,14.2523,7.9913,7.9913,589.2416,42.7147,31.7169,10.9978,1.019,1.3467,9159.4,14.8291,581.9097,35.3828,5.4989,0,80.2121,37.2158,0.5269,0.0123,0,0,1507964,-546.5269,0,0,0,1.51E+08,0,0,53.8483,32.1512,592.6812,580.0935,570.9123,35.1939,14.2523,-7.8218,-6.9762,28.1315,618.6354,580.0935,544.9581,72.1085,33.5666,-1.5688,26.1847,-7.8218,-18.9086,581.229,34.7021,73.6773,0.4769,-45.9641,36.4073,-0.5457,0.0362
1,194.8,194.8,577.7033,151887.9,553,0,0.0908,555.3264,27.314,0,0,0.0528,0.0522,0.0518,0,0,0,53.8416,0,0,100,0,0,0,0,0,0,0,0,0,0,585.3427,8666.509,61.1888,5.0372,0,0,0,0,0,0,0,0,0,0,5.3806,14.226,7.9747,7.9747,587.6204,32.294,22.3769,9.9171,1.0172,1.4432,9156.592,14.8005,581.009,25.6826,4.9586,0,277.9556,27.3355,2.3264,0.072,0,0,1507964,-555.3264,0,0,0,1.51E+08,0,0,53.832,32.1328,588.969,580.5588,566.3907,19.582,14.226,-7.8307,-6.9387,28.4649,600.2829,580.5588,555.0767,44.9565,25.2324,-0.2497,26.3837,-7.8307,-19.0964,578.6395,23.3131,45.2062,0.5637,-180.0421,30.0181,-0.5434,0.0363
1,197.8,197.8,577.5856,153143,571,0,0.0885,572.8852,29.9013,0,0,0.0528,0.0522,0.0518,0,0,0,58.1643,0,0,100,0,0,0,0,0,0,0,0,0,0,584.8702,7167.757,46.8641,-0.5846,0,0,0,0,0,0,0,0,0,0,5.4616,15.5736,8.8331,8.8331,587.0953,14.2101,4.7004,9.5097,1.0165,3.0232,9302.748,16.2711,580.7554,7.8702,4.7549,0,622.3784,9.4553,1.8852,0.1327,0,0,1507964,-572.8852,0,0,0,1.51E+08,0,0,54.287,32.4336,588.4067,580.3101,566.7742,-2.2176,15.5736,-8.481,-7.7497,22.3423,588.6317,580.3101,566.5492,15.7465,7.4249,-6.336,23.5482,-8.481,-15.7243,578.497,5.6118,22.0825,0.6232,-2.4852,-5.7932,-0.6571,0.0327
1,200.8,200.8,578.1322,153968.7,553,0,0.1027,556.7674,30.4932,0,0,0.0528,0.0522,0.0518,0,0,0,59.176,0,0,100,0,0,0,0,0,0,0,0,0,0,583.6385,6090.002,60.9166,6.8982,0,0,0,0,0,0,0,0,0,0,5.5006,15.8819,9.0323,9.0323,589.1285,32.3611,21.3648,10.9963,1.019,1.5147,9336.843,16.6095,581.7976,25.0302,5.4982,0,107.9181,26.863,3.7674,0.1164,0,0,1507964,-556.7674,0,0,0,1.51E+08,0,0,54.4059,32.5257,592.2563,580.1924,569.947,26.0096,15.8819,-8.5932,-7.9736,29.2176,609.4023,580.1924,552.8011,52.6349,23.425,-3.9663,27.8101,-8.5932,-19.9018,580.7986,24.0312,56.6012,0.4839,-13.2705,33.3936,-0.6849,0.0322
1,203.8,203.8,578.1138,153288.1,546,0,0.093,548.3922,30.0785,0,0,0.0528,0.0522,0.0518,0,0,0,58.4575,0,0,100,0,0,0,0,0,0,0,0,0,0,584.438,6895.619,64.7201,7.9016,0,0,0,0,0,0,0,0,0,0,5.4769,15.6659,8.8926,8.8926,588.0964,39.7042,29.7216,9.9826,1.0173,1.3359,9312.93,16.3723,581.4413,33.0491,4.9913,0,98.4461,34.7129,2.3922,0.0603,0,0,1507964,-548.3922,0,0,0,1.51E+08,0,0,54.3216,32.4596,590.2049,580.4792,568.7239,29.9201,15.6659,-8.5171,-7.8141,30.91,611.2538,580.4792,547.6749,62.8616,32.087,-0.7173,28.736,-8.5171,-20.8842,579.8026,31.4104,63.5789,0.516,-87.6364,35.1266,-0.6653,0.0328
1,206.8,206.8,577.3921,154421.6,572,0,0.0533,575.0298,31.777,0,0,0.0528,0.0522,0.0518,0,0,0,61.2045,0,0,100,0,0,0,0,0,0,0,0,0,0,585.2055,5583.3,56.6717,0.2697,0,0,0,0,0,0,0,0,0,0,5.4875,16.5505,9.4682,9.4682,583.054,8.0242,2.3623,5.6619,1.0098,3.3968,9411.65,17.3458,579.2794,4.2496,2.831,0,-1958.697,5.1933,3.0298,0.3776,0,0,1507964,-575.0298,0,0,0,1.51E+08,0,0,54.6327,32.6711,581.891,580.316,565.7685,1.0045,16.5505,-8.932,-8.366,27.5161,581.9533,580.316,565.7061,6.9235,5.2862,-9.3237,27.1958,-8.932,-19.0113,575.9918,0.962,16.2472,0.8992,-0.7426,3.5515,-0.7475,0.0308
1,209.8,209.8,577.637,155562.4,566,0,0.0959,568.2249,33.6481,0,0,0.0528,0.0522,0.0518,0,0,0,64.2664,0,0,100,0,0,0,0,0,0,0,0,0,0,585.2503,4122.999,59.6145,3.7697,0,0,0,0,0,0,0,0,0,0,5.5967,17.5251,10.1131,10.1131,587.7117,19.4868,9.4121,10.0747,1.0174,2.0704,9522.867,18.4255,580.9952,12.7703,5.0374,0,436.5919,14.4495,2.2249,0.1142,0,0,1507964,-568.2249,0,0,0,1.51E+08,0,0,54.9812,32.9082,589.1222,580.4876,566.2866,13.7853,17.5251,-9.3916,-8.9765,29.4815,595.6041,580.4876,559.8047,27.3792,12.2627,-8.4202,28.9758,-9.3916,-20.4272,578.6321,10.4072,35.7994,0.5777,-3.2516,25.1832,-0.843,0.029
1,212.8,212.8,578.0393,155239,544,0,0.0947,545.3993,32.9697,0,0,0.0528,0.0522,0.0518,0,0,0,63.182,0,0,100,0,0,0,0,0,0,0,0,0,0,583.1863,4412.857,67.8992,9.3787,0,0,0,0,0,0,0,0,0,0,5.5758,17.1717,9.878,9.878,588.0258,42.6265,32.64,9.9865,1.0173,1.306,9482.236,18.0331,581.3682,35.9689,4.9933,0,105.6788,37.6333,1.3993,0.0328,0,0,1507964,-545.3993,0,0,0,1.51E+08,0,0,54.8585,32.8291,590.7725,579.9662,570.3691,34.5225,17.1717,-9.2122,-8.767,33.3589,616.5691,579.9662,544.5725,71.1698,34.5669,-0.8268,31.121,-9.2122,-22.7163,580.3693,34.97,71.9966,0.4916,-86.0786,36.7685,-0.8075,0.0297
1,215.8,215.8,577.3099,155803.2,569,0,0.0766,569.3385,33.3552,0,0,0.0528,0.0522,0.0518,0,0,0,63.7734,0,0,100,0,0,0,0,0,0,0,0,0,0,585.6992,3795.007,66.5107,2.0508,0,0,0,0,0,0,0,0,0,0,5.5641,17.3725,10.0114,10.0114,585.3694,16.0309,7.9714,8.0595,1.014,2.0111,9505.279,18.2559,579.9964,10.6579,4.0298,0,-673.233,12.0012,0.3385,0.0211,0,0,1507964,-569.3385,0,0,0,1.51E+08,0,0,54.9364,32.8878,585.2156,580.4514,564.7963,7.5191,17.3725,-9.2913,-8.9089,32.8063,587.6856,580.4514,562.3264,18.3471,11.1129,-7.0121,30.8927,-9.2913,-22.4291,576.8211,7.4826,25.3592,0.7147,-2.6165,18.1853,-0.8277,0.0293
1,218.8,218.8,577.7033,157107.4,572,0,0.0758,574.4989,35.9344,0,0,0.0528,0.0522,0.0518,0,0,0,67.9956,0,0,100,0,0,0,0,0,0,0,0,0,0,585.5931,2215.002,54.5259,0.6147,0,0,0,0,0,0,0,0,0,0,5.6578,18.7158,10.9167,10.9167,585.5503,11.0514,3.2044,7.847,1.0136,3.4488,9662.363,19.755,580.319,5.8201,3.9235,0,350.6522,7.1279,2.4989,0.2261,0,0,1507964,-574.4989,0,0,0,1.51E+08,0,0,55.4176,33.207,585.541,580.6595,565.9073,2.1972,18.7158,-9.9529,-9.7316,27.5864,585.7839,580.6595,565.6644,11.285,6.1606,-8.8345,28.6337,-9.9529,-19.6495,577.3693,2.8704,20.1195,0.7453,-1.2774,6.308,-0.9687,0.027
1,221.8,221.8,578.6301,157564,549,0,0.0984,549.1694,36.1032,0,0,0.0528,0.0522,0.0518,0,0,0,68.3225,0,0,100,0,0,0,0,0,0,0,0,0,0,583.2877,1572.904,69.9581,9.0591,0,0,0,0,0,0,0,0,0,0,5.6954,18.8037,10.9767,10.9767,588.8043,39.635,29.4608,10.1742,1.0176,1.3453,9672.823,19.8536,582.0215,32.8521,5.0871,0,56.4016,34.5479,0.1694,0.0043,0,0,1507964,-549.1694,0,0,0,1.51E+08,0,0,55.4594,33.2447,591.9129,580.3757,571.66,32.3185,18.8037,-9.9695,-9.8125,35.4632,615.6543,580.3757,547.9186,66.4849,31.2063,-1.2508,33.3667,-9.9695,-24.3755,581.3162,32.1468,67.7357,0.4792,-53.1539,36.3012,-0.9783,0.027
1,224.8,224.8,577.5038,157451.7,557,0,0.0913,557.3832,36.0802,0,0,0.0528,0.0522,0.0518,0,0,0,68.2524,0,0,100,0,0,0,0,0,0,0,0,0,0,585.1671,1691.761,70.6069,5.0432,0,0,0,0,0,0,0,0,0,0,5.6766,18.7918,10.9686,10.9686,586.9467,29.5635,20.1206,9.4429,1.0164,1.4693,9671.406,19.8403,580.6514,23.2683,4.7215,0,1173.711,24.8421,0.3832,0.013,0,0,1507964,-557.3832,0,0,0,1.51E+08,0,0,55.4532,33.2387,587.9569,580.3757,566.0374,17.9967,18.7918,-9.9687,-9.8001,35.7821,598.0684,580.3757,555.926,40.6852,22.9925,-1.4572,33.5571,-9.9687,-24.5654,578.1234,20.7402,42.1424,0.5802,-27.9201,29.3296,-0.977,0.027
1,227.8,227.8,577.5989,158876,571,0,0.0882,572.6455,38.6378,0,0,0.0528,0.0522,0.0518,0,0,0,72.3764,0,0,100,0,0,0,0,0,0,0,0,0,0,585.5172,-15.4684,56.6922,-0.589,0,0,0,0,0,0,0,0,0,0,5.7676,20.1239,11.8901,11.8901,586.5735,13.928,4.9534,8.9746,1.0155,2.8118,9832.697,21.3427,580.5904,7.9449,4.4873,0,568.8896,9.4407,1.6455,0.1181,0,0,1507964,-572.6455,0,0,0,1.51E+08,0,0,55.9453,33.5675,587.1604,580.5683,565.7211,-2.0486,20.1239,-10.6257,-10.6273,29.4776,587.3544,580.5683,565.5272,14.7089,7.9228,-7.1183,30.6495,-10.6257,-21.1529,577.8166,5.1711,21.8272,0.6891,-2.0664,-5.4096,-1.1291,0.025
1,230.8,230.8,577.8638,159918.3,558,0,0.1005,557.687,39.5051,0,0,0.0528,0.0522,0.0518,0,0,0,73.8251,0,0,100,0,0,0,0,0,0,0,0,0,0,584.7199,-1403.993,70.2958,6.8829,0,0,0,0,0,0,0,0,0,0,5.8148,20.5756,12.2078,12.2078,588.0296,30.3426,20.1768,10.1658,1.0176,1.5038,9888.617,21.8556,581.2524,23.5654,5.0829,0,178.3773,25.2597,-0.313,-0.0103,0,0,1507964,-557.687,0,0,0,1.51E+08,0,0,56.13,33.7058,589.8772,580.4362,567.5583,23.7196,20.5756,-10.8106,-10.9486,36.8891,604.9314,580.4362,552.5042,47.2444,22.7492,-5.1828,35.2905,-10.8106,-25.6635,579.2906,21.6036,52.4272,0.5328,-9.1156,32.4021,-1.1836,0.0245
1,233.8,233.8,577.9084,159680,549,0,0.0928,550.3074,39.1883,0,0,0.0528,0.0522,0.0518,0,0,0,73.2871,0,0,100,0,0,0,0,0,0,0,0,0,0,584.4622,-1100.422,73.8349,7.9279,0,0,0,0,0,0,0,0,0,0,5.7957,20.4106,12.0914,12.0914,587.3157,37.0083,27.601,9.4073,1.0163,1.3408,9868.117,21.668,581.0441,30.7368,4.7037,0,145.6599,32.3047,1.3074,0.0353,0,0,1507964,-550.3074,0,0,0,1.51E+08,0,0,56.0662,33.6615,588.9081,580.3671,568.0616,27.4102,20.4106,-10.733,-10.8414,38.62,607.81,580.3671,549.1597,57.5026,30.0598,-1.1476,36.2477,-10.733,-26.6785,579.1123,28.8049,58.6502,0.5321,-50.1068,34.5899,-1.1638,0.0247
1,236.8,236.8,577.6595,161010.2,573,0,0.0526,575.2229,40.9049,0,0,0.0528,0.0522,0.0518,0,0,0,76.0756,0,0,100,0,0,0,0,0,0,0,0,0,0,585.8171,-2638.372,65.513,0.2731,0,0,0,0,0,0,0,0,0,0,5.8178,21.3046,12.7263,12.7263,582.9329,7.71,2.4366,5.2734,1.0091,3.1642,9980.222,22.6873,579.4173,4.1944,2.6367,0,423.8218,5.0733,2.2229,0.2883,0,0,1507964,-575.2229,0,0,0,1.51E+08,0,0,56.4124,33.9,581.2836,580.7216,565.3755,0.9276,21.3046,-11.1601,-11.4186,34.8799,581.3376,580.7216,565.3216,6.1147,5.4987,-9.9013,34.5404,-11.1601,-24.6544,575.7936,0.5707,16.016,0.9615,-0.6176,3.3259,-1.2741,0.0236
1,239.8,239.8,577.5388,162342.5,566,0,0.0901,568.7142,42.9609,0,0,0.0528,0.0522,0.0518,0,0,0,79.3035,0,0,100,0,0,0,0,0,0,0,0,0,0,585.2542,-4337.925,69.042,3.7738,0,0,0,0,0,0,0,0,0,0,5.9336,22.3755,13.5012,13.5012,586.4454,17.7312,8.8246,8.9066,1.0154,2.0093,10117.91,23.9178,580.5076,11.7935,4.4533,0,873.5492,13.2779,2.7142,0.1531,0,0,1507964,-568.7142,0,0,0,1.51E+08,0,0,56.8321,34.1861,587.0783,580.4366,565.8917,12.547,22.3755,-11.6842,-12.1055,37.5543,592.9059,580.4366,560.0641,24.1917,11.7224,-8.6501,36.7957,-11.6842,-26.5257,577.8022,9.088,32.8418,0.6203,-2.7967,24.913,-1.4142,0.0224
1,242.8,242.8,578.2786,162532,546,0,0.0943,547.7617,42.5285,0,0,0.0528,0.0522,0.0518,0,0,0,78.6705,0,0,100,0,0,0,0,0,0,0,0,0,0,583.7964,-4640.898,76.8144,9.3842,0,0,0,0,0,0,0,0,0,0,5.9283,22.1503,13.337,13.337,587.6214,39.8597,30.5169,9.3428,1.0162,1.3062,10088.64,23.6582,581.3929,33.6312,4.6714,0,78.3521,35.1883,1.7617,0.0442,0,0,1507964,-547.7617,0,0,0,1.51E+08,0,0,56.7556,34.1461,589.7533,580.3513,569.9454,31.3313,22.1503,-11.5416,-11.9928,41.6072,612.7087,580.3513,546.99,64.947,32.5896,-0.7717,39.0937,-11.5416,-28.9362,580.0167,32.255,65.7187,0.5076,-84.1609,36.229,-1.3841,0.0227
1,245.8,245.8,577.538,163341.4,567,0,0.0762,570.5822,42.9083,0,0,0.0528,0.0522,0.0518,0,0,0,79.2209,0,0,100,0,0,0,0,0,0,0,0,0,0,585.9434,-5567.802,75.4087,2.091,0,0,0,0,0,0,0,0,0,0,5.9176,22.3481,13.4812,13.4812,585.0705,14.4883,6.9558,7.5325,1.013,2.0829,10114.34,23.8862,580.0488,9.4666,3.7663,0,899.5641,10.7221,3.5822,0.2472,0,0,1507964,-570.5822,0,0,0,1.51E+08,0,0,56.8452,34.2185,584.5332,580.6965,564.8266,6.9515,22.3481,-11.6089,-12.1494,41.0211,586.7386,580.6965,562.6213,16.1564,10.1143,-7.9609,38.8467,-11.6089,-28.648,576.6855,6.1033,24.1173,0.7495,-2.0295,17.6015,-1.4102,0.0224
1,247.2,247.2,577.64,164088.1,572,0,0.0646,573.2979,44.8728,0,0,0.0528,0.0522,0.0518,0,0,0,82.3247,0,0,100,0,0,0,0,0,0,0,0,0,0,585.533,-6490.683,63.2683,-0.6921,0,0,0,0,0,0,0,0,0,0,5.9851,23.3712,14.2363,14.2363,583.9476,10.6497,4.3421,6.3076,1.0109,2.4527,10249.38,25.0717,579.7425,6.4446,3.1538,0,455.387,7.4959,1.2979,0.1219,0,0,1507964,-573.2979,0,0,0,1.51E+08,0,0,57.2409,34.4751,582.9953,580.6069,565.6873,-2.2545,23.3712,-12.1489,-12.7742,35.1249,583.2841,580.6069,565.3985,9.9862,7.309,-7.8994,36.015,-12.1489,-25.418,576.4299,3.1319,17.8856,0.8503,-1.2642,-7.3009,-1.5519,0.0213