File: datas/d100-60-0.2.csv
Stage Number,Time since start of test (s),Time since start of stage (s),Radial Pressure (kPa),Radial Volume (mm3),Back Pressure (kPa),Back Volume (mm3),Load Cell (kN),Pore Pressure (kPa),Axial Displacement (mm),L/C Pressure (kPa),L/C Volume (mm3),Local Axial 1,Local Axial 2,Local Radial,Base Pressure (kPa),Base Volume (mm3),Back Differential Pressure (kPa),Axial Displacement 2 (mm),Pore Air Pressure (kPa),Pore Air Volume (mm3),Atmospheric Pressure (kPa),Temperature (°C),Mid Plane PWP (kPa),Back to Cell Differential (kPa),Total Volume Change (mm3),Undefined Tx 1,Undefined Tx 2,Undefined Tx 3,Undefined Tx. 4,HCA secondary control axial load (kN),HCA secondary control torque,Internal Cell Pr. (kPa),Internal Cell Vol. (mm3),Rotational Displ. (mm),Torque,Local Int Defmn 1 (mm),Local Int Defmn 2 (mm),Circumf. Defmn 1 (mm),Circumf. Defmn 2 (mm),Circumf. Defmn 3 (mm),Outer Cell Pr 2 (kPa),Internal cell Pr 2 (kPa),Rotation 2 (°),Secondary Cell Pr (kPa),Secondary Back Pr (kPa),Axial Force (kN),Axial Strain (%),Av Diameter Change (mm),Radial Strain (%),Axial Stress (kPa),Eff. Axial Stress (kPa),Eff. Radial Stress (kPa),Deviator Stress (kPa),Total Stress Ratio (%),Eff. Stress Ratio (%),Current Area (mm2),Shear Strain (%),Cambridge p (kPa),Eff. Cambridge p' (kPa),Max Shear Stress t,Volume Change (mm3),B Value,Mean Stress s/Eff. Axial Stress 2,Excess PWP (kPa),PWP Ratio,Lower Chamber Displacement (mm),Lower Chamber Axial Load (kPa),Specimen Air Volume (mm3),Matric Suction (kPa),Voids ratio,Degree of Saturation (°),Specimen Water Volume (mm3),kRT constant,Permeability IN,Permeability OUT,HCA Outer Rad,HCA Inner Rad,HCA Sigma Z (kPa),HCA Sigma R (kPa),HCA Sigma Theta (kPa),HCA Tau Theta Z,HCA Ez,HCA Er,HCA Etheta,HCA Gamma,HCA Sigma1,HCA Sigma2,HCA Sigma3,HCA Eff Sigma1,HCA Eff Sigma2,HCA Eff Sigma3,HCA E1,HCA E2,HCA E3,HCA P,HCA Eff P,HCA Q,HCA B,HCA Eff R,HCA Alpha,HCA Ev,HCA E1 rtv
1,0,0,559.8925,101543.1,459,0,-0.0842,460.7617,-0.0002,0,0,0.0528,0.0522,0.0518,0,0,0,6.1126,0,0,100,0,0,0,0,0,0,0,0,0,0,561.2751,-135091.8,0.0011,4.2498,0,0,0,0,0,0,0,0,0,0,4.3132,-0.0001,0,0,549.1747,88.413,99.1308,-10.7178,0.9809,0.8919,7853.967,-0.0001,556.3199,95.5582,-5.3589,0,-0.5639,93.7719,1.7617,0.0199,0,0,1514954,-460.7617,0,0,0,1.51E+08,0,0,52.1816,33.5101,542.171,560.4332,557.4112,19.4255,-0.0001,7.1151,-6.6421,0.0004,570.6578,560.4332,528.9245,109.8961,99.6715,68.1628,-0.0001,7.1151,-6.6421,553.3386,92.5768,41.7333,0.755,1.6123,55.7094,0.4729,0
1,3.8,3.8,562.1372,102619.9,472,0,-0.0931,472.2499,-0.0598,0,0,0.0528,0.0522,0.0518,0,0,0,6.0178,0,0,100,0,0,0,0,0,0,0,0,0,0,557.1327,-136203.7,1.4907,7.2069,0,0,0,0,0,0,0,0,0,0,4.3205,-0.031,-0.0155,-0.0155,550.2741,78.0242,89.8873,-11.8631,0.9789,0.868,7851.541,-0.031,558.1829,85.933,-5.9316,0,4.7857,83.9558,0.2499,0.0032,0,0,1514954,-472.2499,0,0,0,1.51E+08,0,0,52.1912,33.5323,547.1279,560.1796,571.1309,32.9411,-0.031,7.1874,-6.6767,0.5871,594.1887,560.1796,524.0701,121.9388,87.9297,51.8202,-0.0052,7.1874,-6.7025,559.4795,87.2296,70.1186,0.515,2.3531,55.0091,0.4797,0.0399
1,7.8,7.8,561.8926,103354.1,479,0,-0.0947,480.8828,-0.0045,0,0,0.0528,0.0522,0.0518,0,0,0,6.1067,0,0,100,0,0,0,0,0,0,0,0,0,0,556.8299,-137033.2,0.9304,0.3613,0,0,0,0,0,0,0,0,0,0,4.3183,-0.0023,-0.0011,-0.0011,549.8361,68.9533,81.0098,-12.0565,0.9785,0.8512,7853.794,-0.0023,557.8738,76.991,-6.0283,0,9.368,74.9816,1.8828,0.0273,0,0,1514954,-480.8828,0,0,0,1.51E+08,0,0,52.2118,33.5575,546.6155,559.9117,570.9999,1.6501,-0.0023,7.2139,-6.7265,0.3667,571.111,559.9117,546.5043,90.2282,79.0289,65.6215,0.0077,7.2139,-6.7365,559.1757,78.2929,24.6067,0.5449,1.375,86.1462,0.4851,0.0261
1,11.8,11.8,561.9829,103383.6,477,0,-0.091,478.6326,-0.0615,0,0,0.0528,0.0522,0.0518,0,0,0,6.038,0,0,100,0,0,0,0,0,0,0,0,0,0,556.4123,-137079.9,1.7191,8.1058,0,0,0,0,0,0,0,0,0,0,4.3214,-0.0319,-0.0159,-0.0159,550.3938,71.7612,83.3503,-11.5891,0.9794,0.861,7851.47,-0.0319,558.1199,79.4873,-5.7946,0,7.9793,77.5558,1.6326,0.0228,0,0,1514954,-478.6326,0,0,0,1.51E+08,0,0,52.2048,33.5537,547.7943,559.8034,572.0045,37.0359,-0.0319,7.2323,-6.7148,0.6773,598.8634,559.8034,520.9354,120.2308,81.1708,42.3028,0.0022,7.2323,-6.7489,559.8674,81.2348,77.928,0.4988,2.8421,54.0499,0.4856,0.0445
1,15.8,15.8,561.5774,104316.6,487,0,-0.0945,489.628,-0.0715,0,0,0.0528,0.0522,0.0518,0,0,0,5.9783,0,0,100,0,0,0,0,0,0,0,0,0,0,556.7119,-138147.6,2.0287,2.4513,0,0,0,0,0,0,0,0,0,0,4.3145,-0.0371,-0.0185,-0.0185,549.5434,59.9154,71.9494,-12.034,0.9786,0.8327,7851.063,-0.0371,557.5661,67.9381,-6.017,0,15.7803,65.9324,2.628,0.0439,0,0,1514954,-489.628,0,0,0,1.51E+08,0,0,52.2203,33.5791,546.2003,559.6732,570.3417,11.1958,-0.0371,7.2892,-6.7593,0.7996,574.7345,559.6732,541.8075,85.1065,70.0452,52.1795,0.0101,7.2892,-6.8065,558.7384,69.1104,32.927,0.5426,1.631,68.5767,0.4928,0.0502
1,19.8,19.8,561.8742,104877.4,491,0,-0.0935,493.0913,-0.0499,0,0,0.0528,0.0522,0.0518,0,0,0,6.0803,0,0,100,0,0,0,0,0,0,0,0,0,0,556.2197,-138816.3,1.9631,3.9245,0,0,0,0,0,0,0,0,0,0,4.3183,-0.0259,-0.0129,-0.0129,549.9659,56.8746,68.7829,-11.9083,0.9788,0.8269,7851.941,-0.0259,557.9048,64.8135,-5.9542,0,15.2049,62.8288,2.0913,0.0368,0,0,1514954,-493.0913,0,0,0,1.51E+08,0,0,52.2338,33.5974,547.2584,559.6608,572.068,17.916,-0.0259,7.3169,-6.7938,0.7741,581.4545,559.6608,537.8719,88.3632,66.5695,44.7806,0.0181,7.3169,-6.8378,559.6624,66.5711,43.5826,0.4999,1.9732,62.3491,0.4972,0.0487
1,23.8,23.8,561.9164,105079.5,490,0,-0.0947,490.1732,-0.1842,0,0,0.0528,0.0522,0.0518,0,0,0,5.831,0,0,100,0,0,0,0,0,0,0,0,0,0,556.4581,-139052,3.3347,7.2294,0,0,0,0,0,0,0,0,0,0,4.3144,-0.0955,-0.0477,-0.0477,549.8516,59.6784,71.7432,-12.0648,0.9785,0.8318,7846.481,-0.0955,557.8948,67.7216,-6.0324,0,13.5595,65.7108,0.1732,0.0029,0,0,1514954,-490.1732,0,0,0,1.51E+08,0,0,52.2194,33.5915,546.9115,559.7797,571.7592,33.0343,-0.0955,7.3658,-6.7717,1.3137,594.6287,559.7797,524.042,104.4555,69.6065,33.8688,0.0313,7.3658,-6.8985,559.4835,69.3103,70.5867,0.5063,3.0841,55.3054,0.4986,0.0689
1,27.8,27.8,561.9437,106248,501,0,-0.0945,503.3874,-0.086,0,0,0.0528,0.0522,0.0518,0,0,0,5.9698,0,0,100,0,0,0,0,0,0,0,0,0,0,556.6174,-140379.3,2.484,0.3809,0,0,0,0,0,0,0,0,0,0,4.317,-0.0446,-0.0223,-0.0223,549.9031,46.5157,58.5563,-12.0407,0.9786,0.7944,7850.474,-0.0446,557.9302,54.5428,-6.0204,0,19.4225,52.536,2.3874,0.0513,0,0,1514954,-503.3874,0,0,0,1.51E+08,0,0,52.2536,33.6326,546.9024,559.8579,571.5641,1.7382,-0.0446,7.4056,-6.8535,0.9799,571.686,559.8579,546.7805,68.2986,56.4705,43.3931,0.0252,7.4056,-6.9233,559.4415,56.0541,24.9055,0.5251,1.574,85.9881,0.5075,0.0569
1,31.8,31.8,561.8298,106218.4,494,0,-0.0913,495.0669,-0.195,0,0,0.0528,0.0522,0.0518,0,0,0,5.8402,0,0,100,0,0,0,0,0,0,0,0,0,0,555.9021,-140347.4,3.6376,8.0969,0,0,0,0,0,0,0,0,0,0,4.3168,-0.1011,-0.0505,-0.0505,550.1882,55.1213,66.7629,-11.6416,0.9793,0.8256,7846.042,-0.1011,557.9492,62.8823,-5.8208,0,16.4816,60.9421,1.0669,0.0194,0,0,1514954,-495.0669,0,0,0,1.51E+08,0,0,52.2383,33.6223,547.8402,559.5086,572.5358,36.9804,-0.1011,7.4345,-6.8257,1.4337,599.1754,559.5086,521.2006,104.1085,64.4417,26.1337,0.0484,7.4345,-6.9752,559.9616,64.8946,77.9748,0.4913,3.9837,54.2321,0.5077,0.0715
1,35.8,35.8,561.6803,106949,503,0,-0.0955,504.6362,-0.1996,0,0,0.0528,0.0522,0.0518,0,0,0,5.78,0,0,100,0,0,0,0,0,0,0,0,0,0,557.1682,-141206.3,3.8004,2.4178,0,0,0,0,0,0,0,0,0,0,4.3114,-0.1035,-0.0517,-0.0517,549.5131,44.8769,57.0441,-12.1672,0.9783,0.7867,7845.854,-0.1035,557.6246,52.9884,-6.0836,0,22.7253,50.9605,1.6362,0.0365,0,0,1514954,-504.6362,0,0,0,1.51E+08,0,0,52.2513,33.643,545.8567,559.913,569.838,11.0388,-0.1035,7.4789,-6.8623,1.4984,574.1456,559.913,541.5491,69.5094,55.2768,36.9129,0.0587,7.4789,-7.0245,558.5359,53.8997,32.5965,0.5634,1.8831,68.6834,0.5131,0.0727
1,39.8,39.8,561.9962,107904.8,507,0,-0.0937,508.9458,-0.1577,0,0,0.0528,0.0522,0.0518,0,0,0,5.8771,0,0,100,0,0,0,0,0,0,0,0,0,0,555.7352,-142304.8,3.6364,3.8879,0,0,0,0,0,0,0,0,0,0,4.3166,-0.0818,-0.0409,-0.0409,550.0566,41.1108,53.0504,-11.9396,0.9788,0.7749,7847.556,-0.0818,558.0164,49.0706,-5.9698,0,21.446,47.0806,1.9458,0.0473,0,0,1514954,-508.9458,0,0,0,1.51E+08,0,0,52.2742,33.6735,547.7806,559.5432,573.3306,17.7366,-0.0818,7.5228,-6.9201,1.4349,582.4139,559.5432,538.6973,73.4681,50.5974,29.7515,0.0656,7.5228,-7.0675,560.2181,51.2723,43.7166,0.4768,2.4694,62.8819,0.5209,0.0703
1,43.8,43.8,562.0439,107659.7,498,0,-0.0944,498.7954,-0.3554,0,0,0.0528,0.0522,0.0518,0,0,0,5.5807,0,0,100,0,0,0,0,0,0,0,0,0,0,556.5482,-142061.9,5.3111,7.2144,0,0,0,0,0,0,0,0,0,0,4.3118,-0.1843,-0.092,-0.092,550.0077,51.2123,63.2485,-12.0362,0.9786,0.8097,7839.527,-0.1842,558.0318,59.2364,-6.0181,0,16.5687,57.2304,0.7954,0.0155,0,0,1514954,-498.7954,0,0,0,1.51E+08,0,0,52.2436,33.6503,547.1255,559.8909,571.99,32.9661,-0.1843,7.5656,-6.8618,2.0923,594.7902,559.8909,524.3253,95.9948,61.0955,25.5299,0.1288,7.5656,-7.1749,559.6688,60.8734,70.4649,0.5047,3.7601,55.3313,0.5195,0.0842
1,47.8,47.8,561.9261,109155.4,514,0,-0.0947,516.4822,-0.2081,0,0,0.0528,0.0522,0.0518,0,0,0,5.7849,0,0,100,0,0,0,0,0,0,0,0,0,0,557.0968,-143806.2,4.1479,0.3836,0,0,0,0,0,0,0,0,0,0,4.3139,-0.1079,-0.0539,-0.0539,549.8559,33.3737,45.4439,-12.0702,0.9785,0.7344,7845.51,-0.1079,557.9026,41.4204,-6.0351,0,25.6063,39.4088,2.4822,0.0744,0,0,1514954,-516.4822,0,0,0,1.51E+08,0,0,52.2911,33.7059,546.4985,560.0333,570.6844,1.7495,-0.1079,7.6125,-6.9735,1.6372,570.8103,560.0333,546.3726,54.3281,43.5512,29.8904,0.0821,7.6125,-7.1635,559.0721,42.5899,24.4377,0.559,1.8176,85.884,0.5311,0.0745
1,51.8,51.8,562.0995,109082,501,0,-0.091,503.0107,-0.3739,0,0,0.0528,0.0522,0.0518,0,0,0,5.5723,0,0,100,0,0,0,0,0,0,0,0,0,0,555.3701,-143760.8,5.7099,8.0753,0,0,0,0,0,0,0,0,0,0,4.3152,-0.1938,-0.0968,-0.0968,550.4936,47.4829,59.0888,-11.6059,0.9794,0.8036,7838.783,-0.1937,558.2309,55.2202,-5.803,0,17.9726,53.2859,2.0107,0.0423,0,0,1514954,-503.0107,0,0,0,1.51E+08,0,0,52.268,33.6903,548.7436,559.462,574.303,36.8775,-0.1938,7.6559,-6.9316,2.2507,600.5524,559.462,522.4942,97.5417,56.4513,19.4835,0.1632,7.6559,-7.2886,560.8362,57.8255,78.0582,0.4736,5.0064,54.5567,0.5305,0.0855
1,55.8,55.8,561.579,109694.8,511,0,-0.0955,513.3233,-0.3663,0,0,0.0528,0.0522,0.0518,0,0,0,5.5405,0,0,100,0,0,0,0,0,0,0,0,0,0,557.5447,-144440.3,5.7579,2.4357,0,0,0,0,0,0,0,0,0,0,4.3068,-0.1899,-0.0948,-0.0948,549.4006,36.0773,48.2557,-12.1784,0.9783,0.7476,7839.088,-0.1898,557.5195,44.1962,-6.0892,0,28.7442,42.1665,2.3233,0.0644,0,0,1514954,-513.3233,0,0,0,1.51E+08,0,0,52.2797,33.7076,545.4141,559.9974,568.9011,11.1192,-0.1899,7.6884,-6.963,2.2705,573.33,559.9974,540.9852,60.0067,46.6741,27.6619,0.1714,7.6884,-7.3243,558.1042,44.7809,32.3448,0.5878,2.1693,68.2821,0.5355,0.0853
1,59.8,59.8,561.9633,110961.5,516,0,-0.0923,518.3605,-0.304,0,0,0.0528,0.0522,0.0518,0,0,0,5.6513,0,0,100,0,0,0,0,0,0,0,0,0,0,555.8612,-145967.9,5.4955,3.8941,0,0,0,0,0,0,0,0,0,0,4.3144,-0.1576,-0.0787,-0.0787,550.1927,31.8322,43.6028,-11.7706,0.9791,0.73,7841.617,-0.1575,558.0398,39.6793,-5.8853,0,26.0248,37.7175,2.3605,0.0742,0,0,1514954,-518.3605,0,0,0,1.51E+08,0,0,52.3122,33.7503,547.923,559.5703,573.0586,17.7564,-0.1576,7.7476,-7.0443,2.1695,582.2449,559.5703,538.7367,63.8844,41.2098,20.3762,0.1687,7.7476,-7.3706,560.184,41.8235,43.5082,0.4788,3.1352,62.6452,0.5457,0.0827
1,63.8,63.8,561.6927,110412.7,503,0,-0.0957,504.501,-0.5497,0,0,0.0528,0.0522,0.0518,0,0,0,5.3062,0,0,100,0,0,0,0,0,0,0,0,0,0,556.6617,-145371.1,7.4014,7.2243,0,0,0,0,0,0,0,0,0,0,4.3033,-0.285,-0.1422,-0.1422,549.4752,44.9742,57.1917,-12.2175,0.9782,0.7864,7831.655,-0.2848,557.6202,53.1192,-6.1088,0,22.5105,51.083,1.501,0.0334,0,0,1514954,-504.501,0,0,0,1.51E+08,0,0,52.2695,33.7143,546.1837,559.72,570.8339,33.0132,-0.285,7.7865,-6.9592,2.9156,593.7477,559.72,523.2699,89.2467,55.219,18.7689,0.3005,7.7865,-7.5447,558.9125,54.4115,70.4778,0.5172,4.755,55.2363,0.5423,0.0929
1,67.8,67.8,561.7541,112185.3,523,0,-0.0936,525.2633,-0.3612,0,0,0.0528,0.0522,0.0518,0,0,0,5.5569,0,0,100,0,0,0,0,0,0,0,0,0,0,557.5693,-147407.7,5.9434,0.3492,0,0,0,0,0,0,0,0,0,0,4.3102,-0.1873,-0.0935,-0.0935,549.8201,24.5568,36.4908,-11.934,0.9788,0.673,7839.292,-0.1872,557.7761,32.5128,-5.967,0,32.1958,30.5238,2.2633,0.0922,0,0,1514954,-525.2633,0,0,0,1.51E+08,0,0,52.3271,33.7804,546.0883,560.1124,569.3762,1.592,-0.1873,7.8359,-7.0929,2.3467,569.4846,560.1124,545.98,44.2213,34.8491,20.7167,0.1907,7.8359,-7.4709,558.5257,33.2624,23.5046,0.6013,2.1346,86.1073,0.5557,0.0846
1,71.8,71.8,562.156,112102.1,504,0,-0.092,507.9037,-0.5724,0,0,0.0528,0.0522,0.0518,0,0,0,5.2512,0,0,100,0,0,0,0,0,0,0,0,0,0,555.3656,-147372.5,7.8654,8.09,0,0,0,0,0,0,0,0,0,0,4.3101,-0.2967,-0.148,-0.148,550.4077,42.504,54.2523,-11.7483,0.9791,0.7835,7830.741,-0.2965,558.2399,50.3362,-5.8742,0,19.5861,48.3782,3.9037,0.0918,0,0,1514954,-507.9037,0,0,0,1.51E+08,0,0,52.298,33.7611,548.6506,559.4922,574.5233,36.9431,-0.2967,7.8929,-7.0406,3.1005,600.7295,559.4922,522.4443,92.8258,51.5885,14.5406,0.3534,7.8929,-7.6907,560.8887,52.985,78.2852,0.4732,6.3839,54.6494,0.5556,0.0933
1,75.8,75.8,561.3685,112552.6,514,0,-0.0957,518.8234,-0.554,0,0,0.0528,0.0522,0.0518,0,0,0,5.2591,0,0,100,0,0,0,0,0,0,0,0,0,0,557.6348,-147916.5,7.82,2.4417,0,0,0,0,0,0,0,0,0,0,4.3006,-0.2872,-0.1433,-0.1433,549.1425,30.3191,42.5451,-12.226,0.9782,0.7126,7831.483,-0.287,557.2932,38.4698,-6.113,0,35.8936,36.4321,4.8234,0.1591,0,0,1514954,-518.8234,0,0,0,1.51E+08,0,0,52.309,33.776,544.9447,559.9036,568.1732,11.1459,-0.2872,7.9156,-7.0686,3.0838,572.6563,559.9036,540.4617,53.8329,41.0802,21.6382,0.3534,7.9156,-7.7092,557.6739,38.8504,32.1947,0.6039,2.4879,68.0894,0.5598,0.0927
1,79.8,79.8,562.1099,114130.5,522,0,-0.0894,524.816,-0.4752,0,0,0.0528,0.0522,0.0518,0,0,0,5.3729,0,0,100,0,0,0,0,0,0,0,0,0,0,556.1362,-149821.3,7.4774,3.8929,0,0,0,0,0,0,0,0,0,0,4.3145,-0.2464,-0.123,-0.123,550.6932,25.8772,37.294,-11.4168,0.9797,0.6939,7834.67,-0.2463,558.3044,33.4884,-5.7084,0,27.145,31.5856,2.816,0.1088,0,0,1514954,-524.816,0,0,0,1.51E+08,0,0,52.3496,33.8292,548.5638,559.765,573.0214,17.7446,-0.2464,7.989,-7.1697,2.9529,582.3429,559.765,539.2423,57.5269,34.949,14.4263,0.3346,7.989,-7.7507,560.4501,35.6341,43.1006,0.4762,3.9876,62.2865,0.5729,0.0899
1,83.8,83.8,561.5962,113337.2,506,0,-0.0945,508.1551,-0.7564,0,0,0.0528,0.0522,0.0518,0,0,0,4.98,0,0,100,0,0,0,0,0,0,0,0,0,0,556.3376,-148958.6,9.5558,7.1986,0,0,0,0,0,0,0,0,0,0,4.299,-0.3921,-0.1955,-0.1955,549.5123,41.3572,53.4411,-12.0839,0.9785,0.7739,7823.3,-0.3917,557.5682,49.4131,-6.042,0,25.6716,47.3992,2.1551,0.0521,0,0,1514954,-508.1551,0,0,0,1.51E+08,0,0,52.2981,33.7837,546.4882,559.5323,571.1918,32.8965,-0.3921,8.024,-7.0651,3.7641,593.9789,559.5323,523.701,85.8238,51.3772,15.5459,0.5395,8.024,-7.9967,559.0707,50.9156,70.2779,0.5099,5.5207,55.2899,0.5668,0.0982
1,87.8,87.8,561.4669,115226,529,0,-0.0943,531.2997,-0.5372,0,0,0.0528,0.0522,0.0518,0,0,0,5.2733,0,0,100,0,0,0,0,0,0,0,0,0,0,557.8307,-151176,7.8098,0.3866,0,0,0,0,0,0,0,0,0,0,4.3032,-0.2785,-0.139,-0.139,549.4268,18.1271,30.1672,-12.0401,0.9786,0.6009,7832.163,-0.2783,557.4536,26.1539,-6.0201,0,41.1128,24.1472,2.2997,0.1269,0,0,1514954,-531.2997,0,0,0,1.51E+08,0,0,52.3626,33.8568,545.2667,560.039,568.1196,1.762,-0.2785,8.0742,-7.2135,3.0846,568.2547,560.039,545.1317,36.955,28.7393,13.832,0.3505,8.0742,-7.8425,557.8085,26.5088,23.123,0.6447,2.6717,85.6169,0.5822,0.0906
1,91.8,91.8,562.4095,115205.3,509,0,-0.0911,510.7829,-0.7827,0,0,0.0528,0.0522,0.0518,0,0,0,4.9346,0,0,100,0,0,0,0,0,0,0,0,0,0,555.0477,-151202.2,10.0558,8.1185,0,0,0,0,0,0,0,0,0,0,4.3082,-0.4058,-0.2023,-0.2023,550.7635,39.9806,51.6266,-11.646,0.9793,0.7744,7822.232,-0.4054,558.5275,47.7446,-5.823,0,18.8011,45.8036,1.7829,0.0446,0,0,1514954,-510.7829,0,0,0,1.51E+08,0,0,52.3297,33.8359,549.5012,559.5186,575.8785,37.0718,-0.4058,8.1443,-7.1555,3.9641,602.0377,559.5186,523.3419,91.2548,48.7357,12.559,0.6065,8.1443,-8.1678,561.6328,50.8498,78.6958,0.4597,7.2661,54.7917,0.583,0.0981
1,95.8,95.8,561.3857,115473.5,519,0,-0.0959,522.6082,-0.7581,0,0,0.0528,0.0522,0.0518,0,0,0,4.9397,0,0,100,0,0,0,0,0,0,0,0,0,0,557.7889,-151561.3,9.9384,2.4185,0,0,0,0,0,0,0,0,0,0,4.2959,-0.393,-0.1959,-0.1959,549.121,26.5128,38.7775,-12.2647,0.9782,0.6837,7823.229,-0.3926,557.2974,34.6892,-6.1324,0,37.8348,32.6452,3.6082,0.1361,0,0,1514954,-522.6082,0,0,0,1.51E+08,0,0,52.3387,33.8468,544.8174,559.9731,567.9692,11.0398,-0.393,8.1555,-7.177,3.9192,572.3895,559.9731,540.3971,49.7813,37.3649,17.7889,0.5952,8.1555,-8.1652,557.5865,34.9784,31.9924,0.6119,2.7984,68.179,0.5855,0.0974
1,99.8,99.8,562.1281,117333.1,525,0,-0.0909,528.5363,-0.6686,0,0,0.0528,0.0522,0.0518,0,0,0,5.0668,0,0,100,0,0,0,0,0,0,0,0,0,0,556.3513,-153756.8,9.5344,3.8973,0,0,0,0,0,0,0,0,0,0,4.3088,-0.3466,-0.1729,-0.1729,550.5154,21.9791,33.5918,-11.6127,0.9793,0.6543,7826.847,-0.3463,558.2572,29.7209,-5.8064,0,28.5036,27.7855,3.5363,0.1609,0,0,1514954,-528.5363,0,0,0,1.51E+08,0,0,52.3853,33.9079,548.147,559.8582,572.7292,17.7608,-0.3466,8.2403,-7.2928,3.7661,582.0371,559.8582,538.8391,53.5008,31.3219,10.3028,0.5568,8.2403,-8.1962,560.2448,31.7085,43.198,0.4866,5.1928,62.3423,0.6009,0.0944
1,103.8,103.8,561.9238,116322.6,509,0,-0.0945,510.5759,-0.9719,0,0,0.0528,0.0522,0.0518,0,0,0,4.5969,0,0,100,0,0,0,0,0,0,0,0,0,0,556.4108,-152636.3,11.7073,7.2141,0,0,0,0,0,0,0,0,0,0,4.2967,-0.5039,-0.251,-0.251,549.83,39.2541,51.3479,-12.0938,0.9785,0.7645,7814.597,-0.5033,557.8926,47.3167,-6.0469,0,22.9121,45.301,1.5759,0.0401,0,0,1514954,-510.5759,0,0,0,1.51E+08,0,0,52.3267,33.8542,546.9979,559.7582,572.0275,32.9696,-0.5039,8.269,-7.172,4.6113,594.7776,559.7582,524.2478,84.2017,49.1823,13.6719,0.8255,8.269,-8.5014,559.5945,49.0186,70.5298,0.5035,6.1587,55.393,0.5931,0.1018
1,107.8,107.8,561.4498,118349.4,533,0,-0.094,535.6057,-0.73,0,0,0.0528,0.0522,0.0518,0,0,0,4.9689,0,0,100,0,0,0,0,0,0,0,0,0,0,557.9233,-154991.4,9.6761,0.3779,0,0,0,0,0,0,0,0,0,0,4.299,-0.3785,-0.1887,-0.1887,549.4379,13.8322,25.8441,-12.0119,0.9786,0.5352,7824.36,-0.3781,557.4459,21.8402,-6.006,0,44.0648,19.8382,2.6057,0.1884,0,0,1514954,-535.6057,0,0,0,1.51E+08,0,0,52.3963,33.9324,545.2257,560.0637,567.9308,1.7221,-0.3785,8.3195,-7.3309,3.8223,568.0607,560.0637,545.0958,32.455,24.458,9.4901,0.5486,8.3195,-8.258,557.7401,22.1344,22.9649,0.6518,3.4199,85.6872,0.6101,0.0946
1,111.8,111.8,562.2666,118372.2,510,0,-0.0912,513.1022,-1.0004,0,0,0.0528,0.0522,0.0518,0,0,0,4.5718,0,0,100,0,0,0,0,0,0,0,0,0,0,554.7703,-155101.9,12.2273,8.1031,0,0,0,0,0,0,0,0,0,0,4.302,-0.5186,-0.2583,-0.2583,550.5887,37.4865,49.1644,-11.6779,0.9792,0.7625,7813.455,-0.5179,558.374,45.2719,-5.839,0,20.7926,43.3255,3.1022,0.0828,0,0,1514954,-513.1022,0,0,0,1.51E+08,0,0,52.3616,33.9115,549.4447,559.32,576.0448,37.0008,-0.5186,8.4005,-7.2712,4.8202,602.0634,559.32,523.4261,88.9612,46.2178,10.3239,0.9027,8.4005,-8.6925,561.6032,48.501,78.6373,0.4564,8.617,54.8856,0.6107,0.1012
1,115.8,115.8,561.5774,118579.8,522,0,-0.0965,525.717,-0.9694,0,0,0.0528,0.0522,0.0518,0,0,0,4.5828,0,0,100,0,0,0,0,0,0,0,0,0,0,557.8015,-155354.3,12.0422,2.4322,0,0,0,0,0,0,0,0,0,0,4.2921,-0.5026,-0.2504,-0.2504,549.2343,23.5173,35.8604,-12.3431,0.978,0.6558,7814.698,-0.502,557.4631,31.7461,-6.1716,0,35.5629,29.6889,3.717,0.1581,0,0,1514954,-525.717,0,0,0,1.51E+08,0,0,52.3697,33.9203,545.0118,560.0931,568.5195,11.1022,-0.5026,8.4046,-7.2894,4.7489,572.9338,560.0931,540.5974,47.2168,34.3761,14.8804,0.878,8.4046,-8.67,557.8748,32.1578,32.3364,0.6029,3.1731,68.3166,0.6126,0.1004
1,119.8,119.8,562.0751,120571.9,527,0,-0.0915,531.36,-0.875,0,0,0.0528,0.0522,0.0518,0,0,0,4.7491,0,0,100,0,0,0,0,0,0,0,0,0,0,556.1464,-157811.8,11.5835,3.8864,0,0,0,0,0,0,0,0,0,0,4.3031,-0.4536,-0.226,-0.226,550.3734,19.0134,30.7151,-11.7017,0.9792,0.619,7818.51,-0.4531,558.1745,26.8145,-5.8509,0,30.3708,24.8643,4.36,0.2293,0,0,1514954,-531.36,0,0,0,1.51E+08,0,0,52.421,33.988,548.089,559.7432,573.0067,17.7082,-0.4536,8.501,-7.4171,4.5762,582.1997,559.7432,538.896,50.8397,28.3832,7.536,0.8179,8.501,-8.6886,560.2796,28.9196,43.3037,0.4814,6.7462,62.5644,0.6303,0.0973
1,123.8,123.8,561.64,119432.5,511,0,-0.0952,512.877,-1.1929,0,0,0.0528,0.0522,0.0518,0,0,0,4.2503,0,0,100,0,0,0,0,0,0,0,0,0,0,556.509,-156507.6,13.8263,7.2126,0,0,0,0,0,0,0,0,0,0,4.2888,-0.6184,-0.3078,-0.3078,549.4443,36.5673,48.763,-12.1957,0.9783,0.7499,7805.705,-0.6175,557.5748,44.6978,-6.0979,0,27.5779,42.6652,1.877,0.0513,0,0,1514954,-512.877,0,0,0,1.51E+08,0,0,52.3576,33.9286,546.2979,559.6224,571.0864,32.9635,-0.6184,8.5246,-7.2853,5.4458,593.9088,559.6224,523.4755,81.0318,46.7454,10.5985,1.1413,8.5246,-9.045,559.0023,46.1252,70.4333,0.5132,7.6456,55.3031,0.6209,0.1042
1,127.8,127.8,561.5522,121517.3,537,0,-0.093,539.5282,-0.9389,0,0,0.0528,0.0522,0.0518,0,0,0,4.6123,0,0,100,0,0,0,0,0,0,0,0,0,0,558.2254,-158952.5,11.5009,0.3986,0,0,0,0,0,0,0,0,0,0,4.2961,-0.4868,-0.2425,-0.2425,549.6597,10.1315,22.024,-11.8925,0.9788,0.46,7815.927,-0.4862,557.5881,18.0599,-5.9463,0,43.738,16.0778,2.5282,0.2495,0,0,1514954,-539.5282,0,0,0,1.51E+08,0,0,52.4302,34.0099,545.3771,560.2433,567.6945,1.8162,-0.4868,8.5759,-7.4504,4.5436,567.8413,560.2433,545.2302,28.3131,20.7151,5.702,0.769,8.5759,-8.7062,557.7716,18.2434,22.6111,0.664,4.9655,85.3778,0.6387,0.0972
1,131.8,131.8,562.5198,121588.5,513,0,-0.0909,514.8208,-1.2241,0,0,0.0528,0.0522,0.0518,0,0,0,4.2221,0,0,100,0,0,0,0,0,0,0,0,0,0,555.1053,-159158.1,14.3658,8.1154,0,0,0,0,0,0,0,0,0,0,4.2993,-0.6346,-0.3158,-0.3158,550.8782,36.0574,47.699,-11.6416,0.9793,0.7559,7804.448,-0.6336,558.6392,43.8184,-5.8208,0,19.5111,41.8782,1.8208,0.0505,0,0,1514954,-514.8208,0,0,0,1.51E+08,0,0,52.3949,33.9899,549.7088,559.6024,576.2126,37.0559,-0.6346,8.6661,-7.3911,5.6634,602.3149,559.6024,523.6065,87.4941,44.7816,8.7857,1.2264,8.6661,-9.2521,561.8412,47.0205,78.7084,0.4573,9.9587,54.839,0.6404,0.1033
1,135.8,135.8,561.6113,121698,527,0,-0.0955,528.2133,-1.1903,0,0,0.0528,0.0522,0.0518,0,0,0,4.2285,0,0,100,0,0,0,0,0,0,0,0,0,0,558.0674,-159284.9,14.1367,2.4499,0,0,0,0,0,0,0,0,0,0,4.2883,-0.6171,-0.3071,-0.3071,549.3732,21.1599,33.398,-12.2381,0.9782,0.6336,7805.805,-0.6161,557.532,29.3187,-6.1191,0,36.2568,27.279,1.2133,0.0573,0,0,1514954,-528.2133,0,0,0,1.51E+08,0,0,52.4014,33.9959,545.0706,560.2169,568.1572,11.183,-0.6171,8.6632,-7.4045,5.5749,572.6859,560.2169,540.5419,44.4726,32.0036,12.3286,1.1908,8.6632,-9.2124,557.8149,29.6016,32.144,0.6121,3.6073,67.9541,0.6416,0.1026
1,139.8,139.8,561.8444,123930.9,533,0,-0.092,533.6925,-1.0953,0,0,0.0528,0.0522,0.0518,0,0,0,4.3953,0,0,100,0,0,0,0,0,0,0,0,0,0,556.2919,-161971.9,13.6285,3.8857,0,0,0,0,0,0,0,0,0,0,4.2958,-0.5678,-0.2827,-0.2827,550.0644,16.3719,28.1519,-11.78,0.979,0.5816,7809.632,-0.567,557.9177,24.2252,-5.89,0,34.8357,22.2619,0.6925,0.0423,0,0,1514954,-533.6925,0,0,0,1.51E+08,0,0,52.4563,34.069,547.4886,559.6581,572.1325,17.7034,-0.5678,8.7707,-7.5415,5.3847,581.38,559.6581,538.2411,47.6875,25.9656,4.5486,1.1083,8.7707,-9.2176,559.7597,26.0672,43.1389,0.4965,10.484,62.4194,0.6614,0.0995
1,143.8,143.8,561.7255,122637,512,0,-0.0946,514.5161,-1.4237,0,0,0.0528,0.0522,0.0518,0,0,0,3.893,0,0,100,0,0,0,0,0,0,0,0,0,0,556.3468,-160512.8,15.9649,7.1924,0,0,0,0,0,0,0,0,0,0,4.2849,-0.7381,-0.367,-0.367,549.5977,35.0816,47.2094,-12.1278,0.9784,0.7431,7796.43,-0.7367,557.6829,43.1668,-6.0639,0,27.2133,41.1455,2.5161,0.0717,0,0,1514954,-514.5161,0,0,0,1.51E+08,0,0,52.3891,34.0051,546.6825,559.6085,571.6746,32.873,-0.7381,8.7903,-7.4012,6.2878,594.3466,559.6085,524.0106,79.8305,45.0924,9.4945,1.4862,8.7903,-9.6255,559.3219,44.8058,70.336,0.5061,8.4081,55.4067,0.651,0.106
1,147.8,147.8,561.4858,124772.6,540,0,-0.0962,542.274,-1.1683,0,0,0.0528,0.0522,0.0518,0,0,0,4.2734,0,0,100,0,0,0,0,0,0,0,0,0,0,558.1772,-162997.1,13.2863,0.408,0,0,0,0,0,0,0,0,0,0,4.2871,-0.6057,-0.3015,-0.3015,549.1572,6.8832,19.2118,-12.3286,0.978,0.3583,7806.69,-0.6048,557.3763,15.1023,-6.1643,0,46.9991,13.0475,2.274,0.3304,0,0,1514954,-542.274,0,0,0,1.51E+08,0,0,52.4625,34.0873,544.6488,560.1827,567.6235,1.8591,-0.6057,8.8423,-7.5677,5.2488,567.7729,560.1827,544.4993,25.4989,17.9087,2.2253,1.0017,8.8423,-9.1751,557.4849,15.211,23.2736,0.6739,11.4586,85.4035,0.6689,0.0993
1,151.8,151.8,562.2897,124903.8,514,0,-0.0916,516.3292,-1.4622,0,0,0.0528,0.0522,0.0518,0,0,0,3.8314,0,0,100,0,0,0,0,0,0,0,0,0,0,554.4132,-163279.9,16.533,8.0704,0,0,0,0,0,0,0,0,0,0,4.2914,-0.758,-0.3769,-0.3769,550.5402,34.211,45.9605,-11.7495,0.9791,0.7444,7794.89,-0.7566,558.3732,42.044,-5.8748,0,21.8757,40.0858,2.3292,0.0681,0,0,1514954,-516.3292,0,0,0,1.51E+08,0,0,52.4272,34.0683,549.6852,559.1873,576.9059,36.8526,-0.758,8.939,-7.5096,6.5174,602.5811,559.1873,524.0099,86.2519,42.8581,7.6807,1.5788,8.939,-9.8464,561.9261,45.5969,78.5712,0.4477,11.2297,55.1351,0.6714,0.1051
1,155.8,155.8,561.6078,124997.4,529,0,-0.0977,530.3818,-1.4265,0,0,0.0528,0.0522,0.0518,0,0,0,3.8783,0,0,100,0,0,0,0,0,0,0,0,0,0,558.3254,-163325.9,16.2757,2.4269,0,0,0,0,0,0,0,0,0,0,4.2808,-0.7395,-0.3677,-0.3677,549.0795,18.6978,31.226,-12.5283,0.9777,0.5988,7796.321,-0.7381,557.4317,27.0499,-6.2642,0,37.4952,24.9619,1.3818,0.0739,0,0,1514954,-530.3818,0,0,0,1.51E+08,0,0,52.4327,34.0725,544.4265,560.3149,567.6992,11.0789,-0.7395,8.9313,-7.52,6.4179,572.1298,560.3149,539.9959,41.7481,29.9331,9.6141,1.5349,8.9313,-9.7944,557.4802,27.0984,32.134,0.6323,4.3424,68.2029,0.6718,0.1044
1,159.8,159.8,561.9633,127373,533,0,-0.0906,535.3846,-1.3378,0,0,0.0528,0.0522,0.0518,0,0,0,4.0186,0,0,100,0,0,0,0,0,0,0,0,0,0,556.3507,-166227.2,15.7239,3.8906,0,0,0,0,0,0,0,0,0,0,4.2926,-0.6936,-0.345,-0.345,550.3422,14.9576,26.5787,-11.6211,0.9793,0.5628,7799.875,-0.6924,558.0896,22.705,-5.8106,0,33.7273,20.7682,2.3846,0.1594,0,0,1514954,-535.3846,0,0,0,1.51E+08,0,0,52.49,34.15,547.9333,559.751,572.4143,17.7264,-0.6936,9.0513,-7.6639,6.2123,581.7158,559.751,538.6319,46.3312,24.3664,3.2473,1.4286,9.0513,-9.7861,560.0329,24.6483,43.0839,0.4902,14.2676,62.313,0.6938,0.1012
1,163.8,163.8,562.0341,125985.6,514,0,-0.0947,515.6531,-1.6708,0,0,0.0528,0.0522,0.0518,0,0,0,3.4586,0,0,100,0,0,0,0,0,0,0,0,0,0,556.1223,-164709.4,18.1576,7.2282,0,0,0,0,0,0,0,0,0,0,4.2816,-0.8662,-0.4303,-0.4303,549.8728,34.2197,46.381,-12.1613,0.9784,0.7378,7786.528,-0.8643,557.9803,42.3272,-6.0807,0,24.0301,40.3004,1.6531,0.0483,0,0,1514954,-515.6531,0,0,0,1.51E+08,0,0,52.4214,34.0843,547.3607,559.7048,573.0228,33.0395,-0.8662,9.0685,-7.5205,7.1508,595.6353,559.7048,524.7482,79.9822,44.0517,9.0952,1.8595,9.0685,-10.2462,560.0295,44.3764,70.887,0.4931,8.7939,55.612,0.6818,0.1076
1,167.8,167.8,561.1788,128242.7,543,0,-0.0961,544.7512,-1.4241,0,0,0.0528,0.0522,0.0518,0,0,0,3.8543,0,0,100,0,0,0,0,0,0,0,0,0,0,558.2215,-167255.1,15.0514,0.3894,0,0,0,0,0,0,0,0,0,0,4.2791,-0.7383,-0.3671,-0.3671,548.8549,4.1037,16.4276,-12.3239,0.978,0.2498,7796.414,-0.7369,557.0708,12.3196,-6.162,0,58.8576,10.2657,1.7512,0.4267,0,0,1514954,-544.7512,0,0,0,1.51E+08,0,0,52.4943,34.167,544.0927,560.0128,566.692,1.7746,-0.7383,9.1268,-7.6866,5.9453,566.8305,560.0128,543.9542,22.0793,15.2616,-0.797,1.2413,9.1268,-9.6662,556.9325,12.1813,22.8763,0.702,-27.703,85.5373,0.7019,0.101
1,171.8,171.8,562.1409,128461.4,515,0,-0.0915,517.0876,-1.7216,0,0,0.0528,0.0522,0.0518,0,0,0,3.418,0,0,100,0,0,0,0,0,0,0,0,0,0,554.4413,-167666,18.7683,8.1103,0,0,0,0,0,0,0,0,0,0,4.2845,-0.8925,-0.4433,-0.4433,550.3887,33.3011,45.0533,-11.7523,0.9791,0.7391,7784.499,-0.8905,558.2235,41.1359,-5.8762,0,23.5559,39.1772,2.0876,0.0627,0,0,1514954,-517.0876,0,0,0,1.51E+08,0,0,52.4607,34.1508,549.4377,559.105,576.5019,37.0389,-0.8925,9.2305,-7.6335,7.3978,602.4033,559.105,523.5363,85.3157,42.0174,6.4487,1.9599,9.2305,-10.4859,561.6816,44.5939,78.867,0.451,13.2299,55.0348,0.7045,0.1065
1,175.8,175.8,561.5029,128470.9,530,0,-0.0966,531.8011,-1.6852,0,0,0.0528,0.0522,0.0518,0,0,0,3.4298,0,0,100,0,0,0,0,0,0,0,0,0,0,558.0834,-167628.2,18.4916,2.4186,0,0,0,0,0,0,0,0,0,0,4.2752,-0.8737,-0.434,-0.434,549.0917,17.2906,29.7018,-12.4113,0.9779,0.5821,7785.949,-0.8718,557.3658,25.5647,-6.2057,0,40.5533,23.4962,1.8011,0.1042,0,0,1514954,-531.8011,0,0,0,1.51E+08,0,0,52.4649,34.153,544.6317,560.1545,567.8807,11.0426,-0.8737,9.2186,-7.6403,7.2906,572.2896,560.1545,540.2229,40.4885,28.3534,8.4218,1.9093,9.2186,-10.4233,557.5557,25.7546,32.0667,0.6216,4.8076,68.2353,0.7046,0.106
1,179.8,179.8,562.2585,130966.5,534,0,-0.0912,536.363,-1.6137,0,0,0.0528,0.0522,0.0519,0,0,0,3.5604,0,0,100,0,0,0,0,0,0,0,0,0,0,556.5992,-170689,17.8928,3.895,0,0,0,0,0,0,0,0,0,0,4.2881,-0.8366,-0.4157,-0.4157,550.5459,14.1829,25.8955,-11.7126,0.9792,0.5477,7788.814,-0.8349,558.3543,21.9913,-5.8563,0,30.1443,20.0392,2.363,0.1666,0,0,1514954,-536.363,0,0,0,1.51E+08,0,0,52.5223,34.2326,548.1427,560.0254,572.851,17.7503,-0.8366,9.3512,-7.7862,7.0677,582.1232,560.0254,538.8705,45.7603,23.6624,2.5075,1.7755,9.3512,-10.3983,560.3397,23.9767,43.2528,0.4891,18.2494,62.4189,0.7284,0.1029
1,183.8,183.8,562.1776,129498.8,515,0,-0.0937,516.4529,-1.9528,0,0,0.0528,0.0522,0.0518,0,0,0,3.0106,0,0,100,0,0,0,0,0,0,0,0,0,0,555.8652,-169029.7,20.4705,7.2023,0,0,0,0,0,0,0,0,0,0,4.2774,-1.0124,-0.5024,-0.5024,550.1296,33.6767,45.7247,-12.048,0.9786,0.7365,7775.258,-1.0099,558.1616,41.7087,-6.024,0,22.9378,39.7007,1.4529,0.0431,0,0,1514954,-516.4529,0,0,0,1.51E+08,0,0,52.4507,34.1631,547.999,559.6878,573.9699,32.9317,-1.0124,9.3637,-7.636,8.0591,596.3839,559.6878,525.5851,79.931,43.2349,9.1322,2.2669,9.3637,-10.9153,560.5523,44.0994,70.7988,0.4817,8.7527,55.76,0.7153,0.1093
1,187.8,187.8,561.2935,131802.1,545,0,-0.0952,546.6856,-1.7287,0,0,0.0528,0.0522,0.0518,0,0,0,3.3466,0,0,100,0,0,0,0,0,0,0,0,0,0,558.469,-171622.6,16.7805,0.3792,0,0,0,0,0,0,0,0,0,0,4.274,-0.8962,-0.4451,-0.4451,549.06,2.3744,14.6079,-12.2335,0.9782,0.1625,7784.213,-0.8942,557.2156,10.53,-6.1168,0,55.729,8.4912,1.6856,0.7099,0,0,1514954,-546.6856,0,0,0,1.51E+08,0,0,52.5214,34.2448,544.2731,560.1787,566.5858,1.7289,-0.8962,9.4295,-7.7982,6.6251,566.719,560.1787,544.1399,20.0334,13.4931,-2.5457,1.4713,9.4295,-10.1657,557.0125,10.3269,22.5791,0.7103,-7.8695,85.5955,0.7351,0.1029
1,191.8,191.8,562.5636,132188.1,516,0,-0.0913,517.9095,-2.024,0,0,0.0528,0.0522,0.0518,0,0,0,2.8951,0,0,100,0,0,0,0,0,0,0,0,0,0,554.6442,-172222.6,21.1558,8.1279,0,0,0,0,0,0,0,0,0,0,4.2812,-1.0493,-0.5206,-0.5206,550.8195,32.91,44.6541,-11.7441,0.9791,0.737,7772.419,-1.0466,558.6489,40.7394,-5.8721,0,20.3058,38.7821,1.9095,0.058,0,0,1514954,-517.9095,0,0,0,1.51E+08,0,0,52.4908,34.2331,550.0707,559.4375,577.4124,37.1335,-1.0493,9.5428,-7.7532,8.3357,603.3116,559.4375,524.1715,85.4021,41.528,6.262,2.3794,9.5428,-11.1819,562.3068,44.3974,79.1401,0.4456,13.6382,55.1057,0.7403,0.1083
1,195.8,195.8,561.2544,132086.8,532,0,-0.0975,532.9733,-1.9875,0,0,0.0528,0.0522,0.0518,0,0,0,2.9222,0,0,100,0,0,0,0,0,0,0,0,0,0,558.1923,-172103.8,20.8794,2.4372,0,0,0,0,0,0,0,0,0,0,4.2656,-1.0304,-0.5113,-0.5113,548.7098,15.7365,28.2811,-12.5446,0.9776,0.5564,7773.873,-1.0278,557.0728,24.0995,-6.2723,0,48.0476,22.0088,0.9733,0.0618,0,0,1514954,-532.9733,0,0,0,1.51E+08,0,0,52.4939,34.2335,543.9234,560.0457,566.995,11.1321,-1.0304,9.5266,-7.757,8.2287,571.4904,560.0457,539.428,38.5171,27.0724,6.4547,2.327,9.5266,-11.1144,556.988,24.0147,32.0624,0.643,5.9673,68.0101,0.7392,0.1078
1,199.8,199.8,561.7193,134777.9,535,0,-0.0918,537.7904,-1.9485,0,0,0.0528,0.0522,0.0518,0,0,0,3.0168,0,0,100,0,0,0,0,0,0,0,0,0,0,556.973,-175318.2,20.2292,3.8615,0,0,0,0,0,0,0,0,0,0,4.2758,-1.0102,-0.5013,-0.5013,549.9119,12.1215,23.9289,-11.8074,0.979,0.5066,7775.428,-1.0077,557.7835,19.9931,-5.9037,0,39.1367,18.0252,2.7904,0.2302,0,0,1514954,-537.7904,0,0,0,1.51E+08,0,0,52.5491,34.3135,546.7997,559.8444,570.6503,17.6083,-1.0102,9.6756,-7.9005,7.9858,579.9915,559.8444,537.4584,42.2011,22.054,-0.332,2.1594,9.6756,-11.0702,559.0981,21.3077,42.5331,0.5263,-127.1117,62.054,0.7648,0.1049
1,203.8,203.8,562.0361,133317.6,515,0,-0.0915,517.0159,-2.2881,0,0,0.0528,0.0522,0.0518,0,0,0,2.4562,0,0,100,0,0,0,0,0,0,0,0,0,0,556.0102,-173703.5,23.0085,7.2249,0,0,0,0,0,0,0,0,0,0,4.271,-1.1862,-0.5879,-0.5879,550.2516,33.2357,45.0201,-11.7845,0.979,0.7382,7761.903,-1.1827,558.1079,41.092,-5.8923,0,24.6065,39.1279,2.0159,0.0607,0,0,1514954,-517.0159,0,0,0,1.51E+08,0,0,52.4783,34.2452,548.0859,559.6566,573.3538,33.0541,-1.1862,9.6906,-7.7528,9.053,596.1061,559.6566,525.3336,79.0902,42.6407,8.3177,2.7248,9.6906,-11.6638,560.3654,43.3495,70.7725,0.485,9.5087,55.459,0.7516,0.1112
1,207.8,207.8,561.2332,135618.8,547,0,-0.0953,548.6859,-2.1079,0,0,0.0528,0.0522,0.0518,0,0,0,2.7298,0,0,100,0,0,0,0,0,0,0,0,0,0,558.3569,-176322.7,18.4871,0.392,0,0,0,0,0,0,0,0,0,0,4.265,-1.0928,-0.542,-0.542,548.9714,0.2855,12.5473,-12.2618,0.9782,0.0228,7769.075,-1.0899,557.1459,8.46,-6.1309,0,59.351,6.4164,1.6859,5.9051,0,0,1514954,-548.6859,0,0,0,1.51E+08,0,0,52.5433,34.3234,544.2077,560.0967,566.6518,1.7889,-1.0928,9.7701,-7.9049,7.2923,566.7935,560.0967,544.066,18.1076,11.4108,-4.6199,1.681,9.7701,-10.6787,556.9854,8.2995,22.7275,0.7053,-3.9195,85.4714,0.7724,0.1053
1,211.8,211.8,562.472,136085.2,516,0,-0.0908,518.2346,-2.4049,0,0,0.0528,0.0522,0.0518,0,0,0,2.2893,0,0,100,0,0,0,0,0,0,0,0,0,0,554.4374,-177028.9,23.8653,8.1162,0,0,0,0,0,0,0,0,0,0,4.2724,-1.2468,-0.6176,-0.6176,550.7617,32.5271,44.2374,-11.7103,0.9792,0.7353,7757.257,-1.2429,558.5685,40.3339,-5.8552,0,21.1096,38.3823,2.2346,0.0687,0,0,1514954,-518.2346,0,0,0,1.51E+08,0,0,52.5143,34.3141,550.1691,559.2968,577.6202,37.1124,-1.2468,9.8889,-7.8642,9.3951,603.4639,559.2968,524.3254,85.2293,41.0622,6.0908,2.8662,9.8889,-11.9772,562.3621,44.1274,79.1385,0.4419,13.9931,55.1481,0.7779,0.1107
1,215.8,215.8,561.3975,135996.3,533,0,-0.0961,534.0842,-2.3659,0,0,0.0528,0.0522,0.0518,0,0,0,2.3176,0,0,100,0,0,0,0,0,0,0,0,0,0,558.1705,-176885.1,23.591,2.42,0,0,0,0,0,0,0,0,0,0,4.2597,-1.2266,-0.6077,-0.6077,549.0149,14.9307,27.3133,-12.3826,0.9779,0.5466,7758.806,-1.2229,557.27,23.1858,-6.1913,0,44.5412,21.122,1.0842,0.0726,0,0,1514954,-534.0842,0,0,0,1.51E+08,0,0,52.5173,34.3141,544.4484,560.1223,567.4807,11.0631,-1.2266,9.8708,-7.8674,9.2893,571.9338,560.1223,539.9954,37.8496,26.0381,5.9112,2.8131,9.8708,-11.9071,557.3505,23.2663,31.9384,0.6302,6.403,68.0747,0.7768,0.1102
1,219.8,219.8,561.9327,138810.4,536,0,-0.0926,538.7423,-2.3864,0,0,0.0528,0.0522,0.0518,0,0,0,2.3158,0,0,100,0,0,0,0,0,0,0,0,0,0,556.7466,-180263.8,22.908,3.8792,0,0,0,0,0,0,0,0,0,0,4.2669,-1.2372,-0.6129,-0.6129,550.0005,11.2582,23.1904,-11.9322,0.9788,0.4855,7757.993,-1.2334,557.9553,19.213,-5.9661,0,35.742,17.2243,2.7423,0.2436,0,0,1514954,-538.7423,0,0,0,1.51E+08,0,0,52.5669,34.3924,547.1639,559.8815,571.7466,17.7113,-1.2372,10.0443,-8.0029,9.0319,581.0137,559.8815,537.8967,42.2714,21.1392,-0.8456,2.6071,10.0443,-11.8472,559.5973,20.855,43.117,0.5099,-49.9898,62.38,0.8042,0.1079
1,223.8,223.8,561.8554,137383.1,516,0,-0.0928,517.6613,-2.726,0,0,0.0528,0.0522,0.0518,0,0,0,1.7178,0,0,100,0,0,0,0,0,0,0,0,0,0,556.0995,-178633.3,25.9718,7.2272,0,0,0,0,0,0,0,0,0,0,4.2585,-1.4132,-0.6992,-0.6992,549.872,32.2107,44.1941,-11.9834,0.9787,0.7288,7744.529,-1.4083,557.8609,40.1996,-5.9917,0,27.0281,38.2024,1.6613,0.0516,0,0,1514954,-517.6613,0,0,0,1.51E+08,0,0,52.496,34.3239,547.4307,559.5798,572.7273,33.1063,-1.4132,10.0588,-7.8552,10.2061,595.5192,559.5798,524.6388,77.8579,41.9185,6.9775,3.2688,10.0588,-12.5372,559.9126,42.2513,70.8804,0.493,11.1584,55.4547,0.7904,0.1143
1,227.8,227.8,561.1812,139698.8,549,0,-0.0938,550.4166,-2.6031,0,0,0.0528,0.0522,0.0518,0,0,0,1.9404,0,0,100,0,0,0,0,0,0,0,0,0,0,558.7137,-181306.8,20.457,0.4736,0,0,0,0,0,0,0,0,0,0,4.255,-1.3495,-0.668,-0.668,549.075,-1.3416,10.7646,-12.1062,0.9784,-0.1246,7749.397,-1.345,557.1458,6.7292,-6.0531,0,62.7241,4.7115,1.4166,-1.0559,0,0,1514954,-550.4166,0,0,0,1.51E+08,0,0,52.554,34.3981,544.1179,560.2051,565.8563,2.1649,-1.3495,10.157,-7.9953,8.0557,566.0698,560.2051,543.9044,15.6532,9.7885,-6.5122,1.9222,10.157,-11.267,556.7264,6.3098,22.1654,0.7354,-2.4037,84.3677,0.8122,0.1089
1,231.8,231.8,562.7321,140275.8,516,0,-0.0912,518.9061,-2.9116,0,0,0.0528,0.0522,0.0518,0,0,0,1.4214,0,0,100,0,0,0,0,0,0,0,0,0,0,554.2197,-182169.2,27.0712,8.1079,0,0,0,0,0,0,0,0,0,0,4.2628,-1.5095,-0.7463,-0.7463,550.95,32.0439,43.826,-11.7821,0.9791,0.7312,7737.182,-1.5039,558.8047,39.8986,-5.8911,0,19.4917,37.935,2.9061,0.0907,0,0,1514954,-518.9061,0,0,0,1.51E+08,0,0,52.5259,34.3913,550.7022,559.364,578.8754,37.1375,-1.5095,10.2864,-7.9584,10.639,604.5082,559.364,525.0695,85.6021,40.4579,6.1634,3.4509,10.2864,-12.9188,562.9805,44.0745,79.4387,0.4317,13.8888,55.3861,0.8185,0.1145
1,235.8,235.8,561.5066,140169.5,534,0,-0.096,535.3436,-2.8685,0,0,0.0528,0.0522,0.0518,0,0,0,1.4918,0,0,100,0,0,0,0,0,0,0,0,0,0,558.1464,-182037.6,26.8008,2.4384,0,0,0,0,0,0,0,0,0,0,4.2494,-1.4871,-0.7354,-0.7354,549.0968,13.7532,26.163,-12.4098,0.9779,0.5257,7738.89,-1.4817,557.37,22.0264,-6.2049,0,42.4889,19.9581,1.3436,0.0977,0,0,1514954,-535.3436,0,0,0,1.51E+08,0,0,52.5296,34.392,544.6449,560.1771,567.878,11.1659,-1.4871,10.2682,-7.963,10.5356,572.3743,560.1771,540.1487,37.0307,24.8335,4.8051,3.398,10.2682,-12.8481,557.5667,22.2231,32.2256,0.6215,7.7065,68.0666,0.8181,0.114
1,239.8,239.8,561.6497,143057.2,537,0,-0.0922,539.4344,-2.9827,0,0,0.0528,0.0522,0.0518,0,0,0,1.3259,0,0,100,0,0,0,0,0,0,0,0,0,0,556.7961,-185530.3,26.1296,3.9185,0,0,0,0,0,0,0,0,0,0,4.2518,-1.5463,-0.7643,-0.7643,549.7274,10.293,22.2153,-11.9223,0.9788,0.4633,7734.378,-1.5404,557.6756,18.2412,-5.9612,0,41.4393,16.2542,2.4344,0.2365,0,0,1514954,-539.4344,0,0,0,1.51E+08,0,0,52.5683,34.4644,546.6824,559.7277,570.8896,17.9326,-1.5463,10.4735,-8.0805,10.278,580.4211,559.7277,537.1509,40.9867,20.2933,-2.2835,3.1548,10.4735,-12.7816,559.0999,19.6655,43.2702,0.5218,-17.9491,62.0087,0.8467,0.1128
1,243.8,243.8,561.911,141630.5,516,0,-0.0936,517.6973,-3.3102,0,0,0.0528,0.0522,0.0518,0,0,0,0.7405,0,0,100,0,0,0,0,0,0,0,0,0,0,556.0356,-183999.4,29.5515,7.2131,0,0,0,0,0,0,0,0,0,0,4.2452,-1.7161,-0.8472,-0.8472,549.7919,32.0945,44.2137,-12.1191,0.9784,0.7259,7721.467,-1.7089,557.8713,40.174,-6.0596,0,26.3483,38.1541,1.6973,0.0529,0,0,1514954,-517.6973,0,0,0,1.51E+08,0,0,52.5008,34.3996,547.3902,559.5852,573.0767,33.1143,-1.7161,10.4899,-7.9406,11.5874,595.7512,559.5852,524.7158,78.0539,41.8879,7.0185,3.9364,10.4899,-13.5931,560.0174,42.3201,71.0354,0.4909,11.1212,55.5993,0.8332,0.1193
1,247.8,247.8,561.3901,144101.6,550,0,-0.0914,551.9563,-3.2566,0,0,0.0528,0.0522,0.0518,0,0,0,0.8562,0,0,100,0,0,0,0,0,0,0,0,0,0,558.7267,-186744.2,22.8517,0.4557,0,0,0,0,0,0,0,0,0,0,4.2445,-1.6883,-0.8336,-0.8336,549.551,-2.4053,9.4338,-11.8391,0.9789,-0.255,7723.578,-1.6813,557.4437,5.4874,-5.9196,0,55.6616,3.5143,1.9563,-0.8133,0,0,1514954,-551.9563,0,0,0,1.51E+08,0,0,52.5503,34.4689,544.9107,560.3351,566.4673,2.0888,-1.6883,10.6109,-8.0663,8.9744,566.6678,560.3351,544.7101,14.7115,8.3788,-7.2462,2.2248,10.6109,-11.9794,557.2377,5.2814,21.9577,0.7116,-2.0302,84.5161,0.8563,0.1144
1,251.8,251.8,562.2538,144823.4,517,0,-0.0929,518.9078,-3.5951,0,0,0.0528,0.0522,0.0518,0,0,0,0.3182,0,0,100,0,0,0,0,0,0,0,0,0,0,554.524,-187818.4,30.9745,8.0991,0,0,0,0,0,0,0,0,0,0,4.2422,-1.8638,-0.9191,-0.9191,550.2011,31.2933,43.346,-12.0527,0.9786,0.7219,7710.271,-1.8553,558.2363,39.3286,-6.0264,0,23.2208,37.3197,1.9078,0.061,0,0,1514954,-518.9078,0,0,0,1.51E+08,0,0,52.5217,34.4645,549.2728,559.1912,577.0071,37.2025,-1.8638,10.7591,-8.0314,12.1385,602.8429,559.1912,523.437,83.9351,40.2835,4.5292,4.1728,10.7591,-14.068,561.8237,42.9159,79.4059,0.4503,18.532,55.2214,0.8639,0.1207
1,255.8,255.8,561.2626,144776.3,535,0,-0.0972,536.1712,-3.5462,0,0,0.0528,0.0522,0.0518,0,0,0,0.3541,0,0,100,0,0,0,0,0,0,0,0,0,0,558.0713,-187715.2,30.7144,2.4418,0,0,0,0,0,0,0,0,0,0,4.2314,-1.8385,-0.9068,-0.9068,548.6641,12.4929,25.0914,-12.5985,0.9776,0.4979,7712.187,-1.8302,557.063,20.8918,-6.2993,0,49.9059,18.7922,1.1712,0.0937,0,0,1514954,-536.1712,0,0,0,1.51E+08,0,0,52.5266,34.4664,543.9826,559.9982,567.3528,11.2125,-1.8385,10.7407,-8.0386,12.0406,571.8622,559.9982,539.4733,35.691,23.827,3.3021,4.1223,10.7407,-13.9994,557.1113,20.94,32.3889,0.6337,10.8086,68.0912,0.8636,0.12
1,259.8,259.8,561.9579,147727.5,537,0,-0.0925,540.168,-3.784,0,0,0.0528,0.0522,0.0518,0,0,0,-0.0281,0,0,100,0,0,0,0,0,0,0,0,0,0,556.9683,-191322.6,30.0265,3.8941,0,0,0,0,0,0,0,0,0,0,4.2362,-1.9617,-0.9667,-0.9667,549.951,9.783,21.7899,-12.0069,0.9786,0.449,7702.868,-1.9523,557.9556,17.7876,-6.0035,0,35.98,15.7865,3.168,0.3238,0,0,1514954,-540.168,0,0,0,1.51E+08,0,0,52.5505,34.5302,546.9858,559.9794,571.5188,17.8865,-1.9617,10.986,-8.1312,11.7675,580.9409,559.9794,537.5637,40.7729,19.8113,-2.6043,3.8278,10.986,-13.9207,559.4947,19.3266,43.3772,0.5168,-15.656,62.2211,0.8931,0.1204
1,263.8,263.8,561.9503,146399.8,516,0,-0.0948,517.8033,-4.1031,0,0,0.0528,0.0522,0.0518,0,0,0,-0.5783,0,0,100,0,0,0,0,0,0,0,0,0,0,556.0582,-189875.6,33.8775,7.2204,0,0,0,0,0,0,0,0,0,0,4.2268,-2.1272,-1.0469,-1.0469,549.6214,31.8181,44.147,-12.3289,0.9781,0.7207,7690.385,-2.1161,557.8406,40.0373,-6.1645,0,25.9252,37.9826,1.8033,0.0567,0,0,1514954,-517.8033,0,0,0,1.51E+08,0,0,52.4856,34.4683,547.1575,559.6147,573.2223,33.2661,-2.1272,11.0044,-7.9972,13.2363,595.9177,559.6147,524.462,78.1144,41.8114,6.6587,4.7467,11.0044,-14.8711,559.9981,42.1948,71.4557,0.492,11.7312,55.6967,0.88,0.1274
1,267.8,267.8,561.3959,148853.7,551,0,-0.0905,552.9706,-4.1119,0,0,0.0528,0.0522,0.0518,0,0,0,-0.5507,0,0,100,0,0,0,0,0,0,0,0,0,0,558.6829,-192656.6,25.8394,0.5062,0,0,0,0,0,0,0,0,0,0,4.2267,-2.1317,-1.0491,-1.0491,549.6326,-3.338,8.4253,-11.7632,0.979,-0.3962,7690.046,-2.1205,557.4748,4.5042,-5.8816,0,56.0826,2.5437,1.9706,-0.5904,0,0,1514954,-552.9706,0,0,0,1.51E+08,0,0,52.5272,34.5326,545.0728,560.3198,566.6022,2.3296,-2.1317,11.1445,-8.1091,10.1069,566.8514,560.3198,544.8237,13.8808,7.3492,-8.1469,2.626,11.1445,-12.8668,557.3316,4.361,22.0277,0.7035,-1.7038,83.8944,0.9037,0.1231
1,271.8,271.8,562.4872,149642.8,516,0,-0.0914,518.3632,-4.5052,0,0,0.0528,0.0522,0.0518,0,0,0,-1.2346,0,0,100,0,0,0,0,0,0,0,0,0,0,554.5307,-193813.2,35.6517,8.1171,0,0,0,0,0,0,0,0,0,0,4.2255,-2.3356,-1.1477,-1.1477,550.5736,32.2104,44.124,-11.9136,0.9788,0.73,7674.724,-2.3222,558.516,40.1528,-5.9568,0,21.0393,38.1672,2.3632,0.0734,0,0,1514954,-518.3632,0,0,0,1.51E+08,0,0,52.4926,34.5252,549.945,559.3303,577.7759,37.4499,-2.3356,11.3127,-8.0648,13.91,603.8121,559.3303,523.9088,85.4489,40.9671,5.5456,5.0443,11.3127,-15.4447,562.3504,43.9872,79.9033,0.4433,15.4084,55.1919,0.9123,0.1308
1,275.8,275.8,561.24,149648.2,536,0,-0.0961,537.0819,-4.4482,0,0,0.0528,0.0522,0.0518,0,0,0,-1.1789,0,0,100,0,0,0,0,0,0,0,0,0,0,558.3177,-193732.5,35.3969,2.4456,0,0,0,0,0,0,0,0,0,0,4.2125,-2.3061,-1.1335,-1.1335,548.7215,11.6396,24.1581,-12.5185,0.9777,0.4818,7676.937,-2.2931,557.0671,19.9852,-6.2593,0,51.2763,17.8989,1.0819,0.0929,0,0,1514954,-537.0819,0,0,0,1.51E+08,0,0,52.4989,34.5283,543.9083,560.0805,566.8548,11.2788,-2.3061,11.2929,-8.0747,13.8161,571.4703,560.0805,539.2929,34.3884,22.9986,2.211,4.9959,11.2929,-15.3767,556.9479,19.866,32.1774,0.646,15.5533,67.7448,0.9121,0.1299
1,279.8,279.8,561.8378,152643.7,538,0,-0.0923,540.8629,-4.8132,0,0,0.0528,0.0522,0.0518,0,0,0,-1.7329,0,0,100,0,0,0,0,0,0,0,0,0,0,556.9712,-197422.6,34.6554,3.8478,0,0,0,0,0,0,0,0,0,0,4.2129,-2.4953,-1.2248,-1.2248,549.7884,8.9255,20.9749,-12.0494,0.9786,0.4255,7662.766,-2.4801,557.8214,16.9585,-6.0247,0,38.3854,14.9502,2.8629,0.3208,0,0,1514954,-540.8629,0,0,0,1.51E+08,0,0,52.5071,34.5825,546.7455,559.9053,571.2272,17.7673,-2.4953,11.5785,-8.1406,13.5102,580.5621,559.9053,537.4105,39.6992,19.0424,-3.4524,4.6435,11.5785,-15.2794,559.2926,18.4297,43.1516,0.5213,-11.499,62.2825,0.9426,0.1326
1,283.8,283.8,561.9744,151364.9,517,0,-0.0931,517.9323,-5.1237,0,0,0.0528,0.0522,0.0518,0,0,0,-2.2438,0,0,100,0,0,0,0,0,0,0,0,0,0,555.8366,-196033.2,38.9894,7.2246,0,0,0,0,0,0,0,0,0,0,4.2064,-2.6563,-1.3023,-1.3023,549.8024,31.8701,44.0421,-12.172,0.9783,0.7236,7650.748,-2.6391,557.9171,39.9848,-6.086,0,25.7019,37.9561,0.9323,0.0293,0,0,1514954,-517.9323,0,0,0,1.51E+08,0,0,52.4446,34.523,547.6543,559.538,573.7979,33.4578,-2.6563,11.5972,-8.0117,15.1552,596.6468,559.538,524.8054,78.7145,41.6057,6.8731,5.7118,11.5972,-16.3798,560.3301,42.3978,71.8414,0.4835,11.4526,55.6702,0.9292,0.1405
1,287.8,287.8,561.3337,153867.5,552,0,-0.0894,554.0868,-5.1797,0,0,0.0528,0.0522,0.0518,0,0,0,-2.3226,0,0,100,0,0,0,0,0,0,0,0,0,0,558.6965,-198879,29.4685,0.5864,0,0,0,0,0,0,0,0,0,0,4.204,-2.6853,-1.3162,-1.3162,549.644,-4.4428,7.2469,-11.6897,0.9792,-0.6131,7648.587,-2.6677,557.4371,3.3503,-5.8449,0,58.9956,1.4021,2.0868,-0.4697,0,0,1514954,-554.0868,0,0,0,1.51E+08,0,0,52.4808,34.5843,545.0949,560.2861,566.4299,2.7136,-2.6853,11.7537,-8.1147,11.4632,566.7696,560.2861,544.7552,12.6828,6.1993,-9.3316,3.1482,11.7537,-13.9482,557.2703,3.1835,22.0144,0.7055,-1.3591,82.8639,0.9537,0.1366
1,291.8,291.8,562.4155,154799.4,519,0,-0.0916,518.7724,-5.6408,0,0,0.0528,0.0522,0.0518,0,0,0,-3.0733,0,0,100,0,0,0,0,0,0,0,0,0,0,554.5922,-200212.3,41.0987,8.1162,0,0,0,0,0,0,0,0,0,0,4.2001,-2.9244,-1.4309,-1.4309,550.4127,31.6403,43.6431,-12.0028,0.9787,0.725,7630.819,-2.9035,558.4146,39.6422,-6.0014,0,21.7592,37.6417,-0.2276,-0.0072,0,0,1514954,-518.7724,0,0,0,1.51E+08,0,0,52.4401,34.575,549.6754,559.307,577.5562,37.6685,-2.9244,11.9501,-8.0619,15.9405,603.7811,559.307,523.4506,85.0087,40.5346,4.6782,6.0675,11.9501,-17.0538,562.1796,43.4072,80.3305,0.4464,18.1712,55.1543,0.9638,0.1468
1,295.8,295.8,561.473,154810.3,537,0,-0.0965,537.8237,-5.5753,0,0,0.0528,0.0522,0.0518,0,0,0,-2.9894,0,0,100,0,0,0,0,0,0,0,0,0,0,558.2548,-200214.8,40.8483,2.4499,0,0,0,0,0,0,0,0,0,0,4.1894,-2.8904,-1.4146,-1.4146,548.8292,11.0055,23.6493,-12.6438,0.9775,0.4654,7633.341,-2.87,557.2584,19.4347,-6.3219,0,44.7602,17.3274,0.8237,0.0748,0,0,1514954,-537.8237,0,0,0,1.51E+08,0,0,52.4489,34.5808,544.1949,560.1943,567.7012,11.3646,-2.8904,11.9313,-8.0774,15.8513,572.297,560.1943,539.599,34.4733,22.3705,1.7753,6.0208,11.9313,-16.9886,557.3634,19.5397,32.698,0.6299,19.4183,67.9814,0.9635,0.1453
1,299.8,299.8,561.92,157909,538,0,-0.0921,541.4095,-6.0538,0,0,0.0528,0.0522,0.0518,0,0,0,-3.7502,0,0,100,0,0,0,0,0,0,0,0,0,0,557.4237,-204019.6,40.008,3.7562,0,0,0,0,0,0,0,0,0,0,4.1869,-3.1385,-1.5333,-1.5333,549.8243,8.4148,20.5105,-12.0957,0.9785,0.4103,7614.979,-3.1145,557.8881,16.4786,-6.0479,0,37.1823,14.4627,3.4095,0.4052,0,0,1514954,-541.4095,0,0,0,1.51E+08,0,0,52.4438,34.6272,546.4975,560.1319,570.6586,17.4597,-3.1385,12.2549,-8.121,15.4937,579.8097,560.1319,537.3464,38.4002,18.7224,-4.0631,5.6056,12.2549,-16.8651,559.096,17.6865,42.4633,0.5366,-9.451,62.3399,0.9954,0.1512
1,303.8,303.8,561.7369,156694.2,517,0,-0.0948,518.1181,-6.3616,0,0,0.0528,0.0522,0.0518,0,0,0,-4.2674,0,0,100,0,0,0,0,0,0,0,0,0,0,556.1523,-202732.9,44.8616,7.2452,0,0,0,0,0,0,0,0,0,0,4.1762,-3.298,-1.6093,-1.6093,549.2672,31.1491,43.6188,-12.4697,0.9778,0.7141,7603.221,-3.2715,557.5803,39.4622,-6.2349,0,28.8733,37.384,1.1181,0.0359,0,0,1514954,-518.1181,0,0,0,1.51E+08,0,0,52.3837,34.5707,546.5641,559.5165,572.5753,33.7736,-3.298,12.2776,-7.9978,17.3239,595.7609,559.5165,523.3785,77.6428,41.3984,5.2604,6.8253,12.2776,-18.1211,559.5519,41.4339,72.3824,0.4993,14.7599,55.5304,0.9818,0.161
1,307.8,307.8,561.2094,159213.8,553,0,-0.0869,555.1703,-6.45,0,0,0.0528,0.0522,0.0518,0,0,0,-4.3459,0,0,100,0,0,0,0,0,0,0,0,0,0,559.04,-205612.8,33.7946,0.6344,0,0,0,0,0,0,0,0,0,0,4.1782,-3.3439,-1.6312,-1.6312,549.7744,-5.3959,6.0391,-11.435,0.9796,-0.8935,7599.844,-3.3167,557.3978,2.2275,-5.7175,0,64.7738,0.3216,2.1703,-0.4022,0,0,1514954,-555.1703,0,0,0,1.51E+08,0,0,52.4159,34.6295,545.0234,560.3463,565.4332,2.9557,-3.3439,12.4455,-8.0939,13.0572,565.8526,560.3463,544.6039,10.6823,5.176,-10.5664,3.8145,12.4455,-15.2523,556.9343,1.764,21.2487,0.7409,-1.011,81.9236,1.0077,0.1573
1,311.8,311.8,562.5784,160292.4,516,0,-0.0913,518.5446,-6.9807,0,0,0.0528,0.0522,0.0518,0,0,0,-5.2524,0,0,100,0,0,0,0,0,0,0,0,0,0,554.3975,-207090,47.2915,8.1111,0,0,0,0,0,0,0,0,0,0,4.1729,-3.619,-1.7618,-1.7618,550.5387,31.9941,44.0338,-12.0397,0.9786,0.7266,7579.667,-3.5872,558.5652,40.0206,-6.0199,0,20.424,38.014,2.5446,0.0795,0,0,1514954,-518.5446,0,0,0,1.51E+08,0,0,52.3688,34.6175,550.1066,559.3228,578.5324,37.9176,-3.619,12.6678,-8.0315,18.2104,604.8134,559.3228,523.8257,86.2688,40.7782,5.2811,7.2391,12.6678,-18.8896,562.654,44.1094,80.9877,0.4383,16.3354,55.2739,1.0173,0.1718
1,315.8,315.8,561.2692,160342.2,539,0,-0.098,538.8863,-6.9096,0,0,0.0528,0.0522,0.0518,0,0,0,-5.1721,0,0,100,0,0,0,0,0,0,0,0,0,0,558.0794,-207126.5,47.0516,2.461,0,0,0,0,0,0,0,0,0,0,4.1577,-3.5821,-1.7443,-1.7443,548.338,9.4517,22.3829,-12.9312,0.977,0.4223,7582.367,-3.5509,556.9588,18.0725,-6.4656,0,51.4777,15.9173,-0.1137,-0.012,0,0,1514954,-538.8863,0,0,0,1.51E+08,0,0,52.3787,34.6245,543.5501,559.9998,567.4901,11.4983,-3.5821,12.6494,-8.0494,18.128,572.1181,559.9998,538.9222,33.2318,21.1135,0.0359,7.1958,12.6494,-18.8273,557.0134,18.1271,33.1959,0.6349,925.6769,68.0757,1.0179,0.1696
1,319.8,319.8,561.7975,163522.6,538,0,-0.0913,542.179,-7.4881,0,0,0.0528,0.0522,0.0518,0,0,0,-6.081,0,0,100,0,0,0,0,0,0,0,0,0,0,557.4199,-210993.9,46.1259,3.7581,0,0,0,0,0,0,0,0,0,0,4.1562,-3.8821,-1.8863,-1.8863,549.7277,7.5487,19.6185,-12.0698,0.9785,0.3848,7560.47,-3.8456,557.7742,15.5952,-6.0349,0,39.7866,13.5836,4.179,0.5536,0,0,1514954,-542.179,0,0,0,1.51E+08,0,0,52.3617,34.6632,546.3438,560.0538,570.371,17.6067,-3.8821,13.0039,-8.0723,17.7228,579.6722,560.0538,537.0426,37.4932,17.8748,-5.1364,6.7286,13.0039,-18.683,558.9229,16.7439,42.6296,0.5398,-7.2995,62.1534,1.0495,0.1807
1,323.8,323.8,562.1111,162427.5,515,0,-0.0941,518.4999,-7.8005,0,0,0.0528,0.0522,0.0518,0,0,0,-6.5907,0,0,100,0,0,0,0,0,0,0,0,0,0,556.0742,-209820.1,51.4666,7.2075,0,0,0,0,0,0,0,0,0,0,4.1491,-4.044,-1.9627,-1.9627,549.6439,31.144,43.6112,-12.4672,0.9778,0.7141,7548.706,-4.0045,557.9554,39.4555,-6.2336,0,24.453,37.3776,3.4999,0.1124,0,0,1514954,-518.4999,0,0,0,1.51E+08,0,0,52.3032,34.6094,547.3356,559.7072,573.9193,33.8625,-4.044,13.034,-7.9535,19.7191,597.0052,559.7072,524.2496,78.5053,41.2073,5.7497,8.0811,13.034,-20.0786,560.3206,41.8208,72.7556,0.4874,13.6538,55.7156,1.0365,0.1944
1,327.8,327.8,561.5364,165002.3,553,0,-0.0867,555.808,-7.9109,0,0,0.0528,0.0522,0.0518,0,0,0,-6.7504,0,0,100,0,0,0,0,0,0,0,0,0,0,558.6667,-212777.7,38.6707,0.7546,0,0,0,0,0,0,0,0,0,0,4.1498,-4.1012,-1.9896,-1.9896,550.0389,-5.7691,5.7284,-11.4975,0.9795,-1.0071,7544.558,-4.0605,557.7039,1.8959,-5.7488,0,53.255,-0.0203,2.808,-0.4867,0,0,1514954,-555.808,0,0,0,1.51E+08,0,0,52.3335,34.6675,545.8245,560.3929,567.1678,3.5439,-4.1012,13.2118,-8.047,14.8223,567.7408,560.3929,545.2515,11.9328,4.5849,-10.5565,4.5909,13.2118,-16.7391,557.7951,1.9871,22.4893,0.6733,-1.1304,80.8147,1.0636,0.1905