File: datas/d100-90-0.15_1.csv
Stage Number,Time since start of test (s),Time since start of stage (s),Radial Pressure (kPa),Radial Volume (mm3),Back Pressure (kPa),Back Volume (mm3),Load Cell (kN),Pore Pressure (kPa),Axial Displacement (mm),L/C Pressure (kPa),L/C Volume (mm3),Local Axial 1,Local Axial 2,Local Radial,Base Pressure (kPa),Base Volume (mm3),Back Differential Pressure (kPa),Axial Displacement 2 (mm),Pore Air Pressure (kPa),Pore Air Volume (mm3),Atmospheric Pressure (kPa),Temperature (°C),Mid Plane PWP (kPa),Back to Cell Differential (kPa),Total Volume Change (mm3),Undefined Tx 1,Undefined Tx 2,Undefined Tx 3,Undefined Tx. 4,HCA secondary control axial load (kN),HCA secondary control torque,Internal Cell Pr. (kPa),Internal Cell Vol. (mm3),Rotational Displ. (mm),Torque,Local Int Defmn 1 (mm),Local Int Defmn 2 (mm),Circumf. Defmn 1 (mm),Circumf. Defmn 2 (mm),Circumf. Defmn 3 (mm),Outer Cell Pr 2 (kPa),Internal cell Pr 2 (kPa),Rotation 2 (°),Secondary Cell Pr (kPa),Secondary Back Pr (kPa),Axial Force (kN),Axial Strain (%),Av Diameter Change (mm),Radial Strain (%),Axial Stress (kPa),Eff. Axial Stress (kPa),Eff. Radial Stress (kPa),Deviator Stress (kPa),Total Stress Ratio (%),Eff. Stress Ratio (%),Current Area (mm2),Shear Strain (%),Cambridge p (kPa),Eff. Cambridge p' (kPa),Max Shear Stress t,Volume Change (mm3),B Value,Mean Stress s/Eff. Axial Stress 2,Excess PWP (kPa),PWP Ratio,Lower Chamber Displacement (mm),Lower Chamber Axial Load (kPa),Specimen Air Volume (mm3),Matric Suction (kPa),Voids ratio,Degree of Saturation (°),Specimen Water Volume (mm3),kRT constant,Permeability IN,Permeability OUT,HCA Outer Rad,HCA Inner Rad,HCA Sigma Z (kPa),HCA Sigma R (kPa),HCA Sigma Theta (kPa),HCA Tau Theta Z,HCA Ez,HCA Er,HCA Etheta,HCA Gamma,HCA Sigma1,HCA Sigma2,HCA Sigma3,HCA Eff Sigma1,HCA Eff Sigma2,HCA Eff Sigma3,HCA E1,HCA E2,HCA E3,HCA P,HCA Eff P,HCA Q,HCA B,HCA Eff R,HCA Alpha,HCA Ev,HCA E1 rtv
1,0,0,604.8281,145625.9,503,0,-0.1848,505.3422,-0.0001,0,0,0.0528,0.0522,0.0518,0,0,0,7.266,0,0,100,0,0,0,0,0,0,0,0,0,0,592.1778,-42852.86,-0.0011,0.0269,0,0,0,0,0,0,0,0,0,0,4.5655,-0.0001,0,0,581.2985,75.9563,99.4859,-23.5296,0.9611,0.7635,7853.967,-0.0001,596.9849,91.6427,-11.7648,0,19.3894,87.7211,2.3422,0.0308,0,0,1524615,-505.3422,0,0,0,1.52E+08,0,0,50.6978,31.1491,575.7347,600.0137,624.9853,0.1283,-0.0001,2.3086,-2.2565,-0.0004,624.9856,600.0137,575.7344,119.6434,94.6715,70.3922,-0.0001,2.3086,-2.2565,600.2446,94.9024,49.2512,0.493,1.6997,89.8507,0.052,-0.0001
1,8,8,605.0095,145877.1,505,0,-0.1863,507.4159,0.0073,0,0,0.0528,0.0522,0.0518,0,0,0,7.2467,0,0,100,0,0,0,0,0,0,0,0,0,0,592.1118,-43071.94,-0.1091,-2.9181,0,0,0,0,0,0,0,0,0,0,4.5656,0.0038,0.0019,0.0019,581.2886,73.8727,97.5936,-23.721,0.9608,0.7569,7854.273,0.0038,597.1025,89.6866,-11.8605,0,11.9734,85.7332,2.4159,0.0327,0,0,1524615,-507.4159,0,0,0,1.52E+08,0,0,50.7023,31.1555,575.772,600.1006,625.5671,-13.919,0.0038,2.3185,-2.2695,-0.0409,629.1937,600.1006,572.1454,121.7778,92.6847,64.7295,0.0042,2.3185,-2.2699,600.4799,93.064,57.0483,0.49,1.8813,-75.3963,0.0528,-0.009
1,16.2,16.2,604.9479,145980.4,507,0,-0.1871,509.0559,0.0158,0,0,0.0528,0.0522,0.0518,0,0,0,7.2748,0,0,100,0,0,0,0,0,0,0,0,0,0,591.8975,-43224.05,-0.0224,-2.0791,0,0,0,0,0,0,0,0,0,0,4.5645,0.0081,0.0041,0.0041,581.1236,72.0677,95.892,-23.8243,0.9606,0.7516,7854.611,0.0081,597.0064,87.9505,-11.9122,0,29.8545,83.9799,2.0559,0.0285,0,0,1524615,-509.0559,0,0,0,1.52E+08,0,0,50.7058,31.1601,575.6474,599.9807,625.753,-9.9157,0.0081,2.3243,-2.2792,-0.0084,627.6439,599.9807,573.7565,118.588,90.9248,64.7006,0.0081,2.3243,-2.2792,600.4604,91.4045,53.8874,0.4866,1.8329,-79.2034,0.0532,-0.0018
1,24.4,24.4,605.3419,146074.8,508,0,-0.188,509.9548,0.0214,0,0,0.0528,0.0522,0.0518,0,0,0,7.2775,0,0,100,0,0,0,0,0,0,0,0,0,0,592.1561,-43346.11,0.1868,1.0613,0,0,0,0,0,0,0,0,0,0,4.5669,0.011,0.0055,0.0055,581.4123,71.4575,95.3871,-23.9296,0.9605,0.7491,7854.839,0.011,597.3654,87.4106,-11.9648,0,9.2392,83.4223,1.9548,0.0274,0,0,1524615,-509.9548,0,0,0,1.52E+08,0,0,50.7086,31.1638,575.9474,600.3229,626.3665,5.061,0.011,2.329,-2.287,0.0701,626.8696,600.3229,575.4444,116.9148,90.3681,65.4896,0.0121,2.329,-2.2881,600.879,90.9242,51.4252,0.4838,1.7852,84.3242,0.053,0.0152
1,32.6,32.6,605.0645,146190.5,509,0,-0.1863,510.7417,0.0221,0,0,0.0528,0.0522,0.0518,0,0,0,7.3001,0,0,100,0,0,0,0,0,0,0,0,0,0,591.9681,-43436.88,0.3218,3.0342,0,0,0,0,0,0,0,0,0,0,4.5664,0.0114,0.0057,0.0057,581.3463,70.6046,94.3228,-23.7182,0.9608,0.7485,7854.871,0.0114,597.1584,86.4167,-11.8591,0,22.6584,82.4637,1.7417,0.0247,0,0,1524615,-510.7417,0,0,0,1.52E+08,0,0,50.7101,31.1663,575.9552,600.0793,625.9492,14.4686,0.0114,2.3343,-2.2917,0.1207,629.8346,600.0793,572.0698,119.0929,89.3376,61.3281,0.0146,2.3343,-2.2949,600.6612,89.9195,57.7648,0.4849,1.9419,74.9686,0.054,0.0261
1,40.8,40.8,604.9877,146280.8,510,0,-0.1881,511.4669,0.0277,0,0,0.0528,0.0522,0.0518,0,0,0,7.3017,0,0,100,0,0,0,0,0,0,0,0,0,0,592.3116,-43550.16,0.2041,1.4874,0,0,0,0,0,0,0,0,0,0,4.5641,0.0143,0.0071,0.0071,581.0366,69.5697,93.5208,-23.9511,0.9604,0.7439,7855.098,0.0143,597.004,85.5371,-11.9756,0,36.932,81.5453,1.4669,0.0211,0,0,1524615,-511.4669,0,0,0,1.52E+08,0,0,50.7127,31.1697,575.2678,600.1624,625.2052,7.092,0.0143,2.3384,-2.2989,0.0766,626.1929,600.1624,574.2802,114.726,88.6955,62.8133,0.0156,2.3384,-2.3002,600.2119,88.7449,51.9127,0.4986,1.8265,82.0718,0.0538,0.0165
1,49,49,604.7601,146328.3,509,0,-0.1875,511.5106,0.0267,0,0,0.0528,0.0522,0.0518,0,0,0,7.2948,0,0,100,0,0,0,0,0,0,0,0,0,0,591.7606,-43627.17,0.0142,-1.7993,0,0,0,0,0,0,0,0,0,0,4.5629,0.0138,0.0069,0.0069,580.8868,69.3762,93.2495,-23.8733,0.9605,0.744,7855.059,0.0138,596.8023,85.2917,-11.9367,0,-117.2277,81.3129,2.5106,0.0362,0,0,1524615,-511.5106,0,0,0,1.52E+08,0,0,50.7138,31.1716,575.3567,599.8115,625.4954,-8.5789,0.0138,2.3426,-2.3025,0.0053,626.9227,599.8115,573.9294,115.4121,88.3009,62.4188,0.0138,2.3426,-2.3025,600.2212,88.7106,52.9933,0.4884,1.849,-80.5544,0.0539,0.0011
1,57.2,57.2,605.0479,146433.4,510,0,-0.1879,511.6979,0.026,0,0,0.0528,0.0522,0.0518,0,0,0,7.2998,0,0,100,0,0,0,0,0,0,0,0,0,0,592.0623,-43722.35,-0.0697,-2.9872,0,0,0,0,0,0,0,0,0,0,4.5648,0.0134,0.0067,0.0067,581.1309,69.433,93.35,-23.917,0.9605,0.7438,7855.028,0.0134,597.0756,85.3777,-11.9585,0,28.376,81.3915,1.6979,0.0245,0,0,1524615,-511.6979,0,0,0,1.52E+08,0,0,50.7153,31.1741,575.5577,600.1044,625.7639,-14.242,0.0134,2.3479,-2.3073,-0.0261,629.5225,600.1044,571.799,117.8246,88.4065,60.1011,0.0135,2.3479,-2.3074,600.4753,88.7774,57.7235,0.4904,1.9604,-75.216,0.054,-0.0056
1,65.4,65.4,605.0205,146551.5,511,0,-0.1858,513.0402,0.0327,0,0,0.0528,0.0522,0.0518,0,0,0,7.3114,0,0,100,0,0,0,0,0,0,0,0,0,0,592.3207,-43836.24,0.0956,-0.7055,0,0,0,0,0,0,0,0,0,0,4.5668,0.0168,0.0084,0.0084,581.3658,68.3256,91.9803,-23.6547,0.9609,0.7428,7855.295,0.0168,597.1356,84.0954,-11.8274,0,38.6857,80.153,2.0402,0.0299,0,0,1524615,-513.0402,0,0,0,1.52E+08,0,0,50.7179,31.1776,575.7771,600.1857,625.2837,-3.3633,0.0168,2.3526,-2.3145,0.0359,625.5111,600.1857,575.5497,112.4709,87.1455,62.5095,0.0171,2.3526,-2.3148,600.4155,87.3753,49.9614,0.4931,1.7993,-86.1312,0.0549,0.0077
1,73.6,73.6,604.7399,146589,511,0,-0.1869,513.0673,0.0307,0,0,0.0528,0.0522,0.0518,0,0,0,7.2866,0,0,100,0,0,0,0,0,0,0,0,0,0,592.3362,-43914.49,0.2881,2.34,0,0,0,0,0,0,0,0,0,0,4.5635,0.0158,0.0079,0.0079,580.9515,67.8842,91.6726,-23.7885,0.9607,0.7405,7855.216,0.0158,596.8105,83.7432,-11.8943,0,-106.4951,79.7784,2.0673,0.0305,0,0,1524615,-513.0673,0,0,0,1.52E+08,0,0,50.719,31.1795,575.0986,600.0177,624.5328,11.1549,0.0158,2.3568,-2.3181,0.1081,626.9333,600.0177,572.698,113.866,86.9504,59.6307,0.0183,2.3568,-2.3206,599.883,86.8157,54.2353,0.5037,1.9095,77.8551,0.0545,0.0231
1,81.8,81.8,604.9346,146707,512,0,-0.1875,513.6042,0.0333,0,0,0.0528,0.0522,0.0518,0,0,0,7.3023,0,0,100,0,0,0,0,0,0,0,0,0,0,591.8699,-44025.94,0.3251,2.7652,0,0,0,0,0,0,0,0,0,0,4.5645,0.0172,0.0086,0.0086,581.0707,67.4665,91.3304,-23.8639,0.9606,0.7387,7855.326,0.0172,596.9799,83.3757,-11.932,0,71.1739,79.3985,1.6042,0.0238,0,0,1524615,-513.6042,0,0,0,1.52E+08,0,0,50.7211,31.1827,575.5773,599.9605,625.7855,13.181,0.0172,2.3625,-2.3244,0.122,629.0355,599.9605,572.3273,115.4313,86.3563,58.7231,0.0204,2.3625,-2.3276,600.4411,86.8369,56.7082,0.4873,1.9657,76.1491,0.0553,0.0259
1,90,90,604.7681,146736.7,512,0,-0.1883,514.2086,0.0354,0,0,0.0528,0.0522,0.0518,0,0,0,7.3093,0,0,100,0,0,0,0,0,0,0,0,0,0,592.108,-44094.14,0.1237,-0.0003,0,0,0,0,0,0,0,0,0,0,4.5624,0.0182,0.0091,0.0091,580.7976,66.589,90.5595,-23.9705,0.9604,0.7353,7855.405,0.0182,596.778,82.5694,-11.9853,0,-195.1371,78.5743,2.2086,0.0332,0,0,1524615,-514.2086,0,0,0,1.52E+08,0,0,50.7225,31.1846,575.0073,599.9479,624.9752,-0.0014,0.0182,2.3652,-2.3284,0.0464,624.9752,599.9479,575.0073,110.7666,85.7393,60.7987,0.0187,2.3652,-2.3289,599.9768,85.7682,49.9679,0.4991,1.8219,-89.9984,0.055,0.0099
1,98.2,98.2,604.8966,146821.8,512,0,-0.1879,513.7051,0.0304,0,0,0.0528,0.0522,0.0518,0,0,0,7.3232,0,0,100,0,0,0,0,0,0,0,0,0,0,592.1171,-44149.85,-0.045,-2.7635,0,0,0,0,0,0,0,0,0,0,4.5637,0.0157,0.0079,0.0079,580.9776,67.2725,91.1915,-23.919,0.9605,0.7377,7855.208,0.0157,596.9236,83.2185,-11.9595,0,105.4705,79.232,1.7051,0.0253,0,0,1524615,-513.7051,0,0,0,1.52E+08,0,0,50.7228,31.1857,575.2877,600.0309,625.2957,-13.1723,0.0157,2.3693,-2.33,-0.0169,628.5532,600.0309,572.0303,114.8481,86.3258,58.3252,0.0158,2.3693,-2.3301,600.2048,86.4997,56.5229,0.4954,1.9691,-76.1097,0.055,-0.0036
1,106.4,106.4,605.2164,146926.2,513,0,-0.1865,514.5815,0.0348,0,0,0.0528,0.0522,0.0518,0,0,0,7.3175,0,0,100,0,0,0,0,0,0,0,0,0,0,591.8231,-44286.34,-0.0101,-2.3169,0,0,0,0,0,0,0,0,0,0,4.5677,0.0179,0.0089,0.0089,581.474,66.8925,90.6349,-23.7424,0.9608,0.738,7855.381,0.0179,597.3022,82.7207,-11.8712,0,23.6522,78.7637,1.5815,0.0236,0,0,1524615,-514.5815,0,0,0,1.52E+08,0,0,50.7255,31.1896,576.2616,600.1168,626.5991,-11.0425,0.0179,2.3756,-2.3379,-0.0038,628.915,600.1168,573.9457,114.3335,85.5353,59.3642,0.0179,2.3756,-2.3379,600.9925,86.411,54.9693,0.4761,1.926,-78.1555,0.0556,-0.0008
1,114.6,114.6,605.0449,146977.5,513,0,-0.1877,515.4243,0.0377,0,0,0.0528,0.0522,0.0518,0,0,0,7.3111,0,0,100,0,0,0,0,0,0,0,0,0,0,591.9857,-44357.05,0.2093,0.7367,0,0,0,0,0,0,0,0,0,0,4.5652,0.0194,0.0097,0.0097,581.147,65.7227,89.6206,-23.898,0.9605,0.7333,7855.499,0.0194,597.0789,81.6546,-11.949,0,44.9438,77.6717,2.4243,0.0369,0,0,1524615,-515.4243,0,0,0,1.52E+08,0,0,50.727,31.1917,575.6498,600.0724,625.8964,3.511,0.0194,2.3788,-2.3422,0.0786,626.1406,600.0724,575.4056,110.7163,84.6481,59.9813,0.0207,2.3788,-2.3435,600.5396,85.1152,50.735,0.4862,1.8458,86.0222,0.056,0.0166
1,122.8,122.8,605.0389,147030.9,513,0,-0.1877,515.1859,0.0344,0,0,0.0528,0.0522,0.0518,0,0,0,7.3071,0,0,100,0,0,0,0,0,0,0,0,0,0,592.2462,-44425.26,0.3675,3.0082,0,0,0,0,0,0,0,0,0,0,4.5651,0.0177,0.0089,0.0089,581.1442,65.9583,89.853,-23.8947,0.9605,0.7341,7855.365,0.0177,597.074,81.8881,-11.9474,0,45.0918,77.9057,2.1859,0.0331,0,0,1524615,-515.1859,0,0,0,1.52E+08,0,0,50.7277,31.1932,575.4821,600.1678,625.4665,14.3364,0.0177,2.383,-2.3448,0.1379,629.2865,600.1678,571.6621,114.1006,84.9819,56.4762,0.0217,2.383,-2.3488,600.3721,85.1862,57.6244,0.4947,2.0203,75.0799,0.0559,0.029
1,131,131,605.0657,147145.5,514,0,-0.1876,515.9308,0.0397,0,0,0.0528,0.0522,0.0518,0,0,0,7.3062,0,0,100,0,0,0,0,0,0,0,0,0,0,591.9268,-44543.58,0.2722,1.7978,0,0,0,0,0,0,0,0,0,0,4.5655,0.0205,0.0103,0.0103,581.1788,65.248,89.1349,-23.8869,0.9605,0.732,7855.585,0.0205,597.1033,81.1725,-11.9435,0,43.2443,77.1915,1.9308,0.0296,0,0,1524615,-515.9308,0,0,0,1.52E+08,0,0,50.7303,31.1968,575.7418,600.0626,626.0497,8.5671,0.0205,2.3882,-2.3522,0.1022,627.4686,600.0626,574.3229,111.5378,84.1318,58.3921,0.0227,2.3882,-2.3544,600.618,84.6872,53.1457,0.4843,1.9102,80.5959,0.0565,0.0215
1,139.2,139.2,604.5927,147182.2,514,0,-0.1895,516.0672,0.0383,0,0,0.0528,0.0522,0.0518,0,0,0,7.2971,0,0,100,0,0,0,0,0,0,0,0,0,0,592.3026,-44582.86,0.0537,-1.4826,0,0,0,0,0,0,0,0,0,0,4.5599,0.0197,0.0099,0.0099,580.4706,64.4034,88.5255,-24.1221,0.9601,0.7275,7855.522,0.0197,596.552,80.4848,-12.0611,0,-49.4302,76.4645,2.0672,0.0321,0,0,1524615,-516.0672,0,0,0,1.52E+08,0,0,50.7308,31.1977,574.3751,599.9128,624.222,-7.065,0.0197,2.3903,-2.3539,0.0202,625.204,599.9128,573.3931,109.1368,83.8456,57.3259,0.0198,2.3903,-2.354,599.5032,83.4361,51.8109,0.5119,1.9038,-82.0868,0.0561,0.0043
1,147.4,147.4,605.0491,147262.2,514,0,-0.1885,516.1456,0.034,0,0,0.0528,0.0522,0.0518,0,0,0,7.306,0,0,100,0,0,0,0,0,0,0,0,0,0,591.9726,-44652.53,-0.0581,-3.0439,0,0,0,0,0,0,0,0,0,0,4.5644,0.0175,0.0088,0.0088,581.0563,64.9106,88.9034,-23.9928,0.9603,0.7301,7855.35,0.0175,597.0515,80.9059,-11.9964,0,47.2273,76.907,2.1456,0.0331,0,0,1524615,-516.1456,0,0,0,1.52E+08,0,0,50.7313,31.1992,575.5086,600.0696,625.9365,-14.5051,0.0175,2.3955,-2.3563,-0.0218,629.811,600.0696,571.634,113.6653,83.924,55.4883,0.0176,2.3955,-2.3564,600.5049,84.3592,58.177,0.4888,2.0485,-75.0445,0.0567,-0.0046
1,155.6,155.6,605.3315,147379.6,515,0,-0.1859,516.9898,0.0411,0,0,0.0528,0.0522,0.0518,0,0,0,7.3128,0,0,100,0,0,0,0,0,0,0,0,0,0,592.0103,-44778.32,0.0923,-1.0887,0,0,0,0,0,0,0,0,0,0,4.5694,0.0212,0.0106,0.0106,581.6712,64.6814,88.3417,-23.6603,0.9609,0.7322,7855.641,0.0212,597.4448,80.455,-11.8302,0,23.0437,76.5116,1.9898,0.0308,0,0,1524615,-516.9898,0,0,0,1.52E+08,0,0,50.7343,31.2031,576.4601,600.2585,626.6135,-5.1874,0.0212,2.4003,-2.3645,0.0346,627.1445,600.2585,575.9291,110.1547,83.2687,58.9393,0.0215,2.4003,-2.3648,601.1107,84.1209,51.2154,0.475,1.869,-84.1563,0.057,0.0072
1,163.8,163.8,604.9224,147412.5,515,0,-0.1863,516.8583,0.0381,0,0,0.0528,0.0522,0.0518,0,0,0,7.3163,0,0,100,0,0,0,0,0,0,0,0,0,0,592.026,-44842.79,0.3038,2.105,0,0,0,0,0,0,0,0,0,0,4.5657,0.0196,0.0098,0.0098,581.2095,64.3512,88.0642,-23.713,0.9608,0.7307,7855.515,0.0196,597.0181,80.1599,-11.8565,0,109.4705,76.2077,1.8583,0.0289,0,0,1524615,-516.8583,0,0,0,1.52E+08,0,0,50.7349,31.2045,575.7133,600.0112,625.5276,10.0297,0.0196,2.4045,-2.3669,0.114,627.4712,600.0112,573.7698,110.6129,83.153,56.9115,0.0223,2.4045,-2.3696,600.4174,83.5591,53.7014,0.4887,1.9436,79.0331,0.0572,0.0238
1,172,172,605.0577,147528.7,515,0,-0.1874,516.9784,0.0383,0,0,0.0528,0.0522,0.0518,0,0,0,7.318,0,0,100,0,0,0,0,0,0,0,0,0,0,591.9539,-44936.09,0.3701,2.8843,0,0,0,0,0,0,0,0,0,0,4.5656,0.0197,0.0099,0.0099,581.1962,64.2178,88.0793,-23.8615,0.9606,0.7291,7855.522,0.0197,597.1038,80.1254,-11.9308,0,48.9832,76.1485,1.9784,0.0308,0,0,1524615,-516.9784,0,0,0,1.52E+08,0,0,50.7365,31.207,575.7573,600.0673,625.9967,13.7421,0.0197,2.4092,-2.3718,0.1389,629.5099,600.0673,572.2441,112.5315,83.0889,55.2657,0.0237,2.4092,-2.3758,600.6071,83.6287,57.2658,0.4859,2.0362,75.6592,0.0571,0.0289
1,180.2,180.2,604.6234,147579.8,516,0,-0.1856,517.6882,0.0431,0,0,0.0528,0.0522,0.0518,0,0,0,7.309,0,0,100,0,0,0,0,0,0,0,0,0,0,592.2462,-45024.32,0.1821,0.4134,0,0,0,0,0,0,0,0,0,0,4.5642,0.0222,0.0111,0.0111,581.0034,63.3153,86.9352,-23.62,0.9609,0.7283,7855.719,0.0222,596.7501,79.062,-11.81,0,-65.8221,75.1253,1.6882,0.0267,0,0,1524615,-517.6882,0,0,0,1.52E+08,0,0,50.7385,31.2097,575.2409,599.9096,624.4039,1.9695,0.0222,2.4129,-2.3774,0.0684,624.4827,599.9096,575.1621,106.7946,82.2214,57.4739,0.0232,2.4129,-2.3784,599.8515,82.1633,49.3207,0.5018,1.8581,87.7096,0.0577,0.0142
1,188.4,188.4,605.0437,147623.3,515,0,-0.1883,517.3503,0.0375,0,0,0.0528,0.0522,0.0518,0,0,0,7.3184,0,0,100,0,0,0,0,0,0,0,0,0,0,592.0667,-45069.39,-0.0101,-2.5802,0,0,0,0,0,0,0,0,0,0,4.5646,0.0193,0.0097,0.0097,581.0712,63.721,87.6934,-23.9725,0.9604,0.7266,7855.491,0.0193,597.0529,79.7026,-11.9863,0,53.6004,75.7072,2.3503,0.0369,0,0,1524615,-517.3503,0,0,0,1.52E+08,0,0,50.7385,31.2104,575.4887,600.1014,625.7839,-12.2926,0.0193,2.4165,-2.3782,-0.0038,628.6275,600.1014,572.6451,111.2772,82.7511,55.2948,0.0193,2.4165,-2.3782,600.458,83.1077,55.9824,0.4904,2.0124,-76.9749,0.0576,-0.0008
1,196.6,196.6,604.8004,147706.6,516,0,-0.1869,517.5402,0.039,0,0,0.0528,0.0522,0.0518,0,0,0,7.3376,0,0,100,0,0,0,0,0,0,0,0,0,0,591.7759,-45178.34,-0.0124,-2.5653,0,0,0,0,0,0,0,0,0,0,4.5641,0.0201,0.0101,0.0101,581.0029,63.4627,87.2602,-23.7975,0.9607,0.7273,7855.554,0.0201,596.8679,79.3277,-11.8988,0,-861.0126,75.3615,1.5402,0.0243,0,0,1524615,-517.5402,0,0,0,1.52E+08,0,0,50.7405,31.2134,575.5547,599.8398,625.6197,-12.2208,0.0201,2.4218,-2.3841,-0.0047,628.4435,599.8398,572.7308,110.9033,82.2996,55.1906,0.0201,2.4218,-2.3841,600.338,82.7978,55.7127,0.4866,2.0095,-76.9892,0.0578,-0.001
1,204.8,204.8,604.8822,147803.5,517,0,-0.1872,518.6086,0.0435,0,0,0.0528,0.0522,0.0518,0,0,0,7.3185,0,0,100,0,0,0,0,0,0,0,0,0,0,592.3801,-45278.45,0.2104,0.3737,0,0,0,0,0,0,0,0,0,0,4.5646,0.0224,0.0112,0.0112,581.0532,62.4446,86.2736,-23.829,0.9606,0.7238,7855.735,0.0224,596.9392,78.3306,-11.9145,0,200.874,74.3591,1.6086,0.0258,0,0,1524615,-518.6086,0,0,0,1.52E+08,0,0,50.7427,31.2164,575.2608,600.1204,624.8691,1.7801,0.0224,2.426,-2.3903,0.079,624.9329,600.1204,575.197,106.3243,81.5118,56.5884,0.0237,2.426,-2.3916,600.0834,81.4748,49.7359,0.5011,1.8789,87.9476,0.0581,0.0163
1,213,213,604.8748,147842.5,516,0,-0.1872,518.2659,0.0385,0,0,0.0528,0.0522,0.0518,0,0,0,7.3155,0,0,100,0,0,0,0,0,0,0,0,0,0,592.1208,-45339.21,0.3836,2.9092,0,0,0,0,0,0,0,0,0,0,4.5644,0.0198,0.0099,0.0099,581.0429,62.777,86.6089,-23.8319,0.9606,0.7248,7855.53,0.0198,596.9308,78.6649,-11.916,0,219.9084,74.693,2.2659,0.0361,0,0,1524615,-518.2659,0,0,0,1.52E+08,0,0,50.743,31.2176,575.4066,600.017,625.2662,13.8581,0.0198,2.4307,-2.3921,0.144,628.8591,600.017,571.8138,110.5931,81.7511,53.5479,0.0241,2.4307,-2.3964,600.23,81.964,57.0452,0.4944,2.0653,75.4655,0.0584,0.0296
1,221.2,221.2,604.9644,147959.3,517,0,-0.1865,518.8447,0.0431,0,0,0.0528,0.0522,0.0518,0,0,0,7.3132,0,0,100,0,0,0,0,0,0,0,0,0,0,592.0169,-45453.73,0.3211,2.1003,0,0,0,0,0,0,0,0,0,0,4.5659,0.0222,0.0111,0.0111,581.2198,62.3751,86.1197,-23.7446,0.9608,0.7243,7855.719,0.0222,597.0496,78.2049,-11.8723,0,92.0135,74.2474,1.8447,0.0296,0,0,1524615,-518.8447,0,0,0,1.52E+08,0,0,50.7455,31.221,575.7558,600.0327,625.6684,10.004,0.0222,2.4354,-2.3992,0.1206,627.5988,600.0327,573.8254,108.7541,81.188,54.9807,0.0252,2.4354,-2.4022,600.4857,81.6409,53.7734,0.4874,1.978,79.078,0.0584,0.0248
1,229.4,229.4,604.942,147980.5,517,0,-0.1871,518.9877,0.0431,0,0,0.0528,0.0522,0.0518,0,0,0,7.3275,0,0,100,0,0,0,0,0,0,0,0,0,0,591.9842,-45502.56,0.0899,-1.107,0,0,0,0,0,0,0,0,0,0,4.5652,0.0222,0.0111,0.0111,581.1307,62.143,85.9544,-23.8113,0.9606,0.723,7855.719,0.0222,597.0049,78.0172,-11.9057,0,109.3495,74.0487,1.9877,0.032,0,0,1524615,-518.9877,0,0,0,1.52E+08,0,0,50.7462,31.2222,575.6209,600.0063,625.6638,-5.2727,0.0222,2.438,-2.4014,0.0338,626.2133,600.0063,575.0714,107.2256,81.0186,56.0837,0.0224,2.438,-2.4016,600.4304,81.4426,51.1419,0.4876,1.9119,-84.0502,0.0588,0.007
1,237.6,237.6,604.832,148053.1,517,0,-0.187,518.541,0.0373,0,0,0.0528,0.0522,0.0518,0,0,0,7.301,0,0,100,0,0,0,0,0,0,0,0,0,0,592.1454,-45567.69,-0.048,-3.0388,0,0,0,0,0,0,0,0,0,0,4.5642,0.0192,0.0096,0.0096,581.0209,62.4799,86.291,-23.8111,0.9606,0.7241,7855.483,0.0192,596.895,78.354,-11.9056,0,787.3464,74.3855,1.541,0.0247,0,0,1524615,-518.541,0,0,0,1.52E+08,0,0,50.7466,31.2235,575.3654,599.9995,625.1217,-14.474,0.0192,2.4427,-2.4034,-0.018,629.0258,599.9995,571.4612,110.4848,81.4585,52.9202,0.0193,2.4427,-2.4035,600.1622,81.6212,57.5646,0.4958,2.0878,-74.9047,0.0585,-0.0037
1,245.8,245.8,604.7574,148160.8,517,0,-0.1878,519.4268,0.0439,0,0,0.0528,0.0522,0.0518,0,0,0,7.3353,0,0,100,0,0,0,0,0,0,0,0,0,0,592.0623,-45697.86,0.0799,-1.4787,0,0,0,0,0,0,0,0,0,0,4.563,0.0226,0.0113,0.0113,580.8484,61.4216,85.3306,-23.909,0.9605,0.7198,7855.75,0.0226,596.7877,77.3609,-11.9545,0,-249.4374,73.3761,2.4268,0.0395,0,0,1524615,-519.4268,0,0,0,1.52E+08,0,0,50.7495,31.2274,575.1397,599.9215,625.0643,-7.0423,0.0226,2.448,-2.4115,0.03,626.0386,599.9215,574.1653,106.6118,80.4947,54.7385,0.0228,2.448,-2.4117,600.0418,80.615,51.8733,0.4965,1.9477,-82.1227,0.0591,0.0062
1,254,254,604.8138,148206.2,518,0,-0.1869,519.611,0.0423,0,0,0.0528,0.0522,0.0518,0,0,0,7.331,0,0,100,0,0,0,0,0,0,0,0,0,0,592.3431,-45762.96,0.3105,1.8091,0,0,0,0,0,0,0,0,0,0,4.5643,0.0218,0.0109,0.0109,581.0185,61.4075,85.2028,-23.7953,0.9607,0.7207,7855.688,0.0218,596.882,77.271,-11.8977,0,-13221.56,73.3052,1.611,0.0262,0,0,1524615,-519.611,0,0,0,1.52E+08,0,0,50.7503,31.229,575.2388,600.0632,624.7637,8.6158,0.0218,2.4522,-2.4144,0.1166,626.2197,600.0632,573.7827,106.6087,80.4522,54.1717,0.0246,2.4522,-2.4172,600.0219,80.4109,52.437,0.5012,1.968,80.4076,0.0596,0.0238
1,262.2,262.2,605.0015,148288.5,518,0,-0.1875,519.5432,0.0402,0,0,0.0528,0.0522,0.0518,0,0,0,7.3097,0,0,100,0,0,0,0,0,0,0,0,0,0,591.8975,-45846.87,0.4039,2.9936,0,0,0,0,0,0,0,0,0,0,4.5652,0.0207,0.0104,0.0104,581.1395,61.5963,85.4583,-23.862,0.9606,0.7208,7855.601,0.0207,597.0475,77.5043,-11.931,0,77.4614,73.5273,1.5432,0.0251,0,0,1524615,-519.5432,0,0,0,1.52E+08,0,0,50.7515,31.2311,575.6941,600.0096,625.9669,14.2564,0.0207,2.4569,-2.4183,0.1517,629.7283,600.0096,571.9327,110.1851,80.4664,52.3895,0.0254,2.4569,-2.423,600.5568,81.0137,57.7956,0.4858,2.1032,75.2199,0.0593,0.0309
1,270.4,270.4,604.915,148377.8,518,0,-0.1872,520.5581,0.0462,0,0,0.0528,0.0522,0.0518,0,0,0,7.321,0,0,100,0,0,0,0,0,0,0,0,0,0,592.2688,-45941.98,0.2272,0.7954,0,0,0,0,0,0,0,0,0,0,4.5649,0.0238,0.0119,0.0119,581.0833,60.5252,84.3569,-23.8317,0.9606,0.7175,7855.845,0.0238,596.9711,76.413,-11.9159,0,154.5762,72.4411,2.5581,0.0423,0,0,1524615,-520.5581,0,0,0,1.52E+08,0,0,50.7537,31.234,575.3904,600.0973,625.1505,3.7876,0.0238,2.4606,-2.4244,0.0853,625.4371,600.0973,575.1038,104.879,79.5392,54.5457,0.0253,2.4606,-2.4259,600.2127,79.6546,50.3333,0.4966,1.9228,85.672,0.06,0.0174
1,278.6,278.6,604.8466,148411.2,518,0,-0.1852,520.0167,0.0406,0,0,0.0528,0.0522,0.0518,0,0,0,7.3232,0,0,100,0,0,0,0,0,0,0,0,0,0,592.3695,-45976.41,0.018,-2.341,0,0,0,0,0,0,0,0,0,0,4.5662,0.0209,0.0105,0.0105,581.2656,61.2489,84.8299,-23.581,0.961,0.722,7855.617,0.0209,596.9863,76.9696,-11.7905,0,470.4519,73.0394,2.0167,0.0329,0,0,1524615,-520.0167,0,0,0,1.52E+08,0,0,50.7536,31.2345,575.6162,600.0933,624.8126,-11.1479,0.0209,2.4637,-2.4249,0.0068,627.2208,600.0933,573.208,107.2041,80.0766,53.1913,0.0209,2.4637,-2.4249,600.1741,80.1573,54.0128,0.4978,2.0154,-77.81,0.0597,0.0014
1,286.8,286.8,604.9949,148496.7,518,0,-0.1874,520.0504,0.0396,0,0,0.0528,0.0522,0.0518,0,0,0,7.309,0,0,100,0,0,0,0,0,0,0,0,0,0,592.1937,-46071.59,-0.0191,-2.7645,0,0,0,0,0,0,0,0,0,0,4.5652,0.0204,0.0102,0.0102,581.1412,61.0908,84.9445,-23.8537,0.9606,0.7192,7855.578,0.0204,597.0436,76.9932,-11.9269,0,83.1424,73.0177,2.0504,0.0336,0,0,1524615,-520.0504,0,0,0,1.52E+08,0,0,50.755,31.2369,575.5255,600.118,625.4819,-13.1641,0.0204,2.469,-2.4294,-0.0072,628.7385,600.118,572.2689,108.6881,80.0676,52.2185,0.0204,2.469,-2.4294,600.3751,80.3247,56.4696,0.4932,2.0814,-76.1048,0.06,-0.0015
1,295,295,604.9283,148588.4,519,0,-0.1882,521.043,0.0453,0,0,0.0528,0.0522,0.0518,0,0,0,7.3395,0,0,100,0,0,0,0,0,0,0,0,0,0,592.1883,-46176.69,0.2014,-0.0054,0,0,0,0,0,0,0,0,0,0,4.564,0.0233,0.0117,0.0117,580.9717,59.9287,83.8853,-23.9566,0.9604,0.7144,7855.805,0.0233,596.9427,75.8997,-11.9783,0,140.7158,71.907,2.043,0.0341,0,0,1524615,-521.043,0,0,0,1.52E+08,0,0,50.7574,31.2401,575.2649,600.0745,625.3204,-0.0257,0.0233,2.4732,-2.4361,0.0757,625.3204,600.0745,575.2648,104.2773,79.0315,54.2217,0.0245,2.4732,-2.4373,600.2199,79.1768,50.0556,0.4956,1.9232,-89.9706,0.0604,0.0154
1,303.2,303.2,604.788,148611.8,519,0,-0.1866,520.6985,0.0394,0,0,0.0528,0.0522,0.0518,0,0,0,7.3304,0,0,100,0,0,0,0,0,0,0,0,0,0,592.1343,-46230.55,0.3938,2.7748,0,0,0,0,0,0,0,0,0,0,4.5644,0.0203,0.0102,0.0102,581.04,60.3415,84.0895,-23.7481,0.9607,0.7176,7855.57,0.0203,596.872,76.1735,-11.8741,0,-581.375,72.2155,1.6985,0.0281,0,0,1524615,-520.6985,0,0,0,1.52E+08,0,0,50.7576,31.2411,575.39,599.967,625.0436,13.2121,0.0203,2.4774,-2.4375,0.1479,628.3403,599.967,572.0933,107.6418,79.2685,51.3948,0.0247,2.4774,-2.4419,600.1335,79.435,56.247,0.4956,2.0944,75.9897,0.0602,0.0299
1,311.4,311.4,605.2363,148700.9,519,0,-0.1869,521.0226,0.0429,0,0,0.0528,0.0522,0.0518,0,0,0,7.3208,0,0,100,0,0,0,0,0,0,0,0,0,0,592.1763,-46336.34,0.3622,2.3325,0,0,0,0,0,0,0,0,0,0,4.5677,0.0221,0.0111,0.0111,581.4496,60.427,84.2138,-23.7867,0.9607,0.7175,7855.711,0.0221,597.3074,76.2848,-11.8934,0,37.8154,72.3204,2.0226,0.0335,0,0,1524615,-521.0226,0,0,0,1.52E+08,0,0,50.7597,31.2441,576.0284,600.2604,626.1452,11.1053,0.0221,2.4821,-2.4435,0.1361,628.4958,600.2604,573.6778,107.4732,79.2378,52.6552,0.0259,2.4821,-2.4473,600.8113,79.7887,54.818,0.4849,2.0411,78.0491,0.0607,0.0274
1,319.6,319.6,604.5294,148750.5,519,0,-0.1869,521.5179,0.0447,0,0,0.0528,0.0522,0.0518,0,0,0,7.3059,0,0,100,0,0,0,0,0,0,0,0,0,0,592.2385,-46399.57,0.1204,-0.7571,0,0,0,0,0,0,0,0,0,0,4.5622,0.023,0.0115,0.0115,580.7442,59.2263,83.0115,-23.7852,0.9607,0.7135,7855.782,0.023,596.601,75.0831,-11.8926,0,-57.5647,71.1189,2.5179,0.0425,0,0,1524615,-521.5179,0,0,0,1.52E+08,0,0,50.7609,31.2459,574.8534,599.8464,624.2087,-3.6045,0.023,2.4853,-2.4471,0.0452,624.4705,599.8464,574.5915,102.9526,78.3285,53.0736,0.0234,2.4853,-2.4475,599.6362,78.1182,49.879,0.5063,1.9398,-85.845,0.0612,0.0091
1,327.8,327.8,605.1938,148836.3,519,0,-0.1869,520.9353,0.0373,0,0,0.0528,0.0522,0.0518,0,0,0,7.3225,0,0,100,0,0,0,0,0,0,0,0,0,0,591.9539,-46440.25,-0.0383,-3.0131,0,0,0,0,0,0,0,0,0,0,4.5672,0.0192,0.0096,0.0096,581.4028,60.4675,84.2585,-23.791,0.9607,0.7176,7855.483,0.0192,597.2634,76.3281,-11.8955,0,41.8307,72.363,1.9353,0.032,0,0,1524615,-520.9353,0,0,0,1.52E+08,0,0,50.7607,31.2464,576.096,600.1491,626.3936,-14.3455,0.0192,2.4889,-2.4475,-0.0144,630.1974,600.1491,572.2922,109.2621,79.2138,51.3569,0.0192,2.4889,-2.4475,600.8796,79.9443,57.9052,0.4811,2.1275,-75.1492,0.0606,-0.0029
1,336,336,605.1353,148958.9,520,0,-0.1885,521.6188,0.0435,0,0,0.0528,0.0522,0.0518,0,0,0,7.3285,0,0,100,0,0,0,0,0,0,0,0,0,0,592.1725,-46585.51,0.0641,-1.7794,0,0,0,0,0,0,0,0,0,0,4.5653,0.0224,0.0112,0.0112,581.1423,59.5235,83.5165,-23.993,0.9604,0.7127,7855.735,0.0224,597.1376,75.5188,-11.9965,0,51.5968,71.52,1.6188,0.0272,0,0,1524615,-521.6188,0,0,0,1.52E+08,0,0,50.7638,31.2507,575.5533,600.196,625.8956,-8.4709,0.0224,2.4952,-2.4563,0.0241,627.2828,600.196,574.1662,105.664,78.5772,52.5474,0.0225,2.4952,-2.4564,600.5483,78.9295,53.1166,0.4901,2.0108,-80.7001,0.0613,0.0049
1,344.2,344.2,604.8478,149003.8,520,0,-0.1903,521.9479,0.0427,0,0,0.0528,0.0522,0.0518,0,0,0,7.3198,0,0,100,0,0,0,0,0,0,0,0,0,0,592.1319,-46644.95,0.3117,1.4505,0,0,0,0,0,0,0,0,0,0,4.5612,0.022,0.011,0.011,580.6228,58.6749,82.8999,-24.225,0.9599,0.7078,7855.703,0.022,596.7728,74.825,-12.1125,0,512.5696,70.7874,1.9479,0.0332,0,0,1524615,-521.9479,0,0,0,1.52E+08,0,0,50.7647,31.2522,574.7577,600.0025,625.2142,6.905,0.022,2.4984,-2.4591,0.1171,626.1421,600.0025,573.8298,104.1942,78.0546,51.8819,0.0248,2.4984,-2.4619,599.9915,78.0436,52.3123,0.5003,2.0083,82.3465,0.0613,0.0235
1,352.4,352.4,604.9211,149051.3,520,0,-0.1879,521.7321,0.0388,0,0,0.0528,0.0522,0.0518,0,0,0,7.3187,0,0,100,0,0,0,0,0,0,0,0,0,0,591.8352,-46716.33,0.4297,3.0408,0,0,0,0,0,0,0,0,0,0,4.5641,0.02,0.01,0.01,581.0035,59.2714,83.189,-23.9176,0.9605,0.7125,7855.546,0.02,596.9485,75.2164,-11.9588,0,156.7471,71.2302,1.7321,0.0292,0,0,1524615,-521.7321,0,0,0,1.52E+08,0,0,50.7653,31.2538,575.5343,599.9346,625.8821,14.4754,0.02,2.5036,-2.4617,0.1615,629.7472,599.9346,571.6692,108.0151,78.2025,49.9371,0.0252,2.5036,-2.4669,600.4503,78.7182,58.078,0.4867,2.163,75.0502,0.0619,0.0323
1,360.6,360.6,604.89,149135.8,521,0,-0.1868,522.7609,0.046,0,0,0.0528,0.0522,0.0518,0,0,0,7.3243,0,0,100,0,0,0,0,0,0,0,0,0,0,592.1735,-46825.22,0.2699,1.1302,0,0,0,0,0,0,0,0,0,0,4.5651,0.0237,0.0119,0.0119,581.1093,58.3484,82.1291,-23.7807,0.9607,0.7104,7855.837,0.0237,596.9631,74.2022,-11.8904,0,235.2526,70.2388,1.7609,0.0302,0,0,1524615,-522.7609,0,0,0,1.52E+08,0,0,50.768,31.2572,575.4994,600.0442,625.2625,5.3796,0.0237,2.5073,-2.469,0.1014,625.8375,600.0442,574.9245,103.0766,77.2833,52.1636,0.0258,2.5073,-2.4711,600.2687,77.5078,50.913,0.4934,1.976,83.9,0.062,0.0203
1,368.8,368.8,605.3659,149160.5,520,0,-0.1868,522.1524,0.0405,0,0,0.0528,0.0522,0.0518,0,0,0,7.3215,0,0,100,0,0,0,0,0,0,0,0,0,0,592.2319,-46856.52,0.0427,-2.0768,0,0,0,0,0,0,0,0,0,0,4.5687,0.0209,0.0105,0.0105,581.5839,59.4315,83.2135,-23.782,0.9607,0.7142,7855.617,0.0209,597.4385,75.2861,-11.891,0,30.9732,71.3225,2.1524,0.0362,0,0,1524615,-522.1524,0,0,0,1.52E+08,0,0,50.7678,31.2576,576.2295,600.3609,626.4081,-9.8856,0.0209,2.5105,-2.4692,0.016,628.2854,600.3609,574.3522,106.133,78.2085,52.1998,0.021,2.5105,-2.4693,600.9995,78.8471,53.9332,0.4822,2.0332,-79.2474,0.0622,0.0032
1,377,377,605.0992,149269.3,520,0,-0.1874,522.1061,0.0385,0,0,0.0528,0.0522,0.0518,0,0,0,7.3261,0,0,100,0,0,0,0,0,0,0,0,0,0,591.9943,-46949.25,-0.0256,-2.8995,0,0,0,0,0,0,0,0,0,0,4.566,0.0198,0.0099,0.0099,581.2466,59.1405,82.9931,-23.8526,0.9606,0.7126,7855.53,0.0198,597.1483,75.0422,-11.9263,0,59.8684,71.0668,2.1061,0.0356,0,0,1524615,-522.1061,0,0,0,1.52E+08,0,0,50.769,31.2598,575.8265,600.1052,626.0972,-13.8013,0.0198,2.5157,-2.4733,-0.0096,629.637,600.1052,572.2867,107.5309,77.9992,50.1806,0.0198,2.5157,-2.4733,600.6763,78.5702,57.3503,0.4851,2.1429,-75.6149,0.0622,-0.0019
1,385.2,385.2,605.1028,149369,521,0,-0.1865,523.0933,0.045,0,0,0.0528,0.0522,0.0518,0,0,0,7.3255,0,0,100,0,0,0,0,0,0,0,0,0,0,591.9766,-47062.42,0.1868,-0.3958,0,0,0,0,0,0,0,0,0,0,4.5671,0.0232,0.0116,0.0116,581.3668,58.2735,82.0095,-23.736,0.9608,0.7106,7855.797,0.0232,597.1908,74.0975,-11.868,0,62.5487,70.1415,2.0933,0.0359,0,0,1524615,-523.0933,0,0,0,1.52E+08,0,0,50.7717,31.2633,576.0249,600.1005,626.1382,-1.8838,0.0232,2.5199,-2.4807,0.0702,626.2089,600.1005,575.9542,103.1156,77.0072,52.8609,0.0242,2.5199,-2.4817,600.7546,77.6612,50.2547,0.4805,1.9507,-87.8502,0.0624,0.014
1,393.4,393.4,604.9518,149407.4,521,0,-0.1866,522.8292,0.0381,0,0,0.0528,0.0522,0.0518,0,0,0,7.3163,0,0,100,0,0,0,0,0,0,0,0,0,0,592.1201,-47105.03,0.3971,2.5461,0,0,0,0,0,0,0,0,0,0,4.5656,0.0196,0.0098,0.0098,581.1968,58.3676,82.1226,-23.755,0.9607,0.7107,7855.515,0.0196,597.0334,74.2042,-11.8775,0,129.6099,70.2451,1.8292,0.0313,0,0,1524615,-522.8292,0,0,0,1.52E+08,0,0,50.7715,31.2639,575.6734,600.0616,625.5165,12.1182,0.0196,2.5242,-2.4811,0.1492,628.3066,600.0616,572.8834,105.4774,77.2324,50.0542,0.024,2.5242,-2.4855,600.4172,77.588,55.4232,0.4904,2.1073,77.0342,0.0627,0.0296
1,401.6,401.6,604.7972,149482.8,521,0,-0.188,523.0336,0.0404,0,0,0.0528,0.0522,0.0518,0,0,0,7.3186,0,0,100,0,0,0,0,0,0,0,0,0,0,591.9689,-47200.2,0.4005,2.5706,0,0,0,0,0,0,0,0,0,0,4.5631,0.0208,0.0104,0.0104,580.8716,57.838,81.7636,-23.9256,0.9604,0.7074,7855.609,0.0208,596.822,73.7884,-11.9628,0,-1014.014,69.8008,2.0336,0.0352,0,0,1524615,-523.0336,0,0,0,1.52E+08,0,0,50.7733,31.2666,575.2399,599.9081,625.3593,12.2341,0.0208,2.5289,-2.4865,0.1505,628.1862,599.9081,572.413,105.1526,76.8745,49.3794,0.0253,2.5289,-2.491,600.1691,77.1355,55.7732,0.493,2.1295,76.9892,0.0632,0.0298
1,409.8,409.8,604.8021,149556.5,521,0,-0.1887,523.6473,0.0446,0,0,0.0528,0.0522,0.0518,0,0,0,7.3028,0,0,100,0,0,0,0,0,0,0,0,0,0,592.1802,-47289.69,0.1573,-0.3961,0,0,0,0,0,0,0,0,0,0,4.5625,0.023,0.0115,0.0115,580.7824,57.1351,81.1549,-24.0197,0.9603,0.704,7855.782,0.023,596.7956,73.1483,-12.0099,0,-1455.11,69.145,2.6473,0.0463,0,0,1524615,-523.6473,0,0,0,1.52E+08,0,0,50.7753,31.2693,574.9815,599.9916,625.0358,-1.885,0.023,2.5326,-2.4921,0.0591,625.1067,599.9916,574.9106,101.4594,76.3443,51.2633,0.0237,2.5326,-2.4928,600.0029,76.3557,50.1961,0.4997,1.9792,-87.8464,0.0635,0.0117
1,418,418,605.1066,149610.4,521,0,-0.1878,523.135,0.0367,0,0,0.0528,0.0522,0.0518,0,0,0,7.3215,0,0,100,0,0,0,0,0,0,0,0,0,0,592.1629,-47329.75,-0.0248,-2.9162,0,0,0,0,0,0,0,0,0,0,4.5656,0.0189,0.0095,0.0095,581.2009,58.0659,81.9716,-23.9057,0.9605,0.7084,7855.459,0.0189,597.1381,74.0031,-11.9529,0,61.8672,70.0188,2.135,0.0368,0,0,1524615,-523.135,0,0,0,1.52E+08,0,0,50.7749,31.2697,575.6606,600.1733,625.8574,-13.8785,0.0189,2.5368,-2.4921,-0.0093,629.439,600.1733,572.079,106.304,77.0383,48.944,0.0189,2.5368,-2.4921,600.5638,77.4288,57.36,0.4898,2.172,-75.5295,0.0636,-0.0019
1,426.2,426.2,605.0113,149726.3,521,0,-0.1875,523.733,0.0415,0,0,0.0528,0.0522,0.0518,0,0,0,7.3181,0,0,100,0,0,0,0,0,0,0,0,0,0,592.0315,-47463.7,0.0451,-2.0902,0,0,0,0,0,0,0,0,0,0,4.5653,0.0214,0.0107,0.0107,581.1481,57.4151,81.2783,-23.8632,0.9606,0.7064,7855.656,0.0214,597.0569,73.3239,-11.9316,0,94.9416,69.3467,2.733,0.0476,0,0,1524615,-523.733,0,0,0,1.52E+08,0,0,50.7777,31.2736,575.6497,600.064,625.8236,-9.9464,0.0214,2.5425,-2.5,0.017,627.7234,600.064,573.7499,103.9904,76.3311,50.0169,0.0215,2.5425,-2.5001,600.5124,76.7795,53.9735,0.4875,2.0791,-79.1864,0.0639,0.0034
1,434.4,434.4,604.7894,149767.3,522,0,-0.1871,524.0093,0.0419,0,0,0.0528,0.0522,0.0518,0,0,0,7.3295,0,0,100,0,0,0,0,0,0,0,0,0,0,592.1671,-47528.18,0.3071,1.1148,0,0,0,0,0,0,0,0,0,0,4.5639,0.0216,0.0108,0.0108,580.9688,56.9595,80.7802,-23.8206,0.9606,0.7051,7855.672,0.0216,596.8492,72.8399,-11.9103,0,-743.5228,68.8699,2.0093,0.0353,0,0,1524615,-524.0093,0,0,0,1.52E+08,0,0,50.7788,31.2753,575.2899,599.9784,625.0303,5.3047,0.0216,2.5457,-2.5033,0.1154,625.5897,599.9784,574.7305,101.5804,75.9691,50.7213,0.0242,2.5457,-2.5059,600.0995,76.0903,50.8591,0.4964,2.0027,83.9797,0.064,0.0228
1,442.6,442.6,604.9595,149826.1,522,0,-0.1881,523.7247,0.0365,0,0,0.0528,0.0522,0.0518,0,0,0,7.3217,0,0,100,0,0,0,0,0,0,0,0,0,0,592.0433,-47589.55,0.4511,3.0558,0,0,0,0,0,0,0,0,0,0,4.5641,0.0188,0.0094,0.0094,581.0105,57.2858,81.2348,-23.949,0.9604,0.7052,7855.452,0.0188,596.9765,73.2518,-11.9745,0,128.9092,69.2603,1.7247,0.0301,0,0,1524615,-523.7247,0,0,0,1.52E+08,0,0,50.7791,31.2765,575.4405,600.0363,625.6733,14.541,0.0188,2.5504,-2.5051,0.1696,629.5789,600.0363,571.5349,105.8542,76.3117,47.8102,0.0245,2.5504,-2.5108,600.3834,76.6587,58.044,0.491,2.2141,74.9658,0.0641,0.0333
1,450.8,450.8,605.1778,149960.8,523,0,-0.1841,524.7225,0.044,0,0,0.0528,0.0522,0.0518,0,0,0,7.3106,0,0,100,0,0,0,0,0,0,0,0,0,0,592.0674,-47710.96,0.3136,1.5129,0,0,0,0,0,0,0,0,0,0,4.57,0.0227,0.0114,0.0114,581.7389,57.0164,80.4553,-23.4389,0.9613,0.7087,7855.758,0.0227,597.3648,72.6423,-11.7195,0,54.1093,68.7359,1.7225,0.0302,0,0,1524615,-524.7225,0,0,0,1.52E+08,0,0,50.7821,31.2803,576.5763,600.1804,626.2065,7.1983,0.0227,2.5546,-2.5132,0.1179,627.2294,600.1804,575.5533,102.5069,75.458,50.8308,0.0254,2.5546,-2.5159,600.9877,76.2652,51.6761,0.4766,2.0166,81.9119,0.0641,0.0231
1,459,459,605.0425,149975.4,522,0,-0.1876,524.2386,0.0396,0,0,0.0528,0.0522,0.0518,0,0,0,7.3175,0,0,100,0,0,0,0,0,0,0,0,0,0,592.2395,-47732.63,0.0633,-1.7856,0,0,0,0,0,0,0,0,0,0,4.5654,0.0204,0.0102,0.0102,581.1667,56.9281,80.8039,-23.8758,0.9605,0.7045,7855.578,0.0204,597.0839,72.8453,-11.9379,0,84.1529,68.866,2.2386,0.0393,0,0,1524615,-524.2386,0,0,0,1.52E+08,0,0,50.7818,31.2805,575.5561,600.1622,625.5787,-8.496,0.0204,2.5573,-2.5131,0.0238,626.9823,600.1622,574.1525,102.7437,75.9236,49.9139,0.0205,2.5573,-2.5132,600.4324,76.1937,52.8298,0.4923,2.0584,-80.619,0.0646,0.0047
1,467.2,467.2,604.887,150039.4,522,0,-0.1872,524.1085,0.0352,0,0,0.0528,0.0522,0.0518,0,0,0,7.3195,0,0,100,0,0,0,0,0,0,0,0,0,0,592.0164,-47809.27,-0.0315,-2.9987,0,0,0,0,0,0,0,0,0,0,4.5644,0.0181,0.0091,0.0091,581.0528,56.9443,80.7785,-23.8342,0.9606,0.7049,7855.397,0.0181,596.9423,72.8338,-11.9171,0,263.6844,68.8614,2.1085,0.037,0,0,1524615,-524.1085,0,0,0,1.52E+08,0,0,50.7825,31.2821,575.5219,599.9809,625.5338,-14.2679,0.0181,2.562,-2.5158,-0.0118,629.3179,599.9809,571.7377,105.2094,75.8724,47.6292,0.0181,2.562,-2.5158,600.3455,76.237,57.5802,0.4905,2.2089,-75.1459,0.0643,-0.0023
1,475.4,475.4,604.8686,150125,523,0,-0.1874,525.1199,0.0427,0,0,0.0528,0.0522,0.0518,0,0,0,7.3096,0,0,100,0,0,0,0,0,0,0,0,0,0,592.0194,-47937.56,0.1665,-0.7428,0,0,0,0,0,0,0,0,0,0,4.5643,0.022,0.011,0.011,581.0174,55.8975,79.7487,-23.8512,0.9606,0.7009,7855.703,0.022,596.9182,71.7983,-11.9256,0,373.0057,67.8231,2.1199,0.0379,0,0,1524615,-525.1199,0,0,0,1.52E+08,0,0,50.7855,31.2861,575.4536,599.9704,625.4846,-3.5339,0.022,2.5673,-2.5241,0.0626,625.733,599.9704,575.2053,100.6131,74.8505,50.0855,0.0228,2.5673,-2.5249,600.3029,75.183,50.5276,0.4901,2.0088,-85.9796,0.0652,0.0123
1,483.6,483.6,604.9857,150175.8,523,0,-0.1879,524.8609,0.0358,0,0,0.0528,0.0522,0.0518,0,0,0,7.3128,0,0,100,0,0,0,0,0,0,0,0,0,0,592.2568,-47971.99,0.3971,2.324,0,0,0,0,0,0,0,0,0,0,4.5645,0.0184,0.0092,0.0092,581.0637,56.2028,80.1248,-23.922,0.9605,0.7014,7855.42,0.0184,597.0117,72.1508,-11.961,0,115.7563,68.1638,1.8609,0.0331,0,0,1524615,-524.8609,0,0,0,1.52E+08,0,0,50.7852,31.2864,575.3969,600.1334,625.4097,11.0567,0.0184,2.5704,-2.5241,0.1493,627.7451,600.1334,573.0616,102.8842,75.2725,48.2007,0.0228,2.5704,-2.5285,600.3134,75.4525,54.6835,0.4951,2.1345,78.0736,0.0647,0.0291
1,491.8,491.8,605.134,150284,523,0,-0.1868,525.1542,0.0367,0,0,0.0528,0.0522,0.0518,0,0,0,7.3163,0,0,100,0,0,0,0,0,0,0,0,0,0,591.752,-48070.92,0.4341,2.7686,0,0,0,0,0,0,0,0,0,0,4.5668,0.0189,0.0095,0.0095,581.3537,56.1995,79.9798,-23.7803,0.9607,0.7027,7855.459,0.0189,597.2072,72.053,-11.8902,0,62.8935,68.0897,2.1542,0.0383,0,0,1524615,-525.1542,0,0,0,1.52E+08,0,0,50.7869,31.2891,576.1649,600.0325,626.6087,13.1713,0.0189,2.5757,-2.5294,0.1632,629.8408,600.0325,572.9329,104.6866,74.8783,47.7788,0.0241,2.5757,-2.5346,600.9354,75.7812,56.9078,0.4762,2.1911,76.2128,0.0652,0.0317
1,500,500,604.9022,150341.7,524,0,-0.1875,525.8381,0.0427,0,0,0.0528,0.0522,0.0518,0,0,0,7.3151,0,0,100,0,0,0,0,0,0,0,0,0,0,592.2944,-48164.79,0.1935,0.0299,0,0,0,0,0,0,0,0,0,0,4.5644,0.022,0.011,0.011,581.0301,55.192,79.0642,-23.8721,0.9605,0.6981,7855.703,0.022,596.9448,71.1068,-11.9361,0,237.6045,67.1281,1.8381,0.0333,0,0,1524615,-525.8381,0,0,0,1.52E+08,0,0,50.7892,31.2921,575.3227,600.0957,625.1374,0.1422,0.022,2.5794,-2.5357,0.0728,625.1378,600.0957,575.3223,99.2997,74.2576,49.4843,0.023,2.5794,-2.5367,600.1853,74.3472,49.8154,0.4973,2.0067,89.8364,0.0657,0.0142
1,508.2,508.2,604.9108,150390.2,523,0,-0.1858,525.0771,0.034,0,0,0.0528,0.0522,0.0518,0,0,0,7.3021,0,0,100,0,0,0,0,0,0,0,0,0,0,592.1545,-48192.91,-0.009,-2.7305,0,0,0,0,0,0,0,0,0,0,4.566,0.0175,0.0088,0.0088,581.2599,56.1828,79.8337,-23.6509,0.9609,0.7037,7855.35,0.0175,597.0272,71.9501,-11.8255,0,208.3613,68.0083,2.0771,0.037,0,0,1524615,-525.0771,0,0,0,1.52E+08,0,0,50.7885,31.2921,575.759,600.0477,625.3849,-12.9896,0.0175,2.583,-2.5348,-0.0034,628.5793,600.0477,572.5645,103.5022,74.9706,47.4874,0.0175,2.583,-2.5348,600.3972,75.3201,56.0148,0.4906,2.1796,-76.184,0.0657,-0.0007
1,516.4,516.4,604.915,150491.5,523,0,-0.1876,525.575,0.0373,0,0,0.0528,0.0522,0.0518,0,0,0,7.3115,0,0,100,0,0,0,0,0,0,0,0,0,0,591.9398,-48320.05,0.0273,-2.395,0,0,0,0,0,0,0,0,0,0,4.5643,0.0192,0.0096,0.0096,581.0336,55.4586,79.34,-23.8814,0.9605,0.699,7855.483,0.0192,596.9545,71.3795,-11.9407,0,204.6963,67.3993,2.575,0.0464,0,0,1524615,-525.575,0,0,0,1.52E+08,0,0,50.791,31.2957,575.5413,599.9681,625.7438,-11.3925,0.0192,2.5888,-2.5421,0.0103,628.2081,599.9681,573.077,102.6331,74.3931,47.502,0.0192,2.5888,-2.5421,600.4178,74.8427,55.1311,0.4878,2.1606,-77.7942,0.0659,0.002
1,524.6,524.6,604.9943,150543.3,524,0,-0.188,526.1456,0.0396,0,0,0.0528,0.0522,0.0518,0,0,0,7.3125,0,0,100,0,0,0,0,0,0,0,0,0,0,592.081,-48398.27,0.2981,0.7405,0,0,0,0,0,0,0,0,0,0,4.5646,0.0204,0.0102,0.0102,581.0648,54.9192,78.8487,-23.9295,0.9604,0.6965,7855.578,0.0204,597.0178,70.8722,-11.9648,0,117.3643,66.884,2.1456,0.0391,0,0,1524615,-526.1456,0,0,0,1.52E+08,0,0,50.7926,31.2979,575.5048,600.071,625.7262,3.5222,0.0204,2.592,-2.5466,0.1121,625.972,600.071,575.259,99.8264,73.9254,49.1133,0.0228,2.592,-2.549,600.434,74.2884,50.7131,0.4893,2.0326,86.0077,0.0658,0.0217
1,532.8,532.8,604.9235,150601.3,524,0,-0.1886,525.8491,0.0325,0,0,0.0528,0.0522,0.0518,0,0,0,7.3163,0,0,100,0,0,0,0,0,0,0,0,0,0,592.1635,-48453.38,0.4691,3.0034,0,0,0,0,0,0,0,0,0,0,4.5632,0.0167,0.0083,0.0083,580.9081,55.059,79.0744,-24.0154,0.9603,0.6963,7855.287,0.0167,596.9184,71.0693,-12.0077,0,191.1197,67.0667,1.8491,0.0336,0,0,1524615,-525.8491,0,0,0,1.52E+08,0,0,50.7925,31.2988,575.2201,600.0585,625.4108,14.2862,0.0167,2.5972,-2.5475,0.1764,629.1923,600.0585,571.4386,103.3432,74.2094,45.5895,0.0228,2.5972,-2.5536,600.2298,74.3807,57.7537,0.4956,2.2668,75.1741,0.0664,0.034
1,541,541,605.1296,150707.7,524,0,-0.1866,526.4547,0.0394,0,0,0.0528,0.0522,0.0518,0,0,0,7.3175,0,0,100,0,0,0,0,0,0,0,0,0,0,592.08,-48579.08,0.3577,1.8087,0,0,0,0,0,0,0,0,0,0,4.567,0.0203,0.0102,0.0102,581.3709,54.9162,78.6749,-23.7587,0.9607,0.698,7855.57,0.0203,597.21,70.7553,-11.8794,0,67.9044,66.7956,2.4547,0.0447,0,0,1524615,-526.4547,0,0,0,1.52E+08,0,0,50.7955,31.3027,576.0043,600.1539,626.0854,8.6024,0.0203,2.602,-2.5557,0.1345,627.5218,600.1539,574.5678,101.0671,73.6992,48.1131,0.0238,2.602,-2.5592,600.7478,74.2931,52.954,0.4832,2.1006,80.5202,0.0666,0.026
1,549.2,549.2,605.1707,150771.2,524,0,-0.1875,526.4223,0.0371,0,0,0.0528,0.0522,0.0518,0,0,0,7.3009,0,0,100,0,0,0,0,0,0,0,0,0,0,592.3882,-48611.67,0.0866,-1.4859,0,0,0,0,0,0,0,0,0,0,4.5664,0.0191,0.0096,0.0096,581.3015,54.8792,78.7484,-23.8692,0.9606,0.6969,7855.476,0.0191,597.2143,70.792,-11.9346,0,59.963,66.8138,2.4223,0.0441,0,0,1524615,-526.4223,0,0,0,1.52E+08,0,0,50.7957,31.3033,575.7029,600.2969,625.6985,-7.0671,0.0191,2.6041,-2.5567,0.0326,626.6782,600.2969,574.7231,100.2559,73.8746,48.3008,0.0193,2.6041,-2.5569,600.5661,74.1438,51.9551,0.4922,2.0757,-82.107,0.0665,0.0063
1,557.4,557.4,604.8656,150803.1,524,0,-0.1871,525.7961,0.0304,0,0,0.0528,0.0522,0.0518,0,0,0,7.3054,0,0,100,0,0,0,0,0,0,0,0,0,0,592.4296,-48671.84,-0.0349,-3.0366,0,0,0,0,0,0,0,0,0,0,4.5642,0.0157,0.0079,0.0079,581.0412,55.2451,79.0695,-23.8244,0.9606,0.6987,7855.208,0.0157,596.9241,71.128,-11.9122,0,408.3321,67.1573,1.7961,0.0325,0,0,1524615,-525.7961,0,0,0,1.52E+08,0,0,50.7958,31.3044,575.2646,600.1238,624.8385,-14.4428,0.0157,2.6094,-2.5581,-0.0131,628.7393,600.1238,571.3638,102.9432,74.3277,45.5677,0.0157,2.6094,-2.5581,600.0756,74.2795,57.3755,0.5013,2.2591,-74.8858,0.067,-0.0025
1,565.6,565.6,605.087,150896,525,0,-0.1873,527.1214,0.0387,0,0,0.0528,0.0522,0.0518,0,0,0,7.316,0,0,100,0,0,0,0,0,0,0,0,0,0,592.0916,-48801.42,0.1451,-1.142,0,0,0,0,0,0,0,0,0,0,4.566,0.0199,0.01,0.01,581.246,54.1246,77.9656,-23.841,0.9606,0.6942,7855.538,0.0199,597.14,70.0186,-11.9205,0,80.9865,66.0451,2.1214,0.0392,0,0,1524615,-527.1214,0,0,0,1.52E+08,0,0,50.7989,31.3084,575.792,600.1317,625.962,-5.431,0.0199,2.6141,-2.5665,0.0546,626.5432,600.1317,575.2108,99.4218,73.0103,48.0894,0.0205,2.6141,-2.5671,600.6286,73.5072,51.3324,0.4855,2.0674,-83.8919,0.0675,0.0105
1,573.8,573.8,604.8754,150944.4,525,0,-0.1869,526.8661,0.0325,0,0,0.0528,0.0522,0.0518,0,0,0,7.3188,0,0,100,0,0,0,0,0,0,0,0,0,0,592.1725,-48833.94,0.3983,2.0636,0,0,0,0,0,0,0,0,0,0,4.5646,0.0167,0.0083,0.0083,581.0864,54.2203,78.0093,-23.789,0.9607,0.695,7855.287,0.0167,596.9457,70.0796,-11.8945,0,359.7328,66.1148,1.8661,0.0344,0,0,1524615,-526.8661,0,0,0,1.52E+08,0,0,50.7987,31.3088,575.4802,600.0316,625.2816,9.8141,0.0167,2.6173,-2.5668,0.1498,627.1459,600.0316,573.616,100.2798,73.1655,46.7499,0.021,2.6173,-2.5711,600.2645,73.3984,53.5299,0.4935,2.145,79.2446,0.0672,0.0288
1,582,582,605.0817,151037.1,525,0,-0.1877,526.7424,0.0312,0,0,0.0528,0.0522,0.0518,0,0,0,7.3028,0,0,100,0,0,0,0,0,0,0,0,0,0,591.959,-48929.74,0.468,2.9156,0,0,0,0,0,0,0,0,0,0,4.5654,0.0161,0.0081,0.0081,581.1917,54.4493,78.3394,-23.89,0.9605,0.695,7855.24,0.0161,597.1184,70.376,-11.945,0,81.1592,66.3944,1.7424,0.032,0,0,1524615,-526.7424,0,0,0,1.52E+08,0,0,50.8001,31.3112,575.7856,600.0777,626.165,13.8655,0.0161,2.6225,-2.5713,0.176,629.7289,600.0777,572.2216,102.9865,73.3353,45.4793,0.0221,2.6225,-2.5773,600.6761,73.9337,57.5072,0.4844,2.2645,75.5849,0.0673,0.0337
1,590.2,590.2,604.8712,151133.3,526,0,-0.188,527.757,0.0386,0,0,0.0528,0.0522,0.0518,0,0,0,7.3083,0,0,100,0,0,0,0,0,0,0,0,0,0,592.0583,-49034.88,0.234,0.3788,0,0,0,0,0,0,0,0,0,0,4.5636,0.0199,0.01,0.01,580.9405,53.1835,77.1142,-23.9307,0.9604,0.6897,7855.538,0.0199,596.8943,69.1373,-11.9654,0,402.4399,65.1489,1.757,0.033,0,0,1524615,-527.757,0,0,0,1.52E+08,0,0,50.8027,31.3145,575.3284,599.9852,625.4597,1.8012,0.0199,2.6262,-2.5783,0.088,625.5243,599.9852,575.2638,97.7673,72.2282,47.5068,0.0214,2.6262,-2.5798,600.2578,72.5008,50.2605,0.4919,2.058,87.9449,0.0678,0.0169
1,598.4,598.4,604.7955,151150.1,525,0,-0.1874,526.8818,0.0294,0,0,0.0528,0.0522,0.0518,0,0,0,7.3047,0,0,100,0,0,0,0,0,0,0,0,0,0,592.3237,-49049.93,0.009,-2.5793,0,0,0,0,0,0,0,0,0,0,4.5634,0.0151,0.0076,0.0076,580.9429,54.0611,77.9137,-23.8526,0.9606,0.6939,7855.161,0.0151,596.8446,69.9628,-11.9263,0,-1122.994,65.9874,1.8818,0.0348,0,0,1524615,-526.8818,0,0,0,1.52E+08,0,0,50.8018,31.3142,575.1614,600.0396,624.8361,-12.2656,0.0151,2.6294,-2.5768,0.0034,627.6997,600.0396,572.2979,100.8179,73.1578,45.4161,0.0151,2.6294,-2.5768,600.0124,73.1306,55.4018,0.5007,2.2199,-76.8591,0.0677,0.0007
1,606.6,606.6,604.9545,151246.8,525,0,-0.1878,527.2723,0.0312,0,0,0.0528,0.0522,0.0518,0,0,0,7.3174,0,0,100,0,0,0,0,0,0,0,0,0,0,592.0403,-49175.12,0.0101,-2.5713,0,0,0,0,0,0,0,0,0,0,4.5643,0.0161,0.0081,0.0081,581.0517,53.7794,77.6823,-23.9028,0.9605,0.6923,7855.24,0.0161,596.9869,69.7146,-11.9514,0,158.8768,65.7309,2.2723,0.0423,0,0,1524615,-527.2723,0,0,0,1.52E+08,0,0,50.804,31.3176,575.514,600.0296,625.7097,-12.2267,0.0161,2.6357,-2.5835,0.0038,628.5295,600.0296,572.6942,101.2572,72.7573,45.4219,0.0161,2.6357,-2.5835,600.4178,73.1455,55.8353,0.4896,2.2293,-77.0132,0.0683,0.0007
1,614.8,614.8,604.8546,151330.6,526,0,-0.1874,528.0588,0.0356,0,0,0.0528,0.0522,0.0518,0,0,0,7.3036,0,0,100,0,0,0,0,0,0,0,0,0,0,592.3792,-49278.28,0.2869,0.3927,0,0,0,0,0,0,0,0,0,0,4.564,0.0183,0.0092,0.0092,581.0007,52.9419,76.7958,-23.8539,0.9606,0.6894,7855.413,0.0183,596.9033,68.8445,-11.927,0,578.1813,64.8689,2.0588,0.0389,0,0,1524615,-528.0588,0,0,0,1.52E+08,0,0,50.8062,31.3206,575.2268,600.0969,624.9073,1.8672,0.0183,2.6399,-2.5897,0.1079,624.9774,600.0969,575.1567,96.9186,72.0382,47.0979,0.0205,2.6399,-2.5919,600.077,72.0182,49.8207,0.5006,2.0578,87.8506,0.0685,0.0206
1,623,623,604.9521,151387.8,525,0,-0.1899,527.4023,0.0267,0,0,0.0528,0.0522,0.0518,0,0,0,7.3094,0,0,100,0,0,0,0,0,0,0,0,0,0,591.8022,-49317.18,0.4804,2.891,0,0,0,0,0,0,0,0,0,0,4.562,0.0138,0.0069,0.0069,580.7722,53.3699,77.5498,-24.1799,0.96,0.6882,7855.059,0.0138,596.8922,69.4899,-12.09,0,162.6512,65.4599,2.4023,0.045,0,0,1524615,-527.4023,0,0,0,1.52E+08,0,0,50.8058,31.321,575.2394,599.9371,626.09,13.7464,0.0138,2.6441,-2.5897,0.1807,629.5681,599.9371,571.7612,102.1658,72.5348,44.359,0.0201,2.6441,-2.596,600.4221,73.0199,57.8068,0.4874,2.3032,75.8009,0.0682,0.0343
1,631.2,631.2,605.3091,151484.3,526,0,-0.1873,528.2725,0.0331,0,0,0.0528,0.0522,0.0518,0,0,0,7.3285,0,0,100,0,0,0,0,0,0,0,0,0,0,591.9606,-49456.77,0.4016,2.0894,0,0,0,0,0,0,0,0,0,0,4.5676,0.0171,0.0086,0.0086,581.4659,53.1934,77.0366,-23.8432,0.9606,0.6905,7855.318,0.0171,597.3613,69.0888,-11.9216,0,46.9184,65.115,2.2725,0.0427,0,0,1524615,-528.2725,0,0,0,1.52E+08,0,0,50.8088,31.3251,576.2384,600.2181,626.7702,9.9338,0.0171,2.6499,-2.5981,0.1511,628.6529,600.2181,574.3557,100.3804,71.9456,46.0832,0.0215,2.6499,-2.6025,601.0756,72.8031,54.2972,0.4763,2.1782,79.2684,0.0689,0.0287
1,639.4,639.4,604.7844,151548.1,527,0,-0.1875,528.4825,0.0331,0,0,0.0528,0.0522,0.0518,0,0,0,7.3001,0,0,100,0,0,0,0,0,0,0,0,0,0,592.0546,-49504.35,0.1147,-1.1149,0,0,0,0,0,0,0,0,0,0,4.5633,0.0171,0.0086,0.0086,580.9185,52.436,76.3019,-23.8659,0.9605,0.6872,7855.318,0.0171,596.8291,68.3466,-11.933,0,-768.2124,64.369,1.4825,0.0283,0,0,1524615,-528.4825,0,0,0,1.52E+08,0,0,50.8096,31.3264,575.2952,599.9293,625.2522,-5.3005,0.0171,2.6525,-2.6006,0.0432,625.8083,599.9293,574.739,97.3258,71.4468,46.2565,0.0175,2.6525,-2.601,600.1589,71.6764,51.0693,0.4933,2.104,-84.0097,0.069,0.0082
1,647.6,647.6,605.0151,151593,526,0,-0.1865,527.7904,0.0242,0,0,0.0528,0.0522,0.0518,0,0,0,7.2936,0,0,100,0,0,0,0,0,0,0,0,0,0,591.9736,-49543.19,-0.0371,-3.0478,0,0,0,0,0,0,0,0,0,0,4.5659,0.0125,0.0063,0.0063,581.2762,53.4858,77.2247,-23.7389,0.9608,0.6926,7854.957,0.0125,597.1021,69.3117,-11.8695,0,113.4143,65.3553,1.7904,0.0335,0,0,1524615,-527.7904,0,0,0,1.52E+08,0,0,50.8091,31.3267,575.9148,600.041,625.9851,-14.4907,0.0125,2.6568,-2.6003,-0.014,629.8764,600.041,572.0235,102.086,72.2506,44.2331,0.0125,2.6568,-2.6003,600.647,72.8566,57.8529,0.4843,2.3079,-74.9686,0.069,-0.0027
1,655.8,655.8,604.6985,151707.2,527,0,-0.1882,528.7907,0.0327,0,0,0.0528,0.0522,0.0518,0,0,0,7.2939,0,0,100,0,0,0,0,0,0,0,0,0,0,591.8113,-49695.89,0.1215,-1.4687,0,0,0,0,0,0,0,0,0,0,4.5619,0.0168,0.0084,0.0084,580.7421,51.9514,75.9078,-23.9564,0.9604,0.6844,7855.295,0.0168,596.7131,67.9224,-11.9782,0,-203.6644,63.9296,1.7907,0.0345,0,0,1524615,-528.7907,0,0,0,1.52E+08,0,0,50.8126,31.3313,575.169,599.7831,625.4247,-6.982,0.0168,2.6626,-2.6099,0.0457,626.3767,599.7831,574.217,97.586,70.9924,45.4263,0.0172,2.6626,-2.6103,600.1255,71.3349,52.1597,0.4902,2.1482,-82.2358,0.0695,0.0087
1,664,664,604.8728,151751.5,526,0,-0.1877,528.7433,0.0283,0,0,0.0528,0.0522,0.0518,0,0,0,7.2885,0,0,100,0,0,0,0,0,0,0,0,0,0,592.2799,-49732.2,0.4489,1.7836,0,0,0,0,0,0,0,0,0,0,4.5636,0.0146,0.0073,0.0073,580.9713,52.228,76.1295,-23.9015,0.9605,0.686,7855.122,0.0146,596.9056,68.1623,-11.9508,0,408.4415,64.1788,2.7433,0.0525,0,0,1524615,-528.7433,0,0,0,1.52E+08,0,0,50.8127,31.332,575.2619,600.0695,625.1267,8.4791,0.0146,2.6657,-2.6109,0.1689,626.5291,600.0695,573.8596,97.7858,71.3262,45.1163,0.02,2.6657,-2.6163,600.1528,71.4094,52.6695,0.4976,2.1674,80.6088,0.0694,0.0319
1,672.2,672.2,604.9156,151830.2,527,0,-0.1868,528.5899,0.0242,0,0,0.0528,0.0522,0.0518,0,0,0,7.2891,0,0,100,0,0,0,0,0,0,0,0,0,0,592.1004,-49817.98,0.5467,2.9975,0,0,0,0,0,0,0,0,0,0,4.5648,0.0125,0.0063,0.0063,581.1362,52.5463,76.3257,-23.7794,0.9607,0.6884,7854.957,0.0125,596.9891,68.3992,-11.8897,0,233.3927,64.436,1.5899,0.0303,0,0,1524615,-528.5899,0,0,0,1.52E+08,0,0,50.8135,31.3339,575.6204,600.0274,625.5294,14.2497,0.0125,2.6715,-2.6141,0.2057,629.3113,600.0274,571.8386,100.7214,71.4375,43.2487,0.0205,2.6715,-2.6221,600.3924,71.8025,57.4727,0.4905,2.3289,75.1362,0.0699,0.0386
1,680.4,680.4,605.1266,151926.1,528,0,-0.1875,529.662,0.0327,0,0,0.0528,0.0522,0.0518,0,0,0,7.2964,0,0,100,0,0,0,0,0,0,0,0,0,0,592.1545,-49930,0.326,0.7603,0,0,0,0,0,0,0,0,0,0,4.5659,0.0168,0.0084,0.0084,581.2512,51.5892,75.4646,-23.8754,0.9605,0.6836,7855.295,0.0168,597.1682,67.5062,-11.9377,0,78.8453,63.5269,1.662,0.0322,0,0,1524615,-529.662,0,0,0,1.52E+08,0,0,50.8164,31.3375,575.7915,600.1783,625.996,3.6139,0.0168,2.6752,-2.6218,0.1227,626.2548,600.1783,575.5327,96.5928,70.5163,45.8707,0.0196,2.6752,-2.6247,600.6553,70.9933,50.7221,0.4859,2.1058,85.9038,0.0701,0.0231
1,688.6,688.6,604.8849,151928.4,527,0,-0.1871,528.8807,0.0241,0,0,0.0528,0.0522,0.0518,0,0,0,7.2892,0,0,100,0,0,0,0,0,0,0,0,0,0,592.1319,-49946.9,0.0753,-2.35,0,0,0,0,0,0,0,0,0,0,4.5642,0.0124,0.0062,0.0062,581.0604,52.1798,76.0042,-23.8245,0.9606,0.6865,7854.949,0.0124,596.9434,68.0627,-11.9123,0,339.8971,64.092,1.8807,0.036,0,0,1524615,-528.8807,0,0,0,1.52E+08,0,0,50.8155,31.3372,575.4934,600.0203,625.4022,-11.171,0.0124,2.6784,-2.6204,0.0283,627.7885,600.0203,573.1071,98.9078,71.1397,44.2264,0.0126,2.6784,-2.6206,600.3054,71.4246,54.6814,0.4922,2.2364,-77.942,0.0704,0.0054
1,694.4,694.4,604.865,152001.6,527,0,-0.1875,529.6869,0.0278,0,0,0.0528,0.0522,0.0518,0,0,0,7.303,0,0,100,0,0,0,0,0,0,0,0,0,0,592.1004,-50050.81,0.4095,1.1166,0,0,0,0,0,0,0,0,0,0,4.5638,0.0143,0.0071,0.0071,580.9985,51.3116,75.1781,-23.8665,0.9605,0.6825,7855.098,0.0143,596.9095,67.2226,-11.9333,0,490.9513,63.2449,2.6869,0.0524,0,0,1524615,-529.6869,0,0,0,1.52E+08,0,0,50.8177,31.3402,575.4032,599.9958,625.4039,5.3074,0.0143,2.6826,-2.6265,0.1541,625.9611,599.9958,574.8461,96.2742,70.3089,45.1592,0.0188,2.6826,-2.631,600.2676,70.5808,51.115,0.492,2.1319,84.0072,0.0704,0.0289