File: datas/d100-90-0.2.csv
Stage Number,Time since start of test (s),Time since start of stage (s),Radial Pressure (kPa),Radial Volume (mm3),Back Pressure (kPa),Back Volume (mm3),Load Cell (kN),Pore Pressure (kPa),Axial Displacement (mm),L/C Pressure (kPa),L/C Volume (mm3),Local Axial 1,Local Axial 2,Local Radial,Base Pressure (kPa),Base Volume (mm3),Back Differential Pressure (kPa),Axial Displacement 2 (mm),Pore Air Pressure (kPa),Pore Air Volume (mm3),Atmospheric Pressure (kPa),Temperature (°C),Mid Plane PWP (kPa),Back to Cell Differential (kPa),Total Volume Change (mm3),Undefined Tx 1,Undefined Tx 2,Undefined Tx 3,Undefined Tx. 4,HCA secondary control axial load (kN),HCA secondary control torque,Internal Cell Pr. (kPa),Internal Cell Vol. (mm3),Rotational Displ. (mm),Torque,Local Int Defmn 1 (mm),Local Int Defmn 2 (mm),Circumf. Defmn 1 (mm),Circumf. Defmn 2 (mm),Circumf. Defmn 3 (mm),Outer Cell Pr 2 (kPa),Internal cell Pr 2 (kPa),Rotation 2 (°),Secondary Cell Pr (kPa),Secondary Back Pr (kPa),Axial Force (kN),Axial Strain (%),Av Diameter Change (mm),Radial Strain (%),Axial Stress (kPa),Eff. Axial Stress (kPa),Eff. Radial Stress (kPa),Deviator Stress (kPa),Total Stress Ratio (%),Eff. Stress Ratio (%),Current Area (mm2),Shear Strain (%),Cambridge p (kPa),Eff. Cambridge p' (kPa),Max Shear Stress t,Volume Change (mm3),B Value,Mean Stress s/Eff. Axial Stress 2,Excess PWP (kPa),PWP Ratio,Lower Chamber Displacement (mm),Lower Chamber Axial Load (kPa),Specimen Air Volume (mm3),Matric Suction (kPa),Voids ratio,Degree of Saturation (°),Specimen Water Volume (mm3),kRT constant,Permeability IN,Permeability OUT,HCA Outer Rad,HCA Inner Rad,HCA Sigma Z (kPa),HCA Sigma R (kPa),HCA Sigma Theta (kPa),HCA Tau Theta Z,HCA Ez,HCA Er,HCA Etheta,HCA Gamma,HCA Sigma1,HCA Sigma2,HCA Sigma3,HCA Eff Sigma1,HCA Eff Sigma2,HCA Eff Sigma3,HCA E1,HCA E2,HCA E3,HCA P,HCA Eff P,HCA Q,HCA B,HCA Eff R,HCA Alpha,HCA Ev,HCA E1 rtv
1,0,0,604.7632,54219.77,500,0,-0.1892,494.4378,0.0112,0,0,0.0528,0.0522,0.0518,0,0,0,3.3168,0,0,100,0,0,0,0,0,0,0,0,0,0,592.5571,81023.54,0.0023,-0.0091,0,0,0,0,0,0,0,0,0,0,4.5609,0.0057,0.0029,0.0029,580.6792,86.2414,110.3254,-24.084,0.9602,0.7817,7854.423,0.0057,596.7352,102.2974,-12.042,0,0.4614,98.2834,-5.5622,-0.0645,0,0,1536474,-494.4378,0,0,0,1.54E+08,0,0,48.6652,27.7166,572.9854,600.334,620.9127,-0.0462,0.0057,-4.5282,4.737,0.0008,620.9128,600.334,572.9854,126.475,105.8962,78.5476,4.737,-4.5282,0.0057,598.0774,103.6396,47.9274,0.5706,1.6102,-89.9448,0.2145,89.9999
1,2.4,2.4,604.9357,54378.83,501,0,-0.1872,495.0596,0.0032,0,0,0.0528,0.0522,0.0518,0,0,0,3.3119,0,0,100,0,0,0,0,0,0,0,0,0,0,592.0502,80918.37,0.2205,4.0805,0,0,0,0,0,0,0,0,0,0,4.564,0.0016,0.0008,0.0008,581.0977,86.0381,109.8761,-23.838,0.9606,0.783,7854.101,0.0016,596.9897,101.9301,-11.919,0,7.0956,97.9571,-5.9404,-0.069,0,0,1536474,-495.0596,0,0,0,1.54E+08,0,0,48.6659,27.7191,573.8818,600.2597,621.9874,20.7352,0.0016,-4.52,4.7326,0.077,629.6913,600.2597,566.1779,134.6317,105.2001,71.1183,4.7332,-4.52,0.001,598.7097,103.65,63.5134,0.5366,1.8931,69.6182,0.2142,89.9919
1,5,5,605.0297,54452.46,502,0,-0.1887,496.0239,0.0079,0,0,0.0528,0.0522,0.0518,0,0,0,3.3173,0,0,100,0,0,0,0,0,0,0,0,0,0,592.1967,80849.51,0.0257,-0.0054,0,0,0,0,0,0,0,0,0,0,4.5634,0.004,0.002,0.002,581.0074,84.9835,109.0058,-24.0223,0.9603,0.7796,7854.289,0.004,597.0223,100.9984,-12.0112,0,8.7878,96.9946,-5.9761,-0.0703,0,0,1536474,-496.0239,0,0,0,1.54E+08,0,0,48.6677,27.7215,573.654,600.3726,622.0137,-0.0274,0.004,-4.5173,4.7268,0.009,622.0137,600.3726,573.654,125.9898,104.3487,77.6301,4.7268,-4.5173,0.004,598.6801,102.6562,48.3597,0.5525,1.623,-89.9675,0.2135,89.999
1,7.6,7.6,604.9138,54500.94,503,0,-0.1876,496.8255,0.0037,0,0,0.0528,0.0522,0.0518,0,0,0,3.309,0,0,100,0,0,0,0,0,0,0,0,0,0,592.3493,80777.21,-0.2205,-4.073,0,0,0,0,0,0,0,0,0,0,4.5635,0.0019,0.0009,0.0009,581.0323,84.2068,108.0883,-23.8815,0.9605,0.7791,7854.124,0.0019,596.9533,100.1278,-11.9408,0,39.2179,96.1476,-6.1745,-0.0733,0,0,1536474,-496.8255,0,0,0,1.54E+08,0,0,48.6684,27.7233,573.6281,600.3541,621.5444,-20.6953,0.0019,-4.5123,4.7234,-0.077,629.2452,600.3541,565.9273,132.4197,103.5286,69.1018,4.724,-4.5123,0.0013,598.5089,101.6834,63.3179,0.5437,1.9163,-69.5896,0.213,90.0081
1,10.2,10.2,605.1266,54572.52,504,0,-0.1864,497.7774,0.0068,0,0,0.0528,0.0522,0.0518,0,0,0,3.305,0,0,100,0,0,0,0,0,0,0,0,0,0,592.111,80689.89,0.0135,0.5568,0,0,0,0,0,0,0,0,0,0,4.5664,0.0035,0.0018,0.0018,581.3922,83.6148,107.3492,-23.7344,0.9608,0.7789,7854.25,0.0035,597.2151,99.4377,-11.8672,0,12.098,95.482,-6.2226,-0.0744,0,0,1536474,-497.7774,0,0,0,1.54E+08,0,0,48.6702,27.7261,574.2979,600.4029,622.3568,2.829,0.0035,-4.5077,4.7171,0.0047,622.5228,600.4029,574.132,124.7454,102.6255,76.3546,4.7171,-4.5077,0.0035,599.0193,101.2418,48.3908,0.5429,1.6338,86.6427,0.2129,89.9995
1,12.8,12.8,604.9553,54620.75,504,0,-0.1885,498.7435,-0.0005,0,0,0.0528,0.0522,0.0518,0,0,0,3.3223,0,0,100,0,0,0,0,0,0,0,0,0,0,592.317,80636.68,0.2329,4.0378,0,0,0,0,0,0,0,0,0,0,4.5628,-0.0003,-0.0002,-0.0002,580.956,82.2125,106.2118,-23.9993,0.9603,0.774,7853.951,-0.0003,596.9556,98.2121,-11.9997,0,42.0831,94.2122,-5.2565,-0.0639,0,0,1536474,-498.7435,0,0,0,1.54E+08,0,0,48.6702,27.7271,573.527,600.3685,621.6876,20.5155,-0.0003,-4.5032,4.7157,0.0814,629.2419,600.3685,565.9727,130.4984,101.625,67.2292,4.7164,-4.5032,-0.001,598.5276,99.7842,63.2692,0.5436,1.9411,69.7851,0.2122,89.9914
1,15.4,15.4,604.8778,54720.17,505,0,-0.1875,499.1765,0.0065,0,0,0.0528,0.0522,0.0518,0,0,0,3.3173,0,0,100,0,0,0,0,0,0,0,0,0,0,592.1846,80560.94,-0.0297,-1.035,0,0,0,0,0,0,0,0,0,0,4.5634,0.0033,0.0017,0.0017,581.0114,81.8349,105.7013,-23.8664,0.9605,0.7742,7854.234,0.0033,596.9224,97.7459,-11.9332,0,197.3141,93.7681,-5.8235,-0.0712,0,0,1536474,-499.1765,0,0,0,1.54E+08,0,0,48.6723,27.7298,573.6771,600.2709,621.6848,-5.2582,0.0033,-4.5004,4.7092,-0.0104,622.254,600.2709,573.108,123.0775,101.0944,73.9315,4.7092,-4.5004,0.0033,598.5443,99.3678,49.146,0.5527,1.6648,-83.8221,0.2121,90.0011
1,18,18,604.9443,54740.51,506,0,-0.1878,499.9761,0,0,0,0.0528,0.0522,0.0518,0,0,0,3.3173,0,0,100,0,0,0,0,0,0,0,0,0,0,592.2109,80509.61,-0.2261,-3.9301,0,0,0,0,0,0,0,0,0,0,4.5634,0,0,0,581.0306,81.0545,104.9682,-23.9137,0.9605,0.7722,7853.975,0,596.9731,96.997,-11.9569,0,60.8878,93.0114,-6.0239,-0.0743,0,0,1536474,-499.9761,0,0,0,1.54E+08,0,0,48.6724,27.7309,573.7027,600.3226,621.8059,-19.9669,0,-4.4959,4.7075,-0.079,629.0138,600.3226,566.4948,129.0377,100.3465,66.5187,4.7082,-4.4959,-0.0007,598.6104,98.6343,62.519,0.5411,1.9399,-70.1508,0.2116,90.0084
1,20.6,20.6,604.8936,54852.88,506,0,-0.1888,501.0481,0.0031,0,0,0.0528,0.0522,0.0518,0,0,0,3.3099,0,0,100,0,0,0,0,0,0,0,0,0,0,592.0044,80428.86,0.0607,1.5074,0,0,0,0,0,0,0,0,0,0,4.5621,0.0016,0.0008,0.0008,580.8558,79.8077,103.8455,-24.0378,0.9603,0.7685,7854.101,0.0016,596.881,95.8329,-12.0189,0,165.819,91.8266,-4.9519,-0.062,0,0,1536474,-501.0481,0,0,0,1.54E+08,0,0,48.6741,27.7335,573.5295,600.2153,621.964,7.6578,0.0016,-4.4918,4.7016,0.0212,623.1459,600.2153,572.3475,122.0978,99.1672,71.2994,4.7016,-4.4918,0.0016,598.5695,97.5215,50.7984,0.5486,1.7125,81.2262,0.2114,89.9977
1,23.2,23.2,604.9913,54897.31,507,0,-0.1877,501.3732,-0.0042,0,0,0.0528,0.0522,0.0518,0,0,0,3.2974,0,0,100,0,0,0,0,0,0,0,0,0,0,592.1484,80365.64,0.2205,3.7007,0,0,0,0,0,0,0,0,0,0,4.5638,-0.0021,-0.0011,-0.0011,581.0937,79.7205,103.6181,-23.8976,0.9605,0.7694,7853.81,-0.0021,597.0254,95.6522,-11.9488,0,50.2192,91.6693,-5.6268,-0.0706,0,0,1536474,-501.3732,0,0,0,1.54E+08,0,0,48.6743,27.7348,573.8233,600.3296,622.002,18.8005,-0.0021,-4.4867,4.6996,0.077,628.4701,600.3296,567.3552,127.0969,98.9564,65.982,4.7002,-4.4867,-0.0027,598.7183,97.3451,61.1149,0.5395,1.9262,71.0149,0.2108,89.9918
1,25.8,25.8,605.0597,54963.7,508,0,-0.1881,502.1134,0.0017,0,0,0.0528,0.0522,0.0518,0,0,0,3.2851,0,0,100,0,0,0,0,0,0,0,0,0,0,592.3614,80282.57,-0.0836,-1.982,0,0,0,0,0,0,0,0,0,0,4.5641,0.0009,0.0005,0.0005,581.1145,79.0011,102.9463,-23.9452,0.9604,0.7674,7854.046,0.0009,597.0779,94.9645,-11.9726,0,37.1129,90.9737,-5.8866,-0.0745,0,0,1536474,-502.1134,0,0,0,1.54E+08,0,0,48.6764,27.7377,573.7448,600.4503,621.8812,-10.0682,0.0009,-4.4831,4.6927,-0.0292,623.9022,600.4503,571.7238,121.7888,98.3369,69.6104,4.6928,-4.4831,0.0008,598.6921,96.5787,52.1784,0.5505,1.7496,-78.6497,0.2105,90.0031
1,28.4,28.4,604.9485,55044.57,509,0,-0.1874,503.151,-0.0032,0,0,0.0528,0.0522,0.0518,0,0,0,3.3218,0,0,100,0,0,0,0,0,0,0,0,0,0,592.2095,80214.78,-0.2036,-3.4731,0,0,0,0,0,0,0,0,0,0,4.5638,-0.0016,-0.0008,-0.0008,581.0908,77.9398,101.7975,-23.8577,0.9606,0.7656,7853.849,-0.0016,596.9959,93.8449,-11.9289,0,91.7768,89.8687,-5.849,-0.075,0,0,1536474,-503.151,0,0,0,1.54E+08,0,0,48.6769,27.7393,573.7923,600.3242,621.8258,-17.6427,-0.0016,-4.4781,4.6898,-0.0711,627.6096,600.3242,568.0086,124.4586,97.1732,64.8576,4.6903,-4.4781,-0.0021,598.6475,95.4965,59.601,0.5422,1.919,-71.8495,0.2101,90.0076
1,31,31,604.8892,55100.97,509,0,-0.187,503.4881,-0.0033,0,0,0.0528,0.0522,0.0518,0,0,0,3.3017,0,0,100,0,0,0,0,0,0,0,0,0,0,592.0381,80145.3,0.1136,2.4252,0,0,0,0,0,0,0,0,0,0,4.5637,-0.0017,-0.0009,-0.0009,581.0787,77.5906,101.4011,-23.8106,0.9606,0.7652,7853.841,-0.0017,596.9524,93.4643,-11.9053,0,255.7946,89.4959,-5.5119,-0.071,0,0,1536474,-503.4881,0,0,0,1.54E+08,0,0,48.678,27.7413,573.8674,600.2241,621.9171,12.3192,-0.0017,-4.474,4.6856,0.0397,624.8914,600.2241,570.893,121.4033,96.736,67.4049,4.6858,-4.474,-0.0019,598.6695,95.1814,53.9984,0.5432,1.8011,76.4263,0.2099,89.9958
1,33.6,33.6,604.9857,55126.91,510,0,-0.1875,504.5328,-0.0096,0,0,0.0528,0.0522,0.0518,0,0,0,3.295,0,0,100,0,0,0,0,0,0,0,0,0,0,592.2643,80087.71,0.1869,3.1448,0,0,0,0,0,0,0,0,0,0,4.5638,-0.0049,-0.0024,-0.0024,581.11,76.5772,100.4529,-23.8757,0.9605,0.7623,7853.59,-0.0049,597.0272,92.4944,-11.9379,0,76.3253,88.5151,-5.4672,-0.0714,0,0,1536474,-504.5328,0,0,0,1.54E+08,0,0,48.6782,27.7426,573.8016,600.3676,621.8434,15.9747,-0.0049,-4.4689,4.6835,0.0653,626.6703,600.3676,568.9747,122.1375,95.8348,64.4419,4.684,-4.4689,-0.0054,598.6708,94.1381,57.6956,0.5441,1.8953,73.1874,0.2097,89.993
1,36.2,36.2,604.9108,55205.87,511,0,-0.1879,505.0212,-0.0065,0,0,0.0528,0.0522,0.0518,0,0,0,3.2822,0,0,100,0,0,0,0,0,0,0,0,0,0,591.8734,80006.96,-0.1395,-2.8181,0,0,0,0,0,0,0,0,0,0,4.5629,-0.0033,-0.0017,-0.0017,580.9861,75.9649,99.8896,-23.9247,0.9604,0.7605,7853.716,-0.0033,596.9359,91.9147,-11.9624,0,185.5124,87.9273,-5.9788,-0.0787,0,0,1536474,-505.0212,0,0,0,1.54E+08,0,0,48.68,27.7452,573.8009,600.1777,622.1895,-14.3142,-0.0033,-4.4653,4.6775,-0.0487,626.1068,600.1777,569.8837,121.0856,95.1565,64.8625,4.6778,-4.4653,-0.0036,598.7227,93.7015,56.2231,0.5388,1.8668,-74.695,0.2089,90.0052
1,38.8,38.8,605.0809,55295.67,511,0,-0.1882,505.7904,-0.01,0,0,0.0528,0.0522,0.0518,0,0,0,3.2934,0,0,100,0,0,0,0,0,0,0,0,0,0,591.9802,79924.96,-0.16,-2.788,0,0,0,0,0,0,0,0,0,0,4.5638,-0.0051,-0.0025,-0.0025,581.1112,75.3208,99.2905,-23.9697,0.9604,0.7586,7853.575,-0.0051,597.091,91.3006,-11.9849,0,49.8559,87.3057,-5.2096,-0.0692,0,0,1536474,-505.7904,0,0,0,1.54E+08,0,0,48.6809,27.7473,573.942,600.3247,622.4457,-14.161,-0.0051,-4.4598,4.6734,-0.0559,626.2774,600.3247,570.1103,120.487,94.5343,64.3199,4.6737,-4.4598,-0.0054,598.9041,93.1137,56.1671,0.5379,1.8732,-74.8594,0.2085,90.006
1,41.4,41.4,604.9119,55369.9,512,0,-0.1864,506.3999,-0.0134,0,0,0.0528,0.0522,0.0518,0,0,0,3.2881,0,0,100,0,0,0,0,0,0,0,0,0,0,592.4311,79853.16,0.1665,3.1814,0,0,0,0,0,0,0,0,0,0,4.5642,-0.0068,-0.0034,-0.0034,581.172,74.7721,98.512,-23.7399,0.9608,0.759,7853.441,-0.0068,596.9986,90.5987,-11.87,0,205.7961,86.6421,-5.6001,-0.0749,0,0,1536474,-506.3999,0,0,0,1.54E+08,0,0,48.6817,27.7492,573.8332,600.3806,621.4572,16.159,-0.0068,-4.4548,4.6697,0.0582,626.4224,600.3806,568.868,120.0225,93.9807,62.4681,4.6701,-4.4548,-0.0072,598.5569,92.1571,57.5544,0.5475,1.9213,72.9195,0.2081,89.9938
1,44,44,605.0906,55431.18,513,0,-0.1869,507.2879,-0.0177,0,0,0.0528,0.0522,0.0518,0,0,0,3.2804,0,0,100,0,0,0,0,0,0,0,0,0,0,592.1373,79781.8,0.1451,2.4026,0,0,0,0,0,0,0,0,0,0,4.565,-0.009,-0.0045,-0.0045,581.2867,73.9988,97.8027,-23.8039,0.9607,0.7566,7853.268,-0.009,597.1559,89.868,-11.902,0,54.1407,85.9008,-5.7121,-0.0772,0,0,1536474,-507.2879,0,0,0,1.54E+08,0,0,48.6824,27.751,574.14,600.3876,622.2641,12.2032,-0.009,-4.4498,4.6663,0.0507,625.1816,600.3876,571.2224,117.8937,93.0997,63.9345,4.6666,-4.4498,-0.0093,598.9305,91.6426,53.9592,0.5405,1.844,76.5539,0.2075,89.9946
1,46.6,46.6,605.251,55518.78,514,0,-0.1857,508.0172,-0.0171,0,0,0.0528,0.0522,0.0518,0,0,0,3.2771,0,0,100,0,0,0,0,0,0,0,0,0,0,592.2626,79692.73,-0.1946,-3.4305,0,0,0,0,0,0,0,0,0,0,4.5675,-0.0087,-0.0043,-0.0043,581.6032,73.586,97.2338,-23.6478,0.9609,0.7568,7853.292,-0.0087,597.3684,89.3512,-11.8239,0,34.1019,85.4099,-5.9828,-0.0813,0,0,1536474,-508.0172,0,0,0,1.54E+08,0,0,48.6839,27.7536,574.5572,600.535,622.4736,-17.4232,-0.0087,-4.4448,4.6607,-0.068,628.139,600.535,568.8917,120.1218,92.5178,60.8745,4.6612,-4.4448,-0.0092,599.1885,91.1714,59.2473,0.5341,1.9733,-71.987,0.2072,90.0073
1,49.2,49.2,605.0589,55594.38,514,0,-0.1887,508.8,-0.0198,0,0,0.0528,0.0522,0.0518,0,0,0,3.2765,0,0,100,0,0,0,0,0,0,0,0,0,0,592.092,79607.09,-0.1294,-2.0023,0,0,0,0,0,0,0,0,0,0,4.5629,-0.0101,-0.0051,-0.0051,581.0257,72.2257,96.2589,-24.0332,0.9603,0.7503,7853.182,-0.0101,597.0479,88.2479,-12.0166,0,69.8908,84.2423,-5.2,-0.072,0,0,1536474,-508.8,0,0,0,1.54E+08,0,0,48.685,27.7559,573.7586,600.3505,622.2555,-10.1692,-0.0101,-4.4393,4.656,-0.0452,624.3016,600.3505,571.7126,115.5016,91.5505,62.9126,4.6562,-4.4393,-0.0103,598.7883,89.9882,52.589,0.5446,1.8359,-78.624,0.2066,90.0048
1,51.8,51.8,604.8145,55644.99,515,0,-0.1843,509.2843,-0.0269,0,0,0.0528,0.0522,0.0518,0,0,0,3.2734,0,0,100,0,0,0,0,0,0,0,0,0,0,592.0689,79536.86,0.2189,3.742,0,0,0,0,0,0,0,0,0,0,4.5652,-0.0138,-0.0069,-0.0069,581.34,72.0557,95.5302,-23.4745,0.9612,0.7543,7852.891,-0.0138,596.9897,87.7054,-11.7373,0,-374.8972,83.793,-5.7157,-0.0793,0,0,1536474,-509.2843,0,0,0,1.54E+08,0,0,48.6853,27.7575,574.2826,600.1865,621.7196,19.0051,-0.0138,-4.4333,4.6534,0.0765,628.3945,600.1865,567.6077,119.1102,90.9022,58.3234,4.654,-4.4333,-0.0144,598.7296,89.4453,60.7868,0.536,2.0422,70.6478,0.2063,89.9918
1,54.4,54.4,604.7321,55753.41,516,0,-0.1878,510.2377,-0.0267,0,0,0.0528,0.0522,0.0518,0,0,0,3.2664,0,0,100,0,0,0,0,0,0,0,0,0,0,592.1696,79450.48,0.1108,1.495,0,0,0,0,0,0,0,0,0,0,4.5611,-0.0136,-0.0068,-0.0068,580.8167,70.579,94.4944,-23.9154,0.9605,0.7469,7852.907,-0.0136,596.7603,86.5226,-11.9577,0,-129.2834,82.5367,-5.7623,-0.0816,0,0,1536474,-510.2377,0,0,0,1.54E+08,0,0,48.6868,27.7601,573.4168,600.1703,621.3968,7.5925,-0.0136,-4.4283,4.6478,0.0387,622.5696,600.1703,572.244,112.3319,89.9326,62.0063,4.648,-4.4283,-0.0138,598.3279,88.0903,50.3256,0.5549,1.8116,81.2191,0.2059,89.9959
1,57,57,604.8344,55831.6,517,0,-0.1872,510.7943,-0.0317,0,0,0.0528,0.0522,0.0518,0,0,0,3.2716,0,0,100,0,0,0,0,0,0,0,0,0,0,592.4673,79359.09,-0.2441,-3.8547,0,0,0,0,0,0,0,0,0,0,4.5624,-0.0162,-0.0081,-0.0081,580.9974,70.2031,94.0401,-23.837,0.9606,0.7465,7852.703,-0.0162,596.8887,86.0944,-11.9185,0,-832.7056,82.1216,-6.2057,-0.0884,0,0,1536474,-510.7943,0,0,0,1.54E+08,0,0,48.6877,27.7624,573.5446,600.3434,621.2424,-19.5763,-0.0162,-4.4219,4.6434,-0.0853,628.248,600.3434,566.539,117.4537,89.5491,55.7447,4.6442,-4.4219,-0.017,598.3768,87.5825,61.709,0.5478,2.107,-70.3096,0.2053,90.0091
1,59.6,59.6,604.807,55898,518,0,-0.1889,512.0754,-0.0309,0,0,0.0528,0.0522,0.0518,0,0,0,3.2798,0,0,100,0,0,0,0,0,0,0,0,0,0,592.2784,79264.63,-0.0878,-1.033,0,0,0,0,0,0,0,0,0,0,4.5605,-0.0158,-0.0079,-0.0079,580.7531,68.6777,92.7316,-24.0539,0.9602,0.7406,7852.734,-0.0158,596.7891,84.7138,-12.027,0,-374.3994,80.7047,-5.9246,-0.0863,0,0,1536474,-512.0754,0,0,0,1.54E+08,0,0,48.6893,27.7652,573.258,600.2571,621.4319,-5.2459,-0.0158,-4.4164,4.6374,-0.0307,621.9965,600.2571,572.6934,109.9211,88.1817,60.618,4.6375,-4.4164,-0.0159,598.3157,86.2403,49.3031,0.5591,1.8133,-83.8567,0.2052,90.0033
1,62.2,62.2,605.0359,55952.57,518,0,-0.187,512.2277,-0.0434,0,0,0.0528,0.0522,0.0518,0,0,0,3.2468,0,0,100,0,0,0,0,0,0,0,0,0,0,591.9795,79192.58,0.2644,4.0419,0,0,0,0,0,0,0,0,0,0,4.5639,-0.0222,-0.0111,-0.0111,581.2233,68.9956,92.8082,-23.8126,0.9606,0.7434,7852.232,-0.0222,597.0984,84.8707,-11.9063,0,97.5784,80.9019,-5.7723,-0.0837,0,0,1536474,-512.2277,0,0,0,1.54E+08,0,0,48.689,27.7664,574.1179,600.2942,622.363,20.527,-0.0222,-4.4096,4.6362,0.0924,629.9147,600.2942,566.5663,117.687,88.0665,54.3386,4.6371,-4.4096,-0.0231,598.925,86.6974,63.3484,0.5324,2.1658,69.802,0.2044,89.9901
1,64.8,64.8,604.9435,56075.75,519,0,-0.1881,513.3228,-0.0387,0,0,0.0528,0.0522,0.0518,0,0,0,3.2415,0,0,100,0,0,0,0,0,0,0,0,0,0,592.144,79092.43,0.0653,0.5017,0,0,0,0,0,0,0,0,0,0,4.5622,-0.0198,-0.0099,-0.0099,580.9928,67.67,91.6207,-23.9507,0.9604,0.7386,7852.42,-0.0198,596.9599,83.6371,-11.9754,0,210.5904,79.6454,-5.6772,-0.0839,0,0,1536474,-513.3228,0,0,0,1.54E+08,0,0,48.6913,27.7697,573.6851,600.2949,621.9326,2.5477,-0.0198,-4.405,4.6285,0.0228,622.0668,600.2949,573.5509,108.744,86.9721,60.2281,4.6286,-4.405,-0.0199,598.6375,85.3147,48.5159,0.5512,1.8055,86.9857,0.2037,89.9975
1,67.4,67.4,605.0535,56152.43,520,0,-0.1876,513.9855,-0.0492,0,0,0.0528,0.0522,0.0518,0,0,0,3.2664,0,0,100,0,0,0,0,0,0,0,0,0,0,591.9027,79012.3,-0.2858,-4.0904,0,0,0,0,0,0,0,0,0,0,4.5633,-0.0251,-0.0125,-0.0125,581.1638,67.1783,91.0681,-23.8897,0.9605,0.7377,7852.004,-0.0251,597.0903,83.1048,-11.9449,0,97.7616,79.1232,-6.0145,-0.0895,0,0,1536474,-513.9855,0,0,0,1.54E+08,0,0,48.6913,27.7713,574.063,600.2771,622.5112,-20.7722,-0.0251,-4.3977,4.6263,-0.0999,630.1978,600.2771,566.3764,116.2123,86.2916,52.3909,4.6274,-4.3977,-0.0262,598.9504,84.9649,63.8214,0.5312,2.2182,-69.6934,0.2035,90.0107
1,70,70,604.9521,56228.2,521,0,-0.1876,514.8849,-0.0452,0,0,0.0528,0.0522,0.0518,0,0,0,3.2322,0,0,100,0,0,0,0,0,0,0,0,0,0,592.2634,78909.15,-0.0405,-0.0038,0,0,0,0,0,0,0,0,0,0,4.5626,-0.0231,-0.0115,-0.0115,581.063,66.1781,90.0672,-23.8891,0.9605,0.7348,7852.161,-0.0231,596.9891,82.1042,-11.9446,0,208.0389,78.1227,-6.1151,-0.0924,0,0,1536474,-514.8849,0,0,0,1.54E+08,0,0,48.6935,27.7746,573.7408,600.3433,621.7992,-0.0193,-0.0231,-4.3927,4.6188,-0.0142,621.7993,600.3433,573.7408,106.9144,85.4584,58.8559,4.6188,-4.3927,-0.0231,598.6277,83.7429,48.0585,0.5535,1.8165,-89.977,0.203,90.0015
1,72.6,72.6,604.9084,56313.27,521,0,-0.1876,515.1448,-0.0619,0,0,0.0528,0.0522,0.0518,0,0,0,3.2218,0,0,100,0,0,0,0,0,0,0,0,0,0,592.4259,78833.28,0.2952,4.0833,0,0,0,0,0,0,0,0,0,0,4.5618,-0.0316,-0.0158,-0.0158,581.0104,65.8656,89.7636,-23.898,0.9605,0.7338,7851.494,-0.0316,596.9424,81.7976,-11.949,0,379.9961,77.8146,-5.8552,-0.0889,0,0,1536474,-515.1448,0,0,0,1.54E+08,0,0,48.6927,27.7756,573.5954,600.3744,621.4838,20.7361,-0.0316,-4.3844,4.6185,0.1032,629.2147,600.3744,565.8645,114.0699,85.2296,50.7197,4.6196,-4.3844,-0.0327,598.4846,83.3397,63.3502,0.5447,2.249,69.5534,0.2025,89.9889
1,75.2,75.2,604.8412,56411.35,522,0,-0.1864,516.4899,-0.0535,0,0,0.0528,0.0522,0.0518,0,0,0,3.2161,0,0,100,0,0,0,0,0,0,0,0,0,0,592.2949,78716.23,0.009,-0.5289,0,0,0,0,0,0,0,0,0,0,4.5627,-0.0273,-0.0136,-0.0136,581.1001,64.6102,88.3513,-23.7411,0.9607,0.7313,7851.832,-0.0273,596.9275,80.4376,-11.8706,0,-1717.217,76.4808,-5.5101,-0.0853,0,0,1536474,-516.4899,0,0,0,1.54E+08,0,0,48.6957,27.7797,573.8009,600.2838,621.5046,-2.6856,-0.0273,-4.3794,4.6088,0.0031,621.6553,600.2838,573.6501,105.1653,83.7939,57.1602,4.6088,-4.3794,-0.0273,598.5297,82.0398,48.0051,0.5548,1.8398,-86.7879,0.2021,89.9997
1,77.8,77.8,604.9639,56473.4,523,0,-0.1855,516.6336,-0.0683,0,0,0.0528,0.0522,0.0518,0,0,0,3.2116,0,0,100,0,0,0,0,0,0,0,0,0,0,592.3821,78640.48,-0.3082,-4.002,0,0,0,0,0,0,0,0,0,0,4.5642,-0.0349,-0.0174,-0.0174,581.3353,64.7017,88.3303,-23.6286,0.9609,0.7325,7851.235,-0.0349,597.0877,80.4541,-11.8143,0,201.5378,76.516,-6.3664,-0.0984,0,0,1536474,-516.6336,0,0,0,1.54E+08,0,0,48.6951,27.7808,574.118,600.3934,621.6766,-20.3222,-0.0349,-4.3716,4.6081,-0.1077,629.1774,600.3934,566.6171,112.5438,83.7598,49.9835,4.6093,-4.3716,-0.0361,598.7293,82.0957,62.5603,0.5399,2.2516,-69.7411,0.2016,90.0116
1,80.4,80.4,604.8576,56579.43,524,0,-0.188,518.3891,-0.0625,0,0,0.0528,0.0522,0.0518,0,0,0,3.2085,0,0,100,0,0,0,0,0,0,0,0,0,0,592.1297,78529.69,0.0191,1.0043,0,0,0,0,0,0,0,0,0,0,4.561,-0.0319,-0.0159,-0.0159,580.9103,62.5212,86.4685,-23.9473,0.9604,0.7231,7851.47,-0.0319,596.8752,78.4861,-11.9737,0,6639.517,74.4949,-5.6109,-0.0897,0,0,1536474,-518.3891,0,0,0,1.54E+08,0,0,48.6977,27.7845,573.5872,600.2338,621.7674,5.0993,-0.0319,-4.3666,4.5995,0.0067,622.3012,600.2338,573.0534,103.9121,81.8447,54.6643,4.5995,-4.3666,-0.0319,598.5295,80.1404,49.2478,0.5519,1.9009,84.0241,0.201,89.9993
1,83,83,604.832,56613.59,524,0,-0.1874,518.2084,-0.0823,0,0,0.0528,0.0522,0.0518,0,0,0,3.1833,0,0,100,0,0,0,0,0,0,0,0,0,0,592.1071,78455.2,0.3038,3.9098,0,0,0,0,0,0,0,0,0,0,4.5609,-0.0421,-0.021,-0.021,580.9568,62.7484,86.6236,-23.8752,0.9605,0.7244,7850.67,-0.0421,596.8736,78.6652,-11.9376,0,-1076.927,74.686,-5.7916,-0.0923,0,0,1536474,-518.2084,0,0,0,1.54E+08,0,0,48.6964,27.7852,573.6766,600.2091,621.7397,19.8542,-0.0421,-4.3575,4.6003,0.1062,628.8803,600.2091,566.5359,110.6719,82.0007,48.3275,4.6015,-4.3575,-0.0433,598.5417,80.3334,62.3444,0.5401,2.29,70.2187,0.2007,89.9886
1,85.6,85.6,604.78,56759.57,525,0,-0.1868,519.5043,-0.0721,0,0,0.0528,0.0522,0.0518,0,0,0,3.1894,0,0,100,0,0,0,0,0,0,0,0,0,0,592.5266,78316.86,-0.0585,-1.5415,0,0,0,0,0,0,0,0,0,0,4.5614,-0.0369,-0.0184,-0.0184,580.9903,61.486,85.2758,-23.7897,0.9607,0.721,7851.078,-0.0369,596.8501,77.3458,-11.8949,0,-338.2859,73.3809,-5.4957,-0.0894,0,0,1536474,-519.5043,0,0,0,1.54E+08,0,0,48.7,27.79,573.5202,600.3281,621.0652,-7.8266,-0.0369,-4.352,4.5888,-0.0205,622.3204,600.3281,572.265,102.8161,80.8239,52.7607,4.5888,-4.352,-0.0369,598.3045,78.8002,50.0554,0.5606,1.9487,-80.8885,0.1999,90.0022
1,88.2,88.2,604.9186,56846.76,525,0,-0.1882,519.8491,-0.0877,0,0,0.0528,0.0522,0.0518,0,0,0,3.1791,0,0,100,0,0,0,0,0,0,0,0,0,0,592.3483,78231.73,-0.3004,-3.719,0,0,0,0,0,0,0,0,0,0,4.5607,-0.0448,-0.0224,-0.0224,580.947,61.0979,85.0695,-23.9716,0.9604,0.7182,7850.458,-0.0448,596.928,77.0789,-11.9858,0,392.8663,73.0837,-5.1509,-0.0843,0,0,1536474,-519.8491,0,0,0,1.54E+08,0,0,48.6995,27.7914,573.5312,600.3514,621.6271,-18.8838,-0.0448,-4.3433,4.5876,-0.105,628.1553,600.3514,567.0029,108.3062,80.5023,47.1538,4.5888,-4.3433,-0.046,598.5032,78.6541,61.1524,0.5453,2.2969,-70.9295,0.1995,90.0113
1,90.8,90.8,604.8204,56966.57,527,0,-0.1865,520.852,-0.0844,0,0,0.0528,0.0522,0.0518,0,0,0,3.1725,0,0,100,0,0,0,0,0,0,0,0,0,0,592.4003,78105.28,0.0899,2.005,0,0,0,0,0,0,0,0,0,0,4.5617,-0.0431,-0.0215,-0.0215,581.0645,60.2125,83.9684,-23.7559,0.9607,0.7171,7850.591,-0.0431,596.9018,76.0498,-11.878,0,-784.1806,72.0905,-6.148,-0.1021,0,0,1536474,-520.852,0,0,0,1.54E+08,0,0,48.702,27.7953,573.701,600.3076,621.3326,10.1797,-0.0431,-4.3369,4.5789,0.0314,623.4169,600.3076,571.6166,102.5649,79.4556,50.7646,4.579,-4.3369,-0.0432,598.447,77.595,51.8003,0.5539,2.0204,78.4282,0.1989,89.9966
1,93.4,93.4,605.0906,57021.63,527,0,-0.1882,521.2291,-0.1027,0,0,0.0528,0.0522,0.0518,0,0,0,3.1722,0,0,100,0,0,0,0,0,0,0,0,0,0,592.0029,78017.65,0.2858,3.4546,0,0,0,0,0,0,0,0,0,0,4.5617,-0.0525,-0.0262,-0.0262,581.1191,59.89,83.8615,-23.9715,0.9604,0.7142,7849.854,-0.0525,597.1001,75.871,-11.9858,0,113.0708,71.8758,-5.7709,-0.0964,0,0,1536474,-521.2291,0,0,0,1.54E+08,0,0,48.7012,27.7966,573.9531,600.335,622.4931,17.5412,-0.0525,-4.3273,4.5782,0.0999,628.1685,600.335,568.2778,106.9394,79.1059,47.0487,4.5793,-4.3273,-0.0536,598.9271,77.698,59.8907,0.5353,2.273,72.0712,0.1984,89.9892
1,96,96,604.9182,57131.08,528,0,-0.1878,522.2303,-0.0956,0,0,0.0528,0.0522,0.0518,0,0,0,3.1679,0,0,100,0,0,0,0,0,0,0,0,0,0,592.1021,77884.32,-0.1339,-2.4232,0,0,0,0,0,0,0,0,0,0,4.5609,-0.0489,-0.0244,-0.0244,580.9963,58.766,82.6879,-23.9219,0.9605,0.7107,7850.136,-0.0489,596.9443,74.714,-11.961,0,432.1915,70.7269,-5.7697,-0.0982,0,0,1536474,-522.2303,0,0,0,1.54E+08,0,0,48.7043,27.801,573.7322,600.261,621.9633,-12.3026,-0.0489,-4.3213,4.5679,-0.0468,624.9202,600.261,570.7754,102.6899,78.0307,48.5451,4.5681,-4.3213,-0.0491,598.6522,76.4219,54.1448,0.5446,2.1154,-76.4858,0.1977,90.0051
1,98.6,98.6,605.3214,57244.5,529,0,-0.1877,522.9847,-0.1098,0,0,0.0528,0.0522,0.0518,0,0,0,3.1715,0,0,100,0,0,0,0,0,0,0,0,0,0,592.3348,77800.63,-0.27,-3.1653,0,0,0,0,0,0,0,0,0,0,4.5638,-0.0561,-0.028,-0.028,581.4075,58.4228,82.3367,-23.9139,0.9605,0.7096,7849.571,-0.0561,597.3501,74.3654,-11.957,0,60.9853,70.3798,-6.0153,-0.103,0,0,1536474,-522.9847,0,0,0,1.54E+08,0,0,48.704,27.8025,574.2362,600.6021,622.5958,-16.0712,-0.0561,-4.3131,4.5663,-0.0944,627.4496,600.6021,569.3824,104.4649,77.6174,46.3977,4.5673,-4.3131,-0.0571,599.1447,76.16,58.0672,0.5376,2.2515,-73.1949,0.1971,90.0102
1,101.2,101.2,604.9349,57353.36,530,0,-0.1876,523.9396,-0.111,0,0,0.0528,0.0522,0.0518,0,0,0,3.1344,0,0,100,0,0,0,0,0,0,0,0,0,0,592.1755,77670.23,0.167,2.8159,0,0,0,0,0,0,0,0,0,0,4.5609,-0.0567,-0.0283,-0.0283,581.0416,57.1021,80.9953,-23.8933,0.9605,0.705,7849.524,-0.0567,596.9705,73.0309,-11.9467,0,364.2796,69.0487,-6.0604,-0.1061,0,0,1536474,-523.9396,0,0,0,1.54E+08,0,0,48.706,27.8062,573.7612,600.2979,621.9106,14.2963,-0.0567,-4.3053,4.5585,0.0584,625.8354,600.2979,569.8364,101.8958,76.3583,45.8969,4.5589,-4.3053,-0.0571,598.6566,74.717,55.9989,0.544,2.2201,74.6484,0.1965,89.9937
1,103.8,103.8,604.9595,57431.48,530,0,-0.1874,524.3313,-0.1267,0,0,0.0528,0.0522,0.0518,0,0,0,3.1321,0,0,100,0,0,0,0,0,0,0,0,0,0,592.3589,77563.2,0.2509,2.7869,0,0,0,0,0,0,0,0,0,0,4.5609,-0.0648,-0.0324,-0.0324,581.0887,56.7574,80.6282,-23.8708,0.9605,0.7039,7848.889,-0.0648,597.0025,72.6712,-11.9354,0,283.0373,68.6928,-5.6687,-0.0999,0,0,1536474,-524.3313,0,0,0,1.54E+08,0,0,48.7058,27.8082,573.7471,600.3799,621.7269,14.15,-0.0648,-4.2952,4.556,0.0877,625.5891,600.3799,569.8849,101.2578,76.0486,45.5536,4.5568,-4.2952,-0.0656,598.618,74.2867,55.7042,0.5474,2.2228,74.7333,0.196,89.9905
1,106.4,106.4,604.6355,57557.02,531,0,-0.1864,525.3669,-0.1254,0,0,0.0528,0.0522,0.0518,0,0,0,3.1096,0,0,100,0,0,0,0,0,0,0,0,0,0,592.3806,77426.73,-0.2171,-3.1512,0,0,0,0,0,0,0,0,0,0,4.5594,-0.0641,-0.032,-0.032,580.8935,55.5266,79.2686,-23.742,0.9607,0.7005,7848.944,-0.0641,596.7215,71.3546,-11.871,0,-141.3563,67.3976,-5.6331,-0.1014,0,0,1536474,-525.3669,0,0,0,1.54E+08,0,0,48.7083,27.8123,573.4571,600.1813,620.9466,-15.9983,-0.0641,-4.2879,4.547,-0.0759,625.8333,600.1813,568.5704,100.4664,74.8144,43.2035,4.5476,-4.2879,-0.0647,598.195,72.8281,57.2629,0.552,2.3254,-73.0147,0.195,90.0082
1,109,109,604.8532,57672.81,532,0,-0.1878,526.4119,-0.1358,0,0,0.0528,0.0522,0.0518,0,0,0,3.0931,0,0,100,0,0,0,0,0,0,0,0,0,0,592.0916,77310.3,-0.2453,-2.4104,0,0,0,0,0,0,0,0,0,0,4.5594,-0.0694,-0.0347,-0.0347,580.9242,54.5123,78.4413,-23.929,0.9604,0.6949,7848.528,-0.0694,596.8769,70.465,-11.9645,0,-40244.42,66.4768,-5.5881,-0.1025,0,0,1536474,-526.4119,0,0,0,1.54E+08,0,0,48.7089,27.8149,573.6407,600.2146,621.8419,-12.2375,-0.0694,-4.2787,4.5426,-0.0858,624.7709,600.2146,570.7118,98.359,73.8027,44.2999,4.5434,-4.2787,-0.0702,598.5657,72.1539,54.0591,0.5458,2.2203,-76.54,0.1945,90.0093
1,111.6,111.6,604.7704,57801.56,533,0,-0.1869,527.1932,-0.1452,0,0,0.0528,0.0522,0.0518,0,0,0,3.0867,0,0,100,0,0,0,0,0,0,0,0,0,0,592.3257,77173.98,0.2527,3.4009,0,0,0,0,0,0,0,0,0,0,4.5594,-0.0742,-0.0371,-0.0371,580.9521,53.7589,77.5772,-23.8183,0.9606,0.693,7848.152,-0.0742,596.831,69.6378,-11.9092,0,-391.2245,65.6681,-5.8068,-0.108,0,0,1536474,-527.1932,0,0,0,1.54E+08,0,0,48.71,27.8182,573.5836,600.2467,621.341,17.2663,-0.0742,-4.2687,4.5366,0.0883,626.9295,600.2467,567.9951,99.7363,73.0535,40.8019,4.5374,-4.2687,-0.075,598.3904,71.1972,58.9344,0.5472,2.4444,72.065,0.1937,89.9904
1,114.2,114.2,604.782,57890.98,534,0,-0.1859,528.0864,-0.1544,0,0,0.0528,0.0522,0.0518,0,0,0,3.0528,0,0,100,0,0,0,0,0,0,0,0,0,0,592.486,77046.77,0.225,1.9752,0,0,0,0,0,0,0,0,0,0,4.5603,-0.0789,-0.0394,-0.0394,581.094,53.0076,76.6956,-23.688,0.9608,0.6911,7847.783,-0.0789,596.886,68.7996,-11.844,0,-466.6208,64.8516,-5.9136,-0.1116,0,0,1536474,-528.0864,0,0,0,1.54E+08,0,0,48.711,27.8213,573.7222,600.3121,621.158,10.028,-0.0789,-4.259,4.531,0.0787,623.1909,600.3121,571.6894,95.1045,72.2257,43.603,4.5317,-4.259,-0.0796,598.3975,70.3111,51.5015,0.5558,2.1811,78.5406,0.1931,89.9915
1,116.8,116.8,604.9901,58020.62,535,0,-0.1872,528.669,-0.1627,0,0,0.0528,0.0522,0.0518,0,0,0,3.045,0,0,100,0,0,0,0,0,0,0,0,0,0,592.0462,76890.29,-0.3104,-3.7247,0,0,0,0,0,0,0,0,0,0,4.5604,-0.0832,-0.0416,-0.0416,581.1318,52.4628,76.3211,-23.8583,0.9606,0.6874,7847.446,-0.0832,597.0374,68.3684,-11.9292,0,251.1917,64.392,-6.331,-0.1207,0,0,1536474,-528.669,0,0,0,1.54E+08,0,0,48.7126,27.8253,573.9857,600.2844,622.2336,-18.9098,-0.0832,-4.248,4.5234,-0.1085,628.7616,600.2844,567.4576,100.0926,71.6154,38.7886,4.5247,-4.248,-0.0845,598.8345,70.1655,61.304,0.5355,2.5805,-70.9543,0.1922,90.0117
1,119.4,119.4,604.78,58172.63,536,0,-0.1881,530.1368,-0.1669,0,0,0.0528,0.0522,0.0518,0,0,0,3.0391,0,0,100,0,0,0,0,0,0,0,0,0,0,592.2523,76760.71,-0.2118,-1.5075,0,0,0,0,0,0,0,0,0,0,4.5578,-0.0853,-0.0426,-0.0426,580.8126,50.6758,74.6433,-23.9674,0.9604,0.6789,7847.281,-0.0853,596.7909,66.6541,-11.9837,0,-482.0177,62.6596,-5.8632,-0.1157,0,0,1536474,-530.1368,0,0,0,1.54E+08,0,0,48.7142,27.8288,573.3956,600.2253,621.4726,-7.6531,-0.0853,-4.2393,4.5164,-0.074,622.6614,600.2253,572.2067,92.5246,70.0885,42.07,4.517,-4.2393,-0.0859,598.3645,68.2277,50.4546,0.5553,2.1993,-81.1701,0.1918,90.008
1,122,122,604.8588,58290.23,536,0,-0.1859,530.3057,-0.1879,0,0,0.0528,0.0522,0.0518,0,0,0,3.0044,0,0,100,0,0,0,0,0,0,0,0,0,0,592.222,76612.98,0.3485,3.9089,0,0,0,0,0,0,0,0,0,0,4.5601,-0.096,-0.048,-0.048,581.1679,50.8622,74.5531,-23.6909,0.9608,0.6822,7846.442,-0.096,596.9619,66.6562,-11.8455,0,7430.044,62.7077,-5.6943,-0.112,0,0,1536474,-530.3057,0,0,0,1.54E+08,0,0,48.7141,27.8316,573.9634,600.2642,621.7007,19.8458,-0.096,-4.226,4.5127,0.1218,628.8734,600.2642,566.7906,98.5677,69.9585,36.4849,4.5143,-4.226,-0.0976,598.6428,68.337,62.0828,0.5392,2.7016,70.1289,0.1907,89.9869
1,124.6,124.6,604.9877,58421.96,537,0,-0.1853,531.9203,-0.188,0,0,0.0528,0.0522,0.0518,0,0,0,2.9868,0,0,100,0,0,0,0,0,0,0,0,0,0,592.2341,76448.42,0.189,1.0174,0,0,0,0,0,0,0,0,0,0,4.5617,-0.0961,-0.048,-0.048,581.3723,49.452,73.0674,-23.6154,0.961,0.6768,7846.435,-0.0961,597.1159,65.1956,-11.8077,0,280.1034,61.2597,-5.0797,-0.1027,0,0,1536474,-531.9203,0,0,0,1.54E+08,0,0,48.7168,27.8364,574.2703,600.3502,621.99,5.165,-0.0961,-4.2164,4.5025,0.0661,622.5426,600.3502,573.7177,90.6223,68.4299,41.7974,4.503,-4.2164,-0.0966,598.8702,66.9499,48.8249,0.5455,2.1681,83.8927,0.19,89.9928
1,127.2,127.2,604.8912,58562.59,538,0,-0.1873,532.0926,-0.2106,0,0,0.0528,0.0522,0.0518,0,0,0,2.9896,0,0,100,0,0,0,0,0,0,0,0,0,0,592.2319,76285.6,-0.4106,-4.0231,0,0,0,0,0,0,0,0,0,0,4.5584,-0.1077,-0.0538,-0.0538,581.0191,48.9265,72.7986,-23.8721,0.9605,0.6721,7845.525,-0.1077,596.9338,64.8412,-11.9361,0,1011.904,60.8626,-5.9074,-0.1207,0,0,1536474,-532.0926,0,0,0,1.54E+08,0,0,48.7167,27.8395,573.7277,600.2877,621.7722,-20.4255,-0.1077,-4.2017,4.4984,-0.1435,629.282,600.2877,566.218,97.1894,68.1951,34.1254,4.5006,-4.2017,-0.1099,598.5959,66.5033,63.064,0.5402,2.848,-69.8132,0.189,90.0155
1,129.8,129.8,604.7422,58712.75,539,0,-0.1878,533.7648,-0.2071,0,0,0.0528,0.0522,0.0518,0,0,0,2.9625,0,0,100,0,0,0,0,0,0,0,0,0,0,592.5197,76114.16,-0.1736,-0.499,0,0,0,0,0,0,0,0,0,0,4.5568,-0.1059,-0.0529,-0.0529,580.8047,47.0399,70.9774,-23.9375,0.9604,0.6627,7845.667,-0.1059,596.763,62.9982,-11.9688,0,-351.3354,59.0087,-5.2352,-0.1113,0,0,1536474,-533.7648,0,0,0,1.54E+08,0,0,48.72,27.8448,573.27,600.2971,621.0454,-2.5332,-0.1059,-4.1925,4.4867,-0.0607,621.1794,600.2971,573.136,87.4146,66.5324,39.3712,4.4871,-4.1925,-0.1063,598.2042,64.4394,48.0434,0.5653,2.2203,-86.9733,0.1883,90.0066
1,132.4,132.4,604.6961,58827.47,540,0,-0.1882,533.8976,-0.245,0,0,0.0528,0.0522,0.0518,0,0,0,2.9314,0,0,100,0,0,0,0,0,0,0,0,0,0,592.159,75961.98,0.45,4.0833,0,0,0,0,0,0,0,0,0,0,4.5551,-0.1252,-0.0625,-0.0625,580.6999,46.8023,70.7985,-23.9962,0.9603,0.6611,7844.154,-0.1251,596.6973,62.7997,-11.9981,0,-249.6415,58.8004,-6.1024,-0.1304,0,0,1536474,-533.8976,0,0,0,1.54E+08,0,0,48.7179,27.8466,573.2917,600.1364,621.4231,20.7329,-0.1252,-4.1746,4.4871,0.1573,629.1224,600.1364,565.5925,95.2248,66.2388,31.695,4.4898,-4.1746,-0.1279,598.2838,64.3862,63.5298,0.5437,3.0044,69.6273,0.1873,89.9831
1,135,135,604.6569,59032.27,542,0,-0.1878,535.8854,-0.2337,0,0,0.0528,0.0522,0.0518,0,0,0,2.917,0,0,100,0,0,0,0,0,0,0,0,0,0,592.2395,75750.41,0.1353,-0.014,0,0,0,0,0,0,0,0,0,0,4.5555,-0.1195,-0.0597,-0.0597,580.7179,44.8325,68.7716,-23.939,0.9604,0.6519,7844.601,-0.1195,596.6772,60.7918,-11.9695,0,-210.0931,56.8021,-6.1146,-0.1364,0,0,1536474,-535.8854,0,0,0,1.54E+08,0,0,48.7227,27.8535,573.2788,600.1403,621.2301,-0.0711,-0.1195,-4.165,4.4711,0.0473,621.2302,600.1403,573.2787,85.3449,64.2549,37.3933,4.4713,-4.165,-0.1197,598.2164,62.331,47.9516,0.5602,2.2824,-89.915,0.1866,89.9949
1,137.6,137.6,604.8368,59194.57,542,0,-0.1879,535.884,-0.2742,0,0,0.0528,0.0522,0.0518,0,0,0,2.8635,0,0,100,0,0,0,0,0,0,0,0,0,0,592.1292,75565.75,-0.5164,-4.0713,0,0,0,0,0,0,0,0,0,0,4.5558,-0.1402,-0.07,-0.07,580.8762,44.9923,68.9528,-23.9606,0.9604,0.6525,7842.979,-0.1401,596.8499,60.9659,-11.9803,0,-2405.559,56.9726,-6.116,-0.1359,0,0,1536474,-535.884,0,0,0,1.54E+08,0,0,48.7208,27.856,573.5743,600.2142,621.8023,-20.6723,-0.1402,-4.1448,4.4703,-0.1805,629.4504,600.2142,565.9262,93.5664,64.3302,30.0422,4.4738,-4.1448,-0.1437,598.5303,62.6463,63.5242,0.5398,3.1145,-69.6972,0.1853,90.0194
1,140.2,140.2,604.5546,59379.03,543,0,-0.1876,538.2039,-0.2615,0,0,0.0528,0.0522,0.0518,0,0,0,2.8918,0,0,100,0,0,0,0,0,0,0,0,0,0,592.3417,75332.89,-0.115,0.5178,0,0,0,0,0,0,0,0,0,0,4.5542,-0.1337,-0.0668,-0.0668,580.6345,42.4306,66.3507,-23.9201,0.9604,0.6395,7843.488,-0.1337,596.5812,58.3773,-11.9601,0,-146.0505,54.3907,-4.7961,-0.113,0,0,1536474,-538.2039,0,0,0,1.54E+08,0,0,48.7263,27.8637,573.1171,600.1115,620.866,2.6286,-0.1337,-4.1347,4.4523,-0.0402,621.0103,600.1115,572.9728,82.8064,61.9076,34.7689,4.4525,-4.1347,-0.1339,598.0316,59.8276,48.0375,0.5649,2.3816,86.8585,0.1839,90.0044
1,142.8,142.8,604.9247,59549.7,544,0,-0.1853,537.884,-0.3198,0,0,0.0528,0.0522,0.0518,0,0,0,2.8096,0,0,100,0,0,0,0,0,0,0,0,0,0,592.2809,75146.35,0.5591,4.069,0,0,0,0,0,0,0,0,0,0,4.558,-0.1635,-0.0816,-0.0816,581.2919,43.4079,67.0407,-23.6328,0.9609,0.6475,7841.155,-0.1634,597.0471,59.1632,-11.8164,0,614.1066,55.2243,-6.116,-0.1409,0,0,1536474,-537.884,0,0,0,1.54E+08,0,0,48.7221,27.865,574.146,600.3245,621.8168,20.6632,-0.1635,-4.1094,4.4562,0.1954,629.5265,600.3245,566.4363,91.6425,62.4406,28.5523,4.4603,-4.1094,-0.1676,598.7625,60.8785,63.0902,0.5371,3.2096,69.5388,0.1833,89.9791
1,145.4,145.4,604.9059,59804.58,546,0,-0.1874,540.7203,-0.2994,0,0,0.0528,0.0522,0.0518,0,0,0,2.8231,0,0,100,0,0,0,0,0,0,0,0,0,0,592.725,74861.6,0.0563,-1.033,0,0,0,0,0,0,0,0,0,0,4.5563,-0.153,-0.0764,-0.0764,581.0143,40.294,64.1856,-23.8916,0.9605,0.6278,7841.977,-0.1529,596.942,56.2217,-11.9458,0,891.3006,52.2398,-5.2797,-0.131,0,0,1536474,-540.7203,0,0,0,1.54E+08,0,0,48.7294,27.8748,573.4911,600.4734,621.1872,-5.2441,-0.153,-4.0979,4.4329,0.0197,621.757,600.4734,572.9213,81.0367,59.7531,32.2011,4.4329,-4.0979,-0.153,598.384,57.6636,48.8356,0.5642,2.5166,-83.7991,0.182,89.9979
1,148,148,605.0217,59994.7,546,0,-0.1884,540.3835,-0.3631,0,0,0.0528,0.0522,0.0518,0,0,0,2.7242,0,0,100,0,0,0,0,0,0,0,0,0,0,592.2018,74631.18,-0.639,-3.9257,0,0,0,0,0,0,0,0,0,0,4.5546,-0.1856,-0.0927,-0.0927,580.9865,40.603,64.6382,-24.0352,0.9603,0.6282,7839.425,-0.1855,597.01,56.6265,-12.0176,0,273.6854,52.6206,-5.6165,-0.1383,0,0,1536474,-540.3835,0,0,0,1.54E+08,0,0,48.7253,27.8769,573.7093,600.3563,622.1636,-19.9365,-0.1856,-4.0694,4.4356,-0.2233,629.3118,600.3563,566.561,88.9283,59.9728,26.1775,4.441,-4.0694,-0.191,598.7431,58.3595,62.7508,0.5386,3.3971,-70.2745,0.1806,90.0238
1,150.6,150.6,604.7625,60280.93,548,0,-0.1866,543.1199,-0.3462,0,0,0.0528,0.0522,0.0518,0,0,0,2.7339,0,0,100,0,0,0,0,0,0,0,0,0,0,592.4731,74306.62,-0.0242,1.5042,0,0,0,0,0,0,0,0,0,0,4.5548,-0.177,-0.0884,-0.0884,580.9621,37.8422,61.6426,-23.8004,0.9606,0.6139,7840.098,-0.1769,596.829,53.7091,-11.9002,0,-531.6348,49.7424,-4.8801,-0.129,0,0,1536474,-543.1199,0,0,0,1.54E+08,0,0,48.7328,27.8876,573.558,600.2895,621.2038,7.6367,-0.177,-4.0546,4.4108,-0.0085,622.3978,600.2895,572.3639,79.278,57.1696,29.244,4.4108,-4.0546,-0.177,598.3504,55.2305,50.034,0.5581,2.7109,81.1131,0.1792,90.0009
1,153.2,153.2,604.73,60496.17,548,0,-0.1887,542.4985,-0.4356,0,0,0.0528,0.0522,0.0518,0,0,0,2.5859,0,0,100,0,0,0,0,0,0,0,0,0,0,592.4365,74037.52,0.6975,3.7084,0,0,0,0,0,0,0,0,0,0,4.5503,-0.2227,-0.1112,-0.1112,580.6529,38.1544,62.2315,-24.0771,0.9602,0.6131,7836.523,-0.2226,596.7043,54.2058,-12.0386,0,-387.175,50.193,-5.5015,-0.1442,0,0,1536474,-542.4985,0,0,0,1.54E+08,0,0,48.7262,27.8891,573.0951,600.255,621.1839,18.8374,-0.2227,-4.0174,4.4178,0.2437,627.6843,600.255,566.5948,85.1859,57.7565,24.0963,4.4242,-4.0174,-0.2291,598.178,55.6796,61.0896,0.551,3.5352,70.9617,0.1777,89.9742
1,155.8,155.8,604.8418,60851.84,551,0,-0.1852,545.8725,-0.4148,0,0,0.0528,0.0522,0.0518,0,0,0,2.6417,0,0,100,0,0,0,0,0,0,0,0,0,0,592.3671,73617.3,-0.0741,-2.005,0,0,0,0,0,0,0,0,0,0,4.5552,-0.212,-0.1058,-0.1058,581.2161,35.3436,58.9693,-23.6257,0.9609,0.5994,7837.36,-0.2119,596.9666,51.0941,-11.8129,0,-4210.098,47.1565,-5.1275,-0.1451,0,0,1536474,-545.8725,0,0,0,1.54E+08,0,0,48.7358,27.9028,574.0024,600.2999,621.5498,-10.1808,-0.212,-3.9985,4.386,-0.0259,623.638,600.2999,571.9142,77.7655,54.4274,26.0417,4.3861,-3.9985,-0.2121,598.6174,52.7449,51.7238,0.5488,2.9862,-78.4088,0.1755,90.0028
1,158.4,158.4,604.8978,61152.48,551,0,-0.1885,545.332,-0.5201,0,0,0.0528,0.0522,0.0518,0,0,0,2.4959,0,0,100,0,0,0,0,0,0,0,0,0,0,592.6175,73309.27,-0.8449,-3.4773,0,0,0,0,0,0,0,0,0,0,4.5498,-0.2659,-0.1327,-0.1327,580.8394,35.5075,59.5659,-24.0584,0.9602,0.5961,7833.146,-0.2657,596.8784,51.5465,-12.0292,0,1160.395,47.5367,-5.668,-0.1596,0,0,1536474,-545.332,0,0,0,1.54E+08,0,0,48.7278,27.9042,573.2893,600.4262,621.3538,-17.668,-0.2659,-3.9551,4.395,-0.2951,627.1495,600.4262,567.4936,81.8175,55.0942,22.1616,4.4043,-3.9551,-0.2752,598.3564,53.0244,59.6559,0.552,3.6919,-71.8387,0.174,90.0308
1,161,161,604.6765,61595.27,555,0,-0.1862,549.1568,-0.5179,0,0,0.0528,0.0522,0.0518,0,0,0,2.5031,0,0,100,0,0,0,0,0,0,0,0,0,0,592.7896,72769.7,0.1426,2.396,0,0,0,0,0,0,0,0,0,0,4.5504,-0.2647,-0.1321,-0.1321,580.909,31.7522,55.5197,-23.7675,0.9607,0.5719,7833.24,-0.2645,596.754,47.5972,-11.8838,0,-308.0569,43.636,-5.8432,-0.184,0,0,1536474,-549.1568,0,0,0,1.54E+08,0,0,48.7371,27.9201,573.3418,600.347,620.6195,12.1702,-0.2647,-3.9247,4.3607,0.0498,623.5684,600.347,570.3929,74.4116,51.1902,21.2361,4.361,-3.9247,-0.265,598.1028,48.946,53.1755,0.5633,3.504,76.3794,0.1713,89.9946
1,163.6,163.6,604.7852,61952.46,554,0,-0.1889,548.4446,-0.6785,0,0,0.0528,0.0522,0.0518,0,0,0,2.2259,0,0,100,0,0,0,0,0,0,0,0,0,0,592.5175,72324.2,1.0384,3.169,0,0,0,0,0,0,0,0,0,0,4.5447,-0.3468,-0.173,-0.173,580.6564,32.2118,56.3406,-24.1289,0.9601,0.5717,7826.832,-0.3465,596.7422,48.2976,-12.0645,0,-784.5258,44.2762,-5.5554,-0.1725,0,0,1536474,-548.4446,0,0,0,1.54E+08,0,0,48.7246,27.9216,573.0727,600.3162,621.2508,16.1124,-0.3468,-3.86,4.3757,0.3625,626.1426,600.3162,568.1808,77.698,51.8716,19.7362,4.3896,-3.86,-0.3607,598.2132,49.7686,57.9618,0.5544,3.9368,73.1113,0.1689,89.9632
1,166.2,166.2,604.6049,62572.02,558,0,-0.1861,552.7198,-0.7045,0,0,0.0528,0.0522,0.0518,0,0,0,2.1935,0,0,100,0,0,0,0,0,0,0,0,0,0,592.9668,71606.71,-0.4034,-2.7604,0,0,0,0,0,0,0,0,0,0,4.5454,-0.3601,-0.1796,-0.1796,580.8228,28.103,51.8851,-23.7821,0.9607,0.5416,7825.794,-0.3598,596.6776,43.9578,-11.8911,0,-233.8166,39.9941,-5.2802,-0.1879,0,0,1536474,-552.7198,0,0,0,1.54E+08,0,0,48.7333,27.9406,573.1471,600.364,620.2439,-14.0323,-0.3601,-3.8124,4.338,-0.1408,624.1078,600.364,569.2832,71.388,47.6442,16.5634,4.3401,-3.8124,-0.3622,597.9183,45.1985,54.8246,0.5669,4.31,-74.6048,0.1655,90.0149
1,168.8,168.8,604.7601,63073.34,558,0,-0.1872,552.1467,-0.9239,0,0,0.0528,0.0522,0.0518,0,0,0,1.7994,0,0,100,0,0,0,0,0,0,0,0,0,0,592.4163,71004.41,-1.5132,-2.827,0,0,0,0,0,0,0,0,0,0,4.5402,-0.4723,-0.2353,-0.2353,580.807,28.6603,52.6133,-23.9531,0.9604,0.5447,7817.055,-0.4717,596.7757,44.629,-11.9766,0,-613.9158,40.6368,-5.8533,-0.2042,0,0,1536474,-552.1467,0,0,0,1.54E+08,0,0,48.7161,27.9424,573.394,600.2607,621.3635,-14.3903,-0.4723,-3.7244,4.3589,-0.5276,625.3493,600.2607,569.4083,73.2026,48.114,17.2616,4.3875,-3.7244,-0.5009,598.3394,46.1927,55.941,0.5515,4.2408,-74.5186,0.1622,90.0502
1,171.4,171.4,604.5746,63886.75,562,0,-0.1798,556.5092,-1.0872,0,0,0.0528,0.0522,0.0518,0,0,0,1.5445,0,0,100,0,0,0,0,0,0,0,0,0,0,593.1719,69974.63,0.8141,3.1754,0,0,0,0,0,0,0,0,0,0,4.5423,-0.5557,-0.2767,-0.2767,581.558,25.0488,48.0654,-23.0166,0.9619,0.5211,7810.572,-0.5549,596.9024,40.3932,-11.5083,0,-221.9946,36.5571,-5.4908,-0.2192,0,0,1536474,-556.5092,0,0,0,1.54E+08,0,0,48.713,27.9607,574.2083,600.4163,619.9381,16.1749,-0.5557,-3.6252,4.3383,0.2837,625.0809,600.4163,569.0656,68.5717,43.9071,12.5564,4.3465,-3.6252,-0.5639,598.1876,41.6784,56.0153,0.5597,5.4611,72.362,0.1574,89.9718
1,174,174,604.5784,64578.25,561,0,-0.1886,555.9115,-1.4458,0,0,0.0528,0.0522,0.0518,0,0,0,0.9395,0,0,100,0,0,0,0,0,0,0,0,0,0,592.9481,69087.52,2.3018,2.4035,0,0,0,0,0,0,0,0,0,0,4.5249,-0.739,-0.3675,-0.3675,580.3862,24.4747,48.6669,-24.1922,0.96,0.5029,7796.36,-0.7377,596.5143,40.6028,-12.0961,0,-222.9232,36.5708,-5.0885,-0.2079,0,0,1536474,-555.9115,0,0,0,1.54E+08,0,0,48.6834,27.9609,572.5053,600.3355,620.2712,12.2706,-0.739,-3.4865,4.3783,0.8002,623.239,600.3355,569.5375,67.3275,44.424,13.626,4.4401,-3.4865,-0.8008,597.704,41.7925,53.7015,0.5735,4.9411,76.4034,0.1528,89.9341
1,176.6,176.6,604.5368,65839.86,564,0,-0.1765,559.2654,-1.9438,0,0,0.0528,0.0522,0.0518,0,0,0,0.1324,0,0,100,0,0,0,0,0,0,0,0,0,0,593.2231,67575.76,-2.2049,-3.4502,0,0,0,0,0,0,0,0,0,0,4.5248,-0.9936,-0.4931,-0.4931,581.8402,22.5748,45.2714,-22.6966,0.9625,0.4987,7776.706,-0.9911,596.9713,37.7059,-11.3483,0,-204.2425,33.9231,-4.7346,-0.2097,0,0,1536474,-559.2654,0,0,0,1.54E+08,0,0,48.647,27.9692,574.6608,600.4067,619.84,-17.6669,-0.9936,-3.2779,4.4166,-0.7643,625.9281,600.4067,568.5728,66.6627,41.1413,9.3074,4.4701,-3.2779,-1.0471,598.3025,39.0371,57.3553,0.555,7.1623,-70.9859,0.1451,90.0603
1,179.2,179.2,604.5342,66698.14,567,0,-0.1881,560.3037,-2.3475,0,0,0.0528,0.0522,0.0518,0,0,0,-0.5806,0,0,100,0,0,0,0,0,0,0,0,0,0,593.3342,66446.95,-3.7793,-1.9953,0,0,0,0,0,0,0,0,0,0,4.5036,-1.2,-0.5947,-0.5947,580.2977,19.994,44.2305,-24.2365,0.9599,0.452,7760.845,-1.1965,596.4554,36.1517,-12.1183,0,-205.8131,32.1123,-6.6963,-0.3349,0,0,1536474,-560.3037,0,0,0,1.54E+08,0,0,48.6161,27.9731,572.2071,600.4435,619.7111,-10.2421,-1.2,-3.1149,4.4534,-1.3068,621.8253,600.4435,570.093,61.5216,40.1398,9.7893,4.6006,-3.1149,-1.3472,597.4539,37.1502,51.7323,0.5867,6.2846,-78.3369,0.1385,90.0812
1,181.8,181.8,604.4271,68258.39,566,0,-0.1726,560.7842,-3.5343,0,0,0.0528,0.0522,0.0518,0,0,0,-2.488,0,0,100,0,0,0,0,0,0,0,0,0,0,593.5839,64505.96,4.3368,3.6952,0,0,0,0,0,0,0,0,0,0,4.4903,-1.8066,-0.8912,-0.8912,582.052,21.2678,43.6429,-22.3751,0.963,0.4873,7714.603,-1.7985,596.9688,36.1846,-11.1876,0,-155.3235,32.4554,-5.2158,-0.2452,0,0,1536474,-560.7842,0,0,0,1.54E+08,0,0,48.503,27.9452,574.8571,600.4635,619.1667,19.1189,-1.8066,-2.7133,4.646,1.4877,626.2756,600.4635,567.7482,65.4914,39.6793,6.9641,4.8132,-2.7133,-1.9738,598.1624,37.3783,58.5273,0.559,9.4041,69.6034,0.1261,89.9241
1,184.4,184.4,604.2452,69334.23,569,0,-0.1862,564.6564,-3.9699,0,0,0.0528,0.0522,0.0518,0,0,0,-3.1911,0,0,100,0,0,0,0,0,0,0,0,0,0,593.9143,63165.71,5.6296,1.5441,0,0,0,0,0,0,0,0,0,0,4.4651,-2.0293,-0.9995,-0.9995,580.0515,15.3951,39.5888,-24.1937,0.96,0.3889,7697.764,-2.0192,596.1806,31.5242,-12.0969,0,-115.2656,27.492,-4.3436,-0.2821,0,0,1536474,-564.6564,0,0,0,1.54E+08,0,0,48.4721,27.9529,571.5977,600.4666,618.3188,8.0096,-2.0293,-2.5303,4.6778,1.9262,619.6537,600.4666,570.2628,54.9973,35.8102,5.6064,4.9438,-2.5303,-2.2953,596.7944,32.138,49.3909,0.6115,9.8097,80.5374,0.1182,89.9186
1,187,187,604.7071,71112.39,568,0,-0.1748,561.0356,-5.7922,0,0,0.0528,0.0522,0.0518,0,0,0,-6.1558,0,0,100,0,0,0,0,0,0,0,0,0,0,593.7543,60915.81,-7.5208,-3.9046,0,0,0,0,0,0,0,0,0,0,4.438,-2.9608,-1.4483,-1.4483,581.7946,20.759,43.6715,-22.9125,0.9621,0.4753,7628.122,-2.9394,597.0696,36.034,-11.4563,0,-453.0334,32.2153,-6.9644,-0.3355,0,0,1536474,-561.0356,0,0,0,1.54E+08,0,0,48.2891,27.89,574.3845,600.6972,619.6819,-20.5076,-2.9608,-1.9565,5.0157,-2.5415,627.5869,600.6972,566.4796,66.5513,39.6616,5.444,5.4019,-1.9565,-3.347,598.2546,37.219,61.1073,0.56,12.2247,-68.9201,0.0984,90.075
1,189.6,189.6,604.0207,72343.66,577,0,-0.1806,569.1526,-6.1202,0,0,0.0528,0.0522,0.0518,0,0,0,-6.6828,0,0,100,0,0,0,0,0,0,0,0,0,0,594.5958,59430.91,-7.9878,-1.1361,0,0,0,0,0,0,0,0,0,0,4.4195,-3.1285,-1.5285,-1.5285,580.313,11.1604,34.8681,-23.7077,0.9608,0.3201,7615.717,-3.1047,596.1181,26.9655,-11.8539,0,-89.6097,23.0143,-7.8474,-0.7031,0,0,1536474,-569.1526,0,0,0,1.54E+08,0,0,48.2741,27.9093,571.6992,600.568,616.9371,-5.9769,-3.1285,-1.7913,5.0098,-2.6949,617.7134,600.568,570.9229,48.5608,31.4154,1.7703,5.4339,-1.7913,-3.5526,596.4014,27.2488,46.7905,0.6336,27.4308,-82.5991,0.09,90.0747
1,192.2,192.2,604.7465,74248.75,567,0,-0.1763,561.1946,-8.6092,0,0,0.0528,0.0522,0.0518,0,0,0,-10.6434,0,0,100,0,0,0,0,0,0,0,0,0,0,593.4967,56984.66,10.2735,4.008,0,0,0,0,0,0,0,0,0,0,4.3732,-4.4008,-2.1303,-2.1303,581.3178,20.1232,43.5519,-23.4287,0.9613,0.4621,7522.907,-4.3541,596.937,35.7424,-11.7144,0,-620.7021,31.8376,-5.8054,-0.2885,0,0,1536474,-561.1946,0,0,0,1.54E+08,0,0,48.0188,27.8074,573.8053,600.6209,620.2244,21.449,-4.4008,-1.0459,5.5044,3.4073,628.6178,600.6209,565.412,67.4232,39.4263,4.2174,6.0593,-1.0459,-4.9557,598.2169,37.0223,63.2058,0.5571,15.9869,68.6288,0.0577,89.9351
1,194.8,194.8,603.9457,75650.59,579,0,-0.1719,573.9521,-9.0062,0,0,0.0528,0.0522,0.0518,0,0,0,-11.2455,0,0,100,0,0,0,0,0,0,0,0,0,0,594.6613,55308.07,9.419,0.7717,0,0,0,0,0,0,0,0,0,0,4.3627,-4.6037,-2.2253,-2.2253,581.0491,7.097,29.9936,-22.8966,0.9621,0.2366,7508.315,-4.5527,596.3135,22.3614,-11.4483,0,-87.4933,18.5453,-5.0479,-0.7113,0,0,1536474,-573.9521,0,0,0,1.54E+08,0,0,47.9994,27.8273,572.8731,600.5385,616.7534,4.1382,-4.6037,-0.8532,5.5037,3.1176,617.1403,600.5385,572.4862,43.1882,26.5864,-1.4659,5.9636,-0.8532,-5.0636,596.7217,22.7696,44.6541,0.6282,-29.4619,84.6594,0.0468,89.9376
1,197.4,197.4,604.4575,77571.71,567,0,-0.1805,560.7775,-11.6487,0,0,0.0528,0.0522,0.0518,0,0,0,-15.5893,0,0,100,0,0,0,0,0,0,0,0,0,0,593.4509,52859.85,-13.6388,-4.0856,0,0,0,0,0,0,0,0,0,0,4.3001,-5.9545,-2.8506,-2.8506,580.1074,19.3299,43.68,-24.3501,0.9597,0.4425,7412.592,-5.8701,596.3408,35.5633,-12.1751,0,-167.2142,31.505,-6.2225,-0.3219,0,0,1536474,-560.7775,0,0,0,1.54E+08,0,0,47.7318,27.7172,572.0095,600.4141,619.7,-22.3055,-5.9545,-0.073,6.0319,-4.434,628.5064,600.4141,563.2031,67.7289,39.6366,2.4256,6.8025,-0.073,-6.7251,597.3746,36.597,65.3033,0.5698,27.9225,-68.4554,0.0044,90.0563
1,200,200,604.1474,79143.98,580,0,-0.1617,578.3348,-12.1302,0,0,0.0528,0.0522,0.0518,0,0,0,-16.3678,0,0,100,0,0,0,0,0,0,0,0,0,0,594.9177,51054.93,-11.2354,-0.4487,0,0,0,0,0,0,0,0,0,0,4.3062,-6.2006,-2.9632,-2.9632,582.2797,3.9449,25.8126,-21.8677,0.9638,0.1528,7395.415,-6.1092,596.8582,18.5234,-10.9339,0,-118.6734,14.8788,-1.6652,-0.4221,0,0,1536474,-578.3348,0,0,0,1.54E+08,0,0,47.7055,27.735,574.696,600.7542,616.9656,-2.4559,-6.2006,0.1477,6.0438,-3.6434,617.1078,600.7542,574.5538,38.773,22.4194,-3.781,6.5638,0.1477,-6.7206,597.4719,19.1371,42.554,0.6157,-10.2547,-86.6859,-0.0091,90.0532
1,202.6,202.6,604.3135,81015.91,567,0,-0.1836,561.4184,-15.0555,0,0,0.0528,0.0522,0.0518,0,0,0,-21.1887,0,0,100,0,0,0,0,0,0,0,0,0,0,593.7956,48585.48,15.5348,3.9605,0,0,0,0,0,0,0,0,0,0,4.2235,-7.6959,-3.6392,-3.6392,579.1381,17.7197,42.8951,-25.1754,0.9583,0.4131,7292.733,-7.5567,595.9217,34.5033,-12.5877,0,-123.8396,30.3074,-5.5816,-0.315,0,0,1536474,-561.4184,0,0,0,1.54E+08,0,0,47.4125,27.6094,570.3731,600.4427,618.9775,22.108,-7.6959,0.9943,6.6355,4.9394,627.5289,600.4427,561.8217,66.1105,39.0243,0.4033,7.4414,0.9943,-8.5018,596.5977,35.1794,65.7072,0.5878,163.9239,68.8534,-0.0661,89.9522
1,205.2,205.2,604.0695,82801.46,587,0,-0.1501,582.2299,-15.8676,0,0,0.0528,0.0522,0.0518,0,0,0,-22.5032,0,0,100,0,0,0,0,0,0,0,0,0,0,595.5457,46550.04,10.3919,0.2763,0,0,0,0,0,0,0,0,0,0,4.2383,-8.111,-3.8244,-3.8244,583.4076,1.1777,21.8396,-20.6619,0.9658,0.0539,7264.732,-7.9569,597.1822,14.9523,-10.331,0,-111.8571,11.5087,-4.7701,-4.0504,0,0,1536474,-582.2299,0,0,0,1.54E+08,0,0,47.3537,27.6119,576.1771,600.9299,615.9914,1.5496,-8.111,1.3079,6.7156,3.2887,616.0516,600.9299,576.1169,33.8217,18.7,-6.113,7.0718,1.3079,-8.4672,597.6995,15.4696,39.9347,0.6213,-5.5328,87.7745,-0.0875,89.957
1,207.8,207.8,604.7333,84523.02,567,0,-0.1839,561.3758,-18.4709,0,0,0.0528,0.0522,0.0518,0,0,0,-26.7626,0,0,100,0,0,0,0,0,0,0,0,0,0,593.4777,44212.24,-18.7222,-3.9132,0,0,0,0,0,0,0,0,0,0,4.1559,-9.4418,-4.4109,-4.4109,579.107,17.7312,43.3575,-25.6263,0.9576,0.409,7176.394,-9.2351,596.1912,34.8154,-12.8132,0,-554.1079,30.5444,-5.6242,-0.3172,0,0,1536474,-561.3758,0,0,0,1.54E+08,0,0,47.1019,27.5068,570.5184,600.5836,620.5334,-22.3261,-9.4418,2.0663,7.2261,-5.8244,629.0494,600.5836,562.0023,67.6736,39.2078,0.6265,8.1882,2.0663,-10.4039,597.2118,35.836,67.0471,0.5754,108.0185,-69.1211,-0.1494,90.042
1,210.4,210.4,604.0731,86415.15,588,0,-0.1429,584.8087,-19.572,0,0,0.0528,0.0522,0.0518,0,0,0,-28.4591,0,0,100,0,0,0,0,0,0,0,0,0,0,595.7683,42053.93,-10.6538,0.0274,0,0,0,0,0,0,0,0,0,0,4.17,-10.0046,-4.6557,-4.6557,584.0599,-0.7488,19.2644,-20.0132,0.9669,-0.0389,7139.679,-9.7735,597.402,12.5933,-10.0066,0,-115.6754,9.2578,-3.1913,4.2619,0,0,1536474,-584.8087,0,0,0,1.54E+08,0,0,47.0152,27.4944,577.1162,601.0086,615.7701,0.1574,-10.0046,2.4548,7.3687,-3.2926,615.7707,601.0086,577.1155,30.962,16.1999,-7.6932,7.6753,2.4548,-10.3112,597.9649,13.1562,38.6552,0.6181,-4.0246,89.7667,-0.1811,90.0367
1,211.4,211.4,604.5894,87316.28,582,0,-0.1557,570.4718,-21.4473,0,0,0.0528,0.0522,0.0518,0,0,0,-31.6411,0,0,100,0,0,0,0,0,0,0,0,0,0,594.6584,40837.97,15.3101,3.2041,0,0,0,0,0,0,0,0,0,0,4.1236,-10.9632,-5.0685,-5.0685,582.594,12.1222,34.1176,-21.9954,0.9636,0.3553,7078,-10.6878,597.2576,26.7858,-10.9977,0,-287.2098,23.1199,-11.5282,-0.951,0,0,1536474,-570.4718,0,0,0,1.54E+08,0,0,46.8307,27.408,575.3917,600.923,618.6035,18.6302,-10.9632,2.9723,7.7605,4.6735,625.5266,600.923,568.4687,55.0548,30.4512,-2.0031,8.3266,2.9723,-11.5293,598.3061,27.8343,57.0579,0.5688,-27.4848,69.6148,-0.2304,89.9637